{"dir":"out","text":"{\"assets_ids\":[\"56108879726720646120583724001239294777304794469144970684362785767667828318889\",\"107011546575057755426871645700605806081353395825571114128343592072429146374928\"],\"custom_feature_enabled\":true,\"type\":\"market\"}","ts_local_ms":1781254836967}
{"dir":"out","text":"PING","ts_local_ms":1781254836981}
{"dir":"in","text":"[{\"market\":\"0x9c535590faae21bf76fed844aa47fc3c5c82253ef38bd545bf12c93470502685\",\"asset_id\":\"56108879726720646120583724001239294777304794469144970684362785767667828318889\",\"timestamp\":\"1781254836832\",\"hash\":\"52a622e4dd8859ef5d92b98c111f9af614e4a4c2\",\"bids\":[{\"price\":\"0.01\",\"size\":\"57284.15\"},{\"price\":\"0.02\",\"size\":\"22462.28\"},{\"price\":\"0.03\",\"size\":\"2161.73\"},{\"price\":\"0.04\",\"size\":\"1743.28\"},{\"price\":\"0.05\",\"size\":\"1914.1\"},{\"price\":\"0.06\",\"size\":\"991.6\"},{\"price\":\"0.07\",\"size\":\"1035.18\"},{\"price\":\"0.08\",\"size\":\"832.11\"},{\"price\":\"0.09\",\"size\":\"679.28\"},{\"price\":\"0.1\",\"size\":\"314.76\"},{\"price\":\"0.11\",\"size\":\"597\"},{\"price\":\"0.12\",\"size\":\"335.24\"},{\"price\":\"0.13\",\"size\":\"84.2\"},{\"price\":\"0.14\",\"size\":\"69.95\"},{\"price\":\"0.15\",\"size\":\"52.86\"},{\"price\":\"0.16\",\"size\":\"66.94\"},{\"price\":\"0.17\",\"size\":\"54.08\"},{\"price\":\"0.18\",\"size\":\"370.6\"},{\"price\":\"0.19\",\"size\":\"39.67\"},{\"price\":\"0.2\",\"size\":\"729.5\"},{\"price\":\"0.21\",\"size\":\"177.95\"},{\"price\":\"0.22\",\"size\":\"513.6\"},{\"price\":\"0.23\",\"size\":\"39.3\"},{\"price\":\"0.24\",\"size\":\"58.1\"},{\"price\":\"0.25\",\"size\":\"27.9\"},{\"price\":\"0.26\",\"size\":\"92.8\"},{\"price\":\"0.27\",\"size\":\"118.11\"},{\"price\":\"0.28\",\"size\":\"67.4\"},{\"price\":\"0.29\",\"size\":\"87.3\"},{\"price\":\"0.3\",\"size\":\"97.2\"},{\"price\":\"0.31\",\"size\":\"71\"},{\"price\":\"0.32\",\"size\":\"78.22\"},{\"price\":\"0.33\",\"size\":\"123\"},{\"price\":\"0.34\",\"size\":\"101\"},{\"price\":\"0.35\",\"size\":\"216\"},{\"price\":\"0.36\",\"size\":\"136\"},{\"price\":\"0.37\",\"size\":\"292.04\"},{\"price\":\"0.38\",\"size\":\"256\"},{\"price\":\"0.39\",\"size\":\"431\"},{\"price\":\"0.4\",\"size\":\"372\"},{\"price\":\"0.41\",\"size\":\"116\"},{\"price\":\"0.42\",\"size\":\"137.76\"},{\"price\":\"0.43\",\"size\":\"176\"},{\"price\":\"0.44\",\"size\":\"85.83\"},{\"price\":\"0.45\",\"size\":\"610.96\"}],\"asks\":[{\"price\":\"0.99\",\"size\":\"54992.6\"},{\"price\":\"0.98\",\"size\":\"22471.85\"},{\"price\":\"0.97\",\"size\":\"2148.4\"},{\"price\":\"0.96\",\"size\":\"1677.1\"},{\"price\":\"0.95\",\"size\":\"1864.11\"},{\"price\":\"0.94\",\"size\":\"1008.6\"},{\"price\":\"0.93\",\"size\":\"992.18\"},{\"price\":\"0.92\",\"size\":\"829.12\"},{\"price\":\"0.91\",\"size\":\"781.72\"},{\"price\":\"0.9\",\"size\":\"1282.15\"},{\"price\":\"0.89\",\"size\":\"564.4\"},{\"price\":\"0.88\",\"size\":\"303.64\"},{\"price\":\"0.87\",\"size\":\"253.2\"},{\"price\":\"0.86\",\"size\":\"61.95\"},{\"price\":\"0.85\",\"size\":\"43.86\"},{\"price\":\"0.84\",\"size\":\"58.94\"},{\"price\":\"0.83\",\"size\":\"26.08\"},{\"price\":\"0.82\",\"size\":\"45.36\"},{\"price\":\"0.81\",\"size\":\"24.67\"},{\"price\":\"0.8\",\"size\":\"83.51\"},{\"price\":\"0.79\",\"size\":\"172.8\"},{\"price\":\"0.78\",\"size\":\"77.6\"},{\"price\":\"0.77\",\"size\":\"47.3\"},{\"price\":\"0.76\",\"size\":\"47.1\"},{\"price\":\"0.75\",\"size\":\"469.9\"},{\"price\":\"0.74\",\"size\":\"46.8\"},{\"price\":\"0.73\",\"size\":\"46.6\"},{\"price\":\"0.72\",\"size\":\"51.4\"},{\"price\":\"0.71\",\"size\":\"81.3\"},{\"price\":\"0.7\",\"size\":\"74.2\"},{\"price\":\"0.69\",\"size\":\"103.6\"},{\"price\":\"0.68\",\"size\":\"82\"},{\"price\":\"0.67\",\"size\":\"61.9\"},{\"price\":\"0.66\",\"size\":\"91.8\"},{\"price\":\"0.65\",\"size\":\"113.97\"},{\"price\":\"0.64\",\"size\":\"371.6\"},{\"price\":\"0.63\",\"size\":\"91.6\"},{\"price\":\"0.62\",\"size\":\"71.5\"},{\"price\":\"0.61\",\"size\":\"729.22\"},{\"price\":\"0.6\",\"size\":\"111.4\"},{\"price\":\"0.59\",\"size\":\"562.54\"},{\"price\":\"0.58\",\"size\":\"250.24\"},{\"price\":\"0.57\",\"size\":\"147.88\"},{\"price\":\"0.56\",\"size\":\"128.53\"},{\"price\":\"0.55\",\"size\":\"128.77\"},{\"price\":\"0.54\",\"size\":\"337.36\"},{\"price\":\"0.53\",\"size\":\"197.19\"},{\"price\":\"0.52\",\"size\":\"1027.68\"},{\"price\":\"0.51\",\"size\":\"354.91\"},{\"price\":\"0.5\",\"size\":\"321.5\"},{\"price\":\"0.49\",\"size\":\"133.59\"},{\"price\":\"0.48\",\"size\":\"146.37\"},{\"price\":\"0.47\",\"size\":\"77\"},{\"price\":\"0.46\",\"size\":\"458.52\"}],\"tick_size\":\"0.01\",\"event_type\":\"book\",\"last_trade_price\":\"0.540\"},{\"market\":\"0x9c535590faae21bf76fed844aa47fc3c5c82253ef38bd545bf12c93470502685\",\"asset_id\":\"107011546575057755426871645700605806081353395825571114128343592072429146374928\",\"timestamp\":\"1781254836831\",\"hash\":\"547ddcc1bc634025afe3d24fb017b9155ea095c6\",\"bids\":[{\"price\":\"0.01\",\"size\":\"54992.6\"},{\"price\":\"0.02\",\"size\":\"22471.85\"},{\"price\":\"0.03\",\"size\":\"2148.4\"},{\"price\":\"0.04\",\"size\":\"1677.1\"},{\"price\":\"0.05\",\"size\":\"1864.11\"},{\"price\":\"0.06\",\"size\":\"1008.6\"},{\"price\":\"0.07\",\"size\":\"992.18\"},{\"price\":\"0.08\",\"size\":\"829.12\"},{\"price\":\"0.09\",\"size\":\"781.72\"},{\"price\":\"0.1\",\"size\":\"1282.15\"},{\"price\":\"0.11\",\"size\":\"564.4\"},{\"price\":\"0.12\",\"size\":\"303.64\"},{\"price\":\"0.13\",\"size\":\"253.2\"},{\"price\":\"0.14\",\"size\":\"61.95\"},{\"price\":\"0.15\",\"size\":\"43.86\"},{\"price\":\"0.16\",\"size\":\"58.94\"},{\"price\":\"0.17\",\"size\":\"26.08\"},{\"price\":\"0.18\",\"size\":\"45.36\"},{\"price\":\"0.19\",\"size\":\"24.67\"},{\"price\":\"0.2\",\"size\":\"83.51\"},{\"price\":\"0.21\",\"size\":\"172.8\"},{\"price\":\"0.22\",\"size\":\"77.6\"},{\"price\":\"0.23\",\"size\":\"47.3\"},{\"price\":\"0.24\",\"size\":\"47.1\"},{\"price\":\"0.25\",\"size\":\"469.9\"},{\"price\":\"0.26\",\"size\":\"46.8\"},{\"price\":\"0.27\",\"size\":\"46.6\"},{\"price\":\"0.28\",\"size\":\"51.4\"},{\"price\":\"0.29\",\"size\":\"81.3\"},{\"price\":\"0.3\",\"size\":\"74.2\"},{\"price\":\"0.31\",\"size\":\"103.6\"},{\"price\":\"0.32\",\"size\":\"82\"},{\"price\":\"0.33\",\"size\":\"61.9\"},{\"price\":\"0.34\",\"size\":\"91.8\"},{\"price\":\"0.35\",\"size\":\"113.97\"},{\"price\":\"0.36\",\"size\":\"371.6\"},{\"price\":\"0.37\",\"size\":\"91.6\"},{\"price\":\"0.38\",\"size\":\"71.5\"},{\"price\":\"0.39\",\"size\":\"729.22\"},{\"price\":\"0.4\",\"size\":\"111.4\"},{\"price\":\"0.41\",\"size\":\"556\"},{\"price\":\"0.42\",\"size\":\"250.24\"},{\"price\":\"0.43\",\"size\":\"147.88\"},{\"price\":\"0.44\",\"size\":\"128.53\"},{\"price\":\"0.45\",\"size\":\"128.77\"},{\"price\":\"0.46\",\"size\":\"337.36\"},{\"price\":\"0.47\",\"size\":\"197.19\"},{\"price\":\"0.48\",\"size\":\"1027.68\"},{\"price\":\"0.49\",\"size\":\"354.91\"},{\"price\":\"0.5\",\"size\":\"321.5\"},{\"price\":\"0.51\",\"size\":\"133.59\"},{\"price\":\"0.52\",\"size\":\"146.37\"},{\"price\":\"0.53\",\"size\":\"77\"},{\"price\":\"0.54\",\"size\":\"458.52\"}],\"asks\":[{\"price\":\"0.99\",\"size\":\"57284.15\"},{\"price\":\"0.98\",\"size\":\"22462.28\"},{\"price\":\"0.97\",\"size\":\"2161.73\"},{\"price\":\"0.96\",\"size\":\"1743.28\"},{\"price\":\"0.95\",\"size\":\"1914.1\"},{\"price\":\"0.94\",\"size\":\"991.6\"},{\"price\":\"0.93\",\"size\":\"1035.18\"},{\"price\":\"0.92\",\"size\":\"832.11\"},{\"price\":\"0.91\",\"size\":\"679.28\"},{\"price\":\"0.9\",\"size\":\"314.76\"},{\"price\":\"0.89\",\"size\":\"597\"},{\"price\":\"0.88\",\"size\":\"335.24\"},{\"price\":\"0.87\",\"size\":\"84.2\"},{\"price\":\"0.86\",\"size\":\"69.95\"},{\"price\":\"0.85\",\"size\":\"52.86\"},{\"price\":\"0.84\",\"size\":\"66.94\"},{\"price\":\"0.83\",\"size\":\"54.08\"},{\"price\":\"0.82\",\"size\":\"370.6\"},{\"price\":\"0.81\",\"size\":\"39.67\"},{\"price\":\"0.8\",\"size\":\"729.5\"},{\"price\":\"0.79\",\"size\":\"177.95\"},{\"price\":\"0.78\",\"size\":\"513.6\"},{\"price\":\"0.77\",\"size\":\"39.3\"},{\"price\":\"0.76\",\"size\":\"58.1\"},{\"price\":\"0.75\",\"size\":\"27.9\"},{\"price\":\"0.74\",\"size\":\"92.8\"},{\"price\":\"0.73\",\"size\":\"118.11\"},{\"price\":\"0.72\",\"size\":\"67.4\"},{\"price\":\"0.71\",\"size\":\"87.3\"},{\"price\":\"0.7\",\"size\":\"97.2\"},{\"price\":\"0.69\",\"size\":\"71\"},{\"price\":\"0.68\",\"size\":\"78.22\"},{\"price\":\"0.67\",\"size\":\"123\"},{\"price\":\"0.66\",\"size\":\"101\"},{\"price\":\"0.65\",\"size\":\"216\"},{\"price\":\"0.64\",\"size\":\"136\"},{\"price\":\"0.63\",\"size\":\"292.04\"},{\"price\":\"0.62\",\"size\":\"256\"},{\"price\":\"0.61\",\"size\":\"431\"},{\"price\":\"0.6\",\"size\":\"372\"},{\"price\":\"0.59\",\"size\":\"116\"},{\"price\":\"0.58\",\"size\":\"137.76\"},{\"price\":\"0.57\",\"size\":\"176\"},{\"price\":\"0.56\",\"size\":\"85.83\"},{\"price\":\"0.55\",\"size\":\"610.96\"}],\"tick_size\":\"0.01\",\"event_type\":\"book\",\"last_trade_price\":\"0.540\"}]\n","ts_local_ms":1781254837140}
{"dir":"in","text":"{\"market\":\"0x9c535590faae21bf76fed844aa47fc3c5c82253ef38bd545bf12c93470502685\", \"price_changes\":[{\"asset_id\":\"107011546575057755426871645700605806081353395825571114128343592072429146374928\", \"price\":\"0.52\", \"size\":\"146.37\", \"side\":\"BUY\", \"hash\":\"3e1f72bac0fa2426ae2f8da21bd5c4c736baf106\", \"best_bid\":\"0.54\", \"best_ask\":\"0.55\"}, {\"asset_id\":\"56108879726720646120583724001239294777304794469144970684362785767667828318889\", \"price\":\"0.48\", \"size\":\"146.37\", \"side\":\"SELL\", \"hash\":\"1f955a2293362c01a4d568bfb850c8ff88b59d90\", \"best_bid\":\"0.45\", \"best_ask\":\"0.46\"}], \"timestamp\":\"1781254836830\", \"event_type\":\"price_change\"}","ts_local_ms":1781254837141}
{"dir":"in","text":"{\"market\":\"0x9c535590faae21bf76fed844aa47fc3c5c82253ef38bd545bf12c93470502685\", \"price_changes\":[{\"asset_id\":\"56108879726720646120583724001239294777304794469144970684362785767667828318889\", \"price\":\"0.45\", \"size\":\"610.96\", \"side\":\"BUY\", \"hash\":\"63e9fd1b6c9292740efdc141c2c63dc80d846975\", \"best_bid\":\"0.45\", \"best_ask\":\"0.46\"}, {\"asset_id\":\"107011546575057755426871645700605806081353395825571114128343592072429146374928\", \"price\":\"0.55\", \"size\":\"610.96\", \"side\":\"SELL\", \"hash\":\"b63da18bd06d96456cd1c8f24744afd1eda9ee28\", \"best_bid\":\"0.54\", \"best_ask\":\"0.55\"}], \"timestamp\":\"1781254836831\", \"event_type\":\"price_change\"}","ts_local_ms":1781254837141}
{"dir":"in","text":"{\"market\":\"0x9c535590faae21bf76fed844aa47fc3c5c82253ef38bd545bf12c93470502685\", \"price_changes\":[{\"asset_id\":\"56108879726720646120583724001239294777304794469144970684362785767667828318889\", \"price\":\"0.41\", \"size\":\"116\", \"side\":\"BUY\", \"hash\":\"615265ea429ec9d858150041acbf4c6495038254\", \"best_bid\":\"0.45\", \"best_ask\":\"0.46\"}, {\"asset_id\":\"107011546575057755426871645700605806081353395825571114128343592072429146374928\", \"price\":\"0.59\", \"size\":\"116\", \"side\":\"SELL\", \"hash\":\"547ddcc1bc634025afe3d24fb017b9155ea095c6\", \"best_bid\":\"0.54\", \"best_ask\":\"0.55\"}], \"timestamp\":\"1781254836831\", \"event_type\":\"price_change\"}","ts_local_ms":1781254837141}
{"dir":"in","text":"{\"market\":\"0x9c535590faae21bf76fed844aa47fc3c5c82253ef38bd545bf12c93470502685\", \"price_changes\":[{\"asset_id\":\"107011546575057755426871645700605806081353395825571114128343592072429146374928\", \"price\":\"0.41\", \"size\":\"562.54\", \"side\":\"BUY\", \"hash\":\"8de8248d05d80416f96dbc453447eb3f56476c0c\", \"best_bid\":\"0.54\", \"best_ask\":\"0.55\"}, {\"asset_id\":\"56108879726720646120583724001239294777304794469144970684362785767667828318889\", \"price\":\"0.59\", \"size\":\"562.54\", \"side\":\"SELL\", \"hash\":\"52a622e4dd8859ef5d92b98c111f9af614e4a4c2\", \"best_bid\":\"0.45\", \"best_ask\":\"0.46\"}], \"timestamp\":\"1781254836832\", \"event_type\":\"price_change\"}","ts_local_ms":1781254837141}
{"dir":"in","text":"{\"market\":\"0x9c535590faae21bf76fed844aa47fc3c5c82253ef38bd545bf12c93470502685\", \"price_changes\":[{\"asset_id\":\"56108879726720646120583724001239294777304794469144970684362785767667828318889\", \"price\":\"0.45\", \"size\":\"616.96\", \"side\":\"BUY\", \"hash\":\"81a02a4d2742f6eee293faed4bd4b5d737e4b7d4\", \"best_bid\":\"0.45\", \"best_ask\":\"0.46\"}, {\"asset_id\":\"107011546575057755426871645700605806081353395825571114128343592072429146374928\", \"price\":\"0.55\", \"size\":\"616.96\", \"side\":\"SELL\", \"hash\":\"9433647f9575c44abf286fc11ca452e020495592\", \"best_bid\":\"0.54\", \"best_ask\":\"0.55\"}], \"timestamp\":\"1781254836832\", \"event_type\":\"price_change\"}","ts_local_ms":1781254837142}
{"dir":"in","text":"{\"market\":\"0x9c535590faae21bf76fed844aa47fc3c5c82253ef38bd545bf12c93470502685\", \"price_changes\":[{\"asset_id\":\"56108879726720646120583724001239294777304794469144970684362785767667828318889\", \"price\":\"0.05\", \"size\":\"1962.1\", \"side\":\"BUY\", \"hash\":\"5446ae203f476e76112e5ed7e8bebdc6afe0d439\", \"best_bid\":\"0.45\", \"best_ask\":\"0.46\"}, {\"asset_id\":\"107011546575057755426871645700605806081353395825571114128343592072429146374928\", \"price\":\"0.95\", \"size\":\"1962.1\", \"side\":\"SELL\", \"hash\":\"df5d1ad1e2a69dfec052898ff53aacb49167868e\", \"best_bid\":\"0.54\", \"best_ask\":\"0.55\"}], \"timestamp\":\"1781254836833\", \"event_type\":\"price_change\"}","ts_local_ms":1781254837142}
{"dir":"in","text":"{\"market\":\"0x9c535590faae21bf76fed844aa47fc3c5c82253ef38bd545bf12c93470502685\", \"price_changes\":[{\"asset_id\":\"56108879726720646120583724001239294777304794469144970684362785767667828318889\", \"price\":\"0.45\", \"size\":\"621.98\", \"side\":\"BUY\", \"hash\":\"fdca87e90d59de6d5b7574ffd47c54a616b1e26a\", \"best_bid\":\"0.45\", \"best_ask\":\"0.46\"}, {\"asset_id\":\"107011546575057755426871645700605806081353395825571114128343592072429146374928\", \"price\":\"0.55\", \"size\":\"621.98\", \"side\":\"SELL\", \"hash\":\"67ffc898c3ef18e2cb0b53432101a22d878fdb2d\", \"best_bid\":\"0.54\", \"best_ask\":\"0.55\"}], \"timestamp\":\"1781254836833\", \"event_type\":\"price_change\"}","ts_local_ms":1781254837143}
{"dir":"in","text":"{\"market\":\"0x9c535590faae21bf76fed844aa47fc3c5c82253ef38bd545bf12c93470502685\", \"price_changes\":[{\"asset_id\":\"107011546575057755426871645700605806081353395825571114128343592072429146374928\", \"price\":\"0.01\", \"size\":\"54997.6\", \"side\":\"BUY\", \"hash\":\"d6fbd4853ee24b3695a3eb2097336b1a89f0a875\", \"best_bid\":\"0.54\", \"best_ask\":\"0.55\"}, {\"asset_id\":\"56108879726720646120583724001239294777304794469144970684362785767667828318889\", \"price\":\"0.99\", \"size\":\"54997.6\", \"side\":\"SELL\", \"hash\":\"365226afa4215510bc1bdd2d711f8edb53bac60a\", \"best_bid\":\"0.45\", \"best_ask\":\"0.46\"}], \"timestamp\":\"1781254836834\", \"event_type\":\"price_change\"}","ts_local_ms":1781254837143}
{"dir":"in","text":"{\"market\":\"0x9c535590faae21bf76fed844aa47fc3c5c82253ef38bd545bf12c93470502685\", \"price_changes\":[{\"asset_id\":\"56108879726720646120583724001239294777304794469144970684362785767667828318889\", \"price\":\"0.45\", \"size\":\"615.98\", \"side\":\"BUY\", \"hash\":\"13a360de4b0a0f8170ed3caa8990746d90c42432\", \"best_bid\":\"0.45\", \"best_ask\":\"0.46\"}, {\"asset_id\":\"107011546575057755426871645700605806081353395825571114128343592072429146374928\", \"price\":\"0.55\", \"size\":\"615.98\", \"side\":\"SELL\", \"hash\":\"569a71eb89a09310838e085819bc7e8f83fa60db\", \"best_bid\":\"0.54\", \"best_ask\":\"0.55\"}], \"timestamp\":\"1781254836834\", \"event_type\":\"price_change\"}","ts_local_ms":1781254837309}
{"dir":"in","text":"{\"market\":\"0x9c535590faae21bf76fed844aa47fc3c5c82253ef38bd545bf12c93470502685\", \"price_changes\":[{\"asset_id\":\"56108879726720646120583724001239294777304794469144970684362785767667828318889\", \"price\":\"0.3\", \"size\":\"87.2\", \"side\":\"BUY\", \"hash\":\"d75c3f39be2ce88dfc73b291bde8b2842407fe7a\", \"best_bid\":\"0.45\", \"best_ask\":\"0.46\"}, {\"asset_id\":\"107011546575057755426871645700605806081353395825571114128343592072429146374928\", \"price\":\"0.7\", \"size\":\"87.2\", \"side\":\"SELL\", \"hash\":\"4d6a3acb805c872034b73ede9b46fccd4f885a29\", \"best_bid\":\"0.54\", \"best_ask\":\"0.55\"}], \"timestamp\":\"1781254836834\", \"event_type\":\"price_change\"}","ts_local_ms":1781254837309}
{"dir":"in","text":"{\"market\":\"0x9c535590faae21bf76fed844aa47fc3c5c82253ef38bd545bf12c93470502685\", \"price_changes\":[{\"asset_id\":\"56108879726720646120583724001239294777304794469144970684362785767667828318889\", \"price\":\"0.04\", \"size\":\"1695.28\", \"side\":\"BUY\", \"hash\":\"641275d14a8a684ae18ac0ab00f998abe7ecdb85\", \"best_bid\":\"0.45\", \"best_ask\":\"0.46\"}, {\"asset_id\":\"107011546575057755426871645700605806081353395825571114128343592072429146374928\", \"price\":\"0.96\", \"size\":\"1695.28\", \"side\":\"SELL\", \"hash\":\"9c01e38849b5ca2d518b4b3b7ad91a5f43240775\", \"best_bid\":\"0.54\", \"best_ask\":\"0.55\"}], \"timestamp\":\"1781254836835\", \"event_type\":\"price_change\"}","ts_local_ms":1781254837309}
{"dir":"in","text":"{\"market\":\"0x9c535590faae21bf76fed844aa47fc3c5c82253ef38bd545bf12c93470502685\", \"price_changes\":[{\"asset_id\":\"107011546575057755426871645700605806081353395825571114128343592072429146374928\", \"price\":\"0.1\", \"size\":\"1234.15\", \"side\":\"BUY\", \"hash\":\"fe1ce3b8a68e475eb9898c11a85a5242309ec8cb\", \"best_bid\":\"0.54\", \"best_ask\":\"0.55\"}, {\"asset_id\":\"56108879726720646120583724001239294777304794469144970684362785767667828318889\", \"price\":\"0.9\", \"size\":\"1234.15\", \"side\":\"SELL\", \"hash\":\"8dc1b0a16449137f9d1896314f8997b72b22eb61\", \"best_bid\":\"0.45\", \"best_ask\":\"0.46\"}], \"timestamp\":\"1781254836835\", \"event_type\":\"price_change\"}","ts_local_ms":1781254837309}
{"dir":"in","text":"{\"market\":\"0x9c535590faae21bf76fed844aa47fc3c5c82253ef38bd545bf12c93470502685\", \"price_changes\":[{\"asset_id\":\"56108879726720646120583724001239294777304794469144970684362785767667828318889\", \"price\":\"0.45\", \"size\":\"607.98\", \"side\":\"BUY\", \"hash\":\"d040ead2c1b03d5fdf1670a44fa5359f5e018884\", \"best_bid\":\"0.45\", \"best_ask\":\"0.46\"}, {\"asset_id\":\"107011546575057755426871645700605806081353395825571114128343592072429146374928\", \"price\":\"0.55\", \"size\":\"607.98\", \"side\":\"SELL\", \"hash\":\"bb675b6fc17b545c0cf5a8b097df9d1c3928bccf\", \"best_bid\":\"0.54\", \"best_ask\":\"0.55\"}], \"timestamp\":\"1781254836836\", \"event_type\":\"price_change\"}","ts_local_ms":1781254837309}
{"dir":"in","text":"{\"market\":\"0x9c535590faae21bf76fed844aa47fc3c5c82253ef38bd545bf12c93470502685\", \"price_changes\":[{\"asset_id\":\"107011546575057755426871645700605806081353395825571114128343592072429146374928\", \"price\":\"0.39\", \"size\":\"704.22\", \"side\":\"BUY\", \"hash\":\"136960694733d1297ecc628edf0c586bd9d6e9f5\", \"best_bid\":\"0.54\", \"best_ask\":\"0.55\"}, {\"asset_id\":\"56108879726720646120583724001239294777304794469144970684362785767667828318889\", \"price\":\"0.61\", \"size\":\"704.22\", \"side\":\"SELL\", \"hash\":\"511bcd533be60f025b88152c5ad39a7531654640\", \"best_bid\":\"0.45\", \"best_ask\":\"0.46\"}], \"timestamp\":\"1781254836836\", \"event_type\":\"price_change\"}","ts_local_ms":1781254837309}
{"dir":"in","text":"{\"market\":\"0x9c535590faae21bf76fed844aa47fc3c5c82253ef38bd545bf12c93470502685\", \"price_changes\":[{\"asset_id\":\"107011546575057755426871645700605806081353395825571114128343592072429146374928\", \"price\":\"0.54\", \"size\":\"508.52\", \"side\":\"BUY\", \"hash\":\"c08c23ce5f47f0057620a337730f7b701af21c39\", \"best_bid\":\"0.54\", \"best_ask\":\"0.55\"}, {\"asset_id\":\"56108879726720646120583724001239294777304794469144970684362785767667828318889\", \"price\":\"0.46\", \"size\":\"508.52\", \"side\":\"SELL\", \"hash\":\"2efb5b90afa5c436c3e061d70c50aa406cc1eaf4\", \"best_bid\":\"0.45\", \"best_ask\":\"0.46\"}], \"timestamp\":\"1781254836836\", \"event_type\":\"price_change\"}","ts_local_ms":1781254837309}
{"dir":"in","text":"{\"market\":\"0x9c535590faae21bf76fed844aa47fc3c5c82253ef38bd545bf12c93470502685\", \"price_changes\":[{\"asset_id\":\"56108879726720646120583724001239294777304794469144970684362785767667828318889\", \"price\":\"0.44\", \"size\":\"90.83\", \"side\":\"BUY\", \"hash\":\"8624861c15e26b5ce837ea7c17b0faea263f9d1f\", \"best_bid\":\"0.45\", \"best_ask\":\"0.46\"}, {\"asset_id\":\"107011546575057755426871645700605806081353395825571114128343592072429146374928\", \"price\":\"0.56\", \"size\":\"90.83\", \"side\":\"SELL\", \"hash\":\"84c27d68486ba03ddd498beda571aa83bd108472\", \"best_bid\":\"0.54\", \"best_ask\":\"0.55\"}], \"timestamp\":\"1781254836837\", \"event_type\":\"price_change\"}","ts_local_ms":1781254837309}
{"dir":"in","text":"{\"market\":\"0x9c535590faae21bf76fed844aa47fc3c5c82253ef38bd545bf12c93470502685\", \"price_changes\":[{\"asset_id\":\"107011546575057755426871645700605806081353395825571114128343592072429146374928\", \"price\":\"0.49\", \"size\":\"369.91\", \"side\":\"BUY\", \"hash\":\"5436adc4a8da4a0073db2d02fa2ba3a8e1ffb354\", \"best_bid\":\"0.54\", \"best_ask\":\"0.55\"}, {\"asset_id\":\"56108879726720646120583724001239294777304794469144970684362785767667828318889\", \"price\":\"0.51\", \"size\":\"369.91\", \"side\":\"SELL\", \"hash\":\"ca7507af742133a1672434c1abb24a5df73530c5\", \"best_bid\":\"0.45\", \"best_ask\":\"0.46\"}], \"timestamp\":\"1781254836837\", \"event_type\":\"price_change\"}","ts_local_ms":1781254837309}
{"dir":"in","text":"{\"market\":\"0x9c535590faae21bf76fed844aa47fc3c5c82253ef38bd545bf12c93470502685\", \"price_changes\":[{\"asset_id\":\"56108879726720646120583724001239294777304794469144970684362785767667828318889\", \"price\":\"0.42\", \"size\":\"145.76\", \"side\":\"BUY\", \"hash\":\"7c00c9a905a7c767d8a8a66a27d1abf043b4e3d3\", \"best_bid\":\"0.45\", \"best_ask\":\"0.46\"}, {\"asset_id\":\"107011546575057755426871645700605806081353395825571114128343592072429146374928\", \"price\":\"0.58\", \"size\":\"145.76\", \"side\":\"SELL\", \"hash\":\"f78579f74d5b61ea4c6cfd2f44d8594f155b5fc9\", \"best_bid\":\"0.54\", \"best_ask\":\"0.55\"}], \"timestamp\":\"1781254836838\", \"event_type\":\"price_change\"}","ts_local_ms":1781254837309}
{"dir":"in","text":"{\"market\":\"0x9c535590faae21bf76fed844aa47fc3c5c82253ef38bd545bf12c93470502685\", \"price_changes\":[{\"asset_id\":\"107011546575057755426871645700605806081353395825571114128343592072429146374928\", \"price\":\"0.41\", \"size\":\"556\", \"side\":\"BUY\", \"hash\":\"64ad9533527f44734fe5f443305af4bf32299ea6\", \"best_bid\":\"0.54\", \"best_ask\":\"0.55\"}, {\"asset_id\":\"56108879726720646120583724001239294777304794469144970684362785767667828318889\", \"price\":\"0.59\", \"size\":\"556\", \"side\":\"SELL\", \"hash\":\"990f9c3c2abbfc91850315848dc0511ce2b08d2c\", \"best_bid\":\"0.45\", \"best_ask\":\"0.46\"}], \"timestamp\":\"1781254836839\", \"event_type\":\"price_change\"}","ts_local_ms":1781254837309}
{"dir":"in","text":"{\"market\":\"0x9c535590faae21bf76fed844aa47fc3c5c82253ef38bd545bf12c93470502685\", \"price_changes\":[{\"asset_id\":\"107011546575057755426871645700605806081353395825571114128343592072429146374928\", \"price\":\"0.5\", \"size\":\"384.15\", \"side\":\"BUY\", \"hash\":\"ce02e34ffb6bed56adc33f547beea5878cb8d946\", \"best_bid\":\"0.54\", \"best_ask\":\"0.55\"}, {\"asset_id\":\"56108879726720646120583724001239294777304794469144970684362785767667828318889\", \"price\":\"0.5\", \"size\":\"384.15\", \"side\":\"SELL\", \"hash\":\"0ca767028842e73c1fad5e609444b5c4400dc463\", \"best_bid\":\"0.45\", \"best_ask\":\"0.46\"}], \"timestamp\":\"1781254836839\", \"event_type\":\"price_change\"}","ts_local_ms":1781254837309}
{"dir":"in","text":"{\"market\":\"0x9c535590faae21bf76fed844aa47fc3c5c82253ef38bd545bf12c93470502685\", \"price_changes\":[{\"asset_id\":\"56108879726720646120583724001239294777304794469144970684362785767667828318889\", \"price\":\"0.45\", \"size\":\"601.98\", \"side\":\"BUY\", \"hash\":\"ce4eaa383f00347465866b5d9120e59f90c7ac6c\", \"best_bid\":\"0.45\", \"best_ask\":\"0.46\"}, {\"asset_id\":\"107011546575057755426871645700605806081353395825571114128343592072429146374928\", \"price\":\"0.55\", \"size\":\"601.98\", \"side\":\"SELL\", \"hash\":\"34ce6f9f56b65c851937dd31f479172dcb9f3db3\", \"best_bid\":\"0.54\", \"best_ask\":\"0.55\"}], \"timestamp\":\"1781254836840\", \"event_type\":\"price_change\"}","ts_local_ms":1781254837309}
{"dir":"in","text":"{\"market\":\"0x9c535590faae21bf76fed844aa47fc3c5c82253ef38bd545bf12c93470502685\", \"price_changes\":[{\"asset_id\":\"56108879726720646120583724001239294777304794469144970684362785767667828318889\", \"price\":\"0.26\", \"size\":\"62.8\", \"side\":\"BUY\", \"hash\":\"4fbc2b872b631a9e7d668ce26771cd38e90819be\", \"best_bid\":\"0.45\", \"best_ask\":\"0.46\"}, {\"asset_id\":\"107011546575057755426871645700605806081353395825571114128343592072429146374928\", \"price\":\"0.74\", \"size\":\"62.8\", \"side\":\"SELL\", \"hash\":\"756bfdffc4b6591b8d272aff2b2d973a09aee575\", \"best_bid\":\"0.54\", \"best_ask\":\"0.55\"}], \"timestamp\":\"1781254836840\", \"event_type\":\"price_change\"}","ts_local_ms":1781254837309}
{"dir":"in","text":"{\"market\":\"0x9c535590faae21bf76fed844aa47fc3c5c82253ef38bd545bf12c93470502685\", \"price_changes\":[{\"asset_id\":\"107011546575057755426871645700605806081353395825571114128343592072429146374928\", \"price\":\"0.54\", \"size\":\"513.52\", \"side\":\"BUY\", \"hash\":\"26993896a8ae46aae7b64d6c566b9ec58232ecd7\", \"best_bid\":\"0.54\", \"best_ask\":\"0.55\"}, {\"asset_id\":\"56108879726720646120583724001239294777304794469144970684362785767667828318889\", \"price\":\"0.46\", \"size\":\"513.52\", \"side\":\"SELL\", \"hash\":\"36b875cee7abb03ff46f1cbc0c50f64bc8de77be\", \"best_bid\":\"0.45\", \"best_ask\":\"0.46\"}], \"timestamp\":\"1781254836840\", \"event_type\":\"price_change\"}","ts_local_ms":1781254837309}
{"dir":"in","text":"{\"market\":\"0x9c535590faae21bf76fed844aa47fc3c5c82253ef38bd545bf12c93470502685\", \"price_changes\":[{\"asset_id\":\"107011546575057755426871645700605806081353395825571114128343592072429146374928\", \"price\":\"0.54\", \"size\":\"508.52\", \"side\":\"BUY\", \"hash\":\"5cc86fac152ecdcb968364e43027a255f31e4f23\", \"best_bid\":\"0.54\", \"best_ask\":\"0.55\"}, {\"asset_id\":\"56108879726720646120583724001239294777304794469144970684362785767667828318889\", \"price\":\"0.46\", \"size\":\"508.52\", \"side\":\"SELL\", \"hash\":\"c6f298f602ae0830f77fbebaef31809a2355e575\", \"best_bid\":\"0.45\", \"best_ask\":\"0.46\"}], \"timestamp\":\"1781254836841\", \"event_type\":\"price_change\"}","ts_local_ms":1781254837309}
{"dir":"in","text":"{\"market\":\"0x9c535590faae21bf76fed844aa47fc3c5c82253ef38bd545bf12c93470502685\", \"price_changes\":[{\"asset_id\":\"107011546575057755426871645700605806081353395825571114128343592072429146374928\", \"price\":\"0.51\", \"size\":\"103.59\", \"side\":\"BUY\", \"hash\":\"5b78ae4a0947972f743e13eef5d920b1b88832e7\", \"best_bid\":\"0.54\", \"best_ask\":\"0.55\"}, {\"asset_id\":\"56108879726720646120583724001239294777304794469144970684362785767667828318889\", \"price\":\"0.49\", \"size\":\"103.59\", \"side\":\"SELL\", \"hash\":\"f51b47bebdeca66a09499cbb0870f6a6522161f3\", \"best_bid\":\"0.45\", \"best_ask\":\"0.46\"}], \"timestamp\":\"1781254836841\", \"event_type\":\"price_change\"}","ts_local_ms":1781254837309}
{"dir":"in","text":"{\"market\":\"0x9c535590faae21bf76fed844aa47fc3c5c82253ef38bd545bf12c93470502685\", \"price_changes\":[{\"asset_id\":\"107011546575057755426871645700605806081353395825571114128343592072429146374928\", \"price\":\"0.5\", \"size\":\"354.15\", \"side\":\"BUY\", \"hash\":\"c2a65b35e525cf2a2bc409b407c699c66e38574b\", \"best_bid\":\"0.54\", \"best_ask\":\"0.55\"}, {\"asset_id\":\"56108879726720646120583724001239294777304794469144970684362785767667828318889\", \"price\":\"0.5\", \"size\":\"354.15\", \"side\":\"SELL\", \"hash\":\"b0a05fa990c3cab078dd7131204a4671ddcc26af\", \"best_bid\":\"0.45\", \"best_ask\":\"0.46\"}], \"timestamp\":\"1781254836841\", \"event_type\":\"price_change\"}","ts_local_ms":1781254837309}
{"dir":"in","text":"{\"market\":\"0x9c535590faae21bf76fed844aa47fc3c5c82253ef38bd545bf12c93470502685\", \"price_changes\":[{\"asset_id\":\"56108879726720646120583724001239294777304794469144970684362785767667828318889\", \"price\":\"0.45\", \"size\":\"594.98\", \"side\":\"BUY\", \"hash\":\"2b43b6318a6075e621ede151f9aed903a1f5391e\", \"best_bid\":\"0.45\", \"best_ask\":\"0.46\"}, {\"asset_id\":\"107011546575057755426871645700605806081353395825571114128343592072429146374928\", \"price\":\"0.55\", \"size\":\"594.98\", \"side\":\"SELL\", \"hash\":\"dc7cecb5addb6b03195f0736d085545e71279c56\", \"best_bid\":\"0.54\", \"best_ask\":\"0.55\"}], \"timestamp\":\"1781254836842\", \"event_type\":\"price_change\"}","ts_local_ms":1781254837309}
{"dir":"in","text":"{\"market\":\"0x9c535590faae21bf76fed844aa47fc3c5c82253ef38bd545bf12c93470502685\", \"price_changes\":[{\"asset_id\":\"107011546575057755426871645700605806081353395825571114128343592072429146374928\", \"price\":\"0.29\", \"size\":\"89.3\", \"side\":\"BUY\", \"hash\":\"7ec6cdc93be3ad794e1b9e02f0630f39d5b706ca\", \"best_bid\":\"0.54\", \"best_ask\":\"0.55\"}, {\"asset_id\":\"56108879726720646120583724001239294777304794469144970684362785767667828318889\", \"price\":\"0.71\", \"size\":\"89.3\", \"side\":\"SELL\", \"hash\":\"cfeb8ad3e971345d58f08af9929e18ddeeeb8b10\", \"best_bid\":\"0.45\", \"best_ask\":\"0.46\"}], \"timestamp\":\"1781254836842\", \"event_type\":\"price_change\"}","ts_local_ms":1781254837309}
{"dir":"in","text":"{\"market\":\"0x9c535590faae21bf76fed844aa47fc3c5c82253ef38bd545bf12c93470502685\", \"price_changes\":[{\"asset_id\":\"107011546575057755426871645700605806081353395825571114128343592072429146374928\", \"price\":\"0.5\", \"size\":\"369.15\", \"side\":\"BUY\", \"hash\":\"b43b13042ac1179a6fc697ccdf961d023b3ba6b1\", \"best_bid\":\"0.54\", \"best_ask\":\"0.55\"}, {\"asset_id\":\"56108879726720646120583724001239294777304794469144970684362785767667828318889\", \"price\":\"0.5\", \"size\":\"369.15\", \"side\":\"SELL\", \"hash\":\"9415c9de94951a885fdaf86672bdee87d26a2ce8\", \"best_bid\":\"0.45\", \"best_ask\":\"0.46\"}], \"timestamp\":\"1781254836843\", \"event_type\":\"price_change\"}","ts_local_ms":1781254837309}
{"dir":"in","text":"PONG","ts_local_ms":1781254837310}
{"dir":"in","text":"{\"market\":\"0x9c535590faae21bf76fed844aa47fc3c5c82253ef38bd545bf12c93470502685\", \"price_changes\":[{\"asset_id\":\"56108879726720646120583724001239294777304794469144970684362785767667828318889\", \"price\":\"0.27\", \"size\":\"88.11\", \"side\":\"BUY\", \"hash\":\"56072f8f73ee72727fe0445096c9b316a696b03d\", \"best_bid\":\"0.45\", \"best_ask\":\"0.46\"}, {\"asset_id\":\"107011546575057755426871645700605806081353395825571114128343592072429146374928\", \"price\":\"0.73\", \"size\":\"88.11\", \"side\":\"SELL\", \"hash\":\"e6637ead0624b4f67b56dfb7aa5cbdd09c3fdc06\", \"best_bid\":\"0.54\", \"best_ask\":\"0.55\"}], \"timestamp\":\"1781254836843\", \"event_type\":\"price_change\"}","ts_local_ms":1781254837310}
{"dir":"in","text":"{\"market\":\"0x9c535590faae21bf76fed844aa47fc3c5c82253ef38bd545bf12c93470502685\", \"price_changes\":[{\"asset_id\":\"107011546575057755426871645700605806081353395825571114128343592072429146374928\", \"price\":\"0.5\", \"size\":\"394.15\", \"side\":\"BUY\", \"hash\":\"05602f104bcd61f221147d2d36e14b7a0f04f566\", \"best_bid\":\"0.54\", \"best_ask\":\"0.55\"}, {\"asset_id\":\"56108879726720646120583724001239294777304794469144970684362785767667828318889\", \"price\":\"0.5\", \"size\":\"394.15\", \"side\":\"SELL\", \"hash\":\"6cc414676951e79522d2c413d21b1a51fe4d177b\", \"best_bid\":\"0.45\", \"best_ask\":\"0.46\"}], \"timestamp\":\"1781254836844\", \"event_type\":\"price_change\"}","ts_local_ms":1781254837310}
{"dir":"in","text":"{\"market\":\"0x9c535590faae21bf76fed844aa47fc3c5c82253ef38bd545bf12c93470502685\", \"price_changes\":[{\"asset_id\":\"56108879726720646120583724001239294777304794469144970684362785767667828318889\", \"price\":\"0.45\", \"size\":\"600.8\", \"side\":\"BUY\", \"hash\":\"7116fda970b89f08be80fb37c0a1404664065bef\", \"best_bid\":\"0.45\", \"best_ask\":\"0.46\"}, {\"asset_id\":\"107011546575057755426871645700605806081353395825571114128343592072429146374928\", \"price\":\"0.55\", \"size\":\"600.8\", \"side\":\"SELL\", \"hash\":\"1b5d48806b95781acbb3328eb3089dd33d79bf4e\", \"best_bid\":\"0.54\", \"best_ask\":\"0.55\"}], \"timestamp\":\"1781254836845\", \"event_type\":\"price_change\"}","ts_local_ms":1781254837310}
{"dir":"in","text":"{\"market\":\"0x9c535590faae21bf76fed844aa47fc3c5c82253ef38bd545bf12c93470502685\", \"price_changes\":[{\"asset_id\":\"107011546575057755426871645700605806081353395825571114128343592072429146374928\", \"price\":\"0.53\", \"size\":\"72\", \"side\":\"BUY\", \"hash\":\"35ea6736bdc99e69bad419396ea2c75c6f6cb6c0\", \"best_bid\":\"0.54\", \"best_ask\":\"0.55\"}, {\"asset_id\":\"56108879726720646120583724001239294777304794469144970684362785767667828318889\", \"price\":\"0.47\", \"size\":\"72\", \"side\":\"SELL\", \"hash\":\"e626ce13dfd6c66084cb004d0dbe3eaf7a8bcc44\", \"best_bid\":\"0.45\", \"best_ask\":\"0.46\"}], \"timestamp\":\"1781254836846\", \"event_type\":\"price_change\"}","ts_local_ms":1781254837310}
{"dir":"in","text":"{\"market\":\"0x9c535590faae21bf76fed844aa47fc3c5c82253ef38bd545bf12c93470502685\", \"price_changes\":[{\"asset_id\":\"107011546575057755426871645700605806081353395825571114128343592072429146374928\", \"price\":\"0.52\", \"size\":\"141.37\", \"side\":\"BUY\", \"hash\":\"35ea6736bdc99e69bad419396ea2c75c6f6cb6c0\", \"best_bid\":\"0.54\", \"best_ask\":\"0.55\"}, {\"asset_id\":\"56108879726720646120583724001239294777304794469144970684362785767667828318889\", \"price\":\"0.48\", \"size\":\"141.37\", \"side\":\"SELL\", \"hash\":\"e626ce13dfd6c66084cb004d0dbe3eaf7a8bcc44\", \"best_bid\":\"0.45\", \"best_ask\":\"0.46\"}], \"timestamp\":\"1781254836846\", \"event_type\":\"price_change\"}","ts_local_ms":1781254837310}
{"dir":"in","text":"{\"market\":\"0x9c535590faae21bf76fed844aa47fc3c5c82253ef38bd545bf12c93470502685\", \"price_changes\":[{\"asset_id\":\"56108879726720646120583724001239294777304794469144970684362785767667828318889\", \"price\":\"0.43\", \"size\":\"171\", \"side\":\"BUY\", \"hash\":\"b77fc7023fa2b5f949375f1d3776cb80aabe46de\", \"best_bid\":\"0.45\", \"best_ask\":\"0.46\"}, {\"asset_id\":\"107011546575057755426871645700605806081353395825571114128343592072429146374928\", \"price\":\"0.57\", \"size\":\"171\", \"side\":\"SELL\", \"hash\":\"3d27d23e066d476c5a3149c5c35a75ca5a94f565\", \"best_bid\":\"0.54\", \"best_ask\":\"0.55\"}], \"timestamp\":\"1781254836846\", \"event_type\":\"price_change\"}","ts_local_ms":1781254837310}
{"dir":"in","text":"{\"market\":\"0x9c535590faae21bf76fed844aa47fc3c5c82253ef38bd545bf12c93470502685\", \"price_changes\":[{\"asset_id\":\"56108879726720646120583724001239294777304794469144970684362785767667828318889\", \"price\":\"0.42\", \"size\":\"140.76\", \"side\":\"BUY\", \"hash\":\"b77fc7023fa2b5f949375f1d3776cb80aabe46de\", \"best_bid\":\"0.45\", \"best_ask\":\"0.46\"}, {\"asset_id\":\"107011546575057755426871645700605806081353395825571114128343592072429146374928\", \"price\":\"0.58\", \"size\":\"140.76\", \"side\":\"SELL\", \"hash\":\"3d27d23e066d476c5a3149c5c35a75ca5a94f565\", \"best_bid\":\"0.54\", \"best_ask\":\"0.55\"}], \"timestamp\":\"1781254836846\", \"event_type\":\"price_change\"}","ts_local_ms":1781254837310}
{"dir":"in","text":"{\"market\":\"0x9c535590faae21bf76fed844aa47fc3c5c82253ef38bd545bf12c93470502685\", \"price_changes\":[{\"asset_id\":\"107011546575057755426871645700605806081353395825571114128343592072429146374928\", \"price\":\"0.41\", \"size\":\"531\", \"side\":\"BUY\", \"hash\":\"d16fbc43531687fc3a866465b5af7df9da8caf61\", \"best_bid\":\"0.54\", \"best_ask\":\"0.55\"}, {\"asset_id\":\"56108879726720646120583724001239294777304794469144970684362785767667828318889\", \"price\":\"0.59\", \"size\":\"531\", \"side\":\"SELL\", \"hash\":\"4ab002f224bc9b3bd9f915d2870cacfe8157e45c\", \"best_bid\":\"0.45\", \"best_ask\":\"0.46\"}], \"timestamp\":\"1781254836846\", \"event_type\":\"price_change\"}","ts_local_ms":1781254837310}
{"dir":"in","text":"{\"market\":\"0x9c535590faae21bf76fed844aa47fc3c5c82253ef38bd545bf12c93470502685\", \"price_changes\":[{\"asset_id\":\"56108879726720646120583724001239294777304794469144970684362785767667828318889\", \"price\":\"0.45\", \"size\":\"594.8\", \"side\":\"BUY\", \"hash\":\"a53dd6ea293bef43d7187dbe981e89d7b009ef21\", \"best_bid\":\"0.45\", \"best_ask\":\"0.46\"}, {\"asset_id\":\"107011546575057755426871645700605806081353395825571114128343592072429146374928\", \"price\":\"0.55\", \"size\":\"594.8\", \"side\":\"SELL\", \"hash\":\"9fcabb222a56adae8d1af520402eaff5868af4ae\", \"best_bid\":\"0.54\", \"best_ask\":\"0.55\"}], \"timestamp\":\"1781254836846\", \"event_type\":\"price_change\"}","ts_local_ms":1781254837310}
{"dir":"in","text":"{\"market\":\"0x9c535590faae21bf76fed844aa47fc3c5c82253ef38bd545bf12c93470502685\", \"price_changes\":[{\"asset_id\":\"56108879726720646120583724001239294777304794469144970684362785767667828318889\", \"price\":\"0.45\", \"size\":\"589.78\", \"side\":\"BUY\", \"hash\":\"268a9a94242fc799f3061c0e194c4c1f16b32115\", \"best_bid\":\"0.45\", \"best_ask\":\"0.46\"}, {\"asset_id\":\"107011546575057755426871645700605806081353395825571114128343592072429146374928\", \"price\":\"0.55\", \"size\":\"589.78\", \"side\":\"SELL\", \"hash\":\"085a3fe6abbd5949b91597ba5189b79aa51efe59\", \"best_bid\":\"0.54\", \"best_ask\":\"0.55\"}], \"timestamp\":\"1781254836847\", \"event_type\":\"price_change\"}","ts_local_ms":1781254837310}
{"dir":"in","text":"{\"market\":\"0x9c535590faae21bf76fed844aa47fc3c5c82253ef38bd545bf12c93470502685\", \"price_changes\":[{\"asset_id\":\"56108879726720646120583724001239294777304794469144970684362785767667828318889\", \"price\":\"0.43\", \"size\":\"163\", \"side\":\"BUY\", \"hash\":\"0ea89cbb9e33e10081f96e903c0625a8d48239bb\", \"best_bid\":\"0.45\", \"best_ask\":\"0.46\"}, {\"asset_id\":\"107011546575057755426871645700605806081353395825571114128343592072429146374928\", \"price\":\"0.57\", \"size\":\"163\", \"side\":\"SELL\", \"hash\":\"c03398f9ab7ba88c42d6bf38948eaf25a1572b1d\", \"best_bid\":\"0.54\", \"best_ask\":\"0.55\"}], \"timestamp\":\"1781254836847\", \"event_type\":\"price_change\"}","ts_local_ms":1781254837310}
{"dir":"in","text":"{\"market\":\"0x9c535590faae21bf76fed844aa47fc3c5c82253ef38bd545bf12c93470502685\", \"price_changes\":[{\"asset_id\":\"107011546575057755426871645700605806081353395825571114128343592072429146374928\", \"price\":\"0.54\", \"size\":\"513.52\", \"side\":\"BUY\", \"hash\":\"eb027f0b9adff9cdaba9544a6c5277ed7c1939fe\", \"best_bid\":\"0.54\", \"best_ask\":\"0.55\"}, {\"asset_id\":\"56108879726720646120583724001239294777304794469144970684362785767667828318889\", \"price\":\"0.46\", \"size\":\"513.52\", \"side\":\"SELL\", \"hash\":\"6c77d0bcae235691111169e8276b97bf36413246\", \"best_bid\":\"0.45\", \"best_ask\":\"0.46\"}], \"timestamp\":\"1781254836847\", \"event_type\":\"price_change\"}","ts_local_ms":1781254837310}
{"dir":"in","text":"{\"market\":\"0x9c535590faae21bf76fed844aa47fc3c5c82253ef38bd545bf12c93470502685\", \"price_changes\":[{\"asset_id\":\"56108879726720646120583724001239294777304794469144970684362785767667828318889\", \"price\":\"0.44\", \"size\":\"95.83\", \"side\":\"BUY\", \"hash\":\"be20c5d7a0fa67c07efab9dfd81ba54db8b36c51\", \"best_bid\":\"0.45\", \"best_ask\":\"0.46\"}, {\"asset_id\":\"107011546575057755426871645700605806081353395825571114128343592072429146374928\", \"price\":\"0.56\", \"size\":\"95.83\", \"side\":\"SELL\", \"hash\":\"c3b6a1e5c562ae7c62d6ce6ae371707be8ed61a6\", \"best_bid\":\"0.54\", \"best_ask\":\"0.55\"}], \"timestamp\":\"1781254836848\", \"event_type\":\"price_change\"}","ts_local_ms":1781254837310}
{"dir":"in","text":"{\"market\":\"0x9c535590faae21bf76fed844aa47fc3c5c82253ef38bd545bf12c93470502685\", \"price_changes\":[{\"asset_id\":\"56108879726720646120583724001239294777304794469144970684362785767667828318889\", \"price\":\"0.35\", \"size\":\"266\", \"side\":\"BUY\", \"hash\":\"14a567e86f8c0fd5a85995f43009f49326de12ec\", \"best_bid\":\"0.45\", \"best_ask\":\"0.46\"}, {\"asset_id\":\"107011546575057755426871645700605806081353395825571114128343592072429146374928\", \"price\":\"0.65\", \"size\":\"266\", \"side\":\"SELL\", \"hash\":\"680302c706daaaab5563916829dc0c7b760bfc72\", \"best_bid\":\"0.54\", \"best_ask\":\"0.55\"}], \"timestamp\":\"1781254836849\", \"event_type\":\"price_change\"}","ts_local_ms":1781254837310}
{"dir":"in","text":"{\"market\":\"0x9c535590faae21bf76fed844aa47fc3c5c82253ef38bd545bf12c93470502685\", \"price_changes\":[{\"asset_id\":\"56108879726720646120583724001239294777304794469144970684362785767667828318889\", \"price\":\"0.44\", \"size\":\"87.83\", \"side\":\"BUY\", \"hash\":\"ee2d3c3b38a0f4f62253b98ab7791729d8131c0d\", \"best_bid\":\"0.45\", \"best_ask\":\"0.46\"}, {\"asset_id\":\"107011546575057755426871645700605806081353395825571114128343592072429146374928\", \"price\":\"0.56\", \"size\":\"87.83\", \"side\":\"SELL\", \"hash\":\"e89030c6273d96915df933931dbdde8007c5efea\", \"best_bid\":\"0.54\", \"best_ask\":\"0.55\"}], \"timestamp\":\"1781254836850\", \"event_type\":\"price_change\"}","ts_local_ms":1781254837310}
{"dir":"in","text":"{\"market\":\"0x9c535590faae21bf76fed844aa47fc3c5c82253ef38bd545bf12c93470502685\", \"price_changes\":[{\"asset_id\":\"107011546575057755426871645700605806081353395825571114128343592072429146374928\", \"price\":\"0.42\", \"size\":\"244\", \"side\":\"BUY\", \"hash\":\"52d118d5a46c77e69fac16bf160181bf48d64c39\", \"best_bid\":\"0.54\", \"best_ask\":\"0.55\"}, {\"asset_id\":\"56108879726720646120583724001239294777304794469144970684362785767667828318889\", \"price\":\"0.58\", \"size\":\"244\", \"side\":\"SELL\", \"hash\":\"500d19763eb9ced4943b77b59d3e5585004a25fc\", \"best_bid\":\"0.45\", \"best_ask\":\"0.46\"}], \"timestamp\":\"1781254836850\", \"event_type\":\"price_change\"}","ts_local_ms":1781254837310}
{"dir":"in","text":"{\"market\":\"0x9c535590faae21bf76fed844aa47fc3c5c82253ef38bd545bf12c93470502685\", \"price_changes\":[{\"asset_id\":\"107011546575057755426871645700605806081353395825571114128343592072429146374928\", \"price\":\"0.49\", \"size\":\"339.91\", \"side\":\"BUY\", \"hash\":\"387b3b36df65bc66e06d3c47be49a8b9781f6ab8\", \"best_bid\":\"0.54\", \"best_ask\":\"0.55\"}, {\"asset_id\":\"56108879726720646120583724001239294777304794469144970684362785767667828318889\", \"price\":\"0.51\", \"size\":\"339.91\", \"side\":\"SELL\", \"hash\":\"af64158e6fa4e1c6ace7f1cf55ee03a48b8b56e2\", \"best_bid\":\"0.45\", \"best_ask\":\"0.46\"}], \"timestamp\":\"1781254836850\", \"event_type\":\"price_change\"}","ts_local_ms":1781254837310}
{"dir":"in","text":"{\"market\":\"0x9c535590faae21bf76fed844aa47fc3c5c82253ef38bd545bf12c93470502685\", \"price_changes\":[{\"asset_id\":\"56108879726720646120583724001239294777304794469144970684362785767667828318889\", \"price\":\"0.39\", \"size\":\"436\", \"side\":\"BUY\", \"hash\":\"f098e1529964985e976a6e96e44b960cd3583388\", \"best_bid\":\"0.45\", \"best_ask\":\"0.46\"}, {\"asset_id\":\"107011546575057755426871645700605806081353395825571114128343592072429146374928\", \"price\":\"0.61\", \"size\":\"436\", \"side\":\"SELL\", \"hash\":\"69264114c5b78ffbf20b858759b6b97358cc3dde\", \"best_bid\":\"0.54\", \"best_ask\":\"0.55\"}], \"timestamp\":\"1781254836851\", \"event_type\":\"price_change\"}","ts_local_ms":1781254837310}
{"dir":"in","text":"{\"market\":\"0x9c535590faae21bf76fed844aa47fc3c5c82253ef38bd545bf12c93470502685\", \"price_changes\":[{\"asset_id\":\"107011546575057755426871645700605806081353395825571114128343592072429146374928\", \"price\":\"0.5\", \"size\":\"369.15\", \"side\":\"BUY\", \"hash\":\"da5804777b8ef5525aa4535bdd184514a44dd67b\", \"best_bid\":\"0.54\", \"best_ask\":\"0.55\"}, {\"asset_id\":\"56108879726720646120583724001239294777304794469144970684362785767667828318889\", \"price\":\"0.5\", \"size\":\"369.15\", \"side\":\"SELL\", \"hash\":\"26866bb3016e584055181250851eb4aadbf76bc2\", \"best_bid\":\"0.45\", \"best_ask\":\"0.46\"}], \"timestamp\":\"1781254836852\", \"event_type\":\"price_change\"}","ts_local_ms":1781254837310}
{"dir":"in","text":"{\"market\":\"0x9c535590faae21bf76fed844aa47fc3c5c82253ef38bd545bf12c93470502685\", \"price_changes\":[{\"asset_id\":\"107011546575057755426871645700605806081353395825571114128343592072429146374928\", \"price\":\"0.52\", \"size\":\"116.37\", \"side\":\"BUY\", \"hash\":\"062e266cf5efd22d9f7f60e3c567634b138e6fe0\", \"best_bid\":\"0.54\", \"best_ask\":\"0.55\"}, {\"asset_id\":\"56108879726720646120583724001239294777304794469144970684362785767667828318889\", \"price\":\"0.48\", \"size\":\"116.37\", \"side\":\"SELL\", \"hash\":\"a55cb7a4f04e5ff92dd2c110c0a364b6f804c044\", \"best_bid\":\"0.45\", \"best_ask\":\"0.46\"}], \"timestamp\":\"1781254836852\", \"event_type\":\"price_change\"}","ts_local_ms":1781254837310}
{"dir":"in","text":"{\"market\":\"0x9c535590faae21bf76fed844aa47fc3c5c82253ef38bd545bf12c93470502685\", \"price_changes\":[{\"asset_id\":\"107011546575057755426871645700605806081353395825571114128343592072429146374928\", \"price\":\"0.5\", \"size\":\"364.15\", \"side\":\"BUY\", \"hash\":\"0f72b09a85853437f7a609a529755d24b4072a97\", \"best_bid\":\"0.54\", \"best_ask\":\"0.55\"}, {\"asset_id\":\"56108879726720646120583724001239294777304794469144970684362785767667828318889\", \"price\":\"0.5\", \"size\":\"364.15\", \"side\":\"SELL\", \"hash\":\"90ff3e942a287c51eb05a6fbd4ba25575f2c3087\", \"best_bid\":\"0.45\", \"best_ask\":\"0.46\"}], \"timestamp\":\"1781254836852\", \"event_type\":\"price_change\"}","ts_local_ms":1781254837310}
{"dir":"in","text":"{\"market\":\"0x9c535590faae21bf76fed844aa47fc3c5c82253ef38bd545bf12c93470502685\", \"price_changes\":[{\"asset_id\":\"56108879726720646120583724001239294777304794469144970684362785767667828318889\", \"price\":\"0.45\", \"size\":\"572.78\", \"side\":\"BUY\", \"hash\":\"e7164ba3ff5ead42e3f5fe84f8c3c5f1c30cb865\", \"best_bid\":\"0.45\", \"best_ask\":\"0.46\"}, {\"asset_id\":\"107011546575057755426871645700605806081353395825571114128343592072429146374928\", \"price\":\"0.55\", \"size\":\"572.78\", \"side\":\"SELL\", \"hash\":\"0e5e0d58ca4f1c8c2ce4fa070157bb55619130b6\", \"best_bid\":\"0.54\", \"best_ask\":\"0.55\"}], \"timestamp\":\"1781254836852\", \"event_type\":\"price_change\"}","ts_local_ms":1781254837310}
{"dir":"in","text":"{\"market\":\"0x9c535590faae21bf76fed844aa47fc3c5c82253ef38bd545bf12c93470502685\", \"price_changes\":[{\"asset_id\":\"107011546575057755426871645700605806081353395825571114128343592072429146374928\", \"price\":\"0.54\", \"size\":\"518.52\", \"side\":\"BUY\", \"hash\":\"5f28312ceca1722dcf86bf9f3f2e041188fe1101\", \"best_bid\":\"0.54\", \"best_ask\":\"0.55\"}, {\"asset_id\":\"56108879726720646120583724001239294777304794469144970684362785767667828318889\", \"price\":\"0.46\", \"size\":\"518.52\", \"side\":\"SELL\", \"hash\":\"b5ea0d3f791a923ee9c59da36cf557d031eaceb5\", \"best_bid\":\"0.45\", \"best_ask\":\"0.46\"}], \"timestamp\":\"1781254836853\", \"event_type\":\"price_change\"}","ts_local_ms":1781254837310}
{"dir":"in","text":"{\"market\":\"0x9c535590faae21bf76fed844aa47fc3c5c82253ef38bd545bf12c93470502685\", \"price_changes\":[{\"asset_id\":\"56108879726720646120583724001239294777304794469144970684362785767667828318889\", \"price\":\"0.37\", \"size\":\"317.04\", \"side\":\"BUY\", \"hash\":\"fce5500551e536decb943982f904abcd53da6637\", \"best_bid\":\"0.45\", \"best_ask\":\"0.46\"}, {\"asset_id\":\"107011546575057755426871645700605806081353395825571114128343592072429146374928\", \"price\":\"0.63\", \"size\":\"317.04\", \"side\":\"SELL\", \"hash\":\"b503609cdb536940abc3783a11e54bec3138219b\", \"best_bid\":\"0.54\", \"best_ask\":\"0.55\"}], \"timestamp\":\"1781254836853\", \"event_type\":\"price_change\"}","ts_local_ms":1781254837310}
{"dir":"in","text":"{\"market\":\"0x9c535590faae21bf76fed844aa47fc3c5c82253ef38bd545bf12c93470502685\", \"price_changes\":[{\"asset_id\":\"56108879726720646120583724001239294777304794469144970684362785767667828318889\", \"price\":\"0.33\", \"size\":\"173\", \"side\":\"BUY\", \"hash\":\"81ace4671114fb11ee52dc99a03a098405bf38a3\", \"best_bid\":\"0.45\", \"best_ask\":\"0.46\"}, {\"asset_id\":\"107011546575057755426871645700605806081353395825571114128343592072429146374928\", \"price\":\"0.67\", \"size\":\"173\", \"side\":\"SELL\", \"hash\":\"a6d28410e75196b98c2763a634da78c7e4bd74e8\", \"best_bid\":\"0.54\", \"best_ask\":\"0.55\"}], \"timestamp\":\"1781254836854\", \"event_type\":\"price_change\"}","ts_local_ms":1781254837310}
{"dir":"in","text":"{\"market\":\"0x9c535590faae21bf76fed844aa47fc3c5c82253ef38bd545bf12c93470502685\", \"price_changes\":[{\"asset_id\":\"56108879726720646120583724001239294777304794469144970684362785767667828318889\", \"price\":\"0.34\", \"size\":\"106\", \"side\":\"BUY\", \"hash\":\"36987f2fd1688adb76bf68c944e4f4c57224f8a4\", \"best_bid\":\"0.45\", \"best_ask\":\"0.46\"}, {\"asset_id\":\"107011546575057755426871645700605806081353395825571114128343592072429146374928\", \"price\":\"0.66\", \"size\":\"106\", \"side\":\"SELL\", \"hash\":\"662cc851d61b7da525b8c6f860b291162ecb63b6\", \"best_bid\":\"0.54\", \"best_ask\":\"0.55\"}], \"timestamp\":\"1781254836855\", \"event_type\":\"price_change\"}","ts_local_ms":1781254837311}
{"dir":"in","text":"{\"market\":\"0x9c535590faae21bf76fed844aa47fc3c5c82253ef38bd545bf12c93470502685\", \"price_changes\":[{\"asset_id\":\"56108879726720646120583724001239294777304794469144970684362785767667828318889\", \"price\":\"0.45\", \"size\":\"577.78\", \"side\":\"BUY\", \"hash\":\"a9b010a5c499d31989c03a55f88ab2698447f21e\", \"best_bid\":\"0.45\", \"best_ask\":\"0.46\"}, {\"asset_id\":\"107011546575057755426871645700605806081353395825571114128343592072429146374928\", \"price\":\"0.55\", \"size\":\"577.78\", \"side\":\"SELL\", \"hash\":\"2dfb93b7a112348482b28f7ec5ea3ee5485fdfdd\", \"best_bid\":\"0.54\", \"best_ask\":\"0.55\"}], \"timestamp\":\"1781254836855\", \"event_type\":\"price_change\"}","ts_local_ms":1781254837473}
{"dir":"in","text":"{\"market\":\"0x9c535590faae21bf76fed844aa47fc3c5c82253ef38bd545bf12c93470502685\", \"price_changes\":[{\"asset_id\":\"107011546575057755426871645700605806081353395825571114128343592072429146374928\", \"price\":\"0.44\", \"size\":\"133.53\", \"side\":\"BUY\", \"hash\":\"818f69e30f649986cc88e1dccc166b1c4686e91f\", \"best_bid\":\"0.54\", \"best_ask\":\"0.55\"}, {\"asset_id\":\"56108879726720646120583724001239294777304794469144970684362785767667828318889\", \"price\":\"0.56\", \"size\":\"133.53\", \"side\":\"SELL\", \"hash\":\"087b624932643c7de7f59b0c3e2a7c19ed076cd5\", \"best_bid\":\"0.45\", \"best_ask\":\"0.46\"}], \"timestamp\":\"1781254836856\", \"event_type\":\"price_change\"}","ts_local_ms":1781254837473}
{"dir":"in","text":"{\"market\":\"0x9c535590faae21bf76fed844aa47fc3c5c82253ef38bd545bf12c93470502685\", \"price_changes\":[{\"asset_id\":\"56108879726720646120583724001239294777304794469144970684362785767667828318889\", \"price\":\"0.38\", \"size\":\"281\", \"side\":\"BUY\", \"hash\":\"19fdcf0a0d62a98625bdfa9e4abe3fbd45a31f16\", \"best_bid\":\"0.45\", \"best_ask\":\"0.46\"}, {\"asset_id\":\"107011546575057755426871645700605806081353395825571114128343592072429146374928\", \"price\":\"0.62\", \"size\":\"281\", \"side\":\"SELL\", \"hash\":\"f817c5996968ec731b873551f76a60b74cbafb27\", \"best_bid\":\"0.54\", \"best_ask\":\"0.55\"}], \"timestamp\":\"1781254836858\", \"event_type\":\"price_change\"}","ts_local_ms":1781254837473}
{"dir":"in","text":"{\"market\":\"0x9c535590faae21bf76fed844aa47fc3c5c82253ef38bd545bf12c93470502685\", \"price_changes\":[{\"asset_id\":\"56108879726720646120583724001239294777304794469144970684362785767667828318889\", \"price\":\"0.46\", \"size\":\"468.52\", \"side\":\"SELL\", \"hash\":\"6dc475ac82e8a5a04c90a371f327c234cb029cf0\", \"best_bid\":\"0.45\", \"best_ask\":\"0.46\"}, {\"asset_id\":\"107011546575057755426871645700605806081353395825571114128343592072429146374928\", \"price\":\"0.54\", \"size\":\"468.52\", \"side\":\"BUY\", \"hash\":\"bd0e90892d0d1163f8e6fc1707fd9d1198b8e467\", \"best_bid\":\"0.54\", \"best_ask\":\"0.55\"}], \"timestamp\":\"1781254836858\", \"event_type\":\"price_change\"}","ts_local_ms":1781254837473}
{"dir":"in","text":"{\"market\":\"0x9c535590faae21bf76fed844aa47fc3c5c82253ef38bd545bf12c93470502685\", \"price_changes\":[{\"asset_id\":\"56108879726720646120583724001239294777304794469144970684362785767667828318889\", \"price\":\"0.01\", \"size\":\"57384.15\", \"side\":\"BUY\", \"hash\":\"7d87e28031e41bcea3648f3a1f4f9f0e921a3b39\", \"best_bid\":\"0.45\", \"best_ask\":\"0.46\"}, {\"asset_id\":\"107011546575057755426871645700605806081353395825571114128343592072429146374928\", \"price\":\"0.99\", \"size\":\"57384.15\", \"side\":\"SELL\", \"hash\":\"1a88f67f7dc9ab96f52385c6eda9c176cbc12a91\", \"best_bid\":\"0.54\", \"best_ask\":\"0.55\"}], \"timestamp\":\"1781254836859\", \"event_type\":\"price_change\"}","ts_local_ms":1781254837473}
{"dir":"in","text":"{\"market\":\"0x9c535590faae21bf76fed844aa47fc3c5c82253ef38bd545bf12c93470502685\", \"price_changes\":[{\"asset_id\":\"107011546575057755426871645700605806081353395825571114128343592072429146374928\", \"price\":\"0.5\", \"size\":\"370.73\", \"side\":\"BUY\", \"hash\":\"100c0e3c545986290b13a6e31cd189b980d64885\", \"best_bid\":\"0.54\", \"best_ask\":\"0.55\"}, {\"asset_id\":\"56108879726720646120583724001239294777304794469144970684362785767667828318889\", \"price\":\"0.5\", \"size\":\"370.73\", \"side\":\"SELL\", \"hash\":\"cfacbd14c9e818775233a69db7336ab8a5f834e9\", \"best_bid\":\"0.45\", \"best_ask\":\"0.46\"}], \"timestamp\":\"1781254836860\", \"event_type\":\"price_change\"}","ts_local_ms":1781254837473}
{"dir":"in","text":"{\"market\":\"0x9c535590faae21bf76fed844aa47fc3c5c82253ef38bd545bf12c93470502685\", \"price_changes\":[{\"asset_id\":\"107011546575057755426871645700605806081353395825571114128343592072429146374928\", \"price\":\"0.55\", \"size\":\"583.15\", \"side\":\"SELL\", \"hash\":\"61198ab0145fd6b7e26cfa39d8e725f7c31a53d2\", \"best_bid\":\"0.54\", \"best_ask\":\"0.55\"}, {\"asset_id\":\"56108879726720646120583724001239294777304794469144970684362785767667828318889\", \"price\":\"0.45\", \"size\":\"583.15\", \"side\":\"BUY\", \"hash\":\"a88290b2c0ed9b32bbe3b5951387f7a9459c666c\", \"best_bid\":\"0.45\", \"best_ask\":\"0.46\"}], \"timestamp\":\"1781254836860\", \"event_type\":\"price_change\"}","ts_local_ms":1781254837473}
{"dir":"in","text":"{\"market\":\"0x9c535590faae21bf76fed844aa47fc3c5c82253ef38bd545bf12c93470502685\", \"price_changes\":[{\"asset_id\":\"56108879726720646120583724001239294777304794469144970684362785767667828318889\", \"price\":\"0.45\", \"size\":\"589.53\", \"side\":\"BUY\", \"hash\":\"ecc4c7a3d5e3a8702b073515404359def862a34e\", \"best_bid\":\"0.45\", \"best_ask\":\"0.46\"}, {\"asset_id\":\"107011546575057755426871645700605806081353395825571114128343592072429146374928\", \"price\":\"0.55\", \"size\":\"589.53\", \"side\":\"SELL\", \"hash\":\"0adc99d6e79e1144f06495031440483599111d2b\", \"best_bid\":\"0.54\", \"best_ask\":\"0.55\"}], \"timestamp\":\"1781254836861\", \"event_type\":\"price_change\"}","ts_local_ms":1781254837473}
{"dir":"in","text":"{\"market\":\"0x9c535590faae21bf76fed844aa47fc3c5c82253ef38bd545bf12c93470502685\", \"price_changes\":[{\"asset_id\":\"107011546575057755426871645700605806081353395825571114128343592072429146374928\", \"price\":\"0.46\", \"size\":\"342.36\", \"side\":\"BUY\", \"hash\":\"2fd802546609429439b064b2d6a3c32a2386a473\", \"best_bid\":\"0.54\", \"best_ask\":\"0.55\"}, {\"asset_id\":\"56108879726720646120583724001239294777304794469144970684362785767667828318889\", \"price\":\"0.54\", \"size\":\"342.36\", \"side\":\"SELL\", \"hash\":\"ed45d02795b29eee8e8ecdbf29969d38b8e6e61a\", \"best_bid\":\"0.45\", \"best_ask\":\"0.46\"}], \"timestamp\":\"1781254836862\", \"event_type\":\"price_change\"}","ts_local_ms":1781254837473}
{"dir":"in","text":"{\"market\":\"0x9c535590faae21bf76fed844aa47fc3c5c82253ef38bd545bf12c93470502685\", \"price_changes\":[{\"asset_id\":\"56108879726720646120583724001239294777304794469144970684362785767667828318889\", \"price\":\"0.31\", \"size\":\"96\", \"side\":\"BUY\", \"hash\":\"58852d0c36e78cd7111c8ba94096773088affa72\", \"best_bid\":\"0.45\", \"best_ask\":\"0.46\"}, {\"asset_id\":\"107011546575057755426871645700605806081353395825571114128343592072429146374928\", \"price\":\"0.69\", \"size\":\"96\", \"side\":\"SELL\", \"hash\":\"4f72fb72bd700984ceb06295ec2ad01d7c7c57d8\", \"best_bid\":\"0.54\", \"best_ask\":\"0.55\"}], \"timestamp\":\"1781254836864\", \"event_type\":\"price_change\"}","ts_local_ms":1781254837473}
{"dir":"in","text":"{\"market\":\"0x9c535590faae21bf76fed844aa47fc3c5c82253ef38bd545bf12c93470502685\", \"price_changes\":[{\"asset_id\":\"56108879726720646120583724001239294777304794469144970684362785767667828318889\", \"price\":\"0.42\", \"size\":\"134.2\", \"side\":\"BUY\", \"hash\":\"8a8c09338798383edfed96e59fc96a28333a9c7d\", \"best_bid\":\"0.45\", \"best_ask\":\"0.46\"}, {\"asset_id\":\"107011546575057755426871645700605806081353395825571114128343592072429146374928\", \"price\":\"0.58\", \"size\":\"134.2\", \"side\":\"SELL\", \"hash\":\"150df6dfe649bd7cc262c5a6403c8fe65b8969ed\", \"best_bid\":\"0.54\", \"best_ask\":\"0.55\"}], \"timestamp\":\"1781254836866\", \"event_type\":\"price_change\"}","ts_local_ms":1781254837474}
{"dir":"in","text":"{\"market\":\"0x9c535590faae21bf76fed844aa47fc3c5c82253ef38bd545bf12c93470502685\", \"price_changes\":[{\"asset_id\":\"107011546575057755426871645700605806081353395825571114128343592072429146374928\", \"price\":\"0.54\", \"size\":\"428.52\", \"side\":\"BUY\", \"hash\":\"5395643bcdcd492da864bd17a87ae4f54fd9afd8\", \"best_bid\":\"0.54\", \"best_ask\":\"0.55\"}, {\"asset_id\":\"56108879726720646120583724001239294777304794469144970684362785767667828318889\", \"price\":\"0.46\", \"size\":\"428.52\", \"side\":\"SELL\", \"hash\":\"563f2b240adb4632ec05e9abdb1033b123b90fdb\", \"best_bid\":\"0.45\", \"best_ask\":\"0.46\"}], \"timestamp\":\"1781254836866\", \"event_type\":\"price_change\"}","ts_local_ms":1781254837474}
{"dir":"in","text":"{\"market\":\"0x9c535590faae21bf76fed844aa47fc3c5c82253ef38bd545bf12c93470502685\", \"price_changes\":[{\"asset_id\":\"56108879726720646120583724001239294777304794469144970684362785767667828318889\", \"price\":\"0.33\", \"size\":\"223\", \"side\":\"BUY\", \"hash\":\"5eb1a931e0e2541cffff5c2fc851dc711327dac2\", \"best_bid\":\"0.45\", \"best_ask\":\"0.46\"}, {\"asset_id\":\"107011546575057755426871645700605806081353395825571114128343592072429146374928\", \"price\":\"0.67\", \"size\":\"223\", \"side\":\"SELL\", \"hash\":\"72b6202c06f697b15f9dc8e9ac186c7ac7d558c3\", \"best_bid\":\"0.54\", \"best_ask\":\"0.55\"}], \"timestamp\":\"1781254836867\", \"event_type\":\"price_change\"}","ts_local_ms":1781254837474}
{"dir":"in","text":"{\"market\":\"0x9c535590faae21bf76fed844aa47fc3c5c82253ef38bd545bf12c93470502685\", \"price_changes\":[{\"asset_id\":\"56108879726720646120583724001239294777304794469144970684362785767667828318889\", \"price\":\"0.45\", \"size\":\"604.53\", \"side\":\"BUY\", \"hash\":\"71c75999ec76b79bd998770bdec0080d178ec174\", \"best_bid\":\"0.45\", \"best_ask\":\"0.46\"}, {\"asset_id\":\"107011546575057755426871645700605806081353395825571114128343592072429146374928\", \"price\":\"0.55\", \"size\":\"604.53\", \"side\":\"SELL\", \"hash\":\"4f0ada9cc3a128fa96d9d7f5b787110fd0eef61a\", \"best_bid\":\"0.54\", \"best_ask\":\"0.55\"}], \"timestamp\":\"1781254836867\", \"event_type\":\"price_change\"}","ts_local_ms":1781254837474}
{"dir":"in","text":"{\"market\":\"0x9c535590faae21bf76fed844aa47fc3c5c82253ef38bd545bf12c93470502685\", \"price_changes\":[{\"asset_id\":\"56108879726720646120583724001239294777304794469144970684362785767667828318889\", \"price\":\"0.45\", \"size\":\"596.53\", \"side\":\"BUY\", \"hash\":\"515aea74aca5f2c0fc5d9d63440799aabff948a5\", \"best_bid\":\"0.45\", \"best_ask\":\"0.46\"}, {\"asset_id\":\"107011546575057755426871645700605806081353395825571114128343592072429146374928\", \"price\":\"0.55\", \"size\":\"596.53\", \"side\":\"SELL\", \"hash\":\"80c27bb0be98a2cf6ce5a5fcfed3f3e9fd39cc9e\", \"best_bid\":\"0.54\", \"best_ask\":\"0.55\"}], \"timestamp\":\"1781254836868\", \"event_type\":\"price_change\"}","ts_local_ms":1781254837474}
{"dir":"in","text":"{\"market\":\"0x9c535590faae21bf76fed844aa47fc3c5c82253ef38bd545bf12c93470502685\", \"price_changes\":[{\"asset_id\":\"56108879726720646120583724001239294777304794469144970684362785767667828318889\", \"price\":\"0.37\", \"size\":\"367.04\", \"side\":\"BUY\", \"hash\":\"d9b4687f079d3340ac4546f027aa37e747f2d18a\", \"best_bid\":\"0.45\", \"best_ask\":\"0.46\"}, {\"asset_id\":\"107011546575057755426871645700605806081353395825571114128343592072429146374928\", \"price\":\"0.63\", \"size\":\"367.04\", \"side\":\"SELL\", \"hash\":\"a73637f8c728ad8db4bf8fef579f8775eaddd531\", \"best_bid\":\"0.54\", \"best_ask\":\"0.55\"}], \"timestamp\":\"1781254836868\", \"event_type\":\"price_change\"}","ts_local_ms":1781254837474}
{"dir":"in","text":"{\"market\":\"0x9c535590faae21bf76fed844aa47fc3c5c82253ef38bd545bf12c93470502685\", \"price_changes\":[{\"asset_id\":\"107011546575057755426871645700605806081353395825571114128343592072429146374928\", \"price\":\"0.53\", \"size\":\"67\", \"side\":\"BUY\", \"hash\":\"9225e4e9db58a680d3c22e8112cfab58e3101129\", \"best_bid\":\"0.54\", \"best_ask\":\"0.55\"}, {\"asset_id\":\"56108879726720646120583724001239294777304794469144970684362785767667828318889\", \"price\":\"0.47\", \"size\":\"67\", \"side\":\"SELL\", \"hash\":\"93f96107a62604e24332f4bee220f832e24e2e8c\", \"best_bid\":\"0.45\", \"best_ask\":\"0.46\"}], \"timestamp\":\"1781254836869\", \"event_type\":\"price_change\"}","ts_local_ms":1781254837474}
{"dir":"in","text":"{\"market\":\"0x9c535590faae21bf76fed844aa47fc3c5c82253ef38bd545bf12c93470502685\", \"price_changes\":[{\"asset_id\":\"107011546575057755426871645700605806081353395825571114128343592072429146374928\", \"price\":\"0.44\", \"size\":\"128.53\", \"side\":\"BUY\", \"hash\":\"fecbca35a0ad89620f24001c1bcb650cfc23b53c\", \"best_bid\":\"0.54\", \"best_ask\":\"0.55\"}, {\"asset_id\":\"56108879726720646120583724001239294777304794469144970684362785767667828318889\", \"price\":\"0.56\", \"size\":\"128.53\", \"side\":\"SELL\", \"hash\":\"b42f886ff33ee630e60509a28467d76d125adc1d\", \"best_bid\":\"0.45\", \"best_ask\":\"0.46\"}], \"timestamp\":\"1781254836869\", \"event_type\":\"price_change\"}","ts_local_ms":1781254837474}
{"dir":"in","text":"{\"market\":\"0x9c535590faae21bf76fed844aa47fc3c5c82253ef38bd545bf12c93470502685\", \"price_changes\":[{\"asset_id\":\"56108879726720646120583724001239294777304794469144970684362785767667828318889\", \"price\":\"0.39\", \"size\":\"461\", \"side\":\"BUY\", \"hash\":\"81e270e7cd2603b37a7e2398893eaa1d43d49d39\", \"best_bid\":\"0.45\", \"best_ask\":\"0.46\"}, {\"asset_id\":\"107011546575057755426871645700605806081353395825571114128343592072429146374928\", \"price\":\"0.61\", \"size\":\"461\", \"side\":\"SELL\", \"hash\":\"741b83e48dbe378835d4bc6a4c7a0b19736c4b13\", \"best_bid\":\"0.54\", \"best_ask\":\"0.55\"}], \"timestamp\":\"1781254836869\", \"event_type\":\"price_change\"}","ts_local_ms":1781254837474}
{"dir":"in","text":"{\"market\":\"0x9c535590faae21bf76fed844aa47fc3c5c82253ef38bd545bf12c93470502685\", \"price_changes\":[{\"asset_id\":\"56108879726720646120583724001239294777304794469144970684362785767667828318889\", \"price\":\"0.41\", \"size\":\"126\", \"side\":\"BUY\", \"hash\":\"62dfe6793637960011fde3cf8c50a1ecbe70897f\", \"best_bid\":\"0.45\", \"best_ask\":\"0.46\"}, {\"asset_id\":\"107011546575057755426871645700605806081353395825571114128343592072429146374928\", \"price\":\"0.59\", \"size\":\"126\", \"side\":\"SELL\", \"hash\":\"97299539635815fab3492ccbe1dedb88ef1851b4\", \"best_bid\":\"0.54\", \"best_ask\":\"0.55\"}], \"timestamp\":\"1781254836870\", \"event_type\":\"price_change\"}","ts_local_ms":1781254837474}
{"dir":"in","text":"{\"market\":\"0x9c535590faae21bf76fed844aa47fc3c5c82253ef38bd545bf12c93470502685\", \"price_changes\":[{\"asset_id\":\"107011546575057755426871645700605806081353395825571114128343592072429146374928\", \"price\":\"0.54\", \"size\":\"433.52\", \"side\":\"BUY\", \"hash\":\"2509b3ef67905954dd2373b5011d6a7e6fd0b9be\", \"best_bid\":\"0.54\", \"best_ask\":\"0.55\"}, {\"asset_id\":\"56108879726720646120583724001239294777304794469144970684362785767667828318889\", \"price\":\"0.46\", \"size\":\"433.52\", \"side\":\"SELL\", \"hash\":\"8bb8c94ee20a88f6b0971b7dd4bfed81e42205d2\", \"best_bid\":\"0.45\", \"best_ask\":\"0.46\"}], \"timestamp\":\"1781254836871\", \"event_type\":\"price_change\"}","ts_local_ms":1781254837474}
{"dir":"in","text":"{\"market\":\"0x9c535590faae21bf76fed844aa47fc3c5c82253ef38bd545bf12c93470502685\", \"price_changes\":[{\"asset_id\":\"56108879726720646120583724001239294777304794469144970684362785767667828318889\", \"price\":\"0.39\", \"size\":\"468.07\", \"side\":\"BUY\", \"hash\":\"b876ccd59628991e53c8508ec29999de246739ae\", \"best_bid\":\"0.45\", \"best_ask\":\"0.46\"}, {\"asset_id\":\"107011546575057755426871645700605806081353395825571114128343592072429146374928\", \"price\":\"0.61\", \"size\":\"468.07\", \"side\":\"SELL\", \"hash\":\"d519d8ce43e0a93415241a1c06dd523aed2548af\", \"best_bid\":\"0.54\", \"best_ask\":\"0.55\"}], \"timestamp\":\"1781254836871\", \"event_type\":\"price_change\"}","ts_local_ms":1781254837474}
{"dir":"in","text":"{\"market\":\"0x9c535590faae21bf76fed844aa47fc3c5c82253ef38bd545bf12c93470502685\", \"price_changes\":[{\"asset_id\":\"56108879726720646120583724001239294777304794469144970684362785767667828318889\", \"price\":\"0.18\", \"size\":\"360.6\", \"side\":\"BUY\", \"hash\":\"767d0a9486b86073a133bf08d063624ba40f47ff\", \"best_bid\":\"0.45\", \"best_ask\":\"0.46\"}, {\"asset_id\":\"107011546575057755426871645700605806081353395825571114128343592072429146374928\", \"price\":\"0.82\", \"size\":\"360.6\", \"side\":\"SELL\", \"hash\":\"2615194df4f3bf2eca6c168a1bf3388d2115d03f\", \"best_bid\":\"0.54\", \"best_ask\":\"0.55\"}], \"timestamp\":\"1781254836872\", \"event_type\":\"price_change\"}","ts_local_ms":1781254837474}
{"dir":"in","text":"{\"market\":\"0x9c535590faae21bf76fed844aa47fc3c5c82253ef38bd545bf12c93470502685\", \"price_changes\":[{\"asset_id\":\"107011546575057755426871645700605806081353395825571114128343592072429146374928\", \"price\":\"0.54\", \"size\":\"438.52\", \"side\":\"BUY\", \"hash\":\"5cd48c5c1d3c0bdd3549225c969a7f33404abd9c\", \"best_bid\":\"0.54\", \"best_ask\":\"0.55\"}, {\"asset_id\":\"56108879726720646120583724001239294777304794469144970684362785767667828318889\", \"price\":\"0.46\", \"size\":\"438.52\", \"side\":\"SELL\", \"hash\":\"9499e2b58ebf69d8918e24e92cc528118160e2ac\", \"best_bid\":\"0.45\", \"best_ask\":\"0.46\"}], \"timestamp\":\"1781254836874\", \"event_type\":\"price_change\"}","ts_local_ms":1781254837474}
{"dir":"in","text":"{\"market\":\"0x9c535590faae21bf76fed844aa47fc3c5c82253ef38bd545bf12c93470502685\", \"price_changes\":[{\"asset_id\":\"56108879726720646120583724001239294777304794469144970684362785767667828318889\", \"price\":\"0.42\", \"size\":\"126.2\", \"side\":\"BUY\", \"hash\":\"72fea10f88dbcfa2fa5e35a94aeceb760cb5ad53\", \"best_bid\":\"0.45\", \"best_ask\":\"0.46\"}, {\"asset_id\":\"107011546575057755426871645700605806081353395825571114128343592072429146374928\", \"price\":\"0.58\", \"size\":\"126.2\", \"side\":\"SELL\", \"hash\":\"442ba13fa5862e4d1b61f2a77374f517e965b905\", \"best_bid\":\"0.54\", \"best_ask\":\"0.55\"}], \"timestamp\":\"1781254836874\", \"event_type\":\"price_change\"}","ts_local_ms":1781254837474}
{"dir":"in","text":"{\"market\":\"0x9c535590faae21bf76fed844aa47fc3c5c82253ef38bd545bf12c93470502685\", \"price_changes\":[{\"asset_id\":\"56108879726720646120583724001239294777304794469144970684362785767667828318889\", \"price\":\"0.45\", \"size\":\"602.53\", \"side\":\"BUY\", \"hash\":\"969dc1805622c39e7018a9632e45c12e7aa48110\", \"best_bid\":\"0.45\", \"best_ask\":\"0.46\"}, {\"asset_id\":\"107011546575057755426871645700605806081353395825571114128343592072429146374928\", \"price\":\"0.55\", \"size\":\"602.53\", \"side\":\"SELL\", \"hash\":\"700961d6e3d2804d999f78aa09e780f4f3627702\", \"best_bid\":\"0.54\", \"best_ask\":\"0.55\"}], \"timestamp\":\"1781254836875\", \"event_type\":\"price_change\"}","ts_local_ms":1781254837474}
{"dir":"in","text":"{\"market\":\"0x9c535590faae21bf76fed844aa47fc3c5c82253ef38bd545bf12c93470502685\", \"price_changes\":[{\"asset_id\":\"56108879726720646120583724001239294777304794469144970684362785767667828318889\", \"price\":\"0.35\", \"size\":\"316\", \"side\":\"BUY\", \"hash\":\"98bb4ca4a014633d1244592d00d4b30f41a98d08\", \"best_bid\":\"0.45\", \"best_ask\":\"0.46\"}, {\"asset_id\":\"107011546575057755426871645700605806081353395825571114128343592072429146374928\", \"price\":\"0.65\", \"size\":\"316\", \"side\":\"SELL\", \"hash\":\"af9be30313292ad610602ba72ee27748c0a845b9\", \"best_bid\":\"0.54\", \"best_ask\":\"0.55\"}], \"timestamp\":\"1781254836875\", \"event_type\":\"price_change\"}","ts_local_ms":1781254837474}
{"dir":"in","text":"{\"market\":\"0x9c535590faae21bf76fed844aa47fc3c5c82253ef38bd545bf12c93470502685\", \"price_changes\":[{\"asset_id\":\"56108879726720646120583724001239294777304794469144970684362785767667828318889\", \"price\":\"0.38\", \"size\":\"286\", \"side\":\"BUY\", \"hash\":\"356f6cd8c9a8ebee418312ac7f32d85edb49110f\", \"best_bid\":\"0.45\", \"best_ask\":\"0.46\"}, {\"asset_id\":\"107011546575057755426871645700605806081353395825571114128343592072429146374928\", \"price\":\"0.62\", \"size\":\"286\", \"side\":\"SELL\", \"hash\":\"0a60448edb2dfd3167034287f7b8d64a38aba72e\", \"best_bid\":\"0.54\", \"best_ask\":\"0.55\"}], \"timestamp\":\"1781254836876\", \"event_type\":\"price_change\"}","ts_local_ms":1781254837474}
{"dir":"in","text":"{\"market\":\"0x9c535590faae21bf76fed844aa47fc3c5c82253ef38bd545bf12c93470502685\", \"price_changes\":[{\"asset_id\":\"107011546575057755426871645700605806081353395825571114128343592072429146374928\", \"price\":\"0.21\", \"size\":\"142.8\", \"side\":\"BUY\", \"hash\":\"ee40d09048dc914bf5db3263889a7269a7deb222\", \"best_bid\":\"0.54\", \"best_ask\":\"0.55\"}, {\"asset_id\":\"56108879726720646120583724001239294777304794469144970684362785767667828318889\", \"price\":\"0.79\", \"size\":\"142.8\", \"side\":\"SELL\", \"hash\":\"3cd98d4d05d63062b8673869f0dd033f5f462f95\", \"best_bid\":\"0.45\", \"best_ask\":\"0.46\"}], \"timestamp\":\"1781254836877\", \"event_type\":\"price_change\"}","ts_local_ms":1781254837474}
{"dir":"in","text":"{\"market\":\"0x9c535590faae21bf76fed844aa47fc3c5c82253ef38bd545bf12c93470502685\", \"price_changes\":[{\"asset_id\":\"107011546575057755426871645700605806081353395825571114128343592072429146374928\", \"price\":\"0.49\", \"size\":\"364.91\", \"side\":\"BUY\", \"hash\":\"71e511845b927513eb3873092501fd06dc9b3023\", \"best_bid\":\"0.54\", \"best_ask\":\"0.55\"}, {\"asset_id\":\"56108879726720646120583724001239294777304794469144970684362785767667828318889\", \"price\":\"0.51\", \"size\":\"364.91\", \"side\":\"SELL\", \"hash\":\"f43a0a3d605c81c6f92be0b7306161d7544ab13d\", \"best_bid\":\"0.45\", \"best_ask\":\"0.46\"}], \"timestamp\":\"1781254836877\", \"event_type\":\"price_change\"}","ts_local_ms":1781254837474}
{"dir":"in","text":"{\"market\":\"0x9c535590faae21bf76fed844aa47fc3c5c82253ef38bd545bf12c93470502685\", \"price_changes\":[{\"asset_id\":\"56108879726720646120583724001239294777304794469144970684362785767667828318889\", \"price\":\"0.34\", \"size\":\"101\", \"side\":\"BUY\", \"hash\":\"3ca4dbce5139c8843b2362fce5dafa0a64502980\", \"best_bid\":\"0.45\", \"best_ask\":\"0.46\"}, {\"asset_id\":\"107011546575057755426871645700605806081353395825571114128343592072429146374928\", \"price\":\"0.66\", \"size\":\"101\", \"side\":\"SELL\", \"hash\":\"c44dc04551577689663f6e0d88f03874c3805bcb\", \"best_bid\":\"0.54\", \"best_ask\":\"0.55\"}], \"timestamp\":\"1781254836878\", \"event_type\":\"price_change\"}","ts_local_ms":1781254837474}
{"dir":"in","text":"{\"market\":\"0x9c535590faae21bf76fed844aa47fc3c5c82253ef38bd545bf12c93470502685\", \"price_changes\":[{\"asset_id\":\"107011546575057755426871645700605806081353395825571114128343592072429146374928\", \"price\":\"0.48\", \"size\":\"1032.68\", \"side\":\"BUY\", \"hash\":\"cd6572c5a0a72ec8e6b64265203cb2d4a53d7af2\", \"best_bid\":\"0.54\", \"best_ask\":\"0.55\"}, {\"asset_id\":\"56108879726720646120583724001239294777304794469144970684362785767667828318889\", \"price\":\"0.52\", \"size\":\"1032.68\", \"side\":\"SELL\", \"hash\":\"1f663a93a1f13cfa962ee16f8a731cc62d1a5b28\", \"best_bid\":\"0.45\", \"best_ask\":\"0.46\"}], \"timestamp\":\"1781254836878\", \"event_type\":\"price_change\"}","ts_local_ms":1781254837474}
{"dir":"in","text":"{\"market\":\"0x9c535590faae21bf76fed844aa47fc3c5c82253ef38bd545bf12c93470502685\", \"price_changes\":[{\"asset_id\":\"107011546575057755426871645700605806081353395825571114128343592072429146374928\", \"price\":\"0.54\", \"size\":\"443.52\", \"side\":\"BUY\", \"hash\":\"7d99f8e9d76eadb3fe8b8be8c2bd32f5f985f985\", \"best_bid\":\"0.54\", \"best_ask\":\"0.55\"}, {\"asset_id\":\"56108879726720646120583724001239294777304794469144970684362785767667828318889\", \"price\":\"0.46\", \"size\":\"443.52\", \"side\":\"SELL\", \"hash\":\"56e3726b4768b275a5e28f26dbe96ee7edff2fdc\", \"best_bid\":\"0.45\", \"best_ask\":\"0.46\"}], \"timestamp\":\"1781254836879\", \"event_type\":\"price_change\"}","ts_local_ms":1781254837474}
{"dir":"in","text":"{\"market\":\"0x9c535590faae21bf76fed844aa47fc3c5c82253ef38bd545bf12c93470502685\", \"price_changes\":[{\"asset_id\":\"56108879726720646120583724001239294777304794469144970684362785767667828318889\", \"price\":\"0.38\", \"size\":\"291\", \"side\":\"BUY\", \"hash\":\"a0b4606be9d891d0091e8f934321578cf16b2110\", \"best_bid\":\"0.45\", \"best_ask\":\"0.46\"}, {\"asset_id\":\"107011546575057755426871645700605806081353395825571114128343592072429146374928\", \"price\":\"0.62\", \"size\":\"291\", \"side\":\"SELL\", \"hash\":\"7d52154687f7e205a8a437815b322ecc550ac98a\", \"best_bid\":\"0.54\", \"best_ask\":\"0.55\"}], \"timestamp\":\"1781254836880\", \"event_type\":\"price_change\"}","ts_local_ms":1781254837474}
{"dir":"in","text":"{\"market\":\"0x9c535590faae21bf76fed844aa47fc3c5c82253ef38bd545bf12c93470502685\", \"price_changes\":[{\"asset_id\":\"56108879726720646120583724001239294777304794469144970684362785767667828318889\", \"price\":\"0.45\", \"size\":\"579.53\", \"side\":\"BUY\", \"hash\":\"fb940f8a79e37bb096cf656306628c2448696cd6\", \"best_bid\":\"0.45\", \"best_ask\":\"0.46\"}, {\"asset_id\":\"107011546575057755426871645700605806081353395825571114128343592072429146374928\", \"price\":\"0.55\", \"size\":\"579.53\", \"side\":\"SELL\", \"hash\":\"b50e2f66609081ef5447a4742c328ee5bd8c4031\", \"best_bid\":\"0.54\", \"best_ask\":\"0.55\"}], \"timestamp\":\"1781254836880\", \"event_type\":\"price_change\"}","ts_local_ms":1781254837474}
{"dir":"in","text":"{\"market\":\"0x9c535590faae21bf76fed844aa47fc3c5c82253ef38bd545bf12c93470502685\", \"price_changes\":[{\"asset_id\":\"107011546575057755426871645700605806081353395825571114128343592072429146374928\", \"price\":\"0.01\", \"size\":\"54992.6\", \"side\":\"BUY\", \"hash\":\"3ec220b205b2913a4f9b83af2aed268051eb452e\", \"best_bid\":\"0.54\", \"best_ask\":\"0.55\"}, {\"asset_id\":\"56108879726720646120583724001239294777304794469144970684362785767667828318889\", \"price\":\"0.99\", \"size\":\"54992.6\", \"side\":\"SELL\", \"hash\":\"ee75d6c9f49aa22a6e0ae83b0048af87dcf5ed87\", \"best_bid\":\"0.45\", \"best_ask\":\"0.46\"}], \"timestamp\":\"1781254836880\", \"event_type\":\"price_change\"}","ts_local_ms":1781254837474}
{"dir":"in","text":"{\"market\":\"0x9c535590faae21bf76fed844aa47fc3c5c82253ef38bd545bf12c93470502685\", \"price_changes\":[{\"asset_id\":\"107011546575057755426871645700605806081353395825571114128343592072429146374928\", \"price\":\"0.43\", \"size\":\"141\", \"side\":\"BUY\", \"hash\":\"d0393b5b62a262ea6f72fa74c5d0ab6ac4b2c2bb\", \"best_bid\":\"0.54\", \"best_ask\":\"0.55\"}, {\"asset_id\":\"56108879726720646120583724001239294777304794469144970684362785767667828318889\", \"price\":\"0.57\", \"size\":\"141\", \"side\":\"SELL\", \"hash\":\"d309a9ad52f2303aa7d0f506541c33a35f29a59a\", \"best_bid\":\"0.45\", \"best_ask\":\"0.46\"}], \"timestamp\":\"1781254836880\", \"event_type\":\"price_change\"}","ts_local_ms":1781254837475}
{"dir":"in","text":"{\"market\":\"0x9c535590faae21bf76fed844aa47fc3c5c82253ef38bd545bf12c93470502685\", \"price_changes\":[{\"asset_id\":\"107011546575057755426871645700605806081353395825571114128343592072429146374928\", \"price\":\"0.54\", \"size\":\"448.52\", \"side\":\"BUY\", \"hash\":\"3194375d32eafdf9798def42aaaf918dab0296da\", \"best_bid\":\"0.54\", \"best_ask\":\"0.55\"}, {\"asset_id\":\"56108879726720646120583724001239294777304794469144970684362785767667828318889\", \"price\":\"0.46\", \"size\":\"448.52\", \"side\":\"SELL\", \"hash\":\"bccdedea4dc6c56d38ed50d036440de18227f51c\", \"best_bid\":\"0.45\", \"best_ask\":\"0.46\"}], \"timestamp\":\"1781254836881\", \"event_type\":\"price_change\"}","ts_local_ms":1781254837475}
{"dir":"in","text":"{\"market\":\"0x9c535590faae21bf76fed844aa47fc3c5c82253ef38bd545bf12c93470502685\", \"price_changes\":[{\"asset_id\":\"107011546575057755426871645700605806081353395825571114128343592072429146374928\", \"price\":\"0.54\", \"size\":\"457.52\", \"side\":\"BUY\", \"hash\":\"466d5f504f99243c62e0af9b5b8d33b25e58bddf\", \"best_bid\":\"0.54\", \"best_ask\":\"0.55\"}, {\"asset_id\":\"56108879726720646120583724001239294777304794469144970684362785767667828318889\", \"price\":\"0.46\", \"size\":\"457.52\", \"side\":\"SELL\", \"hash\":\"8139a63109b5f3441cac7eb56a935329068f6986\", \"best_bid\":\"0.45\", \"best_ask\":\"0.46\"}], \"timestamp\":\"1781254836881\", \"event_type\":\"price_change\"}","ts_local_ms":1781254837475}
{"dir":"in","text":"{\"market\":\"0x9c535590faae21bf76fed844aa47fc3c5c82253ef38bd545bf12c93470502685\", \"price_changes\":[{\"asset_id\":\"107011546575057755426871645700605806081353395825571114128343592072429146374928\", \"price\":\"0.5\", \"size\":\"308.08\", \"side\":\"BUY\", \"hash\":\"bc6380a5d3214a468ed8b5d43277ab4339dd16d8\", \"best_bid\":\"0.54\", \"best_ask\":\"0.55\"}, {\"asset_id\":\"56108879726720646120583724001239294777304794469144970684362785767667828318889\", \"price\":\"0.5\", \"size\":\"308.08\", \"side\":\"SELL\", \"hash\":\"8d4d1335c2748cf72cd8be87956e07be95cb0267\", \"best_bid\":\"0.45\", \"best_ask\":\"0.46\"}], \"timestamp\":\"1781254836882\", \"event_type\":\"price_change\"}","ts_local_ms":1781254837475}
{"dir":"in","text":"{\"market\":\"0x9c535590faae21bf76fed844aa47fc3c5c82253ef38bd545bf12c93470502685\", \"price_changes\":[{\"asset_id\":\"56108879726720646120583724001239294777304794469144970684362785767667828318889\", \"price\":\"0.45\", \"size\":\"572.53\", \"side\":\"BUY\", \"hash\":\"7bbf3ae531e7989c262d4bb78bcca16c0e7900e9\", \"best_bid\":\"0.45\", \"best_ask\":\"0.46\"}, {\"asset_id\":\"107011546575057755426871645700605806081353395825571114128343592072429146374928\", \"price\":\"0.55\", \"size\":\"572.53\", \"side\":\"SELL\", \"hash\":\"98de38a3e1931ce92fb3724ab2e9d0cd6368acfb\", \"best_bid\":\"0.54\", \"best_ask\":\"0.55\"}], \"timestamp\":\"1781254836883\", \"event_type\":\"price_change\"}","ts_local_ms":1781254837475}
{"dir":"in","text":"{\"market\":\"0x9c535590faae21bf76fed844aa47fc3c5c82253ef38bd545bf12c93470502685\", \"price_changes\":[{\"asset_id\":\"56108879726720646120583724001239294777304794469144970684362785767667828318889\", \"price\":\"0.32\", \"size\":\"228.22\", \"side\":\"BUY\", \"hash\":\"5afe6bc701458def6f1b5e845877959e84ca1087\", \"best_bid\":\"0.45\", \"best_ask\":\"0.46\"}, {\"asset_id\":\"107011546575057755426871645700605806081353395825571114128343592072429146374928\", \"price\":\"0.68\", \"size\":\"228.22\", \"side\":\"SELL\", \"hash\":\"78884f1d0d5d15b1763cd8dc80481c21092b752f\", \"best_bid\":\"0.54\", \"best_ask\":\"0.55\"}], \"timestamp\":\"1781254836883\", \"event_type\":\"price_change\"}","ts_local_ms":1781254837475}
{"dir":"in","text":"{\"market\":\"0x9c535590faae21bf76fed844aa47fc3c5c82253ef38bd545bf12c93470502685\", \"price_changes\":[{\"asset_id\":\"56108879726720646120583724001239294777304794469144970684362785767667828318889\", \"price\":\"0.41\", \"size\":\"132.72\", \"side\":\"BUY\", \"hash\":\"34e4653a5274cc8ee2015726139b680521e2b483\", \"best_bid\":\"0.45\", \"best_ask\":\"0.46\"}, {\"asset_id\":\"107011546575057755426871645700605806081353395825571114128343592072429146374928\", \"price\":\"0.59\", \"size\":\"132.72\", \"side\":\"SELL\", \"hash\":\"7213c06a12a9285c08227a5077b14dd32748423a\", \"best_bid\":\"0.54\", \"best_ask\":\"0.55\"}], \"timestamp\":\"1781254836884\", \"event_type\":\"price_change\"}","ts_local_ms":1781254837475}
{"dir":"in","text":"{\"market\":\"0x9c535590faae21bf76fed844aa47fc3c5c82253ef38bd545bf12c93470502685\", \"price_changes\":[{\"asset_id\":\"56108879726720646120583724001239294777304794469144970684362785767667828318889\", \"price\":\"0.45\", \"size\":\"565.53\", \"side\":\"BUY\", \"hash\":\"0a11bf2e47fa2bbed6e8ea472b5b2fda98d2aea7\", \"best_bid\":\"0.45\", \"best_ask\":\"0.46\"}, {\"asset_id\":\"107011546575057755426871645700605806081353395825571114128343592072429146374928\", \"price\":\"0.55\", \"size\":\"565.53\", \"side\":\"SELL\", \"hash\":\"d978b2d56e51eb19abf22b285068fe66bb864c76\", \"best_bid\":\"0.54\", \"best_ask\":\"0.55\"}], \"timestamp\":\"1781254836884\", \"event_type\":\"price_change\"}","ts_local_ms":1781254837475}
{"dir":"in","text":"{\"market\":\"0x9c535590faae21bf76fed844aa47fc3c5c82253ef38bd545bf12c93470502685\", \"price_changes\":[{\"asset_id\":\"56108879726720646120583724001239294777304794469144970684362785767667828318889\", \"price\":\"0.45\", \"size\":\"549.53\", \"side\":\"BUY\", \"hash\":\"0b61e25b9dca1eea52b8db32d62aadd7953fb681\", \"best_bid\":\"0.45\", \"best_ask\":\"0.46\"}, {\"asset_id\":\"107011546575057755426871645700605806081353395825571114128343592072429146374928\", \"price\":\"0.55\", \"size\":\"549.53\", \"side\":\"SELL\", \"hash\":\"ff8496e33eeeb4945cb1d2392182b971fc3ebfb3\", \"best_bid\":\"0.54\", \"best_ask\":\"0.55\"}], \"timestamp\":\"1781254836884\", \"event_type\":\"price_change\"}","ts_local_ms":1781254837475}
{"dir":"in","text":"{\"market\":\"0x9c535590faae21bf76fed844aa47fc3c5c82253ef38bd545bf12c93470502685\", \"price_changes\":[{\"asset_id\":\"107011546575057755426871645700605806081353395825571114128343592072429146374928\", \"price\":\"0.65\", \"size\":\"311\", \"side\":\"SELL\", \"hash\":\"01689a691a21d98799c7f085857fb9a414b0a5ed\", \"best_bid\":\"0.54\", \"best_ask\":\"0.55\"}, {\"asset_id\":\"56108879726720646120583724001239294777304794469144970684362785767667828318889\", \"price\":\"0.35\", \"size\":\"311\", \"side\":\"BUY\", \"hash\":\"60f91842ccd024c8378613e2a504d7c182b75201\", \"best_bid\":\"0.45\", \"best_ask\":\"0.46\"}], \"timestamp\":\"1781254836885\", \"event_type\":\"price_change\"}","ts_local_ms":1781254837475}
{"dir":"in","text":"{\"market\":\"0x9c535590faae21bf76fed844aa47fc3c5c82253ef38bd545bf12c93470502685\", \"price_changes\":[{\"asset_id\":\"56108879726720646120583724001239294777304794469144970684362785767667828318889\", \"price\":\"0.36\", \"size\":\"161\", \"side\":\"BUY\", \"hash\":\"a020eb536108838da441502ae86df940592b0b8f\", \"best_bid\":\"0.45\", \"best_ask\":\"0.46\"}, {\"asset_id\":\"107011546575057755426871645700605806081353395825571114128343592072429146374928\", \"price\":\"0.64\", \"size\":\"161\", \"side\":\"SELL\", \"hash\":\"4e7d942b0a6308bd2f5cedb6e9dee9ec43075e71\", \"best_bid\":\"0.54\", \"best_ask\":\"0.55\"}], \"timestamp\":\"1781254836885\", \"event_type\":\"price_change\"}","ts_local_ms":1781254837475}
{"dir":"in","text":"{\"market\":\"0x9c535590faae21bf76fed844aa47fc3c5c82253ef38bd545bf12c93470502685\", \"price_changes\":[{\"asset_id\":\"107011546575057755426871645700605806081353395825571114128343592072429146374928\", \"price\":\"0.52\", \"size\":\"111.37\", \"side\":\"BUY\", \"hash\":\"b9de74085fb0a3ead29465dd816efc7872c2ef5e\", \"best_bid\":\"0.54\", \"best_ask\":\"0.55\"}, {\"asset_id\":\"56108879726720646120583724001239294777304794469144970684362785767667828318889\", \"price\":\"0.48\", \"size\":\"111.37\", \"side\":\"SELL\", \"hash\":\"09d81e3cf15e92ea5ac96a3e0d5b6adc54652dbe\", \"best_bid\":\"0.45\", \"best_ask\":\"0.46\"}], \"timestamp\":\"1781254836886\", \"event_type\":\"price_change\"}","ts_local_ms":1781254837475}
{"dir":"in","text":"{\"market\":\"0x9c535590faae21bf76fed844aa47fc3c5c82253ef38bd545bf12c93470502685\", \"price_changes\":[{\"asset_id\":\"56108879726720646120583724001239294777304794469144970684362785767667828318889\", \"price\":\"0.45\", \"size\":\"542.53\", \"side\":\"BUY\", \"hash\":\"99395a7ccb5efbef759a902f9c8ffc6146ee2c65\", \"best_bid\":\"0.45\", \"best_ask\":\"0.46\"}, {\"asset_id\":\"107011546575057755426871645700605806081353395825571114128343592072429146374928\", \"price\":\"0.55\", \"size\":\"542.53\", \"side\":\"SELL\", \"hash\":\"d70931e392fd68148e787cbb16f781513f43a20f\", \"best_bid\":\"0.54\", \"best_ask\":\"0.55\"}], \"timestamp\":\"1781254836886\", \"event_type\":\"price_change\"}","ts_local_ms":1781254837475}
{"dir":"in","text":"{\"market\":\"0x9c535590faae21bf76fed844aa47fc3c5c82253ef38bd545bf12c93470502685\", \"price_changes\":[{\"asset_id\":\"107011546575057755426871645700605806081353395825571114128343592072429146374928\", \"price\":\"0.65\", \"size\":\"316\", \"side\":\"SELL\", \"hash\":\"e6f787a60bbc76d1eddfdef1bdcdd49d38c07244\", \"best_bid\":\"0.54\", \"best_ask\":\"0.55\"}, {\"asset_id\":\"56108879726720646120583724001239294777304794469144970684362785767667828318889\", \"price\":\"0.35\", \"size\":\"316\", \"side\":\"BUY\", \"hash\":\"d47231a4c36bda5d92724e538af4e9bc5bb5d344\", \"best_bid\":\"0.45\", \"best_ask\":\"0.46\"}], \"timestamp\":\"1781254836886\", \"event_type\":\"price_change\"}","ts_local_ms":1781254837475}
{"dir":"in","text":"{\"market\":\"0x9c535590faae21bf76fed844aa47fc3c5c82253ef38bd545bf12c93470502685\", \"price_changes\":[{\"asset_id\":\"107011546575057755426871645700605806081353395825571114128343592072429146374928\", \"price\":\"0.54\", \"size\":\"462.52\", \"side\":\"BUY\", \"hash\":\"afd9f0038fbe25876906b19ba47bda8d85c4632e\", \"best_bid\":\"0.54\", \"best_ask\":\"0.55\"}, {\"asset_id\":\"56108879726720646120583724001239294777304794469144970684362785767667828318889\", \"price\":\"0.46\", \"size\":\"462.52\", \"side\":\"SELL\", \"hash\":\"91729dceade6c45598b4a60d4c40abaafe2451d9\", \"best_bid\":\"0.45\", \"best_ask\":\"0.46\"}], \"timestamp\":\"1781254836887\", \"event_type\":\"price_change\"}","ts_local_ms":1781254837475}
{"dir":"in","text":"{\"market\":\"0x9c535590faae21bf76fed844aa47fc3c5c82253ef38bd545bf12c93470502685\", \"price_changes\":[{\"asset_id\":\"56108879726720646120583724001239294777304794469144970684362785767667828318889\", \"price\":\"0.45\", \"size\":\"534.53\", \"side\":\"BUY\", \"hash\":\"fc415966096a09ebd7913634172d40b15258ada3\", \"best_bid\":\"0.45\", \"best_ask\":\"0.46\"}, {\"asset_id\":\"107011546575057755426871645700605806081353395825571114128343592072429146374928\", \"price\":\"0.55\", \"size\":\"534.53\", \"side\":\"SELL\", \"hash\":\"e0169bf05bcb92d3db6a0ab84da09538ab6bb0fd\", \"best_bid\":\"0.54\", \"best_ask\":\"0.55\"}], \"timestamp\":\"1781254836888\", \"event_type\":\"price_change\"}","ts_local_ms":1781254837475}
{"dir":"in","text":"{\"market\":\"0x9c535590faae21bf76fed844aa47fc3c5c82253ef38bd545bf12c93470502685\", \"price_changes\":[{\"asset_id\":\"56108879726720646120583724001239294777304794469144970684362785767667828318889\", \"price\":\"0.32\", \"size\":\"236.64\", \"side\":\"BUY\", \"hash\":\"97e576501f6b9f32ec52fd8812b19750cc700e6e\", \"best_bid\":\"0.45\", \"best_ask\":\"0.46\"}, {\"asset_id\":\"107011546575057755426871645700605806081353395825571114128343592072429146374928\", \"price\":\"0.68\", \"size\":\"236.64\", \"side\":\"SELL\", \"hash\":\"adb553b7f7aaa7af544b4f82e4830aeda0d91981\", \"best_bid\":\"0.54\", \"best_ask\":\"0.55\"}], \"timestamp\":\"1781254836888\", \"event_type\":\"price_change\"}","ts_local_ms":1781254837475}
{"dir":"in","text":"{\"market\":\"0x9c535590faae21bf76fed844aa47fc3c5c82253ef38bd545bf12c93470502685\", \"price_changes\":[{\"asset_id\":\"107011546575057755426871645700605806081353395825571114128343592072429146374928\", \"price\":\"0.48\", \"size\":\"1057.68\", \"side\":\"BUY\", \"hash\":\"42dc12a80308d4b8c0c6bf0da4979dd41529b462\", \"best_bid\":\"0.54\", \"best_ask\":\"0.55\"}, {\"asset_id\":\"56108879726720646120583724001239294777304794469144970684362785767667828318889\", \"price\":\"0.52\", \"size\":\"1057.68\", \"side\":\"SELL\", \"hash\":\"f4b90adcd443d404680ee248a6f782f3e84cdbe2\", \"best_bid\":\"0.45\", \"best_ask\":\"0.46\"}], \"timestamp\":\"1781254836888\", \"event_type\":\"price_change\"}","ts_local_ms":1781254837475}
{"dir":"in","text":"{\"market\":\"0x9c535590faae21bf76fed844aa47fc3c5c82253ef38bd545bf12c93470502685\", \"price_changes\":[{\"asset_id\":\"56108879726720646120583724001239294777304794469144970684362785767667828318889\", \"price\":\"0.36\", \"size\":\"166\", \"side\":\"BUY\", \"hash\":\"02dd0984619e2525088bbf0fb7af502337b5e986\", \"best_bid\":\"0.45\", \"best_ask\":\"0.46\"}, {\"asset_id\":\"107011546575057755426871645700605806081353395825571114128343592072429146374928\", \"price\":\"0.64\", \"size\":\"166\", \"side\":\"SELL\", \"hash\":\"42b702c3a690a32e49fe6b99cda837cb7ac143ea\", \"best_bid\":\"0.54\", \"best_ask\":\"0.55\"}], \"timestamp\":\"1781254836889\", \"event_type\":\"price_change\"}","ts_local_ms":1781254837475}
{"dir":"in","text":"{\"market\":\"0x9c535590faae21bf76fed844aa47fc3c5c82253ef38bd545bf12c93470502685\", \"price_changes\":[{\"asset_id\":\"107011546575057755426871645700605806081353395825571114128343592072429146374928\", \"price\":\"0.51\", \"size\":\"153.59\", \"side\":\"BUY\", \"hash\":\"b50ed2b11402a6a88371eddb8476fb089b6f50e9\", \"best_bid\":\"0.54\", \"best_ask\":\"0.55\"}, {\"asset_id\":\"56108879726720646120583724001239294777304794469144970684362785767667828318889\", \"price\":\"0.49\", \"size\":\"153.59\", \"side\":\"SELL\", \"hash\":\"c981cd4982b7368bcd92780909e78e2689b3237f\", \"best_bid\":\"0.45\", \"best_ask\":\"0.46\"}], \"timestamp\":\"1781254836890\", \"event_type\":\"price_change\"}","ts_local_ms":1781254837475}
{"dir":"in","text":"{\"market\":\"0x9c535590faae21bf76fed844aa47fc3c5c82253ef38bd545bf12c93470502685\", \"price_changes\":[{\"asset_id\":\"107011546575057755426871645700605806081353395825571114128343592072429146374928\", \"price\":\"0.54\", \"size\":\"467.52\", \"side\":\"BUY\", \"hash\":\"7732b160d43c6c29d3813e35b9faba8c82560620\", \"best_bid\":\"0.54\", \"best_ask\":\"0.55\"}, {\"asset_id\":\"56108879726720646120583724001239294777304794469144970684362785767667828318889\", \"price\":\"0.46\", \"size\":\"467.52\", \"side\":\"SELL\", \"hash\":\"0a92894945c7fb5d5b3ed97ddaf5d2e672efc689\", \"best_bid\":\"0.45\", \"best_ask\":\"0.46\"}], \"timestamp\":\"1781254836890\", \"event_type\":\"price_change\"}","ts_local_ms":1781254837475}
{"dir":"in","text":"{\"market\":\"0x9c535590faae21bf76fed844aa47fc3c5c82253ef38bd545bf12c93470502685\", \"price_changes\":[{\"asset_id\":\"107011546575057755426871645700605806081353395825571114128343592072429146374928\", \"price\":\"0.32\", \"size\":\"87\", \"side\":\"BUY\", \"hash\":\"b5a332230d0419f44774f6ce2c055dba9703074b\", \"best_bid\":\"0.54\", \"best_ask\":\"0.55\"}, {\"asset_id\":\"56108879726720646120583724001239294777304794469144970684362785767667828318889\", \"price\":\"0.68\", \"size\":\"87\", \"side\":\"SELL\", \"hash\":\"d224edb5888cbca3b6f6e605c409a51adadf5cc0\", \"best_bid\":\"0.45\", \"best_ask\":\"0.46\"}], \"timestamp\":\"1781254836891\", \"event_type\":\"price_change\"}","ts_local_ms":1781254837475}
{"dir":"in","text":"{\"market\":\"0x9c535590faae21bf76fed844aa47fc3c5c82253ef38bd545bf12c93470502685\", \"price_changes\":[{\"asset_id\":\"107011546575057755426871645700605806081353395825571114128343592072429146374928\", \"price\":\"0.54\", \"size\":\"472.52\", \"side\":\"BUY\", \"hash\":\"d1284cb640f461597aaf75d5fac433633c5f8ea8\", \"best_bid\":\"0.54\", \"best_ask\":\"0.55\"}, {\"asset_id\":\"56108879726720646120583724001239294777304794469144970684362785767667828318889\", \"price\":\"0.46\", \"size\":\"472.52\", \"side\":\"SELL\", \"hash\":\"c966b91474dc54a01f33531d9c04c6583b65fa02\", \"best_bid\":\"0.45\", \"best_ask\":\"0.46\"}], \"timestamp\":\"1781254836891\", \"event_type\":\"price_change\"}","ts_local_ms":1781254837475}
{"dir":"in","text":"{\"market\":\"0x9c535590faae21bf76fed844aa47fc3c5c82253ef38bd545bf12c93470502685\", \"price_changes\":[{\"asset_id\":\"107011546575057755426871645700605806081353395825571114128343592072429146374928\", \"price\":\"0.47\", \"size\":\"222.19\", \"side\":\"BUY\", \"hash\":\"083ffa5ab71a634e4ff4298c289f6cee0b1daa7f\", \"best_bid\":\"0.54\", \"best_ask\":\"0.55\"}, {\"asset_id\":\"56108879726720646120583724001239294777304794469144970684362785767667828318889\", \"price\":\"0.53\", \"size\":\"222.19\", \"side\":\"SELL\", \"hash\":\"fa93c6a41e16f7088aa18e18065d6e509697781e\", \"best_bid\":\"0.45\", \"best_ask\":\"0.46\"}], \"timestamp\":\"1781254836892\", \"event_type\":\"price_change\"}","ts_local_ms":1781254837475}
{"dir":"in","text":"{\"market\":\"0x9c535590faae21bf76fed844aa47fc3c5c82253ef38bd545bf12c93470502685\", \"price_changes\":[{\"asset_id\":\"56108879726720646120583724001239294777304794469144970684362785767667828318889\", \"price\":\"0.33\", \"size\":\"213\", \"side\":\"BUY\", \"hash\":\"3a51be2d435f9102778d2be5a5d48c735026f486\", \"best_bid\":\"0.45\", \"best_ask\":\"0.46\"}, {\"asset_id\":\"107011546575057755426871645700605806081353395825571114128343592072429146374928\", \"price\":\"0.67\", \"size\":\"213\", \"side\":\"SELL\", \"hash\":\"87be478d43842c3a271e4150157c1999aac5edf6\", \"best_bid\":\"0.54\", \"best_ask\":\"0.55\"}], \"timestamp\":\"1781254836893\", \"event_type\":\"price_change\"}","ts_local_ms":1781254837475}
{"dir":"in","text":"{\"market\":\"0x9c535590faae21bf76fed844aa47fc3c5c82253ef38bd545bf12c93470502685\", \"price_changes\":[{\"asset_id\":\"56108879726720646120583724001239294777304794469144970684362785767667828318889\", \"price\":\"0.32\", \"size\":\"226.64\", \"side\":\"BUY\", \"hash\":\"3a51be2d435f9102778d2be5a5d48c735026f486\", \"best_bid\":\"0.45\", \"best_ask\":\"0.46\"}, {\"asset_id\":\"107011546575057755426871645700605806081353395825571114128343592072429146374928\", \"price\":\"0.68\", \"size\":\"226.64\", \"side\":\"SELL\", \"hash\":\"87be478d43842c3a271e4150157c1999aac5edf6\", \"best_bid\":\"0.54\", \"best_ask\":\"0.55\"}], \"timestamp\":\"1781254836893\", \"event_type\":\"price_change\"}","ts_local_ms":1781254837475}
{"dir":"in","text":"{\"market\":\"0x9c535590faae21bf76fed844aa47fc3c5c82253ef38bd545bf12c93470502685\", \"price_changes\":[{\"asset_id\":\"107011546575057755426871645700605806081353395825571114128343592072429146374928\", \"price\":\"0.54\", \"size\":\"477.52\", \"side\":\"BUY\", \"hash\":\"105574f707f7ea3775a17214143f1e0ba43fa14a\", \"best_bid\":\"0.54\", \"best_ask\":\"0.55\"}, {\"asset_id\":\"56108879726720646120583724001239294777304794469144970684362785767667828318889\", \"price\":\"0.46\", \"size\":\"477.52\", \"side\":\"SELL\", \"hash\":\"cf325d3a5408f6795d4963e866eae8dcc5886f46\", \"best_bid\":\"0.45\", \"best_ask\":\"0.46\"}], \"timestamp\":\"1781254836893\", \"event_type\":\"price_change\"}","ts_local_ms":1781254837476}
{"dir":"in","text":"{\"market\":\"0x9c535590faae21bf76fed844aa47fc3c5c82253ef38bd545bf12c93470502685\", \"price_changes\":[{\"asset_id\":\"107011546575057755426871645700605806081353395825571114128343592072429146374928\", \"price\":\"0.5\", \"size\":\"383.08\", \"side\":\"BUY\", \"hash\":\"2d5e2da4e95b82d576e645980d60621bcd1560f6\", \"best_bid\":\"0.54\", \"best_ask\":\"0.55\"}, {\"asset_id\":\"56108879726720646120583724001239294777304794469144970684362785767667828318889\", \"price\":\"0.5\", \"size\":\"383.08\", \"side\":\"SELL\", \"hash\":\"1f64258ca63dfbcd4fd83e388762cb898bde9f5b\", \"best_bid\":\"0.45\", \"best_ask\":\"0.46\"}], \"timestamp\":\"1781254836894\", \"event_type\":\"price_change\"}","ts_local_ms":1781254837476}
{"dir":"in","text":"{\"market\":\"0x9c535590faae21bf76fed844aa47fc3c5c82253ef38bd545bf12c93470502685\", \"price_changes\":[{\"asset_id\":\"107011546575057755426871645700605806081353395825571114128343592072429146374928\", \"price\":\"0.54\", \"size\":\"488.52\", \"side\":\"BUY\", \"hash\":\"41468d01f9236dcc0d1b56110da31281ef433cd9\", \"best_bid\":\"0.54\", \"best_ask\":\"0.55\"}, {\"asset_id\":\"56108879726720646120583724001239294777304794469144970684362785767667828318889\", \"price\":\"0.46\", \"size\":\"488.52\", \"side\":\"SELL\", \"hash\":\"d577d4551cba3ca806c9b7b19f90dc65e3743cc8\", \"best_bid\":\"0.45\", \"best_ask\":\"0.46\"}], \"timestamp\":\"1781254836895\", \"event_type\":\"price_change\"}","ts_local_ms":1781254837476}
{"dir":"in","text":"{\"market\":\"0x9c535590faae21bf76fed844aa47fc3c5c82253ef38bd545bf12c93470502685\", \"price_changes\":[{\"asset_id\":\"107011546575057755426871645700605806081353395825571114128343592072429146374928\", \"price\":\"0.54\", \"size\":\"497.52\", \"side\":\"BUY\", \"hash\":\"ae9c8257de8c2796e93631eef62c59a9845fb1eb\", \"best_bid\":\"0.54\", \"best_ask\":\"0.55\"}, {\"asset_id\":\"56108879726720646120583724001239294777304794469144970684362785767667828318889\", \"price\":\"0.46\", \"size\":\"497.52\", \"side\":\"SELL\", \"hash\":\"8049869654ea54829462dbe7e28c4a1a80e4a397\", \"best_bid\":\"0.45\", \"best_ask\":\"0.46\"}], \"timestamp\":\"1781254836896\", \"event_type\":\"price_change\"}","ts_local_ms":1781254837476}
{"dir":"in","text":"{\"market\":\"0x9c535590faae21bf76fed844aa47fc3c5c82253ef38bd545bf12c93470502685\", \"price_changes\":[{\"asset_id\":\"56108879726720646120583724001239294777304794469144970684362785767667828318889\", \"price\":\"0.32\", \"size\":\"219.42\", \"side\":\"BUY\", \"hash\":\"0990069a44ceacaaf9275d93920faae73764e7d5\", \"best_bid\":\"0.45\", \"best_ask\":\"0.46\"}, {\"asset_id\":\"107011546575057755426871645700605806081353395825571114128343592072429146374928\", \"price\":\"0.68\", \"size\":\"219.42\", \"side\":\"SELL\", \"hash\":\"a2c7e240b76325e2ef72a7189d7422ccef67ede1\", \"best_bid\":\"0.54\", \"best_ask\":\"0.55\"}], \"timestamp\":\"1781254836897\", \"event_type\":\"price_change\"}","ts_local_ms":1781254837476}
{"dir":"in","text":"{\"market\":\"0x9c535590faae21bf76fed844aa47fc3c5c82253ef38bd545bf12c93470502685\", \"price_changes\":[{\"asset_id\":\"107011546575057755426871645700605806081353395825571114128343592072429146374928\", \"price\":\"0.54\", \"size\":\"508.52\", \"side\":\"BUY\", \"hash\":\"d4681a00446737256e1dbb3804c9bf59f6c8bd05\", \"best_bid\":\"0.54\", \"best_ask\":\"0.55\"}, {\"asset_id\":\"56108879726720646120583724001239294777304794469144970684362785767667828318889\", \"price\":\"0.46\", \"size\":\"508.52\", \"side\":\"SELL\", \"hash\":\"e78d90955839a4c060d3720df4b5585279c5e3a8\", \"best_bid\":\"0.45\", \"best_ask\":\"0.46\"}], \"timestamp\":\"1781254836898\", \"event_type\":\"price_change\"}","ts_local_ms":1781254837476}
{"dir":"in","text":"{\"market\":\"0x9c535590faae21bf76fed844aa47fc3c5c82253ef38bd545bf12c93470502685\", \"price_changes\":[{\"asset_id\":\"107011546575057755426871645700605806081353395825571114128343592072429146374928\", \"price\":\"0.54\", \"size\":\"503.52\", \"side\":\"BUY\", \"hash\":\"d05f45a28c07375def94513d853a54996925c571\", \"best_bid\":\"0.54\", \"best_ask\":\"0.55\"}, {\"asset_id\":\"56108879726720646120583724001239294777304794469144970684362785767667828318889\", \"price\":\"0.46\", \"size\":\"503.52\", \"side\":\"SELL\", \"hash\":\"ec80d0e0d7bf2a9b514e0944f99e7437ca1f6063\", \"best_bid\":\"0.45\", \"best_ask\":\"0.46\"}], \"timestamp\":\"1781254836898\", \"event_type\":\"price_change\"}","ts_local_ms":1781254837476}
{"dir":"in","text":"{\"market\":\"0x9c535590faae21bf76fed844aa47fc3c5c82253ef38bd545bf12c93470502685\", \"price_changes\":[{\"asset_id\":\"107011546575057755426871645700605806081353395825571114128343592072429146374928\", \"price\":\"0.53\", \"size\":\"92.63\", \"side\":\"BUY\", \"hash\":\"de7758f7d8442e0166abafd11100cf8b56b00cac\", \"best_bid\":\"0.54\", \"best_ask\":\"0.55\"}, {\"asset_id\":\"56108879726720646120583724001239294777304794469144970684362785767667828318889\", \"price\":\"0.47\", \"size\":\"92.63\", \"side\":\"SELL\", \"hash\":\"3677f608dfe570f4d3001a55b5a642040ba7f714\", \"best_bid\":\"0.45\", \"best_ask\":\"0.46\"}], \"timestamp\":\"1781254836899\", \"event_type\":\"price_change\"}","ts_local_ms":1781254837476}
{"dir":"in","text":"{\"market\":\"0x9c535590faae21bf76fed844aa47fc3c5c82253ef38bd545bf12c93470502685\", \"price_changes\":[{\"asset_id\":\"107011546575057755426871645700605806081353395825571114128343592072429146374928\", \"price\":\"0.47\", \"size\":\"227.19\", \"side\":\"BUY\", \"hash\":\"b7fad0001f7b0410ecfe67e3062d4527c73ae165\", \"best_bid\":\"0.54\", \"best_ask\":\"0.55\"}, {\"asset_id\":\"56108879726720646120583724001239294777304794469144970684362785767667828318889\", \"price\":\"0.53\", \"size\":\"227.19\", \"side\":\"SELL\", \"hash\":\"bf8593fdfab24c38ebba111357f608d2ac229f7d\", \"best_bid\":\"0.45\", \"best_ask\":\"0.46\"}], \"timestamp\":\"1781254836900\", \"event_type\":\"price_change\"}","ts_local_ms":1781254837476}
{"dir":"in","text":"{\"market\":\"0x9c535590faae21bf76fed844aa47fc3c5c82253ef38bd545bf12c93470502685\", \"price_changes\":[{\"asset_id\":\"56108879726720646120583724001239294777304794469144970684362785767667828318889\", \"price\":\"0.45\", \"size\":\"528.15\", \"side\":\"BUY\", \"hash\":\"6efd9d8bc186b857d1ec713dbfcc9c7e7966e634\", \"best_bid\":\"0.45\", \"best_ask\":\"0.46\"}, {\"asset_id\":\"107011546575057755426871645700605806081353395825571114128343592072429146374928\", \"price\":\"0.55\", \"size\":\"528.15\", \"side\":\"SELL\", \"hash\":\"40cc8e4117eed1b8f819158d3fd275d8847f275a\", \"best_bid\":\"0.54\", \"best_ask\":\"0.55\"}], \"timestamp\":\"1781254836900\", \"event_type\":\"price_change\"}","ts_local_ms":1781254837476}
{"dir":"in","text":"{\"market\":\"0x9c535590faae21bf76fed844aa47fc3c5c82253ef38bd545bf12c93470502685\", \"price_changes\":[{\"asset_id\":\"56108879726720646120583724001239294777304794469144970684362785767667828318889\", \"price\":\"0.42\", \"size\":\"136.2\", \"side\":\"BUY\", \"hash\":\"21974347871fc6f5ffb845352883a0384c126096\", \"best_bid\":\"0.45\", \"best_ask\":\"0.46\"}, {\"asset_id\":\"107011546575057755426871645700605806081353395825571114128343592072429146374928\", \"price\":\"0.58\", \"size\":\"136.2\", \"side\":\"SELL\", \"hash\":\"41f83119d1be44edca3478d5e48fccce087a0c55\", \"best_bid\":\"0.54\", \"best_ask\":\"0.55\"}], \"timestamp\":\"1781254836901\", \"event_type\":\"price_change\"}","ts_local_ms":1781254837476}
{"dir":"in","text":"{\"market\":\"0x9c535590faae21bf76fed844aa47fc3c5c82253ef38bd545bf12c93470502685\", \"price_changes\":[{\"asset_id\":\"56108879726720646120583724001239294777304794469144970684362785767667828318889\", \"price\":\"0.45\", \"size\":\"513.15\", \"side\":\"BUY\", \"hash\":\"7cabd382a4425f2a11cad7dca6411ad68dfe9700\", \"best_bid\":\"0.45\", \"best_ask\":\"0.46\"}, {\"asset_id\":\"107011546575057755426871645700605806081353395825571114128343592072429146374928\", \"price\":\"0.55\", \"size\":\"513.15\", \"side\":\"SELL\", \"hash\":\"f33c247f15c13f61c9022a6f4b37766948ddd8e6\", \"best_bid\":\"0.54\", \"best_ask\":\"0.55\"}], \"timestamp\":\"1781254836902\", \"event_type\":\"price_change\"}","ts_local_ms":1781254837476}
{"dir":"in","text":"{\"market\":\"0x9c535590faae21bf76fed844aa47fc3c5c82253ef38bd545bf12c93470502685\", \"price_changes\":[{\"asset_id\":\"107011546575057755426871645700605806081353395825571114128343592072429146374928\", \"price\":\"0.01\", \"size\":\"54997.6\", \"side\":\"BUY\", \"hash\":\"8aec9223cd97b07c181c4fb8cc3aaf8260b49c5f\", \"best_bid\":\"0.54\", \"best_ask\":\"0.55\"}, {\"asset_id\":\"56108879726720646120583724001239294777304794469144970684362785767667828318889\", \"price\":\"0.99\", \"size\":\"54997.6\", \"side\":\"SELL\", \"hash\":\"175251cfd9af0f5713b983f48410c51f35925b30\", \"best_bid\":\"0.45\", \"best_ask\":\"0.46\"}], \"timestamp\":\"1781254836902\", \"event_type\":\"price_change\"}","ts_local_ms":1781254837476}
{"dir":"in","text":"{\"market\":\"0x9c535590faae21bf76fed844aa47fc3c5c82253ef38bd545bf12c93470502685\", \"price_changes\":[{\"asset_id\":\"56108879726720646120583724001239294777304794469144970684362785767667828318889\", \"price\":\"0.27\", \"size\":\"118.11\", \"side\":\"BUY\", \"hash\":\"0052dee256f7d6e4ab96a8a2c6bc2b52bc42b32d\", \"best_bid\":\"0.45\", \"best_ask\":\"0.46\"}, {\"asset_id\":\"107011546575057755426871645700605806081353395825571114128343592072429146374928\", \"price\":\"0.73\", \"size\":\"118.11\", \"side\":\"SELL\", \"hash\":\"2c77aa6e282593cd6b49d38a3f5c4fbce2cedaf1\", \"best_bid\":\"0.54\", \"best_ask\":\"0.55\"}], \"timestamp\":\"1781254836903\", \"event_type\":\"price_change\"}","ts_local_ms":1781254837476}
{"dir":"in","text":"{\"market\":\"0x9c535590faae21bf76fed844aa47fc3c5c82253ef38bd545bf12c93470502685\", \"price_changes\":[{\"asset_id\":\"107011546575057755426871645700605806081353395825571114128343592072429146374928\", \"price\":\"0.46\", \"size\":\"347.36\", \"side\":\"BUY\", \"hash\":\"b707f13d076c30f7c3d7057b51ee7d17a2bc6692\", \"best_bid\":\"0.54\", \"best_ask\":\"0.55\"}, {\"asset_id\":\"56108879726720646120583724001239294777304794469144970684362785767667828318889\", \"price\":\"0.54\", \"size\":\"347.36\", \"side\":\"SELL\", \"hash\":\"e711928cdbaae7fbdfff164bb5b18c6a0837e0ea\", \"best_bid\":\"0.45\", \"best_ask\":\"0.46\"}], \"timestamp\":\"1781254836903\", \"event_type\":\"price_change\"}","ts_local_ms":1781254837476}
{"dir":"in","text":"{\"market\":\"0x9c535590faae21bf76fed844aa47fc3c5c82253ef38bd545bf12c93470502685\", \"price_changes\":[{\"asset_id\":\"56108879726720646120583724001239294777304794469144970684362785767667828318889\", \"price\":\"0.36\", \"size\":\"141\", \"side\":\"BUY\", \"hash\":\"674a7194067f74a339cae3d9b8f3468df64c9582\", \"best_bid\":\"0.45\", \"best_ask\":\"0.46\"}, {\"asset_id\":\"107011546575057755426871645700605806081353395825571114128343592072429146374928\", \"price\":\"0.64\", \"size\":\"141\", \"side\":\"SELL\", \"hash\":\"6923df94d38a4f8c13185b0d73c66e48739d99db\", \"best_bid\":\"0.54\", \"best_ask\":\"0.55\"}], \"timestamp\":\"1781254836904\", \"event_type\":\"price_change\"}","ts_local_ms":1781254837476}
{"dir":"in","text":"{\"market\":\"0x9c535590faae21bf76fed844aa47fc3c5c82253ef38bd545bf12c93470502685\", \"price_changes\":[{\"asset_id\":\"56108879726720646120583724001239294777304794469144970684362785767667828318889\", \"price\":\"0.39\", \"size\":\"461\", \"side\":\"BUY\", \"hash\":\"879de9b7567ec5f59f5504b4366736d060c7d933\", \"best_bid\":\"0.45\", \"best_ask\":\"0.46\"}, {\"asset_id\":\"107011546575057755426871645700605806081353395825571114128343592072429146374928\", \"price\":\"0.61\", \"size\":\"461\", \"side\":\"SELL\", \"hash\":\"1a9bf778f4260fe3f5f7a30c2aa37df51318384a\", \"best_bid\":\"0.54\", \"best_ask\":\"0.55\"}], \"timestamp\":\"1781254836904\", \"event_type\":\"price_change\"}","ts_local_ms":1781254837476}
{"dir":"in","text":"{\"market\":\"0x9c535590faae21bf76fed844aa47fc3c5c82253ef38bd545bf12c93470502685\", \"price_changes\":[{\"asset_id\":\"56108879726720646120583724001239294777304794469144970684362785767667828318889\", \"price\":\"0.39\", \"size\":\"476\", \"side\":\"BUY\", \"hash\":\"3cdcc05273693ba95fddc6841e2aad269375f416\", \"best_bid\":\"0.45\", \"best_ask\":\"0.46\"}, {\"asset_id\":\"107011546575057755426871645700605806081353395825571114128343592072429146374928\", \"price\":\"0.61\", \"size\":\"476\", \"side\":\"SELL\", \"hash\":\"f579841e12e7fc450939e9947bf6ceb4881e24a3\", \"best_bid\":\"0.54\", \"best_ask\":\"0.55\"}], \"timestamp\":\"1781254836905\", \"event_type\":\"price_change\"}","ts_local_ms":1781254837476}
{"dir":"in","text":"{\"market\":\"0x9c535590faae21bf76fed844aa47fc3c5c82253ef38bd545bf12c93470502685\", \"price_changes\":[{\"asset_id\":\"56108879726720646120583724001239294777304794469144970684362785767667828318889\", \"price\":\"0.45\", \"size\":\"518.15\", \"side\":\"BUY\", \"hash\":\"1e304f8e92f299dec7efbf4cb60d74e25c275d2e\", \"best_bid\":\"0.45\", \"best_ask\":\"0.46\"}, {\"asset_id\":\"107011546575057755426871645700605806081353395825571114128343592072429146374928\", \"price\":\"0.55\", \"size\":\"518.15\", \"side\":\"SELL\", \"hash\":\"1369f5fe7795eef519b56ca4368fc0b95f0186af\", \"best_bid\":\"0.54\", \"best_ask\":\"0.55\"}], \"timestamp\":\"1781254836905\", \"event_type\":\"price_change\"}","ts_local_ms":1781254837476}
{"dir":"in","text":"{\"market\":\"0x9c535590faae21bf76fed844aa47fc3c5c82253ef38bd545bf12c93470502685\", \"price_changes\":[{\"asset_id\":\"56108879726720646120583724001239294777304794469144970684362785767667828318889\", \"price\":\"0.41\", \"size\":\"126\", \"side\":\"BUY\", \"hash\":\"fb5a9d384c3546a625c49a977a70593538bb77b2\", \"best_bid\":\"0.45\", \"best_ask\":\"0.46\"}, {\"asset_id\":\"107011546575057755426871645700605806081353395825571114128343592072429146374928\", \"price\":\"0.59\", \"size\":\"126\", \"side\":\"SELL\", \"hash\":\"0cac0798203354d8f09ec711a415742cab33758f\", \"best_bid\":\"0.54\", \"best_ask\":\"0.55\"}], \"timestamp\":\"1781254836906\", \"event_type\":\"price_change\"}","ts_local_ms":1781254837476}
{"dir":"in","text":"{\"market\":\"0x9c535590faae21bf76fed844aa47fc3c5c82253ef38bd545bf12c93470502685\", \"price_changes\":[{\"asset_id\":\"107011546575057755426871645700605806081353395825571114128343592072429146374928\", \"price\":\"0.01\", \"size\":\"54991.6\", \"side\":\"BUY\", \"hash\":\"3558c31303cb2a67d3c3ed522ea22182b635f091\", \"best_bid\":\"0.54\", \"best_ask\":\"0.55\"}, {\"asset_id\":\"56108879726720646120583724001239294777304794469144970684362785767667828318889\", \"price\":\"0.99\", \"size\":\"54991.6\", \"side\":\"SELL\", \"hash\":\"89256523bfdd7e7a325a4113d14de1910fa31d53\", \"best_bid\":\"0.45\", \"best_ask\":\"0.46\"}], \"timestamp\":\"1781254836906\", \"event_type\":\"price_change\"}","ts_local_ms":1781254837476}
{"dir":"in","text":"{\"market\":\"0x9c535590faae21bf76fed844aa47fc3c5c82253ef38bd545bf12c93470502685\", \"price_changes\":[{\"asset_id\":\"56108879726720646120583724001239294777304794469144970684362785767667828318889\", \"price\":\"0.37\", \"size\":\"372.04\", \"side\":\"BUY\", \"hash\":\"6a818c33a5c1104a82ff5bd9f9d4b6af5b118385\", \"best_bid\":\"0.45\", \"best_ask\":\"0.46\"}, {\"asset_id\":\"107011546575057755426871645700605806081353395825571114128343592072429146374928\", \"price\":\"0.63\", \"size\":\"372.04\", \"side\":\"SELL\", \"hash\":\"3c48c297021b930166e96feef7e2172084946141\", \"best_bid\":\"0.54\", \"best_ask\":\"0.55\"}], \"timestamp\":\"1781254836906\", \"event_type\":\"price_change\"}","ts_local_ms":1781254837476}
{"dir":"in","text":"{\"market\":\"0x9c535590faae21bf76fed844aa47fc3c5c82253ef38bd545bf12c93470502685\", \"price_changes\":[{\"asset_id\":\"56108879726720646120583724001239294777304794469144970684362785767667828318889\", \"price\":\"0.43\", \"size\":\"173\", \"side\":\"BUY\", \"hash\":\"8f4764ecdd3f0b078a6bd73e9bccb1673d7eb8cd\", \"best_bid\":\"0.45\", \"best_ask\":\"0.46\"}, {\"asset_id\":\"107011546575057755426871645700605806081353395825571114128343592072429146374928\", \"price\":\"0.57\", \"size\":\"173\", \"side\":\"SELL\", \"hash\":\"68c54dd8c70caaafe07b06accb2aacb6cb158dda\", \"best_bid\":\"0.54\", \"best_ask\":\"0.55\"}], \"timestamp\":\"1781254836907\", \"event_type\":\"price_change\"}","ts_local_ms":1781254837476}
{"dir":"in","text":"{\"market\":\"0x9c535590faae21bf76fed844aa47fc3c5c82253ef38bd545bf12c93470502685\", \"price_changes\":[{\"asset_id\":\"107011546575057755426871645700605806081353395825571114128343592072429146374928\", \"price\":\"0.01\", \"size\":\"54996.6\", \"side\":\"BUY\", \"hash\":\"3b5d4cd4e605c2b7279cbc500300e8e85cbb96d5\", \"best_bid\":\"0.54\", \"best_ask\":\"0.55\"}, {\"asset_id\":\"56108879726720646120583724001239294777304794469144970684362785767667828318889\", \"price\":\"0.99\", \"size\":\"54996.6\", \"side\":\"SELL\", \"hash\":\"bfb863919be00125a3316cbe764fa75dbaef4692\", \"best_bid\":\"0.45\", \"best_ask\":\"0.46\"}], \"timestamp\":\"1781254836908\", \"event_type\":\"price_change\"}","ts_local_ms":1781254837476}
{"dir":"in","text":"{\"market\":\"0x9c535590faae21bf76fed844aa47fc3c5c82253ef38bd545bf12c93470502685\", \"price_changes\":[{\"asset_id\":\"107011546575057755426871645700605806081353395825571114128343592072429146374928\", \"price\":\"0.01\", \"size\":\"55001.6\", \"side\":\"BUY\", \"hash\":\"df0d8a36d78c46e06e8041c5a788d9c381ce85bb\", \"best_bid\":\"0.54\", \"best_ask\":\"0.55\"}, {\"asset_id\":\"56108879726720646120583724001239294777304794469144970684362785767667828318889\", \"price\":\"0.99\", \"size\":\"55001.6\", \"side\":\"SELL\", \"hash\":\"859e0e61832f4003f4787f92507b1adf2633ce4b\", \"best_bid\":\"0.45\", \"best_ask\":\"0.46\"}], \"timestamp\":\"1781254836909\", \"event_type\":\"price_change\"}","ts_local_ms":1781254837476}
{"dir":"in","text":"{\"market\":\"0x9c535590faae21bf76fed844aa47fc3c5c82253ef38bd545bf12c93470502685\", \"price_changes\":[{\"asset_id\":\"107011546575057755426871645700605806081353395825571114128343592072429146374928\", \"price\":\"0.49\", \"size\":\"394.91\", \"side\":\"BUY\", \"hash\":\"e684e3e5262777d36fcc0e9eff32bb391ba0e08f\", \"best_bid\":\"0.54\", \"best_ask\":\"0.55\"}, {\"asset_id\":\"56108879726720646120583724001239294777304794469144970684362785767667828318889\", \"price\":\"0.51\", \"size\":\"394.91\", \"side\":\"SELL\", \"hash\":\"791475faeb834c7238d8900d31fa67ce1bc29915\", \"best_bid\":\"0.45\", \"best_ask\":\"0.46\"}], \"timestamp\":\"1781254836909\", \"event_type\":\"price_change\"}","ts_local_ms":1781254837476}
{"dir":"in","text":"{\"market\":\"0x9c535590faae21bf76fed844aa47fc3c5c82253ef38bd545bf12c93470502685\", \"price_changes\":[{\"asset_id\":\"56108879726720646120583724001239294777304794469144970684362785767667828318889\", \"price\":\"0.39\", \"size\":\"471\", \"side\":\"BUY\", \"hash\":\"09adada9cba9aa928d1c26d13007d59e1b9f2926\", \"best_bid\":\"0.45\", \"best_ask\":\"0.46\"}, {\"asset_id\":\"107011546575057755426871645700605806081353395825571114128343592072429146374928\", \"price\":\"0.61\", \"size\":\"471\", \"side\":\"SELL\", \"hash\":\"f94d538c56bd1db12f76f1e3c5d9174422b57a34\", \"best_bid\":\"0.54\", \"best_ask\":\"0.55\"}], \"timestamp\":\"1781254836910\", \"event_type\":\"price_change\"}","ts_local_ms":1781254837476}
{"dir":"in","text":"{\"market\":\"0x9c535590faae21bf76fed844aa47fc3c5c82253ef38bd545bf12c93470502685\", \"price_changes\":[{\"asset_id\":\"107011546575057755426871645700605806081353395825571114128343592072429146374928\", \"price\":\"0.51\", \"size\":\"148.59\", \"side\":\"BUY\", \"hash\":\"9c2cfca638dcc2d97978da4ad7b235c09b7f3614\", \"best_bid\":\"0.54\", \"best_ask\":\"0.55\"}, {\"asset_id\":\"56108879726720646120583724001239294777304794469144970684362785767667828318889\", \"price\":\"0.49\", \"size\":\"148.59\", \"side\":\"SELL\", \"hash\":\"8fa1863f5af45262fb984d2e6359a82936fc5cf3\", \"best_bid\":\"0.45\", \"best_ask\":\"0.46\"}], \"timestamp\":\"1781254836910\", \"event_type\":\"price_change\"}","ts_local_ms":1781254837477}
{"dir":"in","text":"{\"market\":\"0x9c535590faae21bf76fed844aa47fc3c5c82253ef38bd545bf12c93470502685\", \"price_changes\":[{\"asset_id\":\"56108879726720646120583724001239294777304794469144970684362785767667828318889\", \"price\":\"0.33\", \"size\":\"207\", \"side\":\"BUY\", \"hash\":\"565940b5423f739f559fdbecf258bf9ee97f7860\", \"best_bid\":\"0.45\", \"best_ask\":\"0.46\"}, {\"asset_id\":\"107011546575057755426871645700605806081353395825571114128343592072429146374928\", \"price\":\"0.67\", \"size\":\"207\", \"side\":\"SELL\", \"hash\":\"376d95f9287b5ec8891fc83d14e6015605c00690\", \"best_bid\":\"0.54\", \"best_ask\":\"0.55\"}], \"timestamp\":\"1781254836910\", \"event_type\":\"price_change\"}","ts_local_ms":1781254837477}
{"dir":"in","text":"{\"market\":\"0x9c535590faae21bf76fed844aa47fc3c5c82253ef38bd545bf12c93470502685\", \"price_changes\":[{\"asset_id\":\"56108879726720646120583724001239294777304794469144970684362785767667828318889\", \"price\":\"0.37\", \"size\":\"365.04\", \"side\":\"BUY\", \"hash\":\"8a76c5b8ba16f8d80eca5aec31c75bfb14de2d10\", \"best_bid\":\"0.45\", \"best_ask\":\"0.46\"}, {\"asset_id\":\"107011546575057755426871645700605806081353395825571114128343592072429146374928\", \"price\":\"0.63\", \"size\":\"365.04\", \"side\":\"SELL\", \"hash\":\"fefb23136a022815a577a99afb5362893770aabb\", \"best_bid\":\"0.54\", \"best_ask\":\"0.55\"}], \"timestamp\":\"1781254836910\", \"event_type\":\"price_change\"}","ts_local_ms":1781254837477}
{"dir":"in","text":"{\"market\":\"0x9c535590faae21bf76fed844aa47fc3c5c82253ef38bd545bf12c93470502685\", \"price_changes\":[{\"asset_id\":\"56108879726720646120583724001239294777304794469144970684362785767667828318889\", \"price\":\"0.37\", \"size\":\"380.04\", \"side\":\"BUY\", \"hash\":\"12a3d25e09ec9a6beeecc37597d5982a141c6233\", \"best_bid\":\"0.45\", \"best_ask\":\"0.46\"}, {\"asset_id\":\"107011546575057755426871645700605806081353395825571114128343592072429146374928\", \"price\":\"0.63\", \"size\":\"380.04\", \"side\":\"SELL\", \"hash\":\"5e1dbbc746b8be42f1157ae85eb7471b14c47d51\", \"best_bid\":\"0.54\", \"best_ask\":\"0.55\"}], \"timestamp\":\"1781254836911\", \"event_type\":\"price_change\"}","ts_local_ms":1781254837477}
{"dir":"in","text":"{\"market\":\"0x9c535590faae21bf76fed844aa47fc3c5c82253ef38bd545bf12c93470502685\", \"price_changes\":[{\"asset_id\":\"107011546575057755426871645700605806081353395825571114128343592072429146374928\", \"price\":\"0.54\", \"size\":\"508.52\", \"side\":\"BUY\", \"hash\":\"165d147b8ce507dade7d9962ce1bc8c197dd119f\", \"best_bid\":\"0.54\", \"best_ask\":\"0.55\"}, {\"asset_id\":\"56108879726720646120583724001239294777304794469144970684362785767667828318889\", \"price\":\"0.46\", \"size\":\"508.52\", \"side\":\"SELL\", \"hash\":\"f76998e61a3ff08a132a2c7339de85eac003a101\", \"best_bid\":\"0.45\", \"best_ask\":\"0.46\"}], \"timestamp\":\"1781254836912\", \"event_type\":\"price_change\"}","ts_local_ms":1781254837639}
{"dir":"in","text":"{\"market\":\"0x9c535590faae21bf76fed844aa47fc3c5c82253ef38bd545bf12c93470502685\", \"price_changes\":[{\"asset_id\":\"56108879726720646120583724001239294777304794469144970684362785767667828318889\", \"price\":\"0.43\", \"size\":\"178\", \"side\":\"BUY\", \"hash\":\"bc5cf11cc0bc877a4538fa09a2780103b79269f7\", \"best_bid\":\"0.45\", \"best_ask\":\"0.46\"}, {\"asset_id\":\"107011546575057755426871645700605806081353395825571114128343592072429146374928\", \"price\":\"0.57\", \"size\":\"178\", \"side\":\"SELL\", \"hash\":\"a17ab9faca86d6dc16debb06d23787f6ef3c8a73\", \"best_bid\":\"0.54\", \"best_ask\":\"0.55\"}], \"timestamp\":\"1781254836912\", \"event_type\":\"price_change\"}","ts_local_ms":1781254837640}
{"dir":"in","text":"{\"market\":\"0x9c535590faae21bf76fed844aa47fc3c5c82253ef38bd545bf12c93470502685\", \"price_changes\":[{\"asset_id\":\"56108879726720646120583724001239294777304794469144970684362785767667828318889\", \"price\":\"0.01\", \"size\":\"57389.15\", \"side\":\"BUY\", \"hash\":\"5164e0c42124eb3493c9865b5415bd9f8bd20c67\", \"best_bid\":\"0.45\", \"best_ask\":\"0.46\"}, {\"asset_id\":\"107011546575057755426871645700605806081353395825571114128343592072429146374928\", \"price\":\"0.99\", \"size\":\"57389.15\", \"side\":\"SELL\", \"hash\":\"411046a730b13a6c3da67d3ea0586fc641947dd6\", \"best_bid\":\"0.54\", \"best_ask\":\"0.55\"}], \"timestamp\":\"1781254836913\", \"event_type\":\"price_change\"}","ts_local_ms":1781254837640}
{"dir":"in","text":"{\"market\":\"0x9c535590faae21bf76fed844aa47fc3c5c82253ef38bd545bf12c93470502685\", \"price_changes\":[{\"asset_id\":\"56108879726720646120583724001239294777304794469144970684362785767667828318889\", \"price\":\"0.45\", \"size\":\"512.15\", \"side\":\"BUY\", \"hash\":\"04c8bff4733f7c22517bd6bc8ea5d6583784bc24\", \"best_bid\":\"0.45\", \"best_ask\":\"0.46\"}, {\"asset_id\":\"107011546575057755426871645700605806081353395825571114128343592072429146374928\", \"price\":\"0.55\", \"size\":\"512.15\", \"side\":\"SELL\", \"hash\":\"1aa369b2b0634651ddf3a9be3368a2d58e724710\", \"best_bid\":\"0.54\", \"best_ask\":\"0.55\"}], \"timestamp\":\"1781254836913\", \"event_type\":\"price_change\"}","ts_local_ms":1781254837640}
{"dir":"in","text":"{\"market\":\"0x9c535590faae21bf76fed844aa47fc3c5c82253ef38bd545bf12c93470502685\", \"price_changes\":[{\"asset_id\":\"107011546575057755426871645700605806081353395825571114128343592072429146374928\", \"price\":\"0.51\", \"size\":\"173.59\", \"side\":\"BUY\", \"hash\":\"d4a2ab06e1245abd89cbec430afb0b2f9b9e71f1\", \"best_bid\":\"0.54\", \"best_ask\":\"0.55\"}, {\"asset_id\":\"56108879726720646120583724001239294777304794469144970684362785767667828318889\", \"price\":\"0.49\", \"size\":\"173.59\", \"side\":\"SELL\", \"hash\":\"36180a94192bfd9cb774373f6945faca88209bfb\", \"best_bid\":\"0.45\", \"best_ask\":\"0.46\"}], \"timestamp\":\"1781254836914\", \"event_type\":\"price_change\"}","ts_local_ms":1781254837640}
{"dir":"in","text":"{\"market\":\"0x9c535590faae21bf76fed844aa47fc3c5c82253ef38bd545bf12c93470502685\", \"price_changes\":[{\"asset_id\":\"107011546575057755426871645700605806081353395825571114128343592072429146374928\", \"price\":\"0.48\", \"size\":\"1052.68\", \"side\":\"BUY\", \"hash\":\"d995f02d6718cfe533ca091ea3e78d3ce8331fa1\", \"best_bid\":\"0.54\", \"best_ask\":\"0.55\"}, {\"asset_id\":\"56108879726720646120583724001239294777304794469144970684362785767667828318889\", \"price\":\"0.52\", \"size\":\"1052.68\", \"side\":\"SELL\", \"hash\":\"8041761e130993564c4bf8da9444d625dd446cdc\", \"best_bid\":\"0.45\", \"best_ask\":\"0.46\"}], \"timestamp\":\"1781254836915\", \"event_type\":\"price_change\"}","ts_local_ms":1781254837640}
{"dir":"in","text":"{\"market\":\"0x9c535590faae21bf76fed844aa47fc3c5c82253ef38bd545bf12c93470502685\", \"price_changes\":[{\"asset_id\":\"56108879726720646120583724001239294777304794469144970684362785767667828318889\", \"price\":\"0.42\", \"size\":\"141.2\", \"side\":\"BUY\", \"hash\":\"64f081b48c393b194de766015bb72a4f4dc129b3\", \"best_bid\":\"0.45\", \"best_ask\":\"0.46\"}, {\"asset_id\":\"107011546575057755426871645700605806081353395825571114128343592072429146374928\", \"price\":\"0.58\", \"size\":\"141.2\", \"side\":\"SELL\", \"hash\":\"b78eb3a199651f7880bc32f8da622a1855d05f63\", \"best_bid\":\"0.54\", \"best_ask\":\"0.55\"}], \"timestamp\":\"1781254836916\", \"event_type\":\"price_change\"}","ts_local_ms":1781254837640}
{"dir":"in","text":"{\"market\":\"0x9c535590faae21bf76fed844aa47fc3c5c82253ef38bd545bf12c93470502685\", \"price_changes\":[{\"asset_id\":\"107011546575057755426871645700605806081353395825571114128343592072429146374928\", \"price\":\"0.01\", \"size\":\"55006.6\", \"side\":\"BUY\", \"hash\":\"0a9cc5c5a945aa278e7a31e86850a77cb5d82df8\", \"best_bid\":\"0.54\", \"best_ask\":\"0.55\"}, {\"asset_id\":\"56108879726720646120583724001239294777304794469144970684362785767667828318889\", \"price\":\"0.99\", \"size\":\"55006.6\", \"side\":\"SELL\", \"hash\":\"67cb6d2c8a7175feeab7bd74b72f06341200f760\", \"best_bid\":\"0.45\", \"best_ask\":\"0.46\"}], \"timestamp\":\"1781254836917\", \"event_type\":\"price_change\"}","ts_local_ms":1781254837640}
{"dir":"in","text":"{\"market\":\"0x9c535590faae21bf76fed844aa47fc3c5c82253ef38bd545bf12c93470502685\", \"price_changes\":[{\"asset_id\":\"107011546575057755426871645700605806081353395825571114128343592072429146374928\", \"price\":\"0.5\", \"size\":\"413.08\", \"side\":\"BUY\", \"hash\":\"84c395a7e95a76b5a63a7b3b628333ec28dad32b\", \"best_bid\":\"0.54\", \"best_ask\":\"0.55\"}, {\"asset_id\":\"56108879726720646120583724001239294777304794469144970684362785767667828318889\", \"price\":\"0.5\", \"size\":\"413.08\", \"side\":\"SELL\", \"hash\":\"9d9f9e04dc2f108a1dd36897a16b0ff3bb1afac6\", \"best_bid\":\"0.45\", \"best_ask\":\"0.46\"}], \"timestamp\":\"1781254836918\", \"event_type\":\"price_change\"}","ts_local_ms":1781254837640}
{"dir":"in","text":"{\"market\":\"0x9c535590faae21bf76fed844aa47fc3c5c82253ef38bd545bf12c93470502685\", \"price_changes\":[{\"asset_id\":\"107011546575057755426871645700605806081353395825571114128343592072429146374928\", \"price\":\"0.54\", \"size\":\"513.52\", \"side\":\"BUY\", \"hash\":\"c5477fd7bd0dfb898a99c983b1ae74697db0bc49\", \"best_bid\":\"0.54\", \"best_ask\":\"0.55\"}, {\"asset_id\":\"56108879726720646120583724001239294777304794469144970684362785767667828318889\", \"price\":\"0.46\", \"size\":\"513.52\", \"side\":\"SELL\", \"hash\":\"bab0a32ef52b6fb74d3b8cca7a1900082fa9b06a\", \"best_bid\":\"0.45\", \"best_ask\":\"0.46\"}], \"timestamp\":\"1781254836918\", \"event_type\":\"price_change\"}","ts_local_ms":1781254837640}
{"dir":"in","text":"{\"market\":\"0x9c535590faae21bf76fed844aa47fc3c5c82253ef38bd545bf12c93470502685\", \"price_changes\":[{\"asset_id\":\"56108879726720646120583724001239294777304794469144970684362785767667828318889\", \"price\":\"0.41\", \"size\":\"133\", \"side\":\"BUY\", \"hash\":\"389e74b8e0326613719b3ec4bb5614d09972ece6\", \"best_bid\":\"0.45\", \"best_ask\":\"0.46\"}, {\"asset_id\":\"107011546575057755426871645700605806081353395825571114128343592072429146374928\", \"price\":\"0.59\", \"size\":\"133\", \"side\":\"SELL\", \"hash\":\"f03a9717f975af19da8cd7896c42c60a23c38563\", \"best_bid\":\"0.54\", \"best_ask\":\"0.55\"}], \"timestamp\":\"1781254836919\", \"event_type\":\"price_change\"}","ts_local_ms":1781254837640}
{"dir":"in","text":"{\"market\":\"0x9c535590faae21bf76fed844aa47fc3c5c82253ef38bd545bf12c93470502685\", \"price_changes\":[{\"asset_id\":\"56108879726720646120583724001239294777304794469144970684362785767667828318889\", \"price\":\"0.45\", \"size\":\"517.17\", \"side\":\"BUY\", \"hash\":\"0668d682d3a97e613875313a79443d99ae56097c\", \"best_bid\":\"0.45\", \"best_ask\":\"0.46\"}, {\"asset_id\":\"107011546575057755426871645700605806081353395825571114128343592072429146374928\", \"price\":\"0.55\", \"size\":\"517.17\", \"side\":\"SELL\", \"hash\":\"9467fcfb9005ace1ec76f8d0090c0128bcd7c3c5\", \"best_bid\":\"0.54\", \"best_ask\":\"0.55\"}], \"timestamp\":\"1781254836920\", \"event_type\":\"price_change\"}","ts_local_ms":1781254837640}
{"dir":"in","text":"{\"market\":\"0x9c535590faae21bf76fed844aa47fc3c5c82253ef38bd545bf12c93470502685\", \"price_changes\":[{\"asset_id\":\"56108879726720646120583724001239294777304794469144970684362785767667828318889\", \"price\":\"0.4\", \"size\":\"352\", \"side\":\"BUY\", \"hash\":\"6c214d2869ea6b4d3b61fcdc12ac450cb0978451\", \"best_bid\":\"0.45\", \"best_ask\":\"0.46\"}, {\"asset_id\":\"107011546575057755426871645700605806081353395825571114128343592072429146374928\", \"price\":\"0.6\", \"size\":\"352\", \"side\":\"SELL\", \"hash\":\"3459f7ae89b32f10fdcf822c2edbebed1a0470fe\", \"best_bid\":\"0.54\", \"best_ask\":\"0.55\"}], \"timestamp\":\"1781254836920\", \"event_type\":\"price_change\"}","ts_local_ms":1781254837640}
{"dir":"in","text":"{\"market\":\"0x9c535590faae21bf76fed844aa47fc3c5c82253ef38bd545bf12c93470502685\", \"price_changes\":[{\"asset_id\":\"56108879726720646120583724001239294777304794469144970684362785767667828318889\", \"price\":\"0.01\", \"size\":\"57394.15\", \"side\":\"BUY\", \"hash\":\"fa80fb75d6e99b96e0668277c84a81ba217882eb\", \"best_bid\":\"0.45\", \"best_ask\":\"0.46\"}, {\"asset_id\":\"107011546575057755426871645700605806081353395825571114128343592072429146374928\", \"price\":\"0.99\", \"size\":\"57394.15\", \"side\":\"SELL\", \"hash\":\"a780f97f7edbcb2452b1f4ad04dd6f0ba72926be\", \"best_bid\":\"0.54\", \"best_ask\":\"0.55\"}], \"timestamp\":\"1781254836921\", \"event_type\":\"price_change\"}","ts_local_ms":1781254837640}
{"dir":"in","text":"{\"market\":\"0x9c535590faae21bf76fed844aa47fc3c5c82253ef38bd545bf12c93470502685\", \"price_changes\":[{\"asset_id\":\"56108879726720646120583724001239294777304794469144970684362785767667828318889\", \"price\":\"0.42\", \"size\":\"161.2\", \"side\":\"BUY\", \"hash\":\"6a349fbaf4bebe85de03efc03569f064ce864cc8\", \"best_bid\":\"0.45\", \"best_ask\":\"0.46\"}, {\"asset_id\":\"107011546575057755426871645700605806081353395825571114128343592072429146374928\", \"price\":\"0.58\", \"size\":\"161.2\", \"side\":\"SELL\", \"hash\":\"4a6be6eee80822cb7f54811d88328bc905821bba\", \"best_bid\":\"0.54\", \"best_ask\":\"0.55\"}], \"timestamp\":\"1781254836921\", \"event_type\":\"price_change\"}","ts_local_ms":1781254837641}
{"dir":"in","text":"{\"market\":\"0x9c535590faae21bf76fed844aa47fc3c5c82253ef38bd545bf12c93470502685\", \"price_changes\":[{\"asset_id\":\"107011546575057755426871645700605806081353395825571114128343592072429146374928\", \"price\":\"0.52\", \"size\":\"116.37\", \"side\":\"BUY\", \"hash\":\"2ebef1aca7a947d6f4bf9a58aec4ca5fc12ff4cf\", \"best_bid\":\"0.54\", \"best_ask\":\"0.55\"}, {\"asset_id\":\"56108879726720646120583724001239294777304794469144970684362785767667828318889\", \"price\":\"0.48\", \"size\":\"116.37\", \"side\":\"SELL\", \"hash\":\"6f2cc2d3607e4f0923aef01c6b1d39c416c7aa84\", \"best_bid\":\"0.45\", \"best_ask\":\"0.46\"}], \"timestamp\":\"1781254836922\", \"event_type\":\"price_change\"}","ts_local_ms":1781254837641}
{"dir":"in","text":"{\"market\":\"0x9c535590faae21bf76fed844aa47fc3c5c82253ef38bd545bf12c93470502685\", \"price_changes\":[{\"asset_id\":\"107011546575057755426871645700605806081353395825571114128343592072429146374928\", \"price\":\"0.21\", \"size\":\"172.8\", \"side\":\"BUY\", \"hash\":\"51e5e6c416c626775cf247dccf658b3553d4cc21\", \"best_bid\":\"0.54\", \"best_ask\":\"0.55\"}, {\"asset_id\":\"56108879726720646120583724001239294777304794469144970684362785767667828318889\", \"price\":\"0.79\", \"size\":\"172.8\", \"side\":\"SELL\", \"hash\":\"413b582636d6a564ad1667e4dbf219464499451a\", \"best_bid\":\"0.45\", \"best_ask\":\"0.46\"}], \"timestamp\":\"1781254836922\", \"event_type\":\"price_change\"}","ts_local_ms":1781254837641}
{"dir":"in","text":"{\"market\":\"0x9c535590faae21bf76fed844aa47fc3c5c82253ef38bd545bf12c93470502685\", \"price_changes\":[{\"asset_id\":\"56108879726720646120583724001239294777304794469144970684362785767667828318889\", \"price\":\"0.45\", \"size\":\"522.17\", \"side\":\"BUY\", \"hash\":\"5915bcc7d0f5d852f5fd31c7459be9fd57151b6f\", \"best_bid\":\"0.45\", \"best_ask\":\"0.46\"}, {\"asset_id\":\"107011546575057755426871645700605806081353395825571114128343592072429146374928\", \"price\":\"0.55\", \"size\":\"522.17\", \"side\":\"SELL\", \"hash\":\"ee6553afd8f63a0e8f0f08a6c63e5408cb897dc4\", \"best_bid\":\"0.54\", \"best_ask\":\"0.55\"}], \"timestamp\":\"1781254836923\", \"event_type\":\"price_change\"}","ts_local_ms":1781254837641}
{"dir":"in","text":"{\"market\":\"0x9c535590faae21bf76fed844aa47fc3c5c82253ef38bd545bf12c93470502685\", \"price_changes\":[{\"asset_id\":\"56108879726720646120583724001239294777304794469144970684362785767667828318889\", \"price\":\"0.43\", \"size\":\"188\", \"side\":\"BUY\", \"hash\":\"5a1840a3a7a417eef6c85b8e9e02844bd9e2d67f\", \"best_bid\":\"0.45\", \"best_ask\":\"0.46\"}, {\"asset_id\":\"107011546575057755426871645700605806081353395825571114128343592072429146374928\", \"price\":\"0.57\", \"size\":\"188\", \"side\":\"SELL\", \"hash\":\"348c8cf2a8d49d14b1c8a3bed9ff465bba96b4af\", \"best_bid\":\"0.54\", \"best_ask\":\"0.55\"}], \"timestamp\":\"1781254836924\", \"event_type\":\"price_change\"}","ts_local_ms":1781254837641}
{"dir":"in","text":"{\"market\":\"0x9c535590faae21bf76fed844aa47fc3c5c82253ef38bd545bf12c93470502685\", \"price_changes\":[{\"asset_id\":\"56108879726720646120583724001239294777304794469144970684362785767667828318889\", \"price\":\"0.39\", \"size\":\"456\", \"side\":\"BUY\", \"hash\":\"b962674409cafb1ecaab01b4fae7ab1528bdd039\", \"best_bid\":\"0.45\", \"best_ask\":\"0.46\"}, {\"asset_id\":\"107011546575057755426871645700605806081353395825571114128343592072429146374928\", \"price\":\"0.61\", \"size\":\"456\", \"side\":\"SELL\", \"hash\":\"6a04c7b59134807f138c8317de8c7d11a7157af5\", \"best_bid\":\"0.54\", \"best_ask\":\"0.55\"}], \"timestamp\":\"1781254836924\", \"event_type\":\"price_change\"}","ts_local_ms":1781254837641}
{"dir":"in","text":"{\"market\":\"0x9c535590faae21bf76fed844aa47fc3c5c82253ef38bd545bf12c93470502685\", \"price_changes\":[{\"asset_id\":\"56108879726720646120583724001239294777304794469144970684362785767667828318889\", \"price\":\"0.4\", \"size\":\"337\", \"side\":\"BUY\", \"hash\":\"b962674409cafb1ecaab01b4fae7ab1528bdd039\", \"best_bid\":\"0.45\", \"best_ask\":\"0.46\"}, {\"asset_id\":\"107011546575057755426871645700605806081353395825571114128343592072429146374928\", \"price\":\"0.6\", \"size\":\"337\", \"side\":\"SELL\", \"hash\":\"6a04c7b59134807f138c8317de8c7d11a7157af5\", \"best_bid\":\"0.54\", \"best_ask\":\"0.55\"}], \"timestamp\":\"1781254836924\", \"event_type\":\"price_change\"}","ts_local_ms":1781254837641}
{"dir":"in","text":"{\"market\":\"0x9c535590faae21bf76fed844aa47fc3c5c82253ef38bd545bf12c93470502685\", \"price_changes\":[{\"asset_id\":\"56108879726720646120583724001239294777304794469144970684362785767667828318889\", \"price\":\"0.01\", \"size\":\"57399.15\", \"side\":\"BUY\", \"hash\":\"baee3e4df154d665c9957e0376d697899211906f\", \"best_bid\":\"0.45\", \"best_ask\":\"0.46\"}, {\"asset_id\":\"107011546575057755426871645700605806081353395825571114128343592072429146374928\", \"price\":\"0.99\", \"size\":\"57399.15\", \"side\":\"SELL\", \"hash\":\"dd6284ca855f0579d06fa4770c0c858eb87d3d99\", \"best_bid\":\"0.54\", \"best_ask\":\"0.55\"}], \"timestamp\":\"1781254836925\", \"event_type\":\"price_change\"}","ts_local_ms":1781254837641}
{"dir":"in","text":"{\"market\":\"0x9c535590faae21bf76fed844aa47fc3c5c82253ef38bd545bf12c93470502685\", \"price_changes\":[{\"asset_id\":\"56108879726720646120583724001239294777304794469144970684362785767667828318889\", \"price\":\"0.39\", \"size\":\"448\", \"side\":\"BUY\", \"hash\":\"71fa53eaad45cac1e0c40b006b37b681de1db52a\", \"best_bid\":\"0.45\", \"best_ask\":\"0.46\"}, {\"asset_id\":\"107011546575057755426871645700605806081353395825571114128343592072429146374928\", \"price\":\"0.61\", \"size\":\"448\", \"side\":\"SELL\", \"hash\":\"1d824e3a1e67abaefff48b425d878c1fc3b68096\", \"best_bid\":\"0.54\", \"best_ask\":\"0.55\"}], \"timestamp\":\"1781254836925\", \"event_type\":\"price_change\"}","ts_local_ms":1781254837641}
{"dir":"in","text":"{\"market\":\"0x9c535590faae21bf76fed844aa47fc3c5c82253ef38bd545bf12c93470502685\", \"price_changes\":[{\"asset_id\":\"56108879726720646120583724001239294777304794469144970684362785767667828318889\", \"price\":\"0.4\", \"size\":\"329\", \"side\":\"BUY\", \"hash\":\"71fa53eaad45cac1e0c40b006b37b681de1db52a\", \"best_bid\":\"0.45\", \"best_ask\":\"0.46\"}, {\"asset_id\":\"107011546575057755426871645700605806081353395825571114128343592072429146374928\", \"price\":\"0.6\", \"size\":\"329\", \"side\":\"SELL\", \"hash\":\"1d824e3a1e67abaefff48b425d878c1fc3b68096\", \"best_bid\":\"0.54\", \"best_ask\":\"0.55\"}], \"timestamp\":\"1781254836925\", \"event_type\":\"price_change\"}","ts_local_ms":1781254837641}
{"dir":"in","text":"{\"market\":\"0x9c535590faae21bf76fed844aa47fc3c5c82253ef38bd545bf12c93470502685\", \"price_changes\":[{\"asset_id\":\"56108879726720646120583724001239294777304794469144970684362785767667828318889\", \"price\":\"0.39\", \"size\":\"439\", \"side\":\"BUY\", \"hash\":\"a0a547de680fa15ca99c887a8c69193b9d60eb7e\", \"best_bid\":\"0.45\", \"best_ask\":\"0.46\"}, {\"asset_id\":\"107011546575057755426871645700605806081353395825571114128343592072429146374928\", \"price\":\"0.61\", \"size\":\"439\", \"side\":\"SELL\", \"hash\":\"89de8932d5153f5d24f693fe3123b33ae3f8a42a\", \"best_bid\":\"0.54\", \"best_ask\":\"0.55\"}], \"timestamp\":\"1781254836926\", \"event_type\":\"price_change\"}","ts_local_ms":1781254837641}
{"dir":"in","text":"{\"market\":\"0x9c535590faae21bf76fed844aa47fc3c5c82253ef38bd545bf12c93470502685\", \"price_changes\":[{\"asset_id\":\"56108879726720646120583724001239294777304794469144970684362785767667828318889\", \"price\":\"0.4\", \"size\":\"320\", \"side\":\"BUY\", \"hash\":\"a0a547de680fa15ca99c887a8c69193b9d60eb7e\", \"best_bid\":\"0.45\", \"best_ask\":\"0.46\"}, {\"asset_id\":\"107011546575057755426871645700605806081353395825571114128343592072429146374928\", \"price\":\"0.6\", \"size\":\"320\", \"side\":\"SELL\", \"hash\":\"89de8932d5153f5d24f693fe3123b33ae3f8a42a\", \"best_bid\":\"0.54\", \"best_ask\":\"0.55\"}], \"timestamp\":\"1781254836926\", \"event_type\":\"price_change\"}","ts_local_ms":1781254837641}
{"dir":"in","text":"{\"market\":\"0x9c535590faae21bf76fed844aa47fc3c5c82253ef38bd545bf12c93470502685\", \"price_changes\":[{\"asset_id\":\"107011546575057755426871645700605806081353395825571114128343592072429146374928\", \"price\":\"0.54\", \"size\":\"518.52\", \"side\":\"BUY\", \"hash\":\"f0510f104215430df760a61347dc44456c2fc059\", \"best_bid\":\"0.54\", \"best_ask\":\"0.55\"}, {\"asset_id\":\"56108879726720646120583724001239294777304794469144970684362785767667828318889\", \"price\":\"0.46\", \"size\":\"518.52\", \"side\":\"SELL\", \"hash\":\"edd817fce948ca4cd77ef02c9b9fa1dc548337e2\", \"best_bid\":\"0.45\", \"best_ask\":\"0.46\"}], \"timestamp\":\"1781254836927\", \"event_type\":\"price_change\"}","ts_local_ms":1781254837641}
{"dir":"in","text":"{\"market\":\"0x9c535590faae21bf76fed844aa47fc3c5c82253ef38bd545bf12c93470502685\", \"price_changes\":[{\"asset_id\":\"56108879726720646120583724001239294777304794469144970684362785767667828318889\", \"price\":\"0.26\", \"size\":\"92.8\", \"side\":\"BUY\", \"hash\":\"b110f118d22b3be65c1c17ca64e3d28d7626360c\", \"best_bid\":\"0.45\", \"best_ask\":\"0.46\"}, {\"asset_id\":\"107011546575057755426871645700605806081353395825571114128343592072429146374928\", \"price\":\"0.74\", \"size\":\"92.8\", \"side\":\"SELL\", \"hash\":\"4a5925355a908dfe4394f9a1671262563e26b562\", \"best_bid\":\"0.54\", \"best_ask\":\"0.55\"}], \"timestamp\":\"1781254836927\", \"event_type\":\"price_change\"}","ts_local_ms":1781254837641}
{"dir":"in","text":"{\"market\":\"0x9c535590faae21bf76fed844aa47fc3c5c82253ef38bd545bf12c93470502685\", \"price_changes\":[{\"asset_id\":\"107011546575057755426871645700605806081353395825571114128343592072429146374928\", \"price\":\"0.54\", \"size\":\"523.52\", \"side\":\"BUY\", \"hash\":\"6fa33074db5dbbb7d296c558007333128ea33a5b\", \"best_bid\":\"0.54\", \"best_ask\":\"0.55\"}, {\"asset_id\":\"56108879726720646120583724001239294777304794469144970684362785767667828318889\", \"price\":\"0.46\", \"size\":\"523.52\", \"side\":\"SELL\", \"hash\":\"9f4893fb0651bed7a7c3b31edc2f69c086de5930\", \"best_bid\":\"0.45\", \"best_ask\":\"0.46\"}], \"timestamp\":\"1781254836928\", \"event_type\":\"price_change\"}","ts_local_ms":1781254837641}
{"dir":"in","text":"{\"market\":\"0x9c535590faae21bf76fed844aa47fc3c5c82253ef38bd545bf12c93470502685\", \"price_changes\":[{\"asset_id\":\"107011546575057755426871645700605806081353395825571114128343592072429146374928\", \"price\":\"0.49\", \"size\":\"399.91\", \"side\":\"BUY\", \"hash\":\"9058b483b66252b319b6bf61e029f97ae9bf2887\", \"best_bid\":\"0.54\", \"best_ask\":\"0.55\"}, {\"asset_id\":\"56108879726720646120583724001239294777304794469144970684362785767667828318889\", \"price\":\"0.51\", \"size\":\"399.91\", \"side\":\"SELL\", \"hash\":\"fc04df0ec8dfe2096ccc76fe3d131a9999bfde67\", \"best_bid\":\"0.45\", \"best_ask\":\"0.46\"}], \"timestamp\":\"1781254836928\", \"event_type\":\"price_change\"}","ts_local_ms":1781254837642}
{"dir":"in","text":"{\"market\":\"0x9c535590faae21bf76fed844aa47fc3c5c82253ef38bd545bf12c93470502685\", \"price_changes\":[{\"asset_id\":\"107011546575057755426871645700605806081353395825571114128343592072429146374928\", \"price\":\"0.54\", \"size\":\"512.52\", \"side\":\"BUY\", \"hash\":\"12249bd9c70388f90c9bde7442b82233a5c1b70c\", \"best_bid\":\"0.54\", \"best_ask\":\"0.55\"}, {\"asset_id\":\"56108879726720646120583724001239294777304794469144970684362785767667828318889\", \"price\":\"0.46\", \"size\":\"512.52\", \"side\":\"SELL\", \"hash\":\"f34e942628129ecab6961fb732780512783c1b90\", \"best_bid\":\"0.45\", \"best_ask\":\"0.46\"}], \"timestamp\":\"1781254836929\", \"event_type\":\"price_change\"}","ts_local_ms":1781254837642}
{"dir":"in","text":"{\"market\":\"0x9c535590faae21bf76fed844aa47fc3c5c82253ef38bd545bf12c93470502685\", \"price_changes\":[{\"asset_id\":\"107011546575057755426871645700605806081353395825571114128343592072429146374928\", \"price\":\"0.49\", \"size\":\"449.91\", \"side\":\"BUY\", \"hash\":\"71806ad7c0759748866aa90bc6f685032c64a7ce\", \"best_bid\":\"0.54\", \"best_ask\":\"0.55\"}, {\"asset_id\":\"56108879726720646120583724001239294777304794469144970684362785767667828318889\", \"price\":\"0.51\", \"size\":\"449.91\", \"side\":\"SELL\", \"hash\":\"d856d6bc0c170968c0bc25fd7ec7d1033b11d58b\", \"best_bid\":\"0.45\", \"best_ask\":\"0.46\"}], \"timestamp\":\"1781254836930\", \"event_type\":\"price_change\"}","ts_local_ms":1781254837642}
{"dir":"in","text":"{\"market\":\"0x9c535590faae21bf76fed844aa47fc3c5c82253ef38bd545bf12c93470502685\", \"price_changes\":[{\"asset_id\":\"56108879726720646120583724001239294777304794469144970684362785767667828318889\", \"price\":\"0.45\", \"size\":\"528.42\", \"side\":\"BUY\", \"hash\":\"0c8c487dcc298c269e24869121393caaa0af1b9b\", \"best_bid\":\"0.45\", \"best_ask\":\"0.46\"}, {\"asset_id\":\"107011546575057755426871645700605806081353395825571114128343592072429146374928\", \"price\":\"0.55\", \"size\":\"528.42\", \"side\":\"SELL\", \"hash\":\"36fa7b6d583d797a119de6304dd4abe474d18871\", \"best_bid\":\"0.54\", \"best_ask\":\"0.55\"}], \"timestamp\":\"1781254836930\", \"event_type\":\"price_change\"}","ts_local_ms":1781254837642}
{"dir":"in","text":"{\"market\":\"0x9c535590faae21bf76fed844aa47fc3c5c82253ef38bd545bf12c93470502685\", \"price_changes\":[{\"asset_id\":\"56108879726720646120583724001239294777304794469144970684362785767667828318889\", \"price\":\"0.45\", \"size\":\"551.42\", \"side\":\"BUY\", \"hash\":\"cadfc4cb5fd9673aaa3fa0d25f416c1e09415b8c\", \"best_bid\":\"0.45\", \"best_ask\":\"0.46\"}, {\"asset_id\":\"107011546575057755426871645700605806081353395825571114128343592072429146374928\", \"price\":\"0.55\", \"size\":\"551.42\", \"side\":\"SELL\", \"hash\":\"b93ddac6fb95b3e88b2e0c93c3dff05297f5cbcb\", \"best_bid\":\"0.54\", \"best_ask\":\"0.55\"}], \"timestamp\":\"1781254836931\", \"event_type\":\"price_change\"}","ts_local_ms":1781254837642}
{"dir":"in","text":"{\"market\":\"0x9c535590faae21bf76fed844aa47fc3c5c82253ef38bd545bf12c93470502685\", \"price_changes\":[{\"asset_id\":\"107011546575057755426871645700605806081353395825571114128343592072429146374928\", \"price\":\"0.01\", \"size\":\"55011.61\", \"side\":\"BUY\", \"hash\":\"291ea1891d635c51fa1bf520e9f89bbe84360fc1\", \"best_bid\":\"0.54\", \"best_ask\":\"0.55\"}, {\"asset_id\":\"56108879726720646120583724001239294777304794469144970684362785767667828318889\", \"price\":\"0.99\", \"size\":\"55011.61\", \"side\":\"SELL\", \"hash\":\"cc91cecb38b31d164c239177ea3442ee57300d63\", \"best_bid\":\"0.45\", \"best_ask\":\"0.46\"}], \"timestamp\":\"1781254836932\", \"event_type\":\"price_change\"}","ts_local_ms":1781254837642}
{"dir":"in","text":"{\"market\":\"0x9c535590faae21bf76fed844aa47fc3c5c82253ef38bd545bf12c93470502685\", \"price_changes\":[{\"asset_id\":\"56108879726720646120583724001239294777304794469144970684362785767667828318889\", \"price\":\"0.45\", \"size\":\"556.42\", \"side\":\"BUY\", \"hash\":\"ac5d63aa5dbdc6eaf3076c89e1961a9649cc3d7a\", \"best_bid\":\"0.45\", \"best_ask\":\"0.46\"}, {\"asset_id\":\"107011546575057755426871645700605806081353395825571114128343592072429146374928\", \"price\":\"0.55\", \"size\":\"556.42\", \"side\":\"SELL\", \"hash\":\"e2c69f0c387703c7ffa12431aedc88c016cd73f0\", \"best_bid\":\"0.54\", \"best_ask\":\"0.55\"}], \"timestamp\":\"1781254836932\", \"event_type\":\"price_change\"}","ts_local_ms":1781254837642}
{"dir":"in","text":"{\"market\":\"0x9c535590faae21bf76fed844aa47fc3c5c82253ef38bd545bf12c93470502685\", \"price_changes\":[{\"asset_id\":\"107011546575057755426871645700605806081353395825571114128343592072429146374928\", \"price\":\"0.54\", \"size\":\"507.52\", \"side\":\"BUY\", \"hash\":\"26afa0d7a58e62071d07d0a7e56515e62cebea63\", \"best_bid\":\"0.54\", \"best_ask\":\"0.55\"}, {\"asset_id\":\"56108879726720646120583724001239294777304794469144970684362785767667828318889\", \"price\":\"0.46\", \"size\":\"507.52\", \"side\":\"SELL\", \"hash\":\"a4fad66c2592d4a079b72638454077a1c1558676\", \"best_bid\":\"0.45\", \"best_ask\":\"0.46\"}], \"timestamp\":\"1781254836933\", \"event_type\":\"price_change\"}","ts_local_ms":1781254837642}
{"dir":"in","text":"{\"market\":\"0x9c535590faae21bf76fed844aa47fc3c5c82253ef38bd545bf12c93470502685\", \"price_changes\":[{\"asset_id\":\"56108879726720646120583724001239294777304794469144970684362785767667828318889\", \"price\":\"0.45\", \"size\":\"566.42\", \"side\":\"BUY\", \"hash\":\"96da6c9c6948a583ae1e4642fb96e3c857ccb5c5\", \"best_bid\":\"0.45\", \"best_ask\":\"0.46\"}, {\"asset_id\":\"107011546575057755426871645700605806081353395825571114128343592072429146374928\", \"price\":\"0.55\", \"size\":\"566.42\", \"side\":\"SELL\", \"hash\":\"eb3f7b6cdad88c1690c647f280a23af9dc389de4\", \"best_bid\":\"0.54\", \"best_ask\":\"0.55\"}], \"timestamp\":\"1781254836933\", \"event_type\":\"price_change\"}","ts_local_ms":1781254837642}
{"dir":"in","text":"{\"market\":\"0x9c535590faae21bf76fed844aa47fc3c5c82253ef38bd545bf12c93470502685\", \"price_changes\":[{\"asset_id\":\"56108879726720646120583724001239294777304794469144970684362785767667828318889\", \"price\":\"0.34\", \"size\":\"107\", \"side\":\"BUY\", \"hash\":\"68e8b6db3b4a983ffe5e3f6ca2ddc0c8f380c281\", \"best_bid\":\"0.45\", \"best_ask\":\"0.46\"}, {\"asset_id\":\"107011546575057755426871645700605806081353395825571114128343592072429146374928\", \"price\":\"0.66\", \"size\":\"107\", \"side\":\"SELL\", \"hash\":\"24c12c976d44567abfd9c200860a3038b30c0424\", \"best_bid\":\"0.54\", \"best_ask\":\"0.55\"}], \"timestamp\":\"1781254836934\", \"event_type\":\"price_change\"}","ts_local_ms":1781254837642}
{"dir":"in","text":"{\"market\":\"0x9c535590faae21bf76fed844aa47fc3c5c82253ef38bd545bf12c93470502685\", \"price_changes\":[{\"asset_id\":\"56108879726720646120583724001239294777304794469144970684362785767667828318889\", \"price\":\"0.36\", \"size\":\"166\", \"side\":\"BUY\", \"hash\":\"de18b625c8df0794e6f11da137bdec10dca03e45\", \"best_bid\":\"0.45\", \"best_ask\":\"0.46\"}, {\"asset_id\":\"107011546575057755426871645700605806081353395825571114128343592072429146374928\", \"price\":\"0.64\", \"size\":\"166\", \"side\":\"SELL\", \"hash\":\"d75d8925167127a20df97ab9984c9b32da4e1246\", \"best_bid\":\"0.54\", \"best_ask\":\"0.55\"}], \"timestamp\":\"1781254836935\", \"event_type\":\"price_change\"}","ts_local_ms":1781254837642}
{"dir":"in","text":"{\"market\":\"0x9c535590faae21bf76fed844aa47fc3c5c82253ef38bd545bf12c93470502685\", \"price_changes\":[{\"asset_id\":\"107011546575057755426871645700605806081353395825571114128343592072429146374928\", \"price\":\"0.5\", \"size\":\"463.08\", \"side\":\"BUY\", \"hash\":\"2e55cb93cce5918c9afcbd9cc8b4c1a3a0c2b79a\", \"best_bid\":\"0.54\", \"best_ask\":\"0.55\"}, {\"asset_id\":\"56108879726720646120583724001239294777304794469144970684362785767667828318889\", \"price\":\"0.5\", \"size\":\"463.08\", \"side\":\"SELL\", \"hash\":\"db31d29e18ce3fef835942fd0313ba557b9e708d\", \"best_bid\":\"0.45\", \"best_ask\":\"0.46\"}], \"timestamp\":\"1781254836935\", \"event_type\":\"price_change\"}","ts_local_ms":1781254837642}
{"dir":"in","text":"{\"market\":\"0x9c535590faae21bf76fed844aa47fc3c5c82253ef38bd545bf12c93470502685\", \"price_changes\":[{\"asset_id\":\"56108879726720646120583724001239294777304794469144970684362785767667828318889\", \"price\":\"0.41\", \"size\":\"139.72\", \"side\":\"BUY\", \"hash\":\"0594da514312879f2440a1adf7502028f179e831\", \"best_bid\":\"0.45\", \"best_ask\":\"0.46\"}, {\"asset_id\":\"107011546575057755426871645700605806081353395825571114128343592072429146374928\", \"price\":\"0.59\", \"size\":\"139.72\", \"side\":\"SELL\", \"hash\":\"fec61939b150ec0ef794a2cd1319fbe0e0cddb3b\", \"best_bid\":\"0.54\", \"best_ask\":\"0.55\"}], \"timestamp\":\"1781254836936\", \"event_type\":\"price_change\"}","ts_local_ms":1781254837643}
{"dir":"in","text":"{\"market\":\"0x9c535590faae21bf76fed844aa47fc3c5c82253ef38bd545bf12c93470502685\", \"price_changes\":[{\"asset_id\":\"107011546575057755426871645700605806081353395825571114128343592072429146374928\", \"price\":\"0.01\", \"size\":\"55016.61\", \"side\":\"BUY\", \"hash\":\"8c594160c074c6e3026f8411d567edf353150438\", \"best_bid\":\"0.54\", \"best_ask\":\"0.55\"}, {\"asset_id\":\"56108879726720646120583724001239294777304794469144970684362785767667828318889\", \"price\":\"0.99\", \"size\":\"55016.61\", \"side\":\"SELL\", \"hash\":\"b1d629a26574a83c652e291fcec2e31a41491255\", \"best_bid\":\"0.45\", \"best_ask\":\"0.46\"}], \"timestamp\":\"1781254836937\", \"event_type\":\"price_change\"}","ts_local_ms":1781254837643}
{"dir":"in","text":"{\"market\":\"0x9c535590faae21bf76fed844aa47fc3c5c82253ef38bd545bf12c93470502685\", \"price_changes\":[{\"asset_id\":\"107011546575057755426871645700605806081353395825571114128343592072429146374928\", \"price\":\"0.54\", \"size\":\"496.52\", \"side\":\"BUY\", \"hash\":\"142e1938364bdeed701bb69a400fd85ebad1b4ad\", \"best_bid\":\"0.54\", \"best_ask\":\"0.55\"}, {\"asset_id\":\"56108879726720646120583724001239294777304794469144970684362785767667828318889\", \"price\":\"0.46\", \"size\":\"496.52\", \"side\":\"SELL\", \"hash\":\"5c10920de049edcce80d3e3d0057db1f688926ba\", \"best_bid\":\"0.45\", \"best_ask\":\"0.46\"}], \"timestamp\":\"1781254836937\", \"event_type\":\"price_change\"}","ts_local_ms":1781254837643}
{"dir":"in","text":"{\"market\":\"0x9c535590faae21bf76fed844aa47fc3c5c82253ef38bd545bf12c93470502685\", \"price_changes\":[{\"asset_id\":\"56108879726720646120583724001239294777304794469144970684362785767667828318889\", \"price\":\"0.45\", \"size\":\"581.42\", \"side\":\"BUY\", \"hash\":\"f2dfe81b77b4929ec8958e10bdd79a0de54646ef\", \"best_bid\":\"0.45\", \"best_ask\":\"0.46\"}, {\"asset_id\":\"107011546575057755426871645700605806081353395825571114128343592072429146374928\", \"price\":\"0.55\", \"size\":\"581.42\", \"side\":\"SELL\", \"hash\":\"06a5097d41c6d2ec46e8c41c9105b219ed50b9b8\", \"best_bid\":\"0.54\", \"best_ask\":\"0.55\"}], \"timestamp\":\"1781254836938\", \"event_type\":\"price_change\"}","ts_local_ms":1781254837643}
{"dir":"in","text":"{\"market\":\"0x9c535590faae21bf76fed844aa47fc3c5c82253ef38bd545bf12c93470502685\", \"price_changes\":[{\"asset_id\":\"107011546575057755426871645700605806081353395825571114128343592072429146374928\", \"price\":\"0.51\", \"size\":\"188.59\", \"side\":\"BUY\", \"hash\":\"e56f0beeb2a00ada3e7b63a058badf004f335417\", \"best_bid\":\"0.54\", \"best_ask\":\"0.55\"}, {\"asset_id\":\"56108879726720646120583724001239294777304794469144970684362785767667828318889\", \"price\":\"0.49\", \"size\":\"188.59\", \"side\":\"SELL\", \"hash\":\"0a2c8ca1a48130dbf151f9605ca17048c181d50b\", \"best_bid\":\"0.45\", \"best_ask\":\"0.46\"}], \"timestamp\":\"1781254836938\", \"event_type\":\"price_change\"}","ts_local_ms":1781254837643}
{"dir":"in","text":"{\"market\":\"0x9c535590faae21bf76fed844aa47fc3c5c82253ef38bd545bf12c93470502685\", \"price_changes\":[{\"asset_id\":\"107011546575057755426871645700605806081353395825571114128343592072429146374928\", \"price\":\"0.51\", \"size\":\"218.59\", \"side\":\"BUY\", \"hash\":\"b17279bba321d863e7cf8e31fdf5c09d38bf5460\", \"best_bid\":\"0.54\", \"best_ask\":\"0.55\"}, {\"asset_id\":\"56108879726720646120583724001239294777304794469144970684362785767667828318889\", \"price\":\"0.49\", \"size\":\"218.59\", \"side\":\"SELL\", \"hash\":\"d15390f9f724247507068d96f676d35e9952f5eb\", \"best_bid\":\"0.45\", \"best_ask\":\"0.46\"}], \"timestamp\":\"1781254836939\", \"event_type\":\"price_change\"}","ts_local_ms":1781254837643}
{"dir":"in","text":"{\"market\":\"0x9c535590faae21bf76fed844aa47fc3c5c82253ef38bd545bf12c93470502685\", \"price_changes\":[{\"asset_id\":\"107011546575057755426871645700605806081353395825571114128343592072429146374928\", \"price\":\"0.49\", \"size\":\"434.91\", \"side\":\"BUY\", \"hash\":\"28f2ad1034e26b3a19dc58f725a873c7d5f9f695\", \"best_bid\":\"0.54\", \"best_ask\":\"0.55\"}, {\"asset_id\":\"56108879726720646120583724001239294777304794469144970684362785767667828318889\", \"price\":\"0.51\", \"size\":\"434.91\", \"side\":\"SELL\", \"hash\":\"002007377181617d27cf508196a81efbb40f0a7b\", \"best_bid\":\"0.45\", \"best_ask\":\"0.46\"}], \"timestamp\":\"1781254836939\", \"event_type\":\"price_change\"}","ts_local_ms":1781254837643}
{"dir":"in","text":"{\"market\":\"0x9c535590faae21bf76fed844aa47fc3c5c82253ef38bd545bf12c93470502685\", \"price_changes\":[{\"asset_id\":\"56108879726720646120583724001239294777304794469144970684362785767667828318889\", \"price\":\"0.14\", \"size\":\"91.55\", \"side\":\"BUY\", \"hash\":\"425f53ce78583d1758bced4dc1e156bbd8ef1bca\", \"best_bid\":\"0.45\", \"best_ask\":\"0.46\"}, {\"asset_id\":\"107011546575057755426871645700605806081353395825571114128343592072429146374928\", \"price\":\"0.86\", \"size\":\"91.55\", \"side\":\"SELL\", \"hash\":\"84ea1d24db117efc0501b4b5fb77fb3ebcd3fe7e\", \"best_bid\":\"0.54\", \"best_ask\":\"0.55\"}], \"timestamp\":\"1781254836940\", \"event_type\":\"price_change\"}","ts_local_ms":1781254837643}
{"dir":"in","text":"{\"market\":\"0x9c535590faae21bf76fed844aa47fc3c5c82253ef38bd545bf12c93470502685\", \"price_changes\":[{\"asset_id\":\"107011546575057755426871645700605806081353395825571114128343592072429146374928\", \"price\":\"0.42\", \"size\":\"219\", \"side\":\"BUY\", \"hash\":\"f7e818126007adecb8f3edb163d890846d993a6a\", \"best_bid\":\"0.54\", \"best_ask\":\"0.55\"}, {\"asset_id\":\"56108879726720646120583724001239294777304794469144970684362785767667828318889\", \"price\":\"0.58\", \"size\":\"219\", \"side\":\"SELL\", \"hash\":\"aa946a11763a16943d9c3defdd4b087574b369d5\", \"best_bid\":\"0.45\", \"best_ask\":\"0.46\"}], \"timestamp\":\"1781254836941\", \"event_type\":\"price_change\"}","ts_local_ms":1781254837643}
{"dir":"in","text":"{\"market\":\"0x9c535590faae21bf76fed844aa47fc3c5c82253ef38bd545bf12c93470502685\", \"price_changes\":[{\"asset_id\":\"107011546575057755426871645700605806081353395825571114128343592072429146374928\", \"price\":\"0.55\", \"size\":\"576.05\", \"side\":\"SELL\", \"hash\":\"7703c23f930c30adcaf81e632c7da93e2f498e25\", \"best_bid\":\"0.54\", \"best_ask\":\"0.55\"}, {\"asset_id\":\"56108879726720646120583724001239294777304794469144970684362785767667828318889\", \"price\":\"0.45\", \"size\":\"576.05\", \"side\":\"BUY\", \"hash\":\"ad7bcb6afc00ec29bcb80cc1782c17b84525e267\", \"best_bid\":\"0.45\", \"best_ask\":\"0.46\"}], \"timestamp\":\"1781254836943\", \"event_type\":\"price_change\"}","ts_local_ms":1781254837643}
{"dir":"in","text":"{\"market\":\"0x9c535590faae21bf76fed844aa47fc3c5c82253ef38bd545bf12c93470502685\", \"price_changes\":[{\"asset_id\":\"56108879726720646120583724001239294777304794469144970684362785767667828318889\", \"price\":\"0.45\", \"size\":\"571.03\", \"side\":\"BUY\", \"hash\":\"10ed3dd2d0f0bdb180e760b90c86a708d4ee499b\", \"best_bid\":\"0.45\", \"best_ask\":\"0.46\"}, {\"asset_id\":\"107011546575057755426871645700605806081353395825571114128343592072429146374928\", \"price\":\"0.55\", \"size\":\"571.03\", \"side\":\"SELL\", \"hash\":\"530cd4f5d128bc0c47bccd1d213711c49fbf3a6c\", \"best_bid\":\"0.54\", \"best_ask\":\"0.55\"}], \"timestamp\":\"1781254836944\", \"event_type\":\"price_change\"}","ts_local_ms":1781254837643}
{"dir":"in","text":"{\"market\":\"0x9c535590faae21bf76fed844aa47fc3c5c82253ef38bd545bf12c93470502685\", \"price_changes\":[{\"asset_id\":\"107011546575057755426871645700605806081353395825571114128343592072429146374928\", \"price\":\"0.54\", \"size\":\"491.52\", \"side\":\"BUY\", \"hash\":\"08734bbca3b81b5a2bb8c8f911bc5f33c2b4dc6d\", \"best_bid\":\"0.54\", \"best_ask\":\"0.55\"}, {\"asset_id\":\"56108879726720646120583724001239294777304794469144970684362785767667828318889\", \"price\":\"0.46\", \"size\":\"491.52\", \"side\":\"SELL\", \"hash\":\"fd1ec0140f643e108c2e7e369d579aef24397ec9\", \"best_bid\":\"0.45\", \"best_ask\":\"0.46\"}], \"timestamp\":\"1781254836944\", \"event_type\":\"price_change\"}","ts_local_ms":1781254837643}
{"dir":"in","text":"{\"market\":\"0x9c535590faae21bf76fed844aa47fc3c5c82253ef38bd545bf12c93470502685\", \"price_changes\":[{\"asset_id\":\"107011546575057755426871645700605806081353395825571114128343592072429146374928\", \"price\":\"0.54\", \"size\":\"486.52\", \"side\":\"BUY\", \"hash\":\"6374c70ce00fc1281911cef8fcb0272ab2ae23a5\", \"best_bid\":\"0.54\", \"best_ask\":\"0.55\"}, {\"asset_id\":\"56108879726720646120583724001239294777304794469144970684362785767667828318889\", \"price\":\"0.46\", \"size\":\"486.52\", \"side\":\"SELL\", \"hash\":\"c29c37c329e61d9a3bfbb069f691858d18864d91\", \"best_bid\":\"0.45\", \"best_ask\":\"0.46\"}], \"timestamp\":\"1781254836944\", \"event_type\":\"price_change\"}","ts_local_ms":1781254837643}
{"dir":"in","text":"{\"market\":\"0x9c535590faae21bf76fed844aa47fc3c5c82253ef38bd545bf12c93470502685\", \"price_changes\":[{\"asset_id\":\"56108879726720646120583724001239294777304794469144970684362785767667828318889\", \"price\":\"0.44\", \"size\":\"62.83\", \"side\":\"BUY\", \"hash\":\"be13f7953a0bc700ed68193365a921f82d534e59\", \"best_bid\":\"0.45\", \"best_ask\":\"0.46\"}, {\"asset_id\":\"107011546575057755426871645700605806081353395825571114128343592072429146374928\", \"price\":\"0.56\", \"size\":\"62.83\", \"side\":\"SELL\", \"hash\":\"515e76ec040a4f80e5f77c8a4bab948130b2d2dc\", \"best_bid\":\"0.54\", \"best_ask\":\"0.55\"}], \"timestamp\":\"1781254836944\", \"event_type\":\"price_change\"}","ts_local_ms":1781254837643}
{"dir":"in","text":"{\"market\":\"0x9c535590faae21bf76fed844aa47fc3c5c82253ef38bd545bf12c93470502685\", \"price_changes\":[{\"asset_id\":\"107011546575057755426871645700605806081353395825571114128343592072429146374928\", \"price\":\"0.01\", \"size\":\"55011.61\", \"side\":\"BUY\", \"hash\":\"4f0ae8ad0a71c99370ffb2e65787df851e3bdbe7\", \"best_bid\":\"0.54\", \"best_ask\":\"0.55\"}, {\"asset_id\":\"56108879726720646120583724001239294777304794469144970684362785767667828318889\", \"price\":\"0.99\", \"size\":\"55011.61\", \"side\":\"SELL\", \"hash\":\"41a056d671c1db2a196cae1663c535e69cf6e62c\", \"best_bid\":\"0.45\", \"best_ask\":\"0.46\"}], \"timestamp\":\"1781254836945\", \"event_type\":\"price_change\"}","ts_local_ms":1781254837643}
{"dir":"in","text":"{\"market\":\"0x9c535590faae21bf76fed844aa47fc3c5c82253ef38bd545bf12c93470502685\", \"price_changes\":[{\"asset_id\":\"56108879726720646120583724001239294777304794469144970684362785767667828318889\", \"price\":\"0.45\", \"size\":\"576.03\", \"side\":\"BUY\", \"hash\":\"ea1e5d6b61378b58b138d60feb22b5bf94435089\", \"best_bid\":\"0.45\", \"best_ask\":\"0.46\"}, {\"asset_id\":\"107011546575057755426871645700605806081353395825571114128343592072429146374928\", \"price\":\"0.55\", \"size\":\"576.03\", \"side\":\"SELL\", \"hash\":\"9a6b84c4f996f51db4b25eae65a55c55f8a989a8\", \"best_bid\":\"0.54\", \"best_ask\":\"0.55\"}], \"timestamp\":\"1781254836946\", \"event_type\":\"price_change\"}","ts_local_ms":1781254837643}
{"dir":"in","text":"{\"market\":\"0x9c535590faae21bf76fed844aa47fc3c5c82253ef38bd545bf12c93470502685\", \"price_changes\":[{\"asset_id\":\"56108879726720646120583724001239294777304794469144970684362785767667828318889\", \"price\":\"0.38\", \"size\":\"296\", \"side\":\"BUY\", \"hash\":\"2c8c2a197cd756b765a4e66ca812b44058d95940\", \"best_bid\":\"0.45\", \"best_ask\":\"0.46\"}, {\"asset_id\":\"107011546575057755426871645700605806081353395825571114128343592072429146374928\", \"price\":\"0.62\", \"size\":\"296\", \"side\":\"SELL\", \"hash\":\"710baaa4ec2c336b1146d437a5eeef2cd1646e8f\", \"best_bid\":\"0.54\", \"best_ask\":\"0.55\"}], \"timestamp\":\"1781254836946\", \"event_type\":\"price_change\"}","ts_local_ms":1781254837643}
{"dir":"in","text":"{\"market\":\"0x9c535590faae21bf76fed844aa47fc3c5c82253ef38bd545bf12c93470502685\", \"price_changes\":[{\"asset_id\":\"56108879726720646120583724001239294777304794469144970684362785767667828318889\", \"price\":\"0.45\", \"size\":\"586.03\", \"side\":\"BUY\", \"hash\":\"f08e7e53f0aa87d8bdec51ec93edb96b56fe0eed\", \"best_bid\":\"0.45\", \"best_ask\":\"0.46\"}, {\"asset_id\":\"107011546575057755426871645700605806081353395825571114128343592072429146374928\", \"price\":\"0.55\", \"size\":\"586.03\", \"side\":\"SELL\", \"hash\":\"12483c92ceb026aa95529c4c2e2af98bb2b2e15a\", \"best_bid\":\"0.54\", \"best_ask\":\"0.55\"}], \"timestamp\":\"1781254836949\", \"event_type\":\"price_change\"}","ts_local_ms":1781254837643}
{"dir":"in","text":"{\"market\":\"0x9c535590faae21bf76fed844aa47fc3c5c82253ef38bd545bf12c93470502685\", \"price_changes\":[{\"asset_id\":\"56108879726720646120583724001239294777304794469144970684362785767667828318889\", \"price\":\"0.43\", \"size\":\"180\", \"side\":\"BUY\", \"hash\":\"8aa36e4234e76526a1eee0e5168add2c845b03d2\", \"best_bid\":\"0.45\", \"best_ask\":\"0.46\"}, {\"asset_id\":\"107011546575057755426871645700605806081353395825571114128343592072429146374928\", \"price\":\"0.57\", \"size\":\"180\", \"side\":\"SELL\", \"hash\":\"80695704972074ac064603cc67261708ea99ca7d\", \"best_bid\":\"0.54\", \"best_ask\":\"0.55\"}], \"timestamp\":\"1781254836949\", \"event_type\":\"price_change\"}","ts_local_ms":1781254837644}
{"dir":"in","text":"{\"market\":\"0x9c535590faae21bf76fed844aa47fc3c5c82253ef38bd545bf12c93470502685\", \"price_changes\":[{\"asset_id\":\"107011546575057755426871645700605806081353395825571114128343592072429146374928\", \"price\":\"0.54\", \"size\":\"481.52\", \"side\":\"BUY\", \"hash\":\"52aede80e052ca6e0276a6b1a6cb58979b74acc4\", \"best_bid\":\"0.54\", \"best_ask\":\"0.55\"}, {\"asset_id\":\"56108879726720646120583724001239294777304794469144970684362785767667828318889\", \"price\":\"0.46\", \"size\":\"481.52\", \"side\":\"SELL\", \"hash\":\"cb01696613e0adb36515a3c9de71830aa659a68c\", \"best_bid\":\"0.45\", \"best_ask\":\"0.46\"}], \"timestamp\":\"1781254836951\", \"event_type\":\"price_change\"}","ts_local_ms":1781254837644}
{"dir":"in","text":"{\"market\":\"0x9c535590faae21bf76fed844aa47fc3c5c82253ef38bd545bf12c93470502685\", \"price_changes\":[{\"asset_id\":\"56108879726720646120583724001239294777304794469144970684362785767667828318889\", \"price\":\"0.41\", \"size\":\"131.72\", \"side\":\"BUY\", \"hash\":\"1a3c47f4638f11da6a9b02aa401178af819e0d7d\", \"best_bid\":\"0.45\", \"best_ask\":\"0.46\"}, {\"asset_id\":\"107011546575057755426871645700605806081353395825571114128343592072429146374928\", \"price\":\"0.59\", \"size\":\"131.72\", \"side\":\"SELL\", \"hash\":\"34fccd80e99be9ac39bf1c2a70f4c5541041c3d8\", \"best_bid\":\"0.54\", \"best_ask\":\"0.55\"}], \"timestamp\":\"1781254836951\", \"event_type\":\"price_change\"}","ts_local_ms":1781254837644}
{"dir":"in","text":"{\"market\":\"0x9c535590faae21bf76fed844aa47fc3c5c82253ef38bd545bf12c93470502685\", \"price_changes\":[{\"asset_id\":\"56108879726720646120583724001239294777304794469144970684362785767667828318889\", \"price\":\"0.45\", \"size\":\"596.03\", \"side\":\"BUY\", \"hash\":\"6af2f2746c27827552e51f8c523f33343c208390\", \"best_bid\":\"0.45\", \"best_ask\":\"0.46\"}, {\"asset_id\":\"107011546575057755426871645700605806081353395825571114128343592072429146374928\", \"price\":\"0.55\", \"size\":\"596.03\", \"side\":\"SELL\", \"hash\":\"43f797cdc8a732315f983680c85d6738951e490a\", \"best_bid\":\"0.54\", \"best_ask\":\"0.55\"}], \"timestamp\":\"1781254836952\", \"event_type\":\"price_change\"}","ts_local_ms":1781254837644}
{"dir":"in","text":"{\"market\":\"0x9c535590faae21bf76fed844aa47fc3c5c82253ef38bd545bf12c93470502685\", \"price_changes\":[{\"asset_id\":\"107011546575057755426871645700605806081353395825571114128343592072429146374928\", \"price\":\"0.54\", \"size\":\"476.52\", \"side\":\"BUY\", \"hash\":\"037f757176ab00e91222305572cac1743ca6b80d\", \"best_bid\":\"0.54\", \"best_ask\":\"0.55\"}, {\"asset_id\":\"56108879726720646120583724001239294777304794469144970684362785767667828318889\", \"price\":\"0.46\", \"size\":\"476.52\", \"side\":\"SELL\", \"hash\":\"56200b7400a5ab26a6d84822c28857c4d5be9536\", \"best_bid\":\"0.45\", \"best_ask\":\"0.46\"}], \"timestamp\":\"1781254836954\", \"event_type\":\"price_change\"}","ts_local_ms":1781254837644}
{"dir":"in","text":"{\"market\":\"0x9c535590faae21bf76fed844aa47fc3c5c82253ef38bd545bf12c93470502685\", \"price_changes\":[{\"asset_id\":\"56108879726720646120583724001239294777304794469144970684362785767667828318889\", \"price\":\"0.39\", \"size\":\"449\", \"side\":\"BUY\", \"hash\":\"f5050dca7719f1806835b701aa646d3bfee919a1\", \"best_bid\":\"0.45\", \"best_ask\":\"0.46\"}, {\"asset_id\":\"107011546575057755426871645700605806081353395825571114128343592072429146374928\", \"price\":\"0.61\", \"size\":\"449\", \"side\":\"SELL\", \"hash\":\"b8a1bd31b55d4e21b73104336c9de9d80b5cc1f0\", \"best_bid\":\"0.54\", \"best_ask\":\"0.55\"}], \"timestamp\":\"1781254836956\", \"event_type\":\"price_change\"}","ts_local_ms":1781254837644}
{"dir":"in","text":"{\"market\":\"0x9c535590faae21bf76fed844aa47fc3c5c82253ef38bd545bf12c93470502685\", \"price_changes\":[{\"asset_id\":\"107011546575057755426871645700605806081353395825571114128343592072429146374928\", \"price\":\"0.54\", \"size\":\"471.52\", \"side\":\"BUY\", \"hash\":\"5452ce353c546a443a040932b7f93d1192e5f512\", \"best_bid\":\"0.54\", \"best_ask\":\"0.55\"}, {\"asset_id\":\"56108879726720646120583724001239294777304794469144970684362785767667828318889\", \"price\":\"0.46\", \"size\":\"471.52\", \"side\":\"SELL\", \"hash\":\"e195227188beae86323313e7497d92d72c9597ea\", \"best_bid\":\"0.45\", \"best_ask\":\"0.46\"}], \"timestamp\":\"1781254836958\", \"event_type\":\"price_change\"}","ts_local_ms":1781254837644}
{"dir":"in","text":"{\"market\":\"0x9c535590faae21bf76fed844aa47fc3c5c82253ef38bd545bf12c93470502685\", \"price_changes\":[{\"asset_id\":\"107011546575057755426871645700605806081353395825571114128343592072429146374928\", \"price\":\"0.54\", \"size\":\"462.52\", \"side\":\"BUY\", \"hash\":\"be5a7f4047bda98b149e50e9f1071490a88eff94\", \"best_bid\":\"0.54\", \"best_ask\":\"0.55\"}, {\"asset_id\":\"56108879726720646120583724001239294777304794469144970684362785767667828318889\", \"price\":\"0.46\", \"size\":\"462.52\", \"side\":\"SELL\", \"hash\":\"c85b70fcf0ba368b73be7f1e011a00c80015ea66\", \"best_bid\":\"0.45\", \"best_ask\":\"0.46\"}], \"timestamp\":\"1781254836959\", \"event_type\":\"price_change\"}","ts_local_ms":1781254837644}
{"dir":"in","text":"{\"market\":\"0x9c535590faae21bf76fed844aa47fc3c5c82253ef38bd545bf12c93470502685\", \"price_changes\":[{\"asset_id\":\"107011546575057755426871645700605806081353395825571114128343592072429146374928\", \"price\":\"0.01\", \"size\":\"55006.6\", \"side\":\"BUY\", \"hash\":\"a1faef8188b5f35b167a125db2c109b185cb7f3b\", \"best_bid\":\"0.54\", \"best_ask\":\"0.55\"}, {\"asset_id\":\"56108879726720646120583724001239294777304794469144970684362785767667828318889\", \"price\":\"0.99\", \"size\":\"55006.6\", \"side\":\"SELL\", \"hash\":\"f52b4d12ec1b8a3397b1110560205ad06c241d7d\", \"best_bid\":\"0.45\", \"best_ask\":\"0.46\"}], \"timestamp\":\"1781254836959\", \"event_type\":\"price_change\"}","ts_local_ms":1781254837644}
{"dir":"in","text":"{\"market\":\"0x9c535590faae21bf76fed844aa47fc3c5c82253ef38bd545bf12c93470502685\", \"price_changes\":[{\"asset_id\":\"107011546575057755426871645700605806081353395825571114128343592072429146374928\", \"price\":\"0.37\", \"size\":\"156.6\", \"side\":\"BUY\", \"hash\":\"a358ea82df3fde43c2f1a579e840a6ca3816544e\", \"best_bid\":\"0.54\", \"best_ask\":\"0.55\"}, {\"asset_id\":\"56108879726720646120583724001239294777304794469144970684362785767667828318889\", \"price\":\"0.63\", \"size\":\"156.6\", \"side\":\"SELL\", \"hash\":\"18c0cf5574c482dae41cad47e6e400e823934c5a\", \"best_bid\":\"0.45\", \"best_ask\":\"0.46\"}], \"timestamp\":\"1781254836960\", \"event_type\":\"price_change\"}","ts_local_ms":1781254837644}
{"dir":"in","text":"{\"market\":\"0x9c535590faae21bf76fed844aa47fc3c5c82253ef38bd545bf12c93470502685\", \"price_changes\":[{\"asset_id\":\"56108879726720646120583724001239294777304794469144970684362785767667828318889\", \"price\":\"0.36\", \"size\":\"316\", \"side\":\"BUY\", \"hash\":\"47608aa9742fc7cf52537e0077a8355b5f2eb173\", \"best_bid\":\"0.45\", \"best_ask\":\"0.46\"}, {\"asset_id\":\"107011546575057755426871645700605806081353395825571114128343592072429146374928\", \"price\":\"0.64\", \"size\":\"316\", \"side\":\"SELL\", \"hash\":\"f0b81af0897021d7feb0158fe55b4ca49c3a463c\", \"best_bid\":\"0.54\", \"best_ask\":\"0.55\"}], \"timestamp\":\"1781254836961\", \"event_type\":\"price_change\"}","ts_local_ms":1781254837644}
{"dir":"in","text":"{\"market\":\"0x9c535590faae21bf76fed844aa47fc3c5c82253ef38bd545bf12c93470502685\", \"price_changes\":[{\"asset_id\":\"107011546575057755426871645700605806081353395825571114128343592072429146374928\", \"price\":\"0.54\", \"size\":\"457.52\", \"side\":\"BUY\", \"hash\":\"450a180a8a339faf0c013280bfbb7bd29a8e1b15\", \"best_bid\":\"0.54\", \"best_ask\":\"0.55\"}, {\"asset_id\":\"56108879726720646120583724001239294777304794469144970684362785767667828318889\", \"price\":\"0.46\", \"size\":\"457.52\", \"side\":\"SELL\", \"hash\":\"d0fad7da237a18979168f794aa819078e425df4d\", \"best_bid\":\"0.45\", \"best_ask\":\"0.46\"}], \"timestamp\":\"1781254836962\", \"event_type\":\"price_change\"}","ts_local_ms":1781254837644}
{"dir":"in","text":"{\"market\":\"0x9c535590faae21bf76fed844aa47fc3c5c82253ef38bd545bf12c93470502685\", \"price_changes\":[{\"asset_id\":\"56108879726720646120583724001239294777304794469144970684362785767667828318889\", \"price\":\"0.45\", \"size\":\"589.78\", \"side\":\"BUY\", \"hash\":\"a27f4aca287bc7b9b4751adff95c3c5ad5434752\", \"best_bid\":\"0.45\", \"best_ask\":\"0.46\"}, {\"asset_id\":\"107011546575057755426871645700605806081353395825571114128343592072429146374928\", \"price\":\"0.55\", \"size\":\"589.78\", \"side\":\"SELL\", \"hash\":\"17b4cb64175b32ac4f0df6905973fda97eee8402\", \"best_bid\":\"0.54\", \"best_ask\":\"0.55\"}], \"timestamp\":\"1781254836963\", \"event_type\":\"price_change\"}","ts_local_ms":1781254837644}
{"dir":"in","text":"{\"market\":\"0x9c535590faae21bf76fed844aa47fc3c5c82253ef38bd545bf12c93470502685\", \"price_changes\":[{\"asset_id\":\"56108879726720646120583724001239294777304794469144970684362785767667828318889\", \"price\":\"0.19\", \"size\":\"104.67\", \"side\":\"BUY\", \"hash\":\"1ae9263ba0f7aeddd55cf304f071dec31024d0fc\", \"best_bid\":\"0.45\", \"best_ask\":\"0.46\"}, {\"asset_id\":\"107011546575057755426871645700605806081353395825571114128343592072429146374928\", \"price\":\"0.81\", \"size\":\"104.67\", \"side\":\"SELL\", \"hash\":\"10ec821fdd91337be6c31ed48b3caa3324fa9881\", \"best_bid\":\"0.54\", \"best_ask\":\"0.55\"}], \"timestamp\":\"1781254836964\", \"event_type\":\"price_change\"}","ts_local_ms":1781254837644}
{"dir":"in","text":"{\"market\":\"0x9c535590faae21bf76fed844aa47fc3c5c82253ef38bd545bf12c93470502685\", \"price_changes\":[{\"asset_id\":\"107011546575057755426871645700605806081353395825571114128343592072429146374928\", \"price\":\"0.54\", \"size\":\"452.52\", \"side\":\"BUY\", \"hash\":\"3a1e8a70d47482bc4d1c035207d2119745ddbf90\", \"best_bid\":\"0.54\", \"best_ask\":\"0.55\"}, {\"asset_id\":\"56108879726720646120583724001239294777304794469144970684362785767667828318889\", \"price\":\"0.46\", \"size\":\"452.52\", \"side\":\"SELL\", \"hash\":\"d8757cba0ed3160734abfa0c3fa1d3a4def6115c\", \"best_bid\":\"0.45\", \"best_ask\":\"0.46\"}], \"timestamp\":\"1781254836965\", \"event_type\":\"price_change\"}","ts_local_ms":1781254837644}
{"dir":"in","text":"{\"market\":\"0x9c535590faae21bf76fed844aa47fc3c5c82253ef38bd545bf12c93470502685\", \"price_changes\":[{\"asset_id\":\"107011546575057755426871645700605806081353395825571114128343592072429146374928\", \"price\":\"0.41\", \"size\":\"536.4\", \"side\":\"BUY\", \"hash\":\"7e3b4e803dad2768d8a1f81bcb8ffd13581c2c87\", \"best_bid\":\"0.54\", \"best_ask\":\"0.55\"}, {\"asset_id\":\"56108879726720646120583724001239294777304794469144970684362785767667828318889\", \"price\":\"0.59\", \"size\":\"536.4\", \"side\":\"SELL\", \"hash\":\"286429205508cfc625689a82626971f95d32f93e\", \"best_bid\":\"0.45\", \"best_ask\":\"0.46\"}], \"timestamp\":\"1781254836965\", \"event_type\":\"price_change\"}","ts_local_ms":1781254837644}
{"dir":"in","text":"{\"market\":\"0x9c535590faae21bf76fed844aa47fc3c5c82253ef38bd545bf12c93470502685\", \"price_changes\":[{\"asset_id\":\"107011546575057755426871645700605806081353395825571114128343592072429146374928\", \"price\":\"0.54\", \"size\":\"447.52\", \"side\":\"BUY\", \"hash\":\"8fbc69d138626d5751b4270755733ecbf7bd1b83\", \"best_bid\":\"0.54\", \"best_ask\":\"0.55\"}, {\"asset_id\":\"56108879726720646120583724001239294777304794469144970684362785767667828318889\", \"price\":\"0.46\", \"size\":\"447.52\", \"side\":\"SELL\", \"hash\":\"9c1bbcc41ed775b6a80d47764e2847a2e769d191\", \"best_bid\":\"0.45\", \"best_ask\":\"0.46\"}], \"timestamp\":\"1781254836969\", \"event_type\":\"price_change\"}","ts_local_ms":1781254837645}
{"dir":"in","text":"{\"market\":\"0x9c535590faae21bf76fed844aa47fc3c5c82253ef38bd545bf12c93470502685\", \"price_changes\":[{\"asset_id\":\"107011546575057755426871645700605806081353395825571114128343592072429146374928\", \"price\":\"0.52\", \"size\":\"141.37\", \"side\":\"BUY\", \"hash\":\"2395aedb9c25dcd9b897625aa1de3411d4ee2e97\", \"best_bid\":\"0.54\", \"best_ask\":\"0.55\"}, {\"asset_id\":\"56108879726720646120583724001239294777304794469144970684362785767667828318889\", \"price\":\"0.48\", \"size\":\"141.37\", \"side\":\"SELL\", \"hash\":\"1430a3359315f0c2b4c9412099ded48e67a5314d\", \"best_bid\":\"0.45\", \"best_ask\":\"0.46\"}], \"timestamp\":\"1781254836971\", \"event_type\":\"price_change\"}","ts_local_ms":1781254837645}
{"dir":"in","text":"{\"market\":\"0x9c535590faae21bf76fed844aa47fc3c5c82253ef38bd545bf12c93470502685\", \"price_changes\":[{\"asset_id\":\"107011546575057755426871645700605806081353395825571114128343592072429146374928\", \"price\":\"0.54\", \"size\":\"397.52\", \"side\":\"BUY\", \"hash\":\"e2a498c0ba52759ecd25235a8dae9b2446c05b20\", \"best_bid\":\"0.54\", \"best_ask\":\"0.55\"}, {\"asset_id\":\"56108879726720646120583724001239294777304794469144970684362785767667828318889\", \"price\":\"0.46\", \"size\":\"397.52\", \"side\":\"SELL\", \"hash\":\"8c78cfb07ffb64f9ef2de92b0d95ba61d51809ff\", \"best_bid\":\"0.45\", \"best_ask\":\"0.46\"}], \"timestamp\":\"1781254836971\", \"event_type\":\"price_change\"}","ts_local_ms":1781254837645}
{"dir":"in","text":"{\"market\":\"0x9c535590faae21bf76fed844aa47fc3c5c82253ef38bd545bf12c93470502685\", \"price_changes\":[{\"asset_id\":\"56108879726720646120583724001239294777304794469144970684362785767667828318889\", \"price\":\"0.45\", \"size\":\"601.78\", \"side\":\"BUY\", \"hash\":\"cd6a48f813fc2ee4456a3b5f78f79b85f9997069\", \"best_bid\":\"0.45\", \"best_ask\":\"0.46\"}, {\"asset_id\":\"107011546575057755426871645700605806081353395825571114128343592072429146374928\", \"price\":\"0.55\", \"size\":\"601.78\", \"side\":\"SELL\", \"hash\":\"22060abf3d479369f929b8b8bed828bd2f59286e\", \"best_bid\":\"0.54\", \"best_ask\":\"0.55\"}], \"timestamp\":\"1781254836972\", \"event_type\":\"price_change\"}","ts_local_ms":1781254837645}
{"dir":"in","text":"{\"market\":\"0x9c535590faae21bf76fed844aa47fc3c5c82253ef38bd545bf12c93470502685\", \"price_changes\":[{\"asset_id\":\"107011546575057755426871645700605806081353395825571114128343592072429146374928\", \"price\":\"0.52\", \"size\":\"116.37\", \"side\":\"BUY\", \"hash\":\"09a3e23af7f3bcb0619e14660da12cd75a7c8700\", \"best_bid\":\"0.54\", \"best_ask\":\"0.55\"}, {\"asset_id\":\"56108879726720646120583724001239294777304794469144970684362785767667828318889\", \"price\":\"0.48\", \"size\":\"116.37\", \"side\":\"SELL\", \"hash\":\"37d9299cb0c515957ed43feb4adf0f3cca78b0e3\", \"best_bid\":\"0.45\", \"best_ask\":\"0.46\"}], \"timestamp\":\"1781254836972\", \"event_type\":\"price_change\"}","ts_local_ms":1781254837645}
{"dir":"in","text":"{\"market\":\"0x9c535590faae21bf76fed844aa47fc3c5c82253ef38bd545bf12c93470502685\", \"price_changes\":[{\"asset_id\":\"107011546575057755426871645700605806081353395825571114128343592072429146374928\", \"price\":\"0.54\", \"size\":\"388.52\", \"side\":\"BUY\", \"hash\":\"6b6987690524a839a329702264746ef45160d4d2\", \"best_bid\":\"0.54\", \"best_ask\":\"0.55\"}, {\"asset_id\":\"56108879726720646120583724001239294777304794469144970684362785767667828318889\", \"price\":\"0.46\", \"size\":\"388.52\", \"side\":\"SELL\", \"hash\":\"0191c7a17e6e243feb45ea2d2d9b73440264cea5\", \"best_bid\":\"0.45\", \"best_ask\":\"0.46\"}], \"timestamp\":\"1781254836973\", \"event_type\":\"price_change\"}","ts_local_ms":1781254837645}
{"dir":"in","text":"{\"market\":\"0x9c535590faae21bf76fed844aa47fc3c5c82253ef38bd545bf12c93470502685\", \"asset_id\":\"107011546575057755426871645700605806081353395825571114128343592072429146374928\", \"price\":\"0.55\", \"size\":\"10.181817\", \"fee_rate_bps\":\"0\", \"side\":\"BUY\", \"timestamp\":\"1781254836763\", \"event_type\":\"last_trade_price\", \"transaction_hash\":\"0x8ac2267e16a8d0efd8eaf4754d222950febb1180b9ef1a3c157f6f822d0a6b05\"}","ts_local_ms":1781254837645}
{"dir":"in","text":"{\"market\":\"0x9c535590faae21bf76fed844aa47fc3c5c82253ef38bd545bf12c93470502685\", \"price_changes\":[{\"asset_id\":\"107011546575057755426871645700605806081353395825571114128343592072429146374928\", \"price\":\"0.01\", \"size\":\"55012.6\", \"side\":\"BUY\", \"hash\":\"fd5d6adb7f535fcd3179b4f5cc6acfa32a1d9ce2\", \"best_bid\":\"0.54\", \"best_ask\":\"0.55\"}, {\"asset_id\":\"56108879726720646120583724001239294777304794469144970684362785767667828318889\", \"price\":\"0.99\", \"size\":\"55012.6\", \"side\":\"SELL\", \"hash\":\"37b4b6ddcb4826c8a4060853f5faec27dff5a23e\", \"best_bid\":\"0.45\", \"best_ask\":\"0.46\"}], \"timestamp\":\"1781254836980\", \"event_type\":\"price_change\"}","ts_local_ms":1781254837645}
{"dir":"in","text":"{\"market\":\"0x9c535590faae21bf76fed844aa47fc3c5c82253ef38bd545bf12c93470502685\", \"price_changes\":[{\"asset_id\":\"56108879726720646120583724001239294777304794469144970684362785767667828318889\", \"price\":\"0.45\", \"size\":\"606.8\", \"side\":\"BUY\", \"hash\":\"cdc03c9e8a280d5bc27645ee21b76d5574bd1c8b\", \"best_bid\":\"0.45\", \"best_ask\":\"0.46\"}, {\"asset_id\":\"107011546575057755426871645700605806081353395825571114128343592072429146374928\", \"price\":\"0.55\", \"size\":\"606.8\", \"side\":\"SELL\", \"hash\":\"d897f0a1c9eeb7ec7ca7b7138d3b929b5bca610f\", \"best_bid\":\"0.54\", \"best_ask\":\"0.55\"}], \"timestamp\":\"1781254836980\", \"event_type\":\"price_change\"}","ts_local_ms":1781254837645}
{"dir":"in","text":"{\"market\":\"0x9c535590faae21bf76fed844aa47fc3c5c82253ef38bd545bf12c93470502685\", \"price_changes\":[{\"asset_id\":\"56108879726720646120583724001239294777304794469144970684362785767667828318889\", \"price\":\"0.45\", \"size\":\"618.8\", \"side\":\"BUY\", \"hash\":\"2083a0ee0f56fd8a09b556b917710e7c8fb37ec3\", \"best_bid\":\"0.45\", \"best_ask\":\"0.46\"}, {\"asset_id\":\"107011546575057755426871645700605806081353395825571114128343592072429146374928\", \"price\":\"0.55\", \"size\":\"618.8\", \"side\":\"SELL\", \"hash\":\"fabb7f722121bf763f7d6f983bda0560ff516520\", \"best_bid\":\"0.54\", \"best_ask\":\"0.55\"}], \"timestamp\":\"1781254836981\", \"event_type\":\"price_change\"}","ts_local_ms":1781254837645}
{"dir":"in","text":"{\"market\":\"0x9c535590faae21bf76fed844aa47fc3c5c82253ef38bd545bf12c93470502685\", \"price_changes\":[{\"asset_id\":\"107011546575057755426871645700605806081353395825571114128343592072429146374928\", \"price\":\"0.52\", \"size\":\"141.37\", \"side\":\"BUY\", \"hash\":\"0af1a89b36114c83dd01c3d2660e5a30c8543a11\", \"best_bid\":\"0.54\", \"best_ask\":\"0.55\"}, {\"asset_id\":\"56108879726720646120583724001239294777304794469144970684362785767667828318889\", \"price\":\"0.48\", \"size\":\"141.37\", \"side\":\"SELL\", \"hash\":\"d82d7e3f2382582d49ad51a9e32af748a89cd89e\", \"best_bid\":\"0.45\", \"best_ask\":\"0.46\"}], \"timestamp\":\"1781254836984\", \"event_type\":\"price_change\"}","ts_local_ms":1781254837645}
{"dir":"in","text":"{\"market\":\"0x9c535590faae21bf76fed844aa47fc3c5c82253ef38bd545bf12c93470502685\", \"price_changes\":[{\"asset_id\":\"107011546575057755426871645700605806081353395825571114128343592072429146374928\", \"price\":\"0.54\", \"size\":\"383.52\", \"side\":\"BUY\", \"hash\":\"5e094a1672057a6c6d1feb8c4a918e392ca2468c\", \"best_bid\":\"0.54\", \"best_ask\":\"0.55\"}, {\"asset_id\":\"56108879726720646120583724001239294777304794469144970684362785767667828318889\", \"price\":\"0.46\", \"size\":\"383.52\", \"side\":\"SELL\", \"hash\":\"f1aee9218bf9dcf5c10c7f892c34a758b1cc5598\", \"best_bid\":\"0.45\", \"best_ask\":\"0.46\"}], \"timestamp\":\"1781254836985\", \"event_type\":\"price_change\"}","ts_local_ms":1781254837645}
{"dir":"in","text":"{\"market\":\"0x9c535590faae21bf76fed844aa47fc3c5c82253ef38bd545bf12c93470502685\", \"price_changes\":[{\"asset_id\":\"56108879726720646120583724001239294777304794469144970684362785767667828318889\", \"price\":\"0.45\", \"size\":\"613.8\", \"side\":\"BUY\", \"hash\":\"e11ba8c1766a822d8c64d006f23e83c1d4cfdb30\", \"best_bid\":\"0.45\", \"best_ask\":\"0.46\"}, {\"asset_id\":\"107011546575057755426871645700605806081353395825571114128343592072429146374928\", \"price\":\"0.55\", \"size\":\"613.8\", \"side\":\"SELL\", \"hash\":\"c263c037436b8e2d0faa22a2208af9ccd292f6aa\", \"best_bid\":\"0.54\", \"best_ask\":\"0.55\"}], \"timestamp\":\"1781254836985\", \"event_type\":\"price_change\"}","ts_local_ms":1781254837645}
{"dir":"in","text":"{\"market\":\"0x9c535590faae21bf76fed844aa47fc3c5c82253ef38bd545bf12c93470502685\", \"price_changes\":[{\"asset_id\":\"56108879726720646120583724001239294777304794469144970684362785767667828318889\", \"price\":\"0.45\", \"size\":\"625.8\", \"side\":\"BUY\", \"hash\":\"d3ff46f1e3ebd3c4ec7dc0ba40ea3cdb18517abf\", \"best_bid\":\"0.45\", \"best_ask\":\"0.46\"}, {\"asset_id\":\"107011546575057755426871645700605806081353395825571114128343592072429146374928\", \"price\":\"0.55\", \"size\":\"625.8\", \"side\":\"SELL\", \"hash\":\"7485c89bc75ddac17155825cca3bd9e4d7227cd7\", \"best_bid\":\"0.54\", \"best_ask\":\"0.55\"}], \"timestamp\":\"1781254836985\", \"event_type\":\"price_change\"}","ts_local_ms":1781254837645}
{"dir":"in","text":"{\"market\":\"0x9c535590faae21bf76fed844aa47fc3c5c82253ef38bd545bf12c93470502685\", \"price_changes\":[{\"asset_id\":\"107011546575057755426871645700605806081353395825571114128343592072429146374928\", \"price\":\"0.52\", \"size\":\"116.37\", \"side\":\"BUY\", \"hash\":\"a3e6e5c2a04761616fd641eca53d7fdc11dfab04\", \"best_bid\":\"0.54\", \"best_ask\":\"0.55\"}, {\"asset_id\":\"56108879726720646120583724001239294777304794469144970684362785767667828318889\", \"price\":\"0.48\", \"size\":\"116.37\", \"side\":\"SELL\", \"hash\":\"4063984be488428fa045d44d0449f4bee9ba01a8\", \"best_bid\":\"0.45\", \"best_ask\":\"0.46\"}], \"timestamp\":\"1781254836986\", \"event_type\":\"price_change\"}","ts_local_ms":1781254837645}
{"dir":"in","text":"{\"market\":\"0x9c535590faae21bf76fed844aa47fc3c5c82253ef38bd545bf12c93470502685\", \"price_changes\":[{\"asset_id\":\"56108879726720646120583724001239294777304794469144970684362785767667828318889\", \"price\":\"0.39\", \"size\":\"440\", \"side\":\"BUY\", \"hash\":\"96461c400781c92c690c266c5553b5eea043cce5\", \"best_bid\":\"0.45\", \"best_ask\":\"0.46\"}, {\"asset_id\":\"107011546575057755426871645700605806081353395825571114128343592072429146374928\", \"price\":\"0.61\", \"size\":\"440\", \"side\":\"SELL\", \"hash\":\"2cd94118bb92e0351cf98831d9f991af4f6c1294\", \"best_bid\":\"0.54\", \"best_ask\":\"0.55\"}], \"timestamp\":\"1781254836987\", \"event_type\":\"price_change\"}","ts_local_ms":1781254837645}
{"dir":"in","text":"{\"market\":\"0x9c535590faae21bf76fed844aa47fc3c5c82253ef38bd545bf12c93470502685\", \"price_changes\":[{\"asset_id\":\"56108879726720646120583724001239294777304794469144970684362785767667828318889\", \"price\":\"0.4\", \"size\":\"311\", \"side\":\"BUY\", \"hash\":\"96461c400781c92c690c266c5553b5eea043cce5\", \"best_bid\":\"0.45\", \"best_ask\":\"0.46\"}, {\"asset_id\":\"107011546575057755426871645700605806081353395825571114128343592072429146374928\", \"price\":\"0.6\", \"size\":\"311\", \"side\":\"SELL\", \"hash\":\"2cd94118bb92e0351cf98831d9f991af4f6c1294\", \"best_bid\":\"0.54\", \"best_ask\":\"0.55\"}], \"timestamp\":\"1781254836987\", \"event_type\":\"price_change\"}","ts_local_ms":1781254837645}
{"dir":"in","text":"{\"market\":\"0x9c535590faae21bf76fed844aa47fc3c5c82253ef38bd545bf12c93470502685\", \"price_changes\":[{\"asset_id\":\"107011546575057755426871645700605806081353395825571114128343592072429146374928\", \"price\":\"0.37\", \"size\":\"91.6\", \"side\":\"BUY\", \"hash\":\"c005cc518129c446fcaf26b429ee42a8a997fffa\", \"best_bid\":\"0.54\", \"best_ask\":\"0.55\"}, {\"asset_id\":\"56108879726720646120583724001239294777304794469144970684362785767667828318889\", \"price\":\"0.63\", \"size\":\"91.6\", \"side\":\"SELL\", \"hash\":\"bd0d0ee41cc08f80d5cfd13c3e783666ee778d46\", \"best_bid\":\"0.45\", \"best_ask\":\"0.46\"}], \"timestamp\":\"1781254836989\", \"event_type\":\"price_change\"}","ts_local_ms":1781254837645}
{"dir":"in","text":"{\"market\":\"0x9c535590faae21bf76fed844aa47fc3c5c82253ef38bd545bf12c93470502685\", \"price_changes\":[{\"asset_id\":\"56108879726720646120583724001239294777304794469144970684362785767667828318889\", \"price\":\"0.19\", \"size\":\"39.67\", \"side\":\"BUY\", \"hash\":\"6ce192017561ace0566a2edf8e502e31f70eadf0\", \"best_bid\":\"0.45\", \"best_ask\":\"0.46\"}, {\"asset_id\":\"107011546575057755426871645700605806081353395825571114128343592072429146374928\", \"price\":\"0.81\", \"size\":\"39.67\", \"side\":\"SELL\", \"hash\":\"85828ed8df2d720672f7ce8492b2c8f8e132b002\", \"best_bid\":\"0.54\", \"best_ask\":\"0.55\"}], \"timestamp\":\"1781254836989\", \"event_type\":\"price_change\"}","ts_local_ms":1781254837645}
{"dir":"in","text":"{\"market\":\"0x9c535590faae21bf76fed844aa47fc3c5c82253ef38bd545bf12c93470502685\", \"price_changes\":[{\"asset_id\":\"56108879726720646120583724001239294777304794469144970684362785767667828318889\", \"price\":\"0.45\", \"size\":\"401.39\", \"side\":\"BUY\", \"hash\":\"00e0d462398241fc16c1f77b23f04ebf9f599143\", \"best_bid\":\"0.45\", \"best_ask\":\"0.46\"}, {\"asset_id\":\"107011546575057755426871645700605806081353395825571114128343592072429146374928\", \"price\":\"0.55\", \"size\":\"401.39\", \"side\":\"SELL\", \"hash\":\"70bc5c4107a8ba438b38f9fcbf60a1a2bf92edd2\", \"best_bid\":\"0.54\", \"best_ask\":\"0.55\"}], \"timestamp\":\"1781254836991\", \"event_type\":\"price_change\"}","ts_local_ms":1781254837645}
{"dir":"in","text":"{\"market\":\"0x9c535590faae21bf76fed844aa47fc3c5c82253ef38bd545bf12c93470502685\", \"price_changes\":[{\"asset_id\":\"56108879726720646120583724001239294777304794469144970684362785767667828318889\", \"price\":\"0.45\", \"size\":\"414.39\", \"side\":\"BUY\", \"hash\":\"37cd72d4459018dd9ce17eca8968f249cfaf556c\", \"best_bid\":\"0.45\", \"best_ask\":\"0.46\"}, {\"asset_id\":\"107011546575057755426871645700605806081353395825571114128343592072429146374928\", \"price\":\"0.55\", \"size\":\"414.39\", \"side\":\"SELL\", \"hash\":\"ee8f8bb5928d08bfbbc6d46164ec07d228b698be\", \"best_bid\":\"0.54\", \"best_ask\":\"0.55\"}], \"timestamp\":\"1781254836992\", \"event_type\":\"price_change\"}","ts_local_ms":1781254837645}
{"dir":"in","text":"{\"market\":\"0x9c535590faae21bf76fed844aa47fc3c5c82253ef38bd545bf12c93470502685\", \"price_changes\":[{\"asset_id\":\"56108879726720646120583724001239294777304794469144970684362785767667828318889\", \"price\":\"0.45\", \"size\":\"427.39\", \"side\":\"BUY\", \"hash\":\"b457e649eea765f7cbb8de195f821860d6470868\", \"best_bid\":\"0.45\", \"best_ask\":\"0.46\"}, {\"asset_id\":\"107011546575057755426871645700605806081353395825571114128343592072429146374928\", \"price\":\"0.55\", \"size\":\"427.39\", \"side\":\"SELL\", \"hash\":\"11b26602b5ea81afbc3b184dd207fa22973f1166\", \"best_bid\":\"0.54\", \"best_ask\":\"0.55\"}], \"timestamp\":\"1781254836994\", \"event_type\":\"price_change\"}","ts_local_ms":1781254837645}
{"dir":"in","text":"{\"market\":\"0x9c535590faae21bf76fed844aa47fc3c5c82253ef38bd545bf12c93470502685\", \"price_changes\":[{\"asset_id\":\"56108879726720646120583724001239294777304794469144970684362785767667828318889\", \"price\":\"0.45\", \"size\":\"440.39\", \"side\":\"BUY\", \"hash\":\"88c405ae727ab0798ae85f0c3eb854587766803f\", \"best_bid\":\"0.45\", \"best_ask\":\"0.46\"}, {\"asset_id\":\"107011546575057755426871645700605806081353395825571114128343592072429146374928\", \"price\":\"0.55\", \"size\":\"440.39\", \"side\":\"SELL\", \"hash\":\"2a8a0132814c51a2475c75d94d1e1b68d47f80e5\", \"best_bid\":\"0.54\", \"best_ask\":\"0.55\"}], \"timestamp\":\"1781254836994\", \"event_type\":\"price_change\"}","ts_local_ms":1781254837645}
{"dir":"in","text":"{\"market\":\"0x9c535590faae21bf76fed844aa47fc3c5c82253ef38bd545bf12c93470502685\", \"price_changes\":[{\"asset_id\":\"56108879726720646120583724001239294777304794469144970684362785767667828318889\", \"price\":\"0.45\", \"size\":\"453.39\", \"side\":\"BUY\", \"hash\":\"49e4c352958367b41d4970fa8458ab3f39b0e428\", \"best_bid\":\"0.45\", \"best_ask\":\"0.46\"}, {\"asset_id\":\"107011546575057755426871645700605806081353395825571114128343592072429146374928\", \"price\":\"0.55\", \"size\":\"453.39\", \"side\":\"SELL\", \"hash\":\"c685f5fa9ae8d3ebccc7c38ff4a8e82ff325fcb3\", \"best_bid\":\"0.54\", \"best_ask\":\"0.55\"}], \"timestamp\":\"1781254836995\", \"event_type\":\"price_change\"}","ts_local_ms":1781254837646}
{"dir":"in","text":"{\"market\":\"0x9c535590faae21bf76fed844aa47fc3c5c82253ef38bd545bf12c93470502685\", \"price_changes\":[{\"asset_id\":\"56108879726720646120583724001239294777304794469144970684362785767667828318889\", \"price\":\"0.45\", \"size\":\"465.39\", \"side\":\"BUY\", \"hash\":\"6dea367132d09dad8affe01a842417e3a239ca75\", \"best_bid\":\"0.45\", \"best_ask\":\"0.46\"}, {\"asset_id\":\"107011546575057755426871645700605806081353395825571114128343592072429146374928\", \"price\":\"0.55\", \"size\":\"465.39\", \"side\":\"SELL\", \"hash\":\"5aab33173657b81b1c67f1c25a06fd57e1eb2588\", \"best_bid\":\"0.54\", \"best_ask\":\"0.55\"}], \"timestamp\":\"1781254836998\", \"event_type\":\"price_change\"}","ts_local_ms":1781254837646}
{"dir":"in","text":"{\"market\":\"0x9c535590faae21bf76fed844aa47fc3c5c82253ef38bd545bf12c93470502685\", \"price_changes\":[{\"asset_id\":\"56108879726720646120583724001239294777304794469144970684362785767667828318889\", \"price\":\"0.45\", \"size\":\"493.39\", \"side\":\"BUY\", \"hash\":\"73781b7db26bada1b3a75d764e919e0b8ffbb68c\", \"best_bid\":\"0.45\", \"best_ask\":\"0.46\"}, {\"asset_id\":\"107011546575057755426871645700605806081353395825571114128343592072429146374928\", \"price\":\"0.55\", \"size\":\"493.39\", \"side\":\"SELL\", \"hash\":\"7a6c672625ff55bc9d1969cf437113d89ad99f0d\", \"best_bid\":\"0.54\", \"best_ask\":\"0.55\"}], \"timestamp\":\"1781254836999\", \"event_type\":\"price_change\"}","ts_local_ms":1781254837646}
{"dir":"in","text":"{\"market\":\"0x9c535590faae21bf76fed844aa47fc3c5c82253ef38bd545bf12c93470502685\", \"price_changes\":[{\"asset_id\":\"107011546575057755426871645700605806081353395825571114128343592072429146374928\", \"price\":\"0.54\", \"size\":\"378.52\", \"side\":\"BUY\", \"hash\":\"2d702475d6ad8e4bf21e00f302cb2c10f10d23e3\", \"best_bid\":\"0.54\", \"best_ask\":\"0.55\"}, {\"asset_id\":\"56108879726720646120583724001239294777304794469144970684362785767667828318889\", \"price\":\"0.46\", \"size\":\"378.52\", \"side\":\"SELL\", \"hash\":\"9fa5ca4009c75ad9736aa121fc4d1d69f0ad5922\", \"best_bid\":\"0.45\", \"best_ask\":\"0.46\"}], \"timestamp\":\"1781254837025\", \"event_type\":\"price_change\"}","ts_local_ms":1781254837646}
{"dir":"in","text":"{\"market\":\"0x9c535590faae21bf76fed844aa47fc3c5c82253ef38bd545bf12c93470502685\", \"price_changes\":[{\"asset_id\":\"56108879726720646120583724001239294777304794469144970684362785767667828318889\", \"price\":\"0.39\", \"size\":\"365\", \"side\":\"BUY\", \"hash\":\"9fa5ca4009c75ad9736aa121fc4d1d69f0ad5922\", \"best_bid\":\"0.45\", \"best_ask\":\"0.46\"}, {\"asset_id\":\"107011546575057755426871645700605806081353395825571114128343592072429146374928\", \"price\":\"0.61\", \"size\":\"365\", \"side\":\"SELL\", \"hash\":\"2d702475d6ad8e4bf21e00f302cb2c10f10d23e3\", \"best_bid\":\"0.54\", \"best_ask\":\"0.55\"}], \"timestamp\":\"1781254837025\", \"event_type\":\"price_change\"}","ts_local_ms":1781254837646}
{"dir":"in","text":"{\"market\":\"0x9c535590faae21bf76fed844aa47fc3c5c82253ef38bd545bf12c93470502685\", \"price_changes\":[{\"asset_id\":\"56108879726720646120583724001239294777304794469144970684362785767667828318889\", \"price\":\"0.39\", \"size\":\"365\", \"side\":\"BUY\", \"hash\":\"dec9931160fe5c826ec779cede6f101135cdcbf8\", \"best_bid\":\"0.45\", \"best_ask\":\"0.46\"}, {\"asset_id\":\"107011546575057755426871645700605806081353395825571114128343592072429146374928\", \"price\":\"0.61\", \"size\":\"365\", \"side\":\"SELL\", \"hash\":\"7d8118175ee7640b638a6c8750884e1d3e5741c1\", \"best_bid\":\"0.54\", \"best_ask\":\"0.55\"}], \"timestamp\":\"1781254837026\", \"event_type\":\"price_change\"}","ts_local_ms":1781254837646}
{"dir":"in","text":"{\"market\":\"0x9c535590faae21bf76fed844aa47fc3c5c82253ef38bd545bf12c93470502685\", \"price_changes\":[{\"asset_id\":\"56108879726720646120583724001239294777304794469144970684362785767667828318889\", \"price\":\"0.39\", \"size\":\"365\", \"side\":\"BUY\", \"hash\":\"dec9931160fe5c826ec779cede6f101135cdcbf8\", \"best_bid\":\"0.45\", \"best_ask\":\"0.46\"}, {\"asset_id\":\"107011546575057755426871645700605806081353395825571114128343592072429146374928\", \"price\":\"0.61\", \"size\":\"365\", \"side\":\"SELL\", \"hash\":\"7d8118175ee7640b638a6c8750884e1d3e5741c1\", \"best_bid\":\"0.54\", \"best_ask\":\"0.55\"}], \"timestamp\":\"1781254837026\", \"event_type\":\"price_change\"}","ts_local_ms":1781254837646}
{"dir":"in","text":"{\"market\":\"0x9c535590faae21bf76fed844aa47fc3c5c82253ef38bd545bf12c93470502685\", \"price_changes\":[{\"asset_id\":\"56108879726720646120583724001239294777304794469144970684362785767667828318889\", \"price\":\"0.39\", \"size\":\"365\", \"side\":\"BUY\", \"hash\":\"dec9931160fe5c826ec779cede6f101135cdcbf8\", \"best_bid\":\"0.45\", \"best_ask\":\"0.46\"}, {\"asset_id\":\"107011546575057755426871645700605806081353395825571114128343592072429146374928\", \"price\":\"0.61\", \"size\":\"365\", \"side\":\"SELL\", \"hash\":\"7d8118175ee7640b638a6c8750884e1d3e5741c1\", \"best_bid\":\"0.54\", \"best_ask\":\"0.55\"}], \"timestamp\":\"1781254837026\", \"event_type\":\"price_change\"}","ts_local_ms":1781254837646}
{"dir":"in","text":"{\"market\":\"0x9c535590faae21bf76fed844aa47fc3c5c82253ef38bd545bf12c93470502685\", \"price_changes\":[{\"asset_id\":\"56108879726720646120583724001239294777304794469144970684362785767667828318889\", \"price\":\"0.37\", \"size\":\"305.04\", \"side\":\"BUY\", \"hash\":\"dec9931160fe5c826ec779cede6f101135cdcbf8\", \"best_bid\":\"0.45\", \"best_ask\":\"0.46\"}, {\"asset_id\":\"107011546575057755426871645700605806081353395825571114128343592072429146374928\", \"price\":\"0.63\", \"size\":\"305.04\", \"side\":\"SELL\", \"hash\":\"7d8118175ee7640b638a6c8750884e1d3e5741c1\", \"best_bid\":\"0.54\", \"best_ask\":\"0.55\"}], \"timestamp\":\"1781254837026\", \"event_type\":\"price_change\"}","ts_local_ms":1781254837646}
{"dir":"in","text":"{\"market\":\"0x9c535590faae21bf76fed844aa47fc3c5c82253ef38bd545bf12c93470502685\", \"price_changes\":[{\"asset_id\":\"56108879726720646120583724001239294777304794469144970684362785767667828318889\", \"price\":\"0.01\", \"size\":\"56699.15\", \"side\":\"BUY\", \"hash\":\"469a360bb481c76b8cb362db345b5d70dfd622ff\", \"best_bid\":\"0.45\", \"best_ask\":\"0.46\"}, {\"asset_id\":\"107011546575057755426871645700605806081353395825571114128343592072429146374928\", \"price\":\"0.99\", \"size\":\"56699.15\", \"side\":\"SELL\", \"hash\":\"e0dca74ef01f86bbb165c3d524d360c74c942956\", \"best_bid\":\"0.54\", \"best_ask\":\"0.55\"}], \"timestamp\":\"1781254837027\", \"event_type\":\"price_change\"}","ts_local_ms":1781254837646}
{"dir":"in","text":"{\"market\":\"0x9c535590faae21bf76fed844aa47fc3c5c82253ef38bd545bf12c93470502685\", \"price_changes\":[{\"asset_id\":\"107011546575057755426871645700605806081353395825571114128343592072429146374928\", \"price\":\"0.13\", \"size\":\"153.2\", \"side\":\"BUY\", \"hash\":\"e0dca74ef01f86bbb165c3d524d360c74c942956\", \"best_bid\":\"0.54\", \"best_ask\":\"0.55\"}, {\"asset_id\":\"56108879726720646120583724001239294777304794469144970684362785767667828318889\", \"price\":\"0.87\", \"size\":\"153.2\", \"side\":\"SELL\", \"hash\":\"469a360bb481c76b8cb362db345b5d70dfd622ff\", \"best_bid\":\"0.45\", \"best_ask\":\"0.46\"}], \"timestamp\":\"1781254837027\", \"event_type\":\"price_change\"}","ts_local_ms":1781254837646}
{"dir":"in","text":"{\"market\":\"0x9c535590faae21bf76fed844aa47fc3c5c82253ef38bd545bf12c93470502685\", \"price_changes\":[{\"asset_id\":\"56108879726720646120583724001239294777304794469144970684362785767667828318889\", \"price\":\"0.01\", \"size\":\"56699.15\", \"side\":\"BUY\", \"hash\":\"469a360bb481c76b8cb362db345b5d70dfd622ff\", \"best_bid\":\"0.45\", \"best_ask\":\"0.46\"}, {\"asset_id\":\"107011546575057755426871645700605806081353395825571114128343592072429146374928\", \"price\":\"0.99\", \"size\":\"56699.15\", \"side\":\"SELL\", \"hash\":\"e0dca74ef01f86bbb165c3d524d360c74c942956\", \"best_bid\":\"0.54\", \"best_ask\":\"0.55\"}], \"timestamp\":\"1781254837027\", \"event_type\":\"price_change\"}","ts_local_ms":1781254837646}
{"dir":"in","text":"{\"market\":\"0x9c535590faae21bf76fed844aa47fc3c5c82253ef38bd545bf12c93470502685\", \"price_changes\":[{\"asset_id\":\"56108879726720646120583724001239294777304794469144970684362785767667828318889\", \"price\":\"0.01\", \"size\":\"56699.15\", \"side\":\"BUY\", \"hash\":\"37ab7f96fc318e4212da1955d167f48db38a3fed\", \"best_bid\":\"0.45\", \"best_ask\":\"0.46\"}, {\"asset_id\":\"107011546575057755426871645700605806081353395825571114128343592072429146374928\", \"price\":\"0.99\", \"size\":\"56699.15\", \"side\":\"SELL\", \"hash\":\"4eedccae27a18353434de16c9d0efec5b90a9ce4\", \"best_bid\":\"0.54\", \"best_ask\":\"0.55\"}], \"timestamp\":\"1781254837028\", \"event_type\":\"price_change\"}","ts_local_ms":1781254837646}
