{"dir":"in","text":"{\"market\":\"0x9c535590faae21bf76fed844aa47fc3c5c82253ef38bd545bf12c93470502685\", \"price_changes\":[{\"asset_id\":\"56108879726720646120583724001239294777304794469144970684362785767667828318889\", \"price\":\"0.37\", \"size\":\"305.04\", \"side\":\"BUY\", \"hash\":\"37ab7f96fc318e4212da1955d167f48db38a3fed\", \"best_bid\":\"0.45\", \"best_ask\":\"0.46\"}, {\"asset_id\":\"107011546575057755426871645700605806081353395825571114128343592072429146374928\", \"price\":\"0.63\", \"size\":\"305.04\", \"side\":\"SELL\", \"hash\":\"4eedccae27a18353434de16c9d0efec5b90a9ce4\", \"best_bid\":\"0.54\", \"best_ask\":\"0.55\"}], \"timestamp\":\"1781254837028\", \"event_type\":\"price_change\"}","ts_local_ms":1781254837646}
{"dir":"in","text":"{\"market\":\"0x9c535590faae21bf76fed844aa47fc3c5c82253ef38bd545bf12c93470502685\", \"price_changes\":[{\"asset_id\":\"107011546575057755426871645700605806081353395825571114128343592072429146374928\", \"price\":\"0.54\", \"size\":\"373.52\", \"side\":\"BUY\", \"hash\":\"0491292dff0e2d4106656694ad4feae7deae7fa0\", \"best_bid\":\"0.54\", \"best_ask\":\"0.55\"}, {\"asset_id\":\"56108879726720646120583724001239294777304794469144970684362785767667828318889\", \"price\":\"0.46\", \"size\":\"373.52\", \"side\":\"SELL\", \"hash\":\"5b5f8523651307401f146b60d6f2768c9ab8ced7\", \"best_bid\":\"0.45\", \"best_ask\":\"0.46\"}], \"timestamp\":\"1781254837028\", \"event_type\":\"price_change\"}","ts_local_ms":1781254837646}
{"dir":"in","text":"{\"market\":\"0x9c535590faae21bf76fed844aa47fc3c5c82253ef38bd545bf12c93470502685\", \"price_changes\":[{\"asset_id\":\"56108879726720646120583724001239294777304794469144970684362785767667828318889\", \"price\":\"0.39\", \"size\":\"365\", \"side\":\"BUY\", \"hash\":\"d298377350237a17187aef98d8b0527140cecef5\", \"best_bid\":\"0.45\", \"best_ask\":\"0.46\"}, {\"asset_id\":\"107011546575057755426871645700605806081353395825571114128343592072429146374928\", \"price\":\"0.61\", \"size\":\"365\", \"side\":\"SELL\", \"hash\":\"e1a965fd18b6b480dbd44fccf0d6dce1868ef95a\", \"best_bid\":\"0.54\", \"best_ask\":\"0.55\"}], \"timestamp\":\"1781254837029\", \"event_type\":\"price_change\"}","ts_local_ms":1781254837646}
{"dir":"in","text":"{\"market\":\"0x9c535590faae21bf76fed844aa47fc3c5c82253ef38bd545bf12c93470502685\", \"price_changes\":[{\"asset_id\":\"56108879726720646120583724001239294777304794469144970684362785767667828318889\", \"price\":\"0.37\", \"size\":\"305.04\", \"side\":\"BUY\", \"hash\":\"d298377350237a17187aef98d8b0527140cecef5\", \"best_bid\":\"0.45\", \"best_ask\":\"0.46\"}, {\"asset_id\":\"107011546575057755426871645700605806081353395825571114128343592072429146374928\", \"price\":\"0.63\", \"size\":\"305.04\", \"side\":\"SELL\", \"hash\":\"e1a965fd18b6b480dbd44fccf0d6dce1868ef95a\", \"best_bid\":\"0.54\", \"best_ask\":\"0.55\"}], \"timestamp\":\"1781254837029\", \"event_type\":\"price_change\"}","ts_local_ms":1781254837646}
{"dir":"in","text":"{\"market\":\"0x9c535590faae21bf76fed844aa47fc3c5c82253ef38bd545bf12c93470502685\", \"price_changes\":[{\"asset_id\":\"56108879726720646120583724001239294777304794469144970684362785767667828318889\", \"price\":\"0.45\", \"size\":\"483.39\", \"side\":\"BUY\", \"hash\":\"e1819bd2c6442b5cd83f568ff4aff290c5fd7a83\", \"best_bid\":\"0.45\", \"best_ask\":\"0.46\"}, {\"asset_id\":\"107011546575057755426871645700605806081353395825571114128343592072429146374928\", \"price\":\"0.55\", \"size\":\"483.39\", \"side\":\"SELL\", \"hash\":\"ccc3394c1a4c663fd5be086ecee0707a73cb07dc\", \"best_bid\":\"0.54\", \"best_ask\":\"0.55\"}], \"timestamp\":\"1781254837029\", \"event_type\":\"price_change\"}","ts_local_ms":1781254837646}
{"dir":"in","text":"{\"market\":\"0x9c535590faae21bf76fed844aa47fc3c5c82253ef38bd545bf12c93470502685\", \"price_changes\":[{\"asset_id\":\"107011546575057755426871645700605806081353395825571114128343592072429146374928\", \"price\":\"0.54\", \"size\":\"368.52\", \"side\":\"BUY\", \"hash\":\"0f3a0a41477818f3b915eb5377c68e29818b4ead\", \"best_bid\":\"0.54\", \"best_ask\":\"0.55\"}, {\"asset_id\":\"56108879726720646120583724001239294777304794469144970684362785767667828318889\", \"price\":\"0.46\", \"size\":\"368.52\", \"side\":\"SELL\", \"hash\":\"42596e9a475bc7f0582ab16c25b9cc9612f33e90\", \"best_bid\":\"0.45\", \"best_ask\":\"0.46\"}], \"timestamp\":\"1781254837029\", \"event_type\":\"price_change\"}","ts_local_ms":1781254837646}
{"dir":"in","text":"{\"market\":\"0x9c535590faae21bf76fed844aa47fc3c5c82253ef38bd545bf12c93470502685\", \"price_changes\":[{\"asset_id\":\"56108879726720646120583724001239294777304794469144970684362785767667828318889\", \"price\":\"0.45\", \"size\":\"478.39\", \"side\":\"BUY\", \"hash\":\"cfde27fd95e9b04456b313bff4090caff0fae2c4\", \"best_bid\":\"0.45\", \"best_ask\":\"0.46\"}, {\"asset_id\":\"107011546575057755426871645700605806081353395825571114128343592072429146374928\", \"price\":\"0.55\", \"size\":\"478.39\", \"side\":\"SELL\", \"hash\":\"d141257995d6ea351f249f5fd02d645ba557281f\", \"best_bid\":\"0.54\", \"best_ask\":\"0.55\"}], \"timestamp\":\"1781254837030\", \"event_type\":\"price_change\"}","ts_local_ms":1781254837646}
{"dir":"in","text":"{\"market\":\"0x9c535590faae21bf76fed844aa47fc3c5c82253ef38bd545bf12c93470502685\", \"price_changes\":[{\"asset_id\":\"56108879726720646120583724001239294777304794469144970684362785767667828318889\", \"price\":\"0.37\", \"size\":\"305.04\", \"side\":\"BUY\", \"hash\":\"cfde27fd95e9b04456b313bff4090caff0fae2c4\", \"best_bid\":\"0.45\", \"best_ask\":\"0.46\"}, {\"asset_id\":\"107011546575057755426871645700605806081353395825571114128343592072429146374928\", \"price\":\"0.63\", \"size\":\"305.04\", \"side\":\"SELL\", \"hash\":\"d141257995d6ea351f249f5fd02d645ba557281f\", \"best_bid\":\"0.54\", \"best_ask\":\"0.55\"}], \"timestamp\":\"1781254837030\", \"event_type\":\"price_change\"}","ts_local_ms":1781254837646}
{"dir":"in","text":"{\"market\":\"0x9c535590faae21bf76fed844aa47fc3c5c82253ef38bd545bf12c93470502685\", \"price_changes\":[{\"asset_id\":\"56108879726720646120583724001239294777304794469144970684362785767667828318889\", \"price\":\"0.37\", \"size\":\"305.04\", \"side\":\"BUY\", \"hash\":\"cfde27fd95e9b04456b313bff4090caff0fae2c4\", \"best_bid\":\"0.45\", \"best_ask\":\"0.46\"}, {\"asset_id\":\"107011546575057755426871645700605806081353395825571114128343592072429146374928\", \"price\":\"0.63\", \"size\":\"305.04\", \"side\":\"SELL\", \"hash\":\"d141257995d6ea351f249f5fd02d645ba557281f\", \"best_bid\":\"0.54\", \"best_ask\":\"0.55\"}], \"timestamp\":\"1781254837030\", \"event_type\":\"price_change\"}","ts_local_ms":1781254837646}
{"dir":"in","text":"{\"market\":\"0x9c535590faae21bf76fed844aa47fc3c5c82253ef38bd545bf12c93470502685\", \"price_changes\":[{\"asset_id\":\"56108879726720646120583724001239294777304794469144970684362785767667828318889\", \"price\":\"0.44\", \"size\":\"47.83\", \"side\":\"BUY\", \"hash\":\"bb0a269d50a86d27b8d736b5ad438d7d35085172\", \"best_bid\":\"0.45\", \"best_ask\":\"0.46\"}, {\"asset_id\":\"107011546575057755426871645700605806081353395825571114128343592072429146374928\", \"price\":\"0.56\", \"size\":\"47.83\", \"side\":\"SELL\", \"hash\":\"bda9915f0249f9ba300264d1432a879a2850e439\", \"best_bid\":\"0.54\", \"best_ask\":\"0.55\"}], \"timestamp\":\"1781254837030\", \"event_type\":\"price_change\"}","ts_local_ms":1781254837646}
{"dir":"in","text":"{\"market\":\"0x9c535590faae21bf76fed844aa47fc3c5c82253ef38bd545bf12c93470502685\", \"price_changes\":[{\"asset_id\":\"56108879726720646120583724001239294777304794469144970684362785767667828318889\", \"price\":\"0.45\", \"size\":\"491.39\", \"side\":\"BUY\", \"hash\":\"f8232ee45bd986ac161c1c098c3a0d054df32084\", \"best_bid\":\"0.45\", \"best_ask\":\"0.46\"}, {\"asset_id\":\"107011546575057755426871645700605806081353395825571114128343592072429146374928\", \"price\":\"0.55\", \"size\":\"491.39\", \"side\":\"SELL\", \"hash\":\"153a2c80a4eab633a3a728c34c190d9e3f2882c8\", \"best_bid\":\"0.54\", \"best_ask\":\"0.55\"}], \"timestamp\":\"1781254837031\", \"event_type\":\"price_change\"}","ts_local_ms":1781254837646}
{"dir":"in","text":"{\"market\":\"0x9c535590faae21bf76fed844aa47fc3c5c82253ef38bd545bf12c93470502685\", \"price_changes\":[{\"asset_id\":\"107011546575057755426871645700605806081353395825571114128343592072429146374928\", \"price\":\"0.01\", \"size\":\"55006.6\", \"side\":\"BUY\", \"hash\":\"6dfb03964df41d5b655abc6e62fb483e1fa62ac3\", \"best_bid\":\"0.54\", \"best_ask\":\"0.55\"}, {\"asset_id\":\"56108879726720646120583724001239294777304794469144970684362785767667828318889\", \"price\":\"0.99\", \"size\":\"55006.6\", \"side\":\"SELL\", \"hash\":\"785605620cb613ceeaf4dab53d3860bffacbfbaf\", \"best_bid\":\"0.45\", \"best_ask\":\"0.46\"}], \"timestamp\":\"1781254837031\", \"event_type\":\"price_change\"}","ts_local_ms":1781254837646}
{"dir":"in","text":"{\"market\":\"0x9c535590faae21bf76fed844aa47fc3c5c82253ef38bd545bf12c93470502685\", \"price_changes\":[{\"asset_id\":\"56108879726720646120583724001239294777304794469144970684362785767667828318889\", \"price\":\"0.45\", \"size\":\"486.39\", \"side\":\"BUY\", \"hash\":\"5e172a763ccec119c2073f3d9b113b3a41ddb1f2\", \"best_bid\":\"0.45\", \"best_ask\":\"0.46\"}, {\"asset_id\":\"107011546575057755426871645700605806081353395825571114128343592072429146374928\", \"price\":\"0.55\", \"size\":\"486.39\", \"side\":\"SELL\", \"hash\":\"a2b6a4cd109fe85bff249d52ed9144d7e5c6d120\", \"best_bid\":\"0.54\", \"best_ask\":\"0.55\"}], \"timestamp\":\"1781254837031\", \"event_type\":\"price_change\"}","ts_local_ms":1781254837646}
{"dir":"in","text":"{\"market\":\"0x9c535590faae21bf76fed844aa47fc3c5c82253ef38bd545bf12c93470502685\", \"price_changes\":[{\"asset_id\":\"56108879726720646120583724001239294777304794469144970684362785767667828318889\", \"price\":\"0.45\", \"size\":\"463.39\", \"side\":\"BUY\", \"hash\":\"5e66f987bc367ddb8a9e8d0615485e3e0b289b48\", \"best_bid\":\"0.45\", \"best_ask\":\"0.46\"}, {\"asset_id\":\"107011546575057755426871645700605806081353395825571114128343592072429146374928\", \"price\":\"0.55\", \"size\":\"463.39\", \"side\":\"SELL\", \"hash\":\"07bbf699fb8d2d62a76390413f849524fb57e13a\", \"best_bid\":\"0.54\", \"best_ask\":\"0.55\"}], \"timestamp\":\"1781254837031\", \"event_type\":\"price_change\"}","ts_local_ms":1781254837646}
{"dir":"in","text":"{\"market\":\"0x9c535590faae21bf76fed844aa47fc3c5c82253ef38bd545bf12c93470502685\", \"price_changes\":[{\"asset_id\":\"56108879726720646120583724001239294777304794469144970684362785767667828318889\", \"price\":\"0.01\", \"size\":\"56199.15\", \"side\":\"BUY\", \"hash\":\"9fa4a42512ea160c73da6053f594ec4a1c7d2214\", \"best_bid\":\"0.45\", \"best_ask\":\"0.46\"}, {\"asset_id\":\"107011546575057755426871645700605806081353395825571114128343592072429146374928\", \"price\":\"0.99\", \"size\":\"56199.15\", \"side\":\"SELL\", \"hash\":\"4b389ef6c2259077315022787527fefef85ccca7\", \"best_bid\":\"0.54\", \"best_ask\":\"0.55\"}], \"timestamp\":\"1781254837031\", \"event_type\":\"price_change\"}","ts_local_ms":1781254837647}
{"dir":"in","text":"{\"market\":\"0x9c535590faae21bf76fed844aa47fc3c5c82253ef38bd545bf12c93470502685\", \"price_changes\":[{\"asset_id\":\"56108879726720646120583724001239294777304794469144970684362785767667828318889\", \"price\":\"0.45\", \"size\":\"513.39\", \"side\":\"BUY\", \"hash\":\"b768118f056595a0e47a5b5bfc4631d07e8b5fdf\", \"best_bid\":\"0.45\", \"best_ask\":\"0.46\"}, {\"asset_id\":\"107011546575057755426871645700605806081353395825571114128343592072429146374928\", \"price\":\"0.55\", \"size\":\"513.39\", \"side\":\"SELL\", \"hash\":\"acfa017a220fb983bcf4a3316dc70131921dc6d7\", \"best_bid\":\"0.54\", \"best_ask\":\"0.55\"}], \"timestamp\":\"1781254837032\", \"event_type\":\"price_change\"}","ts_local_ms":1781254837647}
{"dir":"in","text":"{\"market\":\"0x9c535590faae21bf76fed844aa47fc3c5c82253ef38bd545bf12c93470502685\", \"price_changes\":[{\"asset_id\":\"56108879726720646120583724001239294777304794469144970684362785767667828318889\", \"price\":\"0.05\", \"size\":\"1862.1\", \"side\":\"BUY\", \"hash\":\"b768118f056595a0e47a5b5bfc4631d07e8b5fdf\", \"best_bid\":\"0.45\", \"best_ask\":\"0.46\"}, {\"asset_id\":\"107011546575057755426871645700605806081353395825571114128343592072429146374928\", \"price\":\"0.95\", \"size\":\"1862.1\", \"side\":\"SELL\", \"hash\":\"acfa017a220fb983bcf4a3316dc70131921dc6d7\", \"best_bid\":\"0.54\", \"best_ask\":\"0.55\"}], \"timestamp\":\"1781254837032\", \"event_type\":\"price_change\"}","ts_local_ms":1781254837647}
{"dir":"in","text":"{\"market\":\"0x9c535590faae21bf76fed844aa47fc3c5c82253ef38bd545bf12c93470502685\", \"price_changes\":[{\"asset_id\":\"56108879726720646120583724001239294777304794469144970684362785767667828318889\", \"price\":\"0.45\", \"size\":\"534.39\", \"side\":\"BUY\", \"hash\":\"23cd1bdd28cf5a72ae3702cce644878047122501\", \"best_bid\":\"0.45\", \"best_ask\":\"0.46\"}, {\"asset_id\":\"107011546575057755426871645700605806081353395825571114128343592072429146374928\", \"price\":\"0.55\", \"size\":\"534.39\", \"side\":\"SELL\", \"hash\":\"79588d6674057436c71fb96b3399f445cd5a6eb0\", \"best_bid\":\"0.54\", \"best_ask\":\"0.55\"}], \"timestamp\":\"1781254837033\", \"event_type\":\"price_change\"}","ts_local_ms":1781254837647}
{"dir":"in","text":"{\"market\":\"0x9c535590faae21bf76fed844aa47fc3c5c82253ef38bd545bf12c93470502685\", \"price_changes\":[{\"asset_id\":\"56108879726720646120583724001239294777304794469144970684362785767667828318889\", \"price\":\"0.45\", \"size\":\"548.39\", \"side\":\"BUY\", \"hash\":\"9459a8dd85ee5bde2ea7679e7a4b68d2804fa328\", \"best_bid\":\"0.45\", \"best_ask\":\"0.46\"}, {\"asset_id\":\"107011546575057755426871645700605806081353395825571114128343592072429146374928\", \"price\":\"0.55\", \"size\":\"548.39\", \"side\":\"SELL\", \"hash\":\"ec682014ee0d42e83f276803dbf8190e4a092464\", \"best_bid\":\"0.54\", \"best_ask\":\"0.55\"}], \"timestamp\":\"1781254837033\", \"event_type\":\"price_change\"}","ts_local_ms":1781254837647}
{"dir":"in","text":"{\"market\":\"0x9c535590faae21bf76fed844aa47fc3c5c82253ef38bd545bf12c93470502685\", \"price_changes\":[{\"asset_id\":\"56108879726720646120583724001239294777304794469144970684362785767667828318889\", \"price\":\"0.4\", \"size\":\"331\", \"side\":\"BUY\", \"hash\":\"77f870164c2f893d0008b550be2542597ebbe9e4\", \"best_bid\":\"0.45\", \"best_ask\":\"0.46\"}, {\"asset_id\":\"107011546575057755426871645700605806081353395825571114128343592072429146374928\", \"price\":\"0.6\", \"size\":\"331\", \"side\":\"SELL\", \"hash\":\"c295b694033780d4b0c3dbf9c5c81145ff4f5fe3\", \"best_bid\":\"0.54\", \"best_ask\":\"0.55\"}], \"timestamp\":\"1781254837034\", \"event_type\":\"price_change\"}","ts_local_ms":1781254837647}
{"dir":"in","text":"{\"market\":\"0x9c535590faae21bf76fed844aa47fc3c5c82253ef38bd545bf12c93470502685\", \"price_changes\":[{\"asset_id\":\"56108879726720646120583724001239294777304794469144970684362785767667828318889\", \"price\":\"0.44\", \"size\":\"56.25\", \"side\":\"BUY\", \"hash\":\"513f032e7014898f52c10dd40a51ffefc60feb1a\", \"best_bid\":\"0.45\", \"best_ask\":\"0.46\"}, {\"asset_id\":\"107011546575057755426871645700605806081353395825571114128343592072429146374928\", \"price\":\"0.56\", \"size\":\"56.25\", \"side\":\"SELL\", \"hash\":\"29515e401dfaba11577ba8db11a43a08f8642a10\", \"best_bid\":\"0.54\", \"best_ask\":\"0.55\"}], \"timestamp\":\"1781254837035\", \"event_type\":\"price_change\"}","ts_local_ms":1781254837647}
{"dir":"in","text":"{\"market\":\"0x9c535590faae21bf76fed844aa47fc3c5c82253ef38bd545bf12c93470502685\", \"price_changes\":[{\"asset_id\":\"107011546575057755426871645700605806081353395825571114128343592072429146374928\", \"price\":\"0.52\", \"size\":\"141.37\", \"side\":\"BUY\", \"hash\":\"8cda0e1f5de00bce42ee6eda57f78eed2ac2a4ce\", \"best_bid\":\"0.54\", \"best_ask\":\"0.55\"}, {\"asset_id\":\"56108879726720646120583724001239294777304794469144970684362785767667828318889\", \"price\":\"0.48\", \"size\":\"141.37\", \"side\":\"SELL\", \"hash\":\"0cb7e2cde8be7a6c242657cb44f4970589118a2f\", \"best_bid\":\"0.45\", \"best_ask\":\"0.46\"}], \"timestamp\":\"1781254837035\", \"event_type\":\"price_change\"}","ts_local_ms":1781254837647}
{"dir":"in","text":"{\"market\":\"0x9c535590faae21bf76fed844aa47fc3c5c82253ef38bd545bf12c93470502685\", \"price_changes\":[{\"asset_id\":\"107011546575057755426871645700605806081353395825571114128343592072429146374928\", \"price\":\"0.51\", \"size\":\"227.14\", \"side\":\"BUY\", \"hash\":\"5b68805df8bb3b5882ee161257f62ed7dafcc2af\", \"best_bid\":\"0.54\", \"best_ask\":\"0.55\"}, {\"asset_id\":\"56108879726720646120583724001239294777304794469144970684362785767667828318889\", \"price\":\"0.49\", \"size\":\"227.14\", \"side\":\"SELL\", \"hash\":\"59ff9e760c9f3c116baea36a96e645cb9c7eeb31\", \"best_bid\":\"0.45\", \"best_ask\":\"0.46\"}], \"timestamp\":\"1781254837036\", \"event_type\":\"price_change\"}","ts_local_ms":1781254837647}
{"dir":"in","text":"{\"market\":\"0x9c535590faae21bf76fed844aa47fc3c5c82253ef38bd545bf12c93470502685\", \"price_changes\":[{\"asset_id\":\"56108879726720646120583724001239294777304794469144970684362785767667828318889\", \"price\":\"0.01\", \"size\":\"56194.15\", \"side\":\"BUY\", \"hash\":\"82f8c172a51a4d6a9e221d194f9bcab66f7e7ae0\", \"best_bid\":\"0.45\", \"best_ask\":\"0.46\"}, {\"asset_id\":\"107011546575057755426871645700605806081353395825571114128343592072429146374928\", \"price\":\"0.99\", \"size\":\"56194.15\", \"side\":\"SELL\", \"hash\":\"e711ac29ff1fcd25ba2fc8478a706cfc6b5d4ed5\", \"best_bid\":\"0.54\", \"best_ask\":\"0.55\"}], \"timestamp\":\"1781254837036\", \"event_type\":\"price_change\"}","ts_local_ms":1781254837647}
{"dir":"in","text":"{\"market\":\"0x9c535590faae21bf76fed844aa47fc3c5c82253ef38bd545bf12c93470502685\", \"price_changes\":[{\"asset_id\":\"56108879726720646120583724001239294777304794469144970684362785767667828318889\", \"price\":\"0.41\", \"size\":\"141.72\", \"side\":\"BUY\", \"hash\":\"2a6de6215e9c78fdb0bbde9b69717f89cf0c5e9f\", \"best_bid\":\"0.45\", \"best_ask\":\"0.46\"}, {\"asset_id\":\"107011546575057755426871645700605806081353395825571114128343592072429146374928\", \"price\":\"0.59\", \"size\":\"141.72\", \"side\":\"SELL\", \"hash\":\"352a6f0359b0db0bc0ad3aa56bd161e60d1d1731\", \"best_bid\":\"0.54\", \"best_ask\":\"0.55\"}], \"timestamp\":\"1781254837037\", \"event_type\":\"price_change\"}","ts_local_ms":1781254837647}
{"dir":"in","text":"{\"market\":\"0x9c535590faae21bf76fed844aa47fc3c5c82253ef38bd545bf12c93470502685\", \"price_changes\":[{\"asset_id\":\"56108879726720646120583724001239294777304794469144970684362785767667828318889\", \"price\":\"0.42\", \"size\":\"176.2\", \"side\":\"BUY\", \"hash\":\"87272c9a3cb59397132dee928588616361e48ecb\", \"best_bid\":\"0.45\", \"best_ask\":\"0.46\"}, {\"asset_id\":\"107011546575057755426871645700605806081353395825571114128343592072429146374928\", \"price\":\"0.58\", \"size\":\"176.2\", \"side\":\"SELL\", \"hash\":\"cf15951c48347caab9629e841de62015fff67cbe\", \"best_bid\":\"0.54\", \"best_ask\":\"0.55\"}], \"timestamp\":\"1781254837038\", \"event_type\":\"price_change\"}","ts_local_ms":1781254837647}
{"dir":"in","text":"{\"market\":\"0x9c535590faae21bf76fed844aa47fc3c5c82253ef38bd545bf12c93470502685\", \"price_changes\":[{\"asset_id\":\"56108879726720646120583724001239294777304794469144970684362785767667828318889\", \"price\":\"0.43\", \"size\":\"170\", \"side\":\"BUY\", \"hash\":\"f0138dbf6b45e195d496614592560da8be382811\", \"best_bid\":\"0.45\", \"best_ask\":\"0.46\"}, {\"asset_id\":\"107011546575057755426871645700605806081353395825571114128343592072429146374928\", \"price\":\"0.57\", \"size\":\"170\", \"side\":\"SELL\", \"hash\":\"f98b54f4b26818d53e25081131d424a17c806ece\", \"best_bid\":\"0.54\", \"best_ask\":\"0.55\"}], \"timestamp\":\"1781254837038\", \"event_type\":\"price_change\"}","ts_local_ms":1781254837647}
{"dir":"in","text":"{\"market\":\"0x9c535590faae21bf76fed844aa47fc3c5c82253ef38bd545bf12c93470502685\", \"price_changes\":[{\"asset_id\":\"107011546575057755426871645700605806081353395825571114128343592072429146374928\", \"price\":\"0.5\", \"size\":\"448.08\", \"side\":\"BUY\", \"hash\":\"c5c42512be2343085bfac172299635c38d327bf4\", \"best_bid\":\"0.54\", \"best_ask\":\"0.55\"}, {\"asset_id\":\"56108879726720646120583724001239294777304794469144970684362785767667828318889\", \"price\":\"0.5\", \"size\":\"448.08\", \"side\":\"SELL\", \"hash\":\"93d42965be4ec4812b0d14c74f4a60ff7a264ecb\", \"best_bid\":\"0.45\", \"best_ask\":\"0.46\"}], \"timestamp\":\"1781254837038\", \"event_type\":\"price_change\"}","ts_local_ms":1781254837647}
{"dir":"in","text":"{\"market\":\"0x9c535590faae21bf76fed844aa47fc3c5c82253ef38bd545bf12c93470502685\", \"price_changes\":[{\"asset_id\":\"56108879726720646120583724001239294777304794469144970684362785767667828318889\", \"price\":\"0.45\", \"size\":\"533.39\", \"side\":\"BUY\", \"hash\":\"6c765e0e029c7faef3838d78b13c82a60bd39a30\", \"best_bid\":\"0.45\", \"best_ask\":\"0.46\"}, {\"asset_id\":\"107011546575057755426871645700605806081353395825571114128343592072429146374928\", \"price\":\"0.55\", \"size\":\"533.39\", \"side\":\"SELL\", \"hash\":\"f6236b65bd7d42e275a8a7f60b4e895303b54f0f\", \"best_bid\":\"0.54\", \"best_ask\":\"0.55\"}], \"timestamp\":\"1781254837038\", \"event_type\":\"price_change\"}","ts_local_ms":1781254837647}
{"dir":"in","text":"{\"market\":\"0x9c535590faae21bf76fed844aa47fc3c5c82253ef38bd545bf12c93470502685\", \"price_changes\":[{\"asset_id\":\"56108879726720646120583724001239294777304794469144970684362785767667828318889\", \"price\":\"0.42\", \"size\":\"156.2\", \"side\":\"BUY\", \"hash\":\"7ede023f4a8c516e11d0c74f265753058bbb04a9\", \"best_bid\":\"0.45\", \"best_ask\":\"0.46\"}, {\"asset_id\":\"107011546575057755426871645700605806081353395825571114128343592072429146374928\", \"price\":\"0.58\", \"size\":\"156.2\", \"side\":\"SELL\", \"hash\":\"afa9e81e6ec86a410e8dcacc512b1962ac780e1e\", \"best_bid\":\"0.54\", \"best_ask\":\"0.55\"}], \"timestamp\":\"1781254837038\", \"event_type\":\"price_change\"}","ts_local_ms":1781254837647}
{"dir":"in","text":"{\"market\":\"0x9c535590faae21bf76fed844aa47fc3c5c82253ef38bd545bf12c93470502685\", \"price_changes\":[{\"asset_id\":\"56108879726720646120583724001239294777304794469144970684362785767667828318889\", \"price\":\"0.01\", \"size\":\"56199.15\", \"side\":\"BUY\", \"hash\":\"2b7898110fc33d039df64907235b02f8901a6949\", \"best_bid\":\"0.45\", \"best_ask\":\"0.46\"}, {\"asset_id\":\"107011546575057755426871645700605806081353395825571114128343592072429146374928\", \"price\":\"0.99\", \"size\":\"56199.15\", \"side\":\"SELL\", \"hash\":\"adeb4dfa2668dc81d04e7118d730698a1d0c70b9\", \"best_bid\":\"0.54\", \"best_ask\":\"0.55\"}], \"timestamp\":\"1781254837039\", \"event_type\":\"price_change\"}","ts_local_ms":1781254837647}
{"dir":"in","text":"{\"market\":\"0x9c535590faae21bf76fed844aa47fc3c5c82253ef38bd545bf12c93470502685\", \"price_changes\":[{\"asset_id\":\"107011546575057755426871645700605806081353395825571114128343592072429146374928\", \"price\":\"0.54\", \"size\":\"378.52\", \"side\":\"BUY\", \"hash\":\"0a58ddbfe9b97bbab482a3206b54314f15e7c55b\", \"best_bid\":\"0.54\", \"best_ask\":\"0.55\"}, {\"asset_id\":\"56108879726720646120583724001239294777304794469144970684362785767667828318889\", \"price\":\"0.46\", \"size\":\"378.52\", \"side\":\"SELL\", \"hash\":\"e083d460f165fb0aab48f0f0adb2ccf29bbb84ad\", \"best_bid\":\"0.45\", \"best_ask\":\"0.46\"}], \"timestamp\":\"1781254837039\", \"event_type\":\"price_change\"}","ts_local_ms":1781254837647}
{"dir":"in","text":"{\"market\":\"0x9c535590faae21bf76fed844aa47fc3c5c82253ef38bd545bf12c93470502685\", \"price_changes\":[{\"asset_id\":\"56108879726720646120583724001239294777304794469144970684362785767667828318889\", \"price\":\"0.45\", \"size\":\"523.39\", \"side\":\"BUY\", \"hash\":\"a111cffb4e156f9787c2fa7991581d21b0c8e399\", \"best_bid\":\"0.45\", \"best_ask\":\"0.46\"}, {\"asset_id\":\"107011546575057755426871645700605806081353395825571114128343592072429146374928\", \"price\":\"0.55\", \"size\":\"523.39\", \"side\":\"SELL\", \"hash\":\"10a577d722a717e02b6e78e172ca7dc4be40e453\", \"best_bid\":\"0.54\", \"best_ask\":\"0.55\"}], \"timestamp\":\"1781254837040\", \"event_type\":\"price_change\"}","ts_local_ms":1781254837647}
{"dir":"in","text":"{\"market\":\"0x9c535590faae21bf76fed844aa47fc3c5c82253ef38bd545bf12c93470502685\", \"price_changes\":[{\"asset_id\":\"107011546575057755426871645700605806081353395825571114128343592072429146374928\", \"price\":\"0.22\", \"size\":\"47.6\", \"side\":\"BUY\", \"hash\":\"384a832fbc537433612d2d70d9e581d8db50006f\", \"best_bid\":\"0.54\", \"best_ask\":\"0.55\"}, {\"asset_id\":\"56108879726720646120583724001239294777304794469144970684362785767667828318889\", \"price\":\"0.78\", \"size\":\"47.6\", \"side\":\"SELL\", \"hash\":\"db33fdb3b702f14bc17623211c0dade1c8059a67\", \"best_bid\":\"0.45\", \"best_ask\":\"0.46\"}], \"timestamp\":\"1781254837040\", \"event_type\":\"price_change\"}","ts_local_ms":1781254837647}
{"dir":"in","text":"{\"market\":\"0x9c535590faae21bf76fed844aa47fc3c5c82253ef38bd545bf12c93470502685\", \"price_changes\":[{\"asset_id\":\"56108879726720646120583724001239294777304794469144970684362785767667828318889\", \"price\":\"0.43\", \"size\":\"140\", \"side\":\"BUY\", \"hash\":\"3d16221a6b20a5a69bb9d6005a577f26ee5481b8\", \"best_bid\":\"0.45\", \"best_ask\":\"0.46\"}, {\"asset_id\":\"107011546575057755426871645700605806081353395825571114128343592072429146374928\", \"price\":\"0.57\", \"size\":\"140\", \"side\":\"SELL\", \"hash\":\"3da6a711c5ff6ec674cc34e8c51fb23a2c75090a\", \"best_bid\":\"0.54\", \"best_ask\":\"0.55\"}], \"timestamp\":\"1781254837040\", \"event_type\":\"price_change\"}","ts_local_ms":1781254837647}
{"dir":"in","text":"{\"market\":\"0x9c535590faae21bf76fed844aa47fc3c5c82253ef38bd545bf12c93470502685\", \"price_changes\":[{\"asset_id\":\"107011546575057755426871645700605806081353395825571114128343592072429146374928\", \"price\":\"0.21\", \"size\":\"142.8\", \"side\":\"BUY\", \"hash\":\"49a1b613ee5c94e4607312cb94d7a97977d385c0\", \"best_bid\":\"0.54\", \"best_ask\":\"0.55\"}, {\"asset_id\":\"56108879726720646120583724001239294777304794469144970684362785767667828318889\", \"price\":\"0.79\", \"size\":\"142.8\", \"side\":\"SELL\", \"hash\":\"052e00576fac2e1e83a3175d28f4f86c5d0bc68e\", \"best_bid\":\"0.45\", \"best_ask\":\"0.46\"}], \"timestamp\":\"1781254837040\", \"event_type\":\"price_change\"}","ts_local_ms":1781254837647}
{"dir":"in","text":"{\"market\":\"0x9c535590faae21bf76fed844aa47fc3c5c82253ef38bd545bf12c93470502685\", \"price_changes\":[{\"asset_id\":\"56108879726720646120583724001239294777304794469144970684362785767667828318889\", \"price\":\"0.45\", \"size\":\"513.39\", \"side\":\"BUY\", \"hash\":\"0d290a332e5ae2321a3a6129dbac516969374262\", \"best_bid\":\"0.45\", \"best_ask\":\"0.46\"}, {\"asset_id\":\"107011546575057755426871645700605806081353395825571114128343592072429146374928\", \"price\":\"0.55\", \"size\":\"513.39\", \"side\":\"SELL\", \"hash\":\"d67b7569876e794f8f9a3265669c7282c200e284\", \"best_bid\":\"0.54\", \"best_ask\":\"0.55\"}], \"timestamp\":\"1781254837040\", \"event_type\":\"price_change\"}","ts_local_ms":1781254837647}
{"dir":"in","text":"{\"market\":\"0x9c535590faae21bf76fed844aa47fc3c5c82253ef38bd545bf12c93470502685\", \"price_changes\":[{\"asset_id\":\"107011546575057755426871645700605806081353395825571114128343592072429146374928\", \"price\":\"0.54\", \"size\":\"408.52\", \"side\":\"BUY\", \"hash\":\"a7c934ed2537314338a70a9dd0c9d2fdf0002f9a\", \"best_bid\":\"0.54\", \"best_ask\":\"0.55\"}, {\"asset_id\":\"56108879726720646120583724001239294777304794469144970684362785767667828318889\", \"price\":\"0.46\", \"size\":\"408.52\", \"side\":\"SELL\", \"hash\":\"cc83cd0c57280cfeadcdedce94d4a5c0d8cf2b47\", \"best_bid\":\"0.45\", \"best_ask\":\"0.46\"}], \"timestamp\":\"1781254837041\", \"event_type\":\"price_change\"}","ts_local_ms":1781254837647}
{"dir":"in","text":"{\"market\":\"0x9c535590faae21bf76fed844aa47fc3c5c82253ef38bd545bf12c93470502685\", \"price_changes\":[{\"asset_id\":\"107011546575057755426871645700605806081353395825571114128343592072429146374928\", \"price\":\"0.52\", \"size\":\"156.37\", \"side\":\"BUY\", \"hash\":\"ed41be4f696f9cc97fcec3038ea2a4af354e5dfd\", \"best_bid\":\"0.54\", \"best_ask\":\"0.55\"}, {\"asset_id\":\"56108879726720646120583724001239294777304794469144970684362785767667828318889\", \"price\":\"0.48\", \"size\":\"156.37\", \"side\":\"SELL\", \"hash\":\"0ae5de902febe4ee321b638ce68ac0912bc4b70b\", \"best_bid\":\"0.45\", \"best_ask\":\"0.46\"}], \"timestamp\":\"1781254837042\", \"event_type\":\"price_change\"}","ts_local_ms":1781254837648}
{"dir":"in","text":"{\"market\":\"0x9c535590faae21bf76fed844aa47fc3c5c82253ef38bd545bf12c93470502685\", \"price_changes\":[{\"asset_id\":\"107011546575057755426871645700605806081353395825571114128343592072429146374928\", \"price\":\"0.01\", \"size\":\"55001.6\", \"side\":\"BUY\", \"hash\":\"a00d5c9369de8fb759ff32535ed3fb5cd2274a8c\", \"best_bid\":\"0.54\", \"best_ask\":\"0.55\"}, {\"asset_id\":\"56108879726720646120583724001239294777304794469144970684362785767667828318889\", \"price\":\"0.99\", \"size\":\"55001.6\", \"side\":\"SELL\", \"hash\":\"ee8c8a1f68d6acd62a2fbc7c686a718b59cb2a97\", \"best_bid\":\"0.45\", \"best_ask\":\"0.46\"}], \"timestamp\":\"1781254837043\", \"event_type\":\"price_change\"}","ts_local_ms":1781254837648}
{"dir":"in","text":"{\"market\":\"0x9c535590faae21bf76fed844aa47fc3c5c82253ef38bd545bf12c93470502685\", \"price_changes\":[{\"asset_id\":\"107011546575057755426871645700605806081353395825571114128343592072429146374928\", \"price\":\"0.53\", \"size\":\"122.63\", \"side\":\"BUY\", \"hash\":\"8bef47239019ac7fbdbba1465e263b788c885dd6\", \"best_bid\":\"0.54\", \"best_ask\":\"0.55\"}, {\"asset_id\":\"56108879726720646120583724001239294777304794469144970684362785767667828318889\", \"price\":\"0.47\", \"size\":\"122.63\", \"side\":\"SELL\", \"hash\":\"c43a6efdfaceddc51b1564fe0c1a875c7b63dee7\", \"best_bid\":\"0.45\", \"best_ask\":\"0.46\"}], \"timestamp\":\"1781254837048\", \"event_type\":\"price_change\"}","ts_local_ms":1781254837648}
{"dir":"in","text":"{\"market\":\"0x9c535590faae21bf76fed844aa47fc3c5c82253ef38bd545bf12c93470502685\", \"price_changes\":[{\"asset_id\":\"56108879726720646120583724001239294777304794469144970684362785767667828318889\", \"price\":\"0.45\", \"size\":\"501.39\", \"side\":\"BUY\", \"hash\":\"3ccc963eaa56b7814dc518c16e7ea40d506eb6be\", \"best_bid\":\"0.45\", \"best_ask\":\"0.46\"}, {\"asset_id\":\"107011546575057755426871645700605806081353395825571114128343592072429146374928\", \"price\":\"0.55\", \"size\":\"501.39\", \"side\":\"SELL\", \"hash\":\"2b60340791a7b2f3d39e9f45cc5f09e2f994f2c4\", \"best_bid\":\"0.54\", \"best_ask\":\"0.55\"}], \"timestamp\":\"1781254837049\", \"event_type\":\"price_change\"}","ts_local_ms":1781254837648}
{"dir":"in","text":"{\"market\":\"0x9c535590faae21bf76fed844aa47fc3c5c82253ef38bd545bf12c93470502685\", \"price_changes\":[{\"asset_id\":\"107011546575057755426871645700605806081353395825571114128343592072429146374928\", \"price\":\"0.52\", \"size\":\"131.37\", \"side\":\"BUY\", \"hash\":\"769a6ed6e8a1dab44bddd1862b4ff25d68f4af97\", \"best_bid\":\"0.54\", \"best_ask\":\"0.55\"}, {\"asset_id\":\"56108879726720646120583724001239294777304794469144970684362785767667828318889\", \"price\":\"0.48\", \"size\":\"131.37\", \"side\":\"SELL\", \"hash\":\"369facbd4c5e6cef326527e81ddda3b466b9e750\", \"best_bid\":\"0.45\", \"best_ask\":\"0.46\"}], \"timestamp\":\"1781254837051\", \"event_type\":\"price_change\"}","ts_local_ms":1781254837648}
{"dir":"in","text":"{\"market\":\"0x9c535590faae21bf76fed844aa47fc3c5c82253ef38bd545bf12c93470502685\", \"price_changes\":[{\"asset_id\":\"107011546575057755426871645700605806081353395825571114128343592072429146374928\", \"price\":\"0.23\", \"size\":\"17.3\", \"side\":\"BUY\", \"hash\":\"13c23baae6052761d81a4fa4ca560f0baa811685\", \"best_bid\":\"0.54\", \"best_ask\":\"0.55\"}, {\"asset_id\":\"56108879726720646120583724001239294777304794469144970684362785767667828318889\", \"price\":\"0.77\", \"size\":\"17.3\", \"side\":\"SELL\", \"hash\":\"ed63be6bcb5df68049b0ef6fa6d5c4566557e7c2\", \"best_bid\":\"0.45\", \"best_ask\":\"0.46\"}], \"timestamp\":\"1781254837053\", \"event_type\":\"price_change\"}","ts_local_ms":1781254837648}
{"dir":"in","text":"{\"market\":\"0x9c535590faae21bf76fed844aa47fc3c5c82253ef38bd545bf12c93470502685\", \"price_changes\":[{\"asset_id\":\"56108879726720646120583724001239294777304794469144970684362785767667828318889\", \"price\":\"0.38\", \"size\":\"303.25\", \"side\":\"BUY\", \"hash\":\"87061d40867bc9e7b0cd3cae6449bbe5247ce8da\", \"best_bid\":\"0.45\", \"best_ask\":\"0.46\"}, {\"asset_id\":\"107011546575057755426871645700605806081353395825571114128343592072429146374928\", \"price\":\"0.62\", \"size\":\"303.25\", \"side\":\"SELL\", \"hash\":\"37e1908217e171225fb720e027d20f5219197432\", \"best_bid\":\"0.54\", \"best_ask\":\"0.55\"}], \"timestamp\":\"1781254837056\", \"event_type\":\"price_change\"}","ts_local_ms":1781254837648}
{"dir":"in","text":"{\"market\":\"0x9c535590faae21bf76fed844aa47fc3c5c82253ef38bd545bf12c93470502685\", \"price_changes\":[{\"asset_id\":\"107011546575057755426871645700605806081353395825571114128343592072429146374928\", \"price\":\"0.52\", \"size\":\"161.37\", \"side\":\"BUY\", \"hash\":\"e48ab77ccc8a82d75165312ee76156eb969fdfef\", \"best_bid\":\"0.54\", \"best_ask\":\"0.55\"}, {\"asset_id\":\"56108879726720646120583724001239294777304794469144970684362785767667828318889\", \"price\":\"0.48\", \"size\":\"161.37\", \"side\":\"SELL\", \"hash\":\"07c6238cd51ddec3d98d30d68adbb46dfeee2368\", \"best_bid\":\"0.45\", \"best_ask\":\"0.46\"}], \"timestamp\":\"1781254837058\", \"event_type\":\"price_change\"}","ts_local_ms":1781254837648}
{"dir":"in","text":"{\"market\":\"0x9c535590faae21bf76fed844aa47fc3c5c82253ef38bd545bf12c93470502685\", \"asset_id\":\"56108879726720646120583724001239294777304794469144970684362785767667828318889\", \"best_bid\":\"0.45\", \"best_ask\":\"0.46\", \"spread\":\"0.01\", \"timestamp\":\"1781254837060\", \"event_type\":\"best_bid_ask\"}","ts_local_ms":1781254837648}
{"dir":"in","text":"{\"market\":\"0x9c535590faae21bf76fed844aa47fc3c5c82253ef38bd545bf12c93470502685\", \"asset_id\":\"107011546575057755426871645700605806081353395825571114128343592072429146374928\", \"best_bid\":\"0.54\", \"best_ask\":\"0.55\", \"spread\":\"0.01\", \"timestamp\":\"1781254837060\", \"event_type\":\"best_bid_ask\"}","ts_local_ms":1781254837648}
{"dir":"in","text":"{\"market\":\"0x9c535590faae21bf76fed844aa47fc3c5c82253ef38bd545bf12c93470502685\", \"price_changes\":[{\"asset_id\":\"107011546575057755426871645700605806081353395825571114128343592072429146374928\", \"price\":\"0.54\", \"size\":\"309.52\", \"side\":\"BUY\", \"hash\":\"4e686dc6fc6680b25a35e5e941888b8f7fe1e8bb\", \"best_bid\":\"0.54\", \"best_ask\":\"0.55\"}, {\"asset_id\":\"56108879726720646120583724001239294777304794469144970684362785767667828318889\", \"price\":\"0.46\", \"size\":\"309.52\", \"side\":\"SELL\", \"hash\":\"ce5f4fc689693dd33c80c8265c933f7b3cf449d9\", \"best_bid\":\"0.45\", \"best_ask\":\"0.46\"}], \"timestamp\":\"1781254837059\", \"event_type\":\"price_change\"}","ts_local_ms":1781254837648}
{"dir":"in","text":"{\"market\":\"0x9c535590faae21bf76fed844aa47fc3c5c82253ef38bd545bf12c93470502685\", \"asset_id\":\"56108879726720646120583724001239294777304794469144970684362785767667828318889\", \"bids\":[{\"price\":\"0.01\", \"size\":\"56199.15\"}, {\"price\":\"0.02\", \"size\":\"22462.28\"}, {\"price\":\"0.03\", \"size\":\"2161.73\"}, {\"price\":\"0.04\", \"size\":\"1695.28\"}, {\"price\":\"0.05\", \"size\":\"1862.1\"}, {\"price\":\"0.06\", \"size\":\"991.6\"}, {\"price\":\"0.07\", \"size\":\"1035.18\"}, {\"price\":\"0.08\", \"size\":\"832.11\"}, {\"price\":\"0.09\", \"size\":\"679.28\"}, {\"price\":\"0.1\", \"size\":\"314.76\"}, {\"price\":\"0.11\", \"size\":\"597\"}, {\"price\":\"0.12\", \"size\":\"335.24\"}, {\"price\":\"0.13\", \"size\":\"84.2\"}, {\"price\":\"0.14\", \"size\":\"91.55\"}, {\"price\":\"0.15\", \"size\":\"52.86\"}, {\"price\":\"0.16\", \"size\":\"66.94\"}, {\"price\":\"0.17\", \"size\":\"54.08\"}, {\"price\":\"0.18\", \"size\":\"360.6\"}, {\"price\":\"0.19\", \"size\":\"39.67\"}, {\"price\":\"0.2\", \"size\":\"729.5\"}, {\"price\":\"0.21\", \"size\":\"177.95\"}, {\"price\":\"0.22\", \"size\":\"513.6\"}, {\"price\":\"0.23\", \"size\":\"39.3\"}, {\"price\":\"0.24\", \"size\":\"58.1\"}, {\"price\":\"0.25\", \"size\":\"27.9\"}, {\"price\":\"0.26\", \"size\":\"92.8\"}, {\"price\":\"0.27\", \"size\":\"118.11\"}, {\"price\":\"0.28\", \"size\":\"67.4\"}, {\"price\":\"0.29\", \"size\":\"87.3\"}, {\"price\":\"0.3\", \"size\":\"87.2\"}, {\"price\":\"0.31\", \"size\":\"96\"}, {\"price\":\"0.32\", \"size\":\"219.42\"}, {\"price\":\"0.33\", \"size\":\"207\"}, {\"price\":\"0.34\", \"size\":\"107\"}, {\"price\":\"0.35\", \"size\":\"316\"}, {\"price\":\"0.36\", \"size\":\"316\"}, {\"price\":\"0.37\", \"size\":\"305.04\"}, {\"price\":\"0.38\", \"size\":\"303.25\"}, {\"price\":\"0.39\", \"size\":\"365\"}, {\"price\":\"0.4\", \"size\":\"331\"}, {\"price\":\"0.41\", \"size\":\"141.72\"}, {\"price\":\"0.42\", \"size\":\"156.2\"}, {\"price\":\"0.43\", \"size\":\"140\"}, {\"price\":\"0.44\", \"size\":\"56.25\"}, {\"price\":\"0.45\", \"size\":\"501.39\"}], \"asks\":[{\"price\":\"0.99\", \"size\":\"55001.6\"}, {\"price\":\"0.98\", \"size\":\"22471.85\"}, {\"price\":\"0.97\", \"size\":\"2148.4\"}, {\"price\":\"0.96\", \"size\":\"1677.1\"}, {\"price\":\"0.95\", \"size\":\"1864.11\"}, {\"price\":\"0.94\", \"size\":\"1008.6\"}, {\"price\":\"0.93\", \"size\":\"992.18\"}, {\"price\":\"0.92\", \"size\":\"829.12\"}, {\"price\":\"0.91\", \"size\":\"781.72\"}, {\"price\":\"0.9\", \"size\":\"1234.15\"}, {\"price\":\"0.89\", \"size\":\"564.4\"}, {\"price\":\"0.88\", \"size\":\"303.64\"}, {\"price\":\"0.87\", \"size\":\"153.2\"}, {\"price\":\"0.86\", \"size\":\"61.95\"}, {\"price\":\"0.85\", \"size\":\"43.86\"}, {\"price\":\"0.84\", \"size\":\"58.94\"}, {\"price\":\"0.83\", \"size\":\"26.08\"}, {\"price\":\"0.82\", \"size\":\"45.36\"}, {\"price\":\"0.81\", \"size\":\"24.67\"}, {\"price\":\"0.8\", \"size\":\"83.51\"}, {\"price\":\"0.79\", \"size\":\"142.8\"}, {\"price\":\"0.78\", \"size\":\"47.6\"}, {\"price\":\"0.77\", \"size\":\"17.3\"}, {\"price\":\"0.76\", \"size\":\"47.1\"}, {\"price\":\"0.75\", \"size\":\"469.9\"}, {\"price\":\"0.74\", \"size\":\"46.8\"}, {\"price\":\"0.73\", \"size\":\"46.6\"}, {\"price\":\"0.72\", \"size\":\"51.4\"}, {\"price\":\"0.71\", \"size\":\"89.3\"}, {\"price\":\"0.7\", \"size\":\"74.2\"}, {\"price\":\"0.69\", \"size\":\"103.6\"}, {\"price\":\"0.68\", \"size\":\"87\"}, {\"price\":\"0.67\", \"size\":\"61.9\"}, {\"price\":\"0.66\", \"size\":\"91.8\"}, {\"price\":\"0.65\", \"size\":\"113.97\"}, {\"price\":\"0.64\", \"size\":\"371.6\"}, {\"price\":\"0.63\", \"size\":\"91.6\"}, {\"price\":\"0.62\", \"size\":\"71.5\"}, {\"price\":\"0.61\", \"size\":\"704.22\"}, {\"price\":\"0.6\", \"size\":\"111.4\"}, {\"price\":\"0.59\", \"size\":\"536.4\"}, {\"price\":\"0.58\", \"size\":\"219\"}, {\"price\":\"0.57\", \"size\":\"141\"}, {\"price\":\"0.56\", \"size\":\"128.53\"}, {\"price\":\"0.55\", \"size\":\"128.77\"}, {\"price\":\"0.54\", \"size\":\"347.36\"}, {\"price\":\"0.53\", \"size\":\"227.19\"}, {\"price\":\"0.52\", \"size\":\"1052.68\"}, {\"price\":\"0.51\", \"size\":\"434.91\"}, {\"price\":\"0.5\", \"size\":\"448.08\"}, {\"price\":\"0.49\", \"size\":\"227.14\"}, {\"price\":\"0.48\", \"size\":\"161.37\"}, {\"price\":\"0.47\", \"size\":\"122.63\"}, {\"price\":\"0.46\", \"size\":\"309.52\"}], \"hash\":\"ce5f4fc689693dd33c80c8265c933f7b3cf449d9\", \"timestamp\":\"1781254837059\", \"event_type\":\"book\"}","ts_local_ms":1781254837648}
{"dir":"in","text":"{\"market\":\"0x9c535590faae21bf76fed844aa47fc3c5c82253ef38bd545bf12c93470502685\", \"asset_id\":\"107011546575057755426871645700605806081353395825571114128343592072429146374928\", \"bids\":[{\"price\":\"0.01\", \"size\":\"55001.6\"}, {\"price\":\"0.02\", \"size\":\"22471.85\"}, {\"price\":\"0.03\", \"size\":\"2148.4\"}, {\"price\":\"0.04\", \"size\":\"1677.1\"}, {\"price\":\"0.05\", \"size\":\"1864.11\"}, {\"price\":\"0.06\", \"size\":\"1008.6\"}, {\"price\":\"0.07\", \"size\":\"992.18\"}, {\"price\":\"0.08\", \"size\":\"829.12\"}, {\"price\":\"0.09\", \"size\":\"781.72\"}, {\"price\":\"0.1\", \"size\":\"1234.15\"}, {\"price\":\"0.11\", \"size\":\"564.4\"}, {\"price\":\"0.12\", \"size\":\"303.64\"}, {\"price\":\"0.13\", \"size\":\"153.2\"}, {\"price\":\"0.14\", \"size\":\"61.95\"}, {\"price\":\"0.15\", \"size\":\"43.86\"}, {\"price\":\"0.16\", \"size\":\"58.94\"}, {\"price\":\"0.17\", \"size\":\"26.08\"}, {\"price\":\"0.18\", \"size\":\"45.36\"}, {\"price\":\"0.19\", \"size\":\"24.67\"}, {\"price\":\"0.2\", \"size\":\"83.51\"}, {\"price\":\"0.21\", \"size\":\"142.8\"}, {\"price\":\"0.22\", \"size\":\"47.6\"}, {\"price\":\"0.23\", \"size\":\"17.3\"}, {\"price\":\"0.24\", \"size\":\"47.1\"}, {\"price\":\"0.25\", \"size\":\"469.9\"}, {\"price\":\"0.26\", \"size\":\"46.8\"}, {\"price\":\"0.27\", \"size\":\"46.6\"}, {\"price\":\"0.28\", \"size\":\"51.4\"}, {\"price\":\"0.29\", \"size\":\"89.3\"}, {\"price\":\"0.3\", \"size\":\"74.2\"}, {\"price\":\"0.31\", \"size\":\"103.6\"}, {\"price\":\"0.32\", \"size\":\"87\"}, {\"price\":\"0.33\", \"size\":\"61.9\"}, {\"price\":\"0.34\", \"size\":\"91.8\"}, {\"price\":\"0.35\", \"size\":\"113.97\"}, {\"price\":\"0.36\", \"size\":\"371.6\"}, {\"price\":\"0.37\", \"size\":\"91.6\"}, {\"price\":\"0.38\", \"size\":\"71.5\"}, {\"price\":\"0.39\", \"size\":\"704.22\"}, {\"price\":\"0.4\", \"size\":\"111.4\"}, {\"price\":\"0.41\", \"size\":\"536.4\"}, {\"price\":\"0.42\", \"size\":\"219\"}, {\"price\":\"0.43\", \"size\":\"141\"}, {\"price\":\"0.44\", \"size\":\"128.53\"}, {\"price\":\"0.45\", \"size\":\"128.77\"}, {\"price\":\"0.46\", \"size\":\"347.36\"}, {\"price\":\"0.47\", \"size\":\"227.19\"}, {\"price\":\"0.48\", \"size\":\"1052.68\"}, {\"price\":\"0.49\", \"size\":\"434.91\"}, {\"price\":\"0.5\", \"size\":\"448.08\"}, {\"price\":\"0.51\", \"size\":\"227.14\"}, {\"price\":\"0.52\", \"size\":\"161.37\"}, {\"price\":\"0.53\", \"size\":\"122.63\"}, {\"price\":\"0.54\", \"size\":\"309.52\"}], \"asks\":[{\"price\":\"0.99\", \"size\":\"56199.15\"}, {\"price\":\"0.98\", \"size\":\"22462.28\"}, {\"price\":\"0.97\", \"size\":\"2161.73\"}, {\"price\":\"0.96\", \"size\":\"1695.28\"}, {\"price\":\"0.95\", \"size\":\"1862.1\"}, {\"price\":\"0.94\", \"size\":\"991.6\"}, {\"price\":\"0.93\", \"size\":\"1035.18\"}, {\"price\":\"0.92\", \"size\":\"832.11\"}, {\"price\":\"0.91\", \"size\":\"679.28\"}, {\"price\":\"0.9\", \"size\":\"314.76\"}, {\"price\":\"0.89\", \"size\":\"597\"}, {\"price\":\"0.88\", \"size\":\"335.24\"}, {\"price\":\"0.87\", \"size\":\"84.2\"}, {\"price\":\"0.86\", \"size\":\"91.55\"}, {\"price\":\"0.85\", \"size\":\"52.86\"}, {\"price\":\"0.84\", \"size\":\"66.94\"}, {\"price\":\"0.83\", \"size\":\"54.08\"}, {\"price\":\"0.82\", \"size\":\"360.6\"}, {\"price\":\"0.81\", \"size\":\"39.67\"}, {\"price\":\"0.8\", \"size\":\"729.5\"}, {\"price\":\"0.79\", \"size\":\"177.95\"}, {\"price\":\"0.78\", \"size\":\"513.6\"}, {\"price\":\"0.77\", \"size\":\"39.3\"}, {\"price\":\"0.76\", \"size\":\"58.1\"}, {\"price\":\"0.75\", \"size\":\"27.9\"}, {\"price\":\"0.74\", \"size\":\"92.8\"}, {\"price\":\"0.73\", \"size\":\"118.11\"}, {\"price\":\"0.72\", \"size\":\"67.4\"}, {\"price\":\"0.71\", \"size\":\"87.3\"}, {\"price\":\"0.7\", \"size\":\"87.2\"}, {\"price\":\"0.69\", \"size\":\"96\"}, {\"price\":\"0.68\", \"size\":\"219.42\"}, {\"price\":\"0.67\", \"size\":\"207\"}, {\"price\":\"0.66\", \"size\":\"107\"}, {\"price\":\"0.65\", \"size\":\"316\"}, {\"price\":\"0.64\", \"size\":\"316\"}, {\"price\":\"0.63\", \"size\":\"305.04\"}, {\"price\":\"0.62\", \"size\":\"303.25\"}, {\"price\":\"0.61\", \"size\":\"365\"}, {\"price\":\"0.6\", \"size\":\"331\"}, {\"price\":\"0.59\", \"size\":\"141.72\"}, {\"price\":\"0.58\", \"size\":\"156.2\"}, {\"price\":\"0.57\", \"size\":\"140\"}, {\"price\":\"0.56\", \"size\":\"56.25\"}, {\"price\":\"0.55\", \"size\":\"501.39\"}], \"hash\":\"4e686dc6fc6680b25a35e5e941888b8f7fe1e8bb\", \"timestamp\":\"1781254837059\", \"event_type\":\"book\"}","ts_local_ms":1781254837648}
{"dir":"in","text":"{\"market\":\"0x9c535590faae21bf76fed844aa47fc3c5c82253ef38bd545bf12c93470502685\", \"price_changes\":[{\"asset_id\":\"56108879726720646120583724001239294777304794469144970684362785767667828318889\", \"price\":\"0.45\", \"size\":\"489.39\", \"side\":\"BUY\", \"hash\":\"32d39d49cc38e685d2304f506ba107e693b6de91\", \"best_bid\":\"0.45\", \"best_ask\":\"0.46\"}, {\"asset_id\":\"107011546575057755426871645700605806081353395825571114128343592072429146374928\", \"price\":\"0.55\", \"size\":\"489.39\", \"side\":\"SELL\", \"hash\":\"5aa8c99679562f8fee47e503959ec1ea498725f1\", \"best_bid\":\"0.54\", \"best_ask\":\"0.55\"}], \"timestamp\":\"1781254837064\", \"event_type\":\"price_change\"}","ts_local_ms":1781254837649}
{"dir":"in","text":"{\"market\":\"0x9c535590faae21bf76fed844aa47fc3c5c82253ef38bd545bf12c93470502685\", \"price_changes\":[{\"asset_id\":\"56108879726720646120583724001239294777304794469144970684362785767667828318889\", \"price\":\"0.45\", \"size\":\"476.39\", \"side\":\"BUY\", \"hash\":\"044c26bce16447088a62f131f9a93db93572f984\", \"best_bid\":\"0.45\", \"best_ask\":\"0.46\"}, {\"asset_id\":\"107011546575057755426871645700605806081353395825571114128343592072429146374928\", \"price\":\"0.55\", \"size\":\"476.39\", \"side\":\"SELL\", \"hash\":\"add4c636b7e4ef1f5e23dfb14ebb2a81e56cd267\", \"best_bid\":\"0.54\", \"best_ask\":\"0.55\"}], \"timestamp\":\"1781254837065\", \"event_type\":\"price_change\"}","ts_local_ms":1781254837649}
{"dir":"in","text":"{\"market\":\"0x9c535590faae21bf76fed844aa47fc3c5c82253ef38bd545bf12c93470502685\", \"asset_id\":\"56108879726720646120583724001239294777304794469144970684362785767667828318889\", \"best_bid\":\"0.45\", \"best_ask\":\"0.46\", \"spread\":\"0.01\", \"timestamp\":\"1781254837068\", \"event_type\":\"best_bid_ask\"}","ts_local_ms":1781254837649}
{"dir":"in","text":"{\"market\":\"0x9c535590faae21bf76fed844aa47fc3c5c82253ef38bd545bf12c93470502685\", \"asset_id\":\"107011546575057755426871645700605806081353395825571114128343592072429146374928\", \"best_bid\":\"0.54\", \"best_ask\":\"0.55\", \"spread\":\"0.01\", \"timestamp\":\"1781254837068\", \"event_type\":\"best_bid_ask\"}","ts_local_ms":1781254837649}
{"dir":"in","text":"{\"market\":\"0x9c535590faae21bf76fed844aa47fc3c5c82253ef38bd545bf12c93470502685\", \"price_changes\":[{\"asset_id\":\"107011546575057755426871645700605806081353395825571114128343592072429146374928\", \"price\":\"0.54\", \"size\":\"304.52\", \"side\":\"BUY\", \"hash\":\"f8def2f71ebc105f2d9f1518c4957c769aa11d56\", \"best_bid\":\"0.54\", \"best_ask\":\"0.55\"}, {\"asset_id\":\"56108879726720646120583724001239294777304794469144970684362785767667828318889\", \"price\":\"0.46\", \"size\":\"304.52\", \"side\":\"SELL\", \"hash\":\"549a5ced2907d2db96b85baa76d470d9ab3ebbf4\", \"best_bid\":\"0.45\", \"best_ask\":\"0.46\"}], \"timestamp\":\"1781254837068\", \"event_type\":\"price_change\"}","ts_local_ms":1781254837649}
{"dir":"in","text":"{\"market\":\"0x9c535590faae21bf76fed844aa47fc3c5c82253ef38bd545bf12c93470502685\", \"asset_id\":\"56108879726720646120583724001239294777304794469144970684362785767667828318889\", \"bids\":[{\"price\":\"0.01\", \"size\":\"56199.15\"}, {\"price\":\"0.02\", \"size\":\"22462.28\"}, {\"price\":\"0.03\", \"size\":\"2161.73\"}, {\"price\":\"0.04\", \"size\":\"1695.28\"}, {\"price\":\"0.05\", \"size\":\"1862.1\"}, {\"price\":\"0.06\", \"size\":\"991.6\"}, {\"price\":\"0.07\", \"size\":\"1035.18\"}, {\"price\":\"0.08\", \"size\":\"832.11\"}, {\"price\":\"0.09\", \"size\":\"679.28\"}, {\"price\":\"0.1\", \"size\":\"314.76\"}, {\"price\":\"0.11\", \"size\":\"597\"}, {\"price\":\"0.12\", \"size\":\"335.24\"}, {\"price\":\"0.13\", \"size\":\"84.2\"}, {\"price\":\"0.14\", \"size\":\"91.55\"}, {\"price\":\"0.15\", \"size\":\"52.86\"}, {\"price\":\"0.16\", \"size\":\"66.94\"}, {\"price\":\"0.17\", \"size\":\"54.08\"}, {\"price\":\"0.18\", \"size\":\"360.6\"}, {\"price\":\"0.19\", \"size\":\"39.67\"}, {\"price\":\"0.2\", \"size\":\"729.5\"}, {\"price\":\"0.21\", \"size\":\"177.95\"}, {\"price\":\"0.22\", \"size\":\"513.6\"}, {\"price\":\"0.23\", \"size\":\"39.3\"}, {\"price\":\"0.24\", \"size\":\"58.1\"}, {\"price\":\"0.25\", \"size\":\"27.9\"}, {\"price\":\"0.26\", \"size\":\"92.8\"}, {\"price\":\"0.27\", \"size\":\"118.11\"}, {\"price\":\"0.28\", \"size\":\"67.4\"}, {\"price\":\"0.29\", \"size\":\"87.3\"}, {\"price\":\"0.3\", \"size\":\"87.2\"}, {\"price\":\"0.31\", \"size\":\"96\"}, {\"price\":\"0.32\", \"size\":\"219.42\"}, {\"price\":\"0.33\", \"size\":\"207\"}, {\"price\":\"0.34\", \"size\":\"107\"}, {\"price\":\"0.35\", \"size\":\"316\"}, {\"price\":\"0.36\", \"size\":\"316\"}, {\"price\":\"0.37\", \"size\":\"305.04\"}, {\"price\":\"0.38\", \"size\":\"303.25\"}, {\"price\":\"0.39\", \"size\":\"365\"}, {\"price\":\"0.4\", \"size\":\"331\"}, {\"price\":\"0.41\", \"size\":\"141.72\"}, {\"price\":\"0.42\", \"size\":\"156.2\"}, {\"price\":\"0.43\", \"size\":\"140\"}, {\"price\":\"0.44\", \"size\":\"56.25\"}, {\"price\":\"0.45\", \"size\":\"476.39\"}], \"asks\":[{\"price\":\"0.99\", \"size\":\"55001.6\"}, {\"price\":\"0.98\", \"size\":\"22471.85\"}, {\"price\":\"0.97\", \"size\":\"2148.4\"}, {\"price\":\"0.96\", \"size\":\"1677.1\"}, {\"price\":\"0.95\", \"size\":\"1864.11\"}, {\"price\":\"0.94\", \"size\":\"1008.6\"}, {\"price\":\"0.93\", \"size\":\"992.18\"}, {\"price\":\"0.92\", \"size\":\"829.12\"}, {\"price\":\"0.91\", \"size\":\"781.72\"}, {\"price\":\"0.9\", \"size\":\"1234.15\"}, {\"price\":\"0.89\", \"size\":\"564.4\"}, {\"price\":\"0.88\", \"size\":\"303.64\"}, {\"price\":\"0.87\", \"size\":\"153.2\"}, {\"price\":\"0.86\", \"size\":\"61.95\"}, {\"price\":\"0.85\", \"size\":\"43.86\"}, {\"price\":\"0.84\", \"size\":\"58.94\"}, {\"price\":\"0.83\", \"size\":\"26.08\"}, {\"price\":\"0.82\", \"size\":\"45.36\"}, {\"price\":\"0.81\", \"size\":\"24.67\"}, {\"price\":\"0.8\", \"size\":\"83.51\"}, {\"price\":\"0.79\", \"size\":\"142.8\"}, {\"price\":\"0.78\", \"size\":\"47.6\"}, {\"price\":\"0.77\", \"size\":\"17.3\"}, {\"price\":\"0.76\", \"size\":\"47.1\"}, {\"price\":\"0.75\", \"size\":\"469.9\"}, {\"price\":\"0.74\", \"size\":\"46.8\"}, {\"price\":\"0.73\", \"size\":\"46.6\"}, {\"price\":\"0.72\", \"size\":\"51.4\"}, {\"price\":\"0.71\", \"size\":\"89.3\"}, {\"price\":\"0.7\", \"size\":\"74.2\"}, {\"price\":\"0.69\", \"size\":\"103.6\"}, {\"price\":\"0.68\", \"size\":\"87\"}, {\"price\":\"0.67\", \"size\":\"61.9\"}, {\"price\":\"0.66\", \"size\":\"91.8\"}, {\"price\":\"0.65\", \"size\":\"113.97\"}, {\"price\":\"0.64\", \"size\":\"371.6\"}, {\"price\":\"0.63\", \"size\":\"91.6\"}, {\"price\":\"0.62\", \"size\":\"71.5\"}, {\"price\":\"0.61\", \"size\":\"704.22\"}, {\"price\":\"0.6\", \"size\":\"111.4\"}, {\"price\":\"0.59\", \"size\":\"536.4\"}, {\"price\":\"0.58\", \"size\":\"219\"}, {\"price\":\"0.57\", \"size\":\"141\"}, {\"price\":\"0.56\", \"size\":\"128.53\"}, {\"price\":\"0.55\", \"size\":\"128.77\"}, {\"price\":\"0.54\", \"size\":\"347.36\"}, {\"price\":\"0.53\", \"size\":\"227.19\"}, {\"price\":\"0.52\", \"size\":\"1052.68\"}, {\"price\":\"0.51\", \"size\":\"434.91\"}, {\"price\":\"0.5\", \"size\":\"448.08\"}, {\"price\":\"0.49\", \"size\":\"227.14\"}, {\"price\":\"0.48\", \"size\":\"161.37\"}, {\"price\":\"0.47\", \"size\":\"122.63\"}, {\"price\":\"0.46\", \"size\":\"304.52\"}], \"hash\":\"549a5ced2907d2db96b85baa76d470d9ab3ebbf4\", \"timestamp\":\"1781254837068\", \"event_type\":\"book\"}","ts_local_ms":1781254837649}
{"dir":"in","text":"{\"market\":\"0x9c535590faae21bf76fed844aa47fc3c5c82253ef38bd545bf12c93470502685\", \"asset_id\":\"107011546575057755426871645700605806081353395825571114128343592072429146374928\", \"bids\":[{\"price\":\"0.01\", \"size\":\"55001.6\"}, {\"price\":\"0.02\", \"size\":\"22471.85\"}, {\"price\":\"0.03\", \"size\":\"2148.4\"}, {\"price\":\"0.04\", \"size\":\"1677.1\"}, {\"price\":\"0.05\", \"size\":\"1864.11\"}, {\"price\":\"0.06\", \"size\":\"1008.6\"}, {\"price\":\"0.07\", \"size\":\"992.18\"}, {\"price\":\"0.08\", \"size\":\"829.12\"}, {\"price\":\"0.09\", \"size\":\"781.72\"}, {\"price\":\"0.1\", \"size\":\"1234.15\"}, {\"price\":\"0.11\", \"size\":\"564.4\"}, {\"price\":\"0.12\", \"size\":\"303.64\"}, {\"price\":\"0.13\", \"size\":\"153.2\"}, {\"price\":\"0.14\", \"size\":\"61.95\"}, {\"price\":\"0.15\", \"size\":\"43.86\"}, {\"price\":\"0.16\", \"size\":\"58.94\"}, {\"price\":\"0.17\", \"size\":\"26.08\"}, {\"price\":\"0.18\", \"size\":\"45.36\"}, {\"price\":\"0.19\", \"size\":\"24.67\"}, {\"price\":\"0.2\", \"size\":\"83.51\"}, {\"price\":\"0.21\", \"size\":\"142.8\"}, {\"price\":\"0.22\", \"size\":\"47.6\"}, {\"price\":\"0.23\", \"size\":\"17.3\"}, {\"price\":\"0.24\", \"size\":\"47.1\"}, {\"price\":\"0.25\", \"size\":\"469.9\"}, {\"price\":\"0.26\", \"size\":\"46.8\"}, {\"price\":\"0.27\", \"size\":\"46.6\"}, {\"price\":\"0.28\", \"size\":\"51.4\"}, {\"price\":\"0.29\", \"size\":\"89.3\"}, {\"price\":\"0.3\", \"size\":\"74.2\"}, {\"price\":\"0.31\", \"size\":\"103.6\"}, {\"price\":\"0.32\", \"size\":\"87\"}, {\"price\":\"0.33\", \"size\":\"61.9\"}, {\"price\":\"0.34\", \"size\":\"91.8\"}, {\"price\":\"0.35\", \"size\":\"113.97\"}, {\"price\":\"0.36\", \"size\":\"371.6\"}, {\"price\":\"0.37\", \"size\":\"91.6\"}, {\"price\":\"0.38\", \"size\":\"71.5\"}, {\"price\":\"0.39\", \"size\":\"704.22\"}, {\"price\":\"0.4\", \"size\":\"111.4\"}, {\"price\":\"0.41\", \"size\":\"536.4\"}, {\"price\":\"0.42\", \"size\":\"219\"}, {\"price\":\"0.43\", \"size\":\"141\"}, {\"price\":\"0.44\", \"size\":\"128.53\"}, {\"price\":\"0.45\", \"size\":\"128.77\"}, {\"price\":\"0.46\", \"size\":\"347.36\"}, {\"price\":\"0.47\", \"size\":\"227.19\"}, {\"price\":\"0.48\", \"size\":\"1052.68\"}, {\"price\":\"0.49\", \"size\":\"434.91\"}, {\"price\":\"0.5\", \"size\":\"448.08\"}, {\"price\":\"0.51\", \"size\":\"227.14\"}, {\"price\":\"0.52\", \"size\":\"161.37\"}, {\"price\":\"0.53\", \"size\":\"122.63\"}, {\"price\":\"0.54\", \"size\":\"304.52\"}], \"asks\":[{\"price\":\"0.99\", \"size\":\"56199.15\"}, {\"price\":\"0.98\", \"size\":\"22462.28\"}, {\"price\":\"0.97\", \"size\":\"2161.73\"}, {\"price\":\"0.96\", \"size\":\"1695.28\"}, {\"price\":\"0.95\", \"size\":\"1862.1\"}, {\"price\":\"0.94\", \"size\":\"991.6\"}, {\"price\":\"0.93\", \"size\":\"1035.18\"}, {\"price\":\"0.92\", \"size\":\"832.11\"}, {\"price\":\"0.91\", \"size\":\"679.28\"}, {\"price\":\"0.9\", \"size\":\"314.76\"}, {\"price\":\"0.89\", \"size\":\"597\"}, {\"price\":\"0.88\", \"size\":\"335.24\"}, {\"price\":\"0.87\", \"size\":\"84.2\"}, {\"price\":\"0.86\", \"size\":\"91.55\"}, {\"price\":\"0.85\", \"size\":\"52.86\"}, {\"price\":\"0.84\", \"size\":\"66.94\"}, {\"price\":\"0.83\", \"size\":\"54.08\"}, {\"price\":\"0.82\", \"size\":\"360.6\"}, {\"price\":\"0.81\", \"size\":\"39.67\"}, {\"price\":\"0.8\", \"size\":\"729.5\"}, {\"price\":\"0.79\", \"size\":\"177.95\"}, {\"price\":\"0.78\", \"size\":\"513.6\"}, {\"price\":\"0.77\", \"size\":\"39.3\"}, {\"price\":\"0.76\", \"size\":\"58.1\"}, {\"price\":\"0.75\", \"size\":\"27.9\"}, {\"price\":\"0.74\", \"size\":\"92.8\"}, {\"price\":\"0.73\", \"size\":\"118.11\"}, {\"price\":\"0.72\", \"size\":\"67.4\"}, {\"price\":\"0.71\", \"size\":\"87.3\"}, {\"price\":\"0.7\", \"size\":\"87.2\"}, {\"price\":\"0.69\", \"size\":\"96\"}, {\"price\":\"0.68\", \"size\":\"219.42\"}, {\"price\":\"0.67\", \"size\":\"207\"}, {\"price\":\"0.66\", \"size\":\"107\"}, {\"price\":\"0.65\", \"size\":\"316\"}, {\"price\":\"0.64\", \"size\":\"316\"}, {\"price\":\"0.63\", \"size\":\"305.04\"}, {\"price\":\"0.62\", \"size\":\"303.25\"}, {\"price\":\"0.61\", \"size\":\"365\"}, {\"price\":\"0.6\", \"size\":\"331\"}, {\"price\":\"0.59\", \"size\":\"141.72\"}, {\"price\":\"0.58\", \"size\":\"156.2\"}, {\"price\":\"0.57\", \"size\":\"140\"}, {\"price\":\"0.56\", \"size\":\"56.25\"}, {\"price\":\"0.55\", \"size\":\"476.39\"}], \"hash\":\"f8def2f71ebc105f2d9f1518c4957c769aa11d56\", \"timestamp\":\"1781254837068\", \"event_type\":\"book\"}","ts_local_ms":1781254837806}
{"dir":"in","text":"{\"market\":\"0x9c535590faae21bf76fed844aa47fc3c5c82253ef38bd545bf12c93470502685\", \"price_changes\":[{\"asset_id\":\"56108879726720646120583724001239294777304794469144970684362785767667828318889\", \"price\":\"0.45\", \"size\":\"489.39\", \"side\":\"BUY\", \"hash\":\"c579f61eadfee66fe70fa7213e5b76e589bf49ff\", \"best_bid\":\"0.45\", \"best_ask\":\"0.46\"}, {\"asset_id\":\"107011546575057755426871645700605806081353395825571114128343592072429146374928\", \"price\":\"0.55\", \"size\":\"489.39\", \"side\":\"SELL\", \"hash\":\"f08950bf4c8f4f7ec006468f169472f78466fb0f\", \"best_bid\":\"0.54\", \"best_ask\":\"0.55\"}], \"timestamp\":\"1781254837072\", \"event_type\":\"price_change\"}","ts_local_ms":1781254837807}
{"dir":"in","text":"{\"market\":\"0x9c535590faae21bf76fed844aa47fc3c5c82253ef38bd545bf12c93470502685\", \"asset_id\":\"56108879726720646120583724001239294777304794469144970684362785767667828318889\", \"best_bid\":\"0.45\", \"best_ask\":\"0.46\", \"spread\":\"0.01\", \"timestamp\":\"1781254837074\", \"event_type\":\"best_bid_ask\"}","ts_local_ms":1781254837807}
{"dir":"in","text":"{\"market\":\"0x9c535590faae21bf76fed844aa47fc3c5c82253ef38bd545bf12c93470502685\", \"asset_id\":\"107011546575057755426871645700605806081353395825571114128343592072429146374928\", \"best_bid\":\"0.54\", \"best_ask\":\"0.55\", \"spread\":\"0.01\", \"timestamp\":\"1781254837074\", \"event_type\":\"best_bid_ask\"}","ts_local_ms":1781254837807}
{"dir":"in","text":"{\"market\":\"0x9c535590faae21bf76fed844aa47fc3c5c82253ef38bd545bf12c93470502685\", \"price_changes\":[{\"asset_id\":\"107011546575057755426871645700605806081353395825571114128343592072429146374928\", \"price\":\"0.54\", \"size\":\"204.52\", \"side\":\"BUY\", \"hash\":\"4cdad129d49a99cbd3b1c8399b808574d9ba652a\", \"best_bid\":\"0.54\", \"best_ask\":\"0.55\"}, {\"asset_id\":\"56108879726720646120583724001239294777304794469144970684362785767667828318889\", \"price\":\"0.46\", \"size\":\"204.52\", \"side\":\"SELL\", \"hash\":\"4e3e9795a652f4afc5bf85db6d0b0eaca90b55fc\", \"best_bid\":\"0.45\", \"best_ask\":\"0.46\"}], \"timestamp\":\"1781254837073\", \"event_type\":\"price_change\"}","ts_local_ms":1781254837807}
{"dir":"in","text":"{\"market\":\"0x9c535590faae21bf76fed844aa47fc3c5c82253ef38bd545bf12c93470502685\", \"asset_id\":\"56108879726720646120583724001239294777304794469144970684362785767667828318889\", \"bids\":[{\"price\":\"0.01\", \"size\":\"56199.15\"}, {\"price\":\"0.02\", \"size\":\"22462.28\"}, {\"price\":\"0.03\", \"size\":\"2161.73\"}, {\"price\":\"0.04\", \"size\":\"1695.28\"}, {\"price\":\"0.05\", \"size\":\"1862.1\"}, {\"price\":\"0.06\", \"size\":\"991.6\"}, {\"price\":\"0.07\", \"size\":\"1035.18\"}, {\"price\":\"0.08\", \"size\":\"832.11\"}, {\"price\":\"0.09\", \"size\":\"679.28\"}, {\"price\":\"0.1\", \"size\":\"314.76\"}, {\"price\":\"0.11\", \"size\":\"597\"}, {\"price\":\"0.12\", \"size\":\"335.24\"}, {\"price\":\"0.13\", \"size\":\"84.2\"}, {\"price\":\"0.14\", \"size\":\"91.55\"}, {\"price\":\"0.15\", \"size\":\"52.86\"}, {\"price\":\"0.16\", \"size\":\"66.94\"}, {\"price\":\"0.17\", \"size\":\"54.08\"}, {\"price\":\"0.18\", \"size\":\"360.6\"}, {\"price\":\"0.19\", \"size\":\"39.67\"}, {\"price\":\"0.2\", \"size\":\"729.5\"}, {\"price\":\"0.21\", \"size\":\"177.95\"}, {\"price\":\"0.22\", \"size\":\"513.6\"}, {\"price\":\"0.23\", \"size\":\"39.3\"}, {\"price\":\"0.24\", \"size\":\"58.1\"}, {\"price\":\"0.25\", \"size\":\"27.9\"}, {\"price\":\"0.26\", \"size\":\"92.8\"}, {\"price\":\"0.27\", \"size\":\"118.11\"}, {\"price\":\"0.28\", \"size\":\"67.4\"}, {\"price\":\"0.29\", \"size\":\"87.3\"}, {\"price\":\"0.3\", \"size\":\"87.2\"}, {\"price\":\"0.31\", \"size\":\"96\"}, {\"price\":\"0.32\", \"size\":\"219.42\"}, {\"price\":\"0.33\", \"size\":\"207\"}, {\"price\":\"0.34\", \"size\":\"107\"}, {\"price\":\"0.35\", \"size\":\"316\"}, {\"price\":\"0.36\", \"size\":\"316\"}, {\"price\":\"0.37\", \"size\":\"305.04\"}, {\"price\":\"0.38\", \"size\":\"303.25\"}, {\"price\":\"0.39\", \"size\":\"365\"}, {\"price\":\"0.4\", \"size\":\"331\"}, {\"price\":\"0.41\", \"size\":\"141.72\"}, {\"price\":\"0.42\", \"size\":\"156.2\"}, {\"price\":\"0.43\", \"size\":\"140\"}, {\"price\":\"0.44\", \"size\":\"56.25\"}, {\"price\":\"0.45\", \"size\":\"489.39\"}], \"asks\":[{\"price\":\"0.99\", \"size\":\"55001.6\"}, {\"price\":\"0.98\", \"size\":\"22471.85\"}, {\"price\":\"0.97\", \"size\":\"2148.4\"}, {\"price\":\"0.96\", \"size\":\"1677.1\"}, {\"price\":\"0.95\", \"size\":\"1864.11\"}, {\"price\":\"0.94\", \"size\":\"1008.6\"}, {\"price\":\"0.93\", \"size\":\"992.18\"}, {\"price\":\"0.92\", \"size\":\"829.12\"}, {\"price\":\"0.91\", \"size\":\"781.72\"}, {\"price\":\"0.9\", \"size\":\"1234.15\"}, {\"price\":\"0.89\", \"size\":\"564.4\"}, {\"price\":\"0.88\", \"size\":\"303.64\"}, {\"price\":\"0.87\", \"size\":\"153.2\"}, {\"price\":\"0.86\", \"size\":\"61.95\"}, {\"price\":\"0.85\", \"size\":\"43.86\"}, {\"price\":\"0.84\", \"size\":\"58.94\"}, {\"price\":\"0.83\", \"size\":\"26.08\"}, {\"price\":\"0.82\", \"size\":\"45.36\"}, {\"price\":\"0.81\", \"size\":\"24.67\"}, {\"price\":\"0.8\", \"size\":\"83.51\"}, {\"price\":\"0.79\", \"size\":\"142.8\"}, {\"price\":\"0.78\", \"size\":\"47.6\"}, {\"price\":\"0.77\", \"size\":\"17.3\"}, {\"price\":\"0.76\", \"size\":\"47.1\"}, {\"price\":\"0.75\", \"size\":\"469.9\"}, {\"price\":\"0.74\", \"size\":\"46.8\"}, {\"price\":\"0.73\", \"size\":\"46.6\"}, {\"price\":\"0.72\", \"size\":\"51.4\"}, {\"price\":\"0.71\", \"size\":\"89.3\"}, {\"price\":\"0.7\", \"size\":\"74.2\"}, {\"price\":\"0.69\", \"size\":\"103.6\"}, {\"price\":\"0.68\", \"size\":\"87\"}, {\"price\":\"0.67\", \"size\":\"61.9\"}, {\"price\":\"0.66\", \"size\":\"91.8\"}, {\"price\":\"0.65\", \"size\":\"113.97\"}, {\"price\":\"0.64\", \"size\":\"371.6\"}, {\"price\":\"0.63\", \"size\":\"91.6\"}, {\"price\":\"0.62\", \"size\":\"71.5\"}, {\"price\":\"0.61\", \"size\":\"704.22\"}, {\"price\":\"0.6\", \"size\":\"111.4\"}, {\"price\":\"0.59\", \"size\":\"536.4\"}, {\"price\":\"0.58\", \"size\":\"219\"}, {\"price\":\"0.57\", \"size\":\"141\"}, {\"price\":\"0.56\", \"size\":\"128.53\"}, {\"price\":\"0.55\", \"size\":\"128.77\"}, {\"price\":\"0.54\", \"size\":\"347.36\"}, {\"price\":\"0.53\", \"size\":\"227.19\"}, {\"price\":\"0.52\", \"size\":\"1052.68\"}, {\"price\":\"0.51\", \"size\":\"434.91\"}, {\"price\":\"0.5\", \"size\":\"448.08\"}, {\"price\":\"0.49\", \"size\":\"227.14\"}, {\"price\":\"0.48\", \"size\":\"161.37\"}, {\"price\":\"0.47\", \"size\":\"122.63\"}, {\"price\":\"0.46\", \"size\":\"204.52\"}], \"hash\":\"4e3e9795a652f4afc5bf85db6d0b0eaca90b55fc\", \"timestamp\":\"1781254837073\", \"event_type\":\"book\"}","ts_local_ms":1781254837807}
{"dir":"in","text":"{\"market\":\"0x9c535590faae21bf76fed844aa47fc3c5c82253ef38bd545bf12c93470502685\", \"asset_id\":\"107011546575057755426871645700605806081353395825571114128343592072429146374928\", \"bids\":[{\"price\":\"0.01\", \"size\":\"55001.6\"}, {\"price\":\"0.02\", \"size\":\"22471.85\"}, {\"price\":\"0.03\", \"size\":\"2148.4\"}, {\"price\":\"0.04\", \"size\":\"1677.1\"}, {\"price\":\"0.05\", \"size\":\"1864.11\"}, {\"price\":\"0.06\", \"size\":\"1008.6\"}, {\"price\":\"0.07\", \"size\":\"992.18\"}, {\"price\":\"0.08\", \"size\":\"829.12\"}, {\"price\":\"0.09\", \"size\":\"781.72\"}, {\"price\":\"0.1\", \"size\":\"1234.15\"}, {\"price\":\"0.11\", \"size\":\"564.4\"}, {\"price\":\"0.12\", \"size\":\"303.64\"}, {\"price\":\"0.13\", \"size\":\"153.2\"}, {\"price\":\"0.14\", \"size\":\"61.95\"}, {\"price\":\"0.15\", \"size\":\"43.86\"}, {\"price\":\"0.16\", \"size\":\"58.94\"}, {\"price\":\"0.17\", \"size\":\"26.08\"}, {\"price\":\"0.18\", \"size\":\"45.36\"}, {\"price\":\"0.19\", \"size\":\"24.67\"}, {\"price\":\"0.2\", \"size\":\"83.51\"}, {\"price\":\"0.21\", \"size\":\"142.8\"}, {\"price\":\"0.22\", \"size\":\"47.6\"}, {\"price\":\"0.23\", \"size\":\"17.3\"}, {\"price\":\"0.24\", \"size\":\"47.1\"}, {\"price\":\"0.25\", \"size\":\"469.9\"}, {\"price\":\"0.26\", \"size\":\"46.8\"}, {\"price\":\"0.27\", \"size\":\"46.6\"}, {\"price\":\"0.28\", \"size\":\"51.4\"}, {\"price\":\"0.29\", \"size\":\"89.3\"}, {\"price\":\"0.3\", \"size\":\"74.2\"}, {\"price\":\"0.31\", \"size\":\"103.6\"}, {\"price\":\"0.32\", \"size\":\"87\"}, {\"price\":\"0.33\", \"size\":\"61.9\"}, {\"price\":\"0.34\", \"size\":\"91.8\"}, {\"price\":\"0.35\", \"size\":\"113.97\"}, {\"price\":\"0.36\", \"size\":\"371.6\"}, {\"price\":\"0.37\", \"size\":\"91.6\"}, {\"price\":\"0.38\", \"size\":\"71.5\"}, {\"price\":\"0.39\", \"size\":\"704.22\"}, {\"price\":\"0.4\", \"size\":\"111.4\"}, {\"price\":\"0.41\", \"size\":\"536.4\"}, {\"price\":\"0.42\", \"size\":\"219\"}, {\"price\":\"0.43\", \"size\":\"141\"}, {\"price\":\"0.44\", \"size\":\"128.53\"}, {\"price\":\"0.45\", \"size\":\"128.77\"}, {\"price\":\"0.46\", \"size\":\"347.36\"}, {\"price\":\"0.47\", \"size\":\"227.19\"}, {\"price\":\"0.48\", \"size\":\"1052.68\"}, {\"price\":\"0.49\", \"size\":\"434.91\"}, {\"price\":\"0.5\", \"size\":\"448.08\"}, {\"price\":\"0.51\", \"size\":\"227.14\"}, {\"price\":\"0.52\", \"size\":\"161.37\"}, {\"price\":\"0.53\", \"size\":\"122.63\"}, {\"price\":\"0.54\", \"size\":\"204.52\"}], \"asks\":[{\"price\":\"0.99\", \"size\":\"56199.15\"}, {\"price\":\"0.98\", \"size\":\"22462.28\"}, {\"price\":\"0.97\", \"size\":\"2161.73\"}, {\"price\":\"0.96\", \"size\":\"1695.28\"}, {\"price\":\"0.95\", \"size\":\"1862.1\"}, {\"price\":\"0.94\", \"size\":\"991.6\"}, {\"price\":\"0.93\", \"size\":\"1035.18\"}, {\"price\":\"0.92\", \"size\":\"832.11\"}, {\"price\":\"0.91\", \"size\":\"679.28\"}, {\"price\":\"0.9\", \"size\":\"314.76\"}, {\"price\":\"0.89\", \"size\":\"597\"}, {\"price\":\"0.88\", \"size\":\"335.24\"}, {\"price\":\"0.87\", \"size\":\"84.2\"}, {\"price\":\"0.86\", \"size\":\"91.55\"}, {\"price\":\"0.85\", \"size\":\"52.86\"}, {\"price\":\"0.84\", \"size\":\"66.94\"}, {\"price\":\"0.83\", \"size\":\"54.08\"}, {\"price\":\"0.82\", \"size\":\"360.6\"}, {\"price\":\"0.81\", \"size\":\"39.67\"}, {\"price\":\"0.8\", \"size\":\"729.5\"}, {\"price\":\"0.79\", \"size\":\"177.95\"}, {\"price\":\"0.78\", \"size\":\"513.6\"}, {\"price\":\"0.77\", \"size\":\"39.3\"}, {\"price\":\"0.76\", \"size\":\"58.1\"}, {\"price\":\"0.75\", \"size\":\"27.9\"}, {\"price\":\"0.74\", \"size\":\"92.8\"}, {\"price\":\"0.73\", \"size\":\"118.11\"}, {\"price\":\"0.72\", \"size\":\"67.4\"}, {\"price\":\"0.71\", \"size\":\"87.3\"}, {\"price\":\"0.7\", \"size\":\"87.2\"}, {\"price\":\"0.69\", \"size\":\"96\"}, {\"price\":\"0.68\", \"size\":\"219.42\"}, {\"price\":\"0.67\", \"size\":\"207\"}, {\"price\":\"0.66\", \"size\":\"107\"}, {\"price\":\"0.65\", \"size\":\"316\"}, {\"price\":\"0.64\", \"size\":\"316\"}, {\"price\":\"0.63\", \"size\":\"305.04\"}, {\"price\":\"0.62\", \"size\":\"303.25\"}, {\"price\":\"0.61\", \"size\":\"365\"}, {\"price\":\"0.6\", \"size\":\"331\"}, {\"price\":\"0.59\", \"size\":\"141.72\"}, {\"price\":\"0.58\", \"size\":\"156.2\"}, {\"price\":\"0.57\", \"size\":\"140\"}, {\"price\":\"0.56\", \"size\":\"56.25\"}, {\"price\":\"0.55\", \"size\":\"489.39\"}], \"hash\":\"4cdad129d49a99cbd3b1c8399b808574d9ba652a\", \"timestamp\":\"1781254837073\", \"event_type\":\"book\"}","ts_local_ms":1781254837807}
{"dir":"in","text":"{\"market\":\"0x9c535590faae21bf76fed844aa47fc3c5c82253ef38bd545bf12c93470502685\", \"price_changes\":[{\"asset_id\":\"56108879726720646120583724001239294777304794469144970684362785767667828318889\", \"price\":\"0.45\", \"size\":\"414.39\", \"side\":\"BUY\", \"hash\":\"256471ac9a831bc805aa9600253f9e4ae4b2f68c\", \"best_bid\":\"0.45\", \"best_ask\":\"0.46\"}, {\"asset_id\":\"107011546575057755426871645700605806081353395825571114128343592072429146374928\", \"price\":\"0.55\", \"size\":\"414.39\", \"side\":\"SELL\", \"hash\":\"e69cf15395f24dad34e8c8443054c936483abdec\", \"best_bid\":\"0.54\", \"best_ask\":\"0.55\"}], \"timestamp\":\"1781254837079\", \"event_type\":\"price_change\"}","ts_local_ms":1781254837808}
{"dir":"in","text":"{\"market\":\"0x9c535590faae21bf76fed844aa47fc3c5c82253ef38bd545bf12c93470502685\", \"price_changes\":[{\"asset_id\":\"107011546575057755426871645700605806081353395825571114128343592072429146374928\", \"price\":\"0.54\", \"size\":\"194.52\", \"side\":\"BUY\", \"hash\":\"e190d774b15d364cfc879a8a72ead9fca1a244af\", \"best_bid\":\"0.54\", \"best_ask\":\"0.55\"}, {\"asset_id\":\"56108879726720646120583724001239294777304794469144970684362785767667828318889\", \"price\":\"0.46\", \"size\":\"194.52\", \"side\":\"SELL\", \"hash\":\"199cf68e2c508f8d1116787299bb7d966934ffb5\", \"best_bid\":\"0.45\", \"best_ask\":\"0.46\"}], \"timestamp\":\"1781254837079\", \"event_type\":\"price_change\"}","ts_local_ms":1781254837808}
{"dir":"in","text":"{\"market\":\"0x9c535590faae21bf76fed844aa47fc3c5c82253ef38bd545bf12c93470502685\", \"price_changes\":[{\"asset_id\":\"56108879726720646120583724001239294777304794469144970684362785767667828318889\", \"price\":\"0.45\", \"size\":\"401.39\", \"side\":\"BUY\", \"hash\":\"b4d3a659b3859dc15a98b399a4f0c76491cb3466\", \"best_bid\":\"0.45\", \"best_ask\":\"0.46\"}, {\"asset_id\":\"107011546575057755426871645700605806081353395825571114128343592072429146374928\", \"price\":\"0.55\", \"size\":\"401.39\", \"side\":\"SELL\", \"hash\":\"97f432c92df55ff107ebd7172508542552a86024\", \"best_bid\":\"0.54\", \"best_ask\":\"0.55\"}], \"timestamp\":\"1781254837079\", \"event_type\":\"price_change\"}","ts_local_ms":1781254837808}
{"dir":"in","text":"{\"market\":\"0x9c535590faae21bf76fed844aa47fc3c5c82253ef38bd545bf12c93470502685\", \"price_changes\":[{\"asset_id\":\"56108879726720646120583724001239294777304794469144970684362785767667828318889\", \"price\":\"0.45\", \"size\":\"429.39\", \"side\":\"BUY\", \"hash\":\"963967ec57e3c853bf7cdea192ec8733d012b71e\", \"best_bid\":\"0.45\", \"best_ask\":\"0.46\"}, {\"asset_id\":\"107011546575057755426871645700605806081353395825571114128343592072429146374928\", \"price\":\"0.55\", \"size\":\"429.39\", \"side\":\"SELL\", \"hash\":\"e68b0ae7f0a9c705abb3e0e954baf15464774905\", \"best_bid\":\"0.54\", \"best_ask\":\"0.55\"}], \"timestamp\":\"1781254837080\", \"event_type\":\"price_change\"}","ts_local_ms":1781254837808}
{"dir":"in","text":"{\"market\":\"0x9c535590faae21bf76fed844aa47fc3c5c82253ef38bd545bf12c93470502685\", \"price_changes\":[{\"asset_id\":\"56108879726720646120583724001239294777304794469144970684362785767667828318889\", \"price\":\"0.45\", \"size\":\"442.39\", \"side\":\"BUY\", \"hash\":\"9617d10cc60cbb90edaccf885190ae0693d2b2c5\", \"best_bid\":\"0.45\", \"best_ask\":\"0.46\"}, {\"asset_id\":\"107011546575057755426871645700605806081353395825571114128343592072429146374928\", \"price\":\"0.55\", \"size\":\"442.39\", \"side\":\"SELL\", \"hash\":\"e2aab8d7a1c4653d4d0115b38a123cc8617b667e\", \"best_bid\":\"0.54\", \"best_ask\":\"0.55\"}], \"timestamp\":\"1781254837080\", \"event_type\":\"price_change\"}","ts_local_ms":1781254837808}
{"dir":"in","text":"{\"market\":\"0x9c535590faae21bf76fed844aa47fc3c5c82253ef38bd545bf12c93470502685\", \"price_changes\":[{\"asset_id\":\"56108879726720646120583724001239294777304794469144970684362785767667828318889\", \"price\":\"0.35\", \"size\":\"266\", \"side\":\"BUY\", \"hash\":\"5d846057098842650b1e1ab4ceba58d77e5d23f4\", \"best_bid\":\"0.45\", \"best_ask\":\"0.46\"}, {\"asset_id\":\"107011546575057755426871645700605806081353395825571114128343592072429146374928\", \"price\":\"0.65\", \"size\":\"266\", \"side\":\"SELL\", \"hash\":\"437541eec371664c5274a6e547cce08996528d35\", \"best_bid\":\"0.54\", \"best_ask\":\"0.55\"}], \"timestamp\":\"1781254837081\", \"event_type\":\"price_change\"}","ts_local_ms":1781254837808}
{"dir":"in","text":"{\"market\":\"0x9c535590faae21bf76fed844aa47fc3c5c82253ef38bd545bf12c93470502685\", \"price_changes\":[{\"asset_id\":\"56108879726720646120583724001239294777304794469144970684362785767667828318889\", \"price\":\"0.45\", \"size\":\"462.39\", \"side\":\"BUY\", \"hash\":\"bdae25365653a010edd0f777fb6879bf5e5c8a60\", \"best_bid\":\"0.45\", \"best_ask\":\"0.46\"}, {\"asset_id\":\"107011546575057755426871645700605806081353395825571114128343592072429146374928\", \"price\":\"0.55\", \"size\":\"462.39\", \"side\":\"SELL\", \"hash\":\"4ec1ca4f491241b5ae146779e4e2d8d4aadec4e0\", \"best_bid\":\"0.54\", \"best_ask\":\"0.55\"}], \"timestamp\":\"1781254837081\", \"event_type\":\"price_change\"}","ts_local_ms":1781254837808}
{"dir":"in","text":"{\"market\":\"0x9c535590faae21bf76fed844aa47fc3c5c82253ef38bd545bf12c93470502685\", \"price_changes\":[{\"asset_id\":\"56108879726720646120583724001239294777304794469144970684362785767667828318889\", \"price\":\"0.45\", \"size\":\"449.39\", \"side\":\"BUY\", \"hash\":\"00d76e15b5e940e10ee44e99f5f603f2406ef699\", \"best_bid\":\"0.45\", \"best_ask\":\"0.46\"}, {\"asset_id\":\"107011546575057755426871645700605806081353395825571114128343592072429146374928\", \"price\":\"0.55\", \"size\":\"449.39\", \"side\":\"SELL\", \"hash\":\"e4abfe3b750c689e3416c9d1fcd3482c8cad2394\", \"best_bid\":\"0.54\", \"best_ask\":\"0.55\"}], \"timestamp\":\"1781254837082\", \"event_type\":\"price_change\"}","ts_local_ms":1781254837808}
{"dir":"in","text":"{\"market\":\"0x9c535590faae21bf76fed844aa47fc3c5c82253ef38bd545bf12c93470502685\", \"price_changes\":[{\"asset_id\":\"56108879726720646120583724001239294777304794469144970684362785767667828318889\", \"price\":\"0.25\", \"size\":\"57.9\", \"side\":\"BUY\", \"hash\":\"17113ead043a6e3c972c2c2f8a401540ec586050\", \"best_bid\":\"0.45\", \"best_ask\":\"0.46\"}, {\"asset_id\":\"107011546575057755426871645700605806081353395825571114128343592072429146374928\", \"price\":\"0.75\", \"size\":\"57.9\", \"side\":\"SELL\", \"hash\":\"a962aa59a7a72217b178a6f55e3861e404a21e40\", \"best_bid\":\"0.54\", \"best_ask\":\"0.55\"}], \"timestamp\":\"1781254837083\", \"event_type\":\"price_change\"}","ts_local_ms":1781254837808}
{"dir":"in","text":"{\"market\":\"0x9c535590faae21bf76fed844aa47fc3c5c82253ef38bd545bf12c93470502685\", \"price_changes\":[{\"asset_id\":\"56108879726720646120583724001239294777304794469144970684362785767667828318889\", \"price\":\"0.45\", \"size\":\"462.39\", \"side\":\"BUY\", \"hash\":\"45e6f2884467e13f57dd48f432b6056e69d44ba8\", \"best_bid\":\"0.45\", \"best_ask\":\"0.46\"}, {\"asset_id\":\"107011546575057755426871645700605806081353395825571114128343592072429146374928\", \"price\":\"0.55\", \"size\":\"462.39\", \"side\":\"SELL\", \"hash\":\"45acbd2720175ce20d3692b4531d8a386c4f767c\", \"best_bid\":\"0.54\", \"best_ask\":\"0.55\"}], \"timestamp\":\"1781254837083\", \"event_type\":\"price_change\"}","ts_local_ms":1781254837808}
{"dir":"in","text":"{\"market\":\"0x9c535590faae21bf76fed844aa47fc3c5c82253ef38bd545bf12c93470502685\", \"price_changes\":[{\"asset_id\":\"56108879726720646120583724001239294777304794469144970684362785767667828318889\", \"price\":\"0.45\", \"size\":\"437.39\", \"side\":\"BUY\", \"hash\":\"316452dedca7fd7aecf9fe25c46bf9b997c063bd\", \"best_bid\":\"0.45\", \"best_ask\":\"0.46\"}, {\"asset_id\":\"107011546575057755426871645700605806081353395825571114128343592072429146374928\", \"price\":\"0.55\", \"size\":\"437.39\", \"side\":\"SELL\", \"hash\":\"1f2331a2d2f542e725628195a80b2fb3fba5eb75\", \"best_bid\":\"0.54\", \"best_ask\":\"0.55\"}], \"timestamp\":\"1781254837084\", \"event_type\":\"price_change\"}","ts_local_ms":1781254837808}
{"dir":"in","text":"{\"market\":\"0x9c535590faae21bf76fed844aa47fc3c5c82253ef38bd545bf12c93470502685\", \"price_changes\":[{\"asset_id\":\"56108879726720646120583724001239294777304794469144970684362785767667828318889\", \"price\":\"0.38\", \"size\":\"296\", \"side\":\"BUY\", \"hash\":\"3c548152c6fb78cfc17da14caf3125c95a3dc008\", \"best_bid\":\"0.45\", \"best_ask\":\"0.46\"}, {\"asset_id\":\"107011546575057755426871645700605806081353395825571114128343592072429146374928\", \"price\":\"0.62\", \"size\":\"296\", \"side\":\"SELL\", \"hash\":\"94490c89923f277075eecdac63a6fdb4c0941623\", \"best_bid\":\"0.54\", \"best_ask\":\"0.55\"}], \"timestamp\":\"1781254837084\", \"event_type\":\"price_change\"}","ts_local_ms":1781254837808}
{"dir":"in","text":"{\"market\":\"0x9c535590faae21bf76fed844aa47fc3c5c82253ef38bd545bf12c93470502685\", \"price_changes\":[{\"asset_id\":\"56108879726720646120583724001239294777304794469144970684362785767667828318889\", \"price\":\"0.45\", \"size\":\"362.39\", \"side\":\"BUY\", \"hash\":\"5e74a69729079ef05bcf49630a3254b7d6f8e333\", \"best_bid\":\"0.45\", \"best_ask\":\"0.46\"}, {\"asset_id\":\"107011546575057755426871645700605806081353395825571114128343592072429146374928\", \"price\":\"0.55\", \"size\":\"362.39\", \"side\":\"SELL\", \"hash\":\"ff66640dd76de4fed23746768b2082e94c5a7bf4\", \"best_bid\":\"0.54\", \"best_ask\":\"0.55\"}], \"timestamp\":\"1781254837084\", \"event_type\":\"price_change\"}","ts_local_ms":1781254837808}
{"dir":"in","text":"{\"market\":\"0x9c535590faae21bf76fed844aa47fc3c5c82253ef38bd545bf12c93470502685\", \"price_changes\":[{\"asset_id\":\"56108879726720646120583724001239294777304794469144970684362785767667828318889\", \"price\":\"0.45\", \"size\":\"375.39\", \"side\":\"BUY\", \"hash\":\"ca49b748f6c5f2b9170d04ea68327c383580d357\", \"best_bid\":\"0.45\", \"best_ask\":\"0.46\"}, {\"asset_id\":\"107011546575057755426871645700605806081353395825571114128343592072429146374928\", \"price\":\"0.55\", \"size\":\"375.39\", \"side\":\"SELL\", \"hash\":\"1453bc147612418335f02f3820978cf41c48483c\", \"best_bid\":\"0.54\", \"best_ask\":\"0.55\"}], \"timestamp\":\"1781254837084\", \"event_type\":\"price_change\"}","ts_local_ms":1781254837808}
{"dir":"in","text":"{\"market\":\"0x9c535590faae21bf76fed844aa47fc3c5c82253ef38bd545bf12c93470502685\", \"price_changes\":[{\"asset_id\":\"107011546575057755426871645700605806081353395825571114128343592072429146374928\", \"price\":\"0.54\", \"size\":\"204.52\", \"side\":\"BUY\", \"hash\":\"b5e66acd563775e5277940e76c9818ab8c832516\", \"best_bid\":\"0.54\", \"best_ask\":\"0.55\"}, {\"asset_id\":\"56108879726720646120583724001239294777304794469144970684362785767667828318889\", \"price\":\"0.46\", \"size\":\"204.52\", \"side\":\"SELL\", \"hash\":\"29e7869701042774a7201b813466f7f227e69105\", \"best_bid\":\"0.45\", \"best_ask\":\"0.46\"}], \"timestamp\":\"1781254837085\", \"event_type\":\"price_change\"}","ts_local_ms":1781254837809}
{"dir":"in","text":"{\"market\":\"0x9c535590faae21bf76fed844aa47fc3c5c82253ef38bd545bf12c93470502685\", \"price_changes\":[{\"asset_id\":\"56108879726720646120583724001239294777304794469144970684362785767667828318889\", \"price\":\"0.45\", \"size\":\"388.39\", \"side\":\"BUY\", \"hash\":\"61ff69e0a54f6f9d9dae5ccaaef84980e3cf101e\", \"best_bid\":\"0.45\", \"best_ask\":\"0.46\"}, {\"asset_id\":\"107011546575057755426871645700605806081353395825571114128343592072429146374928\", \"price\":\"0.55\", \"size\":\"388.39\", \"side\":\"SELL\", \"hash\":\"049d1ae16dffb8cd1b44bcdd4cec1bd89ef2b195\", \"best_bid\":\"0.54\", \"best_ask\":\"0.55\"}], \"timestamp\":\"1781254837086\", \"event_type\":\"price_change\"}","ts_local_ms":1781254837809}
{"dir":"in","text":"{\"market\":\"0x9c535590faae21bf76fed844aa47fc3c5c82253ef38bd545bf12c93470502685\", \"price_changes\":[{\"asset_id\":\"56108879726720646120583724001239294777304794469144970684362785767667828318889\", \"price\":\"0.45\", \"size\":\"360.39\", \"side\":\"BUY\", \"hash\":\"6f4a2320dc5128fe8d227fa03fd2b0055f619b1c\", \"best_bid\":\"0.45\", \"best_ask\":\"0.46\"}, {\"asset_id\":\"107011546575057755426871645700605806081353395825571114128343592072429146374928\", \"price\":\"0.55\", \"size\":\"360.39\", \"side\":\"SELL\", \"hash\":\"2300cc7f48ef84a897da55b54c0614cbc933340a\", \"best_bid\":\"0.54\", \"best_ask\":\"0.55\"}], \"timestamp\":\"1781254837086\", \"event_type\":\"price_change\"}","ts_local_ms":1781254837809}
{"dir":"in","text":"{\"market\":\"0x9c535590faae21bf76fed844aa47fc3c5c82253ef38bd545bf12c93470502685\", \"price_changes\":[{\"asset_id\":\"107011546575057755426871645700605806081353395825571114128343592072429146374928\", \"price\":\"0.01\", \"size\":\"55007.6\", \"side\":\"BUY\", \"hash\":\"99fcbfb0425015433fcb960348a620df6c8e3db3\", \"best_bid\":\"0.54\", \"best_ask\":\"0.55\"}, {\"asset_id\":\"56108879726720646120583724001239294777304794469144970684362785767667828318889\", \"price\":\"0.99\", \"size\":\"55007.6\", \"side\":\"SELL\", \"hash\":\"b98a6547c842d8e9d9062b57b9a25e6cd30020aa\", \"best_bid\":\"0.45\", \"best_ask\":\"0.46\"}], \"timestamp\":\"1781254837086\", \"event_type\":\"price_change\"}","ts_local_ms":1781254837809}
{"dir":"in","text":"{\"market\":\"0x9c535590faae21bf76fed844aa47fc3c5c82253ef38bd545bf12c93470502685\", \"price_changes\":[{\"asset_id\":\"56108879726720646120583724001239294777304794469144970684362785767667828318889\", \"price\":\"0.45\", \"size\":\"347.39\", \"side\":\"BUY\", \"hash\":\"d9d7657666e34288c53d1da01090eec4c06baadc\", \"best_bid\":\"0.45\", \"best_ask\":\"0.46\"}, {\"asset_id\":\"107011546575057755426871645700605806081353395825571114128343592072429146374928\", \"price\":\"0.55\", \"size\":\"347.39\", \"side\":\"SELL\", \"hash\":\"9164dac1026929675e10d23cc43140ed581328f3\", \"best_bid\":\"0.54\", \"best_ask\":\"0.55\"}], \"timestamp\":\"1781254837087\", \"event_type\":\"price_change\"}","ts_local_ms":1781254837809}
{"dir":"in","text":"{\"market\":\"0x9c535590faae21bf76fed844aa47fc3c5c82253ef38bd545bf12c93470502685\", \"price_changes\":[{\"asset_id\":\"56108879726720646120583724001239294777304794469144970684362785767667828318889\", \"price\":\"0.35\", \"size\":\"291\", \"side\":\"BUY\", \"hash\":\"b72a960299cbde86bfb8813bc62c9db4e74d45a4\", \"best_bid\":\"0.45\", \"best_ask\":\"0.46\"}, {\"asset_id\":\"107011546575057755426871645700605806081353395825571114128343592072429146374928\", \"price\":\"0.65\", \"size\":\"291\", \"side\":\"SELL\", \"hash\":\"8b5cead90eab585dd41b4bc39528756a3d4faca3\", \"best_bid\":\"0.54\", \"best_ask\":\"0.55\"}], \"timestamp\":\"1781254837087\", \"event_type\":\"price_change\"}","ts_local_ms":1781254837809}
{"dir":"in","text":"{\"market\":\"0x9c535590faae21bf76fed844aa47fc3c5c82253ef38bd545bf12c93470502685\", \"price_changes\":[{\"asset_id\":\"56108879726720646120583724001239294777304794469144970684362785767667828318889\", \"price\":\"0.45\", \"size\":\"335.39\", \"side\":\"BUY\", \"hash\":\"622d029adb1af035785954f50b82c1c2836e91de\", \"best_bid\":\"0.45\", \"best_ask\":\"0.46\"}, {\"asset_id\":\"107011546575057755426871645700605806081353395825571114128343592072429146374928\", \"price\":\"0.55\", \"size\":\"335.39\", \"side\":\"SELL\", \"hash\":\"278f26c8a3c64cab6d4f0cc726490d63f16a7c6c\", \"best_bid\":\"0.54\", \"best_ask\":\"0.55\"}], \"timestamp\":\"1781254837088\", \"event_type\":\"price_change\"}","ts_local_ms":1781254837809}
{"dir":"in","text":"{\"market\":\"0x9c535590faae21bf76fed844aa47fc3c5c82253ef38bd545bf12c93470502685\", \"price_changes\":[{\"asset_id\":\"56108879726720646120583724001239294777304794469144970684362785767667828318889\", \"price\":\"0.35\", \"size\":\"266\", \"side\":\"BUY\", \"hash\":\"6007eca613e8bdcdc27bd7578a398ebff6569d80\", \"best_bid\":\"0.45\", \"best_ask\":\"0.46\"}, {\"asset_id\":\"107011546575057755426871645700605806081353395825571114128343592072429146374928\", \"price\":\"0.65\", \"size\":\"266\", \"side\":\"SELL\", \"hash\":\"cb08c2253ca056d14de866d4c5297cbe39ead7ec\", \"best_bid\":\"0.54\", \"best_ask\":\"0.55\"}], \"timestamp\":\"1781254837088\", \"event_type\":\"price_change\"}","ts_local_ms":1781254837809}
{"dir":"in","text":"{\"market\":\"0x9c535590faae21bf76fed844aa47fc3c5c82253ef38bd545bf12c93470502685\", \"asset_id\":\"56108879726720646120583724001239294777304794469144970684362785767667828318889\", \"best_bid\":\"0.45\", \"best_ask\":\"0.46\", \"spread\":\"0.01\", \"timestamp\":\"1781254837090\", \"event_type\":\"best_bid_ask\"}","ts_local_ms":1781254837809}
{"dir":"in","text":"{\"market\":\"0x9c535590faae21bf76fed844aa47fc3c5c82253ef38bd545bf12c93470502685\", \"asset_id\":\"107011546575057755426871645700605806081353395825571114128343592072429146374928\", \"best_bid\":\"0.54\", \"best_ask\":\"0.55\", \"spread\":\"0.01\", \"timestamp\":\"1781254837090\", \"event_type\":\"best_bid_ask\"}","ts_local_ms":1781254837809}
{"dir":"in","text":"{\"market\":\"0x9c535590faae21bf76fed844aa47fc3c5c82253ef38bd545bf12c93470502685\", \"price_changes\":[{\"asset_id\":\"107011546575057755426871645700605806081353395825571114128343592072429146374928\", \"price\":\"0.54\", \"size\":\"193.52\", \"side\":\"BUY\", \"hash\":\"a5cff9c9a910a48c72003bb6b091bf342002b3f1\", \"best_bid\":\"0.54\", \"best_ask\":\"0.55\"}, {\"asset_id\":\"56108879726720646120583724001239294777304794469144970684362785767667828318889\", \"price\":\"0.46\", \"size\":\"193.52\", \"side\":\"SELL\", \"hash\":\"0787e0c81aa82254bf173641246350ad6d5c6c03\", \"best_bid\":\"0.45\", \"best_ask\":\"0.46\"}], \"timestamp\":\"1781254837090\", \"event_type\":\"price_change\"}","ts_local_ms":1781254837809}
{"dir":"in","text":"{\"market\":\"0x9c535590faae21bf76fed844aa47fc3c5c82253ef38bd545bf12c93470502685\", \"asset_id\":\"56108879726720646120583724001239294777304794469144970684362785767667828318889\", \"bids\":[{\"price\":\"0.01\", \"size\":\"56199.15\"}, {\"price\":\"0.02\", \"size\":\"22462.28\"}, {\"price\":\"0.03\", \"size\":\"2161.73\"}, {\"price\":\"0.04\", \"size\":\"1695.28\"}, {\"price\":\"0.05\", \"size\":\"1862.1\"}, {\"price\":\"0.06\", \"size\":\"991.6\"}, {\"price\":\"0.07\", \"size\":\"1035.18\"}, {\"price\":\"0.08\", \"size\":\"832.11\"}, {\"price\":\"0.09\", \"size\":\"679.28\"}, {\"price\":\"0.1\", \"size\":\"314.76\"}, {\"price\":\"0.11\", \"size\":\"597\"}, {\"price\":\"0.12\", \"size\":\"335.24\"}, {\"price\":\"0.13\", \"size\":\"84.2\"}, {\"price\":\"0.14\", \"size\":\"91.55\"}, {\"price\":\"0.15\", \"size\":\"52.86\"}, {\"price\":\"0.16\", \"size\":\"66.94\"}, {\"price\":\"0.17\", \"size\":\"54.08\"}, {\"price\":\"0.18\", \"size\":\"360.6\"}, {\"price\":\"0.19\", \"size\":\"39.67\"}, {\"price\":\"0.2\", \"size\":\"729.5\"}, {\"price\":\"0.21\", \"size\":\"177.95\"}, {\"price\":\"0.22\", \"size\":\"513.6\"}, {\"price\":\"0.23\", \"size\":\"39.3\"}, {\"price\":\"0.24\", \"size\":\"58.1\"}, {\"price\":\"0.25\", \"size\":\"57.9\"}, {\"price\":\"0.26\", \"size\":\"92.8\"}, {\"price\":\"0.27\", \"size\":\"118.11\"}, {\"price\":\"0.28\", \"size\":\"67.4\"}, {\"price\":\"0.29\", \"size\":\"87.3\"}, {\"price\":\"0.3\", \"size\":\"87.2\"}, {\"price\":\"0.31\", \"size\":\"96\"}, {\"price\":\"0.32\", \"size\":\"219.42\"}, {\"price\":\"0.33\", \"size\":\"207\"}, {\"price\":\"0.34\", \"size\":\"107\"}, {\"price\":\"0.35\", \"size\":\"266\"}, {\"price\":\"0.36\", \"size\":\"316\"}, {\"price\":\"0.37\", \"size\":\"305.04\"}, {\"price\":\"0.38\", \"size\":\"296\"}, {\"price\":\"0.39\", \"size\":\"365\"}, {\"price\":\"0.4\", \"size\":\"331\"}, {\"price\":\"0.41\", \"size\":\"141.72\"}, {\"price\":\"0.42\", \"size\":\"156.2\"}, {\"price\":\"0.43\", \"size\":\"140\"}, {\"price\":\"0.44\", \"size\":\"56.25\"}, {\"price\":\"0.45\", \"size\":\"335.39\"}], \"asks\":[{\"price\":\"0.99\", \"size\":\"55007.6\"}, {\"price\":\"0.98\", \"size\":\"22471.85\"}, {\"price\":\"0.97\", \"size\":\"2148.4\"}, {\"price\":\"0.96\", \"size\":\"1677.1\"}, {\"price\":\"0.95\", \"size\":\"1864.11\"}, {\"price\":\"0.94\", \"size\":\"1008.6\"}, {\"price\":\"0.93\", \"size\":\"992.18\"}, {\"price\":\"0.92\", \"size\":\"829.12\"}, {\"price\":\"0.91\", \"size\":\"781.72\"}, {\"price\":\"0.9\", \"size\":\"1234.15\"}, {\"price\":\"0.89\", \"size\":\"564.4\"}, {\"price\":\"0.88\", \"size\":\"303.64\"}, {\"price\":\"0.87\", \"size\":\"153.2\"}, {\"price\":\"0.86\", \"size\":\"61.95\"}, {\"price\":\"0.85\", \"size\":\"43.86\"}, {\"price\":\"0.84\", \"size\":\"58.94\"}, {\"price\":\"0.83\", \"size\":\"26.08\"}, {\"price\":\"0.82\", \"size\":\"45.36\"}, {\"price\":\"0.81\", \"size\":\"24.67\"}, {\"price\":\"0.8\", \"size\":\"83.51\"}, {\"price\":\"0.79\", \"size\":\"142.8\"}, {\"price\":\"0.78\", \"size\":\"47.6\"}, {\"price\":\"0.77\", \"size\":\"17.3\"}, {\"price\":\"0.76\", \"size\":\"47.1\"}, {\"price\":\"0.75\", \"size\":\"469.9\"}, {\"price\":\"0.74\", \"size\":\"46.8\"}, {\"price\":\"0.73\", \"size\":\"46.6\"}, {\"price\":\"0.72\", \"size\":\"51.4\"}, {\"price\":\"0.71\", \"size\":\"89.3\"}, {\"price\":\"0.7\", \"size\":\"74.2\"}, {\"price\":\"0.69\", \"size\":\"103.6\"}, {\"price\":\"0.68\", \"size\":\"87\"}, {\"price\":\"0.67\", \"size\":\"61.9\"}, {\"price\":\"0.66\", \"size\":\"91.8\"}, {\"price\":\"0.65\", \"size\":\"113.97\"}, {\"price\":\"0.64\", \"size\":\"371.6\"}, {\"price\":\"0.63\", \"size\":\"91.6\"}, {\"price\":\"0.62\", \"size\":\"71.5\"}, {\"price\":\"0.61\", \"size\":\"704.22\"}, {\"price\":\"0.6\", \"size\":\"111.4\"}, {\"price\":\"0.59\", \"size\":\"536.4\"}, {\"price\":\"0.58\", \"size\":\"219\"}, {\"price\":\"0.57\", \"size\":\"141\"}, {\"price\":\"0.56\", \"size\":\"128.53\"}, {\"price\":\"0.55\", \"size\":\"128.77\"}, {\"price\":\"0.54\", \"size\":\"347.36\"}, {\"price\":\"0.53\", \"size\":\"227.19\"}, {\"price\":\"0.52\", \"size\":\"1052.68\"}, {\"price\":\"0.51\", \"size\":\"434.91\"}, {\"price\":\"0.5\", \"size\":\"448.08\"}, {\"price\":\"0.49\", \"size\":\"227.14\"}, {\"price\":\"0.48\", \"size\":\"161.37\"}, {\"price\":\"0.47\", \"size\":\"122.63\"}, {\"price\":\"0.46\", \"size\":\"193.52\"}], \"hash\":\"0787e0c81aa82254bf173641246350ad6d5c6c03\", \"timestamp\":\"1781254837090\", \"event_type\":\"book\"}","ts_local_ms":1781254837809}
{"dir":"in","text":"{\"market\":\"0x9c535590faae21bf76fed844aa47fc3c5c82253ef38bd545bf12c93470502685\", \"asset_id\":\"107011546575057755426871645700605806081353395825571114128343592072429146374928\", \"bids\":[{\"price\":\"0.01\", \"size\":\"55007.6\"}, {\"price\":\"0.02\", \"size\":\"22471.85\"}, {\"price\":\"0.03\", \"size\":\"2148.4\"}, {\"price\":\"0.04\", \"size\":\"1677.1\"}, {\"price\":\"0.05\", \"size\":\"1864.11\"}, {\"price\":\"0.06\", \"size\":\"1008.6\"}, {\"price\":\"0.07\", \"size\":\"992.18\"}, {\"price\":\"0.08\", \"size\":\"829.12\"}, {\"price\":\"0.09\", \"size\":\"781.72\"}, {\"price\":\"0.1\", \"size\":\"1234.15\"}, {\"price\":\"0.11\", \"size\":\"564.4\"}, {\"price\":\"0.12\", \"size\":\"303.64\"}, {\"price\":\"0.13\", \"size\":\"153.2\"}, {\"price\":\"0.14\", \"size\":\"61.95\"}, {\"price\":\"0.15\", \"size\":\"43.86\"}, {\"price\":\"0.16\", \"size\":\"58.94\"}, {\"price\":\"0.17\", \"size\":\"26.08\"}, {\"price\":\"0.18\", \"size\":\"45.36\"}, {\"price\":\"0.19\", \"size\":\"24.67\"}, {\"price\":\"0.2\", \"size\":\"83.51\"}, {\"price\":\"0.21\", \"size\":\"142.8\"}, {\"price\":\"0.22\", \"size\":\"47.6\"}, {\"price\":\"0.23\", \"size\":\"17.3\"}, {\"price\":\"0.24\", \"size\":\"47.1\"}, {\"price\":\"0.25\", \"size\":\"469.9\"}, {\"price\":\"0.26\", \"size\":\"46.8\"}, {\"price\":\"0.27\", \"size\":\"46.6\"}, {\"price\":\"0.28\", \"size\":\"51.4\"}, {\"price\":\"0.29\", \"size\":\"89.3\"}, {\"price\":\"0.3\", \"size\":\"74.2\"}, {\"price\":\"0.31\", \"size\":\"103.6\"}, {\"price\":\"0.32\", \"size\":\"87\"}, {\"price\":\"0.33\", \"size\":\"61.9\"}, {\"price\":\"0.34\", \"size\":\"91.8\"}, {\"price\":\"0.35\", \"size\":\"113.97\"}, {\"price\":\"0.36\", \"size\":\"371.6\"}, {\"price\":\"0.37\", \"size\":\"91.6\"}, {\"price\":\"0.38\", \"size\":\"71.5\"}, {\"price\":\"0.39\", \"size\":\"704.22\"}, {\"price\":\"0.4\", \"size\":\"111.4\"}, {\"price\":\"0.41\", \"size\":\"536.4\"}, {\"price\":\"0.42\", \"size\":\"219\"}, {\"price\":\"0.43\", \"size\":\"141\"}, {\"price\":\"0.44\", \"size\":\"128.53\"}, {\"price\":\"0.45\", \"size\":\"128.77\"}, {\"price\":\"0.46\", \"size\":\"347.36\"}, {\"price\":\"0.47\", \"size\":\"227.19\"}, {\"price\":\"0.48\", \"size\":\"1052.68\"}, {\"price\":\"0.49\", \"size\":\"434.91\"}, {\"price\":\"0.5\", \"size\":\"448.08\"}, {\"price\":\"0.51\", \"size\":\"227.14\"}, {\"price\":\"0.52\", \"size\":\"161.37\"}, {\"price\":\"0.53\", \"size\":\"122.63\"}, {\"price\":\"0.54\", \"size\":\"193.52\"}], \"asks\":[{\"price\":\"0.99\", \"size\":\"56199.15\"}, {\"price\":\"0.98\", \"size\":\"22462.28\"}, {\"price\":\"0.97\", \"size\":\"2161.73\"}, {\"price\":\"0.96\", \"size\":\"1695.28\"}, {\"price\":\"0.95\", \"size\":\"1862.1\"}, {\"price\":\"0.94\", \"size\":\"991.6\"}, {\"price\":\"0.93\", \"size\":\"1035.18\"}, {\"price\":\"0.92\", \"size\":\"832.11\"}, {\"price\":\"0.91\", \"size\":\"679.28\"}, {\"price\":\"0.9\", \"size\":\"314.76\"}, {\"price\":\"0.89\", \"size\":\"597\"}, {\"price\":\"0.88\", \"size\":\"335.24\"}, {\"price\":\"0.87\", \"size\":\"84.2\"}, {\"price\":\"0.86\", \"size\":\"91.55\"}, {\"price\":\"0.85\", \"size\":\"52.86\"}, {\"price\":\"0.84\", \"size\":\"66.94\"}, {\"price\":\"0.83\", \"size\":\"54.08\"}, {\"price\":\"0.82\", \"size\":\"360.6\"}, {\"price\":\"0.81\", \"size\":\"39.67\"}, {\"price\":\"0.8\", \"size\":\"729.5\"}, {\"price\":\"0.79\", \"size\":\"177.95\"}, {\"price\":\"0.78\", \"size\":\"513.6\"}, {\"price\":\"0.77\", \"size\":\"39.3\"}, {\"price\":\"0.76\", \"size\":\"58.1\"}, {\"price\":\"0.75\", \"size\":\"57.9\"}, {\"price\":\"0.74\", \"size\":\"92.8\"}, {\"price\":\"0.73\", \"size\":\"118.11\"}, {\"price\":\"0.72\", \"size\":\"67.4\"}, {\"price\":\"0.71\", \"size\":\"87.3\"}, {\"price\":\"0.7\", \"size\":\"87.2\"}, {\"price\":\"0.69\", \"size\":\"96\"}, {\"price\":\"0.68\", \"size\":\"219.42\"}, {\"price\":\"0.67\", \"size\":\"207\"}, {\"price\":\"0.66\", \"size\":\"107\"}, {\"price\":\"0.65\", \"size\":\"266\"}, {\"price\":\"0.64\", \"size\":\"316\"}, {\"price\":\"0.63\", \"size\":\"305.04\"}, {\"price\":\"0.62\", \"size\":\"296\"}, {\"price\":\"0.61\", \"size\":\"365\"}, {\"price\":\"0.6\", \"size\":\"331\"}, {\"price\":\"0.59\", \"size\":\"141.72\"}, {\"price\":\"0.58\", \"size\":\"156.2\"}, {\"price\":\"0.57\", \"size\":\"140\"}, {\"price\":\"0.56\", \"size\":\"56.25\"}, {\"price\":\"0.55\", \"size\":\"335.39\"}], \"hash\":\"a5cff9c9a910a48c72003bb6b091bf342002b3f1\", \"timestamp\":\"1781254837090\", \"event_type\":\"book\"}","ts_local_ms":1781254837809}
{"dir":"in","text":"{\"market\":\"0x9c535590faae21bf76fed844aa47fc3c5c82253ef38bd545bf12c93470502685\", \"price_changes\":[{\"asset_id\":\"56108879726720646120583724001239294777304794469144970684362785767667828318889\", \"price\":\"0.32\", \"size\":\"211\", \"side\":\"BUY\", \"hash\":\"6144db0c30b94d706c3ca2fac209ee27773a4264\", \"best_bid\":\"0.45\", \"best_ask\":\"0.46\"}, {\"asset_id\":\"107011546575057755426871645700605806081353395825571114128343592072429146374928\", \"price\":\"0.68\", \"size\":\"211\", \"side\":\"SELL\", \"hash\":\"c684c1ae58a9334c311e6658f04547031ef19c6e\", \"best_bid\":\"0.54\", \"best_ask\":\"0.55\"}], \"timestamp\":\"1781254837094\", \"event_type\":\"price_change\"}","ts_local_ms":1781254837810}
{"dir":"in","text":"{\"market\":\"0x9c535590faae21bf76fed844aa47fc3c5c82253ef38bd545bf12c93470502685\", \"price_changes\":[{\"asset_id\":\"56108879726720646120583724001239294777304794469144970684362785767667828318889\", \"price\":\"0.45\", \"size\":\"348.39\", \"side\":\"BUY\", \"hash\":\"2f06fd5644accbfa909a7b6b5c3e50f7774ca4e8\", \"best_bid\":\"0.45\", \"best_ask\":\"0.46\"}, {\"asset_id\":\"107011546575057755426871645700605806081353395825571114128343592072429146374928\", \"price\":\"0.55\", \"size\":\"348.39\", \"side\":\"SELL\", \"hash\":\"dc3212cbcec0590bd052d0527fe971720a3afccb\", \"best_bid\":\"0.54\", \"best_ask\":\"0.55\"}], \"timestamp\":\"1781254837094\", \"event_type\":\"price_change\"}","ts_local_ms":1781254837810}
{"dir":"in","text":"{\"market\":\"0x9c535590faae21bf76fed844aa47fc3c5c82253ef38bd545bf12c93470502685\", \"price_changes\":[{\"asset_id\":\"56108879726720646120583724001239294777304794469144970684362785767667828318889\", \"price\":\"0.45\", \"size\":\"361.39\", \"side\":\"BUY\", \"hash\":\"bb3d28ba8b8e463df06b97fd8d49b04b5016620d\", \"best_bid\":\"0.45\", \"best_ask\":\"0.46\"}, {\"asset_id\":\"107011546575057755426871645700605806081353395825571114128343592072429146374928\", \"price\":\"0.55\", \"size\":\"361.39\", \"side\":\"SELL\", \"hash\":\"51a43de1e857df5c0ffa6d3b3d3e6ee0a58179de\", \"best_bid\":\"0.54\", \"best_ask\":\"0.55\"}], \"timestamp\":\"1781254837095\", \"event_type\":\"price_change\"}","ts_local_ms":1781254837810}
{"dir":"in","text":"{\"market\":\"0x9c535590faae21bf76fed844aa47fc3c5c82253ef38bd545bf12c93470502685\", \"price_changes\":[{\"asset_id\":\"107011546575057755426871645700605806081353395825571114128343592072429146374928\", \"price\":\"0.65\", \"size\":\"261\", \"side\":\"SELL\", \"hash\":\"b99dd13b9f4bdb91af16aed8907424832e24541c\", \"best_bid\":\"0.54\", \"best_ask\":\"0.55\"}, {\"asset_id\":\"56108879726720646120583724001239294777304794469144970684362785767667828318889\", \"price\":\"0.35\", \"size\":\"261\", \"side\":\"BUY\", \"hash\":\"c0475a207092dd9d78d6f5be6f56106f85f7e085\", \"best_bid\":\"0.45\", \"best_ask\":\"0.46\"}], \"timestamp\":\"1781254837096\", \"event_type\":\"price_change\"}","ts_local_ms":1781254837810}
{"dir":"in","text":"{\"market\":\"0x9c535590faae21bf76fed844aa47fc3c5c82253ef38bd545bf12c93470502685\", \"price_changes\":[{\"asset_id\":\"56108879726720646120583724001239294777304794469144970684362785767667828318889\", \"price\":\"0.45\", \"size\":\"375.39\", \"side\":\"BUY\", \"hash\":\"e0a0a88765c10836c3265e12086b06b024db9b28\", \"best_bid\":\"0.45\", \"best_ask\":\"0.46\"}, {\"asset_id\":\"107011546575057755426871645700605806081353395825571114128343592072429146374928\", \"price\":\"0.55\", \"size\":\"375.39\", \"side\":\"SELL\", \"hash\":\"a880447f9f612d5720cce00b1069eb1ab31a2bb2\", \"best_bid\":\"0.54\", \"best_ask\":\"0.55\"}], \"timestamp\":\"1781254837096\", \"event_type\":\"price_change\"}","ts_local_ms":1781254837810}
{"dir":"in","text":"{\"market\":\"0x9c535590faae21bf76fed844aa47fc3c5c82253ef38bd545bf12c93470502685\", \"price_changes\":[{\"asset_id\":\"56108879726720646120583724001239294777304794469144970684362785767667828318889\", \"price\":\"0.32\", \"size\":\"219.34\", \"side\":\"BUY\", \"hash\":\"4c78534e3869ba00c55fd9616116c002f3120aa9\", \"best_bid\":\"0.45\", \"best_ask\":\"0.46\"}, {\"asset_id\":\"107011546575057755426871645700605806081353395825571114128343592072429146374928\", \"price\":\"0.68\", \"size\":\"219.34\", \"side\":\"SELL\", \"hash\":\"9544f03a310ac8969dee265217fa37b280f23d3e\", \"best_bid\":\"0.54\", \"best_ask\":\"0.55\"}], \"timestamp\":\"1781254837096\", \"event_type\":\"price_change\"}","ts_local_ms":1781254837810}
{"dir":"in","text":"{\"market\":\"0x9c535590faae21bf76fed844aa47fc3c5c82253ef38bd545bf12c93470502685\", \"price_changes\":[{\"asset_id\":\"107011546575057755426871645700605806081353395825571114128343592072429146374928\", \"price\":\"0.65\", \"size\":\"266\", \"side\":\"SELL\", \"hash\":\"45ccf0befe694b0dd6c0d3c3db99bfa58907ea81\", \"best_bid\":\"0.54\", \"best_ask\":\"0.55\"}, {\"asset_id\":\"56108879726720646120583724001239294777304794469144970684362785767667828318889\", \"price\":\"0.35\", \"size\":\"266\", \"side\":\"BUY\", \"hash\":\"63c7d1f726453660574273c07ccd38db10755b60\", \"best_bid\":\"0.45\", \"best_ask\":\"0.46\"}], \"timestamp\":\"1781254837097\", \"event_type\":\"price_change\"}","ts_local_ms":1781254837810}
{"dir":"in","text":"{\"market\":\"0x9c535590faae21bf76fed844aa47fc3c5c82253ef38bd545bf12c93470502685\", \"price_changes\":[{\"asset_id\":\"56108879726720646120583724001239294777304794469144970684362785767667828318889\", \"price\":\"0.45\", \"size\":\"363.39\", \"side\":\"BUY\", \"hash\":\"06b097294d1b598b4f7e291ab84d023fe05c3c41\", \"best_bid\":\"0.45\", \"best_ask\":\"0.46\"}, {\"asset_id\":\"107011546575057755426871645700605806081353395825571114128343592072429146374928\", \"price\":\"0.55\", \"size\":\"363.39\", \"side\":\"SELL\", \"hash\":\"fb63159769c142da558749160a4811f50f61f560\", \"best_bid\":\"0.54\", \"best_ask\":\"0.55\"}], \"timestamp\":\"1781254837098\", \"event_type\":\"price_change\"}","ts_local_ms":1781254837810}
{"dir":"in","text":"{\"market\":\"0x9c535590faae21bf76fed844aa47fc3c5c82253ef38bd545bf12c93470502685\", \"asset_id\":\"56108879726720646120583724001239294777304794469144970684362785767667828318889\", \"price\":\"0.46\", \"size\":\"99\", \"fee_rate_bps\":\"0\", \"side\":\"BUY\", \"timestamp\":\"1781254837092\", \"event_type\":\"last_trade_price\", \"transaction_hash\":\"0xa5ba02f77f29fa5e163a4f0b0b10060d60a6107d1d88d7778ad052a5baf4e9fa\"}","ts_local_ms":1781254837810}
{"dir":"in","text":"{\"market\":\"0x9c535590faae21bf76fed844aa47fc3c5c82253ef38bd545bf12c93470502685\", \"price_changes\":[{\"asset_id\":\"107011546575057755426871645700605806081353395825571114128343592072429146374928\", \"price\":\"0.52\", \"size\":\"186.37\", \"side\":\"BUY\", \"hash\":\"d8230cb31697775d71bafb35326783070ecbd329\", \"best_bid\":\"0.54\", \"best_ask\":\"0.55\"}, {\"asset_id\":\"56108879726720646120583724001239294777304794469144970684362785767667828318889\", \"price\":\"0.48\", \"size\":\"186.37\", \"side\":\"SELL\", \"hash\":\"6a09873d34619287021837b8b9fea940925f9cb5\", \"best_bid\":\"0.45\", \"best_ask\":\"0.46\"}], \"timestamp\":\"1781254837100\", \"event_type\":\"price_change\"}","ts_local_ms":1781254837810}
{"dir":"in","text":"{\"market\":\"0x9c535590faae21bf76fed844aa47fc3c5c82253ef38bd545bf12c93470502685\", \"price_changes\":[{\"asset_id\":\"56108879726720646120583724001239294777304794469144970684362785767667828318889\", \"price\":\"0.39\", \"size\":\"380\", \"side\":\"BUY\", \"hash\":\"8396e652b3c0486126dc4cc99119c06f209a1956\", \"best_bid\":\"0.45\", \"best_ask\":\"0.46\"}, {\"asset_id\":\"107011546575057755426871645700605806081353395825571114128343592072429146374928\", \"price\":\"0.61\", \"size\":\"380\", \"side\":\"SELL\", \"hash\":\"b8390887ceae07923cde016b1c458fb8671ce5e6\", \"best_bid\":\"0.54\", \"best_ask\":\"0.55\"}], \"timestamp\":\"1781254837103\", \"event_type\":\"price_change\"}","ts_local_ms":1781254837810}
{"dir":"in","text":"{\"market\":\"0x9c535590faae21bf76fed844aa47fc3c5c82253ef38bd545bf12c93470502685\", \"price_changes\":[{\"asset_id\":\"107011546575057755426871645700605806081353395825571114128343592072429146374928\", \"price\":\"0.53\", \"size\":\"97\", \"side\":\"BUY\", \"hash\":\"542d20c0ceffe1f3eba196780196ec7470063c48\", \"best_bid\":\"0.54\", \"best_ask\":\"0.55\"}, {\"asset_id\":\"56108879726720646120583724001239294777304794469144970684362785767667828318889\", \"price\":\"0.47\", \"size\":\"97\", \"side\":\"SELL\", \"hash\":\"f589cdad55387ba93418005c19674e98300de973\", \"best_bid\":\"0.45\", \"best_ask\":\"0.46\"}], \"timestamp\":\"1781254837105\", \"event_type\":\"price_change\"}","ts_local_ms":1781254837810}
{"dir":"in","text":"{\"market\":\"0x9c535590faae21bf76fed844aa47fc3c5c82253ef38bd545bf12c93470502685\", \"price_changes\":[{\"asset_id\":\"56108879726720646120583724001239294777304794469144970684362785767667828318889\", \"price\":\"0.45\", \"size\":\"350.39\", \"side\":\"BUY\", \"hash\":\"e67b662ba89838e73f4978fcb24789d59c987bcc\", \"best_bid\":\"0.45\", \"best_ask\":\"0.46\"}, {\"asset_id\":\"107011546575057755426871645700605806081353395825571114128343592072429146374928\", \"price\":\"0.55\", \"size\":\"350.39\", \"side\":\"SELL\", \"hash\":\"9940f0f562931508cf97bea6b34156c42a03ffdd\", \"best_bid\":\"0.54\", \"best_ask\":\"0.55\"}], \"timestamp\":\"1781254837106\", \"event_type\":\"price_change\"}","ts_local_ms":1781254837810}
{"dir":"in","text":"{\"market\":\"0x9c535590faae21bf76fed844aa47fc3c5c82253ef38bd545bf12c93470502685\", \"price_changes\":[{\"asset_id\":\"56108879726720646120583724001239294777304794469144970684362785767667828318889\", \"price\":\"0.37\", \"size\":\"320.04\", \"side\":\"BUY\", \"hash\":\"cc74ed916de32291bbb67ff216f569d02280773d\", \"best_bid\":\"0.45\", \"best_ask\":\"0.46\"}, {\"asset_id\":\"107011546575057755426871645700605806081353395825571114128343592072429146374928\", \"price\":\"0.63\", \"size\":\"320.04\", \"side\":\"SELL\", \"hash\":\"d9483bd1a778e783e1a0bedd5825747bb6d07e49\", \"best_bid\":\"0.54\", \"best_ask\":\"0.55\"}], \"timestamp\":\"1781254837106\", \"event_type\":\"price_change\"}","ts_local_ms":1781254837810}
{"dir":"in","text":"{\"market\":\"0x9c535590faae21bf76fed844aa47fc3c5c82253ef38bd545bf12c93470502685\", \"price_changes\":[{\"asset_id\":\"56108879726720646120583724001239294777304794469144970684362785767667828318889\", \"price\":\"0.38\", \"size\":\"303.74\", \"side\":\"BUY\", \"hash\":\"7992d42db5643a1bdb2af8aade00e96654e4787b\", \"best_bid\":\"0.45\", \"best_ask\":\"0.46\"}, {\"asset_id\":\"107011546575057755426871645700605806081353395825571114128343592072429146374928\", \"price\":\"0.62\", \"size\":\"303.74\", \"side\":\"SELL\", \"hash\":\"7c723b0d0f837f7841d9726ae12f5ca36d0eea30\", \"best_bid\":\"0.54\", \"best_ask\":\"0.55\"}], \"timestamp\":\"1781254837108\", \"event_type\":\"price_change\"}","ts_local_ms":1781254837810}
{"dir":"in","text":"{\"market\":\"0x9c535590faae21bf76fed844aa47fc3c5c82253ef38bd545bf12c93470502685\", \"price_changes\":[{\"asset_id\":\"56108879726720646120583724001239294777304794469144970684362785767667828318889\", \"price\":\"0.37\", \"size\":\"326.94\", \"side\":\"BUY\", \"hash\":\"35ee2d0acdf7a405d3fd600a76f330c8129d97d4\", \"best_bid\":\"0.45\", \"best_ask\":\"0.46\"}, {\"asset_id\":\"107011546575057755426871645700605806081353395825571114128343592072429146374928\", \"price\":\"0.63\", \"size\":\"326.94\", \"side\":\"SELL\", \"hash\":\"4fb73692b810cccdf3d79da763563e9c3b0c0b20\", \"best_bid\":\"0.54\", \"best_ask\":\"0.55\"}], \"timestamp\":\"1781254837108\", \"event_type\":\"price_change\"}","ts_local_ms":1781254837810}
{"dir":"in","text":"{\"market\":\"0x9c535590faae21bf76fed844aa47fc3c5c82253ef38bd545bf12c93470502685\", \"price_changes\":[{\"asset_id\":\"56108879726720646120583724001239294777304794469144970684362785767667828318889\", \"price\":\"0.42\", \"size\":\"188.07\", \"side\":\"BUY\", \"hash\":\"575d67672532b9b438aa4aef18baf78cbf6da1c1\", \"best_bid\":\"0.45\", \"best_ask\":\"0.46\"}, {\"asset_id\":\"107011546575057755426871645700605806081353395825571114128343592072429146374928\", \"price\":\"0.58\", \"size\":\"188.07\", \"side\":\"SELL\", \"hash\":\"1a8664212540f01a4d07a4d92d220f62f0c1c5ca\", \"best_bid\":\"0.54\", \"best_ask\":\"0.55\"}], \"timestamp\":\"1781254837109\", \"event_type\":\"price_change\"}","ts_local_ms":1781254837810}
{"dir":"in","text":"{\"market\":\"0x9c535590faae21bf76fed844aa47fc3c5c82253ef38bd545bf12c93470502685\", \"price_changes\":[{\"asset_id\":\"107011546575057755426871645700605806081353395825571114128343592072429146374928\", \"price\":\"0.43\", \"size\":\"116\", \"side\":\"BUY\", \"hash\":\"9d9facc764261144927c365b1485e7d3010973dc\", \"best_bid\":\"0.54\", \"best_ask\":\"0.55\"}, {\"asset_id\":\"56108879726720646120583724001239294777304794469144970684362785767667828318889\", \"price\":\"0.57\", \"size\":\"116\", \"side\":\"SELL\", \"hash\":\"d0601b607277de117db1d3be42cdcb5fcd4f2767\", \"best_bid\":\"0.45\", \"best_ask\":\"0.46\"}], \"timestamp\":\"1781254837110\", \"event_type\":\"price_change\"}","ts_local_ms":1781254837810}
{"dir":"in","text":"{\"market\":\"0x9c535590faae21bf76fed844aa47fc3c5c82253ef38bd545bf12c93470502685\", \"price_changes\":[{\"asset_id\":\"56108879726720646120583724001239294777304794469144970684362785767667828318889\", \"price\":\"0.44\", \"size\":\"31.25\", \"side\":\"BUY\", \"hash\":\"ff3089c8a444eeef8e1acdf4a3983c65a555cb3f\", \"best_bid\":\"0.45\", \"best_ask\":\"0.46\"}, {\"asset_id\":\"107011546575057755426871645700605806081353395825571114128343592072429146374928\", \"price\":\"0.56\", \"size\":\"31.25\", \"side\":\"SELL\", \"hash\":\"e009bf98ab867af85be57bd617311f8783e409a8\", \"best_bid\":\"0.54\", \"best_ask\":\"0.55\"}], \"timestamp\":\"1781254837110\", \"event_type\":\"price_change\"}","ts_local_ms":1781254837811}
{"dir":"in","text":"{\"market\":\"0x9c535590faae21bf76fed844aa47fc3c5c82253ef38bd545bf12c93470502685\", \"price_changes\":[{\"asset_id\":\"107011546575057755426871645700605806081353395825571114128343592072429146374928\", \"price\":\"0.44\", \"size\":\"122\", \"side\":\"BUY\", \"hash\":\"4f92eef14f7d28f1b988e067921cd51e5eb6fb53\", \"best_bid\":\"0.54\", \"best_ask\":\"0.55\"}, {\"asset_id\":\"56108879726720646120583724001239294777304794469144970684362785767667828318889\", \"price\":\"0.56\", \"size\":\"122\", \"side\":\"SELL\", \"hash\":\"ef9943f789d06de8e174b5271aeb7031d70a8f47\", \"best_bid\":\"0.45\", \"best_ask\":\"0.46\"}], \"timestamp\":\"1781254837110\", \"event_type\":\"price_change\"}","ts_local_ms":1781254837811}
{"dir":"in","text":"{\"market\":\"0x9c535590faae21bf76fed844aa47fc3c5c82253ef38bd545bf12c93470502685\", \"price_changes\":[{\"asset_id\":\"56108879726720646120583724001239294777304794469144970684362785767667828318889\", \"price\":\"0.39\", \"size\":\"388.15\", \"side\":\"BUY\", \"hash\":\"c9c7caec6049efa9d5c5341c35f4c442f0ccef83\", \"best_bid\":\"0.45\", \"best_ask\":\"0.46\"}, {\"asset_id\":\"107011546575057755426871645700605806081353395825571114128343592072429146374928\", \"price\":\"0.61\", \"size\":\"388.15\", \"side\":\"SELL\", \"hash\":\"4fdc7ea09d9159d5cec880eb00f568c84410aa2f\", \"best_bid\":\"0.54\", \"best_ask\":\"0.55\"}], \"timestamp\":\"1781254837110\", \"event_type\":\"price_change\"}","ts_local_ms":1781254837811}
{"dir":"in","text":"{\"market\":\"0x9c535590faae21bf76fed844aa47fc3c5c82253ef38bd545bf12c93470502685\", \"price_changes\":[{\"asset_id\":\"56108879726720646120583724001239294777304794469144970684362785767667828318889\", \"price\":\"0.36\", \"size\":\"322.58\", \"side\":\"BUY\", \"hash\":\"05e19501316d53e90e6ed7f6c5e323447abca198\", \"best_bid\":\"0.45\", \"best_ask\":\"0.46\"}, {\"asset_id\":\"107011546575057755426871645700605806081353395825571114128343592072429146374928\", \"price\":\"0.64\", \"size\":\"322.58\", \"side\":\"SELL\", \"hash\":\"4102d1009b39865370536e288459dcd3867ac98b\", \"best_bid\":\"0.54\", \"best_ask\":\"0.55\"}], \"timestamp\":\"1781254837111\", \"event_type\":\"price_change\"}","ts_local_ms":1781254837811}
{"dir":"in","text":"{\"market\":\"0x9c535590faae21bf76fed844aa47fc3c5c82253ef38bd545bf12c93470502685\", \"price_changes\":[{\"asset_id\":\"56108879726720646120583724001239294777304794469144970684362785767667828318889\", \"price\":\"0.43\", \"size\":\"184.58\", \"side\":\"BUY\", \"hash\":\"cde503f3bd2494266736fcf71dab36f2dba94db2\", \"best_bid\":\"0.45\", \"best_ask\":\"0.46\"}, {\"asset_id\":\"107011546575057755426871645700605806081353395825571114128343592072429146374928\", \"price\":\"0.57\", \"size\":\"184.58\", \"side\":\"SELL\", \"hash\":\"7081dbf8aa990e8030a3b9132e90ea9febbf4a43\", \"best_bid\":\"0.54\", \"best_ask\":\"0.55\"}], \"timestamp\":\"1781254837112\", \"event_type\":\"price_change\"}","ts_local_ms":1781254837811}
{"dir":"in","text":"{\"market\":\"0x9c535590faae21bf76fed844aa47fc3c5c82253ef38bd545bf12c93470502685\", \"price_changes\":[{\"asset_id\":\"56108879726720646120583724001239294777304794469144970684362785767667828318889\", \"price\":\"0.41\", \"size\":\"163.17\", \"side\":\"BUY\", \"hash\":\"24a2808c6cc6584d474ddcc820c62c7ba2ce70d0\", \"best_bid\":\"0.45\", \"best_ask\":\"0.46\"}, {\"asset_id\":\"107011546575057755426871645700605806081353395825571114128343592072429146374928\", \"price\":\"0.59\", \"size\":\"163.17\", \"side\":\"SELL\", \"hash\":\"37009bf82fb127a21398e675d3abf161a05bae81\", \"best_bid\":\"0.54\", \"best_ask\":\"0.55\"}], \"timestamp\":\"1781254837113\", \"event_type\":\"price_change\"}","ts_local_ms":1781254837811}
{"dir":"in","text":"{\"market\":\"0x9c535590faae21bf76fed844aa47fc3c5c82253ef38bd545bf12c93470502685\", \"price_changes\":[{\"asset_id\":\"107011546575057755426871645700605806081353395825571114128343592072429146374928\", \"price\":\"0.44\", \"size\":\"97\", \"side\":\"BUY\", \"hash\":\"f3ea75ca5c24c88547ac156e05b057baf05c66d8\", \"best_bid\":\"0.54\", \"best_ask\":\"0.55\"}, {\"asset_id\":\"56108879726720646120583724001239294777304794469144970684362785767667828318889\", \"price\":\"0.56\", \"size\":\"97\", \"side\":\"SELL\", \"hash\":\"6e2cdd9acde3bcf79f4feaff003b2130e9b10028\", \"best_bid\":\"0.45\", \"best_ask\":\"0.46\"}], \"timestamp\":\"1781254837113\", \"event_type\":\"price_change\"}","ts_local_ms":1781254837811}
{"dir":"in","text":"{\"market\":\"0x9c535590faae21bf76fed844aa47fc3c5c82253ef38bd545bf12c93470502685\", \"price_changes\":[{\"asset_id\":\"107011546575057755426871645700605806081353395825571114128343592072429146374928\", \"price\":\"0.01\", \"size\":\"55001.6\", \"side\":\"BUY\", \"hash\":\"e99a39c069c631e39be52273b33cf838efaae1b9\", \"best_bid\":\"0.54\", \"best_ask\":\"0.55\"}, {\"asset_id\":\"56108879726720646120583724001239294777304794469144970684362785767667828318889\", \"price\":\"0.99\", \"size\":\"55001.6\", \"side\":\"SELL\", \"hash\":\"d4175aed1e68514b6b5a1d8663799295efc81629\", \"best_bid\":\"0.45\", \"best_ask\":\"0.46\"}], \"timestamp\":\"1781254837113\", \"event_type\":\"price_change\"}","ts_local_ms":1781254837811}
{"dir":"in","text":"{\"market\":\"0x9c535590faae21bf76fed844aa47fc3c5c82253ef38bd545bf12c93470502685\", \"price_changes\":[{\"asset_id\":\"107011546575057755426871645700605806081353395825571114128343592072429146374928\", \"price\":\"0.53\", \"size\":\"172\", \"side\":\"BUY\", \"hash\":\"66c89b0b2be10e90c56c80a847407f83f8d4078f\", \"best_bid\":\"0.54\", \"best_ask\":\"0.55\"}, {\"asset_id\":\"56108879726720646120583724001239294777304794469144970684362785767667828318889\", \"price\":\"0.47\", \"size\":\"172\", \"side\":\"SELL\", \"hash\":\"6b6c50f78ed75d79d593a3b18073186f06c97508\", \"best_bid\":\"0.45\", \"best_ask\":\"0.46\"}], \"timestamp\":\"1781254837114\", \"event_type\":\"price_change\"}","ts_local_ms":1781254837811}
{"dir":"in","text":"{\"market\":\"0x9c535590faae21bf76fed844aa47fc3c5c82253ef38bd545bf12c93470502685\", \"price_changes\":[{\"asset_id\":\"56108879726720646120583724001239294777304794469144970684362785767667828318889\", \"price\":\"0.45\", \"size\":\"329.39\", \"side\":\"BUY\", \"hash\":\"d37d4090991616e48022006544b794f2c4ff78cb\", \"best_bid\":\"0.45\", \"best_ask\":\"0.46\"}, {\"asset_id\":\"107011546575057755426871645700605806081353395825571114128343592072429146374928\", \"price\":\"0.55\", \"size\":\"329.39\", \"side\":\"SELL\", \"hash\":\"d41793b1837d12c41d8d43ca3a92f8c6d44d34cb\", \"best_bid\":\"0.54\", \"best_ask\":\"0.55\"}], \"timestamp\":\"1781254837114\", \"event_type\":\"price_change\"}","ts_local_ms":1781254837811}
{"dir":"in","text":"{\"market\":\"0x9c535590faae21bf76fed844aa47fc3c5c82253ef38bd545bf12c93470502685\", \"price_changes\":[{\"asset_id\":\"107011546575057755426871645700605806081353395825571114128343592072429146374928\", \"price\":\"0.54\", \"size\":\"183.52\", \"side\":\"BUY\", \"hash\":\"f1b299c595aee2ecf818f85fb8759b7885b6fd23\", \"best_bid\":\"0.54\", \"best_ask\":\"0.55\"}, {\"asset_id\":\"56108879726720646120583724001239294777304794469144970684362785767667828318889\", \"price\":\"0.46\", \"size\":\"183.52\", \"side\":\"SELL\", \"hash\":\"42a046c62834a9899aa7e1fa5b9b4b5bef212c88\", \"best_bid\":\"0.45\", \"best_ask\":\"0.46\"}], \"timestamp\":\"1781254837114\", \"event_type\":\"price_change\"}","ts_local_ms":1781254837811}
{"dir":"in","text":"{\"market\":\"0x9c535590faae21bf76fed844aa47fc3c5c82253ef38bd545bf12c93470502685\", \"asset_id\":\"56108879726720646120583724001239294777304794469144970684362785767667828318889\", \"price\":\"0.46\", \"size\":\"100\", \"fee_rate_bps\":\"0\", \"side\":\"BUY\", \"timestamp\":\"1781254837111\", \"event_type\":\"last_trade_price\", \"transaction_hash\":\"0xa981dafd0ae3c096da18cbe6b0936e2b02e3e987f80c29eb3e7ee79956da9031\"}","ts_local_ms":1781254837811}
{"dir":"in","text":"{\"market\":\"0x9c535590faae21bf76fed844aa47fc3c5c82253ef38bd545bf12c93470502685\", \"price_changes\":[{\"asset_id\":\"56108879726720646120583724001239294777304794469144970684362785767667828318889\", \"price\":\"0.4\", \"size\":\"338.54\", \"side\":\"BUY\", \"hash\":\"23285682b780a83dc55bb5deb641a253192616a4\", \"best_bid\":\"0.45\", \"best_ask\":\"0.46\"}, {\"asset_id\":\"107011546575057755426871645700605806081353395825571114128343592072429146374928\", \"price\":\"0.6\", \"size\":\"338.54\", \"side\":\"SELL\", \"hash\":\"205edadf5f813b340465217007f4c3156d4589df\", \"best_bid\":\"0.54\", \"best_ask\":\"0.55\"}], \"timestamp\":\"1781254837115\", \"event_type\":\"price_change\"}","ts_local_ms":1781254837811}
{"dir":"in","text":"{\"market\":\"0x9c535590faae21bf76fed844aa47fc3c5c82253ef38bd545bf12c93470502685\", \"asset_id\":\"56108879726720646120583724001239294777304794469144970684362785767667828318889\", \"price\":\"0.46\", \"size\":\"11\", \"fee_rate_bps\":\"0\", \"side\":\"BUY\", \"timestamp\":\"1781254837111\", \"event_type\":\"last_trade_price\", \"transaction_hash\":\"0x15cda193ea44918f66ebf66daa54bdf508cca6ee92bccf868ee42574f9051845\"}","ts_local_ms":1781254837811}
{"dir":"in","text":"{\"market\":\"0x9c535590faae21bf76fed844aa47fc3c5c82253ef38bd545bf12c93470502685\", \"price_changes\":[{\"asset_id\":\"56108879726720646120583724001239294777304794469144970684362785767667828318889\", \"price\":\"0.45\", \"size\":\"315.39\", \"side\":\"BUY\", \"hash\":\"7ae3368269f4271f7f252ea418699d331bce4df4\", \"best_bid\":\"0.45\", \"best_ask\":\"0.46\"}, {\"asset_id\":\"107011546575057755426871645700605806081353395825571114128343592072429146374928\", \"price\":\"0.55\", \"size\":\"315.39\", \"side\":\"SELL\", \"hash\":\"7e8d31e4453701a1ec3ab05ffc9df3c609ebd5ef\", \"best_bid\":\"0.54\", \"best_ask\":\"0.55\"}], \"timestamp\":\"1781254837116\", \"event_type\":\"price_change\"}","ts_local_ms":1781254837811}
{"dir":"in","text":"{\"market\":\"0x9c535590faae21bf76fed844aa47fc3c5c82253ef38bd545bf12c93470502685\", \"price_changes\":[{\"asset_id\":\"56108879726720646120583724001239294777304794469144970684362785767667828318889\", \"price\":\"0.45\", \"size\":\"329.39\", \"side\":\"BUY\", \"hash\":\"502801f0862c7b4cfe3423a7b3de634f3bc1906d\", \"best_bid\":\"0.45\", \"best_ask\":\"0.46\"}, {\"asset_id\":\"107011546575057755426871645700605806081353395825571114128343592072429146374928\", \"price\":\"0.55\", \"size\":\"329.39\", \"side\":\"SELL\", \"hash\":\"7da1e6570e478ffb6237aae8787ae43d9c856239\", \"best_bid\":\"0.54\", \"best_ask\":\"0.55\"}], \"timestamp\":\"1781254837116\", \"event_type\":\"price_change\"}","ts_local_ms":1781254837811}
{"dir":"in","text":"{\"market\":\"0x9c535590faae21bf76fed844aa47fc3c5c82253ef38bd545bf12c93470502685\", \"price_changes\":[{\"asset_id\":\"107011546575057755426871645700605806081353395825571114128343592072429146374928\", \"price\":\"0.54\", \"size\":\"208.52\", \"side\":\"BUY\", \"hash\":\"12e6ac5f3c6990022feaa0b9dd179e157b4767fd\", \"best_bid\":\"0.54\", \"best_ask\":\"0.55\"}, {\"asset_id\":\"56108879726720646120583724001239294777304794469144970684362785767667828318889\", \"price\":\"0.46\", \"size\":\"208.52\", \"side\":\"SELL\", \"hash\":\"fcb715d17b785d95395e4bdcdc06f19c1bc8b902\", \"best_bid\":\"0.45\", \"best_ask\":\"0.46\"}], \"timestamp\":\"1781254837118\", \"event_type\":\"price_change\"}","ts_local_ms":1781254837811}
{"dir":"in","text":"{\"market\":\"0x9c535590faae21bf76fed844aa47fc3c5c82253ef38bd545bf12c93470502685\", \"price_changes\":[{\"asset_id\":\"107011546575057755426871645700605806081353395825571114128343592072429146374928\", \"price\":\"0.54\", \"size\":\"218.52\", \"side\":\"BUY\", \"hash\":\"9e134a6ade95e0f30c9b2d795fb64600d9b63b19\", \"best_bid\":\"0.54\", \"best_ask\":\"0.55\"}, {\"asset_id\":\"56108879726720646120583724001239294777304794469144970684362785767667828318889\", \"price\":\"0.46\", \"size\":\"218.52\", \"side\":\"SELL\", \"hash\":\"7962909cde028f3fbb74163a8de7aa5f3bc16f03\", \"best_bid\":\"0.45\", \"best_ask\":\"0.46\"}], \"timestamp\":\"1781254837120\", \"event_type\":\"price_change\"}","ts_local_ms":1781254837811}
{"dir":"in","text":"{\"market\":\"0x9c535590faae21bf76fed844aa47fc3c5c82253ef38bd545bf12c93470502685\", \"price_changes\":[{\"asset_id\":\"56108879726720646120583724001239294777304794469144970684362785767667828318889\", \"price\":\"0.4\", \"size\":\"348.54\", \"side\":\"BUY\", \"hash\":\"9498e4beb4f0d373cb3faec8e6f64af21620ef44\", \"best_bid\":\"0.45\", \"best_ask\":\"0.46\"}, {\"asset_id\":\"107011546575057755426871645700605806081353395825571114128343592072429146374928\", \"price\":\"0.6\", \"size\":\"348.54\", \"side\":\"SELL\", \"hash\":\"c88eb83bc39ba1b1824fc7126266c4ad82eaa812\", \"best_bid\":\"0.54\", \"best_ask\":\"0.55\"}], \"timestamp\":\"1781254837120\", \"event_type\":\"price_change\"}","ts_local_ms":1781254837811}
{"dir":"in","text":"{\"market\":\"0x9c535590faae21bf76fed844aa47fc3c5c82253ef38bd545bf12c93470502685\", \"price_changes\":[{\"asset_id\":\"56108879726720646120583724001239294777304794469144970684362785767667828318889\", \"price\":\"0.45\", \"size\":\"343.39\", \"side\":\"BUY\", \"hash\":\"46288184c262d34875b6860b0dd49328273c6d04\", \"best_bid\":\"0.45\", \"best_ask\":\"0.46\"}, {\"asset_id\":\"107011546575057755426871645700605806081353395825571114128343592072429146374928\", \"price\":\"0.55\", \"size\":\"343.39\", \"side\":\"SELL\", \"hash\":\"8495c094ecd4d7d9e6496b09b4d0e9022439b7c6\", \"best_bid\":\"0.54\", \"best_ask\":\"0.55\"}], \"timestamp\":\"1781254837123\", \"event_type\":\"price_change\"}","ts_local_ms":1781254837811}
{"dir":"in","text":"{\"market\":\"0x9c535590faae21bf76fed844aa47fc3c5c82253ef38bd545bf12c93470502685\", \"price_changes\":[{\"asset_id\":\"56108879726720646120583724001239294777304794469144970684362785767667828318889\", \"price\":\"0.35\", \"size\":\"291\", \"side\":\"BUY\", \"hash\":\"daeb70f42fed309505e3b1f9c420e6d1cb26b4e3\", \"best_bid\":\"0.45\", \"best_ask\":\"0.46\"}, {\"asset_id\":\"107011546575057755426871645700605806081353395825571114128343592072429146374928\", \"price\":\"0.65\", \"size\":\"291\", \"side\":\"SELL\", \"hash\":\"dcdffd6b1a3b5f0a8e3d995042b5c419a49f9402\", \"best_bid\":\"0.54\", \"best_ask\":\"0.55\"}], \"timestamp\":\"1781254837124\", \"event_type\":\"price_change\"}","ts_local_ms":1781254837811}
{"dir":"in","text":"{\"market\":\"0x9c535590faae21bf76fed844aa47fc3c5c82253ef38bd545bf12c93470502685\", \"price_changes\":[{\"asset_id\":\"56108879726720646120583724001239294777304794469144970684362785767667828318889\", \"price\":\"0.41\", \"size\":\"156.45\", \"side\":\"BUY\", \"hash\":\"1b26307cfe3d6d2b63343536705eec2514fd47a2\", \"best_bid\":\"0.45\", \"best_ask\":\"0.46\"}, {\"asset_id\":\"107011546575057755426871645700605806081353395825571114128343592072429146374928\", \"price\":\"0.59\", \"size\":\"156.45\", \"side\":\"SELL\", \"hash\":\"e4f3429d6f72f5e1dad677f3978f133776de0579\", \"best_bid\":\"0.54\", \"best_ask\":\"0.55\"}], \"timestamp\":\"1781254837124\", \"event_type\":\"price_change\"}","ts_local_ms":1781254837811}
{"dir":"in","text":"{\"market\":\"0x9c535590faae21bf76fed844aa47fc3c5c82253ef38bd545bf12c93470502685\", \"price_changes\":[{\"asset_id\":\"56108879726720646120583724001239294777304794469144970684362785767667828318889\", \"price\":\"0.45\", \"size\":\"357.39\", \"side\":\"BUY\", \"hash\":\"ada193e31d4d77dffe17936972155c8619249913\", \"best_bid\":\"0.45\", \"best_ask\":\"0.46\"}, {\"asset_id\":\"107011546575057755426871645700605806081353395825571114128343592072429146374928\", \"price\":\"0.55\", \"size\":\"357.39\", \"side\":\"SELL\", \"hash\":\"aa91062f403b85fe28a81048353df9c0117a6797\", \"best_bid\":\"0.54\", \"best_ask\":\"0.55\"}], \"timestamp\":\"1781254837127\", \"event_type\":\"price_change\"}","ts_local_ms":1781254837811}
{"dir":"in","text":"{\"market\":\"0x9c535590faae21bf76fed844aa47fc3c5c82253ef38bd545bf12c93470502685\", \"price_changes\":[{\"asset_id\":\"56108879726720646120583724001239294777304794469144970684362785767667828318889\", \"price\":\"0.36\", \"size\":\"372.58\", \"side\":\"BUY\", \"hash\":\"b9056d73971f2246f1cbeb7cdab08bfb9d4ddafc\", \"best_bid\":\"0.45\", \"best_ask\":\"0.46\"}, {\"asset_id\":\"107011546575057755426871645700605806081353395825571114128343592072429146374928\", \"price\":\"0.64\", \"size\":\"372.58\", \"side\":\"SELL\", \"hash\":\"6fba3b972d5435d5d386768191af4700eb502533\", \"best_bid\":\"0.54\", \"best_ask\":\"0.55\"}], \"timestamp\":\"1781254837128\", \"event_type\":\"price_change\"}","ts_local_ms":1781254837811}
{"dir":"in","text":"{\"market\":\"0x9c535590faae21bf76fed844aa47fc3c5c82253ef38bd545bf12c93470502685\", \"price_changes\":[{\"asset_id\":\"56108879726720646120583724001239294777304794469144970684362785767667828318889\", \"price\":\"0.45\", \"size\":\"373.39\", \"side\":\"BUY\", \"hash\":\"a881363d083de57bd35abf00a57c9cbc1252e6cd\", \"best_bid\":\"0.45\", \"best_ask\":\"0.46\"}, {\"asset_id\":\"107011546575057755426871645700605806081353395825571114128343592072429146374928\", \"price\":\"0.55\", \"size\":\"373.39\", \"side\":\"SELL\", \"hash\":\"433f991b7243831db0299c5e189f081aeb5e4abf\", \"best_bid\":\"0.54\", \"best_ask\":\"0.55\"}], \"timestamp\":\"1781254837128\", \"event_type\":\"price_change\"}","ts_local_ms":1781254837811}
{"dir":"in","text":"{\"market\":\"0x9c535590faae21bf76fed844aa47fc3c5c82253ef38bd545bf12c93470502685\", \"price_changes\":[{\"asset_id\":\"56108879726720646120583724001239294777304794469144970684362785767667828318889\", \"price\":\"0.43\", \"size\":\"190.96\", \"side\":\"BUY\", \"hash\":\"9ed93d665b0db1f8688526134f7d2440202a252c\", \"best_bid\":\"0.45\", \"best_ask\":\"0.46\"}, {\"asset_id\":\"107011546575057755426871645700605806081353395825571114128343592072429146374928\", \"price\":\"0.57\", \"size\":\"190.96\", \"side\":\"SELL\", \"hash\":\"4099e37cb02c19cef0c61a1a95129b187191c10e\", \"best_bid\":\"0.54\", \"best_ask\":\"0.55\"}], \"timestamp\":\"1781254837129\", \"event_type\":\"price_change\"}","ts_local_ms":1781254837812}
{"dir":"in","text":"{\"market\":\"0x9c535590faae21bf76fed844aa47fc3c5c82253ef38bd545bf12c93470502685\", \"price_changes\":[{\"asset_id\":\"107011546575057755426871645700605806081353395825571114128343592072429146374928\", \"price\":\"0.54\", \"size\":\"193.52\", \"side\":\"BUY\", \"hash\":\"05d2b351d12d71f74d7ec14463e407154369364a\", \"best_bid\":\"0.54\", \"best_ask\":\"0.55\"}, {\"asset_id\":\"56108879726720646120583724001239294777304794469144970684362785767667828318889\", \"price\":\"0.46\", \"size\":\"193.52\", \"side\":\"SELL\", \"hash\":\"0d36f86c248dc5846e1f23db7f81e253b90aad49\", \"best_bid\":\"0.45\", \"best_ask\":\"0.46\"}], \"timestamp\":\"1781254837129\", \"event_type\":\"price_change\"}","ts_local_ms":1781254837812}
{"dir":"in","text":"{\"market\":\"0x9c535590faae21bf76fed844aa47fc3c5c82253ef38bd545bf12c93470502685\", \"price_changes\":[{\"asset_id\":\"56108879726720646120583724001239294777304794469144970684362785767667828318889\", \"price\":\"0.45\", \"size\":\"387.39\", \"side\":\"BUY\", \"hash\":\"1b455ba88c4348449d35f1f2e06ece1d73abd793\", \"best_bid\":\"0.45\", \"best_ask\":\"0.46\"}, {\"asset_id\":\"107011546575057755426871645700605806081353395825571114128343592072429146374928\", \"price\":\"0.55\", \"size\":\"387.39\", \"side\":\"SELL\", \"hash\":\"45da4750ed38b1cb28d53259e6d4e9b19b604231\", \"best_bid\":\"0.54\", \"best_ask\":\"0.55\"}], \"timestamp\":\"1781254837131\", \"event_type\":\"price_change\"}","ts_local_ms":1781254837812}
{"dir":"in","text":"{\"market\":\"0x9c535590faae21bf76fed844aa47fc3c5c82253ef38bd545bf12c93470502685\", \"price_changes\":[{\"asset_id\":\"107011546575057755426871645700605806081353395825571114128343592072429146374928\", \"price\":\"0.53\", \"size\":\"177.18\", \"side\":\"BUY\", \"hash\":\"15ef8b53b966fc3c74ae8d834bedb351bd87022e\", \"best_bid\":\"0.54\", \"best_ask\":\"0.55\"}, {\"asset_id\":\"56108879726720646120583724001239294777304794469144970684362785767667828318889\", \"price\":\"0.47\", \"size\":\"177.18\", \"side\":\"SELL\", \"hash\":\"3f4ca17ec6a5848fc4a444f1300608f898ddab8e\", \"best_bid\":\"0.45\", \"best_ask\":\"0.46\"}], \"timestamp\":\"1781254837132\", \"event_type\":\"price_change\"}","ts_local_ms":1781254837812}
{"dir":"in","text":"{\"market\":\"0x9c535590faae21bf76fed844aa47fc3c5c82253ef38bd545bf12c93470502685\", \"price_changes\":[{\"asset_id\":\"56108879726720646120583724001239294777304794469144970684362785767667828318889\", \"price\":\"0.45\", \"size\":\"401.39\", \"side\":\"BUY\", \"hash\":\"25afa16734085c5a22c52aa0662e3cae14275e52\", \"best_bid\":\"0.45\", \"best_ask\":\"0.46\"}, {\"asset_id\":\"107011546575057755426871645700605806081353395825571114128343592072429146374928\", \"price\":\"0.55\", \"size\":\"401.39\", \"side\":\"SELL\", \"hash\":\"365c09873395a1d64ed99aadea5d6d2c34da6b4e\", \"best_bid\":\"0.54\", \"best_ask\":\"0.55\"}], \"timestamp\":\"1781254837132\", \"event_type\":\"price_change\"}","ts_local_ms":1781254837812}
{"dir":"in","text":"{\"market\":\"0x9c535590faae21bf76fed844aa47fc3c5c82253ef38bd545bf12c93470502685\", \"price_changes\":[{\"asset_id\":\"107011546575057755426871645700605806081353395825571114128343592072429146374928\", \"price\":\"0.01\", \"size\":\"55006.61\", \"side\":\"BUY\", \"hash\":\"1d6b4962ee7c5a4adffb1eb193fbe65d35bf2506\", \"best_bid\":\"0.54\", \"best_ask\":\"0.55\"}, {\"asset_id\":\"56108879726720646120583724001239294777304794469144970684362785767667828318889\", \"price\":\"0.99\", \"size\":\"55006.61\", \"side\":\"SELL\", \"hash\":\"252aef8e8f488da330901db1e23d5ff21fe00cb1\", \"best_bid\":\"0.45\", \"best_ask\":\"0.46\"}], \"timestamp\":\"1781254837133\", \"event_type\":\"price_change\"}","ts_local_ms":1781254837812}
{"dir":"in","text":"{\"market\":\"0x9c535590faae21bf76fed844aa47fc3c5c82253ef38bd545bf12c93470502685\", \"price_changes\":[{\"asset_id\":\"56108879726720646120583724001239294777304794469144970684362785767667828318889\", \"price\":\"0.48\", \"size\":\"191.65\", \"side\":\"SELL\", \"hash\":\"09b063c13d42e04c7d3f2fbc51ea358ada3b30b0\", \"best_bid\":\"0.45\", \"best_ask\":\"0.46\"}, {\"asset_id\":\"107011546575057755426871645700605806081353395825571114128343592072429146374928\", \"price\":\"0.52\", \"size\":\"191.65\", \"side\":\"BUY\", \"hash\":\"4070a6fa03775c7440a4e4f53da0c56549f5ea73\", \"best_bid\":\"0.54\", \"best_ask\":\"0.55\"}], \"timestamp\":\"1781254837135\", \"event_type\":\"price_change\"}","ts_local_ms":1781254837812}
{"dir":"in","text":"{\"market\":\"0x9c535590faae21bf76fed844aa47fc3c5c82253ef38bd545bf12c93470502685\", \"price_changes\":[{\"asset_id\":\"107011546575057755426871645700605806081353395825571114128343592072429146374928\", \"price\":\"0.54\", \"size\":\"203.69\", \"side\":\"BUY\", \"hash\":\"21156d5f5ce9e7d1193d10d0fe0b18b20a90fb2e\", \"best_bid\":\"0.54\", \"best_ask\":\"0.55\"}, {\"asset_id\":\"56108879726720646120583724001239294777304794469144970684362785767667828318889\", \"price\":\"0.46\", \"size\":\"203.69\", \"side\":\"SELL\", \"hash\":\"11938316a44c22e2882e630e18c48802cd5c7c88\", \"best_bid\":\"0.45\", \"best_ask\":\"0.46\"}], \"timestamp\":\"1781254837136\", \"event_type\":\"price_change\"}","ts_local_ms":1781254837812}
{"dir":"in","text":"{\"market\":\"0x9c535590faae21bf76fed844aa47fc3c5c82253ef38bd545bf12c93470502685\", \"price_changes\":[{\"asset_id\":\"56108879726720646120583724001239294777304794469144970684362785767667828318889\", \"price\":\"0.45\", \"size\":\"415.39\", \"side\":\"BUY\", \"hash\":\"6ce959146efcd1aab3b1ae9f215f38c18101bfad\", \"best_bid\":\"0.45\", \"best_ask\":\"0.46\"}, {\"asset_id\":\"107011546575057755426871645700605806081353395825571114128343592072429146374928\", \"price\":\"0.55\", \"size\":\"415.39\", \"side\":\"SELL\", \"hash\":\"6c6da48f05547767c2ed5dbf838f322064d0a476\", \"best_bid\":\"0.54\", \"best_ask\":\"0.55\"}], \"timestamp\":\"1781254837138\", \"event_type\":\"price_change\"}","ts_local_ms":1781254837812}
{"dir":"in","text":"{\"market\":\"0x9c535590faae21bf76fed844aa47fc3c5c82253ef38bd545bf12c93470502685\", \"price_changes\":[{\"asset_id\":\"107011546575057755426871645700605806081353395825571114128343592072429146374928\", \"price\":\"0.54\", \"size\":\"211.69\", \"side\":\"BUY\", \"hash\":\"629d8a9a249a97d8184e8f98dec24ff00adf019e\", \"best_bid\":\"0.54\", \"best_ask\":\"0.55\"}, {\"asset_id\":\"56108879726720646120583724001239294777304794469144970684362785767667828318889\", \"price\":\"0.46\", \"size\":\"211.69\", \"side\":\"SELL\", \"hash\":\"0d581d843ca82344b2b397cc9757d8c35bd42719\", \"best_bid\":\"0.45\", \"best_ask\":\"0.46\"}], \"timestamp\":\"1781254837139\", \"event_type\":\"price_change\"}","ts_local_ms":1781254837812}
{"dir":"in","text":"{\"market\":\"0x9c535590faae21bf76fed844aa47fc3c5c82253ef38bd545bf12c93470502685\", \"price_changes\":[{\"asset_id\":\"56108879726720646120583724001239294777304794469144970684362785767667828318889\", \"price\":\"0.37\", \"size\":\"276.94\", \"side\":\"BUY\", \"hash\":\"d0eaaa9d5a38bf73924b82ab4d42b00d8fa84840\", \"best_bid\":\"0.45\", \"best_ask\":\"0.46\"}, {\"asset_id\":\"107011546575057755426871645700605806081353395825571114128343592072429146374928\", \"price\":\"0.63\", \"size\":\"276.94\", \"side\":\"SELL\", \"hash\":\"7abecfa9f5e15369515f09bbbaa7c65e5119157a\", \"best_bid\":\"0.54\", \"best_ask\":\"0.55\"}], \"timestamp\":\"1781254837139\", \"event_type\":\"price_change\"}","ts_local_ms":1781254837812}
{"dir":"in","text":"{\"market\":\"0x9c535590faae21bf76fed844aa47fc3c5c82253ef38bd545bf12c93470502685\", \"price_changes\":[{\"asset_id\":\"56108879726720646120583724001239294777304794469144970684362785767667828318889\", \"price\":\"0.43\", \"size\":\"215.96\", \"side\":\"BUY\", \"hash\":\"21abd24ea1b1e63a23f9ac92ed6e4683b9ab5616\", \"best_bid\":\"0.45\", \"best_ask\":\"0.46\"}, {\"asset_id\":\"107011546575057755426871645700605806081353395825571114128343592072429146374928\", \"price\":\"0.57\", \"size\":\"215.96\", \"side\":\"SELL\", \"hash\":\"04c4ed7eaf4f00093845864047733b9804e5a81a\", \"best_bid\":\"0.54\", \"best_ask\":\"0.55\"}], \"timestamp\":\"1781254837140\", \"event_type\":\"price_change\"}","ts_local_ms":1781254837812}
{"dir":"in","text":"{\"market\":\"0x9c535590faae21bf76fed844aa47fc3c5c82253ef38bd545bf12c93470502685\", \"price_changes\":[{\"asset_id\":\"107011546575057755426871645700605806081353395825571114128343592072429146374928\", \"price\":\"0.52\", \"size\":\"198.94\", \"side\":\"BUY\", \"hash\":\"d75ac4dba920db29c02a5ccb5c6d043696c2b884\", \"best_bid\":\"0.54\", \"best_ask\":\"0.55\"}, {\"asset_id\":\"56108879726720646120583724001239294777304794469144970684362785767667828318889\", \"price\":\"0.48\", \"size\":\"198.94\", \"side\":\"SELL\", \"hash\":\"45eb53b9ab5eadb816c816ec2439aabee4a7145d\", \"best_bid\":\"0.45\", \"best_ask\":\"0.46\"}], \"timestamp\":\"1781254837141\", \"event_type\":\"price_change\"}","ts_local_ms":1781254837812}
{"dir":"in","text":"{\"market\":\"0x9c535590faae21bf76fed844aa47fc3c5c82253ef38bd545bf12c93470502685\", \"price_changes\":[{\"asset_id\":\"107011546575057755426871645700605806081353395825571114128343592072429146374928\", \"price\":\"0.44\", \"size\":\"122\", \"side\":\"BUY\", \"hash\":\"2b1f189e0a9ff06f7276bffeb070d08a30444cf6\", \"best_bid\":\"0.54\", \"best_ask\":\"0.55\"}, {\"asset_id\":\"56108879726720646120583724001239294777304794469144970684362785767667828318889\", \"price\":\"0.56\", \"size\":\"122\", \"side\":\"SELL\", \"hash\":\"171708d7a8ab721a9521a4ed19c78a3450f19309\", \"best_bid\":\"0.45\", \"best_ask\":\"0.46\"}], \"timestamp\":\"1781254837142\", \"event_type\":\"price_change\"}","ts_local_ms":1781254837812}
{"dir":"in","text":"{\"market\":\"0x9c535590faae21bf76fed844aa47fc3c5c82253ef38bd545bf12c93470502685\", \"price_changes\":[{\"asset_id\":\"56108879726720646120583724001239294777304794469144970684362785767667828318889\", \"price\":\"0.45\", \"size\":\"402.39\", \"side\":\"BUY\", \"hash\":\"1ef67ea049444a1ddf495f1da6f95448ea268bd9\", \"best_bid\":\"0.45\", \"best_ask\":\"0.46\"}, {\"asset_id\":\"107011546575057755426871645700605806081353395825571114128343592072429146374928\", \"price\":\"0.55\", \"size\":\"402.39\", \"side\":\"SELL\", \"hash\":\"7d20be52be5d5246bc5351309ac98864da5d6d4a\", \"best_bid\":\"0.54\", \"best_ask\":\"0.55\"}], \"timestamp\":\"1781254837143\", \"event_type\":\"price_change\"}","ts_local_ms":1781254837812}
{"dir":"in","text":"{\"market\":\"0x9c535590faae21bf76fed844aa47fc3c5c82253ef38bd545bf12c93470502685\", \"price_changes\":[{\"asset_id\":\"107011546575057755426871645700605806081353395825571114128343592072429146374928\", \"price\":\"0.54\", \"size\":\"201.69\", \"side\":\"BUY\", \"hash\":\"f8bfe30140eb0b01709347d3e46854a057f15b18\", \"best_bid\":\"0.54\", \"best_ask\":\"0.55\"}, {\"asset_id\":\"56108879726720646120583724001239294777304794469144970684362785767667828318889\", \"price\":\"0.46\", \"size\":\"201.69\", \"side\":\"SELL\", \"hash\":\"6ee9347cb8b01b25b0c7b69ff965f3d783853571\", \"best_bid\":\"0.45\", \"best_ask\":\"0.46\"}], \"timestamp\":\"1781254837145\", \"event_type\":\"price_change\"}","ts_local_ms":1781254837812}
{"dir":"in","text":"{\"market\":\"0x9c535590faae21bf76fed844aa47fc3c5c82253ef38bd545bf12c93470502685\", \"price_changes\":[{\"asset_id\":\"107011546575057755426871645700605806081353395825571114128343592072429146374928\", \"price\":\"0.52\", \"size\":\"224.57\", \"side\":\"BUY\", \"hash\":\"3048f5ec60921a718e6dad7de8ae0be5bbbfea8d\", \"best_bid\":\"0.54\", \"best_ask\":\"0.55\"}, {\"asset_id\":\"56108879726720646120583724001239294777304794469144970684362785767667828318889\", \"price\":\"0.48\", \"size\":\"224.57\", \"side\":\"SELL\", \"hash\":\"d75078b92503907eed6e7246a3f30412337d99b6\", \"best_bid\":\"0.45\", \"best_ask\":\"0.46\"}], \"timestamp\":\"1781254837145\", \"event_type\":\"price_change\"}","ts_local_ms":1781254837812}
{"dir":"in","text":"{\"market\":\"0x9c535590faae21bf76fed844aa47fc3c5c82253ef38bd545bf12c93470502685\", \"price_changes\":[{\"asset_id\":\"56108879726720646120583724001239294777304794469144970684362785767667828318889\", \"price\":\"0.44\", \"size\":\"37.48\", \"side\":\"BUY\", \"hash\":\"6bb0482c0323f1fa7c2b9bd1efb9cc6252c14e09\", \"best_bid\":\"0.45\", \"best_ask\":\"0.46\"}, {\"asset_id\":\"107011546575057755426871645700605806081353395825571114128343592072429146374928\", \"price\":\"0.56\", \"size\":\"37.48\", \"side\":\"SELL\", \"hash\":\"feab82900eb7ad314b9a0671bc49ea86fbaae9b6\", \"best_bid\":\"0.54\", \"best_ask\":\"0.55\"}], \"timestamp\":\"1781254837146\", \"event_type\":\"price_change\"}","ts_local_ms":1781254837812}
{"dir":"in","text":"{\"market\":\"0x9c535590faae21bf76fed844aa47fc3c5c82253ef38bd545bf12c93470502685\", \"price_changes\":[{\"asset_id\":\"56108879726720646120583724001239294777304794469144970684362785767667828318889\", \"price\":\"0.45\", \"size\":\"415.39\", \"side\":\"BUY\", \"hash\":\"693ecae76ae0fd19efccd0f0c0b7f15b3677a5fa\", \"best_bid\":\"0.45\", \"best_ask\":\"0.46\"}, {\"asset_id\":\"107011546575057755426871645700605806081353395825571114128343592072429146374928\", \"price\":\"0.55\", \"size\":\"415.39\", \"side\":\"SELL\", \"hash\":\"e68937a7fecbe7fa1fd3be2e1ba1fb3ba2ec856c\", \"best_bid\":\"0.54\", \"best_ask\":\"0.55\"}], \"timestamp\":\"1781254837147\", \"event_type\":\"price_change\"}","ts_local_ms":1781254837812}
{"dir":"in","text":"{\"market\":\"0x9c535590faae21bf76fed844aa47fc3c5c82253ef38bd545bf12c93470502685\", \"price_changes\":[{\"asset_id\":\"56108879726720646120583724001239294777304794469144970684362785767667828318889\", \"price\":\"0.35\", \"size\":\"266\", \"side\":\"BUY\", \"hash\":\"bc4a03203c8c3fb4487927a16be396b4f5c9dbfe\", \"best_bid\":\"0.45\", \"best_ask\":\"0.46\"}, {\"asset_id\":\"107011546575057755426871645700605806081353395825571114128343592072429146374928\", \"price\":\"0.65\", \"size\":\"266\", \"side\":\"SELL\", \"hash\":\"7748391979a6b392b7b1e446b3853edd65efd4b8\", \"best_bid\":\"0.54\", \"best_ask\":\"0.55\"}], \"timestamp\":\"1781254837149\", \"event_type\":\"price_change\"}","ts_local_ms":1781254837812}
{"dir":"in","text":"{\"market\":\"0x9c535590faae21bf76fed844aa47fc3c5c82253ef38bd545bf12c93470502685\", \"price_changes\":[{\"asset_id\":\"107011546575057755426871645700605806081353395825571114128343592072429146374928\", \"price\":\"0.44\", \"size\":\"97\", \"side\":\"BUY\", \"hash\":\"7f8e08ea296f9f2b7795379eea791fa1a5d8fd38\", \"best_bid\":\"0.54\", \"best_ask\":\"0.55\"}, {\"asset_id\":\"56108879726720646120583724001239294777304794469144970684362785767667828318889\", \"price\":\"0.56\", \"size\":\"97\", \"side\":\"SELL\", \"hash\":\"20e2e6188da58604e651653ce421ed465b45525f\", \"best_bid\":\"0.45\", \"best_ask\":\"0.46\"}], \"timestamp\":\"1781254837150\", \"event_type\":\"price_change\"}","ts_local_ms":1781254837812}
{"dir":"in","text":"{\"market\":\"0x9c535590faae21bf76fed844aa47fc3c5c82253ef38bd545bf12c93470502685\", \"price_changes\":[{\"asset_id\":\"56108879726720646120583724001239294777304794469144970684362785767667828318889\", \"price\":\"0.45\", \"size\":\"402.39\", \"side\":\"BUY\", \"hash\":\"7d583ba9a142a8eece6684db8334acfc2d6e08ac\", \"best_bid\":\"0.45\", \"best_ask\":\"0.46\"}, {\"asset_id\":\"107011546575057755426871645700605806081353395825571114128343592072429146374928\", \"price\":\"0.55\", \"size\":\"402.39\", \"side\":\"SELL\", \"hash\":\"6888371c7f6212fa06253b80163f322679ea1c4b\", \"best_bid\":\"0.54\", \"best_ask\":\"0.55\"}], \"timestamp\":\"1781254837151\", \"event_type\":\"price_change\"}","ts_local_ms":1781254837812}
{"dir":"in","text":"{\"market\":\"0x9c535590faae21bf76fed844aa47fc3c5c82253ef38bd545bf12c93470502685\", \"price_changes\":[{\"asset_id\":\"107011546575057755426871645700605806081353395825571114128343592072429146374928\", \"price\":\"0.53\", \"size\":\"172\", \"side\":\"BUY\", \"hash\":\"f719c03c03ba14bbe1cf7754006d29161a6bab25\", \"best_bid\":\"0.54\", \"best_ask\":\"0.55\"}, {\"asset_id\":\"56108879726720646120583724001239294777304794469144970684362785767667828318889\", \"price\":\"0.47\", \"size\":\"172\", \"side\":\"SELL\", \"hash\":\"845e70f1b6906f552dcb3ad31a8b7a29e1e57b58\", \"best_bid\":\"0.45\", \"best_ask\":\"0.46\"}], \"timestamp\":\"1781254837152\", \"event_type\":\"price_change\"}","ts_local_ms":1781254837812}
{"dir":"in","text":"{\"market\":\"0x9c535590faae21bf76fed844aa47fc3c5c82253ef38bd545bf12c93470502685\", \"price_changes\":[{\"asset_id\":\"56108879726720646120583724001239294777304794469144970684362785767667828318889\", \"price\":\"0.43\", \"size\":\"209.58\", \"side\":\"BUY\", \"hash\":\"ebf8fe8918f111fd62a5695600085fe07ea2156c\", \"best_bid\":\"0.45\", \"best_ask\":\"0.46\"}, {\"asset_id\":\"107011546575057755426871645700605806081353395825571114128343592072429146374928\", \"price\":\"0.57\", \"size\":\"209.58\", \"side\":\"SELL\", \"hash\":\"85c62efc60c9c33c2d3e1df721b72ce8aa767d08\", \"best_bid\":\"0.54\", \"best_ask\":\"0.55\"}], \"timestamp\":\"1781254837152\", \"event_type\":\"price_change\"}","ts_local_ms":1781254837812}
{"dir":"in","text":"{\"market\":\"0x9c535590faae21bf76fed844aa47fc3c5c82253ef38bd545bf12c93470502685\", \"price_changes\":[{\"asset_id\":\"56108879726720646120583724001239294777304794469144970684362785767667828318889\", \"price\":\"0.45\", \"size\":\"408.39\", \"side\":\"BUY\", \"hash\":\"f7c3232983e7106cb9fc5a9412521fb8b221186e\", \"best_bid\":\"0.45\", \"best_ask\":\"0.46\"}, {\"asset_id\":\"107011546575057755426871645700605806081353395825571114128343592072429146374928\", \"price\":\"0.55\", \"size\":\"408.39\", \"side\":\"SELL\", \"hash\":\"2cde05684b2e9841ed940244f2ebd3eb330bd515\", \"best_bid\":\"0.54\", \"best_ask\":\"0.55\"}], \"timestamp\":\"1781254837155\", \"event_type\":\"price_change\"}","ts_local_ms":1781254837812}
{"dir":"in","text":"{\"market\":\"0x9c535590faae21bf76fed844aa47fc3c5c82253ef38bd545bf12c93470502685\", \"price_changes\":[{\"asset_id\":\"56108879726720646120583724001239294777304794469144970684362785767667828318889\", \"price\":\"0.45\", \"size\":\"402.39\", \"side\":\"BUY\", \"hash\":\"4beed5f5918efb55c22a2c3f702fefa52a62a388\", \"best_bid\":\"0.45\", \"best_ask\":\"0.46\"}, {\"asset_id\":\"107011546575057755426871645700605806081353395825571114128343592072429146374928\", \"price\":\"0.55\", \"size\":\"402.39\", \"side\":\"SELL\", \"hash\":\"2b7fb0d911d076b6c1953311dff49383c12de037\", \"best_bid\":\"0.54\", \"best_ask\":\"0.55\"}], \"timestamp\":\"1781254837155\", \"event_type\":\"price_change\"}","ts_local_ms":1781254837812}
{"dir":"in","text":"{\"market\":\"0x9c535590faae21bf76fed844aa47fc3c5c82253ef38bd545bf12c93470502685\", \"price_changes\":[{\"asset_id\":\"56108879726720646120583724001239294777304794469144970684362785767667828318889\", \"price\":\"0.21\", \"size\":\"153.8\", \"side\":\"BUY\", \"hash\":\"98b2090f17a66af0d481308e1c2959f67b2172ba\", \"best_bid\":\"0.45\", \"best_ask\":\"0.46\"}, {\"asset_id\":\"107011546575057755426871645700605806081353395825571114128343592072429146374928\", \"price\":\"0.79\", \"size\":\"153.8\", \"side\":\"SELL\", \"hash\":\"d0973427022245ea7ec8cb1d70cc5739e0bf2663\", \"best_bid\":\"0.54\", \"best_ask\":\"0.55\"}], \"timestamp\":\"1781254837155\", \"event_type\":\"price_change\"}","ts_local_ms":1781254837812}
{"dir":"in","text":"{\"market\":\"0x9c535590faae21bf76fed844aa47fc3c5c82253ef38bd545bf12c93470502685\", \"price_changes\":[{\"asset_id\":\"107011546575057755426871645700605806081353395825571114128343592072429146374928\", \"price\":\"0.39\", \"size\":\"691.5\", \"side\":\"BUY\", \"hash\":\"ec9ad5e539c963ad3615ee09201fdcfa1375f202\", \"best_bid\":\"0.54\", \"best_ask\":\"0.55\"}, {\"asset_id\":\"56108879726720646120583724001239294777304794469144970684362785767667828318889\", \"price\":\"0.61\", \"size\":\"691.5\", \"side\":\"SELL\", \"hash\":\"b356dbd4c686b21bbd35fcb2ecf59f0f0def4d17\", \"best_bid\":\"0.45\", \"best_ask\":\"0.46\"}], \"timestamp\":\"1781254837156\", \"event_type\":\"price_change\"}","ts_local_ms":1781254837812}
{"dir":"in","text":"{\"market\":\"0x9c535590faae21bf76fed844aa47fc3c5c82253ef38bd545bf12c93470502685\", \"price_changes\":[{\"asset_id\":\"56108879726720646120583724001239294777304794469144970684362785767667828318889\", \"price\":\"0.45\", \"size\":\"374.39\", \"side\":\"BUY\", \"hash\":\"95f0a9e505d43c9c071071d942b246447af8b9dd\", \"best_bid\":\"0.45\", \"best_ask\":\"0.46\"}, {\"asset_id\":\"107011546575057755426871645700605806081353395825571114128343592072429146374928\", \"price\":\"0.55\", \"size\":\"374.39\", \"side\":\"SELL\", \"hash\":\"545e793a98dea818623797e691a6182846e26a2f\", \"best_bid\":\"0.54\", \"best_ask\":\"0.55\"}], \"timestamp\":\"1781254837157\", \"event_type\":\"price_change\"}","ts_local_ms":1781254837812}
{"dir":"in","text":"{\"market\":\"0x9c535590faae21bf76fed844aa47fc3c5c82253ef38bd545bf12c93470502685\", \"price_changes\":[{\"asset_id\":\"56108879726720646120583724001239294777304794469144970684362785767667828318889\", \"price\":\"0.45\", \"size\":\"361.39\", \"side\":\"BUY\", \"hash\":\"559841874efb8af9f85981e60cb357586bd8cbcf\", \"best_bid\":\"0.45\", \"best_ask\":\"0.46\"}, {\"asset_id\":\"107011546575057755426871645700605806081353395825571114128343592072429146374928\", \"price\":\"0.55\", \"size\":\"361.39\", \"side\":\"SELL\", \"hash\":\"5a286a98cb8a6bae8e0e6e595df3b337155af857\", \"best_bid\":\"0.54\", \"best_ask\":\"0.55\"}], \"timestamp\":\"1781254837157\", \"event_type\":\"price_change\"}","ts_local_ms":1781254837813}
{"dir":"in","text":"{\"market\":\"0x9c535590faae21bf76fed844aa47fc3c5c82253ef38bd545bf12c93470502685\", \"price_changes\":[{\"asset_id\":\"56108879726720646120583724001239294777304794469144970684362785767667828318889\", \"price\":\"0.45\", \"size\":\"348.39\", \"side\":\"BUY\", \"hash\":\"493141d7b632fda3ad888c64da68ff5475f222a8\", \"best_bid\":\"0.45\", \"best_ask\":\"0.46\"}, {\"asset_id\":\"107011546575057755426871645700605806081353395825571114128343592072429146374928\", \"price\":\"0.55\", \"size\":\"348.39\", \"side\":\"SELL\", \"hash\":\"562576e728323245ae51954ac969f7cebd33ed9c\", \"best_bid\":\"0.54\", \"best_ask\":\"0.55\"}], \"timestamp\":\"1781254837158\", \"event_type\":\"price_change\"}","ts_local_ms":1781254837813}
{"dir":"in","text":"{\"market\":\"0x9c535590faae21bf76fed844aa47fc3c5c82253ef38bd545bf12c93470502685\", \"price_changes\":[{\"asset_id\":\"107011546575057755426871645700605806081353395825571114128343592072429146374928\", \"price\":\"0.53\", \"size\":\"197\", \"side\":\"BUY\", \"hash\":\"23c999519752d05197fb54c6c227847caa98e8b5\", \"best_bid\":\"0.54\", \"best_ask\":\"0.55\"}, {\"asset_id\":\"56108879726720646120583724001239294777304794469144970684362785767667828318889\", \"price\":\"0.47\", \"size\":\"197\", \"side\":\"SELL\", \"hash\":\"b89998d1bba2e64b9f63230c530841e46c24a876\", \"best_bid\":\"0.45\", \"best_ask\":\"0.46\"}], \"timestamp\":\"1781254837158\", \"event_type\":\"price_change\"}","ts_local_ms":1781254837813}
{"dir":"in","text":"{\"market\":\"0x9c535590faae21bf76fed844aa47fc3c5c82253ef38bd545bf12c93470502685\", \"price_changes\":[{\"asset_id\":\"56108879726720646120583724001239294777304794469144970684362785767667828318889\", \"price\":\"0.45\", \"size\":\"386.21\", \"side\":\"BUY\", \"hash\":\"ebcdea36243f9c4637ca6221d55ad5ff5e077b4e\", \"best_bid\":\"0.45\", \"best_ask\":\"0.46\"}, {\"asset_id\":\"107011546575057755426871645700605806081353395825571114128343592072429146374928\", \"price\":\"0.55\", \"size\":\"386.21\", \"side\":\"SELL\", \"hash\":\"a2bef00d3867551e92a06f057dca8ba47d0edcf5\", \"best_bid\":\"0.54\", \"best_ask\":\"0.55\"}], \"timestamp\":\"1781254837159\", \"event_type\":\"price_change\"}","ts_local_ms":1781254837813}
{"dir":"in","text":"{\"market\":\"0x9c535590faae21bf76fed844aa47fc3c5c82253ef38bd545bf12c93470502685\", \"price_changes\":[{\"asset_id\":\"56108879726720646120583724001239294777304794469144970684362785767667828318889\", \"price\":\"0.45\", \"size\":\"392.21\", \"side\":\"BUY\", \"hash\":\"6a02c9ec59b1bfe420d2c51631826542f40be01f\", \"best_bid\":\"0.45\", \"best_ask\":\"0.46\"}, {\"asset_id\":\"107011546575057755426871645700605806081353395825571114128343592072429146374928\", \"price\":\"0.55\", \"size\":\"392.21\", \"side\":\"SELL\", \"hash\":\"5aaec45d91a53cc0d4454f9d68be02314f16d937\", \"best_bid\":\"0.54\", \"best_ask\":\"0.55\"}], \"timestamp\":\"1781254837160\", \"event_type\":\"price_change\"}","ts_local_ms":1781254837813}
{"dir":"in","text":"{\"market\":\"0x9c535590faae21bf76fed844aa47fc3c5c82253ef38bd545bf12c93470502685\", \"price_changes\":[{\"asset_id\":\"56108879726720646120583724001239294777304794469144970684362785767667828318889\", \"price\":\"0.45\", \"size\":\"467.21\", \"side\":\"BUY\", \"hash\":\"fa2b348bb91c62b20b85596795809ea1513593ba\", \"best_bid\":\"0.45\", \"best_ask\":\"0.46\"}, {\"asset_id\":\"107011546575057755426871645700605806081353395825571114128343592072429146374928\", \"price\":\"0.55\", \"size\":\"467.21\", \"side\":\"SELL\", \"hash\":\"c21265ee995997d61ee7213b8c4a28ec00cb0218\", \"best_bid\":\"0.54\", \"best_ask\":\"0.55\"}], \"timestamp\":\"1781254837161\", \"event_type\":\"price_change\"}","ts_local_ms":1781254837813}
{"dir":"in","text":"{\"market\":\"0x9c535590faae21bf76fed844aa47fc3c5c82253ef38bd545bf12c93470502685\", \"price_changes\":[{\"asset_id\":\"56108879726720646120583724001239294777304794469144970684362785767667828318889\", \"price\":\"0.48\", \"size\":\"219.29\", \"side\":\"SELL\", \"hash\":\"eb6d477af31e80338011800749b87860c75d77e1\", \"best_bid\":\"0.45\", \"best_ask\":\"0.46\"}, {\"asset_id\":\"107011546575057755426871645700605806081353395825571114128343592072429146374928\", \"price\":\"0.52\", \"size\":\"219.29\", \"side\":\"BUY\", \"hash\":\"2f51e147c01f751bb6876e6b4d1164bb14628087\", \"best_bid\":\"0.54\", \"best_ask\":\"0.55\"}], \"timestamp\":\"1781254837162\", \"event_type\":\"price_change\"}","ts_local_ms":1781254837813}
{"dir":"in","text":"{\"market\":\"0x9c535590faae21bf76fed844aa47fc3c5c82253ef38bd545bf12c93470502685\", \"price_changes\":[{\"asset_id\":\"107011546575057755426871645700605806081353395825571114128343592072429146374928\", \"price\":\"0.54\", \"size\":\"191.52\", \"side\":\"BUY\", \"hash\":\"55cfdd0ab6f820820fb1a212364c96533db46001\", \"best_bid\":\"0.54\", \"best_ask\":\"0.55\"}, {\"asset_id\":\"56108879726720646120583724001239294777304794469144970684362785767667828318889\", \"price\":\"0.46\", \"size\":\"191.52\", \"side\":\"SELL\", \"hash\":\"9881afecf85e65cbecde529866d4f7271b056075\", \"best_bid\":\"0.45\", \"best_ask\":\"0.46\"}], \"timestamp\":\"1781254837163\", \"event_type\":\"price_change\"}","ts_local_ms":1781254837813}
{"dir":"in","text":"{\"market\":\"0x9c535590faae21bf76fed844aa47fc3c5c82253ef38bd545bf12c93470502685\", \"price_changes\":[{\"asset_id\":\"56108879726720646120583724001239294777304794469144970684362785767667828318889\", \"price\":\"0.45\", \"size\":\"392.21\", \"side\":\"BUY\", \"hash\":\"b3fcc8be687b9bd021f9d2158bf9c6ee84f3d5f6\", \"best_bid\":\"0.45\", \"best_ask\":\"0.46\"}, {\"asset_id\":\"107011546575057755426871645700605806081353395825571114128343592072429146374928\", \"price\":\"0.55\", \"size\":\"392.21\", \"side\":\"SELL\", \"hash\":\"6f6515d37dc614b50cacc739f26e52f14c17ede3\", \"best_bid\":\"0.54\", \"best_ask\":\"0.55\"}], \"timestamp\":\"1781254837163\", \"event_type\":\"price_change\"}","ts_local_ms":1781254837813}
{"dir":"in","text":"{\"market\":\"0x9c535590faae21bf76fed844aa47fc3c5c82253ef38bd545bf12c93470502685\", \"price_changes\":[{\"asset_id\":\"56108879726720646120583724001239294777304794469144970684362785767667828318889\", \"price\":\"0.45\", \"size\":\"379.21\", \"side\":\"BUY\", \"hash\":\"00bcdcb6149ad31c0d5be8ade8b63746a5e83c33\", \"best_bid\":\"0.45\", \"best_ask\":\"0.46\"}, {\"asset_id\":\"107011546575057755426871645700605806081353395825571114128343592072429146374928\", \"price\":\"0.55\", \"size\":\"379.21\", \"side\":\"SELL\", \"hash\":\"b2e0854df51fb1925481467f6efc0c9ae7631ae1\", \"best_bid\":\"0.54\", \"best_ask\":\"0.55\"}], \"timestamp\":\"1781254837165\", \"event_type\":\"price_change\"}","ts_local_ms":1781254837813}
{"dir":"in","text":"{\"market\":\"0x9c535590faae21bf76fed844aa47fc3c5c82253ef38bd545bf12c93470502685\", \"price_changes\":[{\"asset_id\":\"56108879726720646120583724001239294777304794469144970684362785767667828318889\", \"price\":\"0.45\", \"size\":\"404.21\", \"side\":\"BUY\", \"hash\":\"3b4661be8b079787ecde59f8b215e096c1ae0759\", \"best_bid\":\"0.45\", \"best_ask\":\"0.46\"}, {\"asset_id\":\"107011546575057755426871645700605806081353395825571114128343592072429146374928\", \"price\":\"0.55\", \"size\":\"404.21\", \"side\":\"SELL\", \"hash\":\"b2f9333896173f10c3a8b08a3b9854bad17ad136\", \"best_bid\":\"0.54\", \"best_ask\":\"0.55\"}], \"timestamp\":\"1781254837165\", \"event_type\":\"price_change\"}","ts_local_ms":1781254837813}
{"dir":"in","text":"{\"market\":\"0x9c535590faae21bf76fed844aa47fc3c5c82253ef38bd545bf12c93470502685\", \"price_changes\":[{\"asset_id\":\"107011546575057755426871645700605806081353395825571114128343592072429146374928\", \"price\":\"0.01\", \"size\":\"55001.6\", \"side\":\"BUY\", \"hash\":\"b0155dc4a8dfdda99c5360266775221ff23fc12f\", \"best_bid\":\"0.54\", \"best_ask\":\"0.55\"}, {\"asset_id\":\"56108879726720646120583724001239294777304794469144970684362785767667828318889\", \"price\":\"0.99\", \"size\":\"55001.6\", \"side\":\"SELL\", \"hash\":\"bb61c5de8d812424c84dc28e8333c4b3daee40ca\", \"best_bid\":\"0.45\", \"best_ask\":\"0.46\"}], \"timestamp\":\"1781254837166\", \"event_type\":\"price_change\"}","ts_local_ms":1781254837813}
{"dir":"in","text":"{\"market\":\"0x9c535590faae21bf76fed844aa47fc3c5c82253ef38bd545bf12c93470502685\", \"price_changes\":[{\"asset_id\":\"56108879726720646120583724001239294777304794469144970684362785767667828318889\", \"price\":\"0.45\", \"size\":\"366.39\", \"side\":\"BUY\", \"hash\":\"e4f99f50cc7c46c6c0d29fbc0051d3ab2600a3e5\", \"best_bid\":\"0.45\", \"best_ask\":\"0.46\"}, {\"asset_id\":\"107011546575057755426871645700605806081353395825571114128343592072429146374928\", \"price\":\"0.55\", \"size\":\"366.39\", \"side\":\"SELL\", \"hash\":\"e8a27a73a7793ffe2ad813af8532edf54de9dbf0\", \"best_bid\":\"0.54\", \"best_ask\":\"0.55\"}], \"timestamp\":\"1781254837166\", \"event_type\":\"price_change\"}","ts_local_ms":1781254837813}
{"dir":"in","text":"{\"market\":\"0x9c535590faae21bf76fed844aa47fc3c5c82253ef38bd545bf12c93470502685\", \"price_changes\":[{\"asset_id\":\"56108879726720646120583724001239294777304794469144970684362785767667828318889\", \"price\":\"0.45\", \"size\":\"341.39\", \"side\":\"BUY\", \"hash\":\"627ee2146cd6c1ecd6b3d8af129f20a6b3193154\", \"best_bid\":\"0.45\", \"best_ask\":\"0.46\"}, {\"asset_id\":\"107011546575057755426871645700605806081353395825571114128343592072429146374928\", \"price\":\"0.55\", \"size\":\"341.39\", \"side\":\"SELL\", \"hash\":\"f53fc01037b69d298b218ba2d4270c9ccc2dcd89\", \"best_bid\":\"0.54\", \"best_ask\":\"0.55\"}], \"timestamp\":\"1781254837166\", \"event_type\":\"price_change\"}","ts_local_ms":1781254837813}
{"dir":"in","text":"{\"market\":\"0x9c535590faae21bf76fed844aa47fc3c5c82253ef38bd545bf12c93470502685\", \"price_changes\":[{\"asset_id\":\"56108879726720646120583724001239294777304794469144970684362785767667828318889\", \"price\":\"0.45\", \"size\":\"321.39\", \"side\":\"BUY\", \"hash\":\"4a1a97b42f1782c26e0f3f5f907bf988a09a6fb6\", \"best_bid\":\"0.45\", \"best_ask\":\"0.46\"}, {\"asset_id\":\"107011546575057755426871645700605806081353395825571114128343592072429146374928\", \"price\":\"0.55\", \"size\":\"321.39\", \"side\":\"SELL\", \"hash\":\"34bf858821339779e3f88896a4c6e14eb1d8b058\", \"best_bid\":\"0.54\", \"best_ask\":\"0.55\"}], \"timestamp\":\"1781254837167\", \"event_type\":\"price_change\"}","ts_local_ms":1781254837813}
{"dir":"in","text":"{\"market\":\"0x9c535590faae21bf76fed844aa47fc3c5c82253ef38bd545bf12c93470502685\", \"price_changes\":[{\"asset_id\":\"56108879726720646120583724001239294777304794469144970684362785767667828318889\", \"price\":\"0.45\", \"size\":\"307.39\", \"side\":\"BUY\", \"hash\":\"5bf3b577d4f4c539ca834d8374c67f7796fcf186\", \"best_bid\":\"0.45\", \"best_ask\":\"0.46\"}, {\"asset_id\":\"107011546575057755426871645700605806081353395825571114128343592072429146374928\", \"price\":\"0.55\", \"size\":\"307.39\", \"side\":\"SELL\", \"hash\":\"695b42a52a46ec866a073705547a66e0d14a19e6\", \"best_bid\":\"0.54\", \"best_ask\":\"0.55\"}], \"timestamp\":\"1781254837167\", \"event_type\":\"price_change\"}","ts_local_ms":1781254837813}
{"dir":"in","text":"{\"market\":\"0x9c535590faae21bf76fed844aa47fc3c5c82253ef38bd545bf12c93470502685\", \"price_changes\":[{\"asset_id\":\"56108879726720646120583724001239294777304794469144970684362785767667828318889\", \"price\":\"0.44\", \"size\":\"62.48\", \"side\":\"BUY\", \"hash\":\"e751ea6e1bba96045e80c005a05d87d9de9d38eb\", \"best_bid\":\"0.45\", \"best_ask\":\"0.46\"}, {\"asset_id\":\"107011546575057755426871645700605806081353395825571114128343592072429146374928\", \"price\":\"0.56\", \"size\":\"62.48\", \"side\":\"SELL\", \"hash\":\"e39c27c12dcc2ce861551df72cc8c2d7ea4983d2\", \"best_bid\":\"0.54\", \"best_ask\":\"0.55\"}], \"timestamp\":\"1781254837170\", \"event_type\":\"price_change\"}","ts_local_ms":1781254837813}
{"dir":"in","text":"{\"market\":\"0x9c535590faae21bf76fed844aa47fc3c5c82253ef38bd545bf12c93470502685\", \"price_changes\":[{\"asset_id\":\"56108879726720646120583724001239294777304794469144970684362785767667828318889\", \"price\":\"0.45\", \"size\":\"294.39\", \"side\":\"BUY\", \"hash\":\"acd3fab06fd2319a282b8ecc983bf2b8651578ab\", \"best_bid\":\"0.45\", \"best_ask\":\"0.46\"}, {\"asset_id\":\"107011546575057755426871645700605806081353395825571114128343592072429146374928\", \"price\":\"0.55\", \"size\":\"294.39\", \"side\":\"SELL\", \"hash\":\"5f39184a11b904680c5357d402347727a9fca59a\", \"best_bid\":\"0.54\", \"best_ask\":\"0.55\"}], \"timestamp\":\"1781254837171\", \"event_type\":\"price_change\"}","ts_local_ms":1781254837813}
{"dir":"in","text":"{\"market\":\"0x9c535590faae21bf76fed844aa47fc3c5c82253ef38bd545bf12c93470502685\", \"price_changes\":[{\"asset_id\":\"56108879726720646120583724001239294777304794469144970684362785767667828318889\", \"price\":\"0.38\", \"size\":\"353.74\", \"side\":\"BUY\", \"hash\":\"1776c3c164940c40e913dd139a8cc4be0925f550\", \"best_bid\":\"0.45\", \"best_ask\":\"0.46\"}, {\"asset_id\":\"107011546575057755426871645700605806081353395825571114128343592072429146374928\", \"price\":\"0.62\", \"size\":\"353.74\", \"side\":\"SELL\", \"hash\":\"0fee1afc4a80ad3a686863ba2275382c973a0e4a\", \"best_bid\":\"0.54\", \"best_ask\":\"0.55\"}], \"timestamp\":\"1781254837171\", \"event_type\":\"price_change\"}","ts_local_ms":1781254837813}
{"dir":"in","text":"{\"market\":\"0x9c535590faae21bf76fed844aa47fc3c5c82253ef38bd545bf12c93470502685\", \"price_changes\":[{\"asset_id\":\"56108879726720646120583724001239294777304794469144970684362785767667828318889\", \"price\":\"0.45\", \"size\":\"281.39\", \"side\":\"BUY\", \"hash\":\"0202b9733a5b35c089b7f0bf6ff251d7bf8f9d84\", \"best_bid\":\"0.45\", \"best_ask\":\"0.46\"}, {\"asset_id\":\"107011546575057755426871645700605806081353395825571114128343592072429146374928\", \"price\":\"0.55\", \"size\":\"281.39\", \"side\":\"SELL\", \"hash\":\"4a0449769f6a2e5993049974d01f7e276c4c1511\", \"best_bid\":\"0.54\", \"best_ask\":\"0.55\"}], \"timestamp\":\"1781254837172\", \"event_type\":\"price_change\"}","ts_local_ms":1781254837813}
{"dir":"in","text":"{\"market\":\"0x9c535590faae21bf76fed844aa47fc3c5c82253ef38bd545bf12c93470502685\", \"price_changes\":[{\"asset_id\":\"107011546575057755426871645700605806081353395825571114128343592072429146374928\", \"price\":\"0.04\", \"size\":\"1682.1\", \"side\":\"BUY\", \"hash\":\"f669e2e8d7ce922e2364f87c629ce41e3e4d3d6b\", \"best_bid\":\"0.54\", \"best_ask\":\"0.55\"}, {\"asset_id\":\"56108879726720646120583724001239294777304794469144970684362785767667828318889\", \"price\":\"0.96\", \"size\":\"1682.1\", \"side\":\"SELL\", \"hash\":\"3628b869cf362cd9267eead40407ab942d0a383f\", \"best_bid\":\"0.45\", \"best_ask\":\"0.46\"}], \"timestamp\":\"1781254837175\", \"event_type\":\"price_change\"}","ts_local_ms":1781254837813}
{"dir":"in","text":"{\"market\":\"0x9c535590faae21bf76fed844aa47fc3c5c82253ef38bd545bf12c93470502685\", \"price_changes\":[{\"asset_id\":\"107011546575057755426871645700605806081353395825571114128343592072429146374928\", \"price\":\"0.54\", \"size\":\"216.52\", \"side\":\"BUY\", \"hash\":\"fc9272491c243e9e53e9911e8af710f2a67db0c9\", \"best_bid\":\"0.54\", \"best_ask\":\"0.55\"}, {\"asset_id\":\"56108879726720646120583724001239294777304794469144970684362785767667828318889\", \"price\":\"0.46\", \"size\":\"216.52\", \"side\":\"SELL\", \"hash\":\"82cc0cfc74c3bf01b40dd314530c9ceb3bbe6880\", \"best_bid\":\"0.45\", \"best_ask\":\"0.46\"}], \"timestamp\":\"1781254837176\", \"event_type\":\"price_change\"}","ts_local_ms":1781254837814}
{"dir":"in","text":"{\"market\":\"0x9c535590faae21bf76fed844aa47fc3c5c82253ef38bd545bf12c93470502685\", \"price_changes\":[{\"asset_id\":\"107011546575057755426871645700605806081353395825571114128343592072429146374928\", \"price\":\"0.37\", \"size\":\"156.6\", \"side\":\"BUY\", \"hash\":\"e61ec9fe27eef0b55f3109b8c33b7d1fef54a133\", \"best_bid\":\"0.54\", \"best_ask\":\"0.55\"}, {\"asset_id\":\"56108879726720646120583724001239294777304794469144970684362785767667828318889\", \"price\":\"0.63\", \"size\":\"156.6\", \"side\":\"SELL\", \"hash\":\"706654fce9c29454791fdc3446561a58278969ca\", \"best_bid\":\"0.45\", \"best_ask\":\"0.46\"}], \"timestamp\":\"1781254837176\", \"event_type\":\"price_change\"}","ts_local_ms":1781254837814}
{"dir":"in","text":"{\"market\":\"0x9c535590faae21bf76fed844aa47fc3c5c82253ef38bd545bf12c93470502685\", \"price_changes\":[{\"asset_id\":\"56108879726720646120583724001239294777304794469144970684362785767667828318889\", \"price\":\"0.34\", \"size\":\"132\", \"side\":\"BUY\", \"hash\":\"efad658806fff3880aca0c05b142d0bb0740a8ca\", \"best_bid\":\"0.45\", \"best_ask\":\"0.46\"}, {\"asset_id\":\"107011546575057755426871645700605806081353395825571114128343592072429146374928\", \"price\":\"0.66\", \"size\":\"132\", \"side\":\"SELL\", \"hash\":\"f7b69daaf91aa8a26932637a26f8138fbf8c90f0\", \"best_bid\":\"0.54\", \"best_ask\":\"0.55\"}], \"timestamp\":\"1781254837179\", \"event_type\":\"price_change\"}","ts_local_ms":1781254837814}
{"dir":"in","text":"{\"market\":\"0x9c535590faae21bf76fed844aa47fc3c5c82253ef38bd545bf12c93470502685\", \"price_changes\":[{\"asset_id\":\"56108879726720646120583724001239294777304794469144970684362785767667828318889\", \"price\":\"0.35\", \"size\":\"291\", \"side\":\"BUY\", \"hash\":\"8688eb4da6c7f0304727a5f42e0ca39734daf6a7\", \"best_bid\":\"0.45\", \"best_ask\":\"0.46\"}, {\"asset_id\":\"107011546575057755426871645700605806081353395825571114128343592072429146374928\", \"price\":\"0.65\", \"size\":\"291\", \"side\":\"SELL\", \"hash\":\"faeb9bf6ce5220f6fda1b9c5bde57d1a6aaa3ae6\", \"best_bid\":\"0.54\", \"best_ask\":\"0.55\"}], \"timestamp\":\"1781254837179\", \"event_type\":\"price_change\"}","ts_local_ms":1781254837814}
{"dir":"in","text":"{\"market\":\"0x9c535590faae21bf76fed844aa47fc3c5c82253ef38bd545bf12c93470502685\", \"price_changes\":[{\"asset_id\":\"56108879726720646120583724001239294777304794469144970684362785767667828318889\", \"price\":\"0.19\", \"size\":\"104.67\", \"side\":\"BUY\", \"hash\":\"783856c18c5de76628f682587ab8eea91bce59de\", \"best_bid\":\"0.45\", \"best_ask\":\"0.46\"}, {\"asset_id\":\"107011546575057755426871645700605806081353395825571114128343592072429146374928\", \"price\":\"0.81\", \"size\":\"104.67\", \"side\":\"SELL\", \"hash\":\"7ba949da8086e3a4f8f567b9ab28e7ac625c6fee\", \"best_bid\":\"0.54\", \"best_ask\":\"0.55\"}], \"timestamp\":\"1781254837180\", \"event_type\":\"price_change\"}","ts_local_ms":1781254837814}
{"dir":"in","text":"{\"market\":\"0x9c535590faae21bf76fed844aa47fc3c5c82253ef38bd545bf12c93470502685\", \"price_changes\":[{\"asset_id\":\"56108879726720646120583724001239294777304794469144970684362785767667828318889\", \"price\":\"0.44\", \"size\":\"37.48\", \"side\":\"BUY\", \"hash\":\"2dd071ed6af9fa78a3371376e9c7a655597fc904\", \"best_bid\":\"0.45\", \"best_ask\":\"0.46\"}, {\"asset_id\":\"107011546575057755426871645700605806081353395825571114128343592072429146374928\", \"price\":\"0.56\", \"size\":\"37.48\", \"side\":\"SELL\", \"hash\":\"d711b2e3706e843a1bfc6a8c52ac1c491a408609\", \"best_bid\":\"0.54\", \"best_ask\":\"0.55\"}], \"timestamp\":\"1781254837180\", \"event_type\":\"price_change\"}","ts_local_ms":1781254837814}
{"dir":"in","text":"{\"market\":\"0x9c535590faae21bf76fed844aa47fc3c5c82253ef38bd545bf12c93470502685\", \"price_changes\":[{\"asset_id\":\"107011546575057755426871645700605806081353395825571114128343592072429146374928\", \"price\":\"0.53\", \"size\":\"172\", \"side\":\"BUY\", \"hash\":\"aa363297a91d85569099d852b49069d3f10bc862\", \"best_bid\":\"0.54\", \"best_ask\":\"0.55\"}, {\"asset_id\":\"56108879726720646120583724001239294777304794469144970684362785767667828318889\", \"price\":\"0.47\", \"size\":\"172\", \"side\":\"SELL\", \"hash\":\"c7419825ea5db429f8a9ca2756b1af9ce310dfdf\", \"best_bid\":\"0.45\", \"best_ask\":\"0.46\"}], \"timestamp\":\"1781254837181\", \"event_type\":\"price_change\"}","ts_local_ms":1781254837814}
{"dir":"in","text":"{\"market\":\"0x9c535590faae21bf76fed844aa47fc3c5c82253ef38bd545bf12c93470502685\", \"price_changes\":[{\"asset_id\":\"56108879726720646120583724001239294777304794469144970684362785767667828318889\", \"price\":\"0.48\", \"size\":\"225.79\", \"side\":\"SELL\", \"hash\":\"5ef78bdd604a58bb95b660f68f9a520fc34c83b5\", \"best_bid\":\"0.45\", \"best_ask\":\"0.46\"}, {\"asset_id\":\"107011546575057755426871645700605806081353395825571114128343592072429146374928\", \"price\":\"0.52\", \"size\":\"225.79\", \"side\":\"BUY\", \"hash\":\"9442c2ee7e03b80a77dfe257da6f6a65513c7036\", \"best_bid\":\"0.54\", \"best_ask\":\"0.55\"}], \"timestamp\":\"1781254837181\", \"event_type\":\"price_change\"}","ts_local_ms":1781254837814}
{"dir":"in","text":"{\"market\":\"0x9c535590faae21bf76fed844aa47fc3c5c82253ef38bd545bf12c93470502685\", \"price_changes\":[{\"asset_id\":\"107011546575057755426871645700605806081353395825571114128343592072429146374928\", \"price\":\"0.01\", \"size\":\"55007.6\", \"side\":\"BUY\", \"hash\":\"a5b7a8bde2f46b88dd17bf82e8a7a1bd250abe4c\", \"best_bid\":\"0.54\", \"best_ask\":\"0.55\"}, {\"asset_id\":\"56108879726720646120583724001239294777304794469144970684362785767667828318889\", \"price\":\"0.99\", \"size\":\"55007.6\", \"side\":\"SELL\", \"hash\":\"c7433acf638df5d613f988ceef8b7d7f286d30b2\", \"best_bid\":\"0.45\", \"best_ask\":\"0.46\"}], \"timestamp\":\"1781254837186\", \"event_type\":\"price_change\"}","ts_local_ms":1781254837814}
{"dir":"in","text":"{\"market\":\"0x9c535590faae21bf76fed844aa47fc3c5c82253ef38bd545bf12c93470502685\", \"price_changes\":[{\"asset_id\":\"56108879726720646120583724001239294777304794469144970684362785767667828318889\", \"price\":\"0.45\", \"size\":\"288.39\", \"side\":\"BUY\", \"hash\":\"283bdae807c0aa622cc333f701963da7e8fc3bd2\", \"best_bid\":\"0.45\", \"best_ask\":\"0.46\"}, {\"asset_id\":\"107011546575057755426871645700605806081353395825571114128343592072429146374928\", \"price\":\"0.55\", \"size\":\"288.39\", \"side\":\"SELL\", \"hash\":\"1417ae4925a35a7e18d58ba50ed93890a5344ca4\", \"best_bid\":\"0.54\", \"best_ask\":\"0.55\"}], \"timestamp\":\"1781254837189\", \"event_type\":\"price_change\"}","ts_local_ms":1781254837814}
{"dir":"in","text":"{\"market\":\"0x9c535590faae21bf76fed844aa47fc3c5c82253ef38bd545bf12c93470502685\", \"price_changes\":[{\"asset_id\":\"107011546575057755426871645700605806081353395825571114128343592072429146374928\", \"price\":\"0.44\", \"size\":\"122\", \"side\":\"BUY\", \"hash\":\"2a503d5b9a634536f62fe32ca795fec24e598b1e\", \"best_bid\":\"0.54\", \"best_ask\":\"0.55\"}, {\"asset_id\":\"56108879726720646120583724001239294777304794469144970684362785767667828318889\", \"price\":\"0.56\", \"size\":\"122\", \"side\":\"SELL\", \"hash\":\"af051cf0f35a22a6d43e181c23d3595cd0b4da03\", \"best_bid\":\"0.45\", \"best_ask\":\"0.46\"}], \"timestamp\":\"1781254837190\", \"event_type\":\"price_change\"}","ts_local_ms":1781254837814}
{"dir":"in","text":"{\"market\":\"0x9c535590faae21bf76fed844aa47fc3c5c82253ef38bd545bf12c93470502685\", \"price_changes\":[{\"asset_id\":\"107011546575057755426871645700605806081353395825571114128343592072429146374928\", \"price\":\"0.54\", \"size\":\"191.52\", \"side\":\"BUY\", \"hash\":\"9ae07513d762f0f17058ceb32ab02bd5b74ec1a3\", \"best_bid\":\"0.54\", \"best_ask\":\"0.55\"}, {\"asset_id\":\"56108879726720646120583724001239294777304794469144970684362785767667828318889\", \"price\":\"0.46\", \"size\":\"191.52\", \"side\":\"SELL\", \"hash\":\"a1d08707b390436080d5c099cf14a5bdd98cbadb\", \"best_bid\":\"0.45\", \"best_ask\":\"0.46\"}], \"timestamp\":\"1781254837191\", \"event_type\":\"price_change\"}","ts_local_ms":1781254837814}
{"dir":"in","text":"{\"market\":\"0x9c535590faae21bf76fed844aa47fc3c5c82253ef38bd545bf12c93470502685\", \"price_changes\":[{\"asset_id\":\"107011546575057755426871645700605806081353395825571114128343592072429146374928\", \"price\":\"0.54\", \"size\":\"202.61\", \"side\":\"BUY\", \"hash\":\"72ac70ab0a04c27dbed497d396e63eeb8521aade\", \"best_bid\":\"0.54\", \"best_ask\":\"0.55\"}, {\"asset_id\":\"56108879726720646120583724001239294777304794469144970684362785767667828318889\", \"price\":\"0.46\", \"size\":\"202.61\", \"side\":\"SELL\", \"hash\":\"092122a254a301ff2a7f7d5122c8041f3ba80395\", \"best_bid\":\"0.45\", \"best_ask\":\"0.46\"}], \"timestamp\":\"1781254837191\", \"event_type\":\"price_change\"}","ts_local_ms":1781254837814}
{"dir":"in","text":"{\"market\":\"0x9c535590faae21bf76fed844aa47fc3c5c82253ef38bd545bf12c93470502685\", \"price_changes\":[{\"asset_id\":\"56108879726720646120583724001239294777304794469144970684362785767667828318889\", \"price\":\"0.42\", \"size\":\"194.6\", \"side\":\"BUY\", \"hash\":\"396a4e8dbcf9fd8debba7d6326d3af6e77a80de1\", \"best_bid\":\"0.45\", \"best_ask\":\"0.46\"}, {\"asset_id\":\"107011546575057755426871645700605806081353395825571114128343592072429146374928\", \"price\":\"0.58\", \"size\":\"194.6\", \"side\":\"SELL\", \"hash\":\"694eecc5b8198339f39e02197514136af5e9ce36\", \"best_bid\":\"0.54\", \"best_ask\":\"0.55\"}], \"timestamp\":\"1781254837192\", \"event_type\":\"price_change\"}","ts_local_ms":1781254837814}
{"dir":"in","text":"{\"market\":\"0x9c535590faae21bf76fed844aa47fc3c5c82253ef38bd545bf12c93470502685\", \"price_changes\":[{\"asset_id\":\"56108879726720646120583724001239294777304794469144970684362785767667828318889\", \"price\":\"0.46\", \"size\":\"207.69\", \"side\":\"SELL\", \"hash\":\"871f6dfeddf889ea3df5f469372d593eb92ea691\", \"best_bid\":\"0.45\", \"best_ask\":\"0.46\"}, {\"asset_id\":\"107011546575057755426871645700605806081353395825571114128343592072429146374928\", \"price\":\"0.54\", \"size\":\"207.69\", \"side\":\"BUY\", \"hash\":\"65320a7e41b8509251765f006a6f1e4315d0d956\", \"best_bid\":\"0.54\", \"best_ask\":\"0.55\"}], \"timestamp\":\"1781254837193\", \"event_type\":\"price_change\"}","ts_local_ms":1781254837814}
{"dir":"in","text":"{\"market\":\"0x9c535590faae21bf76fed844aa47fc3c5c82253ef38bd545bf12c93470502685\", \"price_changes\":[{\"asset_id\":\"56108879726720646120583724001239294777304794469144970684362785767667828318889\", \"price\":\"0.45\", \"size\":\"274.39\", \"side\":\"BUY\", \"hash\":\"8a79515a361d9297ea6a251c8ad24a0aecf40bae\", \"best_bid\":\"0.45\", \"best_ask\":\"0.46\"}, {\"asset_id\":\"107011546575057755426871645700605806081353395825571114128343592072429146374928\", \"price\":\"0.55\", \"size\":\"274.39\", \"side\":\"SELL\", \"hash\":\"128ed3c4b634aeae472e37040a889de5c1bf08de\", \"best_bid\":\"0.54\", \"best_ask\":\"0.55\"}], \"timestamp\":\"1781254837193\", \"event_type\":\"price_change\"}","ts_local_ms":1781254837814}
{"dir":"in","text":"{\"market\":\"0x9c535590faae21bf76fed844aa47fc3c5c82253ef38bd545bf12c93470502685\", \"price_changes\":[{\"asset_id\":\"107011546575057755426871645700605806081353395825571114128343592072429146374928\", \"price\":\"0.54\", \"size\":\"217.69\", \"side\":\"BUY\", \"hash\":\"2f63a5eb8ab39d16f56f6a148a5b072e597d57ad\", \"best_bid\":\"0.54\", \"best_ask\":\"0.55\"}, {\"asset_id\":\"56108879726720646120583724001239294777304794469144970684362785767667828318889\", \"price\":\"0.46\", \"size\":\"217.69\", \"side\":\"SELL\", \"hash\":\"10aa6d6bce06164b165604c18ce78f8b6cb042d3\", \"best_bid\":\"0.45\", \"best_ask\":\"0.46\"}], \"timestamp\":\"1781254837194\", \"event_type\":\"price_change\"}","ts_local_ms":1781254837814}
{"dir":"in","text":"{\"market\":\"0x9c535590faae21bf76fed844aa47fc3c5c82253ef38bd545bf12c93470502685\", \"price_changes\":[{\"asset_id\":\"56108879726720646120583724001239294777304794469144970684362785767667828318889\", \"price\":\"0.45\", \"size\":\"294.39\", \"side\":\"BUY\", \"hash\":\"9f7dad07eb060aeaa5fee7249236a3050db197b8\", \"best_bid\":\"0.45\", \"best_ask\":\"0.46\"}, {\"asset_id\":\"107011546575057755426871645700605806081353395825571114128343592072429146374928\", \"price\":\"0.55\", \"size\":\"294.39\", \"side\":\"SELL\", \"hash\":\"085795ab5b203294b9a1a994c6f9d8d64596f868\", \"best_bid\":\"0.54\", \"best_ask\":\"0.55\"}], \"timestamp\":\"1781254837194\", \"event_type\":\"price_change\"}","ts_local_ms":1781254837814}
{"dir":"in","text":"{\"market\":\"0x9c535590faae21bf76fed844aa47fc3c5c82253ef38bd545bf12c93470502685\", \"price_changes\":[{\"asset_id\":\"56108879726720646120583724001239294777304794469144970684362785767667828318889\", \"price\":\"0.45\", \"size\":\"301.39\", \"side\":\"BUY\", \"hash\":\"ae33a2c212620107dd4db3a6c8eb17cb6617a7de\", \"best_bid\":\"0.45\", \"best_ask\":\"0.46\"}, {\"asset_id\":\"107011546575057755426871645700605806081353395825571114128343592072429146374928\", \"price\":\"0.55\", \"size\":\"301.39\", \"side\":\"SELL\", \"hash\":\"6b7318eae5ce437452b7f17f216d22566c09f656\", \"best_bid\":\"0.54\", \"best_ask\":\"0.55\"}], \"timestamp\":\"1781254837195\", \"event_type\":\"price_change\"}","ts_local_ms":1781254837814}
{"dir":"in","text":"{\"market\":\"0x9c535590faae21bf76fed844aa47fc3c5c82253ef38bd545bf12c93470502685\", \"price_changes\":[{\"asset_id\":\"107011546575057755426871645700605806081353395825571114128343592072429146374928\", \"price\":\"0.44\", \"size\":\"97\", \"side\":\"BUY\", \"hash\":\"71ecd44ed4905ede95858c35397c51aacae1b815\", \"best_bid\":\"0.54\", \"best_ask\":\"0.55\"}, {\"asset_id\":\"56108879726720646120583724001239294777304794469144970684362785767667828318889\", \"price\":\"0.56\", \"size\":\"97\", \"side\":\"SELL\", \"hash\":\"d004bec19a208b9eae46da2be430af1d74f4d785\", \"best_bid\":\"0.45\", \"best_ask\":\"0.46\"}], \"timestamp\":\"1781254837196\", \"event_type\":\"price_change\"}","ts_local_ms":1781254837814}
{"dir":"in","text":"{\"market\":\"0x9c535590faae21bf76fed844aa47fc3c5c82253ef38bd545bf12c93470502685\", \"price_changes\":[{\"asset_id\":\"107011546575057755426871645700605806081353395825571114128343592072429146374928\", \"price\":\"0.54\", \"size\":\"206.6\", \"side\":\"BUY\", \"hash\":\"cfa8e451a912ad9988da827ea8f15cccd8252879\", \"best_bid\":\"0.54\", \"best_ask\":\"0.55\"}, {\"asset_id\":\"56108879726720646120583724001239294777304794469144970684362785767667828318889\", \"price\":\"0.46\", \"size\":\"206.6\", \"side\":\"SELL\", \"hash\":\"30ce639421132f64776a37f3cd42481a11882dd3\", \"best_bid\":\"0.45\", \"best_ask\":\"0.46\"}], \"timestamp\":\"1781254837196\", \"event_type\":\"price_change\"}","ts_local_ms":1781254837814}
{"dir":"in","text":"{\"market\":\"0x9c535590faae21bf76fed844aa47fc3c5c82253ef38bd545bf12c93470502685\", \"price_changes\":[{\"asset_id\":\"107011546575057755426871645700605806081353395825571114128343592072429146374928\", \"price\":\"0.52\", \"size\":\"231.06\", \"side\":\"BUY\", \"hash\":\"e662df3941570d3b0596f2f5ec43b60384c887b6\", \"best_bid\":\"0.54\", \"best_ask\":\"0.55\"}, {\"asset_id\":\"56108879726720646120583724001239294777304794469144970684362785767667828318889\", \"price\":\"0.48\", \"size\":\"231.06\", \"side\":\"SELL\", \"hash\":\"9101acc4b98c57ab9bfaa38034f34a557ebc9858\", \"best_bid\":\"0.45\", \"best_ask\":\"0.46\"}], \"timestamp\":\"1781254837196\", \"event_type\":\"price_change\"}","ts_local_ms":1781254837814}
{"dir":"in","text":"{\"market\":\"0x9c535590faae21bf76fed844aa47fc3c5c82253ef38bd545bf12c93470502685\", \"price_changes\":[{\"asset_id\":\"56108879726720646120583724001239294777304794469144970684362785767667828318889\", \"price\":\"0.45\", \"size\":\"308.39\", \"side\":\"BUY\", \"hash\":\"091c37e0deccba1927afe2bad3d6ec58793cd729\", \"best_bid\":\"0.45\", \"best_ask\":\"0.46\"}, {\"asset_id\":\"107011546575057755426871645700605806081353395825571114128343592072429146374928\", \"price\":\"0.55\", \"size\":\"308.39\", \"side\":\"SELL\", \"hash\":\"09924c772df88a948fc741b176a799e1e4d097f5\", \"best_bid\":\"0.54\", \"best_ask\":\"0.55\"}], \"timestamp\":\"1781254837197\", \"event_type\":\"price_change\"}","ts_local_ms":1781254837814}
{"dir":"in","text":"{\"market\":\"0x9c535590faae21bf76fed844aa47fc3c5c82253ef38bd545bf12c93470502685\", \"price_changes\":[{\"asset_id\":\"107011546575057755426871645700605806081353395825571114128343592072429146374928\", \"price\":\"0.42\", \"size\":\"224.3\", \"side\":\"BUY\", \"hash\":\"fb3c0b144f816a3b54cf1fee152dea2b2a0f82b3\", \"best_bid\":\"0.54\", \"best_ask\":\"0.55\"}, {\"asset_id\":\"56108879726720646120583724001239294777304794469144970684362785767667828318889\", \"price\":\"0.58\", \"size\":\"224.3\", \"side\":\"SELL\", \"hash\":\"fca674059d4070f088ec8ba17e4f7f6b41c142bf\", \"best_bid\":\"0.45\", \"best_ask\":\"0.46\"}], \"timestamp\":\"1781254837198\", \"event_type\":\"price_change\"}","ts_local_ms":1781254837815}
{"dir":"in","text":"{\"market\":\"0x9c535590faae21bf76fed844aa47fc3c5c82253ef38bd545bf12c93470502685\", \"price_changes\":[{\"asset_id\":\"56108879726720646120583724001239294777304794469144970684362785767667828318889\", \"price\":\"0.45\", \"size\":\"315.39\", \"side\":\"BUY\", \"hash\":\"81e24ebade07877579a3873214d6dd72085df671\", \"best_bid\":\"0.45\", \"best_ask\":\"0.46\"}, {\"asset_id\":\"107011546575057755426871645700605806081353395825571114128343592072429146374928\", \"price\":\"0.55\", \"size\":\"315.39\", \"side\":\"SELL\", \"hash\":\"a48420394b14cde5564a0365639ea2269323e5ef\", \"best_bid\":\"0.54\", \"best_ask\":\"0.55\"}], \"timestamp\":\"1781254837199\", \"event_type\":\"price_change\"}","ts_local_ms":1781254837815}
{"dir":"in","text":"{\"market\":\"0x9c535590faae21bf76fed844aa47fc3c5c82253ef38bd545bf12c93470502685\", \"price_changes\":[{\"asset_id\":\"56108879726720646120583724001239294777304794469144970684362785767667828318889\", \"price\":\"0.45\", \"size\":\"301.39\", \"side\":\"BUY\", \"hash\":\"5f3c4e175172d9ce9e4654cab8e885e415db5bad\", \"best_bid\":\"0.45\", \"best_ask\":\"0.46\"}, {\"asset_id\":\"107011546575057755426871645700605806081353395825571114128343592072429146374928\", \"price\":\"0.55\", \"size\":\"301.39\", \"side\":\"SELL\", \"hash\":\"d6debf4d781b1af0ac76be93047e02dac651757d\", \"best_bid\":\"0.54\", \"best_ask\":\"0.55\"}], \"timestamp\":\"1781254837201\", \"event_type\":\"price_change\"}","ts_local_ms":1781254837815}
{"dir":"in","text":"{\"market\":\"0x9c535590faae21bf76fed844aa47fc3c5c82253ef38bd545bf12c93470502685\", \"price_changes\":[{\"asset_id\":\"56108879726720646120583724001239294777304794469144970684362785767667828318889\", \"price\":\"0.28\", \"size\":\"72.4\", \"side\":\"BUY\", \"hash\":\"30e040a7eac7778b3775e8ca1cf3883a7b33d647\", \"best_bid\":\"0.45\", \"best_ask\":\"0.46\"}, {\"asset_id\":\"107011546575057755426871645700605806081353395825571114128343592072429146374928\", \"price\":\"0.72\", \"size\":\"72.4\", \"side\":\"SELL\", \"hash\":\"5491d8f7fe7f8f1b9c0b40dcf35259dd832e0a25\", \"best_bid\":\"0.54\", \"best_ask\":\"0.55\"}], \"timestamp\":\"1781254837201\", \"event_type\":\"price_change\"}","ts_local_ms":1781254837815}
{"dir":"in","text":"{\"market\":\"0x9c535590faae21bf76fed844aa47fc3c5c82253ef38bd545bf12c93470502685\", \"price_changes\":[{\"asset_id\":\"56108879726720646120583724001239294777304794469144970684362785767667828318889\", \"price\":\"0.45\", \"size\":\"287.39\", \"side\":\"BUY\", \"hash\":\"a9977495016c8466a9a8f625f899f322ea12050a\", \"best_bid\":\"0.45\", \"best_ask\":\"0.46\"}, {\"asset_id\":\"107011546575057755426871645700605806081353395825571114128343592072429146374928\", \"price\":\"0.55\", \"size\":\"287.39\", \"side\":\"SELL\", \"hash\":\"9d9945e01d284e784ed2ee52031062bd21b2cb7b\", \"best_bid\":\"0.54\", \"best_ask\":\"0.55\"}], \"timestamp\":\"1781254837202\", \"event_type\":\"price_change\"}","ts_local_ms":1781254837815}
{"dir":"in","text":"{\"market\":\"0x9c535590faae21bf76fed844aa47fc3c5c82253ef38bd545bf12c93470502685\", \"price_changes\":[{\"asset_id\":\"56108879726720646120583724001239294777304794469144970684362785767667828318889\", \"price\":\"0.45\", \"size\":\"273.39\", \"side\":\"BUY\", \"hash\":\"22822a7f4db62a0b4af64f5e7c6743125ea3bd8b\", \"best_bid\":\"0.45\", \"best_ask\":\"0.46\"}, {\"asset_id\":\"107011546575057755426871645700605806081353395825571114128343592072429146374928\", \"price\":\"0.55\", \"size\":\"273.39\", \"side\":\"SELL\", \"hash\":\"ab24d8cf563e11a4f9e346a0eba266df82c0d6d0\", \"best_bid\":\"0.54\", \"best_ask\":\"0.55\"}], \"timestamp\":\"1781254837203\", \"event_type\":\"price_change\"}","ts_local_ms":1781254837815}
{"dir":"in","text":"{\"market\":\"0x9c535590faae21bf76fed844aa47fc3c5c82253ef38bd545bf12c93470502685\", \"price_changes\":[{\"asset_id\":\"56108879726720646120583724001239294777304794469144970684362785767667828318889\", \"price\":\"0.45\", \"size\":\"279.39\", \"side\":\"BUY\", \"hash\":\"156fe3b2b86ddbcbc7b66ef0470eefd876199752\", \"best_bid\":\"0.45\", \"best_ask\":\"0.46\"}, {\"asset_id\":\"107011546575057755426871645700605806081353395825571114128343592072429146374928\", \"price\":\"0.55\", \"size\":\"279.39\", \"side\":\"SELL\", \"hash\":\"a9b6e7d0cde1c32d8b9a112c9f7934448612677f\", \"best_bid\":\"0.54\", \"best_ask\":\"0.55\"}], \"timestamp\":\"1781254837204\", \"event_type\":\"price_change\"}","ts_local_ms":1781254837815}
{"dir":"in","text":"{\"market\":\"0x9c535590faae21bf76fed844aa47fc3c5c82253ef38bd545bf12c93470502685\", \"price_changes\":[{\"asset_id\":\"56108879726720646120583724001239294777304794469144970684362785767667828318889\", \"price\":\"0.45\", \"size\":\"265.39\", \"side\":\"BUY\", \"hash\":\"6b2ea884db20f1c7db99d352e2539c2bb3c0ffaf\", \"best_bid\":\"0.45\", \"best_ask\":\"0.46\"}, {\"asset_id\":\"107011546575057755426871645700605806081353395825571114128343592072429146374928\", \"price\":\"0.55\", \"size\":\"265.39\", \"side\":\"SELL\", \"hash\":\"418605da26544b8a456444af0f8be60277050aa0\", \"best_bid\":\"0.54\", \"best_ask\":\"0.55\"}], \"timestamp\":\"1781254837205\", \"event_type\":\"price_change\"}","ts_local_ms":1781254837815}
{"dir":"in","text":"{\"market\":\"0x9c535590faae21bf76fed844aa47fc3c5c82253ef38bd545bf12c93470502685\", \"price_changes\":[{\"asset_id\":\"107011546575057755426871645700605806081353395825571114128343592072429146374928\", \"price\":\"0.01\", \"size\":\"55001.6\", \"side\":\"BUY\", \"hash\":\"02c0cdc8bfdc0941770f039104df22a646644d04\", \"best_bid\":\"0.54\", \"best_ask\":\"0.55\"}, {\"asset_id\":\"56108879726720646120583724001239294777304794469144970684362785767667828318889\", \"price\":\"0.99\", \"size\":\"55001.6\", \"side\":\"SELL\", \"hash\":\"17b8fddd89ceb66da14e12e42851bbd90ad7871d\", \"best_bid\":\"0.45\", \"best_ask\":\"0.46\"}], \"timestamp\":\"1781254837206\", \"event_type\":\"price_change\"}","ts_local_ms":1781254837815}
{"dir":"in","text":"{\"market\":\"0x9c535590faae21bf76fed844aa47fc3c5c82253ef38bd545bf12c93470502685\", \"price_changes\":[{\"asset_id\":\"56108879726720646120583724001239294777304794469144970684362785767667828318889\", \"price\":\"0.45\", \"size\":\"249.39\", \"side\":\"BUY\", \"hash\":\"ae8e0744cda161622692e36f57f3a0438ee35ace\", \"best_bid\":\"0.45\", \"best_ask\":\"0.46\"}, {\"asset_id\":\"107011546575057755426871645700605806081353395825571114128343592072429146374928\", \"price\":\"0.55\", \"size\":\"249.39\", \"side\":\"SELL\", \"hash\":\"72b970d39debc9dc46b043f3fa371fc3f81be905\", \"best_bid\":\"0.54\", \"best_ask\":\"0.55\"}], \"timestamp\":\"1781254837207\", \"event_type\":\"price_change\"}","ts_local_ms":1781254837815}
{"dir":"in","text":"{\"market\":\"0x9c535590faae21bf76fed844aa47fc3c5c82253ef38bd545bf12c93470502685\", \"price_changes\":[{\"asset_id\":\"56108879726720646120583724001239294777304794469144970684362785767667828318889\", \"price\":\"0.45\", \"size\":\"261.39\", \"side\":\"BUY\", \"hash\":\"3a707ac09c44505823c9d1ea1074e1b193737d02\", \"best_bid\":\"0.45\", \"best_ask\":\"0.46\"}, {\"asset_id\":\"107011546575057755426871645700605806081353395825571114128343592072429146374928\", \"price\":\"0.55\", \"size\":\"261.39\", \"side\":\"SELL\", \"hash\":\"24e24e4c2565ce71e690a684ebceb48018c5531b\", \"best_bid\":\"0.54\", \"best_ask\":\"0.55\"}], \"timestamp\":\"1781254837207\", \"event_type\":\"price_change\"}","ts_local_ms":1781254837815}
{"dir":"in","text":"{\"market\":\"0x9c535590faae21bf76fed844aa47fc3c5c82253ef38bd545bf12c93470502685\", \"price_changes\":[{\"asset_id\":\"56108879726720646120583724001239294777304794469144970684362785767667828318889\", \"price\":\"0.41\", \"size\":\"161.92\", \"side\":\"BUY\", \"hash\":\"f3d21ba6e73af56cef7df400420903287ae040fb\", \"best_bid\":\"0.45\", \"best_ask\":\"0.46\"}, {\"asset_id\":\"107011546575057755426871645700605806081353395825571114128343592072429146374928\", \"price\":\"0.59\", \"size\":\"161.92\", \"side\":\"SELL\", \"hash\":\"5b5872c66c4ef17fb70103025f725e7a30d1cae5\", \"best_bid\":\"0.54\", \"best_ask\":\"0.55\"}], \"timestamp\":\"1781254837208\", \"event_type\":\"price_change\"}","ts_local_ms":1781254837815}
{"dir":"in","text":"{\"market\":\"0x9c535590faae21bf76fed844aa47fc3c5c82253ef38bd545bf12c93470502685\", \"price_changes\":[{\"asset_id\":\"56108879726720646120583724001239294777304794469144970684362785767667828318889\", \"price\":\"0.45\", \"size\":\"267.39\", \"side\":\"BUY\", \"hash\":\"e5c89cd7059e0aac34f3d71985b13a6d28ba90ed\", \"best_bid\":\"0.45\", \"best_ask\":\"0.46\"}, {\"asset_id\":\"107011546575057755426871645700605806081353395825571114128343592072429146374928\", \"price\":\"0.55\", \"size\":\"267.39\", \"side\":\"SELL\", \"hash\":\"10d6ef533a4c1f196f2eb9545e2bb5847e077d91\", \"best_bid\":\"0.54\", \"best_ask\":\"0.55\"}], \"timestamp\":\"1781254837209\", \"event_type\":\"price_change\"}","ts_local_ms":1781254837815}
{"dir":"in","text":"{\"market\":\"0x9c535590faae21bf76fed844aa47fc3c5c82253ef38bd545bf12c93470502685\", \"price_changes\":[{\"asset_id\":\"56108879726720646120583724001239294777304794469144970684362785767667828318889\", \"price\":\"0.45\", \"size\":\"273.39\", \"side\":\"BUY\", \"hash\":\"5f5096584eb04a0b1d4cd85b6c823aede0c9d336\", \"best_bid\":\"0.45\", \"best_ask\":\"0.46\"}, {\"asset_id\":\"107011546575057755426871645700605806081353395825571114128343592072429146374928\", \"price\":\"0.55\", \"size\":\"273.39\", \"side\":\"SELL\", \"hash\":\"57a77b0282381d9a5faf374245adeab121643528\", \"best_bid\":\"0.54\", \"best_ask\":\"0.55\"}], \"timestamp\":\"1781254837212\", \"event_type\":\"price_change\"}","ts_local_ms":1781254837815}
{"dir":"in","text":"{\"market\":\"0x9c535590faae21bf76fed844aa47fc3c5c82253ef38bd545bf12c93470502685\", \"price_changes\":[{\"asset_id\":\"107011546575057755426871645700605806081353395825571114128343592072429146374928\", \"price\":\"0.54\", \"size\":\"176.6\", \"side\":\"BUY\", \"hash\":\"2ee9bb6c4826942dbba00566c900bbc370a83835\", \"best_bid\":\"0.54\", \"best_ask\":\"0.55\"}, {\"asset_id\":\"56108879726720646120583724001239294777304794469144970684362785767667828318889\", \"price\":\"0.46\", \"size\":\"176.6\", \"side\":\"SELL\", \"hash\":\"405f3513a8eaab544749b6443e6c643e59ac7471\", \"best_bid\":\"0.45\", \"best_ask\":\"0.46\"}], \"timestamp\":\"1781254837213\", \"event_type\":\"price_change\"}","ts_local_ms":1781254837815}
{"dir":"in","text":"{\"market\":\"0x9c535590faae21bf76fed844aa47fc3c5c82253ef38bd545bf12c93470502685\", \"price_changes\":[{\"asset_id\":\"56108879726720646120583724001239294777304794469144970684362785767667828318889\", \"price\":\"0.43\", \"size\":\"184.58\", \"side\":\"BUY\", \"hash\":\"c3be5b945a2bb388eafaac72299c6480735cc8d6\", \"best_bid\":\"0.45\", \"best_ask\":\"0.46\"}, {\"asset_id\":\"107011546575057755426871645700605806081353395825571114128343592072429146374928\", \"price\":\"0.57\", \"size\":\"184.58\", \"side\":\"SELL\", \"hash\":\"6b626f89b455e5ab42069f8e904afb03d445c2c5\", \"best_bid\":\"0.54\", \"best_ask\":\"0.55\"}], \"timestamp\":\"1781254837214\", \"event_type\":\"price_change\"}","ts_local_ms":1781254837815}
{"dir":"in","text":"{\"market\":\"0x9c535590faae21bf76fed844aa47fc3c5c82253ef38bd545bf12c93470502685\", \"price_changes\":[{\"asset_id\":\"107011546575057755426871645700605806081353395825571114128343592072429146374928\", \"price\":\"0.53\", \"size\":\"197\", \"side\":\"BUY\", \"hash\":\"2d7e79048f70c037dd0c70b5c3b29321d7e3b8d0\", \"best_bid\":\"0.54\", \"best_ask\":\"0.55\"}, {\"asset_id\":\"56108879726720646120583724001239294777304794469144970684362785767667828318889\", \"price\":\"0.47\", \"size\":\"197\", \"side\":\"SELL\", \"hash\":\"ba495e25b50c2d6acfe08ef1c6d6b45ee5a916c7\", \"best_bid\":\"0.45\", \"best_ask\":\"0.46\"}], \"timestamp\":\"1781254837216\", \"event_type\":\"price_change\"}","ts_local_ms":1781254837815}
{"dir":"in","text":"{\"market\":\"0x9c535590faae21bf76fed844aa47fc3c5c82253ef38bd545bf12c93470502685\", \"price_changes\":[{\"asset_id\":\"107011546575057755426871645700605806081353395825571114128343592072429146374928\", \"price\":\"0.52\", \"size\":\"201.06\", \"side\":\"BUY\", \"hash\":\"c1d6ab7d99260d38b9169807cc4e639616082144\", \"best_bid\":\"0.54\", \"best_ask\":\"0.55\"}, {\"asset_id\":\"56108879726720646120583724001239294777304794469144970684362785767667828318889\", \"price\":\"0.48\", \"size\":\"201.06\", \"side\":\"SELL\", \"hash\":\"87b932952a016fe070c00a7995b7386ffb37b580\", \"best_bid\":\"0.45\", \"best_ask\":\"0.46\"}], \"timestamp\":\"1781254837220\", \"event_type\":\"price_change\"}","ts_local_ms":1781254837815}
{"dir":"in","text":"{\"market\":\"0x9c535590faae21bf76fed844aa47fc3c5c82253ef38bd545bf12c93470502685\", \"price_changes\":[{\"asset_id\":\"107011546575057755426871645700605806081353395825571114128343592072429146374928\", \"price\":\"0.53\", \"size\":\"167\", \"side\":\"BUY\", \"hash\":\"c1d6ab7d99260d38b9169807cc4e639616082144\", \"best_bid\":\"0.54\", \"best_ask\":\"0.55\"}, {\"asset_id\":\"56108879726720646120583724001239294777304794469144970684362785767667828318889\", \"price\":\"0.47\", \"size\":\"167\", \"side\":\"SELL\", \"hash\":\"87b932952a016fe070c00a7995b7386ffb37b580\", \"best_bid\":\"0.45\", \"best_ask\":\"0.46\"}], \"timestamp\":\"1781254837220\", \"event_type\":\"price_change\"}","ts_local_ms":1781254837815}
{"dir":"in","text":"{\"market\":\"0x9c535590faae21bf76fed844aa47fc3c5c82253ef38bd545bf12c93470502685\", \"price_changes\":[{\"asset_id\":\"107011546575057755426871645700605806081353395825571114128343592072429146374928\", \"price\":\"0.52\", \"size\":\"226.06\", \"side\":\"BUY\", \"hash\":\"4795f4707485d4cdf472182637b543c3fb5b1332\", \"best_bid\":\"0.54\", \"best_ask\":\"0.55\"}, {\"asset_id\":\"56108879726720646120583724001239294777304794469144970684362785767667828318889\", \"price\":\"0.48\", \"size\":\"226.06\", \"side\":\"SELL\", \"hash\":\"defae8064ee8781084ff1afa9f245fb57e934f1d\", \"best_bid\":\"0.45\", \"best_ask\":\"0.46\"}], \"timestamp\":\"1781254837222\", \"event_type\":\"price_change\"}","ts_local_ms":1781254837815}
{"dir":"in","text":"{\"market\":\"0x9c535590faae21bf76fed844aa47fc3c5c82253ef38bd545bf12c93470502685\", \"price_changes\":[{\"asset_id\":\"107011546575057755426871645700605806081353395825571114128343592072429146374928\", \"price\":\"0.01\", \"size\":\"55006.6\", \"side\":\"BUY\", \"hash\":\"7a12454f52c0e4bb7fa67746d02fe644d3521f97\", \"best_bid\":\"0.54\", \"best_ask\":\"0.55\"}, {\"asset_id\":\"56108879726720646120583724001239294777304794469144970684362785767667828318889\", \"price\":\"0.99\", \"size\":\"55006.6\", \"side\":\"SELL\", \"hash\":\"c1c4b1136e21f1df8db323ed8a8427c420ccf469\", \"best_bid\":\"0.45\", \"best_ask\":\"0.46\"}], \"timestamp\":\"1781254837223\", \"event_type\":\"price_change\"}","ts_local_ms":1781254837815}
{"dir":"in","text":"{\"market\":\"0x9c535590faae21bf76fed844aa47fc3c5c82253ef38bd545bf12c93470502685\", \"price_changes\":[{\"asset_id\":\"107011546575057755426871645700605806081353395825571114128343592072429146374928\", \"price\":\"0.54\", \"size\":\"201.6\", \"side\":\"BUY\", \"hash\":\"75fbd7557cf3d66ec194bf7bc94ad61f7bb0cbb5\", \"best_bid\":\"0.54\", \"best_ask\":\"0.55\"}, {\"asset_id\":\"56108879726720646120583724001239294777304794469144970684362785767667828318889\", \"price\":\"0.46\", \"size\":\"201.6\", \"side\":\"SELL\", \"hash\":\"9ccb41932c202fbf50bd94e91f80dfb5c9c2506f\", \"best_bid\":\"0.45\", \"best_ask\":\"0.46\"}], \"timestamp\":\"1781254837223\", \"event_type\":\"price_change\"}","ts_local_ms":1781254837815}
{"dir":"in","text":"{\"market\":\"0x9c535590faae21bf76fed844aa47fc3c5c82253ef38bd545bf12c93470502685\", \"price_changes\":[{\"asset_id\":\"107011546575057755426871645700605806081353395825571114128343592072429146374928\", \"price\":\"0.52\", \"size\":\"220.79\", \"side\":\"BUY\", \"hash\":\"f12c46ab953f35fd26dc2b2e5bfa9139211e30d5\", \"best_bid\":\"0.54\", \"best_ask\":\"0.55\"}, {\"asset_id\":\"56108879726720646120583724001239294777304794469144970684362785767667828318889\", \"price\":\"0.48\", \"size\":\"220.79\", \"side\":\"SELL\", \"hash\":\"404fc275783a277bc347ce0d99ced3990bac2b9e\", \"best_bid\":\"0.45\", \"best_ask\":\"0.46\"}], \"timestamp\":\"1781254837225\", \"event_type\":\"price_change\"}","ts_local_ms":1781254837815}
{"dir":"in","text":"{\"market\":\"0x9c535590faae21bf76fed844aa47fc3c5c82253ef38bd545bf12c93470502685\", \"price_changes\":[{\"asset_id\":\"56108879726720646120583724001239294777304794469144970684362785767667828318889\", \"price\":\"0.44\", \"size\":\"31.25\", \"side\":\"BUY\", \"hash\":\"301dec64b8adb42cfa91458c48e0388fb5296b35\", \"best_bid\":\"0.45\", \"best_ask\":\"0.46\"}, {\"asset_id\":\"107011546575057755426871645700605806081353395825571114128343592072429146374928\", \"price\":\"0.56\", \"size\":\"31.25\", \"side\":\"SELL\", \"hash\":\"27bc2871a6f6b45f5c5e5e00f73024b1077aaa79\", \"best_bid\":\"0.54\", \"best_ask\":\"0.55\"}], \"timestamp\":\"1781254837225\", \"event_type\":\"price_change\"}","ts_local_ms":1781254837815}
{"dir":"in","text":"{\"market\":\"0x9c535590faae21bf76fed844aa47fc3c5c82253ef38bd545bf12c93470502685\", \"price_changes\":[{\"asset_id\":\"56108879726720646120583724001239294777304794469144970684362785767667828318889\", \"price\":\"0.42\", \"size\":\"188.07\", \"side\":\"BUY\", \"hash\":\"301dec64b8adb42cfa91458c48e0388fb5296b35\", \"best_bid\":\"0.45\", \"best_ask\":\"0.46\"}, {\"asset_id\":\"107011546575057755426871645700605806081353395825571114128343592072429146374928\", \"price\":\"0.58\", \"size\":\"188.07\", \"side\":\"SELL\", \"hash\":\"27bc2871a6f6b45f5c5e5e00f73024b1077aaa79\", \"best_bid\":\"0.54\", \"best_ask\":\"0.55\"}], \"timestamp\":\"1781254837225\", \"event_type\":\"price_change\"}","ts_local_ms":1781254837815}
{"dir":"in","text":"{\"market\":\"0x9c535590faae21bf76fed844aa47fc3c5c82253ef38bd545bf12c93470502685\", \"price_changes\":[{\"asset_id\":\"107011546575057755426871645700605806081353395825571114128343592072429146374928\", \"price\":\"0.54\", \"size\":\"191.6\", \"side\":\"BUY\", \"hash\":\"32910dd51646489dd1c8535770f49ef879bc92b4\", \"best_bid\":\"0.54\", \"best_ask\":\"0.55\"}, {\"asset_id\":\"56108879726720646120583724001239294777304794469144970684362785767667828318889\", \"price\":\"0.46\", \"size\":\"191.6\", \"side\":\"SELL\", \"hash\":\"d072861c2312ba66e5f8bb1faa5403abbcc679b4\", \"best_bid\":\"0.45\", \"best_ask\":\"0.46\"}], \"timestamp\":\"1781254837225\", \"event_type\":\"price_change\"}","ts_local_ms":1781254837815}
{"dir":"in","text":"{\"market\":\"0x9c535590faae21bf76fed844aa47fc3c5c82253ef38bd545bf12c93470502685\", \"price_changes\":[{\"asset_id\":\"107011546575057755426871645700605806081353395825571114128343592072429146374928\", \"price\":\"0.01\", \"size\":\"55001.6\", \"side\":\"BUY\", \"hash\":\"c03925e6193b0fc8773abf7dd0432c07eb628cb6\", \"best_bid\":\"0.54\", \"best_ask\":\"0.55\"}, {\"asset_id\":\"56108879726720646120583724001239294777304794469144970684362785767667828318889\", \"price\":\"0.99\", \"size\":\"55001.6\", \"side\":\"SELL\", \"hash\":\"8cf576e02e393bde17efe97cd65177b692dfe881\", \"best_bid\":\"0.45\", \"best_ask\":\"0.46\"}], \"timestamp\":\"1781254837226\", \"event_type\":\"price_change\"}","ts_local_ms":1781254837816}
{"dir":"in","text":"{\"market\":\"0x9c535590faae21bf76fed844aa47fc3c5c82253ef38bd545bf12c93470502685\", \"price_changes\":[{\"asset_id\":\"56108879726720646120583724001239294777304794469144970684362785767667828318889\", \"price\":\"0.45\", \"size\":\"260.39\", \"side\":\"BUY\", \"hash\":\"ef04903cf5a7af4aad7e6d24141f0a09da746349\", \"best_bid\":\"0.45\", \"best_ask\":\"0.46\"}, {\"asset_id\":\"107011546575057755426871645700605806081353395825571114128343592072429146374928\", \"price\":\"0.55\", \"size\":\"260.39\", \"side\":\"SELL\", \"hash\":\"e254f062c4e2a431fd4b205174c6034507d2df97\", \"best_bid\":\"0.54\", \"best_ask\":\"0.55\"}], \"timestamp\":\"1781254837226\", \"event_type\":\"price_change\"}","ts_local_ms":1781254837816}
