{"dir":"in","text":"{\"market\":\"0x9c535590faae21bf76fed844aa47fc3c5c82253ef38bd545bf12c93470502685\", \"price_changes\":[{\"asset_id\":\"56108879726720646120583724001239294777304794469144970684362785767667828318889\", \"price\":\"0.45\", \"size\":\"254.39\", \"side\":\"BUY\", \"hash\":\"205435e96db04c297b374db7833a314c55dc7095\", \"best_bid\":\"0.45\", \"best_ask\":\"0.46\"}, {\"asset_id\":\"107011546575057755426871645700605806081353395825571114128343592072429146374928\", \"price\":\"0.55\", \"size\":\"254.39\", \"side\":\"SELL\", \"hash\":\"2ee495ed4d48ccf23e86ec38aa860d0cd2b4fc09\", \"best_bid\":\"0.54\", \"best_ask\":\"0.55\"}], \"timestamp\":\"1781254837226\", \"event_type\":\"price_change\"}","ts_local_ms":1781254837816}
{"dir":"in","text":"{\"market\":\"0x9c535590faae21bf76fed844aa47fc3c5c82253ef38bd545bf12c93470502685\", \"price_changes\":[{\"asset_id\":\"107011546575057755426871645700605806081353395825571114128343592072429146374928\", \"price\":\"0.37\", \"size\":\"170.23\", \"side\":\"BUY\", \"hash\":\"b4b68308cc63eabb3709cab1fb8f700d5fb3689e\", \"best_bid\":\"0.54\", \"best_ask\":\"0.55\"}, {\"asset_id\":\"56108879726720646120583724001239294777304794469144970684362785767667828318889\", \"price\":\"0.63\", \"size\":\"170.23\", \"side\":\"SELL\", \"hash\":\"53493939dad625a459c3410674eeaa0fab7bc0e1\", \"best_bid\":\"0.45\", \"best_ask\":\"0.46\"}], \"timestamp\":\"1781254837227\", \"event_type\":\"price_change\"}","ts_local_ms":1781254837816}
{"dir":"in","text":"{\"market\":\"0x9c535590faae21bf76fed844aa47fc3c5c82253ef38bd545bf12c93470502685\", \"price_changes\":[{\"asset_id\":\"56108879726720646120583724001239294777304794469144970684362785767667828318889\", \"price\":\"0.45\", \"size\":\"240.39\", \"side\":\"BUY\", \"hash\":\"b55f81613e9e10107dc79187fa90a90545d4f391\", \"best_bid\":\"0.45\", \"best_ask\":\"0.46\"}, {\"asset_id\":\"107011546575057755426871645700605806081353395825571114128343592072429146374928\", \"price\":\"0.55\", \"size\":\"240.39\", \"side\":\"SELL\", \"hash\":\"ddca62c4a427143c04e07d642818a04e3e41f4d0\", \"best_bid\":\"0.54\", \"best_ask\":\"0.55\"}], \"timestamp\":\"1781254837228\", \"event_type\":\"price_change\"}","ts_local_ms":1781254837816}
{"dir":"in","text":"{\"market\":\"0x9c535590faae21bf76fed844aa47fc3c5c82253ef38bd545bf12c93470502685\", \"price_changes\":[{\"asset_id\":\"107011546575057755426871645700605806081353395825571114128343592072429146374928\", \"price\":\"0.5\", \"size\":\"453.08\", \"side\":\"BUY\", \"hash\":\"65bcbf1fe87c8bb0111db6848e8e925eed059f21\", \"best_bid\":\"0.54\", \"best_ask\":\"0.55\"}, {\"asset_id\":\"56108879726720646120583724001239294777304794469144970684362785767667828318889\", \"price\":\"0.5\", \"size\":\"453.08\", \"side\":\"SELL\", \"hash\":\"d3be101122aea7974561629280b426f0af824b07\", \"best_bid\":\"0.45\", \"best_ask\":\"0.46\"}], \"timestamp\":\"1781254837229\", \"event_type\":\"price_change\"}","ts_local_ms":1781254837816}
{"dir":"in","text":"{\"market\":\"0x9c535590faae21bf76fed844aa47fc3c5c82253ef38bd545bf12c93470502685\", \"price_changes\":[{\"asset_id\":\"56108879726720646120583724001239294777304794469144970684362785767667828318889\", \"price\":\"0.45\", \"size\":\"247.39\", \"side\":\"BUY\", \"hash\":\"35c4dac5dc018a217951671acad279d7f0466ef3\", \"best_bid\":\"0.45\", \"best_ask\":\"0.46\"}, {\"asset_id\":\"107011546575057755426871645700605806081353395825571114128343592072429146374928\", \"price\":\"0.55\", \"size\":\"247.39\", \"side\":\"SELL\", \"hash\":\"e28c373d436c6dcbbd0f33cd2eb01660e5e1305d\", \"best_bid\":\"0.54\", \"best_ask\":\"0.55\"}], \"timestamp\":\"1781254837230\", \"event_type\":\"price_change\"}","ts_local_ms":1781254837816}
{"dir":"in","text":"{\"market\":\"0x9c535590faae21bf76fed844aa47fc3c5c82253ef38bd545bf12c93470502685\", \"price_changes\":[{\"asset_id\":\"56108879726720646120583724001239294777304794469144970684362785767667828318889\", \"price\":\"0.43\", \"size\":\"190.96\", \"side\":\"BUY\", \"hash\":\"6cf2a9db4e529d4a574333bae4c96892620e5ed1\", \"best_bid\":\"0.45\", \"best_ask\":\"0.46\"}, {\"asset_id\":\"107011546575057755426871645700605806081353395825571114128343592072429146374928\", \"price\":\"0.57\", \"size\":\"190.96\", \"side\":\"SELL\", \"hash\":\"bb43dde0eb75503d7351703e779122c1919b058f\", \"best_bid\":\"0.54\", \"best_ask\":\"0.55\"}], \"timestamp\":\"1781254837231\", \"event_type\":\"price_change\"}","ts_local_ms":1781254837816}
{"dir":"in","text":"{\"market\":\"0x9c535590faae21bf76fed844aa47fc3c5c82253ef38bd545bf12c93470502685\", \"price_changes\":[{\"asset_id\":\"56108879726720646120583724001239294777304794469144970684362785767667828318889\", \"price\":\"0.23\", \"size\":\"60.74\", \"side\":\"BUY\", \"hash\":\"63f99c05ab115f5ba8f2ba6018320bdee88b5c9c\", \"best_bid\":\"0.45\", \"best_ask\":\"0.46\"}, {\"asset_id\":\"107011546575057755426871645700605806081353395825571114128343592072429146374928\", \"price\":\"0.77\", \"size\":\"60.74\", \"side\":\"SELL\", \"hash\":\"49d9b0e66b2c56c0529c57b364e1543b95f842cb\", \"best_bid\":\"0.54\", \"best_ask\":\"0.55\"}], \"timestamp\":\"1781254837231\", \"event_type\":\"price_change\"}","ts_local_ms":1781254837816}
{"dir":"in","text":"{\"market\":\"0x9c535590faae21bf76fed844aa47fc3c5c82253ef38bd545bf12c93470502685\", \"price_changes\":[{\"asset_id\":\"56108879726720646120583724001239294777304794469144970684362785767667828318889\", \"price\":\"0.45\", \"size\":\"253.39\", \"side\":\"BUY\", \"hash\":\"aa38e46066e5eb2707142fbf55ef6d7ff1e8e8e9\", \"best_bid\":\"0.45\", \"best_ask\":\"0.46\"}, {\"asset_id\":\"107011546575057755426871645700605806081353395825571114128343592072429146374928\", \"price\":\"0.55\", \"size\":\"253.39\", \"side\":\"SELL\", \"hash\":\"1fc53fe51bb2e2e681a5a3860a33e688d0d6ae68\", \"best_bid\":\"0.54\", \"best_ask\":\"0.55\"}], \"timestamp\":\"1781254837233\", \"event_type\":\"price_change\"}","ts_local_ms":1781254837816}
{"dir":"in","text":"{\"market\":\"0x9c535590faae21bf76fed844aa47fc3c5c82253ef38bd545bf12c93470502685\", \"price_changes\":[{\"asset_id\":\"107011546575057755426871645700605806081353395825571114128343592072429146374928\", \"price\":\"0.48\", \"size\":\"1057.68\", \"side\":\"BUY\", \"hash\":\"09ad37f11153714fb826a39605891404af4491ec\", \"best_bid\":\"0.54\", \"best_ask\":\"0.55\"}, {\"asset_id\":\"56108879726720646120583724001239294777304794469144970684362785767667828318889\", \"price\":\"0.52\", \"size\":\"1057.68\", \"side\":\"SELL\", \"hash\":\"3e86722d2dc512c86cb6f26da711901624986421\", \"best_bid\":\"0.45\", \"best_ask\":\"0.46\"}], \"timestamp\":\"1781254837234\", \"event_type\":\"price_change\"}","ts_local_ms":1781254837816}
{"dir":"in","text":"{\"market\":\"0x9c535590faae21bf76fed844aa47fc3c5c82253ef38bd545bf12c93470502685\", \"price_changes\":[{\"asset_id\":\"107011546575057755426871645700605806081353395825571114128343592072429146374928\", \"price\":\"0.53\", \"size\":\"172.17\", \"side\":\"BUY\", \"hash\":\"53e2721402adcfadf42a2bb4c8c76502f9d22158\", \"best_bid\":\"0.54\", \"best_ask\":\"0.55\"}, {\"asset_id\":\"56108879726720646120583724001239294777304794469144970684362785767667828318889\", \"price\":\"0.47\", \"size\":\"172.17\", \"side\":\"SELL\", \"hash\":\"ce81e656d74a49d8fe55d6ae3b56291dbfa00692\", \"best_bid\":\"0.45\", \"best_ask\":\"0.46\"}], \"timestamp\":\"1781254837235\", \"event_type\":\"price_change\"}","ts_local_ms":1781254837816}
{"dir":"in","text":"{\"market\":\"0x9c535590faae21bf76fed844aa47fc3c5c82253ef38bd545bf12c93470502685\", \"price_changes\":[{\"asset_id\":\"107011546575057755426871645700605806081353395825571114128343592072429146374928\", \"price\":\"0.52\", \"size\":\"225.79\", \"side\":\"BUY\", \"hash\":\"64474ffb52a5bdcf95c43efd88509a40f4c2f568\", \"best_bid\":\"0.54\", \"best_ask\":\"0.55\"}, {\"asset_id\":\"56108879726720646120583724001239294777304794469144970684362785767667828318889\", \"price\":\"0.48\", \"size\":\"225.79\", \"side\":\"SELL\", \"hash\":\"5447eb7bfff0cf40305614a82d06840a915b1266\", \"best_bid\":\"0.45\", \"best_ask\":\"0.46\"}], \"timestamp\":\"1781254837236\", \"event_type\":\"price_change\"}","ts_local_ms":1781254837816}
{"dir":"in","text":"{\"market\":\"0x9c535590faae21bf76fed844aa47fc3c5c82253ef38bd545bf12c93470502685\", \"price_changes\":[{\"asset_id\":\"56108879726720646120583724001239294777304794469144970684362785767667828318889\", \"price\":\"0.34\", \"size\":\"127\", \"side\":\"BUY\", \"hash\":\"fe4d5b6d1d03a6a6c713beeac0bb4ec362505773\", \"best_bid\":\"0.45\", \"best_ask\":\"0.46\"}, {\"asset_id\":\"107011546575057755426871645700605806081353395825571114128343592072429146374928\", \"price\":\"0.66\", \"size\":\"127\", \"side\":\"SELL\", \"hash\":\"891f134a845e9bfbe55687e3703aafbad8055a96\", \"best_bid\":\"0.54\", \"best_ask\":\"0.55\"}], \"timestamp\":\"1781254837236\", \"event_type\":\"price_change\"}","ts_local_ms":1781254837816}
{"dir":"in","text":"{\"market\":\"0x9c535590faae21bf76fed844aa47fc3c5c82253ef38bd545bf12c93470502685\", \"price_changes\":[{\"asset_id\":\"107011546575057755426871645700605806081353395825571114128343592072429146374928\", \"price\":\"0.54\", \"size\":\"186.6\", \"side\":\"BUY\", \"hash\":\"29467d9d5990f07dc4cd4ccaae2d79d479903981\", \"best_bid\":\"0.54\", \"best_ask\":\"0.55\"}, {\"asset_id\":\"56108879726720646120583724001239294777304794469144970684362785767667828318889\", \"price\":\"0.46\", \"size\":\"186.6\", \"side\":\"SELL\", \"hash\":\"2e11be97abc6d28d3d89d177c0664e47ec266edf\", \"best_bid\":\"0.45\", \"best_ask\":\"0.46\"}], \"timestamp\":\"1781254837236\", \"event_type\":\"price_change\"}","ts_local_ms":1781254837816}
{"dir":"in","text":"{\"market\":\"0x9c535590faae21bf76fed844aa47fc3c5c82253ef38bd545bf12c93470502685\", \"price_changes\":[{\"asset_id\":\"107011546575057755426871645700605806081353395825571114128343592072429146374928\", \"price\":\"0.54\", \"size\":\"234.74\", \"side\":\"BUY\", \"hash\":\"0eb3dced4494e7806167edb8da25fbcd3967dabd\", \"best_bid\":\"0.54\", \"best_ask\":\"0.55\"}, {\"asset_id\":\"56108879726720646120583724001239294777304794469144970684362785767667828318889\", \"price\":\"0.46\", \"size\":\"234.74\", \"side\":\"SELL\", \"hash\":\"c6d4160b220ef586d4154507f7c15875cd5a6c04\", \"best_bid\":\"0.45\", \"best_ask\":\"0.46\"}], \"timestamp\":\"1781254837237\", \"event_type\":\"price_change\"}","ts_local_ms":1781254837816}
{"dir":"in","text":"{\"market\":\"0x9c535590faae21bf76fed844aa47fc3c5c82253ef38bd545bf12c93470502685\", \"price_changes\":[{\"asset_id\":\"56108879726720646120583724001239294777304794469144970684362785767667828318889\", \"price\":\"0.45\", \"size\":\"259.39\", \"side\":\"BUY\", \"hash\":\"12082b4b6c1a787fad961ab14a6506e7cf70c7e8\", \"best_bid\":\"0.45\", \"best_ask\":\"0.46\"}, {\"asset_id\":\"107011546575057755426871645700605806081353395825571114128343592072429146374928\", \"price\":\"0.55\", \"size\":\"259.39\", \"side\":\"SELL\", \"hash\":\"8fde1dc78b95b5080121cd79afe23d4481a4d295\", \"best_bid\":\"0.54\", \"best_ask\":\"0.55\"}], \"timestamp\":\"1781254837238\", \"event_type\":\"price_change\"}","ts_local_ms":1781254837816}
{"dir":"in","text":"{\"market\":\"0x9c535590faae21bf76fed844aa47fc3c5c82253ef38bd545bf12c93470502685\", \"price_changes\":[{\"asset_id\":\"56108879726720646120583724001239294777304794469144970684362785767667828318889\", \"price\":\"0.41\", \"size\":\"168.61\", \"side\":\"BUY\", \"hash\":\"6af8d58274b2d483cc6bc86367bedc70c008f550\", \"best_bid\":\"0.45\", \"best_ask\":\"0.46\"}, {\"asset_id\":\"107011546575057755426871645700605806081353395825571114128343592072429146374928\", \"price\":\"0.59\", \"size\":\"168.61\", \"side\":\"SELL\", \"hash\":\"776840d87c2b2520c56b885342d2984a15befde5\", \"best_bid\":\"0.54\", \"best_ask\":\"0.55\"}], \"timestamp\":\"1781254837238\", \"event_type\":\"price_change\"}","ts_local_ms":1781254837816}
{"dir":"in","text":"{\"market\":\"0x9c535590faae21bf76fed844aa47fc3c5c82253ef38bd545bf12c93470502685\", \"price_changes\":[{\"asset_id\":\"56108879726720646120583724001239294777304794469144970684362785767667828318889\", \"price\":\"0.45\", \"size\":\"265.39\", \"side\":\"BUY\", \"hash\":\"3e3811cef62afb97823e3026a4ea98bd60c85aee\", \"best_bid\":\"0.45\", \"best_ask\":\"0.46\"}, {\"asset_id\":\"107011546575057755426871645700605806081353395825571114128343592072429146374928\", \"price\":\"0.55\", \"size\":\"265.39\", \"side\":\"SELL\", \"hash\":\"96e505e55e64e129ad8f15fb12c3c1216039bfef\", \"best_bid\":\"0.54\", \"best_ask\":\"0.55\"}], \"timestamp\":\"1781254837239\", \"event_type\":\"price_change\"}","ts_local_ms":1781254837816}
{"dir":"in","text":"{\"market\":\"0x9c535590faae21bf76fed844aa47fc3c5c82253ef38bd545bf12c93470502685\", \"price_changes\":[{\"asset_id\":\"107011546575057755426871645700605806081353395825571114128343592072429146374928\", \"price\":\"0.46\", \"size\":\"352.36\", \"side\":\"BUY\", \"hash\":\"c4e8d2ee74e46911c9a5a2bee935273ec24930df\", \"best_bid\":\"0.54\", \"best_ask\":\"0.55\"}, {\"asset_id\":\"56108879726720646120583724001239294777304794469144970684362785767667828318889\", \"price\":\"0.54\", \"size\":\"352.36\", \"side\":\"SELL\", \"hash\":\"d9658016b62ee386da18045533cb2a3c5b0a6930\", \"best_bid\":\"0.45\", \"best_ask\":\"0.46\"}], \"timestamp\":\"1781254837239\", \"event_type\":\"price_change\"}","ts_local_ms":1781254837816}
{"dir":"in","text":"{\"market\":\"0x9c535590faae21bf76fed844aa47fc3c5c82253ef38bd545bf12c93470502685\", \"price_changes\":[{\"asset_id\":\"56108879726720646120583724001239294777304794469144970684362785767667828318889\", \"price\":\"0.45\", \"size\":\"259.39\", \"side\":\"BUY\", \"hash\":\"5be6497f9e7c3cff26113b64475ae7ba03b90c8d\", \"best_bid\":\"0.45\", \"best_ask\":\"0.46\"}, {\"asset_id\":\"107011546575057755426871645700605806081353395825571114128343592072429146374928\", \"price\":\"0.55\", \"size\":\"259.39\", \"side\":\"SELL\", \"hash\":\"dad5e6c469e94f37247d82735640316764668a0e\", \"best_bid\":\"0.54\", \"best_ask\":\"0.55\"}], \"timestamp\":\"1781254837240\", \"event_type\":\"price_change\"}","ts_local_ms":1781254837816}
{"dir":"in","text":"{\"market\":\"0x9c535590faae21bf76fed844aa47fc3c5c82253ef38bd545bf12c93470502685\", \"price_changes\":[{\"asset_id\":\"56108879726720646120583724001239294777304794469144970684362785767667828318889\", \"price\":\"0.45\", \"size\":\"276.39\", \"side\":\"BUY\", \"hash\":\"375011162df5e5683431c7cc5303e88c89cf8eed\", \"best_bid\":\"0.45\", \"best_ask\":\"0.46\"}, {\"asset_id\":\"107011546575057755426871645700605806081353395825571114128343592072429146374928\", \"price\":\"0.55\", \"size\":\"276.39\", \"side\":\"SELL\", \"hash\":\"286a255dfc7f8ddd6701f0ace40a6ae26ddd48c7\", \"best_bid\":\"0.54\", \"best_ask\":\"0.55\"}], \"timestamp\":\"1781254837240\", \"event_type\":\"price_change\"}","ts_local_ms":1781254837816}
{"dir":"in","text":"{\"market\":\"0x9c535590faae21bf76fed844aa47fc3c5c82253ef38bd545bf12c93470502685\", \"price_changes\":[{\"asset_id\":\"56108879726720646120583724001239294777304794469144970684362785767667828318889\", \"price\":\"0.41\", \"size\":\"143.61\", \"side\":\"BUY\", \"hash\":\"747621baaef15b1a7d6f8140f0a804706089ffa8\", \"best_bid\":\"0.45\", \"best_ask\":\"0.46\"}, {\"asset_id\":\"107011546575057755426871645700605806081353395825571114128343592072429146374928\", \"price\":\"0.59\", \"size\":\"143.61\", \"side\":\"SELL\", \"hash\":\"9380632d35c6ba9104809aa8cd2813cfb46f511f\", \"best_bid\":\"0.54\", \"best_ask\":\"0.55\"}], \"timestamp\":\"1781254837241\", \"event_type\":\"price_change\"}","ts_local_ms":1781254837816}
{"dir":"in","text":"{\"market\":\"0x9c535590faae21bf76fed844aa47fc3c5c82253ef38bd545bf12c93470502685\", \"price_changes\":[{\"asset_id\":\"56108879726720646120583724001239294777304794469144970684362785767667828318889\", \"price\":\"0.45\", \"size\":\"282.39\", \"side\":\"BUY\", \"hash\":\"3b51857286c0e5c6a655c886c693f8ca196f2314\", \"best_bid\":\"0.45\", \"best_ask\":\"0.46\"}, {\"asset_id\":\"107011546575057755426871645700605806081353395825571114128343592072429146374928\", \"price\":\"0.55\", \"size\":\"282.39\", \"side\":\"SELL\", \"hash\":\"f72f63927b8d93c1b4ef0249c7c305e4f3e72898\", \"best_bid\":\"0.54\", \"best_ask\":\"0.55\"}], \"timestamp\":\"1781254837241\", \"event_type\":\"price_change\"}","ts_local_ms":1781254837816}
{"dir":"in","text":"{\"market\":\"0x9c535590faae21bf76fed844aa47fc3c5c82253ef38bd545bf12c93470502685\", \"price_changes\":[{\"asset_id\":\"56108879726720646120583724001239294777304794469144970684362785767667828318889\", \"price\":\"0.45\", \"size\":\"288.39\", \"side\":\"BUY\", \"hash\":\"c6d111a2a3599273cd5c1fae02da9a323999bff2\", \"best_bid\":\"0.45\", \"best_ask\":\"0.46\"}, {\"asset_id\":\"107011546575057755426871645700605806081353395825571114128343592072429146374928\", \"price\":\"0.55\", \"size\":\"288.39\", \"side\":\"SELL\", \"hash\":\"2812f6cb0879c2bd4d13d4272a47d5c5e8b2486d\", \"best_bid\":\"0.54\", \"best_ask\":\"0.55\"}], \"timestamp\":\"1781254837242\", \"event_type\":\"price_change\"}","ts_local_ms":1781254837816}
{"dir":"in","text":"{\"market\":\"0x9c535590faae21bf76fed844aa47fc3c5c82253ef38bd545bf12c93470502685\", \"price_changes\":[{\"asset_id\":\"107011546575057755426871645700605806081353395825571114128343592072429146374928\", \"price\":\"0.23\", \"size\":\"47.3\", \"side\":\"BUY\", \"hash\":\"b1822d17bb00ccb7c2cda439d008e84473c9d9ef\", \"best_bid\":\"0.54\", \"best_ask\":\"0.55\"}, {\"asset_id\":\"56108879726720646120583724001239294777304794469144970684362785767667828318889\", \"price\":\"0.77\", \"size\":\"47.3\", \"side\":\"SELL\", \"hash\":\"daaac8ec18ac15d6178dd535955628d22ac40789\", \"best_bid\":\"0.45\", \"best_ask\":\"0.46\"}], \"timestamp\":\"1781254837243\", \"event_type\":\"price_change\"}","ts_local_ms":1781254837816}
{"dir":"in","text":"{\"market\":\"0x9c535590faae21bf76fed844aa47fc3c5c82253ef38bd545bf12c93470502685\", \"price_changes\":[{\"asset_id\":\"107011546575057755426871645700605806081353395825571114128343592072429146374928\", \"price\":\"0.22\", \"size\":\"77.6\", \"side\":\"BUY\", \"hash\":\"87831d6bef5d5fd04c1826c7a1b42e24256081f7\", \"best_bid\":\"0.54\", \"best_ask\":\"0.55\"}, {\"asset_id\":\"56108879726720646120583724001239294777304794469144970684362785767667828318889\", \"price\":\"0.78\", \"size\":\"77.6\", \"side\":\"SELL\", \"hash\":\"687802ad7c92e25224f66370f1dbb4edac2e593c\", \"best_bid\":\"0.45\", \"best_ask\":\"0.46\"}], \"timestamp\":\"1781254837250\", \"event_type\":\"price_change\"}","ts_local_ms":1781254837817}
{"dir":"in","text":"{\"market\":\"0x9c535590faae21bf76fed844aa47fc3c5c82253ef38bd545bf12c93470502685\", \"price_changes\":[{\"asset_id\":\"107011546575057755426871645700605806081353395825571114128343592072429146374928\", \"price\":\"0.21\", \"size\":\"172.8\", \"side\":\"BUY\", \"hash\":\"451522fbdc3e0669cf01ce24232409a4921d86c2\", \"best_bid\":\"0.54\", \"best_ask\":\"0.55\"}, {\"asset_id\":\"56108879726720646120583724001239294777304794469144970684362785767667828318889\", \"price\":\"0.79\", \"size\":\"172.8\", \"side\":\"SELL\", \"hash\":\"7028921bc76a7c31975a6e4940aab7509bcc513a\", \"best_bid\":\"0.45\", \"best_ask\":\"0.46\"}], \"timestamp\":\"1781254837253\", \"event_type\":\"price_change\"}","ts_local_ms":1781254837817}
{"dir":"in","text":"{\"market\":\"0x9c535590faae21bf76fed844aa47fc3c5c82253ef38bd545bf12c93470502685\", \"price_changes\":[{\"asset_id\":\"56108879726720646120583724001239294777304794469144970684362785767667828318889\", \"price\":\"0.45\", \"size\":\"294.39\", \"side\":\"BUY\", \"hash\":\"887d0af8bc4babaebed829bcc666a18166c9ccda\", \"best_bid\":\"0.45\", \"best_ask\":\"0.46\"}, {\"asset_id\":\"107011546575057755426871645700605806081353395825571114128343592072429146374928\", \"price\":\"0.55\", \"size\":\"294.39\", \"side\":\"SELL\", \"hash\":\"742a24cebab0862f1731d5492b54b51a319c929a\", \"best_bid\":\"0.54\", \"best_ask\":\"0.55\"}], \"timestamp\":\"1781254837259\", \"event_type\":\"price_change\"}","ts_local_ms":1781254837817}
{"dir":"in","text":"{\"market\":\"0x9c535590faae21bf76fed844aa47fc3c5c82253ef38bd545bf12c93470502685\", \"price_changes\":[{\"asset_id\":\"56108879726720646120583724001239294777304794469144970684362785767667828318889\", \"price\":\"0.43\", \"size\":\"165.96\", \"side\":\"BUY\", \"hash\":\"0a3231f4020b894b0e521ad52593dd591dcb9cc8\", \"best_bid\":\"0.45\", \"best_ask\":\"0.46\"}, {\"asset_id\":\"107011546575057755426871645700605806081353395825571114128343592072429146374928\", \"price\":\"0.57\", \"size\":\"165.96\", \"side\":\"SELL\", \"hash\":\"d76a8d2ea113f86eae81806a094515d7f189abd9\", \"best_bid\":\"0.54\", \"best_ask\":\"0.55\"}], \"timestamp\":\"1781254837260\", \"event_type\":\"price_change\"}","ts_local_ms":1781254837817}
{"dir":"in","text":"{\"market\":\"0x9c535590faae21bf76fed844aa47fc3c5c82253ef38bd545bf12c93470502685\", \"price_changes\":[{\"asset_id\":\"56108879726720646120583724001239294777304794469144970684362785767667828318889\", \"price\":\"0.43\", \"size\":\"159.58\", \"side\":\"BUY\", \"hash\":\"89048ab9d30a5949319854d32d148f32f2053d43\", \"best_bid\":\"0.45\", \"best_ask\":\"0.46\"}, {\"asset_id\":\"107011546575057755426871645700605806081353395825571114128343592072429146374928\", \"price\":\"0.57\", \"size\":\"159.58\", \"side\":\"SELL\", \"hash\":\"8020b8f6146558c09d66e22edc2b5001f297470a\", \"best_bid\":\"0.54\", \"best_ask\":\"0.55\"}], \"timestamp\":\"1781254837260\", \"event_type\":\"price_change\"}","ts_local_ms":1781254837817}
{"dir":"in","text":"{\"market\":\"0x9c535590faae21bf76fed844aa47fc3c5c82253ef38bd545bf12c93470502685\", \"price_changes\":[{\"asset_id\":\"56108879726720646120583724001239294777304794469144970684362785767667828318889\", \"price\":\"0.41\", \"size\":\"136.92\", \"side\":\"BUY\", \"hash\":\"89048ab9d30a5949319854d32d148f32f2053d43\", \"best_bid\":\"0.45\", \"best_ask\":\"0.46\"}, {\"asset_id\":\"107011546575057755426871645700605806081353395825571114128343592072429146374928\", \"price\":\"0.59\", \"size\":\"136.92\", \"side\":\"SELL\", \"hash\":\"8020b8f6146558c09d66e22edc2b5001f297470a\", \"best_bid\":\"0.54\", \"best_ask\":\"0.55\"}], \"timestamp\":\"1781254837260\", \"event_type\":\"price_change\"}","ts_local_ms":1781254837817}
{"dir":"in","text":"{\"market\":\"0x9c535590faae21bf76fed844aa47fc3c5c82253ef38bd545bf12c93470502685\", \"price_changes\":[{\"asset_id\":\"107011546575057755426871645700605806081353395825571114128343592072429146374928\", \"price\":\"0.53\", \"size\":\"177.17\", \"side\":\"BUY\", \"hash\":\"b3b3d09c3437585b90d696d06f4d34bd9dfcc39c\", \"best_bid\":\"0.54\", \"best_ask\":\"0.55\"}, {\"asset_id\":\"56108879726720646120583724001239294777304794469144970684362785767667828318889\", \"price\":\"0.47\", \"size\":\"177.17\", \"side\":\"SELL\", \"hash\":\"cd2faa5c758fadc7e0a0756eb58fe5ae1004f092\", \"best_bid\":\"0.45\", \"best_ask\":\"0.46\"}], \"timestamp\":\"1781254837261\", \"event_type\":\"price_change\"}","ts_local_ms":1781254837817}
{"dir":"in","text":"{\"market\":\"0x9c535590faae21bf76fed844aa47fc3c5c82253ef38bd545bf12c93470502685\", \"price_changes\":[{\"asset_id\":\"56108879726720646120583724001239294777304794469144970684362785767667828318889\", \"price\":\"0.45\", \"size\":\"287.39\", \"side\":\"BUY\", \"hash\":\"9f9e79371a0f487fe528514d88ee52471f52d2e9\", \"best_bid\":\"0.45\", \"best_ask\":\"0.46\"}, {\"asset_id\":\"107011546575057755426871645700605806081353395825571114128343592072429146374928\", \"price\":\"0.55\", \"size\":\"287.39\", \"side\":\"SELL\", \"hash\":\"8268935c9d2c94bba399d36cf74e655606b4c129\", \"best_bid\":\"0.54\", \"best_ask\":\"0.55\"}], \"timestamp\":\"1781254837265\", \"event_type\":\"price_change\"}","ts_local_ms":1781254837817}
{"dir":"in","text":"{\"market\":\"0x9c535590faae21bf76fed844aa47fc3c5c82253ef38bd545bf12c93470502685\", \"price_changes\":[{\"asset_id\":\"56108879726720646120583724001239294777304794469144970684362785767667828318889\", \"price\":\"0.45\", \"size\":\"298.39\", \"side\":\"BUY\", \"hash\":\"3d941ea38992775181388c38b3dfa8fe67fcb4dc\", \"best_bid\":\"0.45\", \"best_ask\":\"0.46\"}, {\"asset_id\":\"107011546575057755426871645700605806081353395825571114128343592072429146374928\", \"price\":\"0.55\", \"size\":\"298.39\", \"side\":\"SELL\", \"hash\":\"b50affd8a1eff624ff0f33988e5a9043be97d7af\", \"best_bid\":\"0.54\", \"best_ask\":\"0.55\"}], \"timestamp\":\"1781254837266\", \"event_type\":\"price_change\"}","ts_local_ms":1781254837817}
{"dir":"in","text":"{\"market\":\"0x9c535590faae21bf76fed844aa47fc3c5c82253ef38bd545bf12c93470502685\", \"price_changes\":[{\"asset_id\":\"56108879726720646120583724001239294777304794469144970684362785767667828318889\", \"price\":\"0.45\", \"size\":\"278.39\", \"side\":\"BUY\", \"hash\":\"fee77829d6a09787bd8c3001991edf1db795b988\", \"best_bid\":\"0.45\", \"best_ask\":\"0.46\"}, {\"asset_id\":\"107011546575057755426871645700605806081353395825571114128343592072429146374928\", \"price\":\"0.55\", \"size\":\"278.39\", \"side\":\"SELL\", \"hash\":\"fb85b9a1ef1df2ae9839d852471e427239fd6373\", \"best_bid\":\"0.54\", \"best_ask\":\"0.55\"}], \"timestamp\":\"1781254837271\", \"event_type\":\"price_change\"}","ts_local_ms":1781254837817}
{"dir":"in","text":"{\"market\":\"0x9c535590faae21bf76fed844aa47fc3c5c82253ef38bd545bf12c93470502685\", \"price_changes\":[{\"asset_id\":\"107011546575057755426871645700605806081353395825571114128343592072429146374928\", \"price\":\"0.04\", \"size\":\"1677.1\", \"side\":\"BUY\", \"hash\":\"0be2cb71c3fa04323b8f45a682498819ea760242\", \"best_bid\":\"0.54\", \"best_ask\":\"0.55\"}, {\"asset_id\":\"56108879726720646120583724001239294777304794469144970684362785767667828318889\", \"price\":\"0.96\", \"size\":\"1677.1\", \"side\":\"SELL\", \"hash\":\"f33ce4396193ab7b858cba3b0cad8a587804f290\", \"best_bid\":\"0.45\", \"best_ask\":\"0.46\"}], \"timestamp\":\"1781254837272\", \"event_type\":\"price_change\"}","ts_local_ms":1781254837817}
{"dir":"in","text":"{\"market\":\"0x9c535590faae21bf76fed844aa47fc3c5c82253ef38bd545bf12c93470502685\", \"price_changes\":[{\"asset_id\":\"56108879726720646120583724001239294777304794469144970684362785767667828318889\", \"price\":\"0.45\", \"size\":\"271.39\", \"side\":\"BUY\", \"hash\":\"426baafbb7f6442940b9eb3301427f324f5f386b\", \"best_bid\":\"0.45\", \"best_ask\":\"0.46\"}, {\"asset_id\":\"107011546575057755426871645700605806081353395825571114128343592072429146374928\", \"price\":\"0.55\", \"size\":\"271.39\", \"side\":\"SELL\", \"hash\":\"c2bdb2117d455046ce6301b7431f260bd6774b8b\", \"best_bid\":\"0.54\", \"best_ask\":\"0.55\"}], \"timestamp\":\"1781254837273\", \"event_type\":\"price_change\"}","ts_local_ms":1781254837817}
{"dir":"in","text":"{\"market\":\"0x9c535590faae21bf76fed844aa47fc3c5c82253ef38bd545bf12c93470502685\", \"price_changes\":[{\"asset_id\":\"56108879726720646120583724001239294777304794469144970684362785767667828318889\", \"price\":\"0.45\", \"size\":\"264.39\", \"side\":\"BUY\", \"hash\":\"ae46339b7ee51589527fac504ba4a3250c68a352\", \"best_bid\":\"0.45\", \"best_ask\":\"0.46\"}, {\"asset_id\":\"107011546575057755426871645700605806081353395825571114128343592072429146374928\", \"price\":\"0.55\", \"size\":\"264.39\", \"side\":\"SELL\", \"hash\":\"f94a3871ee6d0f7cfbbac20394e76c82f594ae99\", \"best_bid\":\"0.54\", \"best_ask\":\"0.55\"}], \"timestamp\":\"1781254837273\", \"event_type\":\"price_change\"}","ts_local_ms":1781254837817}
{"dir":"in","text":"{\"market\":\"0x9c535590faae21bf76fed844aa47fc3c5c82253ef38bd545bf12c93470502685\", \"price_changes\":[{\"asset_id\":\"56108879726720646120583724001239294777304794469144970684362785767667828318889\", \"price\":\"0.45\", \"size\":\"258.39\", \"side\":\"BUY\", \"hash\":\"43c37b8dde8f126a5e12a202094a2af3322e68c5\", \"best_bid\":\"0.45\", \"best_ask\":\"0.46\"}, {\"asset_id\":\"107011546575057755426871645700605806081353395825571114128343592072429146374928\", \"price\":\"0.55\", \"size\":\"258.39\", \"side\":\"SELL\", \"hash\":\"af539b6c86eae310e05c0e8d1e5376bedb49fc2f\", \"best_bid\":\"0.54\", \"best_ask\":\"0.55\"}], \"timestamp\":\"1781254837273\", \"event_type\":\"price_change\"}","ts_local_ms":1781254837817}
{"dir":"in","text":"{\"market\":\"0x9c535590faae21bf76fed844aa47fc3c5c82253ef38bd545bf12c93470502685\", \"price_changes\":[{\"asset_id\":\"56108879726720646120583724001239294777304794469144970684362785767667828318889\", \"price\":\"0.45\", \"size\":\"251.39\", \"side\":\"BUY\", \"hash\":\"d25fa650bde5fec95c540471632c7a80831cb2cf\", \"best_bid\":\"0.45\", \"best_ask\":\"0.46\"}, {\"asset_id\":\"107011546575057755426871645700605806081353395825571114128343592072429146374928\", \"price\":\"0.55\", \"size\":\"251.39\", \"side\":\"SELL\", \"hash\":\"f5f117c7d88733ee1e0e3b74802a3a857c6ca8f5\", \"best_bid\":\"0.54\", \"best_ask\":\"0.55\"}], \"timestamp\":\"1781254837274\", \"event_type\":\"price_change\"}","ts_local_ms":1781254837817}
{"dir":"in","text":"{\"market\":\"0x9c535590faae21bf76fed844aa47fc3c5c82253ef38bd545bf12c93470502685\", \"price_changes\":[{\"asset_id\":\"107011546575057755426871645700605806081353395825571114128343592072429146374928\", \"price\":\"0.53\", \"size\":\"182.17\", \"side\":\"BUY\", \"hash\":\"2fec898edea2b68f982297e2469ff53969814bf4\", \"best_bid\":\"0.54\", \"best_ask\":\"0.55\"}, {\"asset_id\":\"56108879726720646120583724001239294777304794469144970684362785767667828318889\", \"price\":\"0.47\", \"size\":\"182.17\", \"side\":\"SELL\", \"hash\":\"8d76e962424dda976fdb86c7d00662f108df3396\", \"best_bid\":\"0.45\", \"best_ask\":\"0.46\"}], \"timestamp\":\"1781254837274\", \"event_type\":\"price_change\"}","ts_local_ms":1781254837817}
{"dir":"in","text":"{\"market\":\"0x9c535590faae21bf76fed844aa47fc3c5c82253ef38bd545bf12c93470502685\", \"price_changes\":[{\"asset_id\":\"107011546575057755426871645700605806081353395825571114128343592072429146374928\", \"price\":\"0.01\", \"size\":\"55007.6\", \"side\":\"BUY\", \"hash\":\"e2b619b9ac752093b6d9d4ab955dd185afeaa769\", \"best_bid\":\"0.54\", \"best_ask\":\"0.55\"}, {\"asset_id\":\"56108879726720646120583724001239294777304794469144970684362785767667828318889\", \"price\":\"0.99\", \"size\":\"55007.6\", \"side\":\"SELL\", \"hash\":\"20850663b98967a8d6974c55cd9efb3a871b54b0\", \"best_bid\":\"0.45\", \"best_ask\":\"0.46\"}], \"timestamp\":\"1781254837279\", \"event_type\":\"price_change\"}","ts_local_ms":1781254837817}
{"dir":"in","text":"{\"market\":\"0x9c535590faae21bf76fed844aa47fc3c5c82253ef38bd545bf12c93470502685\", \"price_changes\":[{\"asset_id\":\"56108879726720646120583724001239294777304794469144970684362785767667828318889\", \"price\":\"0.41\", \"size\":\"126.92\", \"side\":\"BUY\", \"hash\":\"e72c4062ae99e33987e7d8c9e6b07e5800c3e819\", \"best_bid\":\"0.45\", \"best_ask\":\"0.46\"}, {\"asset_id\":\"107011546575057755426871645700605806081353395825571114128343592072429146374928\", \"price\":\"0.59\", \"size\":\"126.92\", \"side\":\"SELL\", \"hash\":\"78b5444658fe432d9cb8630aed048f06880bd15a\", \"best_bid\":\"0.54\", \"best_ask\":\"0.55\"}], \"timestamp\":\"1781254837282\", \"event_type\":\"price_change\"}","ts_local_ms":1781254837817}
{"dir":"in","text":"{\"market\":\"0x9c535590faae21bf76fed844aa47fc3c5c82253ef38bd545bf12c93470502685\", \"price_changes\":[{\"asset_id\":\"56108879726720646120583724001239294777304794469144970684362785767667828318889\", \"price\":\"0.45\", \"size\":\"239.39\", \"side\":\"BUY\", \"hash\":\"434702e5495982e1cfcfc4a0e76b14d3744d235e\", \"best_bid\":\"0.45\", \"best_ask\":\"0.46\"}, {\"asset_id\":\"107011546575057755426871645700605806081353395825571114128343592072429146374928\", \"price\":\"0.55\", \"size\":\"239.39\", \"side\":\"SELL\", \"hash\":\"b8acfb77c0ca4895c6963e834e69499002083b3f\", \"best_bid\":\"0.54\", \"best_ask\":\"0.55\"}], \"timestamp\":\"1781254837285\", \"event_type\":\"price_change\"}","ts_local_ms":1781254837817}
{"dir":"in","text":"{\"market\":\"0x9c535590faae21bf76fed844aa47fc3c5c82253ef38bd545bf12c93470502685\", \"price_changes\":[{\"asset_id\":\"56108879726720646120583724001239294777304794469144970684362785767667828318889\", \"price\":\"0.43\", \"size\":\"169.58\", \"side\":\"BUY\", \"hash\":\"3c0838bc8dec2d8f935bb4d8e4fc35216162d3d3\", \"best_bid\":\"0.45\", \"best_ask\":\"0.46\"}, {\"asset_id\":\"107011546575057755426871645700605806081353395825571114128343592072429146374928\", \"price\":\"0.57\", \"size\":\"169.58\", \"side\":\"SELL\", \"hash\":\"6740cf196a2f1ec78bef3ba93843f5081ad83579\", \"best_bid\":\"0.54\", \"best_ask\":\"0.55\"}], \"timestamp\":\"1781254837286\", \"event_type\":\"price_change\"}","ts_local_ms":1781254837817}
{"dir":"in","text":"{\"market\":\"0x9c535590faae21bf76fed844aa47fc3c5c82253ef38bd545bf12c93470502685\", \"price_changes\":[{\"asset_id\":\"56108879726720646120583724001239294777304794469144970684362785767667828318889\", \"price\":\"0.45\", \"size\":\"233.39\", \"side\":\"BUY\", \"hash\":\"1c491fa7678b0c467f07de14469eeb813f3f33cc\", \"best_bid\":\"0.45\", \"best_ask\":\"0.46\"}, {\"asset_id\":\"107011546575057755426871645700605806081353395825571114128343592072429146374928\", \"price\":\"0.55\", \"size\":\"233.39\", \"side\":\"SELL\", \"hash\":\"e76137a87a6b4b1a895b4464fbd121c337c09217\", \"best_bid\":\"0.54\", \"best_ask\":\"0.55\"}], \"timestamp\":\"1781254837288\", \"event_type\":\"price_change\"}","ts_local_ms":1781254837817}
{"dir":"in","text":"{\"market\":\"0x9c535590faae21bf76fed844aa47fc3c5c82253ef38bd545bf12c93470502685\", \"price_changes\":[{\"asset_id\":\"56108879726720646120583724001239294777304794469144970684362785767667828318889\", \"price\":\"0.45\", \"size\":\"239.39\", \"side\":\"BUY\", \"hash\":\"c978672759b9248ce8ed33f04eaed0698ad4320f\", \"best_bid\":\"0.45\", \"best_ask\":\"0.46\"}, {\"asset_id\":\"107011546575057755426871645700605806081353395825571114128343592072429146374928\", \"price\":\"0.55\", \"size\":\"239.39\", \"side\":\"SELL\", \"hash\":\"336af06a3696f46cc8e0eefad808d67ac5a479b8\", \"best_bid\":\"0.54\", \"best_ask\":\"0.55\"}], \"timestamp\":\"1781254837289\", \"event_type\":\"price_change\"}","ts_local_ms":1781254837817}
{"dir":"in","text":"{\"market\":\"0x9c535590faae21bf76fed844aa47fc3c5c82253ef38bd545bf12c93470502685\", \"price_changes\":[{\"asset_id\":\"56108879726720646120583724001239294777304794469144970684362785767667828318889\", \"price\":\"0.43\", \"size\":\"194.58\", \"side\":\"BUY\", \"hash\":\"f98e3975374f369ee19bc7835248a0bc9c76ca90\", \"best_bid\":\"0.45\", \"best_ask\":\"0.46\"}, {\"asset_id\":\"107011546575057755426871645700605806081353395825571114128343592072429146374928\", \"price\":\"0.57\", \"size\":\"194.58\", \"side\":\"SELL\", \"hash\":\"ce684caea84140b55d03409bfa836b00ccb1dcdf\", \"best_bid\":\"0.54\", \"best_ask\":\"0.55\"}], \"timestamp\":\"1781254837291\", \"event_type\":\"price_change\"}","ts_local_ms":1781254837818}
{"dir":"in","text":"{\"market\":\"0x9c535590faae21bf76fed844aa47fc3c5c82253ef38bd545bf12c93470502685\", \"price_changes\":[{\"asset_id\":\"56108879726720646120583724001239294777304794469144970684362785767667828318889\", \"price\":\"0.41\", \"size\":\"133.61\", \"side\":\"BUY\", \"hash\":\"2e5573aa612eb7fb28a6bc1fdf5c37b9fea82026\", \"best_bid\":\"0.45\", \"best_ask\":\"0.46\"}, {\"asset_id\":\"107011546575057755426871645700605806081353395825571114128343592072429146374928\", \"price\":\"0.59\", \"size\":\"133.61\", \"side\":\"SELL\", \"hash\":\"a7f95e5664f96e5563b2a3d548191ff944d0c24d\", \"best_bid\":\"0.54\", \"best_ask\":\"0.55\"}], \"timestamp\":\"1781254837293\", \"event_type\":\"price_change\"}","ts_local_ms":1781254837818}
{"dir":"in","text":"{\"market\":\"0x9c535590faae21bf76fed844aa47fc3c5c82253ef38bd545bf12c93470502685\", \"price_changes\":[{\"asset_id\":\"56108879726720646120583724001239294777304794469144970684362785767667828318889\", \"price\":\"0.01\", \"size\":\"56699.15\", \"side\":\"BUY\", \"hash\":\"583a2bcee6bf9ad3439a76aa5ea49177aea30fb5\", \"best_bid\":\"0.45\", \"best_ask\":\"0.46\"}, {\"asset_id\":\"107011546575057755426871645700605806081353395825571114128343592072429146374928\", \"price\":\"0.99\", \"size\":\"56699.15\", \"side\":\"SELL\", \"hash\":\"7de6edd862197ec6967254d85ffe2c127b67782b\", \"best_bid\":\"0.54\", \"best_ask\":\"0.55\"}], \"timestamp\":\"1781254837294\", \"event_type\":\"price_change\"}","ts_local_ms":1781254837818}
{"dir":"in","text":"{\"market\":\"0x9c535590faae21bf76fed844aa47fc3c5c82253ef38bd545bf12c93470502685\", \"price_changes\":[{\"asset_id\":\"56108879726720646120583724001239294777304794469144970684362785767667828318889\", \"price\":\"0.43\", \"size\":\"169.58\", \"side\":\"BUY\", \"hash\":\"7ccda179c975a24788dbe043ed72cdfa70af8a9e\", \"best_bid\":\"0.45\", \"best_ask\":\"0.46\"}, {\"asset_id\":\"107011546575057755426871645700605806081353395825571114128343592072429146374928\", \"price\":\"0.57\", \"size\":\"169.58\", \"side\":\"SELL\", \"hash\":\"da04ba5f71759b548a710acca5ad6f6207f7bd00\", \"best_bid\":\"0.54\", \"best_ask\":\"0.55\"}], \"timestamp\":\"1781254837296\", \"event_type\":\"price_change\"}","ts_local_ms":1781254837818}
{"dir":"in","text":"{\"market\":\"0x9c535590faae21bf76fed844aa47fc3c5c82253ef38bd545bf12c93470502685\", \"price_changes\":[{\"asset_id\":\"56108879726720646120583724001239294777304794469144970684362785767667828318889\", \"price\":\"0.43\", \"size\":\"175.96\", \"side\":\"BUY\", \"hash\":\"84ac5115c657196ff82459b25642782b6c002266\", \"best_bid\":\"0.45\", \"best_ask\":\"0.46\"}, {\"asset_id\":\"107011546575057755426871645700605806081353395825571114128343592072429146374928\", \"price\":\"0.57\", \"size\":\"175.96\", \"side\":\"SELL\", \"hash\":\"88716d77995f0c6f4826bc87cd53bc1b9fe3037c\", \"best_bid\":\"0.54\", \"best_ask\":\"0.55\"}], \"timestamp\":\"1781254837297\", \"event_type\":\"price_change\"}","ts_local_ms":1781254837818}
{"dir":"in","text":"{\"market\":\"0x9c535590faae21bf76fed844aa47fc3c5c82253ef38bd545bf12c93470502685\", \"price_changes\":[{\"asset_id\":\"56108879726720646120583724001239294777304794469144970684362785767667828318889\", \"price\":\"0.45\", \"size\":\"245.39\", \"side\":\"BUY\", \"hash\":\"8d2d0b8ef646f68628266a9bcbccb994adfba9c3\", \"best_bid\":\"0.45\", \"best_ask\":\"0.46\"}, {\"asset_id\":\"107011546575057755426871645700605806081353395825571114128343592072429146374928\", \"price\":\"0.55\", \"size\":\"245.39\", \"side\":\"SELL\", \"hash\":\"debbd952aa1c23acf27756aa6e2b724891fe10c5\", \"best_bid\":\"0.54\", \"best_ask\":\"0.55\"}], \"timestamp\":\"1781254837298\", \"event_type\":\"price_change\"}","ts_local_ms":1781254837818}
{"dir":"in","text":"{\"market\":\"0x9c535590faae21bf76fed844aa47fc3c5c82253ef38bd545bf12c93470502685\", \"price_changes\":[{\"asset_id\":\"56108879726720646120583724001239294777304794469144970684362785767667828318889\", \"price\":\"0.33\", \"size\":\"232\", \"side\":\"BUY\", \"hash\":\"6fdb79192a362f9ef1c1c9ae15d18deb86e00f53\", \"best_bid\":\"0.45\", \"best_ask\":\"0.46\"}, {\"asset_id\":\"107011546575057755426871645700605806081353395825571114128343592072429146374928\", \"price\":\"0.67\", \"size\":\"232\", \"side\":\"SELL\", \"hash\":\"593d0f50821a24275874193022b6f2131ae63227\", \"best_bid\":\"0.54\", \"best_ask\":\"0.55\"}], \"timestamp\":\"1781254837299\", \"event_type\":\"price_change\"}","ts_local_ms":1781254837818}
{"dir":"in","text":"{\"market\":\"0x9c535590faae21bf76fed844aa47fc3c5c82253ef38bd545bf12c93470502685\", \"price_changes\":[{\"asset_id\":\"56108879726720646120583724001239294777304794469144970684362785767667828318889\", \"price\":\"0.33\", \"size\":\"207\", \"side\":\"BUY\", \"hash\":\"178b311973d5983ecb5a1aeac4d97ef472d80b72\", \"best_bid\":\"0.45\", \"best_ask\":\"0.46\"}, {\"asset_id\":\"107011546575057755426871645700605806081353395825571114128343592072429146374928\", \"price\":\"0.67\", \"size\":\"207\", \"side\":\"SELL\", \"hash\":\"63633707e0cb4bd3f5971d9fe66872bd343c2303\", \"best_bid\":\"0.54\", \"best_ask\":\"0.55\"}], \"timestamp\":\"1781254837299\", \"event_type\":\"price_change\"}","ts_local_ms":1781254837818}
{"dir":"in","text":"{\"market\":\"0x9c535590faae21bf76fed844aa47fc3c5c82253ef38bd545bf12c93470502685\", \"price_changes\":[{\"asset_id\":\"56108879726720646120583724001239294777304794469144970684362785767667828318889\", \"price\":\"0.45\", \"size\":\"251.39\", \"side\":\"BUY\", \"hash\":\"95dedc63e478e110258b45cc6c514d5740020138\", \"best_bid\":\"0.45\", \"best_ask\":\"0.46\"}, {\"asset_id\":\"107011546575057755426871645700605806081353395825571114128343592072429146374928\", \"price\":\"0.55\", \"size\":\"251.39\", \"side\":\"SELL\", \"hash\":\"74e89216fe8ebd6e69c6ea2a9d5be9b07cb3362b\", \"best_bid\":\"0.54\", \"best_ask\":\"0.55\"}], \"timestamp\":\"1781254837303\", \"event_type\":\"price_change\"}","ts_local_ms":1781254837818}
{"dir":"in","text":"{\"market\":\"0x9c535590faae21bf76fed844aa47fc3c5c82253ef38bd545bf12c93470502685\", \"price_changes\":[{\"asset_id\":\"56108879726720646120583724001239294777304794469144970684362785767667828318889\", \"price\":\"0.45\", \"size\":\"256.39\", \"side\":\"BUY\", \"hash\":\"7a5db7c055f68cbd18cc26c748578df7f8016a11\", \"best_bid\":\"0.45\", \"best_ask\":\"0.46\"}, {\"asset_id\":\"107011546575057755426871645700605806081353395825571114128343592072429146374928\", \"price\":\"0.55\", \"size\":\"256.39\", \"side\":\"SELL\", \"hash\":\"841cfa71beaa26e3bf16cabc187f84bcfd599969\", \"best_bid\":\"0.54\", \"best_ask\":\"0.55\"}], \"timestamp\":\"1781254837306\", \"event_type\":\"price_change\"}","ts_local_ms":1781254837818}
{"dir":"in","text":"{\"market\":\"0x9c535590faae21bf76fed844aa47fc3c5c82253ef38bd545bf12c93470502685\", \"price_changes\":[{\"asset_id\":\"56108879726720646120583724001239294777304794469144970684362785767667828318889\", \"price\":\"0.45\", \"size\":\"268.39\", \"side\":\"BUY\", \"hash\":\"3e2483f77eeff2f7936bd900f97c04606cd2620e\", \"best_bid\":\"0.45\", \"best_ask\":\"0.46\"}, {\"asset_id\":\"107011546575057755426871645700605806081353395825571114128343592072429146374928\", \"price\":\"0.55\", \"size\":\"268.39\", \"side\":\"SELL\", \"hash\":\"199e51d584c16da9dffa9883b5b63eb11df4b863\", \"best_bid\":\"0.54\", \"best_ask\":\"0.55\"}], \"timestamp\":\"1781254837307\", \"event_type\":\"price_change\"}","ts_local_ms":1781254837818}
{"dir":"in","text":"{\"market\":\"0x9c535590faae21bf76fed844aa47fc3c5c82253ef38bd545bf12c93470502685\", \"price_changes\":[{\"asset_id\":\"56108879726720646120583724001239294777304794469144970684362785767667828318889\", \"price\":\"0.45\", \"size\":\"262.39\", \"side\":\"BUY\", \"hash\":\"52129e7ea540eb9d361b6e0ab3ae21901eaac8b3\", \"best_bid\":\"0.45\", \"best_ask\":\"0.46\"}, {\"asset_id\":\"107011546575057755426871645700605806081353395825571114128343592072429146374928\", \"price\":\"0.55\", \"size\":\"262.39\", \"side\":\"SELL\", \"hash\":\"f9d0c6fc6782eed96281b6acebf60062f4e63637\", \"best_bid\":\"0.54\", \"best_ask\":\"0.55\"}], \"timestamp\":\"1781254837307\", \"event_type\":\"price_change\"}","ts_local_ms":1781254837818}
{"dir":"in","text":"{\"market\":\"0x9c535590faae21bf76fed844aa47fc3c5c82253ef38bd545bf12c93470502685\", \"price_changes\":[{\"asset_id\":\"56108879726720646120583724001239294777304794469144970684362785767667828318889\", \"price\":\"0.45\", \"size\":\"256.39\", \"side\":\"BUY\", \"hash\":\"c721d86be4cb9bc1b193a42b22972f6a425192d2\", \"best_bid\":\"0.45\", \"best_ask\":\"0.46\"}, {\"asset_id\":\"107011546575057755426871645700605806081353395825571114128343592072429146374928\", \"price\":\"0.55\", \"size\":\"256.39\", \"side\":\"SELL\", \"hash\":\"bb00b3772f03747875f84bc077efcccc5d9d916a\", \"best_bid\":\"0.54\", \"best_ask\":\"0.55\"}], \"timestamp\":\"1781254837307\", \"event_type\":\"price_change\"}","ts_local_ms":1781254837818}
{"dir":"in","text":"{\"market\":\"0x9c535590faae21bf76fed844aa47fc3c5c82253ef38bd545bf12c93470502685\", \"price_changes\":[{\"asset_id\":\"56108879726720646120583724001239294777304794469144970684362785767667828318889\", \"price\":\"0.45\", \"size\":\"249.39\", \"side\":\"BUY\", \"hash\":\"abd69cfd02f8bea6258bfd6c0bd3117d433f2825\", \"best_bid\":\"0.45\", \"best_ask\":\"0.46\"}, {\"asset_id\":\"107011546575057755426871645700605806081353395825571114128343592072429146374928\", \"price\":\"0.55\", \"size\":\"249.39\", \"side\":\"SELL\", \"hash\":\"659d59a9a78c8d3a488889b6b4a55a9ef8fbe11c\", \"best_bid\":\"0.54\", \"best_ask\":\"0.55\"}], \"timestamp\":\"1781254837309\", \"event_type\":\"price_change\"}","ts_local_ms":1781254837818}
{"dir":"in","text":"{\"market\":\"0x9c535590faae21bf76fed844aa47fc3c5c82253ef38bd545bf12c93470502685\", \"price_changes\":[{\"asset_id\":\"56108879726720646120583724001239294777304794469144970684362785767667828318889\", \"price\":\"0.45\", \"size\":\"243.39\", \"side\":\"BUY\", \"hash\":\"f0f67612f7feabca978551ffeddafc81069d99bf\", \"best_bid\":\"0.45\", \"best_ask\":\"0.46\"}, {\"asset_id\":\"107011546575057755426871645700605806081353395825571114128343592072429146374928\", \"price\":\"0.55\", \"size\":\"243.39\", \"side\":\"SELL\", \"hash\":\"11394f329859346d4fd2607c74da5eba09b19f07\", \"best_bid\":\"0.54\", \"best_ask\":\"0.55\"}], \"timestamp\":\"1781254837309\", \"event_type\":\"price_change\"}","ts_local_ms":1781254837818}
{"dir":"in","text":"{\"market\":\"0x9c535590faae21bf76fed844aa47fc3c5c82253ef38bd545bf12c93470502685\", \"price_changes\":[{\"asset_id\":\"56108879726720646120583724001239294777304794469144970684362785767667828318889\", \"price\":\"0.45\", \"size\":\"237.39\", \"side\":\"BUY\", \"hash\":\"4c555af9300905a9df6f3cc6fcb16ad1364342dd\", \"best_bid\":\"0.45\", \"best_ask\":\"0.46\"}, {\"asset_id\":\"107011546575057755426871645700605806081353395825571114128343592072429146374928\", \"price\":\"0.55\", \"size\":\"237.39\", \"side\":\"SELL\", \"hash\":\"c4e03b16490db236614ff6f851c373f52708ff4e\", \"best_bid\":\"0.54\", \"best_ask\":\"0.55\"}], \"timestamp\":\"1781254837310\", \"event_type\":\"price_change\"}","ts_local_ms":1781254837818}
{"dir":"in","text":"{\"market\":\"0x9c535590faae21bf76fed844aa47fc3c5c82253ef38bd545bf12c93470502685\", \"price_changes\":[{\"asset_id\":\"107011546575057755426871645700605806081353395825571114128343592072429146374928\", \"price\":\"0.01\", \"size\":\"55001.6\", \"side\":\"BUY\", \"hash\":\"542783432f67993a7f8459e5aeedfca74b0442d9\", \"best_bid\":\"0.54\", \"best_ask\":\"0.55\"}, {\"asset_id\":\"56108879726720646120583724001239294777304794469144970684362785767667828318889\", \"price\":\"0.99\", \"size\":\"55001.6\", \"side\":\"SELL\", \"hash\":\"071eb763c268a7dc2a8bb4aeb7f763e021357c30\", \"best_bid\":\"0.45\", \"best_ask\":\"0.46\"}], \"timestamp\":\"1781254837310\", \"event_type\":\"price_change\"}","ts_local_ms":1781254837818}
{"dir":"in","text":"{\"market\":\"0x9c535590faae21bf76fed844aa47fc3c5c82253ef38bd545bf12c93470502685\", \"price_changes\":[{\"asset_id\":\"56108879726720646120583724001239294777304794469144970684362785767667828318889\", \"price\":\"0.45\", \"size\":\"231.39\", \"side\":\"BUY\", \"hash\":\"6a59490f9db707b0818c286279b981f1186c509b\", \"best_bid\":\"0.45\", \"best_ask\":\"0.46\"}, {\"asset_id\":\"107011546575057755426871645700605806081353395825571114128343592072429146374928\", \"price\":\"0.55\", \"size\":\"231.39\", \"side\":\"SELL\", \"hash\":\"c6ed684773e4d58d81a7930f3edeedaf5d20cbc8\", \"best_bid\":\"0.54\", \"best_ask\":\"0.55\"}], \"timestamp\":\"1781254837315\", \"event_type\":\"price_change\"}","ts_local_ms":1781254837818}
{"dir":"in","text":"{\"market\":\"0x9c535590faae21bf76fed844aa47fc3c5c82253ef38bd545bf12c93470502685\", \"price_changes\":[{\"asset_id\":\"56108879726720646120583724001239294777304794469144970684362785767667828318889\", \"price\":\"0.45\", \"size\":\"237.39\", \"side\":\"BUY\", \"hash\":\"b8bb01025f469268db110fdbb416ed6d2049cafb\", \"best_bid\":\"0.45\", \"best_ask\":\"0.46\"}, {\"asset_id\":\"107011546575057755426871645700605806081353395825571114128343592072429146374928\", \"price\":\"0.55\", \"size\":\"237.39\", \"side\":\"SELL\", \"hash\":\"eca6508eefe159f0f365840de0d06177681812eb\", \"best_bid\":\"0.54\", \"best_ask\":\"0.55\"}], \"timestamp\":\"1781254837316\", \"event_type\":\"price_change\"}","ts_local_ms":1781254837818}
{"dir":"in","text":"{\"market\":\"0x9c535590faae21bf76fed844aa47fc3c5c82253ef38bd545bf12c93470502685\", \"price_changes\":[{\"asset_id\":\"56108879726720646120583724001239294777304794469144970684362785767667828318889\", \"price\":\"0.45\", \"size\":\"220.39\", \"side\":\"BUY\", \"hash\":\"0344cbd141df0f5599626f4aa922fb0f7fbed37d\", \"best_bid\":\"0.45\", \"best_ask\":\"0.46\"}, {\"asset_id\":\"107011546575057755426871645700605806081353395825571114128343592072429146374928\", \"price\":\"0.55\", \"size\":\"220.39\", \"side\":\"SELL\", \"hash\":\"4f330f79cb158ee2459d617304129a5af9b487aa\", \"best_bid\":\"0.54\", \"best_ask\":\"0.55\"}], \"timestamp\":\"1781254837317\", \"event_type\":\"price_change\"}","ts_local_ms":1781254837818}
{"dir":"in","text":"{\"market\":\"0x9c535590faae21bf76fed844aa47fc3c5c82253ef38bd545bf12c93470502685\", \"price_changes\":[{\"asset_id\":\"56108879726720646120583724001239294777304794469144970684362785767667828318889\", \"price\":\"0.45\", \"size\":\"215.37\", \"side\":\"BUY\", \"hash\":\"6ec60533cf214c02fe79fac0410a1ae0a6d51f54\", \"best_bid\":\"0.45\", \"best_ask\":\"0.46\"}, {\"asset_id\":\"107011546575057755426871645700605806081353395825571114128343592072429146374928\", \"price\":\"0.55\", \"size\":\"215.37\", \"side\":\"SELL\", \"hash\":\"da81be7648c31f026248fdaed25c886313be1b35\", \"best_bid\":\"0.54\", \"best_ask\":\"0.55\"}], \"timestamp\":\"1781254837319\", \"event_type\":\"price_change\"}","ts_local_ms":1781254837818}
{"dir":"in","text":"{\"market\":\"0x9c535590faae21bf76fed844aa47fc3c5c82253ef38bd545bf12c93470502685\", \"price_changes\":[{\"asset_id\":\"56108879726720646120583724001239294777304794469144970684362785767667828318889\", \"price\":\"0.45\", \"size\":\"221.37\", \"side\":\"BUY\", \"hash\":\"1fa4b992cb3bc3efc48e76326cb9834fc53b0df9\", \"best_bid\":\"0.45\", \"best_ask\":\"0.46\"}, {\"asset_id\":\"107011546575057755426871645700605806081353395825571114128343592072429146374928\", \"price\":\"0.55\", \"size\":\"221.37\", \"side\":\"SELL\", \"hash\":\"a4d5b5af628acfff919c70e86acbfb6a2f5b1dda\", \"best_bid\":\"0.54\", \"best_ask\":\"0.55\"}], \"timestamp\":\"1781254837320\", \"event_type\":\"price_change\"}","ts_local_ms":1781254837819}
{"dir":"in","text":"{\"market\":\"0x9c535590faae21bf76fed844aa47fc3c5c82253ef38bd545bf12c93470502685\", \"price_changes\":[{\"asset_id\":\"56108879726720646120583724001239294777304794469144970684362785767667828318889\", \"price\":\"0.45\", \"size\":\"231.37\", \"side\":\"BUY\", \"hash\":\"2298467fdb759cad7cab080d6483ae96884ae6f5\", \"best_bid\":\"0.45\", \"best_ask\":\"0.46\"}, {\"asset_id\":\"107011546575057755426871645700605806081353395825571114128343592072429146374928\", \"price\":\"0.55\", \"size\":\"231.37\", \"side\":\"SELL\", \"hash\":\"5cb0eead6c6dbf21b2aaa5f1a6bfbb362e5f17fd\", \"best_bid\":\"0.54\", \"best_ask\":\"0.55\"}], \"timestamp\":\"1781254837321\", \"event_type\":\"price_change\"}","ts_local_ms":1781254837819}
{"dir":"in","text":"{\"market\":\"0x9c535590faae21bf76fed844aa47fc3c5c82253ef38bd545bf12c93470502685\", \"price_changes\":[{\"asset_id\":\"56108879726720646120583724001239294777304794469144970684362785767667828318889\", \"price\":\"0.45\", \"size\":\"225.37\", \"side\":\"BUY\", \"hash\":\"5be0e1ae8fd5ddfe5ed688c499ceae39c7c27904\", \"best_bid\":\"0.45\", \"best_ask\":\"0.46\"}, {\"asset_id\":\"107011546575057755426871645700605806081353395825571114128343592072429146374928\", \"price\":\"0.55\", \"size\":\"225.37\", \"side\":\"SELL\", \"hash\":\"0cac239b6654b2310a3a1f92acfe04523eb511e0\", \"best_bid\":\"0.54\", \"best_ask\":\"0.55\"}], \"timestamp\":\"1781254837323\", \"event_type\":\"price_change\"}","ts_local_ms":1781254837819}
{"dir":"in","text":"{\"market\":\"0x9c535590faae21bf76fed844aa47fc3c5c82253ef38bd545bf12c93470502685\", \"price_changes\":[{\"asset_id\":\"56108879726720646120583724001239294777304794469144970684362785767667828318889\", \"price\":\"0.45\", \"size\":\"230.37\", \"side\":\"BUY\", \"hash\":\"6c8c54f2c666587badb32a4dad59b71752223977\", \"best_bid\":\"0.45\", \"best_ask\":\"0.46\"}, {\"asset_id\":\"107011546575057755426871645700605806081353395825571114128343592072429146374928\", \"price\":\"0.55\", \"size\":\"230.37\", \"side\":\"SELL\", \"hash\":\"b73c2fce4c2c110230087cbe137fcd4060387247\", \"best_bid\":\"0.54\", \"best_ask\":\"0.55\"}], \"timestamp\":\"1781254837327\", \"event_type\":\"price_change\"}","ts_local_ms":1781254837819}
{"dir":"in","text":"{\"market\":\"0x9c535590faae21bf76fed844aa47fc3c5c82253ef38bd545bf12c93470502685\", \"price_changes\":[{\"asset_id\":\"56108879726720646120583724001239294777304794469144970684362785767667828318889\", \"price\":\"0.45\", \"size\":\"224.37\", \"side\":\"BUY\", \"hash\":\"1c1ad4fcd76d70e96aec5db74a660dfb2bd16b65\", \"best_bid\":\"0.45\", \"best_ask\":\"0.46\"}, {\"asset_id\":\"107011546575057755426871645700605806081353395825571114128343592072429146374928\", \"price\":\"0.55\", \"size\":\"224.37\", \"side\":\"SELL\", \"hash\":\"211fbc1c05488d67b91095ae69fa47b86fba7f58\", \"best_bid\":\"0.54\", \"best_ask\":\"0.55\"}], \"timestamp\":\"1781254837327\", \"event_type\":\"price_change\"}","ts_local_ms":1781254837819}
{"dir":"in","text":"{\"market\":\"0x9c535590faae21bf76fed844aa47fc3c5c82253ef38bd545bf12c93470502685\", \"price_changes\":[{\"asset_id\":\"56108879726720646120583724001239294777304794469144970684362785767667828318889\", \"price\":\"0.46\", \"size\":\"239.74\", \"side\":\"SELL\", \"hash\":\"7abf63ec31fd4ab80f3c4257dbaf5e39a26773c4\", \"best_bid\":\"0.45\", \"best_ask\":\"0.46\"}, {\"asset_id\":\"107011546575057755426871645700605806081353395825571114128343592072429146374928\", \"price\":\"0.54\", \"size\":\"239.74\", \"side\":\"BUY\", \"hash\":\"976d07f62316fc8999fb981ec8c20c8b7cc3352c\", \"best_bid\":\"0.54\", \"best_ask\":\"0.55\"}], \"timestamp\":\"1781254837328\", \"event_type\":\"price_change\"}","ts_local_ms":1781254837819}
{"dir":"in","text":"{\"market\":\"0x9c535590faae21bf76fed844aa47fc3c5c82253ef38bd545bf12c93470502685\", \"price_changes\":[{\"asset_id\":\"107011546575057755426871645700605806081353395825571114128343592072429146374928\", \"price\":\"0.01\", \"size\":\"55006.61\", \"side\":\"BUY\", \"hash\":\"675576ff9a08a85745340e1d78f45546ebe3126a\", \"best_bid\":\"0.54\", \"best_ask\":\"0.55\"}, {\"asset_id\":\"56108879726720646120583724001239294777304794469144970684362785767667828318889\", \"price\":\"0.99\", \"size\":\"55006.61\", \"side\":\"SELL\", \"hash\":\"b0ecd02d6f76efc71ea21ea48f3cb112214b2be6\", \"best_bid\":\"0.45\", \"best_ask\":\"0.46\"}], \"timestamp\":\"1781254837329\", \"event_type\":\"price_change\"}","ts_local_ms":1781254837819}
{"dir":"in","text":"{\"market\":\"0x9c535590faae21bf76fed844aa47fc3c5c82253ef38bd545bf12c93470502685\", \"price_changes\":[{\"asset_id\":\"56108879726720646120583724001239294777304794469144970684362785767667828318889\", \"price\":\"0.33\", \"size\":\"232\", \"side\":\"BUY\", \"hash\":\"e7db370fab4c250e6085477bf4ce2a2887e97b00\", \"best_bid\":\"0.45\", \"best_ask\":\"0.46\"}, {\"asset_id\":\"107011546575057755426871645700605806081353395825571114128343592072429146374928\", \"price\":\"0.67\", \"size\":\"232\", \"side\":\"SELL\", \"hash\":\"67f668d36b85893df8de6a7a87e9673aee57e33c\", \"best_bid\":\"0.54\", \"best_ask\":\"0.55\"}], \"timestamp\":\"1781254837331\", \"event_type\":\"price_change\"}","ts_local_ms":1781254837819}
{"dir":"in","text":"{\"market\":\"0x9c535590faae21bf76fed844aa47fc3c5c82253ef38bd545bf12c93470502685\", \"price_changes\":[{\"asset_id\":\"107011546575057755426871645700605806081353395825571114128343592072429146374928\", \"price\":\"0.01\", \"size\":\"55011.61\", \"side\":\"BUY\", \"hash\":\"d856706d9ca9ac734c1a766fc73a7d385d89fdfa\", \"best_bid\":\"0.54\", \"best_ask\":\"0.55\"}, {\"asset_id\":\"56108879726720646120583724001239294777304794469144970684362785767667828318889\", \"price\":\"0.99\", \"size\":\"55011.61\", \"side\":\"SELL\", \"hash\":\"16e6b5c675f96e7d3a62bdeccc47070117dc988a\", \"best_bid\":\"0.45\", \"best_ask\":\"0.46\"}], \"timestamp\":\"1781254837335\", \"event_type\":\"price_change\"}","ts_local_ms":1781254837819}
{"dir":"in","text":"{\"market\":\"0x9c535590faae21bf76fed844aa47fc3c5c82253ef38bd545bf12c93470502685\", \"price_changes\":[{\"asset_id\":\"56108879726720646120583724001239294777304794469144970684362785767667828318889\", \"price\":\"0.45\", \"size\":\"218.55\", \"side\":\"BUY\", \"hash\":\"07943a16e11d676942fdf134a59be17b82014f56\", \"best_bid\":\"0.45\", \"best_ask\":\"0.46\"}, {\"asset_id\":\"107011546575057755426871645700605806081353395825571114128343592072429146374928\", \"price\":\"0.55\", \"size\":\"218.55\", \"side\":\"SELL\", \"hash\":\"a71a0f1efa0f997e103188262a24765c71398705\", \"best_bid\":\"0.54\", \"best_ask\":\"0.55\"}], \"timestamp\":\"1781254837341\", \"event_type\":\"price_change\"}","ts_local_ms":1781254837819}
{"dir":"in","text":"{\"market\":\"0x9c535590faae21bf76fed844aa47fc3c5c82253ef38bd545bf12c93470502685\", \"price_changes\":[{\"asset_id\":\"56108879726720646120583724001239294777304794469144970684362785767667828318889\", \"price\":\"0.45\", \"size\":\"224.55\", \"side\":\"BUY\", \"hash\":\"e16e587fcba246748f820e390a0ab4933450b240\", \"best_bid\":\"0.45\", \"best_ask\":\"0.46\"}, {\"asset_id\":\"107011546575057755426871645700605806081353395825571114128343592072429146374928\", \"price\":\"0.55\", \"size\":\"224.55\", \"side\":\"SELL\", \"hash\":\"b1a99a73482df7a22b94e147b07d5fdcf53d1f2b\", \"best_bid\":\"0.54\", \"best_ask\":\"0.55\"}], \"timestamp\":\"1781254837341\", \"event_type\":\"price_change\"}","ts_local_ms":1781254837819}
{"dir":"in","text":"{\"market\":\"0x9c535590faae21bf76fed844aa47fc3c5c82253ef38bd545bf12c93470502685\", \"price_changes\":[{\"asset_id\":\"56108879726720646120583724001239294777304794469144970684362785767667828318889\", \"price\":\"0.45\", \"size\":\"230.55\", \"side\":\"BUY\", \"hash\":\"8665035cddb71d6e65a56c45db603d758d1f2b00\", \"best_bid\":\"0.45\", \"best_ask\":\"0.46\"}, {\"asset_id\":\"107011546575057755426871645700605806081353395825571114128343592072429146374928\", \"price\":\"0.55\", \"size\":\"230.55\", \"side\":\"SELL\", \"hash\":\"deb9ea57b5d565f0b2e1ee6f23258a2d7ed24bd9\", \"best_bid\":\"0.54\", \"best_ask\":\"0.55\"}], \"timestamp\":\"1781254837342\", \"event_type\":\"price_change\"}","ts_local_ms":1781254837819}
{"dir":"in","text":"{\"market\":\"0x9c535590faae21bf76fed844aa47fc3c5c82253ef38bd545bf12c93470502685\", \"price_changes\":[{\"asset_id\":\"56108879726720646120583724001239294777304794469144970684362785767667828318889\", \"price\":\"0.45\", \"size\":\"236.55\", \"side\":\"BUY\", \"hash\":\"0c6f6926726e70e4200ac7bdfb69e29fd6a03f6f\", \"best_bid\":\"0.45\", \"best_ask\":\"0.46\"}, {\"asset_id\":\"107011546575057755426871645700605806081353395825571114128343592072429146374928\", \"price\":\"0.55\", \"size\":\"236.55\", \"side\":\"SELL\", \"hash\":\"835fbee93e87dc80f1cb4879c9948dbc28c60a49\", \"best_bid\":\"0.54\", \"best_ask\":\"0.55\"}], \"timestamp\":\"1781254837343\", \"event_type\":\"price_change\"}","ts_local_ms":1781254837819}
{"dir":"in","text":"{\"market\":\"0x9c535590faae21bf76fed844aa47fc3c5c82253ef38bd545bf12c93470502685\", \"price_changes\":[{\"asset_id\":\"107011546575057755426871645700605806081353395825571114128343592072429146374928\", \"price\":\"0.54\", \"size\":\"260.52\", \"side\":\"BUY\", \"hash\":\"ffa6267a09cc8c2ddbd2e28d1a7e59f25b524e8c\", \"best_bid\":\"0.54\", \"best_ask\":\"0.55\"}, {\"asset_id\":\"56108879726720646120583724001239294777304794469144970684362785767667828318889\", \"price\":\"0.46\", \"size\":\"260.52\", \"side\":\"SELL\", \"hash\":\"da6dfedb0c18a2099eb8be38dcd4382ae7243e93\", \"best_bid\":\"0.45\", \"best_ask\":\"0.46\"}], \"timestamp\":\"1781254837345\", \"event_type\":\"price_change\"}","ts_local_ms":1781254837819}
{"dir":"in","text":"{\"market\":\"0x9c535590faae21bf76fed844aa47fc3c5c82253ef38bd545bf12c93470502685\", \"price_changes\":[{\"asset_id\":\"56108879726720646120583724001239294777304794469144970684362785767667828318889\", \"price\":\"0.45\", \"size\":\"225.55\", \"side\":\"BUY\", \"hash\":\"4cba72bb26fddd9402b6eb23ab80394e3eb012bb\", \"best_bid\":\"0.45\", \"best_ask\":\"0.46\"}, {\"asset_id\":\"107011546575057755426871645700605806081353395825571114128343592072429146374928\", \"price\":\"0.55\", \"size\":\"225.55\", \"side\":\"SELL\", \"hash\":\"b649fc879da804ceebd1627b5ab9a735a80ef5d4\", \"best_bid\":\"0.54\", \"best_ask\":\"0.55\"}], \"timestamp\":\"1781254837345\", \"event_type\":\"price_change\"}","ts_local_ms":1781254837819}
{"dir":"in","text":"{\"market\":\"0x9c535590faae21bf76fed844aa47fc3c5c82253ef38bd545bf12c93470502685\", \"price_changes\":[{\"asset_id\":\"56108879726720646120583724001239294777304794469144970684362785767667828318889\", \"price\":\"0.45\", \"size\":\"231.55\", \"side\":\"BUY\", \"hash\":\"1d2c6b74a3d48af57b32c4261f2d6405da726739\", \"best_bid\":\"0.45\", \"best_ask\":\"0.46\"}, {\"asset_id\":\"107011546575057755426871645700605806081353395825571114128343592072429146374928\", \"price\":\"0.55\", \"size\":\"231.55\", \"side\":\"SELL\", \"hash\":\"99448e8da778a50c38347bfe67b5a83f478b1825\", \"best_bid\":\"0.54\", \"best_ask\":\"0.55\"}], \"timestamp\":\"1781254837346\", \"event_type\":\"price_change\"}","ts_local_ms":1781254837819}
{"dir":"in","text":"{\"market\":\"0x9c535590faae21bf76fed844aa47fc3c5c82253ef38bd545bf12c93470502685\", \"price_changes\":[{\"asset_id\":\"56108879726720646120583724001239294777304794469144970684362785767667828318889\", \"price\":\"0.45\", \"size\":\"237.55\", \"side\":\"BUY\", \"hash\":\"1daa13485cbb07709c80c7af141322c9eae776cc\", \"best_bid\":\"0.45\", \"best_ask\":\"0.46\"}, {\"asset_id\":\"107011546575057755426871645700605806081353395825571114128343592072429146374928\", \"price\":\"0.55\", \"size\":\"237.55\", \"side\":\"SELL\", \"hash\":\"46a01cae2f63818f2065694a0fb5a3798e2fc48f\", \"best_bid\":\"0.54\", \"best_ask\":\"0.55\"}], \"timestamp\":\"1781254837354\", \"event_type\":\"price_change\"}","ts_local_ms":1781254837819}
{"dir":"in","text":"{\"market\":\"0x9c535590faae21bf76fed844aa47fc3c5c82253ef38bd545bf12c93470502685\", \"price_changes\":[{\"asset_id\":\"107011546575057755426871645700605806081353395825571114128343592072429146374928\", \"price\":\"0.54\", \"size\":\"273.52\", \"side\":\"BUY\", \"hash\":\"3c3f044bf6ff63a0e8ec5323cb6663fcad905539\", \"best_bid\":\"0.54\", \"best_ask\":\"0.55\"}, {\"asset_id\":\"56108879726720646120583724001239294777304794469144970684362785767667828318889\", \"price\":\"0.46\", \"size\":\"273.52\", \"side\":\"SELL\", \"hash\":\"1f5c965486dac33f653ee7923aa1d2502a19fd51\", \"best_bid\":\"0.45\", \"best_ask\":\"0.46\"}], \"timestamp\":\"1781254837355\", \"event_type\":\"price_change\"}","ts_local_ms":1781254837819}
{"dir":"in","text":"{\"market\":\"0x9c535590faae21bf76fed844aa47fc3c5c82253ef38bd545bf12c93470502685\", \"price_changes\":[{\"asset_id\":\"107011546575057755426871645700605806081353395825571114128343592072429146374928\", \"price\":\"0.01\", \"size\":\"55006.6\", \"side\":\"BUY\", \"hash\":\"cdecfaf88997de5a7b0283316fbab690a5a32860\", \"best_bid\":\"0.54\", \"best_ask\":\"0.55\"}, {\"asset_id\":\"56108879726720646120583724001239294777304794469144970684362785767667828318889\", \"price\":\"0.99\", \"size\":\"55006.6\", \"side\":\"SELL\", \"hash\":\"5c606791586ee411899dce5f9d95294ba3e5402e\", \"best_bid\":\"0.45\", \"best_ask\":\"0.46\"}], \"timestamp\":\"1781254837356\", \"event_type\":\"price_change\"}","ts_local_ms":1781254837819}
{"dir":"in","text":"{\"market\":\"0x9c535590faae21bf76fed844aa47fc3c5c82253ef38bd545bf12c93470502685\", \"price_changes\":[{\"asset_id\":\"56108879726720646120583724001239294777304794469144970684362785767667828318889\", \"price\":\"0.39\", \"size\":\"403.15\", \"side\":\"BUY\", \"hash\":\"8ed6815b266884caad13532703519ac90b75207e\", \"best_bid\":\"0.45\", \"best_ask\":\"0.46\"}, {\"asset_id\":\"107011546575057755426871645700605806081353395825571114128343592072429146374928\", \"price\":\"0.61\", \"size\":\"403.15\", \"side\":\"SELL\", \"hash\":\"8c001a201a2bd66821dc9631806b25b0e1a295d1\", \"best_bid\":\"0.54\", \"best_ask\":\"0.55\"}], \"timestamp\":\"1781254837356\", \"event_type\":\"price_change\"}","ts_local_ms":1781254837819}
{"dir":"in","text":"{\"market\":\"0x9c535590faae21bf76fed844aa47fc3c5c82253ef38bd545bf12c93470502685\", \"price_changes\":[{\"asset_id\":\"56108879726720646120583724001239294777304794469144970684362785767667828318889\", \"price\":\"0.45\", \"size\":\"243.55\", \"side\":\"BUY\", \"hash\":\"153b87403297d21b5c557b84d2165237777ad0f8\", \"best_bid\":\"0.45\", \"best_ask\":\"0.46\"}, {\"asset_id\":\"107011546575057755426871645700605806081353395825571114128343592072429146374928\", \"price\":\"0.55\", \"size\":\"243.55\", \"side\":\"SELL\", \"hash\":\"e6d7f6636925371285de1b36ad1e84856e18127c\", \"best_bid\":\"0.54\", \"best_ask\":\"0.55\"}], \"timestamp\":\"1781254837357\", \"event_type\":\"price_change\"}","ts_local_ms":1781254837819}
{"dir":"in","text":"{\"market\":\"0x9c535590faae21bf76fed844aa47fc3c5c82253ef38bd545bf12c93470502685\", \"price_changes\":[{\"asset_id\":\"107011546575057755426871645700605806081353395825571114128343592072429146374928\", \"price\":\"0.01\", \"size\":\"55001.6\", \"side\":\"BUY\", \"hash\":\"0d8e6f2d081bf5cd9a0240ff15f8c036bcf6ec20\", \"best_bid\":\"0.54\", \"best_ask\":\"0.55\"}, {\"asset_id\":\"56108879726720646120583724001239294777304794469144970684362785767667828318889\", \"price\":\"0.99\", \"size\":\"55001.6\", \"side\":\"SELL\", \"hash\":\"caf4d6f216dc9b09900c8eaabde856a8cbd0f856\", \"best_bid\":\"0.45\", \"best_ask\":\"0.46\"}], \"timestamp\":\"1781254837357\", \"event_type\":\"price_change\"}","ts_local_ms":1781254837819}
{"dir":"in","text":"{\"market\":\"0x9c535590faae21bf76fed844aa47fc3c5c82253ef38bd545bf12c93470502685\", \"price_changes\":[{\"asset_id\":\"56108879726720646120583724001239294777304794469144970684362785767667828318889\", \"price\":\"0.01\", \"size\":\"56799.15\", \"side\":\"BUY\", \"hash\":\"2f7a9b1601c5b28de2827095c5d7b6359d1f6acc\", \"best_bid\":\"0.45\", \"best_ask\":\"0.46\"}, {\"asset_id\":\"107011546575057755426871645700605806081353395825571114128343592072429146374928\", \"price\":\"0.99\", \"size\":\"56799.15\", \"side\":\"SELL\", \"hash\":\"6656a3df15c519668eb298e0f65c20a3a61ff0ad\", \"best_bid\":\"0.54\", \"best_ask\":\"0.55\"}], \"timestamp\":\"1781254837359\", \"event_type\":\"price_change\"}","ts_local_ms":1781254837819}
{"dir":"in","text":"{\"market\":\"0x9c535590faae21bf76fed844aa47fc3c5c82253ef38bd545bf12c93470502685\", \"price_changes\":[{\"asset_id\":\"56108879726720646120583724001239294777304794469144970684362785767667828318889\", \"price\":\"0.37\", \"size\":\"291.94\", \"side\":\"BUY\", \"hash\":\"95f92ad3eebb364ec62cd1d803ef27e5ad06499a\", \"best_bid\":\"0.45\", \"best_ask\":\"0.46\"}, {\"asset_id\":\"107011546575057755426871645700605806081353395825571114128343592072429146374928\", \"price\":\"0.63\", \"size\":\"291.94\", \"side\":\"SELL\", \"hash\":\"7406d195c92c63b4c6ce78e9f980469efa43784a\", \"best_bid\":\"0.54\", \"best_ask\":\"0.55\"}], \"timestamp\":\"1781254837360\", \"event_type\":\"price_change\"}","ts_local_ms":1781254837819}
{"dir":"in","text":"{\"market\":\"0x9c535590faae21bf76fed844aa47fc3c5c82253ef38bd545bf12c93470502685\", \"price_changes\":[{\"asset_id\":\"107011546575057755426871645700605806081353395825571114128343592072429146374928\", \"price\":\"0.54\", \"size\":\"279.52\", \"side\":\"BUY\", \"hash\":\"35d0e6b5b7cac25f23b38b9225f0c649da4b2e4d\", \"best_bid\":\"0.54\", \"best_ask\":\"0.55\"}, {\"asset_id\":\"56108879726720646120583724001239294777304794469144970684362785767667828318889\", \"price\":\"0.46\", \"size\":\"279.52\", \"side\":\"SELL\", \"hash\":\"16628cf9556fd29c903750689dfc001ab94695df\", \"best_bid\":\"0.45\", \"best_ask\":\"0.46\"}], \"timestamp\":\"1781254837361\", \"event_type\":\"price_change\"}","ts_local_ms":1781254837819}
{"dir":"in","text":"{\"market\":\"0x9c535590faae21bf76fed844aa47fc3c5c82253ef38bd545bf12c93470502685\", \"price_changes\":[{\"asset_id\":\"56108879726720646120583724001239294777304794469144970684362785767667828318889\", \"price\":\"0.39\", \"size\":\"339.15\", \"side\":\"BUY\", \"hash\":\"921719d1356d5dd46ccedd059ae6208da4b10c5d\", \"best_bid\":\"0.45\", \"best_ask\":\"0.46\"}, {\"asset_id\":\"107011546575057755426871645700605806081353395825571114128343592072429146374928\", \"price\":\"0.61\", \"size\":\"339.15\", \"side\":\"SELL\", \"hash\":\"5fbe4d5639fa2a223111af33a5e06e9a405da69e\", \"best_bid\":\"0.54\", \"best_ask\":\"0.55\"}], \"timestamp\":\"1781254837364\", \"event_type\":\"price_change\"}","ts_local_ms":1781254837819}
{"dir":"in","text":"{\"market\":\"0x9c535590faae21bf76fed844aa47fc3c5c82253ef38bd545bf12c93470502685\", \"price_changes\":[{\"asset_id\":\"56108879726720646120583724001239294777304794469144970684362785767667828318889\", \"price\":\"0.45\", \"size\":\"248.55\", \"side\":\"BUY\", \"hash\":\"e5f47f1c1605e7d6526e323764a7a509443c27ce\", \"best_bid\":\"0.45\", \"best_ask\":\"0.46\"}, {\"asset_id\":\"107011546575057755426871645700605806081353395825571114128343592072429146374928\", \"price\":\"0.55\", \"size\":\"248.55\", \"side\":\"SELL\", \"hash\":\"e95c99aaf5e1cd29261644357299217e2ba262f9\", \"best_bid\":\"0.54\", \"best_ask\":\"0.55\"}], \"timestamp\":\"1781254837365\", \"event_type\":\"price_change\"}","ts_local_ms":1781254837819}
{"dir":"in","text":"{\"market\":\"0x9c535590faae21bf76fed844aa47fc3c5c82253ef38bd545bf12c93470502685\", \"price_changes\":[{\"asset_id\":\"56108879726720646120583724001239294777304794469144970684362785767667828318889\", \"price\":\"0.25\", \"size\":\"27.9\", \"side\":\"BUY\", \"hash\":\"9bd5b832b2fd766214d92a3a75b15dfbb2d80878\", \"best_bid\":\"0.45\", \"best_ask\":\"0.46\"}, {\"asset_id\":\"107011546575057755426871645700605806081353395825571114128343592072429146374928\", \"price\":\"0.75\", \"size\":\"27.9\", \"side\":\"SELL\", \"hash\":\"b4d2bf51d206702490352c4f42b6a183a7e2506a\", \"best_bid\":\"0.54\", \"best_ask\":\"0.55\"}], \"timestamp\":\"1781254837366\", \"event_type\":\"price_change\"}","ts_local_ms":1781254837819}
{"dir":"in","text":"{\"market\":\"0x9c535590faae21bf76fed844aa47fc3c5c82253ef38bd545bf12c93470502685\", \"price_changes\":[{\"asset_id\":\"107011546575057755426871645700605806081353395825571114128343592072429146374928\", \"price\":\"0.54\", \"size\":\"284.52\", \"side\":\"BUY\", \"hash\":\"0bc4fa77a05f8b266212afcb77d1be30d0f5cc3c\", \"best_bid\":\"0.54\", \"best_ask\":\"0.55\"}, {\"asset_id\":\"56108879726720646120583724001239294777304794469144970684362785767667828318889\", \"price\":\"0.46\", \"size\":\"284.52\", \"side\":\"SELL\", \"hash\":\"287602eaba6829d0fae9bc624c5303e0bc657ef2\", \"best_bid\":\"0.45\", \"best_ask\":\"0.46\"}], \"timestamp\":\"1781254837368\", \"event_type\":\"price_change\"}","ts_local_ms":1781254837820}
{"dir":"in","text":"{\"market\":\"0x9c535590faae21bf76fed844aa47fc3c5c82253ef38bd545bf12c93470502685\", \"price_changes\":[{\"asset_id\":\"107011546575057755426871645700605806081353395825571114128343592072429146374928\", \"price\":\"0.54\", \"size\":\"334.52\", \"side\":\"BUY\", \"hash\":\"619a1c137998945923aae897774bd6f1fe9262fe\", \"best_bid\":\"0.54\", \"best_ask\":\"0.55\"}, {\"asset_id\":\"56108879726720646120583724001239294777304794469144970684362785767667828318889\", \"price\":\"0.46\", \"size\":\"334.52\", \"side\":\"SELL\", \"hash\":\"4d3ff65d27a5b417821beddbc755c1ef4676b6d6\", \"best_bid\":\"0.45\", \"best_ask\":\"0.46\"}], \"timestamp\":\"1781254837371\", \"event_type\":\"price_change\"}","ts_local_ms":1781254837820}
{"dir":"in","text":"{\"market\":\"0x9c535590faae21bf76fed844aa47fc3c5c82253ef38bd545bf12c93470502685\", \"price_changes\":[{\"asset_id\":\"56108879726720646120583724001239294777304794469144970684362785767667828318889\", \"price\":\"0.43\", \"size\":\"205.96\", \"side\":\"BUY\", \"hash\":\"0922d322d06275cdad216fdee5a9e6067c16f558\", \"best_bid\":\"0.45\", \"best_ask\":\"0.46\"}, {\"asset_id\":\"107011546575057755426871645700605806081353395825571114128343592072429146374928\", \"price\":\"0.57\", \"size\":\"205.96\", \"side\":\"SELL\", \"hash\":\"ee8b72a8739de36aceb8e8e78f332671d4d22be1\", \"best_bid\":\"0.54\", \"best_ask\":\"0.55\"}], \"timestamp\":\"1781254837372\", \"event_type\":\"price_change\"}","ts_local_ms":1781254837820}
{"dir":"in","text":"{\"market\":\"0x9c535590faae21bf76fed844aa47fc3c5c82253ef38bd545bf12c93470502685\", \"price_changes\":[{\"asset_id\":\"56108879726720646120583724001239294777304794469144970684362785767667828318889\", \"price\":\"0.45\", \"size\":\"242.55\", \"side\":\"BUY\", \"hash\":\"f341b80bee7f1678963d1a6a57c1888cdcd95ddd\", \"best_bid\":\"0.45\", \"best_ask\":\"0.46\"}, {\"asset_id\":\"107011546575057755426871645700605806081353395825571114128343592072429146374928\", \"price\":\"0.55\", \"size\":\"242.55\", \"side\":\"SELL\", \"hash\":\"813db95a4cbcafb835d8bcddc8d46db3eddc5599\", \"best_bid\":\"0.54\", \"best_ask\":\"0.55\"}], \"timestamp\":\"1781254837374\", \"event_type\":\"price_change\"}","ts_local_ms":1781254837820}
{"dir":"in","text":"{\"market\":\"0x9c535590faae21bf76fed844aa47fc3c5c82253ef38bd545bf12c93470502685\", \"price_changes\":[{\"asset_id\":\"56108879726720646120583724001239294777304794469144970684362785767667828318889\", \"price\":\"0.46\", \"size\":\"384.52\", \"side\":\"SELL\", \"hash\":\"20c89cfff1bfe41ce34e3b04dd69072ce473daca\", \"best_bid\":\"0.45\", \"best_ask\":\"0.46\"}, {\"asset_id\":\"107011546575057755426871645700605806081353395825571114128343592072429146374928\", \"price\":\"0.54\", \"size\":\"384.52\", \"side\":\"BUY\", \"hash\":\"edc2a7a67edd792e432b2a4f62e53cabaccd5270\", \"best_bid\":\"0.54\", \"best_ask\":\"0.55\"}], \"timestamp\":\"1781254837375\", \"event_type\":\"price_change\"}","ts_local_ms":1781254837820}
{"dir":"in","text":"{\"market\":\"0x9c535590faae21bf76fed844aa47fc3c5c82253ef38bd545bf12c93470502685\", \"price_changes\":[{\"asset_id\":\"56108879726720646120583724001239294777304794469144970684362785767667828318889\", \"price\":\"0.45\", \"size\":\"236.55\", \"side\":\"BUY\", \"hash\":\"113a14095948ed8092c4f408dd6a4df8d4f93af5\", \"best_bid\":\"0.45\", \"best_ask\":\"0.46\"}, {\"asset_id\":\"107011546575057755426871645700605806081353395825571114128343592072429146374928\", \"price\":\"0.55\", \"size\":\"236.55\", \"side\":\"SELL\", \"hash\":\"18cbb6155f97a6c3981cda42ee12ac6db81c25d2\", \"best_bid\":\"0.54\", \"best_ask\":\"0.55\"}], \"timestamp\":\"1781254837376\", \"event_type\":\"price_change\"}","ts_local_ms":1781254837820}
{"dir":"in","text":"{\"market\":\"0x9c535590faae21bf76fed844aa47fc3c5c82253ef38bd545bf12c93470502685\", \"price_changes\":[{\"asset_id\":\"56108879726720646120583724001239294777304794469144970684362785767667828318889\", \"price\":\"0.45\", \"size\":\"231.55\", \"side\":\"BUY\", \"hash\":\"6c855701cb079557b240d974238918e01fb58ac0\", \"best_bid\":\"0.45\", \"best_ask\":\"0.46\"}, {\"asset_id\":\"107011546575057755426871645700605806081353395825571114128343592072429146374928\", \"price\":\"0.55\", \"size\":\"231.55\", \"side\":\"SELL\", \"hash\":\"dd96cec952cbf7ae3ef9b3665a8ec7b4b48b2af9\", \"best_bid\":\"0.54\", \"best_ask\":\"0.55\"}], \"timestamp\":\"1781254837378\", \"event_type\":\"price_change\"}","ts_local_ms":1781254837820}
{"dir":"in","text":"{\"market\":\"0x9c535590faae21bf76fed844aa47fc3c5c82253ef38bd545bf12c93470502685\", \"price_changes\":[{\"asset_id\":\"107011546575057755426871645700605806081353395825571114128343592072429146374928\", \"price\":\"0.54\", \"size\":\"394.52\", \"side\":\"BUY\", \"hash\":\"92f0a346fe2b89d7a0a22cb5932f87f65a58b10c\", \"best_bid\":\"0.54\", \"best_ask\":\"0.55\"}, {\"asset_id\":\"56108879726720646120583724001239294777304794469144970684362785767667828318889\", \"price\":\"0.46\", \"size\":\"394.52\", \"side\":\"SELL\", \"hash\":\"ebbf1668a21cced69117deaa8c014cdf3a44d077\", \"best_bid\":\"0.45\", \"best_ask\":\"0.46\"}], \"timestamp\":\"1781254837379\", \"event_type\":\"price_change\"}","ts_local_ms":1781254837820}
{"dir":"in","text":"{\"market\":\"0x9c535590faae21bf76fed844aa47fc3c5c82253ef38bd545bf12c93470502685\", \"price_changes\":[{\"asset_id\":\"56108879726720646120583724001239294777304794469144970684362785767667828318889\", \"price\":\"0.45\", \"size\":\"219.55\", \"side\":\"BUY\", \"hash\":\"620bf9c5f407448b9ea5c325a9399162f1aa9f4b\", \"best_bid\":\"0.45\", \"best_ask\":\"0.46\"}, {\"asset_id\":\"107011546575057755426871645700605806081353395825571114128343592072429146374928\", \"price\":\"0.55\", \"size\":\"219.55\", \"side\":\"SELL\", \"hash\":\"72015f2b218ec9c672f6dc71f64d1b6e82a44ed0\", \"best_bid\":\"0.54\", \"best_ask\":\"0.55\"}], \"timestamp\":\"1781254837382\", \"event_type\":\"price_change\"}","ts_local_ms":1781254837820}
{"dir":"in","text":"{\"market\":\"0x9c535590faae21bf76fed844aa47fc3c5c82253ef38bd545bf12c93470502685\", \"price_changes\":[{\"asset_id\":\"56108879726720646120583724001239294777304794469144970684362785767667828318889\", \"price\":\"0.45\", \"size\":\"213.55\", \"side\":\"BUY\", \"hash\":\"c4b6787b59a7a6b449c75d8968cd126c5b5aef67\", \"best_bid\":\"0.45\", \"best_ask\":\"0.46\"}, {\"asset_id\":\"107011546575057755426871645700605806081353395825571114128343592072429146374928\", \"price\":\"0.55\", \"size\":\"213.55\", \"side\":\"SELL\", \"hash\":\"1b6bb0807daa44e555313b9ad20ff9a9c38aa4c1\", \"best_bid\":\"0.54\", \"best_ask\":\"0.55\"}], \"timestamp\":\"1781254837384\", \"event_type\":\"price_change\"}","ts_local_ms":1781254837820}
{"dir":"in","text":"{\"market\":\"0x9c535590faae21bf76fed844aa47fc3c5c82253ef38bd545bf12c93470502685\", \"price_changes\":[{\"asset_id\":\"107011546575057755426871645700605806081353395825571114128343592072429146374928\", \"price\":\"0.01\", \"size\":\"55007.6\", \"side\":\"BUY\", \"hash\":\"673a595da74ec53f35c87ac49ecc896f02ee2d05\", \"best_bid\":\"0.54\", \"best_ask\":\"0.55\"}, {\"asset_id\":\"56108879726720646120583724001239294777304794469144970684362785767667828318889\", \"price\":\"0.99\", \"size\":\"55007.6\", \"side\":\"SELL\", \"hash\":\"9eb1a29fe08a3fd6f4ab2c67291c994c697b6714\", \"best_bid\":\"0.45\", \"best_ask\":\"0.46\"}], \"timestamp\":\"1781254837385\", \"event_type\":\"price_change\"}","ts_local_ms":1781254837820}
{"dir":"in","text":"{\"market\":\"0x9c535590faae21bf76fed844aa47fc3c5c82253ef38bd545bf12c93470502685\", \"price_changes\":[{\"asset_id\":\"56108879726720646120583724001239294777304794469144970684362785767667828318889\", \"price\":\"0.45\", \"size\":\"207.55\", \"side\":\"BUY\", \"hash\":\"cdd087aff77fc5a6efc161582b6fa2d52bd63c2c\", \"best_bid\":\"0.45\", \"best_ask\":\"0.46\"}, {\"asset_id\":\"107011546575057755426871645700605806081353395825571114128343592072429146374928\", \"price\":\"0.55\", \"size\":\"207.55\", \"side\":\"SELL\", \"hash\":\"82e51f4461da3a4eb911be4c1b4e858c4127f0a4\", \"best_bid\":\"0.54\", \"best_ask\":\"0.55\"}], \"timestamp\":\"1781254837391\", \"event_type\":\"price_change\"}","ts_local_ms":1781254837820}
{"dir":"in","text":"{\"market\":\"0x9c535590faae21bf76fed844aa47fc3c5c82253ef38bd545bf12c93470502685\", \"price_changes\":[{\"asset_id\":\"56108879726720646120583724001239294777304794469144970684362785767667828318889\", \"price\":\"0.45\", \"size\":\"201.55\", \"side\":\"BUY\", \"hash\":\"d9cbd30dbae55970fd87ab8da3c003b53582626b\", \"best_bid\":\"0.45\", \"best_ask\":\"0.46\"}, {\"asset_id\":\"107011546575057755426871645700605806081353395825571114128343592072429146374928\", \"price\":\"0.55\", \"size\":\"201.55\", \"side\":\"SELL\", \"hash\":\"5cb0c7137605f65bc8c7c6e4832d3589a169c3dc\", \"best_bid\":\"0.54\", \"best_ask\":\"0.55\"}], \"timestamp\":\"1781254837393\", \"event_type\":\"price_change\"}","ts_local_ms":1781254837820}
{"dir":"in","text":"{\"market\":\"0x9c535590faae21bf76fed844aa47fc3c5c82253ef38bd545bf12c93470502685\", \"price_changes\":[{\"asset_id\":\"56108879726720646120583724001239294777304794469144970684362785767667828318889\", \"price\":\"0.44\", \"size\":\"23.42\", \"side\":\"BUY\", \"hash\":\"7804be7beeff1f072ac946f0cfa44577694532d8\", \"best_bid\":\"0.45\", \"best_ask\":\"0.46\"}, {\"asset_id\":\"107011546575057755426871645700605806081353395825571114128343592072429146374928\", \"price\":\"0.56\", \"size\":\"23.42\", \"side\":\"SELL\", \"hash\":\"5de02ffbc9feaa39e876ef7fd4996a8bc38fb732\", \"best_bid\":\"0.54\", \"best_ask\":\"0.55\"}], \"timestamp\":\"1781254837398\", \"event_type\":\"price_change\"}","ts_local_ms":1781254837820}
{"dir":"in","text":"{\"market\":\"0x9c535590faae21bf76fed844aa47fc3c5c82253ef38bd545bf12c93470502685\", \"price_changes\":[{\"asset_id\":\"56108879726720646120583724001239294777304794469144970684362785767667828318889\", \"price\":\"0.45\", \"size\":\"191.55\", \"side\":\"BUY\", \"hash\":\"3cd6731cd49ad68825b9cee83ea3205c736aa615\", \"best_bid\":\"0.45\", \"best_ask\":\"0.46\"}, {\"asset_id\":\"107011546575057755426871645700605806081353395825571114128343592072429146374928\", \"price\":\"0.55\", \"size\":\"191.55\", \"side\":\"SELL\", \"hash\":\"5e3698417ed79e9879fff4af337f79aa1c99d45f\", \"best_bid\":\"0.54\", \"best_ask\":\"0.55\"}], \"timestamp\":\"1781254837399\", \"event_type\":\"price_change\"}","ts_local_ms":1781254837820}
{"dir":"in","text":"{\"market\":\"0x9c535590faae21bf76fed844aa47fc3c5c82253ef38bd545bf12c93470502685\", \"price_changes\":[{\"asset_id\":\"56108879726720646120583724001239294777304794469144970684362785767667828318889\", \"price\":\"0.44\", \"size\":\"15\", \"side\":\"BUY\", \"hash\":\"c2203db9f851ffbd17a043d953326bc38840367c\", \"best_bid\":\"0.45\", \"best_ask\":\"0.46\"}, {\"asset_id\":\"107011546575057755426871645700605806081353395825571114128343592072429146374928\", \"price\":\"0.56\", \"size\":\"15\", \"side\":\"SELL\", \"hash\":\"f7a325b142d5b23237c4af875ec4a68ecf01ed8b\", \"best_bid\":\"0.54\", \"best_ask\":\"0.55\"}], \"timestamp\":\"1781254837399\", \"event_type\":\"price_change\"}","ts_local_ms":1781254837820}
{"dir":"in","text":"{\"market\":\"0x9c535590faae21bf76fed844aa47fc3c5c82253ef38bd545bf12c93470502685\", \"price_changes\":[{\"asset_id\":\"107011546575057755426871645700605806081353395825571114128343592072429146374928\", \"price\":\"0.48\", \"size\":\"1067.68\", \"side\":\"BUY\", \"hash\":\"19c17f27346262f719f17b05b04e23479286057f\", \"best_bid\":\"0.54\", \"best_ask\":\"0.55\"}, {\"asset_id\":\"56108879726720646120583724001239294777304794469144970684362785767667828318889\", \"price\":\"0.52\", \"size\":\"1067.68\", \"side\":\"SELL\", \"hash\":\"1c50538b199051073465943939ff5cf24f177cec\", \"best_bid\":\"0.45\", \"best_ask\":\"0.46\"}], \"timestamp\":\"1781254837400\", \"event_type\":\"price_change\"}","ts_local_ms":1781254837820}
{"dir":"in","text":"{\"market\":\"0x9c535590faae21bf76fed844aa47fc3c5c82253ef38bd545bf12c93470502685\", \"price_changes\":[{\"asset_id\":\"56108879726720646120583724001239294777304794469144970684362785767667828318889\", \"price\":\"0.42\", \"size\":\"173.07\", \"side\":\"BUY\", \"hash\":\"071a30ac656617df682f4918b0137be58b415203\", \"best_bid\":\"0.45\", \"best_ask\":\"0.46\"}, {\"asset_id\":\"107011546575057755426871645700605806081353395825571114128343592072429146374928\", \"price\":\"0.58\", \"size\":\"173.07\", \"side\":\"SELL\", \"hash\":\"bdd9a048f7ec01776855a3278f7c569dc4ba32cf\", \"best_bid\":\"0.54\", \"best_ask\":\"0.55\"}], \"timestamp\":\"1781254837401\", \"event_type\":\"price_change\"}","ts_local_ms":1781254837820}
{"dir":"in","text":"{\"market\":\"0x9c535590faae21bf76fed844aa47fc3c5c82253ef38bd545bf12c93470502685\", \"price_changes\":[{\"asset_id\":\"56108879726720646120583724001239294777304794469144970684362785767667828318889\", \"price\":\"0.35\", \"size\":\"296.73\", \"side\":\"BUY\", \"hash\":\"8f45068ec38a7202f13078d98f91cb29fd8daad0\", \"best_bid\":\"0.45\", \"best_ask\":\"0.46\"}, {\"asset_id\":\"107011546575057755426871645700605806081353395825571114128343592072429146374928\", \"price\":\"0.65\", \"size\":\"296.73\", \"side\":\"SELL\", \"hash\":\"1aa02c5ed8cfe5c3d8afa6542ac58491327e5e9c\", \"best_bid\":\"0.54\", \"best_ask\":\"0.55\"}], \"timestamp\":\"1781254837402\", \"event_type\":\"price_change\"}","ts_local_ms":1781254837820}
{"dir":"in","text":"{\"market\":\"0x9c535590faae21bf76fed844aa47fc3c5c82253ef38bd545bf12c93470502685\", \"price_changes\":[{\"asset_id\":\"107011546575057755426871645700605806081353395825571114128343592072429146374928\", \"price\":\"0.54\", \"size\":\"401.52\", \"side\":\"BUY\", \"hash\":\"70731e95bcdf0ccefa59ab62bc45d702ae7ba69e\", \"best_bid\":\"0.54\", \"best_ask\":\"0.55\"}, {\"asset_id\":\"56108879726720646120583724001239294777304794469144970684362785767667828318889\", \"price\":\"0.46\", \"size\":\"401.52\", \"side\":\"SELL\", \"hash\":\"9ed776c317a9bb10c39528ffc0bb54d327b2484a\", \"best_bid\":\"0.45\", \"best_ask\":\"0.46\"}], \"timestamp\":\"1781254837402\", \"event_type\":\"price_change\"}","ts_local_ms":1781254837820}
{"dir":"in","text":"{\"market\":\"0x9c535590faae21bf76fed844aa47fc3c5c82253ef38bd545bf12c93470502685\", \"price_changes\":[{\"asset_id\":\"56108879726720646120583724001239294777304794469144970684362785767667828318889\", \"price\":\"0.39\", \"size\":\"349.15\", \"side\":\"BUY\", \"hash\":\"d51e268d4bbeb206e7c288b11bd2914ec553af5d\", \"best_bid\":\"0.45\", \"best_ask\":\"0.46\"}, {\"asset_id\":\"107011546575057755426871645700605806081353395825571114128343592072429146374928\", \"price\":\"0.61\", \"size\":\"349.15\", \"side\":\"SELL\", \"hash\":\"104974d8889650a826ac0fa7001818433c3f50ee\", \"best_bid\":\"0.54\", \"best_ask\":\"0.55\"}], \"timestamp\":\"1781254837403\", \"event_type\":\"price_change\"}","ts_local_ms":1781254837820}
{"dir":"in","text":"{\"market\":\"0x9c535590faae21bf76fed844aa47fc3c5c82253ef38bd545bf12c93470502685\", \"price_changes\":[{\"asset_id\":\"56108879726720646120583724001239294777304794469144970684362785767667828318889\", \"price\":\"0.45\", \"size\":\"186.55\", \"side\":\"BUY\", \"hash\":\"00d6eadb9f4ef0c438139c907f70e5726477276b\", \"best_bid\":\"0.45\", \"best_ask\":\"0.46\"}, {\"asset_id\":\"107011546575057755426871645700605806081353395825571114128343592072429146374928\", \"price\":\"0.55\", \"size\":\"186.55\", \"side\":\"SELL\", \"hash\":\"23226dac41bfcdd03e02214789f647acfcba5917\", \"best_bid\":\"0.54\", \"best_ask\":\"0.55\"}], \"timestamp\":\"1781254837404\", \"event_type\":\"price_change\"}","ts_local_ms":1781254837820}
{"dir":"in","text":"{\"market\":\"0x9c535590faae21bf76fed844aa47fc3c5c82253ef38bd545bf12c93470502685\", \"price_changes\":[{\"asset_id\":\"107011546575057755426871645700605806081353395825571114128343592072429146374928\", \"price\":\"0.01\", \"size\":\"55001.6\", \"side\":\"BUY\", \"hash\":\"2a5890f06242030fc87c37f30f9ac3a2ead45b3b\", \"best_bid\":\"0.54\", \"best_ask\":\"0.55\"}, {\"asset_id\":\"56108879726720646120583724001239294777304794469144970684362785767667828318889\", \"price\":\"0.99\", \"size\":\"55001.6\", \"side\":\"SELL\", \"hash\":\"9cf8ddd7dd07d80ea6e319c46324c5d6fc18b992\", \"best_bid\":\"0.45\", \"best_ask\":\"0.46\"}], \"timestamp\":\"1781254837404\", \"event_type\":\"price_change\"}","ts_local_ms":1781254837820}
{"dir":"in","text":"{\"market\":\"0x9c535590faae21bf76fed844aa47fc3c5c82253ef38bd545bf12c93470502685\", \"price_changes\":[{\"asset_id\":\"107011546575057755426871645700605806081353395825571114128343592072429146374928\", \"price\":\"0.04\", \"size\":\"1682.1\", \"side\":\"BUY\", \"hash\":\"aa03feb6a668a473866169545a1a79336776ff50\", \"best_bid\":\"0.54\", \"best_ask\":\"0.55\"}, {\"asset_id\":\"56108879726720646120583724001239294777304794469144970684362785767667828318889\", \"price\":\"0.96\", \"size\":\"1682.1\", \"side\":\"SELL\", \"hash\":\"80f3074029b6843ec7d5a6d4336bfb0cd73e2d83\", \"best_bid\":\"0.45\", \"best_ask\":\"0.46\"}], \"timestamp\":\"1781254837408\", \"event_type\":\"price_change\"}","ts_local_ms":1781254837820}
{"dir":"in","text":"{\"market\":\"0x9c535590faae21bf76fed844aa47fc3c5c82253ef38bd545bf12c93470502685\", \"price_changes\":[{\"asset_id\":\"56108879726720646120583724001239294777304794469144970684362785767667828318889\", \"price\":\"0.44\", \"size\":\"30\", \"side\":\"BUY\", \"hash\":\"fb6c94e355b7982ccd966fecce3c951837f647ff\", \"best_bid\":\"0.45\", \"best_ask\":\"0.46\"}, {\"asset_id\":\"107011546575057755426871645700605806081353395825571114128343592072429146374928\", \"price\":\"0.56\", \"size\":\"30\", \"side\":\"SELL\", \"hash\":\"67314698ce55d9c35346aa7b9ec668a4927c4360\", \"best_bid\":\"0.54\", \"best_ask\":\"0.55\"}], \"timestamp\":\"1781254837411\", \"event_type\":\"price_change\"}","ts_local_ms":1781254837820}
{"dir":"in","text":"{\"market\":\"0x9c535590faae21bf76fed844aa47fc3c5c82253ef38bd545bf12c93470502685\", \"price_changes\":[{\"asset_id\":\"56108879726720646120583724001239294777304794469144970684362785767667828318889\", \"price\":\"0.45\", \"size\":\"180.55\", \"side\":\"BUY\", \"hash\":\"3ada04b2b149f558975d252abf01a713f28be4d0\", \"best_bid\":\"0.45\", \"best_ask\":\"0.46\"}, {\"asset_id\":\"107011546575057755426871645700605806081353395825571114128343592072429146374928\", \"price\":\"0.55\", \"size\":\"180.55\", \"side\":\"SELL\", \"hash\":\"eebad4716ee63512f50dd5f21393840969ab45ba\", \"best_bid\":\"0.54\", \"best_ask\":\"0.55\"}], \"timestamp\":\"1781254837411\", \"event_type\":\"price_change\"}","ts_local_ms":1781254837820}
{"dir":"in","text":"{\"market\":\"0x9c535590faae21bf76fed844aa47fc3c5c82253ef38bd545bf12c93470502685\", \"price_changes\":[{\"asset_id\":\"107011546575057755426871645700605806081353395825571114128343592072429146374928\", \"price\":\"0.54\", \"size\":\"408.52\", \"side\":\"BUY\", \"hash\":\"9fa2162051b7ccab0b8970a05860d648b10ace49\", \"best_bid\":\"0.54\", \"best_ask\":\"0.55\"}, {\"asset_id\":\"56108879726720646120583724001239294777304794469144970684362785767667828318889\", \"price\":\"0.46\", \"size\":\"408.52\", \"side\":\"SELL\", \"hash\":\"6ce9aa8c83df737ae7e51ebd3e09940d2053666e\", \"best_bid\":\"0.45\", \"best_ask\":\"0.46\"}], \"timestamp\":\"1781254837412\", \"event_type\":\"price_change\"}","ts_local_ms":1781254837821}
{"dir":"in","text":"{\"market\":\"0x9c535590faae21bf76fed844aa47fc3c5c82253ef38bd545bf12c93470502685\", \"price_changes\":[{\"asset_id\":\"107011546575057755426871645700605806081353395825571114128343592072429146374928\", \"price\":\"0.54\", \"size\":\"425.52\", \"side\":\"BUY\", \"hash\":\"126bedfd4328fdce2b1c6dde1384e627331caba0\", \"best_bid\":\"0.54\", \"best_ask\":\"0.55\"}, {\"asset_id\":\"56108879726720646120583724001239294777304794469144970684362785767667828318889\", \"price\":\"0.46\", \"size\":\"425.52\", \"side\":\"SELL\", \"hash\":\"d28b3cbbf6204ab969b5fd8db13cc754d0a42672\", \"best_bid\":\"0.45\", \"best_ask\":\"0.46\"}], \"timestamp\":\"1781254837413\", \"event_type\":\"price_change\"}","ts_local_ms":1781254837821}
{"dir":"in","text":"{\"market\":\"0x9c535590faae21bf76fed844aa47fc3c5c82253ef38bd545bf12c93470502685\", \"price_changes\":[{\"asset_id\":\"56108879726720646120583724001239294777304794469144970684362785767667828318889\", \"price\":\"0.45\", \"size\":\"174.55\", \"side\":\"BUY\", \"hash\":\"f15db508c6047e0a29ce4a3283df7908902c92b0\", \"best_bid\":\"0.45\", \"best_ask\":\"0.46\"}, {\"asset_id\":\"107011546575057755426871645700605806081353395825571114128343592072429146374928\", \"price\":\"0.55\", \"size\":\"174.55\", \"side\":\"SELL\", \"hash\":\"bce65fbf8959d65a9a704f2d78e507bcd3d32e57\", \"best_bid\":\"0.54\", \"best_ask\":\"0.55\"}], \"timestamp\":\"1781254837417\", \"event_type\":\"price_change\"}","ts_local_ms":1781254837821}
{"dir":"in","text":"{\"market\":\"0x9c535590faae21bf76fed844aa47fc3c5c82253ef38bd545bf12c93470502685\", \"price_changes\":[{\"asset_id\":\"56108879726720646120583724001239294777304794469144970684362785767667828318889\", \"price\":\"0.45\", \"size\":\"168.55\", \"side\":\"BUY\", \"hash\":\"bc53d6bda2ac64fc64a6ad8b97fdcc9ee44aaa32\", \"best_bid\":\"0.45\", \"best_ask\":\"0.46\"}, {\"asset_id\":\"107011546575057755426871645700605806081353395825571114128343592072429146374928\", \"price\":\"0.55\", \"size\":\"168.55\", \"side\":\"SELL\", \"hash\":\"98d324aae5f3a4e35c99ed003405068ecc028c36\", \"best_bid\":\"0.54\", \"best_ask\":\"0.55\"}], \"timestamp\":\"1781254837417\", \"event_type\":\"price_change\"}","ts_local_ms":1781254837821}
{"dir":"in","text":"{\"market\":\"0x9c535590faae21bf76fed844aa47fc3c5c82253ef38bd545bf12c93470502685\", \"price_changes\":[{\"asset_id\":\"56108879726720646120583724001239294777304794469144970684362785767667828318889\", \"price\":\"0.01\", \"size\":\"56804.15\", \"side\":\"BUY\", \"hash\":\"a6ae109e634fbd4dc7f88edb68dde1c7367bda9b\", \"best_bid\":\"0.45\", \"best_ask\":\"0.46\"}, {\"asset_id\":\"107011546575057755426871645700605806081353395825571114128343592072429146374928\", \"price\":\"0.99\", \"size\":\"56804.15\", \"side\":\"SELL\", \"hash\":\"47aac7bda6778f3fd11681be801c054bd63e65ef\", \"best_bid\":\"0.54\", \"best_ask\":\"0.55\"}], \"timestamp\":\"1781254837420\", \"event_type\":\"price_change\"}","ts_local_ms":1781254837821}
{"dir":"in","text":"{\"market\":\"0x9c535590faae21bf76fed844aa47fc3c5c82253ef38bd545bf12c93470502685\", \"price_changes\":[{\"asset_id\":\"107011546575057755426871645700605806081353395825571114128343592072429146374928\", \"price\":\"0.54\", \"size\":\"433.52\", \"side\":\"BUY\", \"hash\":\"3e9fc1bfe97dc10a0ea8a631adf13680aa4a052b\", \"best_bid\":\"0.54\", \"best_ask\":\"0.55\"}, {\"asset_id\":\"56108879726720646120583724001239294777304794469144970684362785767667828318889\", \"price\":\"0.46\", \"size\":\"433.52\", \"side\":\"SELL\", \"hash\":\"92b9907262751ab3b8667594c3d98cf66b9cfd55\", \"best_bid\":\"0.45\", \"best_ask\":\"0.46\"}], \"timestamp\":\"1781254837421\", \"event_type\":\"price_change\"}","ts_local_ms":1781254837821}
{"dir":"in","text":"{\"market\":\"0x9c535590faae21bf76fed844aa47fc3c5c82253ef38bd545bf12c93470502685\", \"price_changes\":[{\"asset_id\":\"107011546575057755426871645700605806081353395825571114128343592072429146374928\", \"price\":\"0.54\", \"size\":\"441.52\", \"side\":\"BUY\", \"hash\":\"44631d36d07be5e63c199506d5e41f2517373eec\", \"best_bid\":\"0.54\", \"best_ask\":\"0.55\"}, {\"asset_id\":\"56108879726720646120583724001239294777304794469144970684362785767667828318889\", \"price\":\"0.46\", \"size\":\"441.52\", \"side\":\"SELL\", \"hash\":\"17ea2b00fd0468892993989f569855fc1cf89541\", \"best_bid\":\"0.45\", \"best_ask\":\"0.46\"}], \"timestamp\":\"1781254837423\", \"event_type\":\"price_change\"}","ts_local_ms":1781254837821}
{"dir":"in","text":"{\"market\":\"0x9c535590faae21bf76fed844aa47fc3c5c82253ef38bd545bf12c93470502685\", \"price_changes\":[{\"asset_id\":\"107011546575057755426871645700605806081353395825571114128343592072429146374928\", \"price\":\"0.45\", \"size\":\"103.77\", \"side\":\"BUY\", \"hash\":\"3bfd04106ad9d716abec257641546eb5a2e63789\", \"best_bid\":\"0.54\", \"best_ask\":\"0.55\"}, {\"asset_id\":\"56108879726720646120583724001239294777304794469144970684362785767667828318889\", \"price\":\"0.55\", \"size\":\"103.77\", \"side\":\"SELL\", \"hash\":\"16a6467e726d7aea6bc7e50d42e056dd9b5fc5e9\", \"best_bid\":\"0.45\", \"best_ask\":\"0.46\"}], \"timestamp\":\"1781254837426\", \"event_type\":\"price_change\"}","ts_local_ms":1781254837821}
{"dir":"in","text":"{\"market\":\"0x9c535590faae21bf76fed844aa47fc3c5c82253ef38bd545bf12c93470502685\", \"price_changes\":[{\"asset_id\":\"56108879726720646120583724001239294777304794469144970684362785767667828318889\", \"price\":\"0.45\", \"size\":\"162.55\", \"side\":\"BUY\", \"hash\":\"7d94c35b912969feefe10a0d7f930fe62b1f812e\", \"best_bid\":\"0.45\", \"best_ask\":\"0.46\"}, {\"asset_id\":\"107011546575057755426871645700605806081353395825571114128343592072429146374928\", \"price\":\"0.55\", \"size\":\"162.55\", \"side\":\"SELL\", \"hash\":\"0a6e2c5707d10e1832677b5f303ff1cb1a0273ff\", \"best_bid\":\"0.54\", \"best_ask\":\"0.55\"}], \"timestamp\":\"1781254837426\", \"event_type\":\"price_change\"}","ts_local_ms":1781254837821}
{"dir":"in","text":"{\"market\":\"0x9c535590faae21bf76fed844aa47fc3c5c82253ef38bd545bf12c93470502685\", \"price_changes\":[{\"asset_id\":\"56108879726720646120583724001239294777304794469144970684362785767667828318889\", \"price\":\"0.01\", \"size\":\"56799.15\", \"side\":\"BUY\", \"hash\":\"05ab6ef3edb26445b59787b19e1928388a8858fd\", \"best_bid\":\"0.45\", \"best_ask\":\"0.46\"}, {\"asset_id\":\"107011546575057755426871645700605806081353395825571114128343592072429146374928\", \"price\":\"0.99\", \"size\":\"56799.15\", \"side\":\"SELL\", \"hash\":\"21704a1539a3d8a72f0d7ddba203dc32d91830c7\", \"best_bid\":\"0.54\", \"best_ask\":\"0.55\"}], \"timestamp\":\"1781254837426\", \"event_type\":\"price_change\"}","ts_local_ms":1781254837821}
{"dir":"in","text":"{\"market\":\"0x9c535590faae21bf76fed844aa47fc3c5c82253ef38bd545bf12c93470502685\", \"price_changes\":[{\"asset_id\":\"107011546575057755426871645700605806081353395825571114128343592072429146374928\", \"price\":\"0.45\", \"size\":\"96\", \"side\":\"BUY\", \"hash\":\"f1eadd88fe6a4fef2e8707a56e2c11c24d2785e6\", \"best_bid\":\"0.54\", \"best_ask\":\"0.55\"}, {\"asset_id\":\"56108879726720646120583724001239294777304794469144970684362785767667828318889\", \"price\":\"0.55\", \"size\":\"96\", \"side\":\"SELL\", \"hash\":\"a0746e76860b262fc67587def8dacc3afa07bd2b\", \"best_bid\":\"0.45\", \"best_ask\":\"0.46\"}], \"timestamp\":\"1781254837427\", \"event_type\":\"price_change\"}","ts_local_ms":1781254837821}
{"dir":"in","text":"{\"market\":\"0x9c535590faae21bf76fed844aa47fc3c5c82253ef38bd545bf12c93470502685\", \"price_changes\":[{\"asset_id\":\"56108879726720646120583724001239294777304794469144970684362785767667828318889\", \"price\":\"0.45\", \"size\":\"156.55\", \"side\":\"BUY\", \"hash\":\"d4d8d3ade30ccbab39ad0a5f4695501f2616e3b6\", \"best_bid\":\"0.45\", \"best_ask\":\"0.46\"}, {\"asset_id\":\"107011546575057755426871645700605806081353395825571114128343592072429146374928\", \"price\":\"0.55\", \"size\":\"156.55\", \"side\":\"SELL\", \"hash\":\"d8b7ed4c741aa2afe2f1339569e3a1b7909c9b13\", \"best_bid\":\"0.54\", \"best_ask\":\"0.55\"}], \"timestamp\":\"1781254837427\", \"event_type\":\"price_change\"}","ts_local_ms":1781254837821}
{"dir":"in","text":"{\"market\":\"0x9c535590faae21bf76fed844aa47fc3c5c82253ef38bd545bf12c93470502685\", \"price_changes\":[{\"asset_id\":\"56108879726720646120583724001239294777304794469144970684362785767667828318889\", \"price\":\"0.43\", \"size\":\"195.96\", \"side\":\"BUY\", \"hash\":\"84f233415dce06c2bd013ba11df1fe25479447e5\", \"best_bid\":\"0.45\", \"best_ask\":\"0.46\"}, {\"asset_id\":\"107011546575057755426871645700605806081353395825571114128343592072429146374928\", \"price\":\"0.57\", \"size\":\"195.96\", \"side\":\"SELL\", \"hash\":\"ce699a06619b67e083e4c05b3d37243ab7aa67cf\", \"best_bid\":\"0.54\", \"best_ask\":\"0.55\"}], \"timestamp\":\"1781254837428\", \"event_type\":\"price_change\"}","ts_local_ms":1781254837821}
{"dir":"in","text":"{\"market\":\"0x9c535590faae21bf76fed844aa47fc3c5c82253ef38bd545bf12c93470502685\", \"price_changes\":[{\"asset_id\":\"56108879726720646120583724001239294777304794469144970684362785767667828318889\", \"price\":\"0.41\", \"size\":\"143.61\", \"side\":\"BUY\", \"hash\":\"a9051dfbf2c45a2d586b18d6ef9b338a2f422d81\", \"best_bid\":\"0.45\", \"best_ask\":\"0.46\"}, {\"asset_id\":\"107011546575057755426871645700605806081353395825571114128343592072429146374928\", \"price\":\"0.59\", \"size\":\"143.61\", \"side\":\"SELL\", \"hash\":\"ef7d2bc97476a7cd6b2f3091c109d6caef7cc59b\", \"best_bid\":\"0.54\", \"best_ask\":\"0.55\"}], \"timestamp\":\"1781254837431\", \"event_type\":\"price_change\"}","ts_local_ms":1781254837821}
{"dir":"in","text":"{\"market\":\"0x9c535590faae21bf76fed844aa47fc3c5c82253ef38bd545bf12c93470502685\", \"price_changes\":[{\"asset_id\":\"107011546575057755426871645700605806081353395825571114128343592072429146374928\", \"price\":\"0.54\", \"size\":\"449.52\", \"side\":\"BUY\", \"hash\":\"ddf09526fcceae6971bb9ec5202ab599cfb4356c\", \"best_bid\":\"0.54\", \"best_ask\":\"0.55\"}, {\"asset_id\":\"56108879726720646120583724001239294777304794469144970684362785767667828318889\", \"price\":\"0.46\", \"size\":\"449.52\", \"side\":\"SELL\", \"hash\":\"731587c6b15a7f2ef29cf230ddfffbb361117b1f\", \"best_bid\":\"0.45\", \"best_ask\":\"0.46\"}], \"timestamp\":\"1781254837431\", \"event_type\":\"price_change\"}","ts_local_ms":1781254837821}
{"dir":"in","text":"{\"market\":\"0x9c535590faae21bf76fed844aa47fc3c5c82253ef38bd545bf12c93470502685\", \"price_changes\":[{\"asset_id\":\"107011546575057755426871645700605806081353395825571114128343592072429146374928\", \"price\":\"0.43\", \"size\":\"121.3\", \"side\":\"BUY\", \"hash\":\"e066be49919e8f78f667a40e032b6e5ebecd3b40\", \"best_bid\":\"0.54\", \"best_ask\":\"0.55\"}, {\"asset_id\":\"56108879726720646120583724001239294777304794469144970684362785767667828318889\", \"price\":\"0.57\", \"size\":\"121.3\", \"side\":\"SELL\", \"hash\":\"ac18120b23ed33f9b9115916d5b7f0dce54fb4bf\", \"best_bid\":\"0.45\", \"best_ask\":\"0.46\"}], \"timestamp\":\"1781254837432\", \"event_type\":\"price_change\"}","ts_local_ms":1781254837821}
{"dir":"in","text":"{\"market\":\"0x9c535590faae21bf76fed844aa47fc3c5c82253ef38bd545bf12c93470502685\", \"price_changes\":[{\"asset_id\":\"56108879726720646120583724001239294777304794469144970684362785767667828318889\", \"price\":\"0.45\", \"size\":\"150.55\", \"side\":\"BUY\", \"hash\":\"b6dfb718d2ff589d9b32d1100a6bd63073828043\", \"best_bid\":\"0.45\", \"best_ask\":\"0.46\"}, {\"asset_id\":\"107011546575057755426871645700605806081353395825571114128343592072429146374928\", \"price\":\"0.55\", \"size\":\"150.55\", \"side\":\"SELL\", \"hash\":\"bf7116ba9ecc09bc36cd6a46e6efb6fa25b71f9a\", \"best_bid\":\"0.54\", \"best_ask\":\"0.55\"}], \"timestamp\":\"1781254837432\", \"event_type\":\"price_change\"}","ts_local_ms":1781254837821}
{"dir":"in","text":"{\"market\":\"0x9c535590faae21bf76fed844aa47fc3c5c82253ef38bd545bf12c93470502685\", \"price_changes\":[{\"asset_id\":\"107011546575057755426871645700605806081353395825571114128343592072429146374928\", \"price\":\"0.54\", \"size\":\"436.52\", \"side\":\"BUY\", \"hash\":\"63b9c13a50ab08f34fd7d7ca24ef566a8b862108\", \"best_bid\":\"0.54\", \"best_ask\":\"0.55\"}, {\"asset_id\":\"56108879726720646120583724001239294777304794469144970684362785767667828318889\", \"price\":\"0.46\", \"size\":\"436.52\", \"side\":\"SELL\", \"hash\":\"c6307aacb6b635f5eba6d9d12723d32c3361fa13\", \"best_bid\":\"0.45\", \"best_ask\":\"0.46\"}], \"timestamp\":\"1781254837432\", \"event_type\":\"price_change\"}","ts_local_ms":1781254837821}
{"dir":"in","text":"{\"market\":\"0x9c535590faae21bf76fed844aa47fc3c5c82253ef38bd545bf12c93470502685\", \"price_changes\":[{\"asset_id\":\"107011546575057755426871645700605806081353395825571114128343592072429146374928\", \"price\":\"0.54\", \"size\":\"430.52\", \"side\":\"BUY\", \"hash\":\"adacdb674427957b169b26367f8667519d7b1464\", \"best_bid\":\"0.54\", \"best_ask\":\"0.55\"}, {\"asset_id\":\"56108879726720646120583724001239294777304794469144970684362785767667828318889\", \"price\":\"0.46\", \"size\":\"430.52\", \"side\":\"SELL\", \"hash\":\"a11dd9fe7126156a65ff2c8da591e0cc56498c87\", \"best_bid\":\"0.45\", \"best_ask\":\"0.46\"}], \"timestamp\":\"1781254837433\", \"event_type\":\"price_change\"}","ts_local_ms":1781254837821}
{"dir":"in","text":"{\"market\":\"0x9c535590faae21bf76fed844aa47fc3c5c82253ef38bd545bf12c93470502685\", \"price_changes\":[{\"asset_id\":\"107011546575057755426871645700605806081353395825571114128343592072429146374928\", \"price\":\"0.54\", \"size\":\"441.52\", \"side\":\"BUY\", \"hash\":\"ac50f7fec9cbeafe56e7e178ee12b79a5f93801f\", \"best_bid\":\"0.54\", \"best_ask\":\"0.55\"}, {\"asset_id\":\"56108879726720646120583724001239294777304794469144970684362785767667828318889\", \"price\":\"0.46\", \"size\":\"441.52\", \"side\":\"SELL\", \"hash\":\"76ffe5351ea0a6b72c12a652ce683b3ecf477944\", \"best_bid\":\"0.45\", \"best_ask\":\"0.46\"}], \"timestamp\":\"1781254837434\", \"event_type\":\"price_change\"}","ts_local_ms":1781254837821}
{"dir":"in","text":"{\"market\":\"0x9c535590faae21bf76fed844aa47fc3c5c82253ef38bd545bf12c93470502685\", \"asset_id\":\"56108879726720646120583724001239294777304794469144970684362785767667828318889\", \"best_bid\":\"0.45\", \"best_ask\":\"0.46\", \"spread\":\"0.01\", \"timestamp\":\"1781254837435\", \"event_type\":\"best_bid_ask\"}","ts_local_ms":1781254837821}
{"dir":"in","text":"{\"market\":\"0x9c535590faae21bf76fed844aa47fc3c5c82253ef38bd545bf12c93470502685\", \"asset_id\":\"107011546575057755426871645700605806081353395825571114128343592072429146374928\", \"best_bid\":\"0.54\", \"best_ask\":\"0.55\", \"spread\":\"0.01\", \"timestamp\":\"1781254837435\", \"event_type\":\"best_bid_ask\"}","ts_local_ms":1781254837821}
{"dir":"in","text":"{\"market\":\"0x9c535590faae21bf76fed844aa47fc3c5c82253ef38bd545bf12c93470502685\", \"price_changes\":[{\"asset_id\":\"107011546575057755426871645700605806081353395825571114128343592072429146374928\", \"price\":\"0.55\", \"size\":\"145.55\", \"side\":\"SELL\", \"hash\":\"296d5cd2197dde2462a140eac2cf3325b8230c48\", \"best_bid\":\"0.54\", \"best_ask\":\"0.55\"}, {\"asset_id\":\"56108879726720646120583724001239294777304794469144970684362785767667828318889\", \"price\":\"0.45\", \"size\":\"145.55\", \"side\":\"BUY\", \"hash\":\"99449951655aa76bb0f86787915898da570fcd59\", \"best_bid\":\"0.45\", \"best_ask\":\"0.46\"}], \"timestamp\":\"1781254837435\", \"event_type\":\"price_change\"}","ts_local_ms":1781254837821}
{"dir":"in","text":"{\"market\":\"0x9c535590faae21bf76fed844aa47fc3c5c82253ef38bd545bf12c93470502685\", \"asset_id\":\"56108879726720646120583724001239294777304794469144970684362785767667828318889\", \"bids\":[{\"price\":\"0.01\", \"size\":\"56799.15\"}, {\"price\":\"0.02\", \"size\":\"22462.28\"}, {\"price\":\"0.03\", \"size\":\"2161.73\"}, {\"price\":\"0.04\", \"size\":\"1695.28\"}, {\"price\":\"0.05\", \"size\":\"1862.1\"}, {\"price\":\"0.06\", \"size\":\"991.6\"}, {\"price\":\"0.07\", \"size\":\"1035.18\"}, {\"price\":\"0.08\", \"size\":\"832.11\"}, {\"price\":\"0.09\", \"size\":\"679.28\"}, {\"price\":\"0.1\", \"size\":\"314.76\"}, {\"price\":\"0.11\", \"size\":\"597\"}, {\"price\":\"0.12\", \"size\":\"335.24\"}, {\"price\":\"0.13\", \"size\":\"84.2\"}, {\"price\":\"0.14\", \"size\":\"91.55\"}, {\"price\":\"0.15\", \"size\":\"52.86\"}, {\"price\":\"0.16\", \"size\":\"66.94\"}, {\"price\":\"0.17\", \"size\":\"54.08\"}, {\"price\":\"0.18\", \"size\":\"360.6\"}, {\"price\":\"0.19\", \"size\":\"104.67\"}, {\"price\":\"0.2\", \"size\":\"729.5\"}, {\"price\":\"0.21\", \"size\":\"153.8\"}, {\"price\":\"0.22\", \"size\":\"513.6\"}, {\"price\":\"0.23\", \"size\":\"60.74\"}, {\"price\":\"0.24\", \"size\":\"58.1\"}, {\"price\":\"0.25\", \"size\":\"27.9\"}, {\"price\":\"0.26\", \"size\":\"92.8\"}, {\"price\":\"0.27\", \"size\":\"118.11\"}, {\"price\":\"0.28\", \"size\":\"72.4\"}, {\"price\":\"0.29\", \"size\":\"87.3\"}, {\"price\":\"0.3\", \"size\":\"87.2\"}, {\"price\":\"0.31\", \"size\":\"96\"}, {\"price\":\"0.32\", \"size\":\"219.34\"}, {\"price\":\"0.33\", \"size\":\"232\"}, {\"price\":\"0.34\", \"size\":\"127\"}, {\"price\":\"0.35\", \"size\":\"296.73\"}, {\"price\":\"0.36\", \"size\":\"372.58\"}, {\"price\":\"0.37\", \"size\":\"291.94\"}, {\"price\":\"0.38\", \"size\":\"353.74\"}, {\"price\":\"0.39\", \"size\":\"349.15\"}, {\"price\":\"0.4\", \"size\":\"348.54\"}, {\"price\":\"0.41\", \"size\":\"143.61\"}, {\"price\":\"0.42\", \"size\":\"173.07\"}, {\"price\":\"0.43\", \"size\":\"195.96\"}, {\"price\":\"0.44\", \"size\":\"30\"}, {\"price\":\"0.45\", \"size\":\"145.55\"}], \"asks\":[{\"price\":\"0.99\", \"size\":\"55001.6\"}, {\"price\":\"0.98\", \"size\":\"22471.85\"}, {\"price\":\"0.97\", \"size\":\"2148.4\"}, {\"price\":\"0.96\", \"size\":\"1682.1\"}, {\"price\":\"0.95\", \"size\":\"1864.11\"}, {\"price\":\"0.94\", \"size\":\"1008.6\"}, {\"price\":\"0.93\", \"size\":\"992.18\"}, {\"price\":\"0.92\", \"size\":\"829.12\"}, {\"price\":\"0.91\", \"size\":\"781.72\"}, {\"price\":\"0.9\", \"size\":\"1234.15\"}, {\"price\":\"0.89\", \"size\":\"564.4\"}, {\"price\":\"0.88\", \"size\":\"303.64\"}, {\"price\":\"0.87\", \"size\":\"153.2\"}, {\"price\":\"0.86\", \"size\":\"61.95\"}, {\"price\":\"0.85\", \"size\":\"43.86\"}, {\"price\":\"0.84\", \"size\":\"58.94\"}, {\"price\":\"0.83\", \"size\":\"26.08\"}, {\"price\":\"0.82\", \"size\":\"45.36\"}, {\"price\":\"0.81\", \"size\":\"24.67\"}, {\"price\":\"0.8\", \"size\":\"83.51\"}, {\"price\":\"0.79\", \"size\":\"172.8\"}, {\"price\":\"0.78\", \"size\":\"77.6\"}, {\"price\":\"0.77\", \"size\":\"47.3\"}, {\"price\":\"0.76\", \"size\":\"47.1\"}, {\"price\":\"0.75\", \"size\":\"469.9\"}, {\"price\":\"0.74\", \"size\":\"46.8\"}, {\"price\":\"0.73\", \"size\":\"46.6\"}, {\"price\":\"0.72\", \"size\":\"51.4\"}, {\"price\":\"0.71\", \"size\":\"89.3\"}, {\"price\":\"0.7\", \"size\":\"74.2\"}, {\"price\":\"0.69\", \"size\":\"103.6\"}, {\"price\":\"0.68\", \"size\":\"87\"}, {\"price\":\"0.67\", \"size\":\"61.9\"}, {\"price\":\"0.66\", \"size\":\"91.8\"}, {\"price\":\"0.65\", \"size\":\"113.97\"}, {\"price\":\"0.64\", \"size\":\"371.6\"}, {\"price\":\"0.63\", \"size\":\"170.23\"}, {\"price\":\"0.62\", \"size\":\"71.5\"}, {\"price\":\"0.61\", \"size\":\"691.5\"}, {\"price\":\"0.6\", \"size\":\"111.4\"}, {\"price\":\"0.59\", \"size\":\"536.4\"}, {\"price\":\"0.58\", \"size\":\"224.3\"}, {\"price\":\"0.57\", \"size\":\"121.3\"}, {\"price\":\"0.56\", \"size\":\"97\"}, {\"price\":\"0.55\", \"size\":\"96\"}, {\"price\":\"0.54\", \"size\":\"352.36\"}, {\"price\":\"0.53\", \"size\":\"227.19\"}, {\"price\":\"0.52\", \"size\":\"1067.68\"}, {\"price\":\"0.51\", \"size\":\"434.91\"}, {\"price\":\"0.5\", \"size\":\"453.08\"}, {\"price\":\"0.49\", \"size\":\"227.14\"}, {\"price\":\"0.48\", \"size\":\"225.79\"}, {\"price\":\"0.47\", \"size\":\"182.17\"}, {\"price\":\"0.46\", \"size\":\"441.52\"}], \"hash\":\"99449951655aa76bb0f86787915898da570fcd59\", \"timestamp\":\"1781254837435\", \"event_type\":\"book\"}","ts_local_ms":1781254837821}
{"dir":"in","text":"{\"market\":\"0x9c535590faae21bf76fed844aa47fc3c5c82253ef38bd545bf12c93470502685\", \"asset_id\":\"107011546575057755426871645700605806081353395825571114128343592072429146374928\", \"bids\":[{\"price\":\"0.01\", \"size\":\"55001.6\"}, {\"price\":\"0.02\", \"size\":\"22471.85\"}, {\"price\":\"0.03\", \"size\":\"2148.4\"}, {\"price\":\"0.04\", \"size\":\"1682.1\"}, {\"price\":\"0.05\", \"size\":\"1864.11\"}, {\"price\":\"0.06\", \"size\":\"1008.6\"}, {\"price\":\"0.07\", \"size\":\"992.18\"}, {\"price\":\"0.08\", \"size\":\"829.12\"}, {\"price\":\"0.09\", \"size\":\"781.72\"}, {\"price\":\"0.1\", \"size\":\"1234.15\"}, {\"price\":\"0.11\", \"size\":\"564.4\"}, {\"price\":\"0.12\", \"size\":\"303.64\"}, {\"price\":\"0.13\", \"size\":\"153.2\"}, {\"price\":\"0.14\", \"size\":\"61.95\"}, {\"price\":\"0.15\", \"size\":\"43.86\"}, {\"price\":\"0.16\", \"size\":\"58.94\"}, {\"price\":\"0.17\", \"size\":\"26.08\"}, {\"price\":\"0.18\", \"size\":\"45.36\"}, {\"price\":\"0.19\", \"size\":\"24.67\"}, {\"price\":\"0.2\", \"size\":\"83.51\"}, {\"price\":\"0.21\", \"size\":\"172.8\"}, {\"price\":\"0.22\", \"size\":\"77.6\"}, {\"price\":\"0.23\", \"size\":\"47.3\"}, {\"price\":\"0.24\", \"size\":\"47.1\"}, {\"price\":\"0.25\", \"size\":\"469.9\"}, {\"price\":\"0.26\", \"size\":\"46.8\"}, {\"price\":\"0.27\", \"size\":\"46.6\"}, {\"price\":\"0.28\", \"size\":\"51.4\"}, {\"price\":\"0.29\", \"size\":\"89.3\"}, {\"price\":\"0.3\", \"size\":\"74.2\"}, {\"price\":\"0.31\", \"size\":\"103.6\"}, {\"price\":\"0.32\", \"size\":\"87\"}, {\"price\":\"0.33\", \"size\":\"61.9\"}, {\"price\":\"0.34\", \"size\":\"91.8\"}, {\"price\":\"0.35\", \"size\":\"113.97\"}, {\"price\":\"0.36\", \"size\":\"371.6\"}, {\"price\":\"0.37\", \"size\":\"170.23\"}, {\"price\":\"0.38\", \"size\":\"71.5\"}, {\"price\":\"0.39\", \"size\":\"691.5\"}, {\"price\":\"0.4\", \"size\":\"111.4\"}, {\"price\":\"0.41\", \"size\":\"536.4\"}, {\"price\":\"0.42\", \"size\":\"224.3\"}, {\"price\":\"0.43\", \"size\":\"121.3\"}, {\"price\":\"0.44\", \"size\":\"97\"}, {\"price\":\"0.45\", \"size\":\"96\"}, {\"price\":\"0.46\", \"size\":\"352.36\"}, {\"price\":\"0.47\", \"size\":\"227.19\"}, {\"price\":\"0.48\", \"size\":\"1067.68\"}, {\"price\":\"0.49\", \"size\":\"434.91\"}, {\"price\":\"0.5\", \"size\":\"453.08\"}, {\"price\":\"0.51\", \"size\":\"227.14\"}, {\"price\":\"0.52\", \"size\":\"225.79\"}, {\"price\":\"0.53\", \"size\":\"182.17\"}, {\"price\":\"0.54\", \"size\":\"441.52\"}], \"asks\":[{\"price\":\"0.99\", \"size\":\"56799.15\"}, {\"price\":\"0.98\", \"size\":\"22462.28\"}, {\"price\":\"0.97\", \"size\":\"2161.73\"}, {\"price\":\"0.96\", \"size\":\"1695.28\"}, {\"price\":\"0.95\", \"size\":\"1862.1\"}, {\"price\":\"0.94\", \"size\":\"991.6\"}, {\"price\":\"0.93\", \"size\":\"1035.18\"}, {\"price\":\"0.92\", \"size\":\"832.11\"}, {\"price\":\"0.91\", \"size\":\"679.28\"}, {\"price\":\"0.9\", \"size\":\"314.76\"}, {\"price\":\"0.89\", \"size\":\"597\"}, {\"price\":\"0.88\", \"size\":\"335.24\"}, {\"price\":\"0.87\", \"size\":\"84.2\"}, {\"price\":\"0.86\", \"size\":\"91.55\"}, {\"price\":\"0.85\", \"size\":\"52.86\"}, {\"price\":\"0.84\", \"size\":\"66.94\"}, {\"price\":\"0.83\", \"size\":\"54.08\"}, {\"price\":\"0.82\", \"size\":\"360.6\"}, {\"price\":\"0.81\", \"size\":\"104.67\"}, {\"price\":\"0.8\", \"size\":\"729.5\"}, {\"price\":\"0.79\", \"size\":\"153.8\"}, {\"price\":\"0.78\", \"size\":\"513.6\"}, {\"price\":\"0.77\", \"size\":\"60.74\"}, {\"price\":\"0.76\", \"size\":\"58.1\"}, {\"price\":\"0.75\", \"size\":\"27.9\"}, {\"price\":\"0.74\", \"size\":\"92.8\"}, {\"price\":\"0.73\", \"size\":\"118.11\"}, {\"price\":\"0.72\", \"size\":\"72.4\"}, {\"price\":\"0.71\", \"size\":\"87.3\"}, {\"price\":\"0.7\", \"size\":\"87.2\"}, {\"price\":\"0.69\", \"size\":\"96\"}, {\"price\":\"0.68\", \"size\":\"219.34\"}, {\"price\":\"0.67\", \"size\":\"232\"}, {\"price\":\"0.66\", \"size\":\"127\"}, {\"price\":\"0.65\", \"size\":\"296.73\"}, {\"price\":\"0.64\", \"size\":\"372.58\"}, {\"price\":\"0.63\", \"size\":\"291.94\"}, {\"price\":\"0.62\", \"size\":\"353.74\"}, {\"price\":\"0.61\", \"size\":\"349.15\"}, {\"price\":\"0.6\", \"size\":\"348.54\"}, {\"price\":\"0.59\", \"size\":\"143.61\"}, {\"price\":\"0.58\", \"size\":\"173.07\"}, {\"price\":\"0.57\", \"size\":\"195.96\"}, {\"price\":\"0.56\", \"size\":\"30\"}, {\"price\":\"0.55\", \"size\":\"145.55\"}], \"hash\":\"296d5cd2197dde2462a140eac2cf3325b8230c48\", \"timestamp\":\"1781254837435\", \"event_type\":\"book\"}","ts_local_ms":1781254837822}
{"dir":"in","text":"{\"market\":\"0x9c535590faae21bf76fed844aa47fc3c5c82253ef38bd545bf12c93470502685\", \"price_changes\":[{\"asset_id\":\"107011546575057755426871645700605806081353395825571114128343592072429146374928\", \"price\":\"0.54\", \"size\":\"456.52\", \"side\":\"BUY\", \"hash\":\"14b7ea606e98e867003307bd04925d0b87a4d7f8\", \"best_bid\":\"0.54\", \"best_ask\":\"0.55\"}, {\"asset_id\":\"56108879726720646120583724001239294777304794469144970684362785767667828318889\", \"price\":\"0.46\", \"size\":\"456.52\", \"side\":\"SELL\", \"hash\":\"57b3cc49c29e0cf1b1deb9d6aaf91008fd96eb91\", \"best_bid\":\"0.45\", \"best_ask\":\"0.46\"}], \"timestamp\":\"1781254837440\", \"event_type\":\"price_change\"}","ts_local_ms":1781254837822}
{"dir":"in","text":"{\"market\":\"0x9c535590faae21bf76fed844aa47fc3c5c82253ef38bd545bf12c93470502685\", \"price_changes\":[{\"asset_id\":\"107011546575057755426871645700605806081353395825571114128343592072429146374928\", \"price\":\"0.54\", \"size\":\"468.52\", \"side\":\"BUY\", \"hash\":\"edd2069d980756b43a3ad6d537b5a893fff866c9\", \"best_bid\":\"0.54\", \"best_ask\":\"0.55\"}, {\"asset_id\":\"56108879726720646120583724001239294777304794469144970684362785767667828318889\", \"price\":\"0.46\", \"size\":\"468.52\", \"side\":\"SELL\", \"hash\":\"7c7aadf0c385ce6498827cc1f9863d563f6c23b8\", \"best_bid\":\"0.45\", \"best_ask\":\"0.46\"}], \"timestamp\":\"1781254837441\", \"event_type\":\"price_change\"}","ts_local_ms":1781254837822}
{"dir":"in","text":"{\"market\":\"0x9c535590faae21bf76fed844aa47fc3c5c82253ef38bd545bf12c93470502685\", \"price_changes\":[{\"asset_id\":\"107011546575057755426871645700605806081353395825571114128343592072429146374928\", \"price\":\"0.54\", \"size\":\"463.52\", \"side\":\"BUY\", \"hash\":\"f30f6fd44f12aeb0261ebc11938db05776e66363\", \"best_bid\":\"0.54\", \"best_ask\":\"0.55\"}, {\"asset_id\":\"56108879726720646120583724001239294777304794469144970684362785767667828318889\", \"price\":\"0.46\", \"size\":\"463.52\", \"side\":\"SELL\", \"hash\":\"665631af66a365142d5187885df2230d96ca3f95\", \"best_bid\":\"0.45\", \"best_ask\":\"0.46\"}], \"timestamp\":\"1781254837443\", \"event_type\":\"price_change\"}","ts_local_ms":1781254837822}
{"dir":"in","text":"{\"market\":\"0x9c535590faae21bf76fed844aa47fc3c5c82253ef38bd545bf12c93470502685\", \"price_changes\":[{\"asset_id\":\"107011546575057755426871645700605806081353395825571114128343592072429146374928\", \"price\":\"0.55\", \"size\":\"139.55\", \"side\":\"SELL\", \"hash\":\"ba60146c167ab20aeff6161259f4a0fb49e98444\", \"best_bid\":\"0.54\", \"best_ask\":\"0.55\"}, {\"asset_id\":\"56108879726720646120583724001239294777304794469144970684362785767667828318889\", \"price\":\"0.45\", \"size\":\"139.55\", \"side\":\"BUY\", \"hash\":\"0096a64214ec935f672392f20c5bfed1726278b6\", \"best_bid\":\"0.45\", \"best_ask\":\"0.46\"}], \"timestamp\":\"1781254837443\", \"event_type\":\"price_change\"}","ts_local_ms":1781254837822}
{"dir":"in","text":"{\"market\":\"0x9c535590faae21bf76fed844aa47fc3c5c82253ef38bd545bf12c93470502685\", \"price_changes\":[{\"asset_id\":\"56108879726720646120583724001239294777304794469144970684362785767667828318889\", \"price\":\"0.45\", \"size\":\"134.55\", \"side\":\"BUY\", \"hash\":\"52f08394f7764282250c4562bd7c4284282ef687\", \"best_bid\":\"0.45\", \"best_ask\":\"0.46\"}, {\"asset_id\":\"107011546575057755426871645700605806081353395825571114128343592072429146374928\", \"price\":\"0.55\", \"size\":\"134.55\", \"side\":\"SELL\", \"hash\":\"3600435e6b77b745fd9846514914b24f8726336c\", \"best_bid\":\"0.54\", \"best_ask\":\"0.55\"}], \"timestamp\":\"1781254837444\", \"event_type\":\"price_change\"}","ts_local_ms":1781254837822}
{"dir":"in","text":"{\"market\":\"0x9c535590faae21bf76fed844aa47fc3c5c82253ef38bd545bf12c93470502685\", \"price_changes\":[{\"asset_id\":\"107011546575057755426871645700605806081353395825571114128343592072429146374928\", \"price\":\"0.54\", \"size\":\"473.52\", \"side\":\"BUY\", \"hash\":\"d68f4d4b3b8459b986a23e8fc66ccb654b278123\", \"best_bid\":\"0.54\", \"best_ask\":\"0.55\"}, {\"asset_id\":\"56108879726720646120583724001239294777304794469144970684362785767667828318889\", \"price\":\"0.46\", \"size\":\"473.52\", \"side\":\"SELL\", \"hash\":\"e83227c89a0066f1cb0fb8ab85e619060eec8875\", \"best_bid\":\"0.45\", \"best_ask\":\"0.46\"}], \"timestamp\":\"1781254837447\", \"event_type\":\"price_change\"}","ts_local_ms":1781254837822}
{"dir":"in","text":"{\"market\":\"0x9c535590faae21bf76fed844aa47fc3c5c82253ef38bd545bf12c93470502685\", \"price_changes\":[{\"asset_id\":\"107011546575057755426871645700605806081353395825571114128343592072429146374928\", \"price\":\"0.54\", \"size\":\"485.52\", \"side\":\"BUY\", \"hash\":\"7d09954a9a69905c4a51d5bbddbbd7eef996785b\", \"best_bid\":\"0.54\", \"best_ask\":\"0.55\"}, {\"asset_id\":\"56108879726720646120583724001239294777304794469144970684362785767667828318889\", \"price\":\"0.46\", \"size\":\"485.52\", \"side\":\"SELL\", \"hash\":\"d70e0f15d8346b85c33f3dc8ab9de6e4d2c993fb\", \"best_bid\":\"0.45\", \"best_ask\":\"0.46\"}], \"timestamp\":\"1781254837453\", \"event_type\":\"price_change\"}","ts_local_ms":1781254837822}
{"dir":"in","text":"{\"market\":\"0x9c535590faae21bf76fed844aa47fc3c5c82253ef38bd545bf12c93470502685\", \"price_changes\":[{\"asset_id\":\"107011546575057755426871645700605806081353395825571114128343592072429146374928\", \"price\":\"0.54\", \"size\":\"496.52\", \"side\":\"BUY\", \"hash\":\"f138a300962afe1ab9758b479b7d6b6cd4126392\", \"best_bid\":\"0.54\", \"best_ask\":\"0.55\"}, {\"asset_id\":\"56108879726720646120583724001239294777304794469144970684362785767667828318889\", \"price\":\"0.46\", \"size\":\"496.52\", \"side\":\"SELL\", \"hash\":\"50e90e67f5347010a01bb48d23bcf9f3fbfca272\", \"best_bid\":\"0.45\", \"best_ask\":\"0.46\"}], \"timestamp\":\"1781254837454\", \"event_type\":\"price_change\"}","ts_local_ms":1781254837822}
{"dir":"in","text":"{\"market\":\"0x9c535590faae21bf76fed844aa47fc3c5c82253ef38bd545bf12c93470502685\", \"price_changes\":[{\"asset_id\":\"107011546575057755426871645700605806081353395825571114128343592072429146374928\", \"price\":\"0.03\", \"size\":\"2154.4\", \"side\":\"BUY\", \"hash\":\"8fd6ff4205325364691350eca2d46ca07d555e58\", \"best_bid\":\"0.54\", \"best_ask\":\"0.55\"}, {\"asset_id\":\"56108879726720646120583724001239294777304794469144970684362785767667828318889\", \"price\":\"0.97\", \"size\":\"2154.4\", \"side\":\"SELL\", \"hash\":\"44779c55a6c1d84a10fa6eee93356fbd0bfb3485\", \"best_bid\":\"0.45\", \"best_ask\":\"0.46\"}], \"timestamp\":\"1781254837458\", \"event_type\":\"price_change\"}","ts_local_ms":1781254837823}
{"dir":"in","text":"{\"market\":\"0x9c535590faae21bf76fed844aa47fc3c5c82253ef38bd545bf12c93470502685\", \"price_changes\":[{\"asset_id\":\"107011546575057755426871645700605806081353395825571114128343592072429146374928\", \"price\":\"0.11\", \"size\":\"591\", \"side\":\"BUY\", \"hash\":\"2cbfc130db1e3b37c92dae6576d77db881956a57\", \"best_bid\":\"0.54\", \"best_ask\":\"0.55\"}, {\"asset_id\":\"56108879726720646120583724001239294777304794469144970684362785767667828318889\", \"price\":\"0.89\", \"size\":\"591\", \"side\":\"SELL\", \"hash\":\"566352483964f619f798bc49b7d748c661e077e1\", \"best_bid\":\"0.45\", \"best_ask\":\"0.46\"}], \"timestamp\":\"1781254837459\", \"event_type\":\"price_change\"}","ts_local_ms":1781254837972}
{"dir":"in","text":"{\"market\":\"0x9c535590faae21bf76fed844aa47fc3c5c82253ef38bd545bf12c93470502685\", \"price_changes\":[{\"asset_id\":\"107011546575057755426871645700605806081353395825571114128343592072429146374928\", \"price\":\"0.54\", \"size\":\"508.52\", \"side\":\"BUY\", \"hash\":\"d735fa465533b87d229db59d3642171f226cccbb\", \"best_bid\":\"0.54\", \"best_ask\":\"0.55\"}, {\"asset_id\":\"56108879726720646120583724001239294777304794469144970684362785767667828318889\", \"price\":\"0.46\", \"size\":\"508.52\", \"side\":\"SELL\", \"hash\":\"f21a4fabbab43e7c38324d775eec1cda855ae974\", \"best_bid\":\"0.45\", \"best_ask\":\"0.46\"}], \"timestamp\":\"1781254837462\", \"event_type\":\"price_change\"}","ts_local_ms":1781254837972}
{"dir":"in","text":"{\"market\":\"0x9c535590faae21bf76fed844aa47fc3c5c82253ef38bd545bf12c93470502685\", \"price_changes\":[{\"asset_id\":\"107011546575057755426871645700605806081353395825571114128343592072429146374928\", \"price\":\"0.54\", \"size\":\"498.52\", \"side\":\"BUY\", \"hash\":\"67d48e444f7567f52366e4f466d2e501e203b465\", \"best_bid\":\"0.54\", \"best_ask\":\"0.55\"}, {\"asset_id\":\"56108879726720646120583724001239294777304794469144970684362785767667828318889\", \"price\":\"0.46\", \"size\":\"498.52\", \"side\":\"SELL\", \"hash\":\"750e1325d875fb6692ba1e1e1534fd0f1da68cef\", \"best_bid\":\"0.45\", \"best_ask\":\"0.46\"}], \"timestamp\":\"1781254837462\", \"event_type\":\"price_change\"}","ts_local_ms":1781254837973}
{"dir":"in","text":"{\"market\":\"0x9c535590faae21bf76fed844aa47fc3c5c82253ef38bd545bf12c93470502685\", \"asset_id\":\"107011546575057755426871645700605806081353395825571114128343592072429146374928\", \"price\":\"0.55\", \"size\":\"5\", \"fee_rate_bps\":\"0\", \"side\":\"BUY\", \"timestamp\":\"1781254837457\", \"event_type\":\"last_trade_price\", \"transaction_hash\":\"0xe5a04236376903a3b107499ad00973eb610aeb819acd319a20d725ebe357e223\"}","ts_local_ms":1781254837973}
{"dir":"in","text":"{\"market\":\"0x9c535590faae21bf76fed844aa47fc3c5c82253ef38bd545bf12c93470502685\", \"price_changes\":[{\"asset_id\":\"107011546575057755426871645700605806081353395825571114128343592072429146374928\", \"price\":\"0.54\", \"size\":\"510.52\", \"side\":\"BUY\", \"hash\":\"c812d3b146fadb7ba9cb032a43cb2c74d47944c3\", \"best_bid\":\"0.54\", \"best_ask\":\"0.55\"}, {\"asset_id\":\"56108879726720646120583724001239294777304794469144970684362785767667828318889\", \"price\":\"0.46\", \"size\":\"510.52\", \"side\":\"SELL\", \"hash\":\"95f76241a2c169ec36931eae5360fac3f2d2329e\", \"best_bid\":\"0.45\", \"best_ask\":\"0.46\"}], \"timestamp\":\"1781254837466\", \"event_type\":\"price_change\"}","ts_local_ms":1781254837973}
{"dir":"in","text":"{\"market\":\"0x9c535590faae21bf76fed844aa47fc3c5c82253ef38bd545bf12c93470502685\", \"price_changes\":[{\"asset_id\":\"107011546575057755426871645700605806081353395825571114128343592072429146374928\", \"price\":\"0.54\", \"size\":\"534.52\", \"side\":\"BUY\", \"hash\":\"123e08c356dc6cf8c94f512e1dea7e842ddd3246\", \"best_bid\":\"0.54\", \"best_ask\":\"0.55\"}, {\"asset_id\":\"56108879726720646120583724001239294777304794469144970684362785767667828318889\", \"price\":\"0.46\", \"size\":\"534.52\", \"side\":\"SELL\", \"hash\":\"93cc36dd8db75f81ff3a2d41164d630a7b7eead2\", \"best_bid\":\"0.45\", \"best_ask\":\"0.46\"}], \"timestamp\":\"1781254837466\", \"event_type\":\"price_change\"}","ts_local_ms":1781254837973}
{"dir":"in","text":"{\"market\":\"0x9c535590faae21bf76fed844aa47fc3c5c82253ef38bd545bf12c93470502685\", \"price_changes\":[{\"asset_id\":\"107011546575057755426871645700605806081353395825571114128343592072429146374928\", \"price\":\"0.52\", \"size\":\"210.79\", \"side\":\"BUY\", \"hash\":\"01b28abe9a667aa6812e8f0713df1e2268a11921\", \"best_bid\":\"0.54\", \"best_ask\":\"0.55\"}, {\"asset_id\":\"56108879726720646120583724001239294777304794469144970684362785767667828318889\", \"price\":\"0.48\", \"size\":\"210.79\", \"side\":\"SELL\", \"hash\":\"7589e169f2272cdd802e9ea398a2ff803f221c07\", \"best_bid\":\"0.45\", \"best_ask\":\"0.46\"}], \"timestamp\":\"1781254837467\", \"event_type\":\"price_change\"}","ts_local_ms":1781254837973}
{"dir":"in","text":"{\"market\":\"0x9c535590faae21bf76fed844aa47fc3c5c82253ef38bd545bf12c93470502685\", \"price_changes\":[{\"asset_id\":\"107011546575057755426871645700605806081353395825571114128343592072429146374928\", \"price\":\"0.5\", \"size\":\"468.08\", \"side\":\"BUY\", \"hash\":\"e8473530103bc3202c1423d1be860ff341c57e1d\", \"best_bid\":\"0.54\", \"best_ask\":\"0.55\"}, {\"asset_id\":\"56108879726720646120583724001239294777304794469144970684362785767667828318889\", \"price\":\"0.5\", \"size\":\"468.08\", \"side\":\"SELL\", \"hash\":\"924b17d1837005957e5df51202575baf475911fc\", \"best_bid\":\"0.45\", \"best_ask\":\"0.46\"}], \"timestamp\":\"1781254837472\", \"event_type\":\"price_change\"}","ts_local_ms":1781254837973}
{"dir":"in","text":"{\"market\":\"0x9c535590faae21bf76fed844aa47fc3c5c82253ef38bd545bf12c93470502685\", \"price_changes\":[{\"asset_id\":\"107011546575057755426871645700605806081353395825571114128343592072429146374928\", \"price\":\"0.54\", \"size\":\"527.52\", \"side\":\"BUY\", \"hash\":\"df9130eadd444de5180801dad5df5a0019258550\", \"best_bid\":\"0.54\", \"best_ask\":\"0.55\"}, {\"asset_id\":\"56108879726720646120583724001239294777304794469144970684362785767667828318889\", \"price\":\"0.46\", \"size\":\"527.52\", \"side\":\"SELL\", \"hash\":\"1986bf26e72aeaac7068cdd22147ed9823b1276e\", \"best_bid\":\"0.45\", \"best_ask\":\"0.46\"}], \"timestamp\":\"1781254837473\", \"event_type\":\"price_change\"}","ts_local_ms":1781254837973}
{"dir":"in","text":"{\"market\":\"0x9c535590faae21bf76fed844aa47fc3c5c82253ef38bd545bf12c93470502685\", \"price_changes\":[{\"asset_id\":\"107011546575057755426871645700605806081353395825571114128343592072429146374928\", \"price\":\"0.54\", \"size\":\"539.52\", \"side\":\"BUY\", \"hash\":\"c89376077bce12039aacd0ba844179ab135eac53\", \"best_bid\":\"0.54\", \"best_ask\":\"0.55\"}, {\"asset_id\":\"56108879726720646120583724001239294777304794469144970684362785767667828318889\", \"price\":\"0.46\", \"size\":\"539.52\", \"side\":\"SELL\", \"hash\":\"16ad77504212cc9cd16f40b8e3674b3852cdc72e\", \"best_bid\":\"0.45\", \"best_ask\":\"0.46\"}], \"timestamp\":\"1781254837473\", \"event_type\":\"price_change\"}","ts_local_ms":1781254837973}
{"dir":"in","text":"{\"market\":\"0x9c535590faae21bf76fed844aa47fc3c5c82253ef38bd545bf12c93470502685\", \"price_changes\":[{\"asset_id\":\"107011546575057755426871645700605806081353395825571114128343592072429146374928\", \"price\":\"0.54\", \"size\":\"550.52\", \"side\":\"BUY\", \"hash\":\"7aac0cb888519036366f03e7afd2ab82734790fb\", \"best_bid\":\"0.54\", \"best_ask\":\"0.55\"}, {\"asset_id\":\"56108879726720646120583724001239294777304794469144970684362785767667828318889\", \"price\":\"0.46\", \"size\":\"550.52\", \"side\":\"SELL\", \"hash\":\"da3880c727efa15b7e1bcff982ce3b80bf30cbc6\", \"best_bid\":\"0.45\", \"best_ask\":\"0.46\"}], \"timestamp\":\"1781254837475\", \"event_type\":\"price_change\"}","ts_local_ms":1781254837973}
{"dir":"in","text":"{\"market\":\"0x9c535590faae21bf76fed844aa47fc3c5c82253ef38bd545bf12c93470502685\", \"price_changes\":[{\"asset_id\":\"107011546575057755426871645700605806081353395825571114128343592072429146374928\", \"price\":\"0.01\", \"size\":\"55007.6\", \"side\":\"BUY\", \"hash\":\"a37d164b5df6caee64405c608bba80bfde03e0e9\", \"best_bid\":\"0.54\", \"best_ask\":\"0.55\"}, {\"asset_id\":\"56108879726720646120583724001239294777304794469144970684362785767667828318889\", \"price\":\"0.99\", \"size\":\"55007.6\", \"side\":\"SELL\", \"hash\":\"e3b510405112c567ace5bbd368155f12fe3bcf4a\", \"best_bid\":\"0.45\", \"best_ask\":\"0.46\"}], \"timestamp\":\"1781254837482\", \"event_type\":\"price_change\"}","ts_local_ms":1781254837973}
{"dir":"in","text":"{\"market\":\"0x9c535590faae21bf76fed844aa47fc3c5c82253ef38bd545bf12c93470502685\", \"price_changes\":[{\"asset_id\":\"107011546575057755426871645700605806081353395825571114128343592072429146374928\", \"price\":\"0.54\", \"size\":\"562.52\", \"side\":\"BUY\", \"hash\":\"ff7d6aa6b07171bc73cf6293babf731b9b0ca0ac\", \"best_bid\":\"0.54\", \"best_ask\":\"0.55\"}, {\"asset_id\":\"56108879726720646120583724001239294777304794469144970684362785767667828318889\", \"price\":\"0.46\", \"size\":\"562.52\", \"side\":\"SELL\", \"hash\":\"24af229ab0c0f596424b698e49fe56efd708dd04\", \"best_bid\":\"0.45\", \"best_ask\":\"0.46\"}], \"timestamp\":\"1781254837484\", \"event_type\":\"price_change\"}","ts_local_ms":1781254837973}
{"dir":"in","text":"{\"market\":\"0x9c535590faae21bf76fed844aa47fc3c5c82253ef38bd545bf12c93470502685\", \"price_changes\":[{\"asset_id\":\"107011546575057755426871645700605806081353395825571114128343592072429146374928\", \"price\":\"0.54\", \"size\":\"555.52\", \"side\":\"BUY\", \"hash\":\"7af0c2f2dfc8c50b83bbda9d4b8d5afffc3ed2c1\", \"best_bid\":\"0.54\", \"best_ask\":\"0.55\"}, {\"asset_id\":\"56108879726720646120583724001239294777304794469144970684362785767667828318889\", \"price\":\"0.46\", \"size\":\"555.52\", \"side\":\"SELL\", \"hash\":\"351a2f65073ef09eb7cf08afde6e928a6e16df12\", \"best_bid\":\"0.45\", \"best_ask\":\"0.46\"}], \"timestamp\":\"1781254837487\", \"event_type\":\"price_change\"}","ts_local_ms":1781254837973}
{"dir":"in","text":"{\"market\":\"0x9c535590faae21bf76fed844aa47fc3c5c82253ef38bd545bf12c93470502685\", \"price_changes\":[{\"asset_id\":\"107011546575057755426871645700605806081353395825571114128343592072429146374928\", \"price\":\"0.54\", \"size\":\"567.52\", \"side\":\"BUY\", \"hash\":\"9de50990e4e194abe530fb57719020a6b1d88b03\", \"best_bid\":\"0.54\", \"best_ask\":\"0.55\"}, {\"asset_id\":\"56108879726720646120583724001239294777304794469144970684362785767667828318889\", \"price\":\"0.46\", \"size\":\"567.52\", \"side\":\"SELL\", \"hash\":\"5df8a45ad9425ab0c951086462b3f165aaa5419d\", \"best_bid\":\"0.45\", \"best_ask\":\"0.46\"}], \"timestamp\":\"1781254837491\", \"event_type\":\"price_change\"}","ts_local_ms":1781254837973}
{"dir":"in","text":"{\"market\":\"0x9c535590faae21bf76fed844aa47fc3c5c82253ef38bd545bf12c93470502685\", \"price_changes\":[{\"asset_id\":\"107011546575057755426871645700605806081353395825571114128343592072429146374928\", \"price\":\"0.54\", \"size\":\"550.52\", \"side\":\"BUY\", \"hash\":\"5067209757c124dee376c410298d461be1c23a4f\", \"best_bid\":\"0.54\", \"best_ask\":\"0.55\"}, {\"asset_id\":\"56108879726720646120583724001239294777304794469144970684362785767667828318889\", \"price\":\"0.46\", \"size\":\"550.52\", \"side\":\"SELL\", \"hash\":\"832f0e1d95dd5203074cf8a294c964ea1a26323a\", \"best_bid\":\"0.45\", \"best_ask\":\"0.46\"}], \"timestamp\":\"1781254837491\", \"event_type\":\"price_change\"}","ts_local_ms":1781254837973}
{"dir":"in","text":"{\"market\":\"0x9c535590faae21bf76fed844aa47fc3c5c82253ef38bd545bf12c93470502685\", \"price_changes\":[{\"asset_id\":\"107011546575057755426871645700605806081353395825571114128343592072429146374928\", \"price\":\"0.54\", \"size\":\"542.52\", \"side\":\"BUY\", \"hash\":\"831f1118c05a63076a09d93d390464e206a09ba1\", \"best_bid\":\"0.54\", \"best_ask\":\"0.55\"}, {\"asset_id\":\"56108879726720646120583724001239294777304794469144970684362785767667828318889\", \"price\":\"0.46\", \"size\":\"542.52\", \"side\":\"SELL\", \"hash\":\"88046b4bd5f9cbbdcf20f64cc479a8fc44257625\", \"best_bid\":\"0.45\", \"best_ask\":\"0.46\"}], \"timestamp\":\"1781254837492\", \"event_type\":\"price_change\"}","ts_local_ms":1781254837974}
{"dir":"in","text":"{\"market\":\"0x9c535590faae21bf76fed844aa47fc3c5c82253ef38bd545bf12c93470502685\", \"price_changes\":[{\"asset_id\":\"107011546575057755426871645700605806081353395825571114128343592072429146374928\", \"price\":\"0.54\", \"size\":\"534.52\", \"side\":\"BUY\", \"hash\":\"b9b15cab0513d71bee7c5b38293d0ab726fb58b3\", \"best_bid\":\"0.54\", \"best_ask\":\"0.55\"}, {\"asset_id\":\"56108879726720646120583724001239294777304794469144970684362785767667828318889\", \"price\":\"0.46\", \"size\":\"534.52\", \"side\":\"SELL\", \"hash\":\"34c54ba8cd3527e09fd41e43f66e6ee02e01c0d3\", \"best_bid\":\"0.45\", \"best_ask\":\"0.46\"}], \"timestamp\":\"1781254837494\", \"event_type\":\"price_change\"}","ts_local_ms":1781254837974}
{"dir":"in","text":"{\"market\":\"0x9c535590faae21bf76fed844aa47fc3c5c82253ef38bd545bf12c93470502685\", \"price_changes\":[{\"asset_id\":\"56108879726720646120583724001239294777304794469144970684362785767667828318889\", \"price\":\"0.37\", \"size\":\"306.94\", \"side\":\"BUY\", \"hash\":\"526dccceb9f6e1ee4acb2b5bdeff7d2489caf8a6\", \"best_bid\":\"0.45\", \"best_ask\":\"0.46\"}, {\"asset_id\":\"107011546575057755426871645700605806081353395825571114128343592072429146374928\", \"price\":\"0.63\", \"size\":\"306.94\", \"side\":\"SELL\", \"hash\":\"d47192c8b864147c1b7f27204c5332428b99133b\", \"best_bid\":\"0.54\", \"best_ask\":\"0.55\"}], \"timestamp\":\"1781254837502\", \"event_type\":\"price_change\"}","ts_local_ms":1781254837974}
{"dir":"in","text":"{\"market\":\"0x9c535590faae21bf76fed844aa47fc3c5c82253ef38bd545bf12c93470502685\", \"price_changes\":[{\"asset_id\":\"107011546575057755426871645700605806081353395825571114128343592072429146374928\", \"price\":\"0.04\", \"size\":\"1677.1\", \"side\":\"BUY\", \"hash\":\"ce413737a707be5678f01db1a9c04f7304f3929d\", \"best_bid\":\"0.54\", \"best_ask\":\"0.55\"}, {\"asset_id\":\"56108879726720646120583724001239294777304794469144970684362785767667828318889\", \"price\":\"0.96\", \"size\":\"1677.1\", \"side\":\"SELL\", \"hash\":\"900369552f803305a9be902d780e5f9c842aa1f9\", \"best_bid\":\"0.45\", \"best_ask\":\"0.46\"}], \"timestamp\":\"1781254837502\", \"event_type\":\"price_change\"}","ts_local_ms":1781254837974}
{"dir":"in","text":"{\"market\":\"0x9c535590faae21bf76fed844aa47fc3c5c82253ef38bd545bf12c93470502685\", \"price_changes\":[{\"asset_id\":\"107011546575057755426871645700605806081353395825571114128343592072429146374928\", \"price\":\"0.54\", \"size\":\"547.52\", \"side\":\"BUY\", \"hash\":\"9b90be77f92d79d25fd32737946df2f98852f366\", \"best_bid\":\"0.54\", \"best_ask\":\"0.55\"}, {\"asset_id\":\"56108879726720646120583724001239294777304794469144970684362785767667828318889\", \"price\":\"0.46\", \"size\":\"547.52\", \"side\":\"SELL\", \"hash\":\"1ddcefc3cefafd2517fe8826dfcb8d42eccf6dfc\", \"best_bid\":\"0.45\", \"best_ask\":\"0.46\"}], \"timestamp\":\"1781254837503\", \"event_type\":\"price_change\"}","ts_local_ms":1781254837974}
{"dir":"in","text":"{\"market\":\"0x9c535590faae21bf76fed844aa47fc3c5c82253ef38bd545bf12c93470502685\", \"price_changes\":[{\"asset_id\":\"56108879726720646120583724001239294777304794469144970684362785767667828318889\", \"price\":\"0.39\", \"size\":\"364.15\", \"side\":\"BUY\", \"hash\":\"78ff4801486aececec26f58e8c4c1e3fbf123f8e\", \"best_bid\":\"0.45\", \"best_ask\":\"0.46\"}, {\"asset_id\":\"107011546575057755426871645700605806081353395825571114128343592072429146374928\", \"price\":\"0.61\", \"size\":\"364.15\", \"side\":\"SELL\", \"hash\":\"7f08b8065dddac876c3b92c8abbe8ab5870066bd\", \"best_bid\":\"0.54\", \"best_ask\":\"0.55\"}], \"timestamp\":\"1781254837505\", \"event_type\":\"price_change\"}","ts_local_ms":1781254837974}
{"dir":"in","text":"{\"market\":\"0x9c535590faae21bf76fed844aa47fc3c5c82253ef38bd545bf12c93470502685\", \"price_changes\":[{\"asset_id\":\"107011546575057755426871645700605806081353395825571114128343592072429146374928\", \"price\":\"0.01\", \"size\":\"55001.6\", \"side\":\"BUY\", \"hash\":\"cdbafad1ba659ba9013be0b619111b468640e594\", \"best_bid\":\"0.54\", \"best_ask\":\"0.55\"}, {\"asset_id\":\"56108879726720646120583724001239294777304794469144970684362785767667828318889\", \"price\":\"0.99\", \"size\":\"55001.6\", \"side\":\"SELL\", \"hash\":\"a668a636a0be665053dd59f22c68b9b1885b01cc\", \"best_bid\":\"0.45\", \"best_ask\":\"0.46\"}], \"timestamp\":\"1781254837510\", \"event_type\":\"price_change\"}","ts_local_ms":1781254837974}
{"dir":"in","text":"{\"market\":\"0x9c535590faae21bf76fed844aa47fc3c5c82253ef38bd545bf12c93470502685\", \"price_changes\":[{\"asset_id\":\"107011546575057755426871645700605806081353395825571114128343592072429146374928\", \"price\":\"0.54\", \"size\":\"535.52\", \"side\":\"BUY\", \"hash\":\"d0ecfb283049e463b6aa9d5d63f76a8848428aa8\", \"best_bid\":\"0.54\", \"best_ask\":\"0.55\"}, {\"asset_id\":\"56108879726720646120583724001239294777304794469144970684362785767667828318889\", \"price\":\"0.46\", \"size\":\"535.52\", \"side\":\"SELL\", \"hash\":\"5fd9767c9d8a9c1eaad96b3e7b691f83e4005ad5\", \"best_bid\":\"0.45\", \"best_ask\":\"0.46\"}], \"timestamp\":\"1781254837510\", \"event_type\":\"price_change\"}","ts_local_ms":1781254837974}
{"dir":"in","text":"{\"market\":\"0x9c535590faae21bf76fed844aa47fc3c5c82253ef38bd545bf12c93470502685\", \"price_changes\":[{\"asset_id\":\"107011546575057755426871645700605806081353395825571114128343592072429146374928\", \"price\":\"0.54\", \"size\":\"524.52\", \"side\":\"BUY\", \"hash\":\"7d02abc494e975ac8bf57458be586324b6c26684\", \"best_bid\":\"0.54\", \"best_ask\":\"0.55\"}, {\"asset_id\":\"56108879726720646120583724001239294777304794469144970684362785767667828318889\", \"price\":\"0.46\", \"size\":\"524.52\", \"side\":\"SELL\", \"hash\":\"95ed4b112b190c4ae5bc43c1e632fa5c4f594f98\", \"best_bid\":\"0.45\", \"best_ask\":\"0.46\"}], \"timestamp\":\"1781254837512\", \"event_type\":\"price_change\"}","ts_local_ms":1781254837974}
{"dir":"in","text":"{\"market\":\"0x9c535590faae21bf76fed844aa47fc3c5c82253ef38bd545bf12c93470502685\", \"price_changes\":[{\"asset_id\":\"107011546575057755426871645700605806081353395825571114128343592072429146374928\", \"price\":\"0.54\", \"size\":\"516.52\", \"side\":\"BUY\", \"hash\":\"79eb520414da6beefbae615479fe19ce54fb6786\", \"best_bid\":\"0.54\", \"best_ask\":\"0.55\"}, {\"asset_id\":\"56108879726720646120583724001239294777304794469144970684362785767667828318889\", \"price\":\"0.46\", \"size\":\"516.52\", \"side\":\"SELL\", \"hash\":\"2ce07149d91df431a21036700c86c8df3b121eb3\", \"best_bid\":\"0.45\", \"best_ask\":\"0.46\"}], \"timestamp\":\"1781254837513\", \"event_type\":\"price_change\"}","ts_local_ms":1781254837974}
{"dir":"in","text":"{\"market\":\"0x9c535590faae21bf76fed844aa47fc3c5c82253ef38bd545bf12c93470502685\", \"price_changes\":[{\"asset_id\":\"107011546575057755426871645700605806081353395825571114128343592072429146374928\", \"price\":\"0.54\", \"size\":\"535.52\", \"side\":\"BUY\", \"hash\":\"268a24a9c46b181c878aacbbd8178d85c3f7c034\", \"best_bid\":\"0.54\", \"best_ask\":\"0.55\"}, {\"asset_id\":\"56108879726720646120583724001239294777304794469144970684362785767667828318889\", \"price\":\"0.46\", \"size\":\"535.52\", \"side\":\"SELL\", \"hash\":\"3f60a015e68437d14c45b303e686e50a039576a6\", \"best_bid\":\"0.45\", \"best_ask\":\"0.46\"}], \"timestamp\":\"1781254837514\", \"event_type\":\"price_change\"}","ts_local_ms":1781254837974}
{"dir":"in","text":"{\"market\":\"0x9c535590faae21bf76fed844aa47fc3c5c82253ef38bd545bf12c93470502685\", \"price_changes\":[{\"asset_id\":\"107011546575057755426871645700605806081353395825571114128343592072429146374928\", \"price\":\"0.54\", \"size\":\"520.52\", \"side\":\"BUY\", \"hash\":\"0476ab923c5d1f843bbd0581410144786589f4f9\", \"best_bid\":\"0.54\", \"best_ask\":\"0.55\"}, {\"asset_id\":\"56108879726720646120583724001239294777304794469144970684362785767667828318889\", \"price\":\"0.46\", \"size\":\"520.52\", \"side\":\"SELL\", \"hash\":\"64e9347a3ef67081f470511b32be56a675c56340\", \"best_bid\":\"0.45\", \"best_ask\":\"0.46\"}], \"timestamp\":\"1781254837523\", \"event_type\":\"price_change\"}","ts_local_ms":1781254837974}
{"dir":"in","text":"{\"market\":\"0x9c535590faae21bf76fed844aa47fc3c5c82253ef38bd545bf12c93470502685\", \"price_changes\":[{\"asset_id\":\"107011546575057755426871645700605806081353395825571114128343592072429146374928\", \"price\":\"0.54\", \"size\":\"533.52\", \"side\":\"BUY\", \"hash\":\"7e645ee253bb3661048f974106ba83d34a4fe4c7\", \"best_bid\":\"0.54\", \"best_ask\":\"0.55\"}, {\"asset_id\":\"56108879726720646120583724001239294777304794469144970684362785767667828318889\", \"price\":\"0.46\", \"size\":\"533.52\", \"side\":\"SELL\", \"hash\":\"f4ab0df0fbed75aac7893a6477214d1bf3852e4a\", \"best_bid\":\"0.45\", \"best_ask\":\"0.46\"}], \"timestamp\":\"1781254837525\", \"event_type\":\"price_change\"}","ts_local_ms":1781254837974}
{"dir":"in","text":"{\"market\":\"0x9c535590faae21bf76fed844aa47fc3c5c82253ef38bd545bf12c93470502685\", \"price_changes\":[{\"asset_id\":\"107011546575057755426871645700605806081353395825571114128343592072429146374928\", \"price\":\"0.54\", \"size\":\"561.52\", \"side\":\"BUY\", \"hash\":\"93c229f4627ce917e9792ad18031770a619e4ae4\", \"best_bid\":\"0.54\", \"best_ask\":\"0.55\"}, {\"asset_id\":\"56108879726720646120583724001239294777304794469144970684362785767667828318889\", \"price\":\"0.46\", \"size\":\"561.52\", \"side\":\"SELL\", \"hash\":\"ea384ad32049954e5956b9226abf2388ffe065a6\", \"best_bid\":\"0.45\", \"best_ask\":\"0.46\"}], \"timestamp\":\"1781254837526\", \"event_type\":\"price_change\"}","ts_local_ms":1781254837974}
{"dir":"in","text":"{\"market\":\"0x9c535590faae21bf76fed844aa47fc3c5c82253ef38bd545bf12c93470502685\", \"price_changes\":[{\"asset_id\":\"107011546575057755426871645700605806081353395825571114128343592072429146374928\", \"price\":\"0.54\", \"size\":\"601.52\", \"side\":\"BUY\", \"hash\":\"60f1e4ea3d4c533c6f154d7d9719b6d970c586f8\", \"best_bid\":\"0.54\", \"best_ask\":\"0.55\"}, {\"asset_id\":\"56108879726720646120583724001239294777304794469144970684362785767667828318889\", \"price\":\"0.46\", \"size\":\"601.52\", \"side\":\"SELL\", \"hash\":\"b66e7872cc0ed982ba081dc96848132c1e33ba7e\", \"best_bid\":\"0.45\", \"best_ask\":\"0.46\"}], \"timestamp\":\"1781254837527\", \"event_type\":\"price_change\"}","ts_local_ms":1781254837974}
{"dir":"in","text":"{\"market\":\"0x9c535590faae21bf76fed844aa47fc3c5c82253ef38bd545bf12c93470502685\", \"price_changes\":[{\"asset_id\":\"107011546575057755426871645700605806081353395825571114128343592072429146374928\", \"price\":\"0.54\", \"size\":\"589.52\", \"side\":\"BUY\", \"hash\":\"14c9d11e9501af0ce6321de0dbe693d588eabbcd\", \"best_bid\":\"0.54\", \"best_ask\":\"0.55\"}, {\"asset_id\":\"56108879726720646120583724001239294777304794469144970684362785767667828318889\", \"price\":\"0.46\", \"size\":\"589.52\", \"side\":\"SELL\", \"hash\":\"8e1e0c7a6f2306837dc070ca77a7505c9e753aec\", \"best_bid\":\"0.45\", \"best_ask\":\"0.46\"}], \"timestamp\":\"1781254837528\", \"event_type\":\"price_change\"}","ts_local_ms":1781254837974}
{"dir":"in","text":"{\"market\":\"0x9c535590faae21bf76fed844aa47fc3c5c82253ef38bd545bf12c93470502685\", \"price_changes\":[{\"asset_id\":\"107011546575057755426871645700605806081353395825571114128343592072429146374928\", \"price\":\"0.54\", \"size\":\"579.52\", \"side\":\"BUY\", \"hash\":\"7ff3deca1d97262558b9bc5f19a92ce1dded8560\", \"best_bid\":\"0.54\", \"best_ask\":\"0.55\"}, {\"asset_id\":\"56108879726720646120583724001239294777304794469144970684362785767667828318889\", \"price\":\"0.46\", \"size\":\"579.52\", \"side\":\"SELL\", \"hash\":\"ad37671cc744401efa92e3e5642a45fad06f5d82\", \"best_bid\":\"0.45\", \"best_ask\":\"0.46\"}], \"timestamp\":\"1781254837531\", \"event_type\":\"price_change\"}","ts_local_ms":1781254837974}
{"dir":"in","text":"{\"market\":\"0x9c535590faae21bf76fed844aa47fc3c5c82253ef38bd545bf12c93470502685\", \"price_changes\":[{\"asset_id\":\"107011546575057755426871645700605806081353395825571114128343592072429146374928\", \"price\":\"0.54\", \"size\":\"579.52\", \"side\":\"BUY\", \"hash\":\"7ff3deca1d97262558b9bc5f19a92ce1dded8560\", \"best_bid\":\"0.54\", \"best_ask\":\"0.55\"}, {\"asset_id\":\"56108879726720646120583724001239294777304794469144970684362785767667828318889\", \"price\":\"0.46\", \"size\":\"579.52\", \"side\":\"SELL\", \"hash\":\"ad37671cc744401efa92e3e5642a45fad06f5d82\", \"best_bid\":\"0.45\", \"best_ask\":\"0.46\"}], \"timestamp\":\"1781254837531\", \"event_type\":\"price_change\"}","ts_local_ms":1781254837974}
{"dir":"in","text":"{\"market\":\"0x9c535590faae21bf76fed844aa47fc3c5c82253ef38bd545bf12c93470502685\", \"price_changes\":[{\"asset_id\":\"107011546575057755426871645700605806081353395825571114128343592072429146374928\", \"price\":\"0.54\", \"size\":\"592.52\", \"side\":\"BUY\", \"hash\":\"1a62b78d2ad6d0468b90a5c02ba809ca65e14114\", \"best_bid\":\"0.54\", \"best_ask\":\"0.55\"}, {\"asset_id\":\"56108879726720646120583724001239294777304794469144970684362785767667828318889\", \"price\":\"0.46\", \"size\":\"592.52\", \"side\":\"SELL\", \"hash\":\"9641c28521cb0b073283f1bee3722b715f2cdc77\", \"best_bid\":\"0.45\", \"best_ask\":\"0.46\"}], \"timestamp\":\"1781254837532\", \"event_type\":\"price_change\"}","ts_local_ms":1781254837974}
{"dir":"in","text":"{\"market\":\"0x9c535590faae21bf76fed844aa47fc3c5c82253ef38bd545bf12c93470502685\", \"price_changes\":[{\"asset_id\":\"107011546575057755426871645700605806081353395825571114128343592072429146374928\", \"price\":\"0.01\", \"size\":\"55006.61\", \"side\":\"BUY\", \"hash\":\"50e964dd50c6dc5ea1b4571c2929b2658338744d\", \"best_bid\":\"0.54\", \"best_ask\":\"0.55\"}, {\"asset_id\":\"56108879726720646120583724001239294777304794469144970684362785767667828318889\", \"price\":\"0.99\", \"size\":\"55006.61\", \"side\":\"SELL\", \"hash\":\"c091548d949101e7e9970bfd86df8ac4dfc05904\", \"best_bid\":\"0.45\", \"best_ask\":\"0.46\"}], \"timestamp\":\"1781254837533\", \"event_type\":\"price_change\"}","ts_local_ms":1781254837974}
{"dir":"in","text":"{\"market\":\"0x9c535590faae21bf76fed844aa47fc3c5c82253ef38bd545bf12c93470502685\", \"price_changes\":[{\"asset_id\":\"107011546575057755426871645700605806081353395825571114128343592072429146374928\", \"price\":\"0.54\", \"size\":\"580.52\", \"side\":\"BUY\", \"hash\":\"c4737a1505a796d92be2a2e83e34ad5172db1c68\", \"best_bid\":\"0.54\", \"best_ask\":\"0.55\"}, {\"asset_id\":\"56108879726720646120583724001239294777304794469144970684362785767667828318889\", \"price\":\"0.46\", \"size\":\"580.52\", \"side\":\"SELL\", \"hash\":\"e79c7c7e4a2360712916a4d22cb815222d49c739\", \"best_bid\":\"0.45\", \"best_ask\":\"0.46\"}], \"timestamp\":\"1781254837534\", \"event_type\":\"price_change\"}","ts_local_ms":1781254837974}
{"dir":"in","text":"{\"market\":\"0x9c535590faae21bf76fed844aa47fc3c5c82253ef38bd545bf12c93470502685\", \"price_changes\":[{\"asset_id\":\"107011546575057755426871645700605806081353395825571114128343592072429146374928\", \"price\":\"0.54\", \"size\":\"593.52\", \"side\":\"BUY\", \"hash\":\"13bba709601eb1d8fa261055254f5331e2679079\", \"best_bid\":\"0.54\", \"best_ask\":\"0.55\"}, {\"asset_id\":\"56108879726720646120583724001239294777304794469144970684362785767667828318889\", \"price\":\"0.46\", \"size\":\"593.52\", \"side\":\"SELL\", \"hash\":\"5aacb64ecf0375fbd250eb87a71193eef8f09819\", \"best_bid\":\"0.45\", \"best_ask\":\"0.46\"}], \"timestamp\":\"1781254837536\", \"event_type\":\"price_change\"}","ts_local_ms":1781254837974}
{"dir":"in","text":"{\"market\":\"0x9c535590faae21bf76fed844aa47fc3c5c82253ef38bd545bf12c93470502685\", \"price_changes\":[{\"asset_id\":\"107011546575057755426871645700605806081353395825571114128343592072429146374928\", \"price\":\"0.54\", \"size\":\"582.52\", \"side\":\"BUY\", \"hash\":\"a1d27f09def075d396aeb61cd1b671824b8945e9\", \"best_bid\":\"0.54\", \"best_ask\":\"0.55\"}, {\"asset_id\":\"56108879726720646120583724001239294777304794469144970684362785767667828318889\", \"price\":\"0.46\", \"size\":\"582.52\", \"side\":\"SELL\", \"hash\":\"9e9fc0e082db71b6f48914826dd97b899c763bcf\", \"best_bid\":\"0.45\", \"best_ask\":\"0.46\"}], \"timestamp\":\"1781254837536\", \"event_type\":\"price_change\"}","ts_local_ms":1781254837974}
{"dir":"in","text":"{\"market\":\"0x9c535590faae21bf76fed844aa47fc3c5c82253ef38bd545bf12c93470502685\", \"price_changes\":[{\"asset_id\":\"107011546575057755426871645700605806081353395825571114128343592072429146374928\", \"price\":\"0.54\", \"size\":\"570.52\", \"side\":\"BUY\", \"hash\":\"15af93ee4c92426126d19fbe1b5cca24566d6c7b\", \"best_bid\":\"0.54\", \"best_ask\":\"0.55\"}, {\"asset_id\":\"56108879726720646120583724001239294777304794469144970684362785767667828318889\", \"price\":\"0.46\", \"size\":\"570.52\", \"side\":\"SELL\", \"hash\":\"427ba96fb5208bb59e3606cb8ecdbb79576d9a4b\", \"best_bid\":\"0.45\", \"best_ask\":\"0.46\"}], \"timestamp\":\"1781254837537\", \"event_type\":\"price_change\"}","ts_local_ms":1781254837974}
{"dir":"in","text":"{\"market\":\"0x9c535590faae21bf76fed844aa47fc3c5c82253ef38bd545bf12c93470502685\", \"price_changes\":[{\"asset_id\":\"107011546575057755426871645700605806081353395825571114128343592072429146374928\", \"price\":\"0.54\", \"size\":\"580.52\", \"side\":\"BUY\", \"hash\":\"da480a1cf178387e192a9a48e87e04f7295f89b3\", \"best_bid\":\"0.54\", \"best_ask\":\"0.55\"}, {\"asset_id\":\"56108879726720646120583724001239294777304794469144970684362785767667828318889\", \"price\":\"0.46\", \"size\":\"580.52\", \"side\":\"SELL\", \"hash\":\"3a991e0d6c880ee9d54160a1e15b8e087e014e1c\", \"best_bid\":\"0.45\", \"best_ask\":\"0.46\"}], \"timestamp\":\"1781254837538\", \"event_type\":\"price_change\"}","ts_local_ms":1781254837974}
{"dir":"in","text":"{\"market\":\"0x9c535590faae21bf76fed844aa47fc3c5c82253ef38bd545bf12c93470502685\", \"price_changes\":[{\"asset_id\":\"107011546575057755426871645700605806081353395825571114128343592072429146374928\", \"price\":\"0.01\", \"size\":\"55011.61\", \"side\":\"BUY\", \"hash\":\"de626a84fd31573b0ab79b4d0d28879145e5215f\", \"best_bid\":\"0.54\", \"best_ask\":\"0.55\"}, {\"asset_id\":\"56108879726720646120583724001239294777304794469144970684362785767667828318889\", \"price\":\"0.99\", \"size\":\"55011.61\", \"side\":\"SELL\", \"hash\":\"25f75428bc21ffe4a41dfd125bd83f7219bf9f31\", \"best_bid\":\"0.45\", \"best_ask\":\"0.46\"}], \"timestamp\":\"1781254837540\", \"event_type\":\"price_change\"}","ts_local_ms":1781254837974}
{"dir":"in","text":"{\"market\":\"0x9c535590faae21bf76fed844aa47fc3c5c82253ef38bd545bf12c93470502685\", \"price_changes\":[{\"asset_id\":\"107011546575057755426871645700605806081353395825571114128343592072429146374928\", \"price\":\"0.5\", \"size\":\"453.08\", \"side\":\"BUY\", \"hash\":\"4a263170856555a83c96e71e29bbd8aff86137ce\", \"best_bid\":\"0.54\", \"best_ask\":\"0.55\"}, {\"asset_id\":\"56108879726720646120583724001239294777304794469144970684362785767667828318889\", \"price\":\"0.5\", \"size\":\"453.08\", \"side\":\"SELL\", \"hash\":\"e55a78feebc233a862999cc7e2863a72b58183ec\", \"best_bid\":\"0.45\", \"best_ask\":\"0.46\"}], \"timestamp\":\"1781254837545\", \"event_type\":\"price_change\"}","ts_local_ms":1781254837974}
{"dir":"in","text":"{\"market\":\"0x9c535590faae21bf76fed844aa47fc3c5c82253ef38bd545bf12c93470502685\", \"price_changes\":[{\"asset_id\":\"107011546575057755426871645700605806081353395825571114128343592072429146374928\", \"price\":\"0.54\", \"size\":\"556.52\", \"side\":\"BUY\", \"hash\":\"1fae60057c5b3949721a7ea8e1a2cc63b53c3f58\", \"best_bid\":\"0.54\", \"best_ask\":\"0.55\"}, {\"asset_id\":\"56108879726720646120583724001239294777304794469144970684362785767667828318889\", \"price\":\"0.46\", \"size\":\"556.52\", \"side\":\"SELL\", \"hash\":\"1eb02846e80d04eee59f9034b0ea5e0fc1c23645\", \"best_bid\":\"0.45\", \"best_ask\":\"0.46\"}], \"timestamp\":\"1781254837548\", \"event_type\":\"price_change\"}","ts_local_ms":1781254837975}
{"dir":"in","text":"{\"market\":\"0x9c535590faae21bf76fed844aa47fc3c5c82253ef38bd545bf12c93470502685\", \"price_changes\":[{\"asset_id\":\"107011546575057755426871645700605806081353395825571114128343592072429146374928\", \"price\":\"0.54\", \"size\":\"566.52\", \"side\":\"BUY\", \"hash\":\"d34735edac4a0f0cab3ce81e6e1d42a623b35d8d\", \"best_bid\":\"0.54\", \"best_ask\":\"0.55\"}, {\"asset_id\":\"56108879726720646120583724001239294777304794469144970684362785767667828318889\", \"price\":\"0.46\", \"size\":\"566.52\", \"side\":\"SELL\", \"hash\":\"6fedc9fb99fb4ca1c4b0447ae1f4954cc66b7878\", \"best_bid\":\"0.45\", \"best_ask\":\"0.46\"}], \"timestamp\":\"1781254837549\", \"event_type\":\"price_change\"}","ts_local_ms":1781254837975}
{"dir":"in","text":"{\"market\":\"0x9c535590faae21bf76fed844aa47fc3c5c82253ef38bd545bf12c93470502685\", \"price_changes\":[{\"asset_id\":\"107011546575057755426871645700605806081353395825571114128343592072429146374928\", \"price\":\"0.54\", \"size\":\"576.52\", \"side\":\"BUY\", \"hash\":\"e6647f6419d67bdfd74fb3500d85c4754db3fe1d\", \"best_bid\":\"0.54\", \"best_ask\":\"0.55\"}, {\"asset_id\":\"56108879726720646120583724001239294777304794469144970684362785767667828318889\", \"price\":\"0.46\", \"size\":\"576.52\", \"side\":\"SELL\", \"hash\":\"c543e27c092e83baaaf38d367f845ceefe8c5c74\", \"best_bid\":\"0.45\", \"best_ask\":\"0.46\"}], \"timestamp\":\"1781254837550\", \"event_type\":\"price_change\"}","ts_local_ms":1781254837975}
{"dir":"in","text":"{\"market\":\"0x9c535590faae21bf76fed844aa47fc3c5c82253ef38bd545bf12c93470502685\", \"price_changes\":[{\"asset_id\":\"107011546575057755426871645700605806081353395825571114128343592072429146374928\", \"price\":\"0.54\", \"size\":\"564.52\", \"side\":\"BUY\", \"hash\":\"5159511f35fc1a149916a8332bf84e4f916a03af\", \"best_bid\":\"0.54\", \"best_ask\":\"0.55\"}, {\"asset_id\":\"56108879726720646120583724001239294777304794469144970684362785767667828318889\", \"price\":\"0.46\", \"size\":\"564.52\", \"side\":\"SELL\", \"hash\":\"7508eaa861471df20c245fbb027f264061624384\", \"best_bid\":\"0.45\", \"best_ask\":\"0.46\"}], \"timestamp\":\"1781254837550\", \"event_type\":\"price_change\"}","ts_local_ms":1781254837975}
{"dir":"in","text":"{\"market\":\"0x9c535590faae21bf76fed844aa47fc3c5c82253ef38bd545bf12c93470502685\", \"price_changes\":[{\"asset_id\":\"107011546575057755426871645700605806081353395825571114128343592072429146374928\", \"price\":\"0.55\", \"size\":\"139.55\", \"side\":\"SELL\", \"hash\":\"9c157730bf926265989f855ebe71d82c3af78561\", \"best_bid\":\"0.54\", \"best_ask\":\"0.55\"}, {\"asset_id\":\"56108879726720646120583724001239294777304794469144970684362785767667828318889\", \"price\":\"0.45\", \"size\":\"139.55\", \"side\":\"BUY\", \"hash\":\"a5e2c78791b23c800985dddfd86ae79abf010c37\", \"best_bid\":\"0.45\", \"best_ask\":\"0.46\"}], \"timestamp\":\"1781254837553\", \"event_type\":\"price_change\"}","ts_local_ms":1781254837975}
{"dir":"in","text":"{\"market\":\"0x9c535590faae21bf76fed844aa47fc3c5c82253ef38bd545bf12c93470502685\", \"price_changes\":[{\"asset_id\":\"107011546575057755426871645700605806081353395825571114128343592072429146374928\", \"price\":\"0.01\", \"size\":\"55016.61\", \"side\":\"BUY\", \"hash\":\"6fbec3ed93522c7cd1745c8b962d31c454ea8b9e\", \"best_bid\":\"0.54\", \"best_ask\":\"0.55\"}, {\"asset_id\":\"56108879726720646120583724001239294777304794469144970684362785767667828318889\", \"price\":\"0.99\", \"size\":\"55016.61\", \"side\":\"SELL\", \"hash\":\"2c0c267a9defda12ab23bdf1864d35184ae05576\", \"best_bid\":\"0.45\", \"best_ask\":\"0.46\"}], \"timestamp\":\"1781254837554\", \"event_type\":\"price_change\"}","ts_local_ms":1781254837975}
{"dir":"in","text":"{\"market\":\"0x9c535590faae21bf76fed844aa47fc3c5c82253ef38bd545bf12c93470502685\", \"price_changes\":[{\"asset_id\":\"107011546575057755426871645700605806081353395825571114128343592072429146374928\", \"price\":\"0.52\", \"size\":\"225.79\", \"side\":\"BUY\", \"hash\":\"ea5588961e77f563db649dbe7367bec3f7fa0b5e\", \"best_bid\":\"0.54\", \"best_ask\":\"0.55\"}, {\"asset_id\":\"56108879726720646120583724001239294777304794469144970684362785767667828318889\", \"price\":\"0.48\", \"size\":\"225.79\", \"side\":\"SELL\", \"hash\":\"aad27fb3cba7659561841163d9651c53bf4e652c\", \"best_bid\":\"0.45\", \"best_ask\":\"0.46\"}], \"timestamp\":\"1781254837555\", \"event_type\":\"price_change\"}","ts_local_ms":1781254837975}
{"dir":"in","text":"{\"market\":\"0x9c535590faae21bf76fed844aa47fc3c5c82253ef38bd545bf12c93470502685\", \"price_changes\":[{\"asset_id\":\"107011546575057755426871645700605806081353395825571114128343592072429146374928\", \"price\":\"0.54\", \"size\":\"581.52\", \"side\":\"BUY\", \"hash\":\"a524966ff4b495248d1d88c91275b05511b536a2\", \"best_bid\":\"0.54\", \"best_ask\":\"0.55\"}, {\"asset_id\":\"56108879726720646120583724001239294777304794469144970684362785767667828318889\", \"price\":\"0.46\", \"size\":\"581.52\", \"side\":\"SELL\", \"hash\":\"0b107ef9b13461bd0361e2a651e53323f6f63e44\", \"best_bid\":\"0.45\", \"best_ask\":\"0.46\"}], \"timestamp\":\"1781254837556\", \"event_type\":\"price_change\"}","ts_local_ms":1781254837975}
{"dir":"in","text":"{\"market\":\"0x9c535590faae21bf76fed844aa47fc3c5c82253ef38bd545bf12c93470502685\", \"price_changes\":[{\"asset_id\":\"107011546575057755426871645700605806081353395825571114128343592072429146374928\", \"price\":\"0.54\", \"size\":\"570.52\", \"side\":\"BUY\", \"hash\":\"16efa4f5ab9b7a0f46cbc022b1a5adb319cd1072\", \"best_bid\":\"0.54\", \"best_ask\":\"0.55\"}, {\"asset_id\":\"56108879726720646120583724001239294777304794469144970684362785767667828318889\", \"price\":\"0.46\", \"size\":\"570.52\", \"side\":\"SELL\", \"hash\":\"27bb6ecc90059e2b92a7c4649d230f6efafb6694\", \"best_bid\":\"0.45\", \"best_ask\":\"0.46\"}], \"timestamp\":\"1781254837556\", \"event_type\":\"price_change\"}","ts_local_ms":1781254837975}
{"dir":"in","text":"{\"market\":\"0x9c535590faae21bf76fed844aa47fc3c5c82253ef38bd545bf12c93470502685\", \"price_changes\":[{\"asset_id\":\"56108879726720646120583724001239294777304794469144970684362785767667828318889\", \"price\":\"0.45\", \"size\":\"110\", \"side\":\"BUY\", \"hash\":\"1fba12ee4065f759606b7c00b8dec6e53ec69d03\", \"best_bid\":\"0.45\", \"best_ask\":\"0.46\"}, {\"asset_id\":\"107011546575057755426871645700605806081353395825571114128343592072429146374928\", \"price\":\"0.55\", \"size\":\"110\", \"side\":\"SELL\", \"hash\":\"1073593a481965c9e78d0c08ee43c63fef8d2056\", \"best_bid\":\"0.54\", \"best_ask\":\"0.55\"}], \"timestamp\":\"1781254837558\", \"event_type\":\"price_change\"}","ts_local_ms":1781254837975}
{"dir":"in","text":"{\"market\":\"0x9c535590faae21bf76fed844aa47fc3c5c82253ef38bd545bf12c93470502685\", \"price_changes\":[{\"asset_id\":\"107011546575057755426871645700605806081353395825571114128343592072429146374928\", \"price\":\"0.54\", \"size\":\"558.52\", \"side\":\"BUY\", \"hash\":\"785ab47a90510d367247b3efea1c087e63a8eac5\", \"best_bid\":\"0.54\", \"best_ask\":\"0.55\"}, {\"asset_id\":\"56108879726720646120583724001239294777304794469144970684362785767667828318889\", \"price\":\"0.46\", \"size\":\"558.52\", \"side\":\"SELL\", \"hash\":\"8473513a374f5d857e69cd08c590f0f7fdc8fd5f\", \"best_bid\":\"0.45\", \"best_ask\":\"0.46\"}], \"timestamp\":\"1781254837558\", \"event_type\":\"price_change\"}","ts_local_ms":1781254837975}
{"dir":"in","text":"{\"market\":\"0x9c535590faae21bf76fed844aa47fc3c5c82253ef38bd545bf12c93470502685\", \"price_changes\":[{\"asset_id\":\"107011546575057755426871645700605806081353395825571114128343592072429146374928\", \"price\":\"0.01\", \"size\":\"55011.61\", \"side\":\"BUY\", \"hash\":\"d8bd53d4936b79247063c6aea16e7380a17c966c\", \"best_bid\":\"0.54\", \"best_ask\":\"0.55\"}, {\"asset_id\":\"56108879726720646120583724001239294777304794469144970684362785767667828318889\", \"price\":\"0.99\", \"size\":\"55011.61\", \"side\":\"SELL\", \"hash\":\"95a2f90980d8ba22414cabf7db6f547f6845119f\", \"best_bid\":\"0.45\", \"best_ask\":\"0.46\"}], \"timestamp\":\"1781254837559\", \"event_type\":\"price_change\"}","ts_local_ms":1781254837975}
{"dir":"in","text":"{\"market\":\"0x9c535590faae21bf76fed844aa47fc3c5c82253ef38bd545bf12c93470502685\", \"price_changes\":[{\"asset_id\":\"107011546575057755426871645700605806081353395825571114128343592072429146374928\", \"price\":\"0.54\", \"size\":\"569.52\", \"side\":\"BUY\", \"hash\":\"b42f0afb5f7aaab9a38894eccd68aa24af61dd4c\", \"best_bid\":\"0.54\", \"best_ask\":\"0.55\"}, {\"asset_id\":\"56108879726720646120583724001239294777304794469144970684362785767667828318889\", \"price\":\"0.46\", \"size\":\"569.52\", \"side\":\"SELL\", \"hash\":\"cd59fa78beb875c99c8955e0b651d4bf26fd84b0\", \"best_bid\":\"0.45\", \"best_ask\":\"0.46\"}], \"timestamp\":\"1781254837562\", \"event_type\":\"price_change\"}","ts_local_ms":1781254837975}
{"dir":"in","text":"{\"market\":\"0x9c535590faae21bf76fed844aa47fc3c5c82253ef38bd545bf12c93470502685\", \"price_changes\":[{\"asset_id\":\"107011546575057755426871645700605806081353395825571114128343592072429146374928\", \"price\":\"0.54\", \"size\":\"580.52\", \"side\":\"BUY\", \"hash\":\"dad2beac53167494d6a2c9e96798a4989bf7f965\", \"best_bid\":\"0.54\", \"best_ask\":\"0.55\"}, {\"asset_id\":\"56108879726720646120583724001239294777304794469144970684362785767667828318889\", \"price\":\"0.46\", \"size\":\"580.52\", \"side\":\"SELL\", \"hash\":\"e4e571dec51ddabfe93c2cd4626eae73625395a4\", \"best_bid\":\"0.45\", \"best_ask\":\"0.46\"}], \"timestamp\":\"1781254837562\", \"event_type\":\"price_change\"}","ts_local_ms":1781254837975}
{"dir":"in","text":"{\"market\":\"0x9c535590faae21bf76fed844aa47fc3c5c82253ef38bd545bf12c93470502685\", \"price_changes\":[{\"asset_id\":\"107011546575057755426871645700605806081353395825571114128343592072429146374928\", \"price\":\"0.54\", \"size\":\"568.52\", \"side\":\"BUY\", \"hash\":\"b56c30f9cdef7c24a3e4a7bf0541329f20290b59\", \"best_bid\":\"0.54\", \"best_ask\":\"0.55\"}, {\"asset_id\":\"56108879726720646120583724001239294777304794469144970684362785767667828318889\", \"price\":\"0.46\", \"size\":\"568.52\", \"side\":\"SELL\", \"hash\":\"030dae67bea1224b95d06c1c73741c5bebacf691\", \"best_bid\":\"0.45\", \"best_ask\":\"0.46\"}], \"timestamp\":\"1781254837567\", \"event_type\":\"price_change\"}","ts_local_ms":1781254837975}
{"dir":"in","text":"{\"market\":\"0x9c535590faae21bf76fed844aa47fc3c5c82253ef38bd545bf12c93470502685\", \"price_changes\":[{\"asset_id\":\"107011546575057755426871645700605806081353395825571114128343592072429146374928\", \"price\":\"0.54\", \"size\":\"578.52\", \"side\":\"BUY\", \"hash\":\"bb39060a7920d50fe7ef5a9bb0d37207904c517d\", \"best_bid\":\"0.54\", \"best_ask\":\"0.55\"}, {\"asset_id\":\"56108879726720646120583724001239294777304794469144970684362785767667828318889\", \"price\":\"0.46\", \"size\":\"578.52\", \"side\":\"SELL\", \"hash\":\"a37c0255fc7c3baab40e33d22c6a146ae6eb6147\", \"best_bid\":\"0.45\", \"best_ask\":\"0.46\"}], \"timestamp\":\"1781254837572\", \"event_type\":\"price_change\"}","ts_local_ms":1781254837975}
{"dir":"in","text":"{\"market\":\"0x9c535590faae21bf76fed844aa47fc3c5c82253ef38bd545bf12c93470502685\", \"price_changes\":[{\"asset_id\":\"107011546575057755426871645700605806081353395825571114128343592072429146374928\", \"price\":\"0.01\", \"size\":\"55006.6\", \"side\":\"BUY\", \"hash\":\"cf926f8bd61e41de78aa61296fce9e8a163c450e\", \"best_bid\":\"0.54\", \"best_ask\":\"0.55\"}, {\"asset_id\":\"56108879726720646120583724001239294777304794469144970684362785767667828318889\", \"price\":\"0.99\", \"size\":\"55006.6\", \"side\":\"SELL\", \"hash\":\"7f2d1a82c4b1873f8461f10832bbd74f7a96dfaa\", \"best_bid\":\"0.45\", \"best_ask\":\"0.46\"}], \"timestamp\":\"1781254837574\", \"event_type\":\"price_change\"}","ts_local_ms":1781254837975}
{"dir":"in","text":"{\"market\":\"0x9c535590faae21bf76fed844aa47fc3c5c82253ef38bd545bf12c93470502685\", \"price_changes\":[{\"asset_id\":\"107011546575057755426871645700605806081353395825571114128343592072429146374928\", \"price\":\"0.54\", \"size\":\"565.52\", \"side\":\"BUY\", \"hash\":\"32d3e46edc05154c6cc97ee4b1970d35bcbaefb9\", \"best_bid\":\"0.54\", \"best_ask\":\"0.55\"}, {\"asset_id\":\"56108879726720646120583724001239294777304794469144970684362785767667828318889\", \"price\":\"0.46\", \"size\":\"565.52\", \"side\":\"SELL\", \"hash\":\"fcee1845cb919c4ab4bb8f77f2d1268ae5966745\", \"best_bid\":\"0.45\", \"best_ask\":\"0.46\"}], \"timestamp\":\"1781254837574\", \"event_type\":\"price_change\"}","ts_local_ms":1781254837975}
{"dir":"in","text":"{\"market\":\"0x9c535590faae21bf76fed844aa47fc3c5c82253ef38bd545bf12c93470502685\", \"price_changes\":[{\"asset_id\":\"107011546575057755426871645700605806081353395825571114128343592072429146374928\", \"price\":\"0.54\", \"size\":\"575.52\", \"side\":\"BUY\", \"hash\":\"6fe35e1062d7e82342b1231bb48aeda5d4bbe51a\", \"best_bid\":\"0.54\", \"best_ask\":\"0.55\"}, {\"asset_id\":\"56108879726720646120583724001239294777304794469144970684362785767667828318889\", \"price\":\"0.46\", \"size\":\"575.52\", \"side\":\"SELL\", \"hash\":\"2e20f6f83a04c1ade0e1beb23948fef02beed847\", \"best_bid\":\"0.45\", \"best_ask\":\"0.46\"}], \"timestamp\":\"1781254837574\", \"event_type\":\"price_change\"}","ts_local_ms":1781254837975}
{"dir":"in","text":"{\"market\":\"0x9c535590faae21bf76fed844aa47fc3c5c82253ef38bd545bf12c93470502685\", \"price_changes\":[{\"asset_id\":\"107011546575057755426871645700605806081353395825571114128343592072429146374928\", \"price\":\"0.54\", \"size\":\"585.52\", \"side\":\"BUY\", \"hash\":\"13b00f55fa4ee8ca8eff9d0aff2475711625f372\", \"best_bid\":\"0.54\", \"best_ask\":\"0.55\"}, {\"asset_id\":\"56108879726720646120583724001239294777304794469144970684362785767667828318889\", \"price\":\"0.46\", \"size\":\"585.52\", \"side\":\"SELL\", \"hash\":\"49de77f7fcc2b97328b279f9394197009d6746c7\", \"best_bid\":\"0.45\", \"best_ask\":\"0.46\"}], \"timestamp\":\"1781254837576\", \"event_type\":\"price_change\"}","ts_local_ms":1781254837975}
{"dir":"in","text":"{\"market\":\"0x9c535590faae21bf76fed844aa47fc3c5c82253ef38bd545bf12c93470502685\", \"price_changes\":[{\"asset_id\":\"107011546575057755426871645700605806081353395825571114128343592072429146374928\", \"price\":\"0.54\", \"size\":\"608.52\", \"side\":\"BUY\", \"hash\":\"0168441e9150294ca7c1e23963678d8aceaabf76\", \"best_bid\":\"0.54\", \"best_ask\":\"0.55\"}, {\"asset_id\":\"56108879726720646120583724001239294777304794469144970684362785767667828318889\", \"price\":\"0.46\", \"size\":\"608.52\", \"side\":\"SELL\", \"hash\":\"f2ccbb16e1b21515c44a024c2cabb513198f8c01\", \"best_bid\":\"0.45\", \"best_ask\":\"0.46\"}], \"timestamp\":\"1781254837578\", \"event_type\":\"price_change\"}","ts_local_ms":1781254837975}
{"dir":"in","text":"{\"market\":\"0x9c535590faae21bf76fed844aa47fc3c5c82253ef38bd545bf12c93470502685\", \"price_changes\":[{\"asset_id\":\"56108879726720646120583724001239294777304794469144970684362785767667828318889\", \"price\":\"0.42\", \"size\":\"148.07\", \"side\":\"BUY\", \"hash\":\"d171e6c5b930f5725cc3ef02b7d5ec6425d82080\", \"best_bid\":\"0.45\", \"best_ask\":\"0.46\"}, {\"asset_id\":\"107011546575057755426871645700605806081353395825571114128343592072429146374928\", \"price\":\"0.58\", \"size\":\"148.07\", \"side\":\"SELL\", \"hash\":\"c7a7a728032c19deac81f4f8141bdfd1cc97b249\", \"best_bid\":\"0.54\", \"best_ask\":\"0.55\"}], \"timestamp\":\"1781254837583\", \"event_type\":\"price_change\"}","ts_local_ms":1781254837975}
{"dir":"in","text":"{\"market\":\"0x9c535590faae21bf76fed844aa47fc3c5c82253ef38bd545bf12c93470502685\", \"price_changes\":[{\"asset_id\":\"107011546575057755426871645700605806081353395825571114128343592072429146374928\", \"price\":\"0.01\", \"size\":\"55012.6\", \"side\":\"BUY\", \"hash\":\"83c3c614fae0551ec584f9313c906fadb39852c3\", \"best_bid\":\"0.54\", \"best_ask\":\"0.55\"}, {\"asset_id\":\"56108879726720646120583724001239294777304794469144970684362785767667828318889\", \"price\":\"0.99\", \"size\":\"55012.6\", \"side\":\"SELL\", \"hash\":\"de4a698f6ebce63876c13d2f27eafd91f1299b73\", \"best_bid\":\"0.45\", \"best_ask\":\"0.46\"}], \"timestamp\":\"1781254837585\", \"event_type\":\"price_change\"}","ts_local_ms":1781254837975}
{"dir":"in","text":"{\"market\":\"0x9c535590faae21bf76fed844aa47fc3c5c82253ef38bd545bf12c93470502685\", \"price_changes\":[{\"asset_id\":\"107011546575057755426871645700605806081353395825571114128343592072429146374928\", \"price\":\"0.54\", \"size\":\"589.52\", \"side\":\"BUY\", \"hash\":\"5cd58d85bd88894551eac3354065cfc2acb25ace\", \"best_bid\":\"0.54\", \"best_ask\":\"0.55\"}, {\"asset_id\":\"56108879726720646120583724001239294777304794469144970684362785767667828318889\", \"price\":\"0.46\", \"size\":\"589.52\", \"side\":\"SELL\", \"hash\":\"e538965e4bceff2b2c37a4ff04d73b5bbd5b6a37\", \"best_bid\":\"0.45\", \"best_ask\":\"0.46\"}], \"timestamp\":\"1781254837593\", \"event_type\":\"price_change\"}","ts_local_ms":1781254837975}
{"dir":"in","text":"{\"market\":\"0x9c535590faae21bf76fed844aa47fc3c5c82253ef38bd545bf12c93470502685\", \"price_changes\":[{\"asset_id\":\"107011546575057755426871645700605806081353395825571114128343592072429146374928\", \"price\":\"0.54\", \"size\":\"600.52\", \"side\":\"BUY\", \"hash\":\"027a8e9078d079c3b698ea2109e4c8ade4b39c8b\", \"best_bid\":\"0.54\", \"best_ask\":\"0.55\"}, {\"asset_id\":\"56108879726720646120583724001239294777304794469144970684362785767667828318889\", \"price\":\"0.46\", \"size\":\"600.52\", \"side\":\"SELL\", \"hash\":\"6e6d40e845b8d991ce929b3a7ef463d71ea45cf6\", \"best_bid\":\"0.45\", \"best_ask\":\"0.46\"}], \"timestamp\":\"1781254837594\", \"event_type\":\"price_change\"}","ts_local_ms":1781254837976}
{"dir":"in","text":"{\"market\":\"0x9c535590faae21bf76fed844aa47fc3c5c82253ef38bd545bf12c93470502685\", \"price_changes\":[{\"asset_id\":\"107011546575057755426871645700605806081353395825571114128343592072429146374928\", \"price\":\"0.54\", \"size\":\"610.52\", \"side\":\"BUY\", \"hash\":\"800909a29a8473df3f28f63529c519f06f9be6b3\", \"best_bid\":\"0.54\", \"best_ask\":\"0.55\"}, {\"asset_id\":\"56108879726720646120583724001239294777304794469144970684362785767667828318889\", \"price\":\"0.46\", \"size\":\"610.52\", \"side\":\"SELL\", \"hash\":\"2c060901a552bd6b36393c746bd94efd6e5e737c\", \"best_bid\":\"0.45\", \"best_ask\":\"0.46\"}], \"timestamp\":\"1781254837596\", \"event_type\":\"price_change\"}","ts_local_ms":1781254837976}
{"dir":"in","text":"{\"market\":\"0x9c535590faae21bf76fed844aa47fc3c5c82253ef38bd545bf12c93470502685\", \"price_changes\":[{\"asset_id\":\"107011546575057755426871645700605806081353395825571114128343592072429146374928\", \"price\":\"0.54\", \"size\":\"597.52\", \"side\":\"BUY\", \"hash\":\"3e5e366e400dbae90c7aab8909bb8e0a5a81bc37\", \"best_bid\":\"0.54\", \"best_ask\":\"0.55\"}, {\"asset_id\":\"56108879726720646120583724001239294777304794469144970684362785767667828318889\", \"price\":\"0.46\", \"size\":\"597.52\", \"side\":\"SELL\", \"hash\":\"ee43a1e00edf904c5d969beb4e21cc0b192d6b1d\", \"best_bid\":\"0.45\", \"best_ask\":\"0.46\"}], \"timestamp\":\"1781254837597\", \"event_type\":\"price_change\"}","ts_local_ms":1781254837976}
{"dir":"in","text":"{\"market\":\"0x9c535590faae21bf76fed844aa47fc3c5c82253ef38bd545bf12c93470502685\", \"price_changes\":[{\"asset_id\":\"107011546575057755426871645700605806081353395825571114128343592072429146374928\", \"price\":\"0.54\", \"size\":\"584.52\", \"side\":\"BUY\", \"hash\":\"a08f7311f43eece9533ec997b2942811e21b71fe\", \"best_bid\":\"0.54\", \"best_ask\":\"0.55\"}, {\"asset_id\":\"56108879726720646120583724001239294777304794469144970684362785767667828318889\", \"price\":\"0.46\", \"size\":\"584.52\", \"side\":\"SELL\", \"hash\":\"cc310044e5f66a15b1269754a8645f373c6c8353\", \"best_bid\":\"0.45\", \"best_ask\":\"0.46\"}], \"timestamp\":\"1781254837601\", \"event_type\":\"price_change\"}","ts_local_ms":1781254837976}
{"dir":"in","text":"{\"market\":\"0x9c535590faae21bf76fed844aa47fc3c5c82253ef38bd545bf12c93470502685\", \"price_changes\":[{\"asset_id\":\"107011546575057755426871645700605806081353395825571114128343592072429146374928\", \"price\":\"0.54\", \"size\":\"596.52\", \"side\":\"BUY\", \"hash\":\"a4d7fb98d00c591644480ff007e360b961e4656b\", \"best_bid\":\"0.54\", \"best_ask\":\"0.55\"}, {\"asset_id\":\"56108879726720646120583724001239294777304794469144970684362785767667828318889\", \"price\":\"0.46\", \"size\":\"596.52\", \"side\":\"SELL\", \"hash\":\"c364416aa31b939dac57d08ff77a132222f0d92a\", \"best_bid\":\"0.45\", \"best_ask\":\"0.46\"}], \"timestamp\":\"1781254837603\", \"event_type\":\"price_change\"}","ts_local_ms":1781254837976}
{"dir":"in","text":"{\"market\":\"0x9c535590faae21bf76fed844aa47fc3c5c82253ef38bd545bf12c93470502685\", \"price_changes\":[{\"asset_id\":\"107011546575057755426871645700605806081353395825571114128343592072429146374928\", \"price\":\"0.54\", \"size\":\"607.52\", \"side\":\"BUY\", \"hash\":\"985976cb91bf22e88a39c26b507b64c7988763fd\", \"best_bid\":\"0.54\", \"best_ask\":\"0.55\"}, {\"asset_id\":\"56108879726720646120583724001239294777304794469144970684362785767667828318889\", \"price\":\"0.46\", \"size\":\"607.52\", \"side\":\"SELL\", \"hash\":\"60d6d69b6afdf5e383b279d484e787b096cb7a2a\", \"best_bid\":\"0.45\", \"best_ask\":\"0.46\"}], \"timestamp\":\"1781254837604\", \"event_type\":\"price_change\"}","ts_local_ms":1781254837976}
{"dir":"in","text":"{\"market\":\"0x9c535590faae21bf76fed844aa47fc3c5c82253ef38bd545bf12c93470502685\", \"price_changes\":[{\"asset_id\":\"107011546575057755426871645700605806081353395825571114128343592072429146374928\", \"price\":\"0.54\", \"size\":\"579.52\", \"side\":\"BUY\", \"hash\":\"af592082433908f436d00016083de8d21ea29c46\", \"best_bid\":\"0.54\", \"best_ask\":\"0.55\"}, {\"asset_id\":\"56108879726720646120583724001239294777304794469144970684362785767667828318889\", \"price\":\"0.46\", \"size\":\"579.52\", \"side\":\"SELL\", \"hash\":\"589da21843bed65d087a410cd2cab1032799c8c3\", \"best_bid\":\"0.45\", \"best_ask\":\"0.46\"}], \"timestamp\":\"1781254837606\", \"event_type\":\"price_change\"}","ts_local_ms":1781254837976}
{"dir":"in","text":"{\"market\":\"0x9c535590faae21bf76fed844aa47fc3c5c82253ef38bd545bf12c93470502685\", \"price_changes\":[{\"asset_id\":\"107011546575057755426871645700605806081353395825571114128343592072429146374928\", \"price\":\"0.01\", \"size\":\"55006.6\", \"side\":\"BUY\", \"hash\":\"dd1d5b0c6983cb85285d2944d17b6d9d0fb06aaf\", \"best_bid\":\"0.54\", \"best_ask\":\"0.55\"}, {\"asset_id\":\"56108879726720646120583724001239294777304794469144970684362785767667828318889\", \"price\":\"0.99\", \"size\":\"55006.6\", \"side\":\"SELL\", \"hash\":\"f5c778757604e0454f1da5bd9b8aa5433d2c4736\", \"best_bid\":\"0.45\", \"best_ask\":\"0.46\"}], \"timestamp\":\"1781254837609\", \"event_type\":\"price_change\"}","ts_local_ms":1781254837976}
{"dir":"in","text":"{\"market\":\"0x9c535590faae21bf76fed844aa47fc3c5c82253ef38bd545bf12c93470502685\", \"price_changes\":[{\"asset_id\":\"107011546575057755426871645700605806081353395825571114128343592072429146374928\", \"price\":\"0.54\", \"size\":\"569.52\", \"side\":\"BUY\", \"hash\":\"7d8a1e6ddc3363f9060ebed881b142ca10f1bf57\", \"best_bid\":\"0.54\", \"best_ask\":\"0.55\"}, {\"asset_id\":\"56108879726720646120583724001239294777304794469144970684362785767667828318889\", \"price\":\"0.46\", \"size\":\"569.52\", \"side\":\"SELL\", \"hash\":\"bbb1c219fc79cd8556986e3a14a434f65debbb58\", \"best_bid\":\"0.45\", \"best_ask\":\"0.46\"}], \"timestamp\":\"1781254837610\", \"event_type\":\"price_change\"}","ts_local_ms":1781254837976}
{"dir":"in","text":"{\"market\":\"0x9c535590faae21bf76fed844aa47fc3c5c82253ef38bd545bf12c93470502685\", \"price_changes\":[{\"asset_id\":\"107011546575057755426871645700605806081353395825571114128343592072429146374928\", \"price\":\"0.54\", \"size\":\"581.52\", \"side\":\"BUY\", \"hash\":\"50f7239670df600f5be60d383e7939c4bea1ab6d\", \"best_bid\":\"0.54\", \"best_ask\":\"0.55\"}, {\"asset_id\":\"56108879726720646120583724001239294777304794469144970684362785767667828318889\", \"price\":\"0.46\", \"size\":\"581.52\", \"side\":\"SELL\", \"hash\":\"bff56f25183162ca6e15c0ebc9e03fd486266ba0\", \"best_bid\":\"0.45\", \"best_ask\":\"0.46\"}], \"timestamp\":\"1781254837612\", \"event_type\":\"price_change\"}","ts_local_ms":1781254837976}
{"dir":"in","text":"{\"market\":\"0x9c535590faae21bf76fed844aa47fc3c5c82253ef38bd545bf12c93470502685\", \"price_changes\":[{\"asset_id\":\"107011546575057755426871645700605806081353395825571114128343592072429146374928\", \"price\":\"0.01\", \"size\":\"55001.6\", \"side\":\"BUY\", \"hash\":\"8ed6990f56d5c850df3885603e638178d00fbba7\", \"best_bid\":\"0.54\", \"best_ask\":\"0.55\"}, {\"asset_id\":\"56108879726720646120583724001239294777304794469144970684362785767667828318889\", \"price\":\"0.99\", \"size\":\"55001.6\", \"side\":\"SELL\", \"hash\":\"16b94c88467c786e60c1d929d3f5d3ac44a4dab0\", \"best_bid\":\"0.45\", \"best_ask\":\"0.46\"}], \"timestamp\":\"1781254837617\", \"event_type\":\"price_change\"}","ts_local_ms":1781254837976}
{"dir":"in","text":"{\"market\":\"0x9c535590faae21bf76fed844aa47fc3c5c82253ef38bd545bf12c93470502685\", \"price_changes\":[{\"asset_id\":\"107011546575057755426871645700605806081353395825571114128343592072429146374928\", \"price\":\"0.01\", \"size\":\"54996.6\", \"side\":\"BUY\", \"hash\":\"2c64ab724c863f292840efe1baa5b1228a28070f\", \"best_bid\":\"0.54\", \"best_ask\":\"0.55\"}, {\"asset_id\":\"56108879726720646120583724001239294777304794469144970684362785767667828318889\", \"price\":\"0.99\", \"size\":\"54996.6\", \"side\":\"SELL\", \"hash\":\"a7906ab9c374071b621a9c5425ae997f3ec1170a\", \"best_bid\":\"0.45\", \"best_ask\":\"0.46\"}], \"timestamp\":\"1781254837617\", \"event_type\":\"price_change\"}","ts_local_ms":1781254837976}
{"dir":"in","text":"{\"market\":\"0x9c535590faae21bf76fed844aa47fc3c5c82253ef38bd545bf12c93470502685\", \"price_changes\":[{\"asset_id\":\"107011546575057755426871645700605806081353395825571114128343592072429146374928\", \"price\":\"0.54\", \"size\":\"571.52\", \"side\":\"BUY\", \"hash\":\"8b16a782796bb027a5353c9c08bfdcbbaa46f917\", \"best_bid\":\"0.54\", \"best_ask\":\"0.55\"}, {\"asset_id\":\"56108879726720646120583724001239294777304794469144970684362785767667828318889\", \"price\":\"0.46\", \"size\":\"571.52\", \"side\":\"SELL\", \"hash\":\"f323ff2a7fbc3b220d05d6b1b87ded0827301da5\", \"best_bid\":\"0.45\", \"best_ask\":\"0.46\"}], \"timestamp\":\"1781254837621\", \"event_type\":\"price_change\"}","ts_local_ms":1781254837976}
{"dir":"in","text":"{\"market\":\"0x9c535590faae21bf76fed844aa47fc3c5c82253ef38bd545bf12c93470502685\", \"price_changes\":[{\"asset_id\":\"107011546575057755426871645700605806081353395825571114128343592072429146374928\", \"price\":\"0.54\", \"size\":\"558.52\", \"side\":\"BUY\", \"hash\":\"82dca3d414a5ba082b7e553cb85d33dd51ec7e78\", \"best_bid\":\"0.54\", \"best_ask\":\"0.55\"}, {\"asset_id\":\"56108879726720646120583724001239294777304794469144970684362785767667828318889\", \"price\":\"0.46\", \"size\":\"558.52\", \"side\":\"SELL\", \"hash\":\"f90d8aa4aff12eea77d880ef31e10531a0016354\", \"best_bid\":\"0.45\", \"best_ask\":\"0.46\"}], \"timestamp\":\"1781254837622\", \"event_type\":\"price_change\"}","ts_local_ms":1781254837976}
{"dir":"in","text":"{\"market\":\"0x9c535590faae21bf76fed844aa47fc3c5c82253ef38bd545bf12c93470502685\", \"price_changes\":[{\"asset_id\":\"107011546575057755426871645700605806081353395825571114128343592072429146374928\", \"price\":\"0.54\", \"size\":\"548.52\", \"side\":\"BUY\", \"hash\":\"5ab963cebe1c42259afb1500df687ae928bb6615\", \"best_bid\":\"0.54\", \"best_ask\":\"0.55\"}, {\"asset_id\":\"56108879726720646120583724001239294777304794469144970684362785767667828318889\", \"price\":\"0.46\", \"size\":\"548.52\", \"side\":\"SELL\", \"hash\":\"12112889f89bb07173ab7b5df9181c52fb92252f\", \"best_bid\":\"0.45\", \"best_ask\":\"0.46\"}], \"timestamp\":\"1781254837623\", \"event_type\":\"price_change\"}","ts_local_ms":1781254837976}
{"dir":"in","text":"{\"market\":\"0x9c535590faae21bf76fed844aa47fc3c5c82253ef38bd545bf12c93470502685\", \"price_changes\":[{\"asset_id\":\"107011546575057755426871645700605806081353395825571114128343592072429146374928\", \"price\":\"0.54\", \"size\":\"565.52\", \"side\":\"BUY\", \"hash\":\"05fbbb96c1abe77a231b9e93f1378e720458284e\", \"best_bid\":\"0.54\", \"best_ask\":\"0.55\"}, {\"asset_id\":\"56108879726720646120583724001239294777304794469144970684362785767667828318889\", \"price\":\"0.46\", \"size\":\"565.52\", \"side\":\"SELL\", \"hash\":\"496eb30fd83250e38949221e39ea64e16215cb0b\", \"best_bid\":\"0.45\", \"best_ask\":\"0.46\"}], \"timestamp\":\"1781254837624\", \"event_type\":\"price_change\"}","ts_local_ms":1781254837976}
{"dir":"in","text":"{\"market\":\"0x9c535590faae21bf76fed844aa47fc3c5c82253ef38bd545bf12c93470502685\", \"price_changes\":[{\"asset_id\":\"107011546575057755426871645700605806081353395825571114128343592072429146374928\", \"price\":\"0.01\", \"size\":\"55001.6\", \"side\":\"BUY\", \"hash\":\"acb7a4cba937b1434d4c3c6aa6d16d4a508c5e76\", \"best_bid\":\"0.54\", \"best_ask\":\"0.55\"}, {\"asset_id\":\"56108879726720646120583724001239294777304794469144970684362785767667828318889\", \"price\":\"0.99\", \"size\":\"55001.6\", \"side\":\"SELL\", \"hash\":\"31bf0b38946420bac7587382e3d4864d7ac1d396\", \"best_bid\":\"0.45\", \"best_ask\":\"0.46\"}], \"timestamp\":\"1781254837628\", \"event_type\":\"price_change\"}","ts_local_ms":1781254837976}
{"dir":"in","text":"{\"market\":\"0x9c535590faae21bf76fed844aa47fc3c5c82253ef38bd545bf12c93470502685\", \"price_changes\":[{\"asset_id\":\"107011546575057755426871645700605806081353395825571114128343592072429146374928\", \"price\":\"0.54\", \"size\":\"548.52\", \"side\":\"BUY\", \"hash\":\"ff2142e4a76a6acb763be44d008b6f349c215bda\", \"best_bid\":\"0.54\", \"best_ask\":\"0.55\"}, {\"asset_id\":\"56108879726720646120583724001239294777304794469144970684362785767667828318889\", \"price\":\"0.46\", \"size\":\"548.52\", \"side\":\"SELL\", \"hash\":\"3fbd638dab2c07de6fc96c9a89cba335368d5ac2\", \"best_bid\":\"0.45\", \"best_ask\":\"0.46\"}], \"timestamp\":\"1781254837631\", \"event_type\":\"price_change\"}","ts_local_ms":1781254837976}
{"dir":"in","text":"{\"market\":\"0x9c535590faae21bf76fed844aa47fc3c5c82253ef38bd545bf12c93470502685\", \"price_changes\":[{\"asset_id\":\"56108879726720646120583724001239294777304794469144970684362785767667828318889\", \"price\":\"0.43\", \"size\":\"189.58\", \"side\":\"BUY\", \"hash\":\"b2f1f79ce628dbe88533c5fedc19bcc3aba992a5\", \"best_bid\":\"0.45\", \"best_ask\":\"0.46\"}, {\"asset_id\":\"107011546575057755426871645700605806081353395825571114128343592072429146374928\", \"price\":\"0.57\", \"size\":\"189.58\", \"side\":\"SELL\", \"hash\":\"c7a97bb4fb806723ca0a557ac226c5fb668baee5\", \"best_bid\":\"0.54\", \"best_ask\":\"0.55\"}], \"timestamp\":\"1781254837633\", \"event_type\":\"price_change\"}","ts_local_ms":1781254837976}
{"dir":"in","text":"{\"market\":\"0x9c535590faae21bf76fed844aa47fc3c5c82253ef38bd545bf12c93470502685\", \"price_changes\":[{\"asset_id\":\"107011546575057755426871645700605806081353395825571114128343592072429146374928\", \"price\":\"0.54\", \"size\":\"537.52\", \"side\":\"BUY\", \"hash\":\"5f1b53b7271347fc8f28c477e6c5aea798215450\", \"best_bid\":\"0.54\", \"best_ask\":\"0.55\"}, {\"asset_id\":\"56108879726720646120583724001239294777304794469144970684362785767667828318889\", \"price\":\"0.46\", \"size\":\"537.52\", \"side\":\"SELL\", \"hash\":\"2fcc4b343f01e810a0303f669005e15c545f2143\", \"best_bid\":\"0.45\", \"best_ask\":\"0.46\"}], \"timestamp\":\"1781254837633\", \"event_type\":\"price_change\"}","ts_local_ms":1781254837976}
{"dir":"in","text":"{\"market\":\"0x9c535590faae21bf76fed844aa47fc3c5c82253ef38bd545bf12c93470502685\", \"price_changes\":[{\"asset_id\":\"107011546575057755426871645700605806081353395825571114128343592072429146374928\", \"price\":\"0.54\", \"size\":\"548.52\", \"side\":\"BUY\", \"hash\":\"df97fce69daadef41656b16f7f6821f9da35e2b0\", \"best_bid\":\"0.54\", \"best_ask\":\"0.55\"}, {\"asset_id\":\"56108879726720646120583724001239294777304794469144970684362785767667828318889\", \"price\":\"0.46\", \"size\":\"548.52\", \"side\":\"SELL\", \"hash\":\"fa7f2e07a3beac9588617dfad97b95a59c4f2b69\", \"best_bid\":\"0.45\", \"best_ask\":\"0.46\"}], \"timestamp\":\"1781254837634\", \"event_type\":\"price_change\"}","ts_local_ms":1781254837976}
{"dir":"in","text":"{\"market\":\"0x9c535590faae21bf76fed844aa47fc3c5c82253ef38bd545bf12c93470502685\", \"price_changes\":[{\"asset_id\":\"107011546575057755426871645700605806081353395825571114128343592072429146374928\", \"price\":\"0.44\", \"size\":\"102.3\", \"side\":\"BUY\", \"hash\":\"9cdec393a64070d8c3d41e416e86d61b9912afcc\", \"best_bid\":\"0.54\", \"best_ask\":\"0.55\"}, {\"asset_id\":\"56108879726720646120583724001239294777304794469144970684362785767667828318889\", \"price\":\"0.56\", \"size\":\"102.3\", \"side\":\"SELL\", \"hash\":\"f683956e0a3a81dc81edfbe9b96f384e2015b775\", \"best_bid\":\"0.45\", \"best_ask\":\"0.46\"}], \"timestamp\":\"1781254837635\", \"event_type\":\"price_change\"}","ts_local_ms":1781254837976}
{"dir":"in","text":"{\"market\":\"0x9c535590faae21bf76fed844aa47fc3c5c82253ef38bd545bf12c93470502685\", \"price_changes\":[{\"asset_id\":\"107011546575057755426871645700605806081353395825571114128343592072429146374928\", \"price\":\"0.01\", \"size\":\"55006.6\", \"side\":\"BUY\", \"hash\":\"e9d3c97b7a335323e4899a45b876a302e4a1df75\", \"best_bid\":\"0.54\", \"best_ask\":\"0.55\"}, {\"asset_id\":\"56108879726720646120583724001239294777304794469144970684362785767667828318889\", \"price\":\"0.99\", \"size\":\"55006.6\", \"side\":\"SELL\", \"hash\":\"2baa9260a86cb8a2e51aab19acc06fe0938a7e8a\", \"best_bid\":\"0.45\", \"best_ask\":\"0.46\"}], \"timestamp\":\"1781254837636\", \"event_type\":\"price_change\"}","ts_local_ms":1781254837976}
{"dir":"in","text":"{\"market\":\"0x9c535590faae21bf76fed844aa47fc3c5c82253ef38bd545bf12c93470502685\", \"price_changes\":[{\"asset_id\":\"56108879726720646120583724001239294777304794469144970684362785767667828318889\", \"price\":\"0.44\", \"size\":\"36.23\", \"side\":\"BUY\", \"hash\":\"b205a6f9d362d41785ffb8ae175d51d52335d006\", \"best_bid\":\"0.45\", \"best_ask\":\"0.46\"}, {\"asset_id\":\"107011546575057755426871645700605806081353395825571114128343592072429146374928\", \"price\":\"0.56\", \"size\":\"36.23\", \"side\":\"SELL\", \"hash\":\"4c41d69ff30ce79382b74e8b7a0251f80ebb014d\", \"best_bid\":\"0.54\", \"best_ask\":\"0.55\"}], \"timestamp\":\"1781254837637\", \"event_type\":\"price_change\"}","ts_local_ms":1781254837976}
{"dir":"in","text":"{\"market\":\"0x9c535590faae21bf76fed844aa47fc3c5c82253ef38bd545bf12c93470502685\", \"price_changes\":[{\"asset_id\":\"107011546575057755426871645700605806081353395825571114128343592072429146374928\", \"price\":\"0.54\", \"size\":\"571.52\", \"side\":\"BUY\", \"hash\":\"7a13865a73ebed8f49c6074dfad8f65e2d99f3af\", \"best_bid\":\"0.54\", \"best_ask\":\"0.55\"}, {\"asset_id\":\"56108879726720646120583724001239294777304794469144970684362785767667828318889\", \"price\":\"0.46\", \"size\":\"571.52\", \"side\":\"SELL\", \"hash\":\"df62ab34889d057c0ff02c9fea5c46f638b0b5bd\", \"best_bid\":\"0.45\", \"best_ask\":\"0.46\"}], \"timestamp\":\"1781254837637\", \"event_type\":\"price_change\"}","ts_local_ms":1781254837977}
{"dir":"in","text":"{\"market\":\"0x9c535590faae21bf76fed844aa47fc3c5c82253ef38bd545bf12c93470502685\", \"price_changes\":[{\"asset_id\":\"107011546575057755426871645700605806081353395825571114128343592072429146374928\", \"price\":\"0.54\", \"size\":\"560.52\", \"side\":\"BUY\", \"hash\":\"95c4d6a642a282b66a0fc2af1b8cbc27d4aa853c\", \"best_bid\":\"0.54\", \"best_ask\":\"0.55\"}, {\"asset_id\":\"56108879726720646120583724001239294777304794469144970684362785767667828318889\", \"price\":\"0.46\", \"size\":\"560.52\", \"side\":\"SELL\", \"hash\":\"6e4f0222e68b66267a34b870114d59735218916e\", \"best_bid\":\"0.45\", \"best_ask\":\"0.46\"}], \"timestamp\":\"1781254837638\", \"event_type\":\"price_change\"}","ts_local_ms":1781254837977}
{"dir":"in","text":"{\"market\":\"0x9c535590faae21bf76fed844aa47fc3c5c82253ef38bd545bf12c93470502685\", \"price_changes\":[{\"asset_id\":\"56108879726720646120583724001239294777304794469144970684362785767667828318889\", \"price\":\"0.41\", \"size\":\"136.92\", \"side\":\"BUY\", \"hash\":\"537e170609dea22c7b1737322596bdc304ddffff\", \"best_bid\":\"0.45\", \"best_ask\":\"0.46\"}, {\"asset_id\":\"107011546575057755426871645700605806081353395825571114128343592072429146374928\", \"price\":\"0.59\", \"size\":\"136.92\", \"side\":\"SELL\", \"hash\":\"e0782135f99f1b543547d823df767de39b64f07b\", \"best_bid\":\"0.54\", \"best_ask\":\"0.55\"}], \"timestamp\":\"1781254837638\", \"event_type\":\"price_change\"}","ts_local_ms":1781254837977}
{"dir":"in","text":"{\"market\":\"0x9c535590faae21bf76fed844aa47fc3c5c82253ef38bd545bf12c93470502685\", \"price_changes\":[{\"asset_id\":\"56108879726720646120583724001239294777304794469144970684362785767667828318889\", \"price\":\"0.42\", \"size\":\"173.07\", \"side\":\"BUY\", \"hash\":\"27a4541531e3aa7faf0d1add7333c91346fe2f54\", \"best_bid\":\"0.45\", \"best_ask\":\"0.46\"}, {\"asset_id\":\"107011546575057755426871645700605806081353395825571114128343592072429146374928\", \"price\":\"0.58\", \"size\":\"173.07\", \"side\":\"SELL\", \"hash\":\"da35747ef7d49a5bb7f53162dbacdc773265c3df\", \"best_bid\":\"0.54\", \"best_ask\":\"0.55\"}], \"timestamp\":\"1781254837643\", \"event_type\":\"price_change\"}","ts_local_ms":1781254837977}
{"dir":"in","text":"{\"market\":\"0x9c535590faae21bf76fed844aa47fc3c5c82253ef38bd545bf12c93470502685\", \"price_changes\":[{\"asset_id\":\"107011546575057755426871645700605806081353395825571114128343592072429146374928\", \"price\":\"0.54\", \"size\":\"571.52\", \"side\":\"BUY\", \"hash\":\"c481c10c74cde8d7bfc0c42f9e1073870dd5c6a3\", \"best_bid\":\"0.54\", \"best_ask\":\"0.55\"}, {\"asset_id\":\"56108879726720646120583724001239294777304794469144970684362785767667828318889\", \"price\":\"0.46\", \"size\":\"571.52\", \"side\":\"SELL\", \"hash\":\"3d614e7df84ed545a6025542c3096ad0821550c0\", \"best_bid\":\"0.45\", \"best_ask\":\"0.46\"}], \"timestamp\":\"1781254837644\", \"event_type\":\"price_change\"}","ts_local_ms":1781254837977}
{"dir":"in","text":"{\"market\":\"0x9c535590faae21bf76fed844aa47fc3c5c82253ef38bd545bf12c93470502685\", \"price_changes\":[{\"asset_id\":\"107011546575057755426871645700605806081353395825571114128343592072429146374928\", \"price\":\"0.54\", \"size\":\"561.52\", \"side\":\"BUY\", \"hash\":\"10e3c2b421c1f163f59fcfff4bf25f7693dc9e46\", \"best_bid\":\"0.54\", \"best_ask\":\"0.55\"}, {\"asset_id\":\"56108879726720646120583724001239294777304794469144970684362785767667828318889\", \"price\":\"0.46\", \"size\":\"561.52\", \"side\":\"SELL\", \"hash\":\"59c6b9891c1c2d9ea26fa9fa56e5c6f5e86563f7\", \"best_bid\":\"0.45\", \"best_ask\":\"0.46\"}], \"timestamp\":\"1781254837646\", \"event_type\":\"price_change\"}","ts_local_ms":1781254837977}
{"dir":"in","text":"{\"market\":\"0x9c535590faae21bf76fed844aa47fc3c5c82253ef38bd545bf12c93470502685\", \"price_changes\":[{\"asset_id\":\"107011546575057755426871645700605806081353395825571114128343592072429146374928\", \"price\":\"0.54\", \"size\":\"551.52\", \"side\":\"BUY\", \"hash\":\"9f74921a0449d9beaee66b9ac2ee025dce27c1a0\", \"best_bid\":\"0.54\", \"best_ask\":\"0.55\"}, {\"asset_id\":\"56108879726720646120583724001239294777304794469144970684362785767667828318889\", \"price\":\"0.46\", \"size\":\"551.52\", \"side\":\"SELL\", \"hash\":\"58478be7f375de28632595ea6d94a7c7f69fe033\", \"best_bid\":\"0.45\", \"best_ask\":\"0.46\"}], \"timestamp\":\"1781254837647\", \"event_type\":\"price_change\"}","ts_local_ms":1781254837977}
{"dir":"in","text":"{\"market\":\"0x9c535590faae21bf76fed844aa47fc3c5c82253ef38bd545bf12c93470502685\", \"price_changes\":[{\"asset_id\":\"107011546575057755426871645700605806081353395825571114128343592072429146374928\", \"price\":\"0.54\", \"size\":\"562.52\", \"side\":\"BUY\", \"hash\":\"cafb268c78f395068705775d83880e94c802ac3d\", \"best_bid\":\"0.54\", \"best_ask\":\"0.55\"}, {\"asset_id\":\"56108879726720646120583724001239294777304794469144970684362785767667828318889\", \"price\":\"0.46\", \"size\":\"562.52\", \"side\":\"SELL\", \"hash\":\"35d77bfd4a640b406da374ca45e45149832061c5\", \"best_bid\":\"0.45\", \"best_ask\":\"0.46\"}], \"timestamp\":\"1781254837651\", \"event_type\":\"price_change\"}","ts_local_ms":1781254837977}
{"dir":"in","text":"{\"market\":\"0x9c535590faae21bf76fed844aa47fc3c5c82253ef38bd545bf12c93470502685\", \"price_changes\":[{\"asset_id\":\"107011546575057755426871645700605806081353395825571114128343592072429146374928\", \"price\":\"0.54\", \"size\":\"522.52\", \"side\":\"BUY\", \"hash\":\"0400abb7ab4a5aa89ada929c0ebd88b3ddc269e9\", \"best_bid\":\"0.54\", \"best_ask\":\"0.55\"}, {\"asset_id\":\"56108879726720646120583724001239294777304794469144970684362785767667828318889\", \"price\":\"0.46\", \"size\":\"522.52\", \"side\":\"SELL\", \"hash\":\"fe30e5f58017a5312c0347561235c92fc2a3ce15\", \"best_bid\":\"0.45\", \"best_ask\":\"0.46\"}], \"timestamp\":\"1781254837651\", \"event_type\":\"price_change\"}","ts_local_ms":1781254837977}
{"dir":"in","text":"{\"market\":\"0x9c535590faae21bf76fed844aa47fc3c5c82253ef38bd545bf12c93470502685\", \"asset_id\":\"56108879726720646120583724001239294777304794469144970684362785767667828318889\", \"best_bid\":\"0.45\", \"best_ask\":\"0.46\", \"spread\":\"0.01\", \"timestamp\":\"1781254837652\", \"event_type\":\"best_bid_ask\"}","ts_local_ms":1781254837977}
{"dir":"in","text":"{\"market\":\"0x9c535590faae21bf76fed844aa47fc3c5c82253ef38bd545bf12c93470502685\", \"asset_id\":\"107011546575057755426871645700605806081353395825571114128343592072429146374928\", \"best_bid\":\"0.54\", \"best_ask\":\"0.55\", \"spread\":\"0.01\", \"timestamp\":\"1781254837652\", \"event_type\":\"best_bid_ask\"}","ts_local_ms":1781254837977}
{"dir":"in","text":"{\"market\":\"0x9c535590faae21bf76fed844aa47fc3c5c82253ef38bd545bf12c93470502685\", \"price_changes\":[{\"asset_id\":\"107011546575057755426871645700605806081353395825571114128343592072429146374928\", \"price\":\"0.54\", \"size\":\"495.52\", \"side\":\"BUY\", \"hash\":\"02b02b44163cb6c42159c3e9c14576d0f953eb22\", \"best_bid\":\"0.54\", \"best_ask\":\"0.55\"}, {\"asset_id\":\"56108879726720646120583724001239294777304794469144970684362785767667828318889\", \"price\":\"0.46\", \"size\":\"495.52\", \"side\":\"SELL\", \"hash\":\"817579a388245cf5697dad310e0a1dbba499c3ca\", \"best_bid\":\"0.45\", \"best_ask\":\"0.46\"}], \"timestamp\":\"1781254837652\", \"event_type\":\"price_change\"}","ts_local_ms":1781254837977}
