{"dir":"in","text":"{\"market\":\"0x9c535590faae21bf76fed844aa47fc3c5c82253ef38bd545bf12c93470502685\", \"asset_id\":\"56108879726720646120583724001239294777304794469144970684362785767667828318889\", \"bids\":[{\"price\":\"0.01\", \"size\":\"56799.15\"}, {\"price\":\"0.02\", \"size\":\"22462.28\"}, {\"price\":\"0.03\", \"size\":\"2161.73\"}, {\"price\":\"0.04\", \"size\":\"1695.28\"}, {\"price\":\"0.05\", \"size\":\"1862.1\"}, {\"price\":\"0.06\", \"size\":\"991.6\"}, {\"price\":\"0.07\", \"size\":\"1035.18\"}, {\"price\":\"0.08\", \"size\":\"832.11\"}, {\"price\":\"0.09\", \"size\":\"679.28\"}, {\"price\":\"0.1\", \"size\":\"314.76\"}, {\"price\":\"0.11\", \"size\":\"597\"}, {\"price\":\"0.12\", \"size\":\"335.24\"}, {\"price\":\"0.13\", \"size\":\"84.2\"}, {\"price\":\"0.14\", \"size\":\"91.55\"}, {\"price\":\"0.15\", \"size\":\"52.86\"}, {\"price\":\"0.16\", \"size\":\"66.94\"}, {\"price\":\"0.17\", \"size\":\"54.08\"}, {\"price\":\"0.18\", \"size\":\"360.6\"}, {\"price\":\"0.19\", \"size\":\"104.67\"}, {\"price\":\"0.2\", \"size\":\"729.5\"}, {\"price\":\"0.21\", \"size\":\"153.8\"}, {\"price\":\"0.22\", \"size\":\"513.6\"}, {\"price\":\"0.23\", \"size\":\"60.74\"}, {\"price\":\"0.24\", \"size\":\"58.1\"}, {\"price\":\"0.25\", \"size\":\"27.9\"}, {\"price\":\"0.26\", \"size\":\"92.8\"}, {\"price\":\"0.27\", \"size\":\"118.11\"}, {\"price\":\"0.28\", \"size\":\"72.4\"}, {\"price\":\"0.29\", \"size\":\"87.3\"}, {\"price\":\"0.3\", \"size\":\"87.2\"}, {\"price\":\"0.31\", \"size\":\"96\"}, {\"price\":\"0.32\", \"size\":\"219.34\"}, {\"price\":\"0.33\", \"size\":\"232\"}, {\"price\":\"0.34\", \"size\":\"127\"}, {\"price\":\"0.35\", \"size\":\"296.73\"}, {\"price\":\"0.36\", \"size\":\"372.58\"}, {\"price\":\"0.37\", \"size\":\"306.94\"}, {\"price\":\"0.38\", \"size\":\"353.74\"}, {\"price\":\"0.39\", \"size\":\"364.15\"}, {\"price\":\"0.4\", \"size\":\"348.54\"}, {\"price\":\"0.41\", \"size\":\"136.92\"}, {\"price\":\"0.42\", \"size\":\"173.07\"}, {\"price\":\"0.43\", \"size\":\"189.58\"}, {\"price\":\"0.44\", \"size\":\"36.23\"}, {\"price\":\"0.45\", \"size\":\"110\"}], \"asks\":[{\"price\":\"0.99\", \"size\":\"55006.6\"}, {\"price\":\"0.98\", \"size\":\"22471.85\"}, {\"price\":\"0.97\", \"size\":\"2154.4\"}, {\"price\":\"0.96\", \"size\":\"1677.1\"}, {\"price\":\"0.95\", \"size\":\"1864.11\"}, {\"price\":\"0.94\", \"size\":\"1008.6\"}, {\"price\":\"0.93\", \"size\":\"992.18\"}, {\"price\":\"0.92\", \"size\":\"829.12\"}, {\"price\":\"0.91\", \"size\":\"781.72\"}, {\"price\":\"0.9\", \"size\":\"1234.15\"}, {\"price\":\"0.89\", \"size\":\"591\"}, {\"price\":\"0.88\", \"size\":\"303.64\"}, {\"price\":\"0.87\", \"size\":\"153.2\"}, {\"price\":\"0.86\", \"size\":\"61.95\"}, {\"price\":\"0.85\", \"size\":\"43.86\"}, {\"price\":\"0.84\", \"size\":\"58.94\"}, {\"price\":\"0.83\", \"size\":\"26.08\"}, {\"price\":\"0.82\", \"size\":\"45.36\"}, {\"price\":\"0.81\", \"size\":\"24.67\"}, {\"price\":\"0.8\", \"size\":\"83.51\"}, {\"price\":\"0.79\", \"size\":\"172.8\"}, {\"price\":\"0.78\", \"size\":\"77.6\"}, {\"price\":\"0.77\", \"size\":\"47.3\"}, {\"price\":\"0.76\", \"size\":\"47.1\"}, {\"price\":\"0.75\", \"size\":\"469.9\"}, {\"price\":\"0.74\", \"size\":\"46.8\"}, {\"price\":\"0.73\", \"size\":\"46.6\"}, {\"price\":\"0.72\", \"size\":\"51.4\"}, {\"price\":\"0.71\", \"size\":\"89.3\"}, {\"price\":\"0.7\", \"size\":\"74.2\"}, {\"price\":\"0.69\", \"size\":\"103.6\"}, {\"price\":\"0.68\", \"size\":\"87\"}, {\"price\":\"0.67\", \"size\":\"61.9\"}, {\"price\":\"0.66\", \"size\":\"91.8\"}, {\"price\":\"0.65\", \"size\":\"113.97\"}, {\"price\":\"0.64\", \"size\":\"371.6\"}, {\"price\":\"0.63\", \"size\":\"170.23\"}, {\"price\":\"0.62\", \"size\":\"71.5\"}, {\"price\":\"0.61\", \"size\":\"691.5\"}, {\"price\":\"0.6\", \"size\":\"111.4\"}, {\"price\":\"0.59\", \"size\":\"536.4\"}, {\"price\":\"0.58\", \"size\":\"224.3\"}, {\"price\":\"0.57\", \"size\":\"121.3\"}, {\"price\":\"0.56\", \"size\":\"102.3\"}, {\"price\":\"0.55\", \"size\":\"96\"}, {\"price\":\"0.54\", \"size\":\"352.36\"}, {\"price\":\"0.53\", \"size\":\"227.19\"}, {\"price\":\"0.52\", \"size\":\"1067.68\"}, {\"price\":\"0.51\", \"size\":\"434.91\"}, {\"price\":\"0.5\", \"size\":\"453.08\"}, {\"price\":\"0.49\", \"size\":\"227.14\"}, {\"price\":\"0.48\", \"size\":\"225.79\"}, {\"price\":\"0.47\", \"size\":\"182.17\"}, {\"price\":\"0.46\", \"size\":\"495.52\"}], \"hash\":\"817579a388245cf5697dad310e0a1dbba499c3ca\", \"timestamp\":\"1781254837652\", \"event_type\":\"book\"}","ts_local_ms":1781254837977}
{"dir":"in","text":"{\"market\":\"0x9c535590faae21bf76fed844aa47fc3c5c82253ef38bd545bf12c93470502685\", \"asset_id\":\"107011546575057755426871645700605806081353395825571114128343592072429146374928\", \"bids\":[{\"price\":\"0.01\", \"size\":\"55006.6\"}, {\"price\":\"0.02\", \"size\":\"22471.85\"}, {\"price\":\"0.03\", \"size\":\"2154.4\"}, {\"price\":\"0.04\", \"size\":\"1677.1\"}, {\"price\":\"0.05\", \"size\":\"1864.11\"}, {\"price\":\"0.06\", \"size\":\"1008.6\"}, {\"price\":\"0.07\", \"size\":\"992.18\"}, {\"price\":\"0.08\", \"size\":\"829.12\"}, {\"price\":\"0.09\", \"size\":\"781.72\"}, {\"price\":\"0.1\", \"size\":\"1234.15\"}, {\"price\":\"0.11\", \"size\":\"591\"}, {\"price\":\"0.12\", \"size\":\"303.64\"}, {\"price\":\"0.13\", \"size\":\"153.2\"}, {\"price\":\"0.14\", \"size\":\"61.95\"}, {\"price\":\"0.15\", \"size\":\"43.86\"}, {\"price\":\"0.16\", \"size\":\"58.94\"}, {\"price\":\"0.17\", \"size\":\"26.08\"}, {\"price\":\"0.18\", \"size\":\"45.36\"}, {\"price\":\"0.19\", \"size\":\"24.67\"}, {\"price\":\"0.2\", \"size\":\"83.51\"}, {\"price\":\"0.21\", \"size\":\"172.8\"}, {\"price\":\"0.22\", \"size\":\"77.6\"}, {\"price\":\"0.23\", \"size\":\"47.3\"}, {\"price\":\"0.24\", \"size\":\"47.1\"}, {\"price\":\"0.25\", \"size\":\"469.9\"}, {\"price\":\"0.26\", \"size\":\"46.8\"}, {\"price\":\"0.27\", \"size\":\"46.6\"}, {\"price\":\"0.28\", \"size\":\"51.4\"}, {\"price\":\"0.29\", \"size\":\"89.3\"}, {\"price\":\"0.3\", \"size\":\"74.2\"}, {\"price\":\"0.31\", \"size\":\"103.6\"}, {\"price\":\"0.32\", \"size\":\"87\"}, {\"price\":\"0.33\", \"size\":\"61.9\"}, {\"price\":\"0.34\", \"size\":\"91.8\"}, {\"price\":\"0.35\", \"size\":\"113.97\"}, {\"price\":\"0.36\", \"size\":\"371.6\"}, {\"price\":\"0.37\", \"size\":\"170.23\"}, {\"price\":\"0.38\", \"size\":\"71.5\"}, {\"price\":\"0.39\", \"size\":\"691.5\"}, {\"price\":\"0.4\", \"size\":\"111.4\"}, {\"price\":\"0.41\", \"size\":\"536.4\"}, {\"price\":\"0.42\", \"size\":\"224.3\"}, {\"price\":\"0.43\", \"size\":\"121.3\"}, {\"price\":\"0.44\", \"size\":\"102.3\"}, {\"price\":\"0.45\", \"size\":\"96\"}, {\"price\":\"0.46\", \"size\":\"352.36\"}, {\"price\":\"0.47\", \"size\":\"227.19\"}, {\"price\":\"0.48\", \"size\":\"1067.68\"}, {\"price\":\"0.49\", \"size\":\"434.91\"}, {\"price\":\"0.5\", \"size\":\"453.08\"}, {\"price\":\"0.51\", \"size\":\"227.14\"}, {\"price\":\"0.52\", \"size\":\"225.79\"}, {\"price\":\"0.53\", \"size\":\"182.17\"}, {\"price\":\"0.54\", \"size\":\"495.52\"}], \"asks\":[{\"price\":\"0.99\", \"size\":\"56799.15\"}, {\"price\":\"0.98\", \"size\":\"22462.28\"}, {\"price\":\"0.97\", \"size\":\"2161.73\"}, {\"price\":\"0.96\", \"size\":\"1695.28\"}, {\"price\":\"0.95\", \"size\":\"1862.1\"}, {\"price\":\"0.94\", \"size\":\"991.6\"}, {\"price\":\"0.93\", \"size\":\"1035.18\"}, {\"price\":\"0.92\", \"size\":\"832.11\"}, {\"price\":\"0.91\", \"size\":\"679.28\"}, {\"price\":\"0.9\", \"size\":\"314.76\"}, {\"price\":\"0.89\", \"size\":\"597\"}, {\"price\":\"0.88\", \"size\":\"335.24\"}, {\"price\":\"0.87\", \"size\":\"84.2\"}, {\"price\":\"0.86\", \"size\":\"91.55\"}, {\"price\":\"0.85\", \"size\":\"52.86\"}, {\"price\":\"0.84\", \"size\":\"66.94\"}, {\"price\":\"0.83\", \"size\":\"54.08\"}, {\"price\":\"0.82\", \"size\":\"360.6\"}, {\"price\":\"0.81\", \"size\":\"104.67\"}, {\"price\":\"0.8\", \"size\":\"729.5\"}, {\"price\":\"0.79\", \"size\":\"153.8\"}, {\"price\":\"0.78\", \"size\":\"513.6\"}, {\"price\":\"0.77\", \"size\":\"60.74\"}, {\"price\":\"0.76\", \"size\":\"58.1\"}, {\"price\":\"0.75\", \"size\":\"27.9\"}, {\"price\":\"0.74\", \"size\":\"92.8\"}, {\"price\":\"0.73\", \"size\":\"118.11\"}, {\"price\":\"0.72\", \"size\":\"72.4\"}, {\"price\":\"0.71\", \"size\":\"87.3\"}, {\"price\":\"0.7\", \"size\":\"87.2\"}, {\"price\":\"0.69\", \"size\":\"96\"}, {\"price\":\"0.68\", \"size\":\"219.34\"}, {\"price\":\"0.67\", \"size\":\"232\"}, {\"price\":\"0.66\", \"size\":\"127\"}, {\"price\":\"0.65\", \"size\":\"296.73\"}, {\"price\":\"0.64\", \"size\":\"372.58\"}, {\"price\":\"0.63\", \"size\":\"306.94\"}, {\"price\":\"0.62\", \"size\":\"353.74\"}, {\"price\":\"0.61\", \"size\":\"364.15\"}, {\"price\":\"0.6\", \"size\":\"348.54\"}, {\"price\":\"0.59\", \"size\":\"136.92\"}, {\"price\":\"0.58\", \"size\":\"173.07\"}, {\"price\":\"0.57\", \"size\":\"189.58\"}, {\"price\":\"0.56\", \"size\":\"36.23\"}, {\"price\":\"0.55\", \"size\":\"110\"}], \"hash\":\"02b02b44163cb6c42159c3e9c14576d0f953eb22\", \"timestamp\":\"1781254837652\", \"event_type\":\"book\"}","ts_local_ms":1781254837977}
{"dir":"in","text":"{\"market\":\"0x9c535590faae21bf76fed844aa47fc3c5c82253ef38bd545bf12c93470502685\", \"price_changes\":[{\"asset_id\":\"107011546575057755426871645700605806081353395825571114128343592072429146374928\", \"price\":\"0.54\", \"size\":\"506.52\", \"side\":\"BUY\", \"hash\":\"24cece38fbc689589f019bbb7b745b241bcb8933\", \"best_bid\":\"0.54\", \"best_ask\":\"0.55\"}, {\"asset_id\":\"56108879726720646120583724001239294777304794469144970684362785767667828318889\", \"price\":\"0.46\", \"size\":\"506.52\", \"side\":\"SELL\", \"hash\":\"4b767844f08503391f315f7854afc8036bae1849\", \"best_bid\":\"0.45\", \"best_ask\":\"0.46\"}], \"timestamp\":\"1781254837660\", \"event_type\":\"price_change\"}","ts_local_ms":1781254837978}
{"dir":"in","text":"{\"market\":\"0x9c535590faae21bf76fed844aa47fc3c5c82253ef38bd545bf12c93470502685\", \"price_changes\":[{\"asset_id\":\"107011546575057755426871645700605806081353395825571114128343592072429146374928\", \"price\":\"0.54\", \"size\":\"517.52\", \"side\":\"BUY\", \"hash\":\"17aca68b56c5a3282b53ef56ae77ab5e310af4b0\", \"best_bid\":\"0.54\", \"best_ask\":\"0.55\"}, {\"asset_id\":\"56108879726720646120583724001239294777304794469144970684362785767667828318889\", \"price\":\"0.46\", \"size\":\"517.52\", \"side\":\"SELL\", \"hash\":\"f7692b7bf5c2ab866faa3d3b1539665193dd6a55\", \"best_bid\":\"0.45\", \"best_ask\":\"0.46\"}], \"timestamp\":\"1781254837662\", \"event_type\":\"price_change\"}","ts_local_ms":1781254837978}
{"dir":"in","text":"{\"market\":\"0x9c535590faae21bf76fed844aa47fc3c5c82253ef38bd545bf12c93470502685\", \"price_changes\":[{\"asset_id\":\"107011546575057755426871645700605806081353395825571114128343592072429146374928\", \"price\":\"0.54\", \"size\":\"494.52\", \"side\":\"BUY\", \"hash\":\"a1d79fdff83c130871d0a72a7f3e878e2a3d7477\", \"best_bid\":\"0.54\", \"best_ask\":\"0.55\"}, {\"asset_id\":\"56108879726720646120583724001239294777304794469144970684362785767667828318889\", \"price\":\"0.46\", \"size\":\"494.52\", \"side\":\"SELL\", \"hash\":\"0a8469d519c4764ec7f675cea553ebe9d522a2ed\", \"best_bid\":\"0.45\", \"best_ask\":\"0.46\"}], \"timestamp\":\"1781254837664\", \"event_type\":\"price_change\"}","ts_local_ms":1781254837978}
{"dir":"in","text":"{\"market\":\"0x9c535590faae21bf76fed844aa47fc3c5c82253ef38bd545bf12c93470502685\", \"price_changes\":[{\"asset_id\":\"56108879726720646120583724001239294777304794469144970684362785767667828318889\", \"price\":\"0.42\", \"size\":\"148.07\", \"side\":\"BUY\", \"hash\":\"a9ccc3932a5ae4baa9532ce80a8d4981c5d2c181\", \"best_bid\":\"0.45\", \"best_ask\":\"0.46\"}, {\"asset_id\":\"107011546575057755426871645700605806081353395825571114128343592072429146374928\", \"price\":\"0.58\", \"size\":\"148.07\", \"side\":\"SELL\", \"hash\":\"4a468dfd6ca8773c11a1fbc117e9f6b668741cc2\", \"best_bid\":\"0.54\", \"best_ask\":\"0.55\"}], \"timestamp\":\"1781254837665\", \"event_type\":\"price_change\"}","ts_local_ms":1781254837978}
{"dir":"in","text":"{\"market\":\"0x9c535590faae21bf76fed844aa47fc3c5c82253ef38bd545bf12c93470502685\", \"price_changes\":[{\"asset_id\":\"107011546575057755426871645700605806081353395825571114128343592072429146374928\", \"price\":\"0.54\", \"size\":\"483.52\", \"side\":\"BUY\", \"hash\":\"f4d7ed051b9562fd81bbbed0d9ced5d5a1b54071\", \"best_bid\":\"0.54\", \"best_ask\":\"0.55\"}, {\"asset_id\":\"56108879726720646120583724001239294777304794469144970684362785767667828318889\", \"price\":\"0.46\", \"size\":\"483.52\", \"side\":\"SELL\", \"hash\":\"ad8e6d7d7b1d66436ace2ec4ae180437ef28580b\", \"best_bid\":\"0.45\", \"best_ask\":\"0.46\"}], \"timestamp\":\"1781254837667\", \"event_type\":\"price_change\"}","ts_local_ms":1781254837978}
{"dir":"in","text":"{\"market\":\"0x9c535590faae21bf76fed844aa47fc3c5c82253ef38bd545bf12c93470502685\", \"price_changes\":[{\"asset_id\":\"107011546575057755426871645700605806081353395825571114128343592072429146374928\", \"price\":\"0.54\", \"size\":\"494.52\", \"side\":\"BUY\", \"hash\":\"3a74afa52c5dce9d45fa6238ad229a32fb533a67\", \"best_bid\":\"0.54\", \"best_ask\":\"0.55\"}, {\"asset_id\":\"56108879726720646120583724001239294777304794469144970684362785767667828318889\", \"price\":\"0.46\", \"size\":\"494.52\", \"side\":\"SELL\", \"hash\":\"d8c26e242b9c07a6576e29031a5574799074b020\", \"best_bid\":\"0.45\", \"best_ask\":\"0.46\"}], \"timestamp\":\"1781254837668\", \"event_type\":\"price_change\"}","ts_local_ms":1781254837978}
{"dir":"in","text":"{\"market\":\"0x9c535590faae21bf76fed844aa47fc3c5c82253ef38bd545bf12c93470502685\", \"price_changes\":[{\"asset_id\":\"107011546575057755426871645700605806081353395825571114128343592072429146374928\", \"price\":\"0.54\", \"size\":\"512.52\", \"side\":\"BUY\", \"hash\":\"a4684eab81079c1f23f2492abdf7e3adefc8c649\", \"best_bid\":\"0.54\", \"best_ask\":\"0.55\"}, {\"asset_id\":\"56108879726720646120583724001239294777304794469144970684362785767667828318889\", \"price\":\"0.46\", \"size\":\"512.52\", \"side\":\"SELL\", \"hash\":\"6f4c5e74ceb61f1b4f587f871bffb639e8754f8e\", \"best_bid\":\"0.45\", \"best_ask\":\"0.46\"}], \"timestamp\":\"1781254837671\", \"event_type\":\"price_change\"}","ts_local_ms":1781254837978}
{"dir":"in","text":"{\"market\":\"0x9c535590faae21bf76fed844aa47fc3c5c82253ef38bd545bf12c93470502685\", \"price_changes\":[{\"asset_id\":\"56108879726720646120583724001239294777304794469144970684362785767667828318889\", \"price\":\"0.41\", \"size\":\"143.61\", \"side\":\"BUY\", \"hash\":\"7fc74fc1f9fa7857d4e51d75ffe8aff63b4727a7\", \"best_bid\":\"0.45\", \"best_ask\":\"0.46\"}, {\"asset_id\":\"107011546575057755426871645700605806081353395825571114128343592072429146374928\", \"price\":\"0.59\", \"size\":\"143.61\", \"side\":\"SELL\", \"hash\":\"08df3d7e71c496ecd3896f1fc5ba83ee2edcfcfa\", \"best_bid\":\"0.54\", \"best_ask\":\"0.55\"}], \"timestamp\":\"1781254837671\", \"event_type\":\"price_change\"}","ts_local_ms":1781254837978}
{"dir":"in","text":"{\"market\":\"0x9c535590faae21bf76fed844aa47fc3c5c82253ef38bd545bf12c93470502685\", \"price_changes\":[{\"asset_id\":\"107011546575057755426871645700605806081353395825571114128343592072429146374928\", \"price\":\"0.54\", \"size\":\"502.52\", \"side\":\"BUY\", \"hash\":\"92b8e9fa6f86c970532b70f667d4f8b0465ff296\", \"best_bid\":\"0.54\", \"best_ask\":\"0.55\"}, {\"asset_id\":\"56108879726720646120583724001239294777304794469144970684362785767667828318889\", \"price\":\"0.46\", \"size\":\"502.52\", \"side\":\"SELL\", \"hash\":\"2eaa78e6055d2afc825442e03f347588867fd67a\", \"best_bid\":\"0.45\", \"best_ask\":\"0.46\"}], \"timestamp\":\"1781254837674\", \"event_type\":\"price_change\"}","ts_local_ms":1781254837982}
{"dir":"in","text":"{\"market\":\"0x9c535590faae21bf76fed844aa47fc3c5c82253ef38bd545bf12c93470502685\", \"price_changes\":[{\"asset_id\":\"107011546575057755426871645700605806081353395825571114128343592072429146374928\", \"price\":\"0.54\", \"size\":\"513.52\", \"side\":\"BUY\", \"hash\":\"2fa6b62f049792530ee780622ec12c52968b29d9\", \"best_bid\":\"0.54\", \"best_ask\":\"0.55\"}, {\"asset_id\":\"56108879726720646120583724001239294777304794469144970684362785767667828318889\", \"price\":\"0.46\", \"size\":\"513.52\", \"side\":\"SELL\", \"hash\":\"bf7b854d3676f37df9a17cc2bfeae0ac9955e6ae\", \"best_bid\":\"0.45\", \"best_ask\":\"0.46\"}], \"timestamp\":\"1781254837676\", \"event_type\":\"price_change\"}","ts_local_ms":1781254837984}
{"dir":"in","text":"{\"market\":\"0x9c535590faae21bf76fed844aa47fc3c5c82253ef38bd545bf12c93470502685\", \"price_changes\":[{\"asset_id\":\"107011546575057755426871645700605806081353395825571114128343592072429146374928\", \"price\":\"0.54\", \"size\":\"524.52\", \"side\":\"BUY\", \"hash\":\"74c150a270a0e18cfd6ec10bfa2b5848462bf292\", \"best_bid\":\"0.54\", \"best_ask\":\"0.55\"}, {\"asset_id\":\"56108879726720646120583724001239294777304794469144970684362785767667828318889\", \"price\":\"0.46\", \"size\":\"524.52\", \"side\":\"SELL\", \"hash\":\"5a7dda128a4820176606190a27f6652ed169b287\", \"best_bid\":\"0.45\", \"best_ask\":\"0.46\"}], \"timestamp\":\"1781254837677\", \"event_type\":\"price_change\"}","ts_local_ms":1781254837984}
{"dir":"in","text":"{\"market\":\"0x9c535590faae21bf76fed844aa47fc3c5c82253ef38bd545bf12c93470502685\", \"price_changes\":[{\"asset_id\":\"107011546575057755426871645700605806081353395825571114128343592072429146374928\", \"price\":\"0.54\", \"size\":\"512.52\", \"side\":\"BUY\", \"hash\":\"6887a4f13aeade2489c48fee3d9495d715e37d10\", \"best_bid\":\"0.54\", \"best_ask\":\"0.55\"}, {\"asset_id\":\"56108879726720646120583724001239294777304794469144970684362785767667828318889\", \"price\":\"0.46\", \"size\":\"512.52\", \"side\":\"SELL\", \"hash\":\"568c9b6bd231151be4c34d02452b278df3831408\", \"best_bid\":\"0.45\", \"best_ask\":\"0.46\"}], \"timestamp\":\"1781254837677\", \"event_type\":\"price_change\"}","ts_local_ms":1781254837985}
{"dir":"in","text":"{\"market\":\"0x9c535590faae21bf76fed844aa47fc3c5c82253ef38bd545bf12c93470502685\", \"price_changes\":[{\"asset_id\":\"107011546575057755426871645700605806081353395825571114128343592072429146374928\", \"price\":\"0.54\", \"size\":\"523.52\", \"side\":\"BUY\", \"hash\":\"fe0150a09304641f6c085976dd3f9c07c5676445\", \"best_bid\":\"0.54\", \"best_ask\":\"0.55\"}, {\"asset_id\":\"56108879726720646120583724001239294777304794469144970684362785767667828318889\", \"price\":\"0.46\", \"size\":\"523.52\", \"side\":\"SELL\", \"hash\":\"fffaaa875506ce52af0ab8373a6c9c77cc499868\", \"best_bid\":\"0.45\", \"best_ask\":\"0.46\"}], \"timestamp\":\"1781254837678\", \"event_type\":\"price_change\"}","ts_local_ms":1781254837985}
{"dir":"in","text":"{\"market\":\"0x9c535590faae21bf76fed844aa47fc3c5c82253ef38bd545bf12c93470502685\", \"price_changes\":[{\"asset_id\":\"107011546575057755426871645700605806081353395825571114128343592072429146374928\", \"price\":\"0.54\", \"size\":\"512.52\", \"side\":\"BUY\", \"hash\":\"7bcb8581d7ddd01542686d4777b057536fd22b32\", \"best_bid\":\"0.54\", \"best_ask\":\"0.55\"}, {\"asset_id\":\"56108879726720646120583724001239294777304794469144970684362785767667828318889\", \"price\":\"0.46\", \"size\":\"512.52\", \"side\":\"SELL\", \"hash\":\"fc7c8335872d83300a67d0b6e9b5a43ca69f2005\", \"best_bid\":\"0.45\", \"best_ask\":\"0.46\"}], \"timestamp\":\"1781254837679\", \"event_type\":\"price_change\"}","ts_local_ms":1781254837986}
{"dir":"in","text":"{\"market\":\"0x9c535590faae21bf76fed844aa47fc3c5c82253ef38bd545bf12c93470502685\", \"asset_id\":\"56108879726720646120583724001239294777304794469144970684362785767667828318889\", \"price\":\"0.46\", \"size\":\"27\", \"fee_rate_bps\":\"0\", \"side\":\"BUY\", \"timestamp\":\"1781254837678\", \"event_type\":\"last_trade_price\", \"transaction_hash\":\"0x1aece07cc216eb1b5703c55a9515d16b2716d50ba75b984b8d0d67956e75537c\"}","ts_local_ms":1781254837992}
{"dir":"in","text":"{\"market\":\"0x9c535590faae21bf76fed844aa47fc3c5c82253ef38bd545bf12c93470502685\", \"price_changes\":[{\"asset_id\":\"107011546575057755426871645700605806081353395825571114128343592072429146374928\", \"price\":\"0.54\", \"size\":\"502.52\", \"side\":\"BUY\", \"hash\":\"87a46aa3d8040940f49e060183ceb981a729f76c\", \"best_bid\":\"0.54\", \"best_ask\":\"0.55\"}, {\"asset_id\":\"56108879726720646120583724001239294777304794469144970684362785767667828318889\", \"price\":\"0.46\", \"size\":\"502.52\", \"side\":\"SELL\", \"hash\":\"fe0fca368a6283c0ce8bbcdfe0e0d47944a43be6\", \"best_bid\":\"0.45\", \"best_ask\":\"0.46\"}], \"timestamp\":\"1781254837684\", \"event_type\":\"price_change\"}","ts_local_ms":1781254837992}
{"dir":"in","text":"{\"market\":\"0x9c535590faae21bf76fed844aa47fc3c5c82253ef38bd545bf12c93470502685\", \"price_changes\":[{\"asset_id\":\"107011546575057755426871645700605806081353395825571114128343592072429146374928\", \"price\":\"0.01\", \"size\":\"55012.6\", \"side\":\"BUY\", \"hash\":\"71095be0f753bda7a24c76680680624670127ba8\", \"best_bid\":\"0.54\", \"best_ask\":\"0.55\"}, {\"asset_id\":\"56108879726720646120583724001239294777304794469144970684362785767667828318889\", \"price\":\"0.99\", \"size\":\"55012.6\", \"side\":\"SELL\", \"hash\":\"5afe9f9328ae463acb460102d7a69df5704751d2\", \"best_bid\":\"0.45\", \"best_ask\":\"0.46\"}], \"timestamp\":\"1781254837687\", \"event_type\":\"price_change\"}","ts_local_ms":1781254837995}
{"dir":"in","text":"{\"market\":\"0x9c535590faae21bf76fed844aa47fc3c5c82253ef38bd545bf12c93470502685\", \"price_changes\":[{\"asset_id\":\"107011546575057755426871645700605806081353395825571114128343592072429146374928\", \"price\":\"0.54\", \"size\":\"513.52\", \"side\":\"BUY\", \"hash\":\"3a2ddb528389ec2a9e1411b5f6918245131bce39\", \"best_bid\":\"0.54\", \"best_ask\":\"0.55\"}, {\"asset_id\":\"56108879726720646120583724001239294777304794469144970684362785767667828318889\", \"price\":\"0.46\", \"size\":\"513.52\", \"side\":\"SELL\", \"hash\":\"21bf5203dcc4a9c414c237eac86d8a067079f807\", \"best_bid\":\"0.45\", \"best_ask\":\"0.46\"}], \"timestamp\":\"1781254837690\", \"event_type\":\"price_change\"}","ts_local_ms":1781254837998}
{"dir":"in","text":"{\"market\":\"0x9c535590faae21bf76fed844aa47fc3c5c82253ef38bd545bf12c93470502685\", \"price_changes\":[{\"asset_id\":\"107011546575057755426871645700605806081353395825571114128343592072429146374928\", \"price\":\"0.54\", \"size\":\"535.52\", \"side\":\"BUY\", \"hash\":\"a84a56d1c9028e5913da9ecd689af3d7b0b06a8c\", \"best_bid\":\"0.54\", \"best_ask\":\"0.55\"}, {\"asset_id\":\"56108879726720646120583724001239294777304794469144970684362785767667828318889\", \"price\":\"0.46\", \"size\":\"535.52\", \"side\":\"SELL\", \"hash\":\"ccb10de3e9241b260b496e1126a6ab238e1b9a15\", \"best_bid\":\"0.45\", \"best_ask\":\"0.46\"}], \"timestamp\":\"1781254837693\", \"event_type\":\"price_change\"}","ts_local_ms":1781254838002}
{"dir":"in","text":"{\"market\":\"0x9c535590faae21bf76fed844aa47fc3c5c82253ef38bd545bf12c93470502685\", \"price_changes\":[{\"asset_id\":\"56108879726720646120583724001239294777304794469144970684362785767667828318889\", \"price\":\"0.42\", \"size\":\"173.07\", \"side\":\"BUY\", \"hash\":\"206be275051efe70a3b6a44c02558f79a1ed5ae2\", \"best_bid\":\"0.45\", \"best_ask\":\"0.46\"}, {\"asset_id\":\"107011546575057755426871645700605806081353395825571114128343592072429146374928\", \"price\":\"0.58\", \"size\":\"173.07\", \"side\":\"SELL\", \"hash\":\"9d2bc292d7fc51a3e1af29225a0e25765dc29ec2\", \"best_bid\":\"0.54\", \"best_ask\":\"0.55\"}], \"timestamp\":\"1781254837696\", \"event_type\":\"price_change\"}","ts_local_ms":1781254838004}
{"dir":"in","text":"{\"market\":\"0x9c535590faae21bf76fed844aa47fc3c5c82253ef38bd545bf12c93470502685\", \"price_changes\":[{\"asset_id\":\"107011546575057755426871645700605806081353395825571114128343592072429146374928\", \"price\":\"0.54\", \"size\":\"545.52\", \"side\":\"BUY\", \"hash\":\"f3a6bf6ba5614381cc294fa9e87fec1db470964b\", \"best_bid\":\"0.54\", \"best_ask\":\"0.55\"}, {\"asset_id\":\"56108879726720646120583724001239294777304794469144970684362785767667828318889\", \"price\":\"0.46\", \"size\":\"545.52\", \"side\":\"SELL\", \"hash\":\"c932d6454c5fe0c5f9a22a4fe03143ccaa43886a\", \"best_bid\":\"0.45\", \"best_ask\":\"0.46\"}], \"timestamp\":\"1781254837700\", \"event_type\":\"price_change\"}","ts_local_ms":1781254838009}
{"dir":"in","text":"{\"market\":\"0x9c535590faae21bf76fed844aa47fc3c5c82253ef38bd545bf12c93470502685\", \"price_changes\":[{\"asset_id\":\"56108879726720646120583724001239294777304794469144970684362785767667828318889\", \"price\":\"0.39\", \"size\":\"379.15\", \"side\":\"BUY\", \"hash\":\"4e2c1a7e42fe7343a8b9ccf1a218f582f48bc97d\", \"best_bid\":\"0.45\", \"best_ask\":\"0.46\"}, {\"asset_id\":\"107011546575057755426871645700605806081353395825571114128343592072429146374928\", \"price\":\"0.61\", \"size\":\"379.15\", \"side\":\"SELL\", \"hash\":\"703fe89fd0a2c3d26a8ed63f40210c0c43748b55\", \"best_bid\":\"0.54\", \"best_ask\":\"0.55\"}], \"timestamp\":\"1781254837701\", \"event_type\":\"price_change\"}","ts_local_ms":1781254838009}
{"dir":"in","text":"{\"market\":\"0x9c535590faae21bf76fed844aa47fc3c5c82253ef38bd545bf12c93470502685\", \"price_changes\":[{\"asset_id\":\"56108879726720646120583724001239294777304794469144970684362785767667828318889\", \"price\":\"0.37\", \"size\":\"321.94\", \"side\":\"BUY\", \"hash\":\"2e71b89be896fe670e8442d5743e05f8ce367ef5\", \"best_bid\":\"0.45\", \"best_ask\":\"0.46\"}, {\"asset_id\":\"107011546575057755426871645700605806081353395825571114128343592072429146374928\", \"price\":\"0.63\", \"size\":\"321.94\", \"side\":\"SELL\", \"hash\":\"88b81ceb59c8aa3ee1bab9beef824242ff1f47df\", \"best_bid\":\"0.54\", \"best_ask\":\"0.55\"}], \"timestamp\":\"1781254837705\", \"event_type\":\"price_change\"}","ts_local_ms":1781254838013}
{"dir":"in","text":"{\"market\":\"0x9c535590faae21bf76fed844aa47fc3c5c82253ef38bd545bf12c93470502685\", \"price_changes\":[{\"asset_id\":\"107011546575057755426871645700605806081353395825571114128343592072429146374928\", \"price\":\"0.54\", \"size\":\"534.52\", \"side\":\"BUY\", \"hash\":\"ee5893fa5b37c39e3643a8b50f932284bcc77d50\", \"best_bid\":\"0.54\", \"best_ask\":\"0.55\"}, {\"asset_id\":\"56108879726720646120583724001239294777304794469144970684362785767667828318889\", \"price\":\"0.46\", \"size\":\"534.52\", \"side\":\"SELL\", \"hash\":\"cea67d96f694170d7da101a056a56cd92fa0b6d3\", \"best_bid\":\"0.45\", \"best_ask\":\"0.46\"}], \"timestamp\":\"1781254837706\", \"event_type\":\"price_change\"}","ts_local_ms":1781254838013}
{"dir":"in","text":"{\"market\":\"0x9c535590faae21bf76fed844aa47fc3c5c82253ef38bd545bf12c93470502685\", \"price_changes\":[{\"asset_id\":\"107011546575057755426871645700605806081353395825571114128343592072429146374928\", \"price\":\"0.54\", \"size\":\"544.52\", \"side\":\"BUY\", \"hash\":\"7fe317800fefa5e2071a6a76e034c00ee2dc4ef1\", \"best_bid\":\"0.54\", \"best_ask\":\"0.55\"}, {\"asset_id\":\"56108879726720646120583724001239294777304794469144970684362785767667828318889\", \"price\":\"0.46\", \"size\":\"544.52\", \"side\":\"SELL\", \"hash\":\"fa03d7e3c169e97247de5cdbfd9c9c7dcca4c999\", \"best_bid\":\"0.45\", \"best_ask\":\"0.46\"}], \"timestamp\":\"1781254837715\", \"event_type\":\"price_change\"}","ts_local_ms":1781254838022}
{"dir":"in","text":"{\"market\":\"0x9c535590faae21bf76fed844aa47fc3c5c82253ef38bd545bf12c93470502685\", \"price_changes\":[{\"asset_id\":\"107011546575057755426871645700605806081353395825571114128343592072429146374928\", \"price\":\"0.54\", \"size\":\"533.52\", \"side\":\"BUY\", \"hash\":\"3c54c8fd3c895f4f539c4423dc9da8b4338c3347\", \"best_bid\":\"0.54\", \"best_ask\":\"0.55\"}, {\"asset_id\":\"56108879726720646120583724001239294777304794469144970684362785767667828318889\", \"price\":\"0.46\", \"size\":\"533.52\", \"side\":\"SELL\", \"hash\":\"a2253cfbc5d7fb8718feab65f678172137a36914\", \"best_bid\":\"0.45\", \"best_ask\":\"0.46\"}], \"timestamp\":\"1781254837716\", \"event_type\":\"price_change\"}","ts_local_ms":1781254838023}
{"dir":"in","text":"{\"market\":\"0x9c535590faae21bf76fed844aa47fc3c5c82253ef38bd545bf12c93470502685\", \"price_changes\":[{\"asset_id\":\"107011546575057755426871645700605806081353395825571114128343592072429146374928\", \"price\":\"0.54\", \"size\":\"510.52\", \"side\":\"BUY\", \"hash\":\"e22c62616ad201537dee75b7268cf689b66dc1df\", \"best_bid\":\"0.54\", \"best_ask\":\"0.55\"}, {\"asset_id\":\"56108879726720646120583724001239294777304794469144970684362785767667828318889\", \"price\":\"0.46\", \"size\":\"510.52\", \"side\":\"SELL\", \"hash\":\"d154032ee557d4f384fb31ced99d84f16448d255\", \"best_bid\":\"0.45\", \"best_ask\":\"0.46\"}], \"timestamp\":\"1781254837716\", \"event_type\":\"price_change\"}","ts_local_ms":1781254838024}
{"dir":"in","text":"{\"market\":\"0x9c535590faae21bf76fed844aa47fc3c5c82253ef38bd545bf12c93470502685\", \"price_changes\":[{\"asset_id\":\"107011546575057755426871645700605806081353395825571114128343592072429146374928\", \"price\":\"0.54\", \"size\":\"520.52\", \"side\":\"BUY\", \"hash\":\"fe0bdc760314aa9b65208556b1507c6013580ae0\", \"best_bid\":\"0.54\", \"best_ask\":\"0.55\"}, {\"asset_id\":\"56108879726720646120583724001239294777304794469144970684362785767667828318889\", \"price\":\"0.46\", \"size\":\"520.52\", \"side\":\"SELL\", \"hash\":\"239baa66f4d3abf88b5220a0d3817b2abc991fdc\", \"best_bid\":\"0.45\", \"best_ask\":\"0.46\"}], \"timestamp\":\"1781254837721\", \"event_type\":\"price_change\"}","ts_local_ms":1781254838028}
{"dir":"in","text":"{\"market\":\"0x9c535590faae21bf76fed844aa47fc3c5c82253ef38bd545bf12c93470502685\", \"price_changes\":[{\"asset_id\":\"107011546575057755426871645700605806081353395825571114128343592072429146374928\", \"price\":\"0.54\", \"size\":\"530.52\", \"side\":\"BUY\", \"hash\":\"a6147b27392746cb8612fdf890adbf41420f1230\", \"best_bid\":\"0.54\", \"best_ask\":\"0.55\"}, {\"asset_id\":\"56108879726720646120583724001239294777304794469144970684362785767667828318889\", \"price\":\"0.46\", \"size\":\"530.52\", \"side\":\"SELL\", \"hash\":\"1f01a75f9356d5a9e1a08a98f28d3235e0b8b42a\", \"best_bid\":\"0.45\", \"best_ask\":\"0.46\"}], \"timestamp\":\"1781254837723\", \"event_type\":\"price_change\"}","ts_local_ms":1781254838030}
{"dir":"in","text":"{\"market\":\"0x9c535590faae21bf76fed844aa47fc3c5c82253ef38bd545bf12c93470502685\", \"price_changes\":[{\"asset_id\":\"107011546575057755426871645700605806081353395825571114128343592072429146374928\", \"price\":\"0.54\", \"size\":\"540.52\", \"side\":\"BUY\", \"hash\":\"cfe9822cf6189e4f6bc463c90e4de66b8e41cd83\", \"best_bid\":\"0.54\", \"best_ask\":\"0.55\"}, {\"asset_id\":\"56108879726720646120583724001239294777304794469144970684362785767667828318889\", \"price\":\"0.46\", \"size\":\"540.52\", \"side\":\"SELL\", \"hash\":\"3085f2ca496691388b86aa3c58a34f632ef15e9d\", \"best_bid\":\"0.45\", \"best_ask\":\"0.46\"}], \"timestamp\":\"1781254837724\", \"event_type\":\"price_change\"}","ts_local_ms":1781254838031}
{"dir":"in","text":"{\"market\":\"0x9c535590faae21bf76fed844aa47fc3c5c82253ef38bd545bf12c93470502685\", \"price_changes\":[{\"asset_id\":\"107011546575057755426871645700605806081353395825571114128343592072429146374928\", \"price\":\"0.54\", \"size\":\"529.52\", \"side\":\"BUY\", \"hash\":\"3126aa8c746e777b788339a10f318d8dc8e19856\", \"best_bid\":\"0.54\", \"best_ask\":\"0.55\"}, {\"asset_id\":\"56108879726720646120583724001239294777304794469144970684362785767667828318889\", \"price\":\"0.46\", \"size\":\"529.52\", \"side\":\"SELL\", \"hash\":\"06e2ad42a0645f4660070610ac0d33c0152c7242\", \"best_bid\":\"0.45\", \"best_ask\":\"0.46\"}], \"timestamp\":\"1781254837724\", \"event_type\":\"price_change\"}","ts_local_ms":1781254838031}
{"dir":"in","text":"{\"market\":\"0x9c535590faae21bf76fed844aa47fc3c5c82253ef38bd545bf12c93470502685\", \"price_changes\":[{\"asset_id\":\"107011546575057755426871645700605806081353395825571114128343592072429146374928\", \"price\":\"0.54\", \"size\":\"517.52\", \"side\":\"BUY\", \"hash\":\"0f4636ebf62bbe55fdf03e2427140925b22f0c64\", \"best_bid\":\"0.54\", \"best_ask\":\"0.55\"}, {\"asset_id\":\"56108879726720646120583724001239294777304794469144970684362785767667828318889\", \"price\":\"0.46\", \"size\":\"517.52\", \"side\":\"SELL\", \"hash\":\"afa0bc6d90598972a3f2bae706045b389dde35f3\", \"best_bid\":\"0.45\", \"best_ask\":\"0.46\"}], \"timestamp\":\"1781254837726\", \"event_type\":\"price_change\"}","ts_local_ms":1781254838034}
{"dir":"in","text":"{\"market\":\"0x9c535590faae21bf76fed844aa47fc3c5c82253ef38bd545bf12c93470502685\", \"price_changes\":[{\"asset_id\":\"107011546575057755426871645700605806081353395825571114128343592072429146374928\", \"price\":\"0.54\", \"size\":\"500.52\", \"side\":\"BUY\", \"hash\":\"8a76374df665d300b343f1758131e9e5e6ed4681\", \"best_bid\":\"0.54\", \"best_ask\":\"0.55\"}, {\"asset_id\":\"56108879726720646120583724001239294777304794469144970684362785767667828318889\", \"price\":\"0.46\", \"size\":\"500.52\", \"side\":\"SELL\", \"hash\":\"a427a393d0e88d943daea98a298c6fd08a2be645\", \"best_bid\":\"0.45\", \"best_ask\":\"0.46\"}], \"timestamp\":\"1781254837728\", \"event_type\":\"price_change\"}","ts_local_ms":1781254838036}
{"dir":"in","text":"{\"market\":\"0x9c535590faae21bf76fed844aa47fc3c5c82253ef38bd545bf12c93470502685\", \"price_changes\":[{\"asset_id\":\"107011546575057755426871645700605806081353395825571114128343592072429146374928\", \"price\":\"0.01\", \"size\":\"55017.61\", \"side\":\"BUY\", \"hash\":\"01142506cc651cc9ca4115eabb1337ccb022748a\", \"best_bid\":\"0.54\", \"best_ask\":\"0.55\"}, {\"asset_id\":\"56108879726720646120583724001239294777304794469144970684362785767667828318889\", \"price\":\"0.99\", \"size\":\"55017.61\", \"side\":\"SELL\", \"hash\":\"ea67e223da2acec4d89b2955f966fc924a8f7fba\", \"best_bid\":\"0.45\", \"best_ask\":\"0.46\"}], \"timestamp\":\"1781254837729\", \"event_type\":\"price_change\"}","ts_local_ms":1781254838037}
{"dir":"in","text":"{\"market\":\"0x9c535590faae21bf76fed844aa47fc3c5c82253ef38bd545bf12c93470502685\", \"price_changes\":[{\"asset_id\":\"56108879726720646120583724001239294777304794469144970684362785767667828318889\", \"price\":\"0.42\", \"size\":\"148.07\", \"side\":\"BUY\", \"hash\":\"5119dc77592604bf749ed056885a8ca04c995106\", \"best_bid\":\"0.45\", \"best_ask\":\"0.46\"}, {\"asset_id\":\"107011546575057755426871645700605806081353395825571114128343592072429146374928\", \"price\":\"0.58\", \"size\":\"148.07\", \"side\":\"SELL\", \"hash\":\"fec03df9b86b84154708d4402de853c38b227593\", \"best_bid\":\"0.54\", \"best_ask\":\"0.55\"}], \"timestamp\":\"1781254837731\", \"event_type\":\"price_change\"}","ts_local_ms":1781254838038}
{"dir":"in","text":"{\"market\":\"0x9c535590faae21bf76fed844aa47fc3c5c82253ef38bd545bf12c93470502685\", \"price_changes\":[{\"asset_id\":\"56108879726720646120583724001239294777304794469144970684362785767667828318889\", \"price\":\"0.34\", \"size\":\"97\", \"side\":\"BUY\", \"hash\":\"3d2aa8d40a32fd1cfbd2feadd1f679010813bff6\", \"best_bid\":\"0.45\", \"best_ask\":\"0.46\"}, {\"asset_id\":\"107011546575057755426871645700605806081353395825571114128343592072429146374928\", \"price\":\"0.66\", \"size\":\"97\", \"side\":\"SELL\", \"hash\":\"f57bcf1495665b90bd53a1371544226c2c51c63d\", \"best_bid\":\"0.54\", \"best_ask\":\"0.55\"}], \"timestamp\":\"1781254837732\", \"event_type\":\"price_change\"}","ts_local_ms":1781254838040}
{"dir":"in","text":"{\"market\":\"0x9c535590faae21bf76fed844aa47fc3c5c82253ef38bd545bf12c93470502685\", \"price_changes\":[{\"asset_id\":\"107011546575057755426871645700605806081353395825571114128343592072429146374928\", \"price\":\"0.54\", \"size\":\"489.52\", \"side\":\"BUY\", \"hash\":\"752b201b6046517fb83a764b465f49ca36e9c177\", \"best_bid\":\"0.54\", \"best_ask\":\"0.55\"}, {\"asset_id\":\"56108879726720646120583724001239294777304794469144970684362785767667828318889\", \"price\":\"0.46\", \"size\":\"489.52\", \"side\":\"SELL\", \"hash\":\"1cc56f4e7b9ce7f9f61242b777b1b289b3cc35ef\", \"best_bid\":\"0.45\", \"best_ask\":\"0.46\"}], \"timestamp\":\"1781254837733\", \"event_type\":\"price_change\"}","ts_local_ms":1781254838040}
{"dir":"in","text":"{\"market\":\"0x9c535590faae21bf76fed844aa47fc3c5c82253ef38bd545bf12c93470502685\", \"price_changes\":[{\"asset_id\":\"107011546575057755426871645700605806081353395825571114128343592072429146374928\", \"price\":\"0.49\", \"size\":\"404.91\", \"side\":\"BUY\", \"hash\":\"e7474ab44fd8282bc3e45b262c9c2b47e7032f24\", \"best_bid\":\"0.54\", \"best_ask\":\"0.55\"}, {\"asset_id\":\"56108879726720646120583724001239294777304794469144970684362785767667828318889\", \"price\":\"0.51\", \"size\":\"404.91\", \"side\":\"SELL\", \"hash\":\"554c5f7968aefdaae07a08f02a6880c4e56760e5\", \"best_bid\":\"0.45\", \"best_ask\":\"0.46\"}], \"timestamp\":\"1781254837733\", \"event_type\":\"price_change\"}","ts_local_ms":1781254838040}
{"dir":"in","text":"{\"market\":\"0x9c535590faae21bf76fed844aa47fc3c5c82253ef38bd545bf12c93470502685\", \"price_changes\":[{\"asset_id\":\"56108879726720646120583724001239294777304794469144970684362785767667828318889\", \"price\":\"0.44\", \"size\":\"30\", \"side\":\"BUY\", \"hash\":\"1c5463d1f51d9ff41bc8bf3d6b5a5aaf6396e546\", \"best_bid\":\"0.45\", \"best_ask\":\"0.46\"}, {\"asset_id\":\"107011546575057755426871645700605806081353395825571114128343592072429146374928\", \"price\":\"0.56\", \"size\":\"30\", \"side\":\"SELL\", \"hash\":\"b735c8ed4df3437e32fd29d57585ee358acf7913\", \"best_bid\":\"0.54\", \"best_ask\":\"0.55\"}], \"timestamp\":\"1781254837734\", \"event_type\":\"price_change\"}","ts_local_ms":1781254838042}
{"dir":"in","text":"{\"market\":\"0x9c535590faae21bf76fed844aa47fc3c5c82253ef38bd545bf12c93470502685\", \"price_changes\":[{\"asset_id\":\"107011546575057755426871645700605806081353395825571114128343592072429146374928\", \"price\":\"0.54\", \"size\":\"499.52\", \"side\":\"BUY\", \"hash\":\"0f9c3d5ce9c85ee327d330c823ae7926177c4dd3\", \"best_bid\":\"0.54\", \"best_ask\":\"0.55\"}, {\"asset_id\":\"56108879726720646120583724001239294777304794469144970684362785767667828318889\", \"price\":\"0.46\", \"size\":\"499.52\", \"side\":\"SELL\", \"hash\":\"5d15d6172589f83d2cfcdb29ae8f60b07e16a10f\", \"best_bid\":\"0.45\", \"best_ask\":\"0.46\"}], \"timestamp\":\"1781254837735\", \"event_type\":\"price_change\"}","ts_local_ms":1781254838043}
{"dir":"in","text":"{\"market\":\"0x9c535590faae21bf76fed844aa47fc3c5c82253ef38bd545bf12c93470502685\", \"price_changes\":[{\"asset_id\":\"107011546575057755426871645700605806081353395825571114128343592072429146374928\", \"price\":\"0.5\", \"size\":\"423.08\", \"side\":\"BUY\", \"hash\":\"70e7effdb100acbb8a8f253b882019e810ed1823\", \"best_bid\":\"0.54\", \"best_ask\":\"0.55\"}, {\"asset_id\":\"56108879726720646120583724001239294777304794469144970684362785767667828318889\", \"price\":\"0.5\", \"size\":\"423.08\", \"side\":\"SELL\", \"hash\":\"aa254065c40e4a5db60f947b0f241399a64d910f\", \"best_bid\":\"0.45\", \"best_ask\":\"0.46\"}], \"timestamp\":\"1781254837736\", \"event_type\":\"price_change\"}","ts_local_ms":1781254838043}
{"dir":"in","text":"{\"market\":\"0x9c535590faae21bf76fed844aa47fc3c5c82253ef38bd545bf12c93470502685\", \"price_changes\":[{\"asset_id\":\"107011546575057755426871645700605806081353395825571114128343592072429146374928\", \"price\":\"0.49\", \"size\":\"374.91\", \"side\":\"BUY\", \"hash\":\"6850d00900cc4090472996eecccc6c4fe1f91580\", \"best_bid\":\"0.54\", \"best_ask\":\"0.55\"}, {\"asset_id\":\"56108879726720646120583724001239294777304794469144970684362785767667828318889\", \"price\":\"0.51\", \"size\":\"374.91\", \"side\":\"SELL\", \"hash\":\"a13e22328f5119f1de0e7c7ac72d23675926255e\", \"best_bid\":\"0.45\", \"best_ask\":\"0.46\"}], \"timestamp\":\"1781254837736\", \"event_type\":\"price_change\"}","ts_local_ms":1781254838043}
{"dir":"in","text":"{\"market\":\"0x9c535590faae21bf76fed844aa47fc3c5c82253ef38bd545bf12c93470502685\", \"price_changes\":[{\"asset_id\":\"56108879726720646120583724001239294777304794469144970684362785767667828318889\", \"price\":\"0.4\", \"size\":\"318.54\", \"side\":\"BUY\", \"hash\":\"8e0afd38ecc9ecdb8250216848fce740133fe762\", \"best_bid\":\"0.45\", \"best_ask\":\"0.46\"}, {\"asset_id\":\"107011546575057755426871645700605806081353395825571114128343592072429146374928\", \"price\":\"0.6\", \"size\":\"318.54\", \"side\":\"SELL\", \"hash\":\"328c0d1aeb10125dd04dfa94c0b7dd1dd60f46e0\", \"best_bid\":\"0.54\", \"best_ask\":\"0.55\"}], \"timestamp\":\"1781254837737\", \"event_type\":\"price_change\"}","ts_local_ms":1781254838044}
{"dir":"in","text":"{\"market\":\"0x9c535590faae21bf76fed844aa47fc3c5c82253ef38bd545bf12c93470502685\", \"price_changes\":[{\"asset_id\":\"107011546575057755426871645700605806081353395825571114128343592072429146374928\", \"price\":\"0.01\", \"size\":\"55012.61\", \"side\":\"BUY\", \"hash\":\"464eac117ebf9904c12af84fc4d7e95f58591828\", \"best_bid\":\"0.54\", \"best_ask\":\"0.55\"}, {\"asset_id\":\"56108879726720646120583724001239294777304794469144970684362785767667828318889\", \"price\":\"0.99\", \"size\":\"55012.61\", \"side\":\"SELL\", \"hash\":\"d7e58afcf90788217c77759978e67184cf4944ae\", \"best_bid\":\"0.45\", \"best_ask\":\"0.46\"}], \"timestamp\":\"1781254837737\", \"event_type\":\"price_change\"}","ts_local_ms":1781254838045}
{"dir":"in","text":"{\"market\":\"0x9c535590faae21bf76fed844aa47fc3c5c82253ef38bd545bf12c93470502685\", \"price_changes\":[{\"asset_id\":\"56108879726720646120583724001239294777304794469144970684362785767667828318889\", \"price\":\"0.32\", \"size\":\"244.34\", \"side\":\"BUY\", \"hash\":\"b2494baf3f68d8e84eed4721aa7eaa84a47c3b2e\", \"best_bid\":\"0.45\", \"best_ask\":\"0.46\"}, {\"asset_id\":\"107011546575057755426871645700605806081353395825571114128343592072429146374928\", \"price\":\"0.68\", \"size\":\"244.34\", \"side\":\"SELL\", \"hash\":\"c598dce310e9a23145938e092f860231c3501a5c\", \"best_bid\":\"0.54\", \"best_ask\":\"0.55\"}], \"timestamp\":\"1781254837738\", \"event_type\":\"price_change\"}","ts_local_ms":1781254838046}
{"dir":"in","text":"{\"market\":\"0x9c535590faae21bf76fed844aa47fc3c5c82253ef38bd545bf12c93470502685\", \"price_changes\":[{\"asset_id\":\"56108879726720646120583724001239294777304794469144970684362785767667828318889\", \"price\":\"0.04\", \"size\":\"1807.28\", \"side\":\"BUY\", \"hash\":\"eae8277c79cea0fbd8925a59aadac94041f05036\", \"best_bid\":\"0.45\", \"best_ask\":\"0.46\"}, {\"asset_id\":\"107011546575057755426871645700605806081353395825571114128343592072429146374928\", \"price\":\"0.96\", \"size\":\"1807.28\", \"side\":\"SELL\", \"hash\":\"2a3a4d4644bac6ddc01dd3462cb7c7a755d19618\", \"best_bid\":\"0.54\", \"best_ask\":\"0.55\"}], \"timestamp\":\"1781254837739\", \"event_type\":\"price_change\"}","ts_local_ms":1781254838046}
{"dir":"in","text":"{\"market\":\"0x9c535590faae21bf76fed844aa47fc3c5c82253ef38bd545bf12c93470502685\", \"price_changes\":[{\"asset_id\":\"107011546575057755426871645700605806081353395825571114128343592072429146374928\", \"price\":\"0.48\", \"size\":\"1037.68\", \"side\":\"BUY\", \"hash\":\"56247ed99772fe34addb084dcd87e9608e80d0fb\", \"best_bid\":\"0.54\", \"best_ask\":\"0.55\"}, {\"asset_id\":\"56108879726720646120583724001239294777304794469144970684362785767667828318889\", \"price\":\"0.52\", \"size\":\"1037.68\", \"side\":\"SELL\", \"hash\":\"ecb26cc1923006bcbfae5bee12166cc2071ca13b\", \"best_bid\":\"0.45\", \"best_ask\":\"0.46\"}], \"timestamp\":\"1781254837739\", \"event_type\":\"price_change\"}","ts_local_ms":1781254838047}
{"dir":"in","text":"{\"market\":\"0x9c535590faae21bf76fed844aa47fc3c5c82253ef38bd545bf12c93470502685\", \"price_changes\":[{\"asset_id\":\"107011546575057755426871645700605806081353395825571114128343592072429146374928\", \"price\":\"0.54\", \"size\":\"488.52\", \"side\":\"BUY\", \"hash\":\"2fefb06df2e6fe4f7781d78e8ae63e0c4bb3b788\", \"best_bid\":\"0.54\", \"best_ask\":\"0.55\"}, {\"asset_id\":\"56108879726720646120583724001239294777304794469144970684362785767667828318889\", \"price\":\"0.46\", \"size\":\"488.52\", \"side\":\"SELL\", \"hash\":\"dc1daccc035916d7b7c4e1ad2b832b377dcd73c1\", \"best_bid\":\"0.45\", \"best_ask\":\"0.46\"}], \"timestamp\":\"1781254837742\", \"event_type\":\"price_change\"}","ts_local_ms":1781254838050}
{"dir":"in","text":"{\"market\":\"0x9c535590faae21bf76fed844aa47fc3c5c82253ef38bd545bf12c93470502685\", \"price_changes\":[{\"asset_id\":\"56108879726720646120583724001239294777304794469144970684362785767667828318889\", \"price\":\"0.44\", \"size\":\"15\", \"side\":\"BUY\", \"hash\":\"975eb0909287e87b4c1cd2235fd0234278bbbfde\", \"best_bid\":\"0.45\", \"best_ask\":\"0.46\"}, {\"asset_id\":\"107011546575057755426871645700605806081353395825571114128343592072429146374928\", \"price\":\"0.56\", \"size\":\"15\", \"side\":\"SELL\", \"hash\":\"d1160db23955e5628b92b17f66c02c179efa3116\", \"best_bid\":\"0.54\", \"best_ask\":\"0.55\"}], \"timestamp\":\"1781254837742\", \"event_type\":\"price_change\"}","ts_local_ms":1781254838050}
{"dir":"in","text":"{\"market\":\"0x9c535590faae21bf76fed844aa47fc3c5c82253ef38bd545bf12c93470502685\", \"price_changes\":[{\"asset_id\":\"107011546575057755426871645700605806081353395825571114128343592072429146374928\", \"price\":\"0.54\", \"size\":\"477.52\", \"side\":\"BUY\", \"hash\":\"5189ce40442d366b16afdaf37d5292d8b66e9086\", \"best_bid\":\"0.54\", \"best_ask\":\"0.55\"}, {\"asset_id\":\"56108879726720646120583724001239294777304794469144970684362785767667828318889\", \"price\":\"0.46\", \"size\":\"477.52\", \"side\":\"SELL\", \"hash\":\"a258701f6376d7b1dbb73ebed884e47306619a08\", \"best_bid\":\"0.45\", \"best_ask\":\"0.46\"}], \"timestamp\":\"1781254837743\", \"event_type\":\"price_change\"}","ts_local_ms":1781254838050}
{"dir":"in","text":"{\"market\":\"0x9c535590faae21bf76fed844aa47fc3c5c82253ef38bd545bf12c93470502685\", \"price_changes\":[{\"asset_id\":\"56108879726720646120583724001239294777304794469144970684362785767667828318889\", \"price\":\"0.43\", \"size\":\"195.96\", \"side\":\"BUY\", \"hash\":\"23262d4f405960304eb7091fd3d48992e43c1f0f\", \"best_bid\":\"0.45\", \"best_ask\":\"0.46\"}, {\"asset_id\":\"107011546575057755426871645700605806081353395825571114128343592072429146374928\", \"price\":\"0.57\", \"size\":\"195.96\", \"side\":\"SELL\", \"hash\":\"422141367013692a23a558dc920792443db8694f\", \"best_bid\":\"0.54\", \"best_ask\":\"0.55\"}], \"timestamp\":\"1781254837744\", \"event_type\":\"price_change\"}","ts_local_ms":1781254838051}
{"dir":"in","text":"{\"market\":\"0x9c535590faae21bf76fed844aa47fc3c5c82253ef38bd545bf12c93470502685\", \"price_changes\":[{\"asset_id\":\"56108879726720646120583724001239294777304794469144970684362785767667828318889\", \"price\":\"0.41\", \"size\":\"136.92\", \"side\":\"BUY\", \"hash\":\"01b10a2a2ccf86c3fe6b08cb09c19439dd9122b7\", \"best_bid\":\"0.45\", \"best_ask\":\"0.46\"}, {\"asset_id\":\"107011546575057755426871645700605806081353395825571114128343592072429146374928\", \"price\":\"0.59\", \"size\":\"136.92\", \"side\":\"SELL\", \"hash\":\"d9d0eb736de7b04a194233c424a65b4db5e4ab54\", \"best_bid\":\"0.54\", \"best_ask\":\"0.55\"}], \"timestamp\":\"1781254837745\", \"event_type\":\"price_change\"}","ts_local_ms":1781254838052}
{"dir":"in","text":"{\"market\":\"0x9c535590faae21bf76fed844aa47fc3c5c82253ef38bd545bf12c93470502685\", \"price_changes\":[{\"asset_id\":\"107011546575057755426871645700605806081353395825571114128343592072429146374928\", \"price\":\"0.54\", \"size\":\"459.52\", \"side\":\"BUY\", \"hash\":\"14662ec37312fa718dbb486f4ab98b4f0d5af29e\", \"best_bid\":\"0.54\", \"best_ask\":\"0.55\"}, {\"asset_id\":\"56108879726720646120583724001239294777304794469144970684362785767667828318889\", \"price\":\"0.46\", \"size\":\"459.52\", \"side\":\"SELL\", \"hash\":\"28e8851e1872e4039c8db38ebbcc3457261aa898\", \"best_bid\":\"0.45\", \"best_ask\":\"0.46\"}], \"timestamp\":\"1781254837745\", \"event_type\":\"price_change\"}","ts_local_ms":1781254838053}
{"dir":"in","text":"{\"market\":\"0x9c535590faae21bf76fed844aa47fc3c5c82253ef38bd545bf12c93470502685\", \"price_changes\":[{\"asset_id\":\"56108879726720646120583724001239294777304794469144970684362785767667828318889\", \"price\":\"0.26\", \"size\":\"62.8\", \"side\":\"BUY\", \"hash\":\"ae6e80e8800fd6f59d5f5886187b9bb122a8d24f\", \"best_bid\":\"0.45\", \"best_ask\":\"0.46\"}, {\"asset_id\":\"107011546575057755426871645700605806081353395825571114128343592072429146374928\", \"price\":\"0.74\", \"size\":\"62.8\", \"side\":\"SELL\", \"hash\":\"452c4f4ef96c695caf18a05fa62d51bd615d23f5\", \"best_bid\":\"0.54\", \"best_ask\":\"0.55\"}], \"timestamp\":\"1781254837745\", \"event_type\":\"price_change\"}","ts_local_ms":1781254838053}
{"dir":"in","text":"{\"market\":\"0x9c535590faae21bf76fed844aa47fc3c5c82253ef38bd545bf12c93470502685\", \"price_changes\":[{\"asset_id\":\"107011546575057755426871645700605806081353395825571114128343592072429146374928\", \"price\":\"0.54\", \"size\":\"469.52\", \"side\":\"BUY\", \"hash\":\"6d73274cb92b254b5c96a85b1277b4ce8d845348\", \"best_bid\":\"0.54\", \"best_ask\":\"0.55\"}, {\"asset_id\":\"56108879726720646120583724001239294777304794469144970684362785767667828318889\", \"price\":\"0.46\", \"size\":\"469.52\", \"side\":\"SELL\", \"hash\":\"60778a46cfde9d1b1351556333dd12682b8d0fb6\", \"best_bid\":\"0.45\", \"best_ask\":\"0.46\"}], \"timestamp\":\"1781254837747\", \"event_type\":\"price_change\"}","ts_local_ms":1781254838055}
{"dir":"in","text":"{\"market\":\"0x9c535590faae21bf76fed844aa47fc3c5c82253ef38bd545bf12c93470502685\", \"price_changes\":[{\"asset_id\":\"56108879726720646120583724001239294777304794469144970684362785767667828318889\", \"price\":\"0.42\", \"size\":\"163.07\", \"side\":\"BUY\", \"hash\":\"7a83ef708f325a5edf69057472d72306c052f914\", \"best_bid\":\"0.45\", \"best_ask\":\"0.46\"}, {\"asset_id\":\"107011546575057755426871645700605806081353395825571114128343592072429146374928\", \"price\":\"0.58\", \"size\":\"163.07\", \"side\":\"SELL\", \"hash\":\"0a34fd7fd78ddf760bbf5973d5374e52d3fe6dc1\", \"best_bid\":\"0.54\", \"best_ask\":\"0.55\"}], \"timestamp\":\"1781254837749\", \"event_type\":\"price_change\"}","ts_local_ms":1781254838056}
{"dir":"in","text":"{\"market\":\"0x9c535590faae21bf76fed844aa47fc3c5c82253ef38bd545bf12c93470502685\", \"price_changes\":[{\"asset_id\":\"107011546575057755426871645700605806081353395825571114128343592072429146374928\", \"price\":\"0.54\", \"size\":\"458.52\", \"side\":\"BUY\", \"hash\":\"551dbc771099fe39eb7ab2080ae6537440bac4cb\", \"best_bid\":\"0.54\", \"best_ask\":\"0.55\"}, {\"asset_id\":\"56108879726720646120583724001239294777304794469144970684362785767667828318889\", \"price\":\"0.46\", \"size\":\"458.52\", \"side\":\"SELL\", \"hash\":\"5268c2f3ba50ac7c912525b50a58ec948d3c49dc\", \"best_bid\":\"0.45\", \"best_ask\":\"0.46\"}], \"timestamp\":\"1781254837750\", \"event_type\":\"price_change\"}","ts_local_ms":1781254838057}
{"dir":"in","text":"{\"market\":\"0x9c535590faae21bf76fed844aa47fc3c5c82253ef38bd545bf12c93470502685\", \"price_changes\":[{\"asset_id\":\"107011546575057755426871645700605806081353395825571114128343592072429146374928\", \"price\":\"0.54\", \"size\":\"481.52\", \"side\":\"BUY\", \"hash\":\"3c073ed5408cd8e2a9b9d21c5a3eb6709702a8fb\", \"best_bid\":\"0.54\", \"best_ask\":\"0.55\"}, {\"asset_id\":\"56108879726720646120583724001239294777304794469144970684362785767667828318889\", \"price\":\"0.46\", \"size\":\"481.52\", \"side\":\"SELL\", \"hash\":\"5ef1465995e8c2e53a14fcb1f847f531a4b00b7d\", \"best_bid\":\"0.45\", \"best_ask\":\"0.46\"}], \"timestamp\":\"1781254837750\", \"event_type\":\"price_change\"}","ts_local_ms":1781254838057}
{"dir":"in","text":"{\"market\":\"0x9c535590faae21bf76fed844aa47fc3c5c82253ef38bd545bf12c93470502685\", \"price_changes\":[{\"asset_id\":\"107011546575057755426871645700605806081353395825571114128343592072429146374928\", \"price\":\"0.54\", \"size\":\"470.52\", \"side\":\"BUY\", \"hash\":\"f6ae3bfd0dd53f259bfe9c4be9b2d5186517c40f\", \"best_bid\":\"0.54\", \"best_ask\":\"0.55\"}, {\"asset_id\":\"56108879726720646120583724001239294777304794469144970684362785767667828318889\", \"price\":\"0.46\", \"size\":\"470.52\", \"side\":\"SELL\", \"hash\":\"b4124163debc0c502c9386d7657e3e8ed132ad29\", \"best_bid\":\"0.45\", \"best_ask\":\"0.46\"}], \"timestamp\":\"1781254837751\", \"event_type\":\"price_change\"}","ts_local_ms":1781254838058}
{"dir":"in","text":"{\"market\":\"0x9c535590faae21bf76fed844aa47fc3c5c82253ef38bd545bf12c93470502685\", \"price_changes\":[{\"asset_id\":\"107011546575057755426871645700605806081353395825571114128343592072429146374928\", \"price\":\"0.54\", \"size\":\"481.52\", \"side\":\"BUY\", \"hash\":\"73a404aa2234ecd1aa2a704817b4ee82c2783126\", \"best_bid\":\"0.54\", \"best_ask\":\"0.55\"}, {\"asset_id\":\"56108879726720646120583724001239294777304794469144970684362785767667828318889\", \"price\":\"0.46\", \"size\":\"481.52\", \"side\":\"SELL\", \"hash\":\"f8a705df48df1392168605f5b1e8a08e78114ec0\", \"best_bid\":\"0.45\", \"best_ask\":\"0.46\"}], \"timestamp\":\"1781254837752\", \"event_type\":\"price_change\"}","ts_local_ms":1781254838060}
{"dir":"in","text":"{\"market\":\"0x9c535590faae21bf76fed844aa47fc3c5c82253ef38bd545bf12c93470502685\", \"price_changes\":[{\"asset_id\":\"56108879726720646120583724001239294777304794469144970684362785767667828318889\", \"price\":\"0.44\", \"size\":\"45\", \"side\":\"BUY\", \"hash\":\"de28535c75fce7f9d3d70ee5f1f3ff7fd8c6555f\", \"best_bid\":\"0.45\", \"best_ask\":\"0.46\"}, {\"asset_id\":\"107011546575057755426871645700605806081353395825571114128343592072429146374928\", \"price\":\"0.56\", \"size\":\"45\", \"side\":\"SELL\", \"hash\":\"8af99499f43179dfa7ddddfbbdef255445ceca5f\", \"best_bid\":\"0.54\", \"best_ask\":\"0.55\"}], \"timestamp\":\"1781254837755\", \"event_type\":\"price_change\"}","ts_local_ms":1781254838064}
{"dir":"in","text":"{\"market\":\"0x9c535590faae21bf76fed844aa47fc3c5c82253ef38bd545bf12c93470502685\", \"price_changes\":[{\"asset_id\":\"107011546575057755426871645700605806081353395825571114128343592072429146374928\", \"price\":\"0.54\", \"size\":\"492.52\", \"side\":\"BUY\", \"hash\":\"b7cdcc1abe00b8d86c18ed1c9ca6383a56f8153b\", \"best_bid\":\"0.54\", \"best_ask\":\"0.55\"}, {\"asset_id\":\"56108879726720646120583724001239294777304794469144970684362785767667828318889\", \"price\":\"0.46\", \"size\":\"492.52\", \"side\":\"SELL\", \"hash\":\"4ad3623d63e713ee5ef734bbb02d32ddb431e095\", \"best_bid\":\"0.45\", \"best_ask\":\"0.46\"}], \"timestamp\":\"1781254837756\", \"event_type\":\"price_change\"}","ts_local_ms":1781254838064}
{"dir":"in","text":"{\"market\":\"0x9c535590faae21bf76fed844aa47fc3c5c82253ef38bd545bf12c93470502685\", \"price_changes\":[{\"asset_id\":\"107011546575057755426871645700605806081353395825571114128343592072429146374928\", \"price\":\"0.01\", \"size\":\"55007.6\", \"side\":\"BUY\", \"hash\":\"c17ee2350be1911142927949005f9f8057c1a9ad\", \"best_bid\":\"0.54\", \"best_ask\":\"0.55\"}, {\"asset_id\":\"56108879726720646120583724001239294777304794469144970684362785767667828318889\", \"price\":\"0.99\", \"size\":\"55007.6\", \"side\":\"SELL\", \"hash\":\"5c617dcff7cb8e739df80ce264c2bd3a647e85a8\", \"best_bid\":\"0.45\", \"best_ask\":\"0.46\"}], \"timestamp\":\"1781254837757\", \"event_type\":\"price_change\"}","ts_local_ms":1781254838065}
{"dir":"in","text":"{\"market\":\"0x9c535590faae21bf76fed844aa47fc3c5c82253ef38bd545bf12c93470502685\", \"price_changes\":[{\"asset_id\":\"56108879726720646120583724001239294777304794469144970684362785767667828318889\", \"price\":\"0.2\", \"size\":\"724.5\", \"side\":\"BUY\", \"hash\":\"6a20243ee9301933367d5bd836016675dac1ac22\", \"best_bid\":\"0.45\", \"best_ask\":\"0.46\"}, {\"asset_id\":\"107011546575057755426871645700605806081353395825571114128343592072429146374928\", \"price\":\"0.8\", \"size\":\"724.5\", \"side\":\"SELL\", \"hash\":\"736f7b903ca10f6ffc39762a3ac2b69634fd2902\", \"best_bid\":\"0.54\", \"best_ask\":\"0.55\"}], \"timestamp\":\"1781254837757\", \"event_type\":\"price_change\"}","ts_local_ms":1781254838065}
{"dir":"in","text":"{\"market\":\"0x9c535590faae21bf76fed844aa47fc3c5c82253ef38bd545bf12c93470502685\", \"price_changes\":[{\"asset_id\":\"107011546575057755426871645700605806081353395825571114128343592072429146374928\", \"price\":\"0.54\", \"size\":\"503.52\", \"side\":\"BUY\", \"hash\":\"e5f1fe59674118d86d8db2027250dcf456860832\", \"best_bid\":\"0.54\", \"best_ask\":\"0.55\"}, {\"asset_id\":\"56108879726720646120583724001239294777304794469144970684362785767667828318889\", \"price\":\"0.46\", \"size\":\"503.52\", \"side\":\"SELL\", \"hash\":\"2ba0ffd95e7f6f00843bb5e4c4fa60ff4b964155\", \"best_bid\":\"0.45\", \"best_ask\":\"0.46\"}], \"timestamp\":\"1781254837758\", \"event_type\":\"price_change\"}","ts_local_ms":1781254838065}
{"dir":"in","text":"{\"market\":\"0x9c535590faae21bf76fed844aa47fc3c5c82253ef38bd545bf12c93470502685\", \"price_changes\":[{\"asset_id\":\"56108879726720646120583724001239294777304794469144970684362785767667828318889\", \"price\":\"0.4\", \"size\":\"323.54\", \"side\":\"BUY\", \"hash\":\"48225922b84a5df4a9cd705346af19fc7f187fda\", \"best_bid\":\"0.45\", \"best_ask\":\"0.46\"}, {\"asset_id\":\"107011546575057755426871645700605806081353395825571114128343592072429146374928\", \"price\":\"0.6\", \"size\":\"323.54\", \"side\":\"SELL\", \"hash\":\"21ae17c50a6289bf806bc74d64d39f61134e1384\", \"best_bid\":\"0.54\", \"best_ask\":\"0.55\"}], \"timestamp\":\"1781254837760\", \"event_type\":\"price_change\"}","ts_local_ms":1781254838067}
{"dir":"in","text":"{\"market\":\"0x9c535590faae21bf76fed844aa47fc3c5c82253ef38bd545bf12c93470502685\", \"price_changes\":[{\"asset_id\":\"107011546575057755426871645700605806081353395825571114128343592072429146374928\", \"price\":\"0.54\", \"size\":\"517.52\", \"side\":\"BUY\", \"hash\":\"2f287d103b682556300ca7fbe8132afd16cbc76c\", \"best_bid\":\"0.54\", \"best_ask\":\"0.55\"}, {\"asset_id\":\"56108879726720646120583724001239294777304794469144970684362785767667828318889\", \"price\":\"0.46\", \"size\":\"517.52\", \"side\":\"SELL\", \"hash\":\"342cd3a75fbe9faec5316165740dabaa2f9ba30c\", \"best_bid\":\"0.45\", \"best_ask\":\"0.46\"}], \"timestamp\":\"1781254837761\", \"event_type\":\"price_change\"}","ts_local_ms":1781254838068}
{"dir":"in","text":"{\"market\":\"0x9c535590faae21bf76fed844aa47fc3c5c82253ef38bd545bf12c93470502685\", \"price_changes\":[{\"asset_id\":\"107011546575057755426871645700605806081353395825571114128343592072429146374928\", \"price\":\"0.53\", \"size\":\"177\", \"side\":\"BUY\", \"hash\":\"1246c0c945364bd5b0f365bf53ab8c7f39f84ca8\", \"best_bid\":\"0.54\", \"best_ask\":\"0.55\"}, {\"asset_id\":\"56108879726720646120583724001239294777304794469144970684362785767667828318889\", \"price\":\"0.47\", \"size\":\"177\", \"side\":\"SELL\", \"hash\":\"8af19d19fc4a71cfac9b378323251c1e3bdedb99\", \"best_bid\":\"0.45\", \"best_ask\":\"0.46\"}], \"timestamp\":\"1781254837764\", \"event_type\":\"price_change\"}","ts_local_ms":1781254838072}
{"dir":"in","text":"{\"market\":\"0x9c535590faae21bf76fed844aa47fc3c5c82253ef38bd545bf12c93470502685\", \"price_changes\":[{\"asset_id\":\"56108879726720646120583724001239294777304794469144970684362785767667828318889\", \"price\":\"0.46\", \"size\":\"512.44\", \"side\":\"SELL\", \"hash\":\"71ebeeff909e4d26aeeab42acd21589fb7f0602a\", \"best_bid\":\"0.45\", \"best_ask\":\"0.46\"}, {\"asset_id\":\"107011546575057755426871645700605806081353395825571114128343592072429146374928\", \"price\":\"0.54\", \"size\":\"512.44\", \"side\":\"BUY\", \"hash\":\"bfda129dd3236ac1ff9e4ac7f2d01ce55080af5d\", \"best_bid\":\"0.54\", \"best_ask\":\"0.55\"}], \"timestamp\":\"1781254837764\", \"event_type\":\"price_change\"}","ts_local_ms":1781254838072}
{"dir":"in","text":"{\"market\":\"0x9c535590faae21bf76fed844aa47fc3c5c82253ef38bd545bf12c93470502685\", \"price_changes\":[{\"asset_id\":\"56108879726720646120583724001239294777304794469144970684362785767667828318889\", \"price\":\"0.43\", \"size\":\"189.58\", \"side\":\"BUY\", \"hash\":\"71ebeeff909e4d26aeeab42acd21589fb7f0602a\", \"best_bid\":\"0.45\", \"best_ask\":\"0.46\"}, {\"asset_id\":\"107011546575057755426871645700605806081353395825571114128343592072429146374928\", \"price\":\"0.57\", \"size\":\"189.58\", \"side\":\"SELL\", \"hash\":\"bfda129dd3236ac1ff9e4ac7f2d01ce55080af5d\", \"best_bid\":\"0.54\", \"best_ask\":\"0.55\"}], \"timestamp\":\"1781254837764\", \"event_type\":\"price_change\"}","ts_local_ms":1781254838072}
{"dir":"in","text":"{\"market\":\"0x9c535590faae21bf76fed844aa47fc3c5c82253ef38bd545bf12c93470502685\", \"price_changes\":[{\"asset_id\":\"56108879726720646120583724001239294777304794469144970684362785767667828318889\", \"price\":\"0.3\", \"size\":\"117.2\", \"side\":\"BUY\", \"hash\":\"4d18e559194983f41c0dd1988c42d0ff698642b1\", \"best_bid\":\"0.45\", \"best_ask\":\"0.46\"}, {\"asset_id\":\"107011546575057755426871645700605806081353395825571114128343592072429146374928\", \"price\":\"0.7\", \"size\":\"117.2\", \"side\":\"SELL\", \"hash\":\"f963bd2c3f93b64c5b409c2448478360185935ff\", \"best_bid\":\"0.54\", \"best_ask\":\"0.55\"}], \"timestamp\":\"1781254837766\", \"event_type\":\"price_change\"}","ts_local_ms":1781254838074}
{"dir":"in","text":"{\"market\":\"0x9c535590faae21bf76fed844aa47fc3c5c82253ef38bd545bf12c93470502685\", \"price_changes\":[{\"asset_id\":\"107011546575057755426871645700605806081353395825571114128343592072429146374928\", \"price\":\"0.54\", \"size\":\"490.44\", \"side\":\"BUY\", \"hash\":\"6d29be2a64b77600bf4d1d4789e1aa6c5c27fad4\", \"best_bid\":\"0.54\", \"best_ask\":\"0.55\"}, {\"asset_id\":\"56108879726720646120583724001239294777304794469144970684362785767667828318889\", \"price\":\"0.46\", \"size\":\"490.44\", \"side\":\"SELL\", \"hash\":\"104b7846f5aa4520a76a11297cd566a85e845fe2\", \"best_bid\":\"0.45\", \"best_ask\":\"0.46\"}], \"timestamp\":\"1781254837767\", \"event_type\":\"price_change\"}","ts_local_ms":1781254838075}
{"dir":"in","text":"{\"market\":\"0x9c535590faae21bf76fed844aa47fc3c5c82253ef38bd545bf12c93470502685\", \"price_changes\":[{\"asset_id\":\"107011546575057755426871645700605806081353395825571114128343592072429146374928\", \"price\":\"0.54\", \"size\":\"479.44\", \"side\":\"BUY\", \"hash\":\"7c0553e90825be82665adc7cd815dd88aeaa4cf1\", \"best_bid\":\"0.54\", \"best_ask\":\"0.55\"}, {\"asset_id\":\"56108879726720646120583724001239294777304794469144970684362785767667828318889\", \"price\":\"0.46\", \"size\":\"479.44\", \"side\":\"SELL\", \"hash\":\"313ab32eb40c27cc2aca1caabe80b59db631a50f\", \"best_bid\":\"0.45\", \"best_ask\":\"0.46\"}], \"timestamp\":\"1781254837767\", \"event_type\":\"price_change\"}","ts_local_ms":1781254838077}
{"dir":"in","text":"{\"market\":\"0x9c535590faae21bf76fed844aa47fc3c5c82253ef38bd545bf12c93470502685\", \"price_changes\":[{\"asset_id\":\"107011546575057755426871645700605806081353395825571114128343592072429146374928\", \"price\":\"0.53\", \"size\":\"207\", \"side\":\"BUY\", \"hash\":\"7e8f5209db42239077813a81584cfcfd55a5e876\", \"best_bid\":\"0.54\", \"best_ask\":\"0.55\"}, {\"asset_id\":\"56108879726720646120583724001239294777304794469144970684362785767667828318889\", \"price\":\"0.47\", \"size\":\"207\", \"side\":\"SELL\", \"hash\":\"fda66b06bcb3e44bc15a3072d614c0e4e680dfdb\", \"best_bid\":\"0.45\", \"best_ask\":\"0.46\"}], \"timestamp\":\"1781254837769\", \"event_type\":\"price_change\"}","ts_local_ms":1781254838077}
{"dir":"in","text":"{\"market\":\"0x9c535590faae21bf76fed844aa47fc3c5c82253ef38bd545bf12c93470502685\", \"price_changes\":[{\"asset_id\":\"107011546575057755426871645700605806081353395825571114128343592072429146374928\", \"price\":\"0.54\", \"size\":\"484.72\", \"side\":\"BUY\", \"hash\":\"e5ae0aa8e2b7450b7b556abd5ae98c004669a339\", \"best_bid\":\"0.54\", \"best_ask\":\"0.55\"}, {\"asset_id\":\"56108879726720646120583724001239294777304794469144970684362785767667828318889\", \"price\":\"0.46\", \"size\":\"484.72\", \"side\":\"SELL\", \"hash\":\"bb297ecc7c37c687204dcdb0f80e612a1ec94313\", \"best_bid\":\"0.45\", \"best_ask\":\"0.46\"}], \"timestamp\":\"1781254837769\", \"event_type\":\"price_change\"}","ts_local_ms":1781254838077}
{"dir":"in","text":"{\"market\":\"0x9c535590faae21bf76fed844aa47fc3c5c82253ef38bd545bf12c93470502685\", \"price_changes\":[{\"asset_id\":\"107011546575057755426871645700605806081353395825571114128343592072429146374928\", \"price\":\"0.53\", \"size\":\"237\", \"side\":\"BUY\", \"hash\":\"17e68b353ae0a5055656b0d5734e2f4b7a6a75e7\", \"best_bid\":\"0.54\", \"best_ask\":\"0.55\"}, {\"asset_id\":\"56108879726720646120583724001239294777304794469144970684362785767667828318889\", \"price\":\"0.47\", \"size\":\"237\", \"side\":\"SELL\", \"hash\":\"beabaa5061aa84607a679d7d5a6ed94521eada5d\", \"best_bid\":\"0.45\", \"best_ask\":\"0.46\"}], \"timestamp\":\"1781254837770\", \"event_type\":\"price_change\"}","ts_local_ms":1781254838078}
{"dir":"in","text":"{\"market\":\"0x9c535590faae21bf76fed844aa47fc3c5c82253ef38bd545bf12c93470502685\", \"price_changes\":[{\"asset_id\":\"56108879726720646120583724001239294777304794469144970684362785767667828318889\", \"price\":\"0.36\", \"size\":\"402.58\", \"side\":\"BUY\", \"hash\":\"de8b124a5c5f812a02c40578bf8ecbbdf7b57329\", \"best_bid\":\"0.45\", \"best_ask\":\"0.46\"}, {\"asset_id\":\"107011546575057755426871645700605806081353395825571114128343592072429146374928\", \"price\":\"0.64\", \"size\":\"402.58\", \"side\":\"SELL\", \"hash\":\"d156e281b9c152ab2da03497efe27f53e66d129d\", \"best_bid\":\"0.54\", \"best_ask\":\"0.55\"}], \"timestamp\":\"1781254837771\", \"event_type\":\"price_change\"}","ts_local_ms":1781254838079}
{"dir":"in","text":"{\"market\":\"0x9c535590faae21bf76fed844aa47fc3c5c82253ef38bd545bf12c93470502685\", \"price_changes\":[{\"asset_id\":\"56108879726720646120583724001239294777304794469144970684362785767667828318889\", \"price\":\"0.44\", \"size\":\"15\", \"side\":\"BUY\", \"hash\":\"03b6279ce4f26d3996bb6f14bda3bda47947ad77\", \"best_bid\":\"0.45\", \"best_ask\":\"0.46\"}, {\"asset_id\":\"107011546575057755426871645700605806081353395825571114128343592072429146374928\", \"price\":\"0.56\", \"size\":\"15\", \"side\":\"SELL\", \"hash\":\"f620b1c7bdf960f00abfa27fe2e660d5306d2394\", \"best_bid\":\"0.54\", \"best_ask\":\"0.55\"}], \"timestamp\":\"1781254837772\", \"event_type\":\"price_change\"}","ts_local_ms":1781254838081}
{"dir":"in","text":"{\"market\":\"0x9c535590faae21bf76fed844aa47fc3c5c82253ef38bd545bf12c93470502685\", \"price_changes\":[{\"asset_id\":\"107011546575057755426871645700605806081353395825571114128343592072429146374928\", \"price\":\"0.51\", \"size\":\"232.5\", \"side\":\"BUY\", \"hash\":\"d606254adcc46f4dc33e6e178f71f93ac14cfbf3\", \"best_bid\":\"0.54\", \"best_ask\":\"0.55\"}, {\"asset_id\":\"56108879726720646120583724001239294777304794469144970684362785767667828318889\", \"price\":\"0.49\", \"size\":\"232.5\", \"side\":\"SELL\", \"hash\":\"9d20c16022b491f5a115d62a99b01007716cf5cc\", \"best_bid\":\"0.45\", \"best_ask\":\"0.46\"}], \"timestamp\":\"1781254837773\", \"event_type\":\"price_change\"}","ts_local_ms":1781254838082}
{"dir":"in","text":"{\"market\":\"0x9c535590faae21bf76fed844aa47fc3c5c82253ef38bd545bf12c93470502685\", \"price_changes\":[{\"asset_id\":\"107011546575057755426871645700605806081353395825571114128343592072429146374928\", \"price\":\"0.21\", \"size\":\"142.8\", \"side\":\"BUY\", \"hash\":\"5bab24ccce5855d66899c8922ffa11e19506a974\", \"best_bid\":\"0.54\", \"best_ask\":\"0.55\"}, {\"asset_id\":\"56108879726720646120583724001239294777304794469144970684362785767667828318889\", \"price\":\"0.79\", \"size\":\"142.8\", \"side\":\"SELL\", \"hash\":\"45258cbc50ea093b096996ae3e471c9c22644d4e\", \"best_bid\":\"0.45\", \"best_ask\":\"0.46\"}], \"timestamp\":\"1781254837774\", \"event_type\":\"price_change\"}","ts_local_ms":1781254838082}
{"dir":"in","text":"{\"market\":\"0x9c535590faae21bf76fed844aa47fc3c5c82253ef38bd545bf12c93470502685\", \"price_changes\":[{\"asset_id\":\"107011546575057755426871645700605806081353395825571114128343592072429146374928\", \"price\":\"0.52\", \"size\":\"255.79\", \"side\":\"BUY\", \"hash\":\"d124f9162ae8e09b46c23bda09b1a682635b5f07\", \"best_bid\":\"0.54\", \"best_ask\":\"0.55\"}, {\"asset_id\":\"56108879726720646120583724001239294777304794469144970684362785767667828318889\", \"price\":\"0.48\", \"size\":\"255.79\", \"side\":\"SELL\", \"hash\":\"f5ae42a9d229db2d7b1de2d507cbba27933e8421\", \"best_bid\":\"0.45\", \"best_ask\":\"0.46\"}], \"timestamp\":\"1781254837775\", \"event_type\":\"price_change\"}","ts_local_ms":1781254838085}
{"dir":"in","text":"{\"market\":\"0x9c535590faae21bf76fed844aa47fc3c5c82253ef38bd545bf12c93470502685\", \"price_changes\":[{\"asset_id\":\"56108879726720646120583724001239294777304794469144970684362785767667828318889\", \"price\":\"0.45\", \"size\":\"116.08\", \"side\":\"BUY\", \"hash\":\"2041196ab6c5c1e393aad6f017a1436dd0f22405\", \"best_bid\":\"0.45\", \"best_ask\":\"0.46\"}, {\"asset_id\":\"107011546575057755426871645700605806081353395825571114128343592072429146374928\", \"price\":\"0.55\", \"size\":\"116.08\", \"side\":\"SELL\", \"hash\":\"139c11c09d965eaded923cd67c51fd9e1276883d\", \"best_bid\":\"0.54\", \"best_ask\":\"0.55\"}], \"timestamp\":\"1781254837777\", \"event_type\":\"price_change\"}","ts_local_ms":1781254838085}
{"dir":"in","text":"{\"market\":\"0x9c535590faae21bf76fed844aa47fc3c5c82253ef38bd545bf12c93470502685\", \"price_changes\":[{\"asset_id\":\"107011546575057755426871645700605806081353395825571114128343592072429146374928\", \"price\":\"0.54\", \"size\":\"493.72\", \"side\":\"BUY\", \"hash\":\"ad4e898ceaa869eead5cf695e34db85e7158ba84\", \"best_bid\":\"0.54\", \"best_ask\":\"0.55\"}, {\"asset_id\":\"56108879726720646120583724001239294777304794469144970684362785767667828318889\", \"price\":\"0.46\", \"size\":\"493.72\", \"side\":\"SELL\", \"hash\":\"c2eb956b1383dff9b79123acb896f41b13d1408c\", \"best_bid\":\"0.45\", \"best_ask\":\"0.46\"}], \"timestamp\":\"1781254837781\", \"event_type\":\"price_change\"}","ts_local_ms":1781254838088}
{"dir":"in","text":"{\"market\":\"0x9c535590faae21bf76fed844aa47fc3c5c82253ef38bd545bf12c93470502685\", \"price_changes\":[{\"asset_id\":\"107011546575057755426871645700605806081353395825571114128343592072429146374928\", \"price\":\"0.54\", \"size\":\"483.72\", \"side\":\"BUY\", \"hash\":\"3fac05a0ec4f6df823e9afe61182600bad078aa5\", \"best_bid\":\"0.54\", \"best_ask\":\"0.55\"}, {\"asset_id\":\"56108879726720646120583724001239294777304794469144970684362785767667828318889\", \"price\":\"0.46\", \"size\":\"483.72\", \"side\":\"SELL\", \"hash\":\"f370dc7c86313c661063fada0e8da920fbcd67f3\", \"best_bid\":\"0.45\", \"best_ask\":\"0.46\"}], \"timestamp\":\"1781254837782\", \"event_type\":\"price_change\"}","ts_local_ms":1781254838091}
{"dir":"in","text":"{\"market\":\"0x9c535590faae21bf76fed844aa47fc3c5c82253ef38bd545bf12c93470502685\", \"price_changes\":[{\"asset_id\":\"56108879726720646120583724001239294777304794469144970684362785767667828318889\", \"price\":\"0.37\", \"size\":\"332.94\", \"side\":\"BUY\", \"hash\":\"9a52279f48490cd2ba26b0c4262f35a5dd30a129\", \"best_bid\":\"0.45\", \"best_ask\":\"0.46\"}, {\"asset_id\":\"107011546575057755426871645700605806081353395825571114128343592072429146374928\", \"price\":\"0.63\", \"size\":\"332.94\", \"side\":\"SELL\", \"hash\":\"2b3c106cbd2c2462cadcf73d608c85a601ba2d84\", \"best_bid\":\"0.54\", \"best_ask\":\"0.55\"}], \"timestamp\":\"1781254837782\", \"event_type\":\"price_change\"}","ts_local_ms":1781254838091}
{"dir":"in","text":"{\"market\":\"0x9c535590faae21bf76fed844aa47fc3c5c82253ef38bd545bf12c93470502685\", \"price_changes\":[{\"asset_id\":\"107011546575057755426871645700605806081353395825571114128343592072429146374928\", \"price\":\"0.5\", \"size\":\"413.08\", \"side\":\"BUY\", \"hash\":\"b1f6ff7dcbecf55a3092f5d67c98e85538a94578\", \"best_bid\":\"0.54\", \"best_ask\":\"0.55\"}, {\"asset_id\":\"56108879726720646120583724001239294777304794469144970684362785767667828318889\", \"price\":\"0.5\", \"size\":\"413.08\", \"side\":\"SELL\", \"hash\":\"cd54e701bfcfeb0e9779771aec59956a4b9104f5\", \"best_bid\":\"0.45\", \"best_ask\":\"0.46\"}], \"timestamp\":\"1781254837783\", \"event_type\":\"price_change\"}","ts_local_ms":1781254838091}
{"dir":"in","text":"{\"market\":\"0x9c535590faae21bf76fed844aa47fc3c5c82253ef38bd545bf12c93470502685\", \"price_changes\":[{\"asset_id\":\"107011546575057755426871645700605806081353395825571114128343592072429146374928\", \"price\":\"0.54\", \"size\":\"496.72\", \"side\":\"BUY\", \"hash\":\"c444c4cc07511fa2f8249879f325ebaa84da3237\", \"best_bid\":\"0.54\", \"best_ask\":\"0.55\"}, {\"asset_id\":\"56108879726720646120583724001239294777304794469144970684362785767667828318889\", \"price\":\"0.46\", \"size\":\"496.72\", \"side\":\"SELL\", \"hash\":\"9afc35fce54d6fb193699d0cda2a7dcaddf71462\", \"best_bid\":\"0.45\", \"best_ask\":\"0.46\"}], \"timestamp\":\"1781254837783\", \"event_type\":\"price_change\"}","ts_local_ms":1781254838091}
{"dir":"in","text":"{\"market\":\"0x9c535590faae21bf76fed844aa47fc3c5c82253ef38bd545bf12c93470502685\", \"price_changes\":[{\"asset_id\":\"107011546575057755426871645700605806081353395825571114128343592072429146374928\", \"price\":\"0.54\", \"size\":\"485.72\", \"side\":\"BUY\", \"hash\":\"eff61ad52248b11768ebf3b10d2bc4cc31eeb21c\", \"best_bid\":\"0.54\", \"best_ask\":\"0.55\"}, {\"asset_id\":\"56108879726720646120583724001239294777304794469144970684362785767667828318889\", \"price\":\"0.46\", \"size\":\"485.72\", \"side\":\"SELL\", \"hash\":\"2e90c952d0c9af6ebf12d6b66ce3e5555f944b32\", \"best_bid\":\"0.45\", \"best_ask\":\"0.46\"}], \"timestamp\":\"1781254837783\", \"event_type\":\"price_change\"}","ts_local_ms":1781254838092}
{"dir":"in","text":"{\"market\":\"0x9c535590faae21bf76fed844aa47fc3c5c82253ef38bd545bf12c93470502685\", \"price_changes\":[{\"asset_id\":\"107011546575057755426871645700605806081353395825571114128343592072429146374928\", \"price\":\"0.52\", \"size\":\"285.79\", \"side\":\"BUY\", \"hash\":\"5e1d6068338f0ea8a1e7283e7278743500cb62ff\", \"best_bid\":\"0.54\", \"best_ask\":\"0.55\"}, {\"asset_id\":\"56108879726720646120583724001239294777304794469144970684362785767667828318889\", \"price\":\"0.48\", \"size\":\"285.79\", \"side\":\"SELL\", \"hash\":\"9aeec438008e1d2afbf41707439ba5a8a2e6fdb5\", \"best_bid\":\"0.45\", \"best_ask\":\"0.46\"}], \"timestamp\":\"1781254837784\", \"event_type\":\"price_change\"}","ts_local_ms":1781254838093}
{"dir":"in","text":"{\"market\":\"0x9c535590faae21bf76fed844aa47fc3c5c82253ef38bd545bf12c93470502685\", \"price_changes\":[{\"asset_id\":\"107011546575057755426871645700605806081353395825571114128343592072429146374928\", \"price\":\"0.22\", \"size\":\"47.6\", \"side\":\"BUY\", \"hash\":\"3165ef55c81f471c306a1368e99f83a6ab8004cb\", \"best_bid\":\"0.54\", \"best_ask\":\"0.55\"}, {\"asset_id\":\"56108879726720646120583724001239294777304794469144970684362785767667828318889\", \"price\":\"0.78\", \"size\":\"47.6\", \"side\":\"SELL\", \"hash\":\"0e266175a77e2ae07f3e49e4ed140cabf9e411a7\", \"best_bid\":\"0.45\", \"best_ask\":\"0.46\"}], \"timestamp\":\"1781254837785\", \"event_type\":\"price_change\"}","ts_local_ms":1781254838094}
{"dir":"in","text":"{\"market\":\"0x9c535590faae21bf76fed844aa47fc3c5c82253ef38bd545bf12c93470502685\", \"price_changes\":[{\"asset_id\":\"107011546575057755426871645700605806081353395825571114128343592072429146374928\", \"price\":\"0.23\", \"size\":\"17.3\", \"side\":\"BUY\", \"hash\":\"229a3ffff9682e07bcb58e1b18c318aa225cc9d8\", \"best_bid\":\"0.54\", \"best_ask\":\"0.55\"}, {\"asset_id\":\"56108879726720646120583724001239294777304794469144970684362785767667828318889\", \"price\":\"0.77\", \"size\":\"17.3\", \"side\":\"SELL\", \"hash\":\"c501374a41487c4d39350caf8ce2dbff9c075a0b\", \"best_bid\":\"0.45\", \"best_ask\":\"0.46\"}], \"timestamp\":\"1781254837785\", \"event_type\":\"price_change\"}","ts_local_ms":1781254838094}
{"dir":"in","text":"{\"market\":\"0x9c535590faae21bf76fed844aa47fc3c5c82253ef38bd545bf12c93470502685\", \"price_changes\":[{\"asset_id\":\"107011546575057755426871645700605806081353395825571114128343592072429146374928\", \"price\":\"0.54\", \"size\":\"494.72\", \"side\":\"BUY\", \"hash\":\"5b14cee33fedd34d9fa0c68f8f2ee9598a85b0b6\", \"best_bid\":\"0.54\", \"best_ask\":\"0.55\"}, {\"asset_id\":\"56108879726720646120583724001239294777304794469144970684362785767667828318889\", \"price\":\"0.46\", \"size\":\"494.72\", \"side\":\"SELL\", \"hash\":\"c5bfb2c6becb9f91cd3b4dfeed1a1c255db21c33\", \"best_bid\":\"0.45\", \"best_ask\":\"0.46\"}], \"timestamp\":\"1781254837786\", \"event_type\":\"price_change\"}","ts_local_ms":1781254838094}
{"dir":"in","text":"{\"market\":\"0x9c535590faae21bf76fed844aa47fc3c5c82253ef38bd545bf12c93470502685\", \"price_changes\":[{\"asset_id\":\"107011546575057755426871645700605806081353395825571114128343592072429146374928\", \"price\":\"0.54\", \"size\":\"503.72\", \"side\":\"BUY\", \"hash\":\"3b696785baa7842f1a58b383302b32d11486095c\", \"best_bid\":\"0.54\", \"best_ask\":\"0.55\"}, {\"asset_id\":\"56108879726720646120583724001239294777304794469144970684362785767667828318889\", \"price\":\"0.46\", \"size\":\"503.72\", \"side\":\"SELL\", \"hash\":\"09a429035deb6ead58d52e40346f2ef57364cf42\", \"best_bid\":\"0.45\", \"best_ask\":\"0.46\"}], \"timestamp\":\"1781254837786\", \"event_type\":\"price_change\"}","ts_local_ms":1781254838094}
{"dir":"in","text":"{\"market\":\"0x9c535590faae21bf76fed844aa47fc3c5c82253ef38bd545bf12c93470502685\", \"price_changes\":[{\"asset_id\":\"107011546575057755426871645700605806081353395825571114128343592072429146374928\", \"price\":\"0.54\", \"size\":\"513.72\", \"side\":\"BUY\", \"hash\":\"08902238f7553d8c26225f011a42c6523ebc89da\", \"best_bid\":\"0.54\", \"best_ask\":\"0.55\"}, {\"asset_id\":\"56108879726720646120583724001239294777304794469144970684362785767667828318889\", \"price\":\"0.46\", \"size\":\"513.72\", \"side\":\"SELL\", \"hash\":\"b89690a72e22de03ea88d80eb80f837b976a7909\", \"best_bid\":\"0.45\", \"best_ask\":\"0.46\"}], \"timestamp\":\"1781254837789\", \"event_type\":\"price_change\"}","ts_local_ms":1781254838098}
{"dir":"in","text":"{\"market\":\"0x9c535590faae21bf76fed844aa47fc3c5c82253ef38bd545bf12c93470502685\", \"price_changes\":[{\"asset_id\":\"107011546575057755426871645700605806081353395825571114128343592072429146374928\", \"price\":\"0.54\", \"size\":\"543.72\", \"side\":\"BUY\", \"hash\":\"e6ccb330b0c3073e2200ec828befeaf68dce1029\", \"best_bid\":\"0.54\", \"best_ask\":\"0.55\"}, {\"asset_id\":\"56108879726720646120583724001239294777304794469144970684362785767667828318889\", \"price\":\"0.46\", \"size\":\"543.72\", \"side\":\"SELL\", \"hash\":\"f10a5cc518c5eb3c98c34e373cb8e70b01fb3ed9\", \"best_bid\":\"0.45\", \"best_ask\":\"0.46\"}], \"timestamp\":\"1781254837791\", \"event_type\":\"price_change\"}","ts_local_ms":1781254838100}
{"dir":"in","text":"{\"market\":\"0x9c535590faae21bf76fed844aa47fc3c5c82253ef38bd545bf12c93470502685\", \"price_changes\":[{\"asset_id\":\"107011546575057755426871645700605806081353395825571114128343592072429146374928\", \"price\":\"0.54\", \"size\":\"533.72\", \"side\":\"BUY\", \"hash\":\"7205d2e18e1ef90e4aac35ac5e275ee79476dab0\", \"best_bid\":\"0.54\", \"best_ask\":\"0.55\"}, {\"asset_id\":\"56108879726720646120583724001239294777304794469144970684362785767667828318889\", \"price\":\"0.46\", \"size\":\"533.72\", \"side\":\"SELL\", \"hash\":\"fa18e3ba6c1431439d290831083703e42733dc06\", \"best_bid\":\"0.45\", \"best_ask\":\"0.46\"}], \"timestamp\":\"1781254837791\", \"event_type\":\"price_change\"}","ts_local_ms":1781254838100}
{"dir":"in","text":"{\"market\":\"0x9c535590faae21bf76fed844aa47fc3c5c82253ef38bd545bf12c93470502685\", \"price_changes\":[{\"asset_id\":\"107011546575057755426871645700605806081353395825571114128343592072429146374928\", \"price\":\"0.53\", \"size\":\"267\", \"side\":\"BUY\", \"hash\":\"1a7d647cd69932a3f9fd26b8ea50d6e4fcebf7ca\", \"best_bid\":\"0.54\", \"best_ask\":\"0.55\"}, {\"asset_id\":\"56108879726720646120583724001239294777304794469144970684362785767667828318889\", \"price\":\"0.47\", \"size\":\"267\", \"side\":\"SELL\", \"hash\":\"d782c1ea47e1695218d6a51bade0f8e4f1832e7a\", \"best_bid\":\"0.45\", \"best_ask\":\"0.46\"}], \"timestamp\":\"1781254837795\", \"event_type\":\"price_change\"}","ts_local_ms":1781254838103}
{"dir":"in","text":"{\"market\":\"0x9c535590faae21bf76fed844aa47fc3c5c82253ef38bd545bf12c93470502685\", \"price_changes\":[{\"asset_id\":\"56108879726720646120583724001239294777304794469144970684362785767667828318889\", \"price\":\"0.47\", \"size\":\"272.16\", \"side\":\"SELL\", \"hash\":\"878aa9f789daba88d3e82d4c4d96d52ec961ba38\", \"best_bid\":\"0.45\", \"best_ask\":\"0.46\"}, {\"asset_id\":\"107011546575057755426871645700605806081353395825571114128343592072429146374928\", \"price\":\"0.53\", \"size\":\"272.16\", \"side\":\"BUY\", \"hash\":\"d28a96380e982deeccff10e4aff7ea56ca288e8c\", \"best_bid\":\"0.54\", \"best_ask\":\"0.55\"}], \"timestamp\":\"1781254837796\", \"event_type\":\"price_change\"}","ts_local_ms":1781254838103}
{"dir":"in","text":"{\"market\":\"0x9c535590faae21bf76fed844aa47fc3c5c82253ef38bd545bf12c93470502685\", \"price_changes\":[{\"asset_id\":\"56108879726720646120583724001239294777304794469144970684362785767667828318889\", \"price\":\"0.43\", \"size\":\"195.94\", \"side\":\"BUY\", \"hash\":\"eda1ac00db4a7afebe409b30710cb9dcc777da1b\", \"best_bid\":\"0.45\", \"best_ask\":\"0.46\"}, {\"asset_id\":\"107011546575057755426871645700605806081353395825571114128343592072429146374928\", \"price\":\"0.57\", \"size\":\"195.94\", \"side\":\"SELL\", \"hash\":\"cfe7941470d0dbad26e07c70a878e3ebb66af782\", \"best_bid\":\"0.54\", \"best_ask\":\"0.55\"}], \"timestamp\":\"1781254837796\", \"event_type\":\"price_change\"}","ts_local_ms":1781254838104}
{"dir":"in","text":"{\"market\":\"0x9c535590faae21bf76fed844aa47fc3c5c82253ef38bd545bf12c93470502685\", \"price_changes\":[{\"asset_id\":\"107011546575057755426871645700605806081353395825571114128343592072429146374928\", \"price\":\"0.54\", \"size\":\"542.72\", \"side\":\"BUY\", \"hash\":\"56dbcbad87051043fd309d4bfa6a3de0e56298c8\", \"best_bid\":\"0.54\", \"best_ask\":\"0.55\"}, {\"asset_id\":\"56108879726720646120583724001239294777304794469144970684362785767667828318889\", \"price\":\"0.46\", \"size\":\"542.72\", \"side\":\"SELL\", \"hash\":\"50ea43d033481b165fc952ade1e3f526d7b98bfc\", \"best_bid\":\"0.45\", \"best_ask\":\"0.46\"}], \"timestamp\":\"1781254837799\", \"event_type\":\"price_change\"}","ts_local_ms":1781254838107}
{"dir":"in","text":"{\"market\":\"0x9c535590faae21bf76fed844aa47fc3c5c82253ef38bd545bf12c93470502685\", \"price_changes\":[{\"asset_id\":\"56108879726720646120583724001239294777304794469144970684362785767667828318889\", \"price\":\"0.32\", \"size\":\"219.34\", \"side\":\"BUY\", \"hash\":\"8d5c2233fa7bf8289bc96c3b71f7dd62fd0c7043\", \"best_bid\":\"0.45\", \"best_ask\":\"0.46\"}, {\"asset_id\":\"107011546575057755426871645700605806081353395825571114128343592072429146374928\", \"price\":\"0.68\", \"size\":\"219.34\", \"side\":\"SELL\", \"hash\":\"49bc3d9d6a7de29031b1ea59a57cad9681bd3535\", \"best_bid\":\"0.54\", \"best_ask\":\"0.55\"}], \"timestamp\":\"1781254837800\", \"event_type\":\"price_change\"}","ts_local_ms":1781254838107}
{"dir":"in","text":"{\"market\":\"0x9c535590faae21bf76fed844aa47fc3c5c82253ef38bd545bf12c93470502685\", \"price_changes\":[{\"asset_id\":\"107011546575057755426871645700605806081353395825571114128343592072429146374928\", \"price\":\"0.54\", \"size\":\"532.72\", \"side\":\"BUY\", \"hash\":\"1dff55cf47a034f36c0df0c43f98eafdf64c4d17\", \"best_bid\":\"0.54\", \"best_ask\":\"0.55\"}, {\"asset_id\":\"56108879726720646120583724001239294777304794469144970684362785767667828318889\", \"price\":\"0.46\", \"size\":\"532.72\", \"side\":\"SELL\", \"hash\":\"77084159abe16b18b660070519814ce4816aa871\", \"best_bid\":\"0.45\", \"best_ask\":\"0.46\"}], \"timestamp\":\"1781254837800\", \"event_type\":\"price_change\"}","ts_local_ms":1781254838108}
{"dir":"in","text":"{\"market\":\"0x9c535590faae21bf76fed844aa47fc3c5c82253ef38bd545bf12c93470502685\", \"price_changes\":[{\"asset_id\":\"107011546575057755426871645700605806081353395825571114128343592072429146374928\", \"price\":\"0.54\", \"size\":\"541.72\", \"side\":\"BUY\", \"hash\":\"76495d4bbe6564f2658bd1d049ed68fec42fcf24\", \"best_bid\":\"0.54\", \"best_ask\":\"0.55\"}, {\"asset_id\":\"56108879726720646120583724001239294777304794469144970684362785767667828318889\", \"price\":\"0.46\", \"size\":\"541.72\", \"side\":\"SELL\", \"hash\":\"c7ec14398a02d45673d4bca6b9d27afc7b9abc83\", \"best_bid\":\"0.45\", \"best_ask\":\"0.46\"}], \"timestamp\":\"1781254837801\", \"event_type\":\"price_change\"}","ts_local_ms":1781254838108}
{"dir":"in","text":"{\"market\":\"0x9c535590faae21bf76fed844aa47fc3c5c82253ef38bd545bf12c93470502685\", \"price_changes\":[{\"asset_id\":\"107011546575057755426871645700605806081353395825571114128343592072429146374928\", \"price\":\"0.51\", \"size\":\"227.14\", \"side\":\"BUY\", \"hash\":\"8608ee10910e5f55ab89b50f745df3c0e7286934\", \"best_bid\":\"0.54\", \"best_ask\":\"0.55\"}, {\"asset_id\":\"56108879726720646120583724001239294777304794469144970684362785767667828318889\", \"price\":\"0.49\", \"size\":\"227.14\", \"side\":\"SELL\", \"hash\":\"1e968b7d6a02bd8b7e6a7a7bcd2a0444bfca369a\", \"best_bid\":\"0.45\", \"best_ask\":\"0.46\"}], \"timestamp\":\"1781254837801\", \"event_type\":\"price_change\"}","ts_local_ms":1781254838109}
{"dir":"in","text":"{\"market\":\"0x9c535590faae21bf76fed844aa47fc3c5c82253ef38bd545bf12c93470502685\", \"price_changes\":[{\"asset_id\":\"56108879726720646120583724001239294777304794469144970684362785767667828318889\", \"price\":\"0.26\", \"size\":\"92.8\", \"side\":\"BUY\", \"hash\":\"c451283d6d4b25264811871442e2312c1ff1d84c\", \"best_bid\":\"0.45\", \"best_ask\":\"0.46\"}, {\"asset_id\":\"107011546575057755426871645700605806081353395825571114128343592072429146374928\", \"price\":\"0.74\", \"size\":\"92.8\", \"side\":\"SELL\", \"hash\":\"725a522b3b8441845a5595d31371c0c1d11a78dd\", \"best_bid\":\"0.54\", \"best_ask\":\"0.55\"}], \"timestamp\":\"1781254837802\", \"event_type\":\"price_change\"}","ts_local_ms":1781254838110}
{"dir":"in","text":"{\"market\":\"0x9c535590faae21bf76fed844aa47fc3c5c82253ef38bd545bf12c93470502685\", \"price_changes\":[{\"asset_id\":\"107011546575057755426871645700605806081353395825571114128343592072429146374928\", \"price\":\"0.54\", \"size\":\"531.72\", \"side\":\"BUY\", \"hash\":\"c97c0c678fd247c15fb62174f1563760237f201d\", \"best_bid\":\"0.54\", \"best_ask\":\"0.55\"}, {\"asset_id\":\"56108879726720646120583724001239294777304794469144970684362785767667828318889\", \"price\":\"0.46\", \"size\":\"531.72\", \"side\":\"SELL\", \"hash\":\"f02082ffe916528353d736927ba689edcf536f00\", \"best_bid\":\"0.45\", \"best_ask\":\"0.46\"}], \"timestamp\":\"1781254837803\", \"event_type\":\"price_change\"}","ts_local_ms":1781254838110}
{"dir":"in","text":"{\"market\":\"0x9c535590faae21bf76fed844aa47fc3c5c82253ef38bd545bf12c93470502685\", \"price_changes\":[{\"asset_id\":\"107011546575057755426871645700605806081353395825571114128343592072429146374928\", \"price\":\"0.01\", \"size\":\"55001.6\", \"side\":\"BUY\", \"hash\":\"fefbc92943fbd84d25253257e8a81e9e7dabcda5\", \"best_bid\":\"0.54\", \"best_ask\":\"0.55\"}, {\"asset_id\":\"56108879726720646120583724001239294777304794469144970684362785767667828318889\", \"price\":\"0.99\", \"size\":\"55001.6\", \"side\":\"SELL\", \"hash\":\"e712b4b479630c8c8e11d1cc1bb28eca9d6b6079\", \"best_bid\":\"0.45\", \"best_ask\":\"0.46\"}], \"timestamp\":\"1781254837804\", \"event_type\":\"price_change\"}","ts_local_ms":1781254838111}
{"dir":"in","text":"{\"market\":\"0x9c535590faae21bf76fed844aa47fc3c5c82253ef38bd545bf12c93470502685\", \"price_changes\":[{\"asset_id\":\"107011546575057755426871645700605806081353395825571114128343592072429146374928\", \"price\":\"0.54\", \"size\":\"526.44\", \"side\":\"BUY\", \"hash\":\"8194749fcdaeb2920679ae5c1259d05de1fd0aee\", \"best_bid\":\"0.54\", \"best_ask\":\"0.55\"}, {\"asset_id\":\"56108879726720646120583724001239294777304794469144970684362785767667828318889\", \"price\":\"0.46\", \"size\":\"526.44\", \"side\":\"SELL\", \"hash\":\"ae3199e4658382da7b7eb046696574c90900faaa\", \"best_bid\":\"0.45\", \"best_ask\":\"0.46\"}], \"timestamp\":\"1781254837806\", \"event_type\":\"price_change\"}","ts_local_ms":1781254838113}
{"dir":"in","text":"{\"market\":\"0x9c535590faae21bf76fed844aa47fc3c5c82253ef38bd545bf12c93470502685\", \"price_changes\":[{\"asset_id\":\"107011546575057755426871645700605806081353395825571114128343592072429146374928\", \"price\":\"0.54\", \"size\":\"542.44\", \"side\":\"BUY\", \"hash\":\"8a66d39401ecc1a72344d8a3b6ff95d547c93cb9\", \"best_bid\":\"0.54\", \"best_ask\":\"0.55\"}, {\"asset_id\":\"56108879726720646120583724001239294777304794469144970684362785767667828318889\", \"price\":\"0.46\", \"size\":\"542.44\", \"side\":\"SELL\", \"hash\":\"405b4fa26dc6b4f006fdc97ec5d27ec97a0d09b7\", \"best_bid\":\"0.45\", \"best_ask\":\"0.46\"}], \"timestamp\":\"1781254837808\", \"event_type\":\"price_change\"}","ts_local_ms":1781254838115}
{"dir":"in","text":"{\"market\":\"0x9c535590faae21bf76fed844aa47fc3c5c82253ef38bd545bf12c93470502685\", \"price_changes\":[{\"asset_id\":\"107011546575057755426871645700605806081353395825571114128343592072429146374928\", \"price\":\"0.65\", \"size\":\"291.73\", \"side\":\"SELL\", \"hash\":\"ed5cf96732d78a24de98318a397f43dcd9973769\", \"best_bid\":\"0.54\", \"best_ask\":\"0.55\"}, {\"asset_id\":\"56108879726720646120583724001239294777304794469144970684362785767667828318889\", \"price\":\"0.35\", \"size\":\"291.73\", \"side\":\"BUY\", \"hash\":\"c774675981abe494f0759cc4ba9653c49a332b0f\", \"best_bid\":\"0.45\", \"best_ask\":\"0.46\"}], \"timestamp\":\"1781254837809\", \"event_type\":\"price_change\"}","ts_local_ms":1781254838116}
{"dir":"in","text":"{\"market\":\"0x9c535590faae21bf76fed844aa47fc3c5c82253ef38bd545bf12c93470502685\", \"price_changes\":[{\"asset_id\":\"56108879726720646120583724001239294777304794469144970684362785767667828318889\", \"price\":\"0.42\", \"size\":\"188.07\", \"side\":\"BUY\", \"hash\":\"0f402bcea2c8b43307f31ef847053adabab68690\", \"best_bid\":\"0.45\", \"best_ask\":\"0.46\"}, {\"asset_id\":\"107011546575057755426871645700605806081353395825571114128343592072429146374928\", \"price\":\"0.58\", \"size\":\"188.07\", \"side\":\"SELL\", \"hash\":\"69f30fcf6e2991caa65bae28d846c29f6e2be6b5\", \"best_bid\":\"0.54\", \"best_ask\":\"0.55\"}], \"timestamp\":\"1781254837810\", \"event_type\":\"price_change\"}","ts_local_ms":1781254838118}
{"dir":"in","text":"{\"market\":\"0x9c535590faae21bf76fed844aa47fc3c5c82253ef38bd545bf12c93470502685\", \"price_changes\":[{\"asset_id\":\"107011546575057755426871645700605806081353395825571114128343592072429146374928\", \"price\":\"0.53\", \"size\":\"287.16\", \"side\":\"BUY\", \"hash\":\"ca2e2d12a1ed7ba825738d5c85e3c2b43ecf1f29\", \"best_bid\":\"0.54\", \"best_ask\":\"0.55\"}, {\"asset_id\":\"56108879726720646120583724001239294777304794469144970684362785767667828318889\", \"price\":\"0.47\", \"size\":\"287.16\", \"side\":\"SELL\", \"hash\":\"759ae33a4e06616769a96774f1a4404e0afaa01d\", \"best_bid\":\"0.45\", \"best_ask\":\"0.46\"}], \"timestamp\":\"1781254837812\", \"event_type\":\"price_change\"}","ts_local_ms":1781254838121}
{"dir":"in","text":"{\"market\":\"0x9c535590faae21bf76fed844aa47fc3c5c82253ef38bd545bf12c93470502685\", \"price_changes\":[{\"asset_id\":\"107011546575057755426871645700605806081353395825571114128343592072429146374928\", \"price\":\"0.54\", \"size\":\"532.44\", \"side\":\"BUY\", \"hash\":\"4495a5801bf9d235d55df4213b8529258d14b2e8\", \"best_bid\":\"0.54\", \"best_ask\":\"0.55\"}, {\"asset_id\":\"56108879726720646120583724001239294777304794469144970684362785767667828318889\", \"price\":\"0.46\", \"size\":\"532.44\", \"side\":\"SELL\", \"hash\":\"b7d04b0bd41ac3be798c0e43d3bcee1f28372a58\", \"best_bid\":\"0.45\", \"best_ask\":\"0.46\"}], \"timestamp\":\"1781254837813\", \"event_type\":\"price_change\"}","ts_local_ms":1781254838121}
{"dir":"in","text":"{\"market\":\"0x9c535590faae21bf76fed844aa47fc3c5c82253ef38bd545bf12c93470502685\", \"price_changes\":[{\"asset_id\":\"56108879726720646120583724001239294777304794469144970684362785767667828318889\", \"price\":\"0.42\", \"size\":\"163.07\", \"side\":\"BUY\", \"hash\":\"bf13c3d4755530d10928421c9a3514a9acce0988\", \"best_bid\":\"0.45\", \"best_ask\":\"0.46\"}, {\"asset_id\":\"107011546575057755426871645700605806081353395825571114128343592072429146374928\", \"price\":\"0.58\", \"size\":\"163.07\", \"side\":\"SELL\", \"hash\":\"8818d92e27c05dfe99d302c1f5d6a1725d936f35\", \"best_bid\":\"0.54\", \"best_ask\":\"0.55\"}], \"timestamp\":\"1781254837813\", \"event_type\":\"price_change\"}","ts_local_ms":1781254838121}
{"dir":"in","text":"{\"market\":\"0x9c535590faae21bf76fed844aa47fc3c5c82253ef38bd545bf12c93470502685\", \"price_changes\":[{\"asset_id\":\"107011546575057755426871645700605806081353395825571114128343592072429146374928\", \"price\":\"0.64\", \"size\":\"407.58\", \"side\":\"SELL\", \"hash\":\"e88522976861d52586be43304e0d6d2cea30331c\", \"best_bid\":\"0.54\", \"best_ask\":\"0.55\"}, {\"asset_id\":\"56108879726720646120583724001239294777304794469144970684362785767667828318889\", \"price\":\"0.36\", \"size\":\"407.58\", \"side\":\"BUY\", \"hash\":\"4fd39036ac8153004c6f88bd68a177afc173458b\", \"best_bid\":\"0.45\", \"best_ask\":\"0.46\"}], \"timestamp\":\"1781254837814\", \"event_type\":\"price_change\"}","ts_local_ms":1781254838121}
{"dir":"in","text":"{\"market\":\"0x9c535590faae21bf76fed844aa47fc3c5c82253ef38bd545bf12c93470502685\", \"price_changes\":[{\"asset_id\":\"107011546575057755426871645700605806081353395825571114128343592072429146374928\", \"price\":\"0.51\", \"size\":\"212.14\", \"side\":\"BUY\", \"hash\":\"647b5e8f1d6bcf9046a16ebd43dd4229244fe162\", \"best_bid\":\"0.54\", \"best_ask\":\"0.55\"}, {\"asset_id\":\"56108879726720646120583724001239294777304794469144970684362785767667828318889\", \"price\":\"0.49\", \"size\":\"212.14\", \"side\":\"SELL\", \"hash\":\"3b2818d889bd1a5e90d4fcd6f2a87437f924946c\", \"best_bid\":\"0.45\", \"best_ask\":\"0.46\"}], \"timestamp\":\"1781254837816\", \"event_type\":\"price_change\"}","ts_local_ms":1781254838123}
{"dir":"in","text":"{\"market\":\"0x9c535590faae21bf76fed844aa47fc3c5c82253ef38bd545bf12c93470502685\", \"price_changes\":[{\"asset_id\":\"56108879726720646120583724001239294777304794469144970684362785767667828318889\", \"price\":\"0.01\", \"size\":\"56794.15\", \"side\":\"BUY\", \"hash\":\"69920222ab8166f4f7d04f8dcbe2a41ded4f82f5\", \"best_bid\":\"0.45\", \"best_ask\":\"0.46\"}, {\"asset_id\":\"107011546575057755426871645700605806081353395825571114128343592072429146374928\", \"price\":\"0.99\", \"size\":\"56794.15\", \"side\":\"SELL\", \"hash\":\"4666012e8ece3bf4be69a667642a9644fc5c5322\", \"best_bid\":\"0.54\", \"best_ask\":\"0.55\"}], \"timestamp\":\"1781254837821\", \"event_type\":\"price_change\"}","ts_local_ms":1781254838131}
{"dir":"in","text":"{\"market\":\"0x9c535590faae21bf76fed844aa47fc3c5c82253ef38bd545bf12c93470502685\", \"price_changes\":[{\"asset_id\":\"107011546575057755426871645700605806081353395825571114128343592072429146374928\", \"price\":\"0.54\", \"size\":\"522.44\", \"side\":\"BUY\", \"hash\":\"ee4213fdee32f1ad908132ebac510f19a50f59c1\", \"best_bid\":\"0.54\", \"best_ask\":\"0.55\"}, {\"asset_id\":\"56108879726720646120583724001239294777304794469144970684362785767667828318889\", \"price\":\"0.46\", \"size\":\"522.44\", \"side\":\"SELL\", \"hash\":\"0f40ad6bce30fe56a82adfdd7969f72cf41e767c\", \"best_bid\":\"0.45\", \"best_ask\":\"0.46\"}], \"timestamp\":\"1781254837823\", \"event_type\":\"price_change\"}","ts_local_ms":1781254838131}
{"dir":"in","text":"{\"market\":\"0x9c535590faae21bf76fed844aa47fc3c5c82253ef38bd545bf12c93470502685\", \"price_changes\":[{\"asset_id\":\"107011546575057755426871645700605806081353395825571114128343592072429146374928\", \"price\":\"0.54\", \"size\":\"511.44\", \"side\":\"BUY\", \"hash\":\"e2bf5a4147d1620a0b0929a10e79d9b1dcd0b7a9\", \"best_bid\":\"0.54\", \"best_ask\":\"0.55\"}, {\"asset_id\":\"56108879726720646120583724001239294777304794469144970684362785767667828318889\", \"price\":\"0.46\", \"size\":\"511.44\", \"side\":\"SELL\", \"hash\":\"28be12ecdadd8343b5d356ae9825702c42ccd089\", \"best_bid\":\"0.45\", \"best_ask\":\"0.46\"}], \"timestamp\":\"1781254837823\", \"event_type\":\"price_change\"}","ts_local_ms":1781254838131}
{"dir":"in","text":"{\"market\":\"0x9c535590faae21bf76fed844aa47fc3c5c82253ef38bd545bf12c93470502685\", \"price_changes\":[{\"asset_id\":\"56108879726720646120583724001239294777304794469144970684362785767667828318889\", \"price\":\"0.01\", \"size\":\"56799.15\", \"side\":\"BUY\", \"hash\":\"1d7260b7e8a8e04c381f4d99f7276c38d1ea8214\", \"best_bid\":\"0.45\", \"best_ask\":\"0.46\"}, {\"asset_id\":\"107011546575057755426871645700605806081353395825571114128343592072429146374928\", \"price\":\"0.99\", \"size\":\"56799.15\", \"side\":\"SELL\", \"hash\":\"9c8710c31b1698ebc7d100f856c64979df3283a1\", \"best_bid\":\"0.54\", \"best_ask\":\"0.55\"}], \"timestamp\":\"1781254837825\", \"event_type\":\"price_change\"}","ts_local_ms":1781254838132}
{"dir":"in","text":"{\"market\":\"0x9c535590faae21bf76fed844aa47fc3c5c82253ef38bd545bf12c93470502685\", \"price_changes\":[{\"asset_id\":\"107011546575057755426871645700605806081353395825571114128343592072429146374928\", \"price\":\"0.54\", \"size\":\"520.44\", \"side\":\"BUY\", \"hash\":\"06f73042b96ac5ab995256c2ae0dc2fc8e883409\", \"best_bid\":\"0.54\", \"best_ask\":\"0.55\"}, {\"asset_id\":\"56108879726720646120583724001239294777304794469144970684362785767667828318889\", \"price\":\"0.46\", \"size\":\"520.44\", \"side\":\"SELL\", \"hash\":\"8619c22de99529e292b5239e8935b318d46fb502\", \"best_bid\":\"0.45\", \"best_ask\":\"0.46\"}], \"timestamp\":\"1781254837827\", \"event_type\":\"price_change\"}","ts_local_ms":1781254838134}
{"dir":"in","text":"{\"market\":\"0x9c535590faae21bf76fed844aa47fc3c5c82253ef38bd545bf12c93470502685\", \"price_changes\":[{\"asset_id\":\"107011546575057755426871645700605806081353395825571114128343592072429146374928\", \"price\":\"0.54\", \"size\":\"497.44\", \"side\":\"BUY\", \"hash\":\"fd5c72ea9974aa1413202b1e66d89999056bfb90\", \"best_bid\":\"0.54\", \"best_ask\":\"0.55\"}, {\"asset_id\":\"56108879726720646120583724001239294777304794469144970684362785767667828318889\", \"price\":\"0.46\", \"size\":\"497.44\", \"side\":\"SELL\", \"hash\":\"075cfb1e4219a978de5e5d6b3486c3f055f1d990\", \"best_bid\":\"0.45\", \"best_ask\":\"0.46\"}], \"timestamp\":\"1781254837828\", \"event_type\":\"price_change\"}","ts_local_ms":1781254838135}
{"dir":"in","text":"{\"market\":\"0x9c535590faae21bf76fed844aa47fc3c5c82253ef38bd545bf12c93470502685\", \"price_changes\":[{\"asset_id\":\"107011546575057755426871645700605806081353395825571114128343592072429146374928\", \"price\":\"0.54\", \"size\":\"486.44\", \"side\":\"BUY\", \"hash\":\"bfed010730fd3cc8eda5b4ea3c07f797dd596a3e\", \"best_bid\":\"0.54\", \"best_ask\":\"0.55\"}, {\"asset_id\":\"56108879726720646120583724001239294777304794469144970684362785767667828318889\", \"price\":\"0.46\", \"size\":\"486.44\", \"side\":\"SELL\", \"hash\":\"590078ecaa0f8021c9324e2facab5e3bc3ad362d\", \"best_bid\":\"0.45\", \"best_ask\":\"0.46\"}], \"timestamp\":\"1781254837831\", \"event_type\":\"price_change\"}","ts_local_ms":1781254838140}
{"dir":"in","text":"{\"market\":\"0x9c535590faae21bf76fed844aa47fc3c5c82253ef38bd545bf12c93470502685\", \"price_changes\":[{\"asset_id\":\"107011546575057755426871645700605806081353395825571114128343592072429146374928\", \"price\":\"0.51\", \"size\":\"217.5\", \"side\":\"BUY\", \"hash\":\"bb5122ba3f194e3427fc362432ba71a103f4057a\", \"best_bid\":\"0.54\", \"best_ask\":\"0.55\"}, {\"asset_id\":\"56108879726720646120583724001239294777304794469144970684362785767667828318889\", \"price\":\"0.49\", \"size\":\"217.5\", \"side\":\"SELL\", \"hash\":\"a071e6bb719181200de23d31e486903fd68193b7\", \"best_bid\":\"0.45\", \"best_ask\":\"0.46\"}], \"timestamp\":\"1781254837832\", \"event_type\":\"price_change\"}","ts_local_ms":1781254838140}
{"dir":"in","text":"{\"market\":\"0x9c535590faae21bf76fed844aa47fc3c5c82253ef38bd545bf12c93470502685\", \"price_changes\":[{\"asset_id\":\"107011546575057755426871645700605806081353395825571114128343592072429146374928\", \"price\":\"0.45\", \"size\":\"101.3\", \"side\":\"BUY\", \"hash\":\"9d6e277a153d5dd63280e968f53ecaacdaf6f77d\", \"best_bid\":\"0.54\", \"best_ask\":\"0.55\"}, {\"asset_id\":\"56108879726720646120583724001239294777304794469144970684362785767667828318889\", \"price\":\"0.55\", \"size\":\"101.3\", \"side\":\"SELL\", \"hash\":\"17a557c41797b10687570e2bc89d3e2ac4e35497\", \"best_bid\":\"0.45\", \"best_ask\":\"0.46\"}], \"timestamp\":\"1781254837834\", \"event_type\":\"price_change\"}","ts_local_ms":1781254838141}
{"dir":"in","text":"{\"market\":\"0x9c535590faae21bf76fed844aa47fc3c5c82253ef38bd545bf12c93470502685\", \"price_changes\":[{\"asset_id\":\"107011546575057755426871645700605806081353395825571114128343592072429146374928\", \"price\":\"0.54\", \"size\":\"475.44\", \"side\":\"BUY\", \"hash\":\"9ec20cfb86571d3a28beaf03c6b13ae91baf62da\", \"best_bid\":\"0.54\", \"best_ask\":\"0.55\"}, {\"asset_id\":\"56108879726720646120583724001239294777304794469144970684362785767667828318889\", \"price\":\"0.46\", \"size\":\"475.44\", \"side\":\"SELL\", \"hash\":\"06218f44ba9c8056381e8e46db8c676b879e5053\", \"best_bid\":\"0.45\", \"best_ask\":\"0.46\"}], \"timestamp\":\"1781254837834\", \"event_type\":\"price_change\"}","ts_local_ms":1781254838141}
{"dir":"in","text":"{\"market\":\"0x9c535590faae21bf76fed844aa47fc3c5c82253ef38bd545bf12c93470502685\", \"price_changes\":[{\"asset_id\":\"107011546575057755426871645700605806081353395825571114128343592072429146374928\", \"price\":\"0.54\", \"size\":\"485.44\", \"side\":\"BUY\", \"hash\":\"a46163b8d49a2dce60e01f7a906d02a2d96ed09d\", \"best_bid\":\"0.54\", \"best_ask\":\"0.55\"}, {\"asset_id\":\"56108879726720646120583724001239294777304794469144970684362785767667828318889\", \"price\":\"0.46\", \"size\":\"485.44\", \"side\":\"SELL\", \"hash\":\"73b2893aa6c9fc282110e1a5111509a9f9c9fc3a\", \"best_bid\":\"0.45\", \"best_ask\":\"0.46\"}], \"timestamp\":\"1781254837835\", \"event_type\":\"price_change\"}","ts_local_ms":1781254838142}
{"dir":"in","text":"{\"market\":\"0x9c535590faae21bf76fed844aa47fc3c5c82253ef38bd545bf12c93470502685\", \"price_changes\":[{\"asset_id\":\"107011546575057755426871645700605806081353395825571114128343592072429146374928\", \"price\":\"0.54\", \"size\":\"494.44\", \"side\":\"BUY\", \"hash\":\"570dc48306d6d61c96f38bda2c5d532cad125f4d\", \"best_bid\":\"0.54\", \"best_ask\":\"0.55\"}, {\"asset_id\":\"56108879726720646120583724001239294777304794469144970684362785767667828318889\", \"price\":\"0.46\", \"size\":\"494.44\", \"side\":\"SELL\", \"hash\":\"f86d989cd2d39285d1757e24438119cdf431c600\", \"best_bid\":\"0.45\", \"best_ask\":\"0.46\"}], \"timestamp\":\"1781254837835\", \"event_type\":\"price_change\"}","ts_local_ms":1781254838143}
{"dir":"in","text":"{\"market\":\"0x9c535590faae21bf76fed844aa47fc3c5c82253ef38bd545bf12c93470502685\", \"price_changes\":[{\"asset_id\":\"107011546575057755426871645700605806081353395825571114128343592072429146374928\", \"price\":\"0.54\", \"size\":\"503.44\", \"side\":\"BUY\", \"hash\":\"e891374e28ad133bfbc09ed676781d560bb7ac22\", \"best_bid\":\"0.54\", \"best_ask\":\"0.55\"}, {\"asset_id\":\"56108879726720646120583724001239294777304794469144970684362785767667828318889\", \"price\":\"0.46\", \"size\":\"503.44\", \"side\":\"SELL\", \"hash\":\"62283e7747ec13c10bea928354c624f63b46baea\", \"best_bid\":\"0.45\", \"best_ask\":\"0.46\"}], \"timestamp\":\"1781254837836\", \"event_type\":\"price_change\"}","ts_local_ms":1781254838143}
{"dir":"in","text":"{\"market\":\"0x9c535590faae21bf76fed844aa47fc3c5c82253ef38bd545bf12c93470502685\", \"price_changes\":[{\"asset_id\":\"56108879726720646120583724001239294777304794469144970684362785767667828318889\", \"price\":\"0.32\", \"size\":\"244.34\", \"side\":\"BUY\", \"hash\":\"6cd4cc67b23024d4712eb3c41ce70489105a319e\", \"best_bid\":\"0.45\", \"best_ask\":\"0.46\"}, {\"asset_id\":\"107011546575057755426871645700605806081353395825571114128343592072429146374928\", \"price\":\"0.68\", \"size\":\"244.34\", \"side\":\"SELL\", \"hash\":\"884ac58b515616e9bd4c828fbad2f5cafb8601c9\", \"best_bid\":\"0.54\", \"best_ask\":\"0.55\"}], \"timestamp\":\"1781254837837\", \"event_type\":\"price_change\"}","ts_local_ms":1781254838144}
{"dir":"in","text":"{\"market\":\"0x9c535590faae21bf76fed844aa47fc3c5c82253ef38bd545bf12c93470502685\", \"price_changes\":[{\"asset_id\":\"107011546575057755426871645700605806081353395825571114128343592072429146374928\", \"price\":\"0.54\", \"size\":\"489.44\", \"side\":\"BUY\", \"hash\":\"8841a1583233268abe5998b9c652d99c55764096\", \"best_bid\":\"0.54\", \"best_ask\":\"0.55\"}, {\"asset_id\":\"56108879726720646120583724001239294777304794469144970684362785767667828318889\", \"price\":\"0.46\", \"size\":\"489.44\", \"side\":\"SELL\", \"hash\":\"d61307e60d1056778eb42ac1c1c7a95b02c9332c\", \"best_bid\":\"0.45\", \"best_ask\":\"0.46\"}], \"timestamp\":\"1781254837839\", \"event_type\":\"price_change\"}","ts_local_ms":1781254838147}
{"dir":"in","text":"{\"market\":\"0x9c535590faae21bf76fed844aa47fc3c5c82253ef38bd545bf12c93470502685\", \"price_changes\":[{\"asset_id\":\"107011546575057755426871645700605806081353395825571114128343592072429146374928\", \"price\":\"0.54\", \"size\":\"494.81\", \"side\":\"BUY\", \"hash\":\"7a2cc5bdc9b24434760f69665414c8b4dd97a9f0\", \"best_bid\":\"0.54\", \"best_ask\":\"0.55\"}, {\"asset_id\":\"56108879726720646120583724001239294777304794469144970684362785767667828318889\", \"price\":\"0.46\", \"size\":\"494.81\", \"side\":\"SELL\", \"hash\":\"1c9d6162638368ee947b9596dc7ad4896e5f0de3\", \"best_bid\":\"0.45\", \"best_ask\":\"0.46\"}], \"timestamp\":\"1781254837845\", \"event_type\":\"price_change\"}","ts_local_ms":1781254838153}
{"dir":"in","text":"{\"market\":\"0x9c535590faae21bf76fed844aa47fc3c5c82253ef38bd545bf12c93470502685\", \"price_changes\":[{\"asset_id\":\"56108879726720646120583724001239294777304794469144970684362785767667828318889\", \"price\":\"0.01\", \"size\":\"56899.15\", \"side\":\"BUY\", \"hash\":\"fc501d1d3e2d93f97ae1da65d329109c5e0fbd4f\", \"best_bid\":\"0.45\", \"best_ask\":\"0.46\"}, {\"asset_id\":\"107011546575057755426871645700605806081353395825571114128343592072429146374928\", \"price\":\"0.99\", \"size\":\"56899.15\", \"side\":\"SELL\", \"hash\":\"219afa3a0f7659fc5d0a32e08bcaa971e4f9e36b\", \"best_bid\":\"0.54\", \"best_ask\":\"0.55\"}], \"timestamp\":\"1781254837847\", \"event_type\":\"price_change\"}","ts_local_ms":1781254838157}
{"dir":"in","text":"{\"market\":\"0x9c535590faae21bf76fed844aa47fc3c5c82253ef38bd545bf12c93470502685\", \"price_changes\":[{\"asset_id\":\"107011546575057755426871645700605806081353395825571114128343592072429146374928\", \"price\":\"0.54\", \"size\":\"485.81\", \"side\":\"BUY\", \"hash\":\"4ab0862e9b794a776749b5970ee77aae895312c5\", \"best_bid\":\"0.54\", \"best_ask\":\"0.55\"}, {\"asset_id\":\"56108879726720646120583724001239294777304794469144970684362785767667828318889\", \"price\":\"0.46\", \"size\":\"485.81\", \"side\":\"SELL\", \"hash\":\"78deaa59a2e9852549d681510864383640ba3f03\", \"best_bid\":\"0.45\", \"best_ask\":\"0.46\"}], \"timestamp\":\"1781254837850\", \"event_type\":\"price_change\"}","ts_local_ms":1781254838157}
{"dir":"in","text":"{\"market\":\"0x9c535590faae21bf76fed844aa47fc3c5c82253ef38bd545bf12c93470502685\", \"price_changes\":[{\"asset_id\":\"107011546575057755426871645700605806081353395825571114128343592072429146374928\", \"price\":\"0.54\", \"size\":\"498.81\", \"side\":\"BUY\", \"hash\":\"fd551b6bb80d0876a53792a7cd12699f38f2fa25\", \"best_bid\":\"0.54\", \"best_ask\":\"0.55\"}, {\"asset_id\":\"56108879726720646120583724001239294777304794469144970684362785767667828318889\", \"price\":\"0.46\", \"size\":\"498.81\", \"side\":\"SELL\", \"hash\":\"d409d2dc02e63053213a0960176e315cc154fd52\", \"best_bid\":\"0.45\", \"best_ask\":\"0.46\"}], \"timestamp\":\"1781254837852\", \"event_type\":\"price_change\"}","ts_local_ms":1781254838159}
{"dir":"in","text":"{\"market\":\"0x9c535590faae21bf76fed844aa47fc3c5c82253ef38bd545bf12c93470502685\", \"price_changes\":[{\"asset_id\":\"107011546575057755426871645700605806081353395825571114128343592072429146374928\", \"price\":\"0.54\", \"size\":\"511.81\", \"side\":\"BUY\", \"hash\":\"5d48366668f612fa2a3c740dc266f7681c7b497c\", \"best_bid\":\"0.54\", \"best_ask\":\"0.55\"}, {\"asset_id\":\"56108879726720646120583724001239294777304794469144970684362785767667828318889\", \"price\":\"0.46\", \"size\":\"511.81\", \"side\":\"SELL\", \"hash\":\"6c28ef1797dabceb04cd6c61d1f5fab7d62a4ec6\", \"best_bid\":\"0.45\", \"best_ask\":\"0.46\"}], \"timestamp\":\"1781254837854\", \"event_type\":\"price_change\"}","ts_local_ms":1781254838162}
{"dir":"in","text":"{\"market\":\"0x9c535590faae21bf76fed844aa47fc3c5c82253ef38bd545bf12c93470502685\", \"price_changes\":[{\"asset_id\":\"107011546575057755426871645700605806081353395825571114128343592072429146374928\", \"price\":\"0.54\", \"size\":\"502.81\", \"side\":\"BUY\", \"hash\":\"e75cbc9ee2d94777e4ff7fc5c1fab736a15abb87\", \"best_bid\":\"0.54\", \"best_ask\":\"0.55\"}, {\"asset_id\":\"56108879726720646120583724001239294777304794469144970684362785767667828318889\", \"price\":\"0.46\", \"size\":\"502.81\", \"side\":\"SELL\", \"hash\":\"764f76215c81e1a24a1f3c4279dde1754452df1a\", \"best_bid\":\"0.45\", \"best_ask\":\"0.46\"}], \"timestamp\":\"1781254837855\", \"event_type\":\"price_change\"}","ts_local_ms":1781254838162}
{"dir":"in","text":"{\"market\":\"0x9c535590faae21bf76fed844aa47fc3c5c82253ef38bd545bf12c93470502685\", \"price_changes\":[{\"asset_id\":\"107011546575057755426871645700605806081353395825571114128343592072429146374928\", \"price\":\"0.54\", \"size\":\"489.81\", \"side\":\"BUY\", \"hash\":\"4fb985c5d6b06d4ed19667505f0b27c172ca70bc\", \"best_bid\":\"0.54\", \"best_ask\":\"0.55\"}, {\"asset_id\":\"56108879726720646120583724001239294777304794469144970684362785767667828318889\", \"price\":\"0.46\", \"size\":\"489.81\", \"side\":\"SELL\", \"hash\":\"777d6d0d44665d07ad524550d1bd25f5e96fa13d\", \"best_bid\":\"0.45\", \"best_ask\":\"0.46\"}], \"timestamp\":\"1781254837859\", \"event_type\":\"price_change\"}","ts_local_ms":1781254838166}
{"dir":"in","text":"{\"market\":\"0x9c535590faae21bf76fed844aa47fc3c5c82253ef38bd545bf12c93470502685\", \"price_changes\":[{\"asset_id\":\"107011546575057755426871645700605806081353395825571114128343592072429146374928\", \"price\":\"0.54\", \"size\":\"529.81\", \"side\":\"BUY\", \"hash\":\"e2dbf87116a14630636e294b98b51d3ba91671ed\", \"best_bid\":\"0.54\", \"best_ask\":\"0.55\"}, {\"asset_id\":\"56108879726720646120583724001239294777304794469144970684362785767667828318889\", \"price\":\"0.46\", \"size\":\"529.81\", \"side\":\"SELL\", \"hash\":\"ae7538b15d840c30ad7f3cd7aad88ad08fc30ed9\", \"best_bid\":\"0.45\", \"best_ask\":\"0.46\"}], \"timestamp\":\"1781254837860\", \"event_type\":\"price_change\"}","ts_local_ms":1781254838167}
{"dir":"in","text":"{\"market\":\"0x9c535590faae21bf76fed844aa47fc3c5c82253ef38bd545bf12c93470502685\", \"price_changes\":[{\"asset_id\":\"107011546575057755426871645700605806081353395825571114128343592072429146374928\", \"price\":\"0.01\", \"size\":\"55006.6\", \"side\":\"BUY\", \"hash\":\"28956203bda1dac6356f646e00467b954b540803\", \"best_bid\":\"0.54\", \"best_ask\":\"0.55\"}, {\"asset_id\":\"56108879726720646120583724001239294777304794469144970684362785767667828318889\", \"price\":\"0.99\", \"size\":\"55006.6\", \"side\":\"SELL\", \"hash\":\"f67b843e78876ebd0a5c98f11edca0a2c7664a02\", \"best_bid\":\"0.45\", \"best_ask\":\"0.46\"}], \"timestamp\":\"1781254837860\", \"event_type\":\"price_change\"}","ts_local_ms":1781254838167}
{"dir":"in","text":"{\"market\":\"0x9c535590faae21bf76fed844aa47fc3c5c82253ef38bd545bf12c93470502685\", \"price_changes\":[{\"asset_id\":\"107011546575057755426871645700605806081353395825571114128343592072429146374928\", \"price\":\"0.54\", \"size\":\"520.81\", \"side\":\"BUY\", \"hash\":\"93a235a67b57d5b1b53c70528b3f8a0422b00c8a\", \"best_bid\":\"0.54\", \"best_ask\":\"0.55\"}, {\"asset_id\":\"56108879726720646120583724001239294777304794469144970684362785767667828318889\", \"price\":\"0.46\", \"size\":\"520.81\", \"side\":\"SELL\", \"hash\":\"23f03ff657471f760db22e47fb46d8c5d1a7af99\", \"best_bid\":\"0.45\", \"best_ask\":\"0.46\"}], \"timestamp\":\"1781254837861\", \"event_type\":\"price_change\"}","ts_local_ms":1781254838168}
{"dir":"in","text":"{\"market\":\"0x9c535590faae21bf76fed844aa47fc3c5c82253ef38bd545bf12c93470502685\", \"price_changes\":[{\"asset_id\":\"107011546575057755426871645700605806081353395825571114128343592072429146374928\", \"price\":\"0.54\", \"size\":\"530.81\", \"side\":\"BUY\", \"hash\":\"75b891b43e841e80598fb9fbe7ca0a2fd51bd8f2\", \"best_bid\":\"0.54\", \"best_ask\":\"0.55\"}, {\"asset_id\":\"56108879726720646120583724001239294777304794469144970684362785767667828318889\", \"price\":\"0.46\", \"size\":\"530.81\", \"side\":\"SELL\", \"hash\":\"d0bdf140ab00992971a664df102fe42bbc8a71b5\", \"best_bid\":\"0.45\", \"best_ask\":\"0.46\"}], \"timestamp\":\"1781254837862\", \"event_type\":\"price_change\"}","ts_local_ms":1781254838170}
